Workbook

Sheet Executive Summary
B1: DISCLAIMER: This is a sample analysis for demonstration purposes only. It does not constitute investment advice.
B3: Core Corporation (2359.T)
B4: Equity Research Report
B6: Company | C6: Core Corporation
B7: Ticker | C7: 2359.T (TSE Prime)
B8: Sector | C8: Information & Communication
B9: Current Price | C9: 2230
B10: Target Price (Mid) | C10: =ROUND(AVERAGE(C16:C19),0) -> 2520
B11: Recommendation | C11: =IF(C12>0.15,"BUY",IF(C12>0.05,"HOLD","SELL")) -> HOLD
B12: Upside / Downside | C12: =(C10-C9)/C9 -> 0.13004484
B14: Valuation Summary
B15: Methodology | C15: Implied Value (JPY) | D15: vs Current Price
B16: DCF - Perpetuity Growth | C16: ='DCF Model'!C53 -> 2804 | D16: =(C16-C9)/C9 -> 0.2573991
B17: DCF - Exit Multiple | C17: ='DCF Model'!C62 -> 3546 | D17: =(C17-C9)/C9 -> 0.59013453
B18: Comps - EV/EBITDA Median | C18: ='Comps Analysis'!C27 -> 2307 | D18: =(C18-C9)/C9 -> 0.034529148
B19: Comps - PER Median | C19: ='Comps Analysis'!C28 -> 1423 | D19: =(C19-C9)/C9 -> -0.36188341
B21: Integrated Valuation Range | C21: =MIN(C16:C19)&" - "&MAX(C16:C19) -> 1423 - 3546
B23: Key Investment Thesis
B24: 1. Stable IT services business with consistent revenue growth
B25: 2. Strong net cash position (JPY 10.5bn) providing downside protection
B26: 3. Expanding margins through operational efficiency improvements
B28: Key Risks
B29: 1. Mature domestic IT services market with limited upside surprise
B30: 2. Labor shortage in Japan's IT sector could pressure margins
B31: 3. Low growth profile limits re-rating potential

Sheet Financial Statements
B2: Core Corporation - Historical Financials (JPY mn)
C4: FY2020 | D4: FY2021 | E4: FY2022 | F4: FY2023 | G4: FY2024E
B5: Income Statement
B6: Revenue | C6: 20904 | D6: 21919 | E6: 22534 | F6: 23554 | G6: 24500
B7: COGS | C7: 16570 | D7: 17290 | E7: 17578 | F7: 18378 | G7: 19110
B8: Gross Profit | C8: =C6-C7 -> 4334 | D8: =D6-D7 -> 4629 | E8: =E6-E7 -> 4956 | F8: =F6-F7 -> 5176 | G8: =G6-G7 -> 5390
B9: Gross Margin | C9: =C8/C6 -> 0.20732874 | D9: =D8/D6 -> 0.21118664 | E9: =E8/E6 -> 0.21993432 | F9: =F8/F6 -> 0.21975036 | G9: =G8/G6 -> 0.22
B10: SGA | C10: 2525 | D10: 2649 | E10: 2816 | F10: 2981 | G10: 3100
B11: Operating Income | C11: 1808 | D11: 1979 | E11: 2139 | F11: 2194 | G11: 2290
B12: Net Income | C12: 1186 | D12: 1284 | E12: 1515 | F12: 1488 | G12: 1550
B13: Operating Margin | C13: =C11/C6 -> 0.086490624 | D13: =D11/D6 -> 0.090286966 | E13: =E11/E6 -> 0.094923227 | F13: =F11/F6 -> 0.093147661 | G13: =G11/G6 -> 0.093469388
B14: Net Margin | C14: =C12/C6 -> 0.056735553 | D14: =D12/D6 -> 0.058579315 | E14: =E12/E6 -> 0.067231739 | F14: =F12/F6 -> 0.063173983 | G14: =G12/G6 -> 0.063265306
B15: Revenue Growth (YoY) | C15: n/a | D15: =(D6-C6)/C6 -> 0.0485553 | E15: =(E6-D6)/D6 -> 0.028057849 | F15: =(F6-E6)/E6 -> 0.045264933 | G15: =(G6-F6)/F6 -> 0.04016303
B16: Operating Income Growth (YoY) | C16: n/a | D16: =(D11-C11)/C11 -> 0.094579646 | E16: =(E11-D11)/D11 -> 0.080848914 | F16: =(F11-E11)/E11 -> 0.02571295 | G16: =(G11-F11)/F11 -> 0.043755697
B18: Cash Flow Statement
B19: Operating Cash Flow | C19: 1323 | D19: 2118 | E19: 1172 | F19: 2302 | G19: 2000
B20: Capex | C20: 151 | D20: 144 | E20: 202 | F20: 107 | G20: 150
B21: Free Cash Flow | C21: =C19-C20 -> 1172 | D21: =D19-D20 -> 1974 | E21: =E19-E20 -> 970 | F21: =F19-F20 -> 2195 | G21: =G19-G20 -> 1850
B22: FCF Margin | C22: =C21/C6 -> 0.056065825 | D22: =D21/D6 -> 0.090058853 | E22: =E21/E6 -> 0.043046064 | F22: =F21/F6 -> 0.093190116 | G22: =G21/G6 -> 0.075510204
B23: Capex / Revenue | C23: =C20/C6 -> 0.0072234979 | D23: =D20/D6 -> 0.0065696428 | E23: =E20/E6 -> 0.0089642318 | F23: =F20/F6 -> 0.0045427528 | G23: =G20/G6 -> 0.006122449
B25: Balance Sheet Highlights
B26: Cash & Deposits | C26: 7703 | D26: 9089 | E26: 9370 | F26: 10260 | G26: 10500
B27: Short-term Debt | C27: 38 | D27: 30 | E27: 8 | F27: 3 | G27: 0
B28: Net Debt (Cash) | C28: =C27-C26 -> -7665 | D28: =D27-D26 -> -9059 | E28: =E27-E26 -> -9362 | F28: =F27-F26 -> -10257 | G28: =G27-G26 -> -10500

Sheet DCF Model
B2: DCF Valuation Model - Core Corporation
B4: Assumptions
B5: Capex / Revenue | C5: 0.008
B6: Effective Tax Rate | C6: 0.306
B7: Risk-Free Rate | C7: 0.022
B8: Beta | C8: 0.88
B9: Equity Risk Premium | C9: 0.06
B10: Size Premium | C10: 0.04
B11: After-tax Cost of Debt | C11: 0.01
B12: D/E Ratio | C12: 0.05
B13: Terminal Growth Rate | C13: 0.01
B14: Exit Multiple (EV/EBITDA) | C14: 9.3
B15: Fully Diluted Shares | C15: 14368501
B16: Net Debt (JPY mn) | C16: -10257
... B18: D&A / Revenue | C18: 0.008
B20: WACC Calculation
B21: Cost of Equity (Ke) | C21: =C7+C8*C9+C10 -> 0.1148
B22: Weight of Equity | C22: =1/(1+C12) -> 0.95238095
B23: Weight of Debt | C23: =C12/(1+C12) -> 0.047619048
B24: WACC | C24: =C21*C22+C11*C23 -> 0.10980952
B25: Active Scenario | C25: Base | D25: =MATCH(C25,B67:B71,0) -> 1
B26: Projected Free Cash Flow
C27: Year 1 | D27: Year 2 | E27: Year 3 | F27: Year 4 | G27: Year 5
B28: Revenue Growth (YoY) | C28: =CHOOSE($D$25,C67,C68,C69,C70,C71) -> 0.1 | D28: =CHOOSE($D$25,D67,D68,D69,D70,D71) -> 0.08 | E28: =CHOOSE($D$25,E67,E68,E69,E70,E71) -> 0.06 | F28: =CHOOSE($D$25,F67,F68,F69,F70,F71) -> 0.06 | G28: =CHOOSE($D$25,G67,G68,G69,G70,G71) -> 0.04
B29: COGS % of Revenue | C29: =CHOOSE($D$25,C74,C75,C76,C77,C78) -> 0.7 | D29: =CHOOSE($D$25,D74,D75,D76,D77,D78) -> 0.7 | E29: =CHOOSE($D$25,E74,E75,E76,E77,E78) -> 0.7 | F29: =CHOOSE($D$25,F74,F75,F76,F77,F78) -> 0.7 | G29: =CHOOSE($D$25,G74,G75,G76,G77,G78) -> 0.7
B30: SGA % of Revenue | C30: =CHOOSE($D$25,C81,C82,C83,C84,C85) -> 0.145 | D30: =CHOOSE($D$25,D81,D82,D83,D84,D85) -> 0.145 | E30: =CHOOSE($D$25,E81,E82,E83,E84,E85) -> 0.145 | F30: =CHOOSE($D$25,F81,F82,F83,F84,F85) -> 0.145 | G30: =CHOOSE($D$25,G81,G82,G83,G84,G85) -> 0.145
B31: Revenue | C31: =C17*(1+C28) -> 26950 | D31: =C31*(1+D28) -> 29106 | E31: =D31*(1+E28) -> 30852.36 | F31: =E31*(1+F28) -> 32703.502 | G31: =F31*(1+G28) -> 34011.642
B32: COGS | C32: =C31*C29 -> 18865 | D32: =D31*D29 -> 20374.2 | E32: =E31*E29 -> 21596.652 | F32: =F31*F29 -> 22892.451 | G32: =G31*G29 -> 23808.149
B33: Gross Profit | C33: =C31-C32 -> 8085 | D33: =D31-D32 -> 8731.8 | E33: =E31-E32 -> 9255.708 | F33: =F31-F32 -> 9811.0505 | G33: =G31-G32 -> 10203.492
B34: Gross Margin | C34: =C33/C31 -> 0.3 | D34: =D33/D31 -> 0.3 | E34: =E33/E31 -> 0.3 | F34: =F33/F31 -> 0.3 | G34: =G33/G31 -> 0.3
B35: SGA Expense | C35: =C31*C30 -> 3907.75 | D35: =D31*D30 -> 4220.37 | E35: =E31*E30 -> 4473.5922 | F35: =F31*F30 -> 4742.0077 | G35: =G31*G30 -> 4931.688
B36: Implied Operating Margin | C36: =(C33-C35)/C31 -> 0.155 | D36: =(D33-D35)/D31 -> 0.155 | E36: =(E33-E35)/E31 -> 0.155 | F36: =(F33-F35)/F31 -> 0.155 | G36: =(G33-G35)/G31 -> 0.155
B37: Operating Income (EBIT) | C37: =C33-C35 -> 4177.25 | D37: =D33-D35 -> 4511.43 | E37: =E33-E35 -> 4782.1158 | F37: =F33-F35 -> 5069.0427 | G37: =G33-G35 -> 5271.8045
B38: Less: Tax | C38: =MAX(0,C37*C6) -> 1278.2385 | D38: =MAX(0,D37*C6) -> 1380.4976 | E38: =MAX(0,E37*C6) -> 1463.3274 | F38: =MAX(0,F37*C6) -> 1551.1271 | G38: =MAX(0,G37*C6) -> 1613.1722
B39: NOPAT | C39: =C37-C38 -> 2899.0115 | D39: =D37-D38 -> 3130.9324 | E39: =E37-E38 -> 3318.7884 | F39: =F37-F38 -> 3517.9157 | G39: =G37-G38 -> 3658.6323
B40: Plus: D&A | C40: =C31*C18 -> 215.6 | D40: =D31*C18 -> 232.848 | E40: =E31*C18 -> 246.81888 | F40: =F31*C18 -> 261.62801 | G40: =G31*C18 -> 272.09313
B41: Less: Capex | C41: =C31*C5 -> 215.6 | D41: =D31*C5 -> 232.848 | E41: =E31*C5 -> 246.81888 | F41: =F31*C5 -> 261.62801 | G41: =G31*C5 -> 272.09313
B42: Change in NWC | C42: ='NWC Schedule'!D19 -> 791.23288 | D42: ='NWC Schedule'!E19 -> 843.26181 | E42: ='NWC Schedule'!F19 -> 283.32498 | F42: ='NWC Schedule'!G19 -> 307.93191 | G42: ='NWC Schedule'!H19 -> 337.07006
B43: Unlevered Free Cash Flow | C43: =C39+C40-C41-C42 -> 2107.7786 | D43: =D39+D40-D41-D42 -> 2287.6706 | E43: =E39+E40-E41-E42 -> 3035.4634 | F43: =F39+F40-F41-F42 -> 3209.9838 | G43: =G39+G40-G41-G42 -> 3321.5622
B44: Discount Factor | C44: =1/(1+C24)^1 -> 0.90105552 | D44: =1/(1+C24)^2 -> 0.81190105 | E44: =1/(1+C24)^3 -> 0.73156793 | F44: =1/(1+C24)^4 -> 0.65918332 | G44: =1/(1+C24)^5 -> 0.59396077
...

Sheet NWC Schedule
B2: NWC Schedule - Core Corporation
B4: Working Capital Drivers (Days) | C4: Base Year | D4: Year 1 | E4: Year 2 | F4: Year 3 | G4: Year 4 | H4: Year 5
B5: DSO (Days Sales Outstanding) | C5: =C12/C9*365 -> 114.99735 | D5: =CHOOSE('DCF Model'!$D$25,D25,D26,D27,D28,D29) -> 115 | E5: =CHOOSE('DCF Model'!$D$25,E25,E26,E27,E28,E29) -> 118 | F5: =CHOOSE('DCF Model'!$D$25,F25,F26,F27,F28,F29) -> 116 | G5: =CHOOSE('DCF Model'!$D$25,G25,G26,G27,G28,G29) -> 114 | H5: =CHOOSE('DCF Model'!$D$25,H25,H26,H27,H28,H29) -> 114
B6: DIH (Days Inventory Held) | C6: =C13/C10*365 -> 5.9973836 | D6: =CHOOSE('DCF Model'!$D$25,D32,D33,D34,D35,D36) -> 6 | E6: =CHOOSE('DCF Model'!$D$25,E32,E33,E34,E35,E36) -> 5.8 | F6: =CHOOSE('DCF Model'!$D$25,F32,F33,F34,F35,F36) -> 5.5 | G6: =CHOOSE('DCF Model'!$D$25,G32,G33,G34,G35,G36) -> 5.5 | H6: =CHOOSE('DCF Model'!$D$25,H32,H33,H34,H35,H36) -> 5.5
B7: DPO (Days Payable Outstanding) | C7: =C15/C10*365 -> 34.991104 | D7: =CHOOSE('DCF Model'!$D$25,D39,D40,D41,D42,D43) -> 35 | E7: =CHOOSE('DCF Model'!$D$25,E39,E40,E41,E42,E43) -> 34 | F7: =CHOOSE('DCF Model'!$D$25,F39,F40,F41,F42,F43) -> 34 | G7: =CHOOSE('DCF Model'!$D$25,G39,G40,G41,G42,G43) -> 34 | H7: =CHOOSE('DCF Model'!$D$25,H39,H40,H41,H42,H43) -> 34
B8: P&L Reference (JPY mn)
B9: Revenue | C9: 24500 | D9: ='DCF Model'!C31 -> 26950 | E9: ='DCF Model'!D31 -> 29106 | F9: ='DCF Model'!E31 -> 30852.36 | G9: ='DCF Model'!F31 -> 32703.502 | H9: ='DCF Model'!G31 -> 34011.642
B10: COGS | C10: 19110 | D10: ='DCF Model'!C32 -> 18865 | E10: ='DCF Model'!D32 -> 20374.2 | F10: ='DCF Model'!E32 -> 21596.652 | G10: ='DCF Model'!F32 -> 22892.451 | H10: ='DCF Model'!G32 -> 23808.149
B11: Working Capital Items (JPY mn)
B12: Accounts Receivable | C12: 7719 | D12: =D9*D5/365 -> 8491.0959 | E12: =E9*E5/365 -> 9409.611 | F12: =F9*F5/365 -> 9805.1336 | G12: =G9*G5/365 -> 10214.244 | H12: =H9*H5/365 -> 10622.814
B13: Inventory | C13: 314 | D13: =D10*D6/365 -> 310.10959 | E13: =E10*E6/365 -> 323.75441 | F13: =F10*F6/365 -> 325.429 | G13: =G10*G6/365 -> 344.95474 | H13: =H10*H6/365 -> 358.75293
B14: Current Assets (AR + Inv) | C14: =C12+C13 -> 8033 | D14: =D12+D13 -> 8801.2055 | E14: =E12+E13 -> 9733.3654 | F14: =F12+F13 -> 10130.563 | G14: =G12+G13 -> 10559.199 | H14: =H12+H13 -> 10981.567
B15: Accounts Payable | C15: 1832 | D15: =D10*D7/365 -> 1808.9726 | E15: =E10*E7/365 -> 1897.8707 | F15: =F10*F7/365 -> 2011.7429 | G15: =G10*G7/365 -> 2132.4475 | H15: =H10*H7/365 -> 2217.7454
B16: Current Liabilities (AP) | C16: =C15 -> 1832 | D16: =D15 -> 1808.9726 | E16: =E15 -> 1897.8707 | F16: =F15 -> 2011.7429 | G16: =G15 -> 2132.4475 | H16: =H15 -> 2217.7454
B17: Net Working Capital (JPY mn)
B18: Net Working Capital | C18: =C14-C16 -> 6201 | D18: =D14-D16 -> 6992.2329 | E18: =E14-E16 -> 7835.4947 | F18: =F14-F16 -> 8118.8197 | G18: =G14-G16 -> 8426.7516 | H18: =H14-H16 -> 8763.8216
B19: Change in NWC | C19: n/a | D19: =D18-C18 -> 791.23288 | E19: =E18-D18 -> 843.26181 | F19: =F18-E18 -> 283.32498 | G19: =G18-F18 -> 307.93191 | H19: =H18-G18 -> 337.07006
B22: Scenario Input Matrix (Working Capital Days)
D23: Year 1 | E23: Year 2 | F23: Year 3 | G23: Year 4 | H23: Year 5
B24: DSO (Days)
B25: Base | D25: 115 | E25: 118 | F25: 116 | G25: 114 | H25: 114
B26: Upside | D26: 105 | E26: 105 | F26: 105 | G26: 105 | H26: 105
B27: Management | D27: 115 | E27: 115 | F27: 115 | G27: 115 | H27: 115
B28: Downside 1 | D28: 120 | E28: 120 | F28: 120 | G28: 120 | H28: 120
B29: Downside 2 | D29: 125 | E29: 125 | F29: 125 | G29: 125 | H29: 125
B31: DIH (Days)
B32: Base | D32: 6 | E32: 5.8 | F32: 5.5 | G32: 5.5 | H32: 5.5
B33: Upside | D33: 5 | E33: 5 | F33: 5 | G33: 5 | H33: 5
B34: Management | D34: 6 | E34: 6 | F34: 6 | G34: 6 | H34: 6
B35: Downside 1 | D35: 7 | E35: 7 | F35: 7 | G35: 7 | H35: 7
B36: Downside 2 | D36: 8 | E36: 8 | F36: 8 | G36: 8 | H36: 8
B38: DPO (Days)
B39: Base | D39: 35 | E39: 34 | F39: 34 | G39: 34 | H39: 34
B40: Upside | D40: 40 | E40: 40 | F40: 40 | G40: 40 | H40: 40
B41: Management | D41: 35 | E41: 35 | F41: 35 | G41: 35 | H41: 35
B42: Downside 1 | D42: 33 | E42: 33 | F42: 33 | G42: 33 | H42: 33
B43: Downside 2 | D43: 30 | E43: 30 | F43: 30 | G43: 30 | H43: 30

Sheet Comps Analysis
B2: Comparable Company Analysis
B4: Company | C4: Ticker | D4: Mkt Cap (JPY mn) | E4: EV (JPY mn) | F4: Revenue (JPY mn) | G4: EBITDA (JPY mn) | H4: Op Income (JPY mn) | I4: Net Income (JPY mn) | J4: EV/EBITDA | K4: EV/Revenue | L4: PER | M4: PBR | N4: Op Margin | O4: ROE
B5: Systena | C5: 2317.T | D5: 152991.11 | E5: 154541.11 | F5: 92410 | G5: 15820 | H5: 15360 | I5: 11250 | J5: =E5/G5 -> 9.7687171 | K5: =E5/F5 -> 1.6723418 | L5: =D5/I5 -> 13.599209 | M5: 4.6431291 | N5: =H5/F5 -> 0.16621578 | O5: 0.3414264
B6: SRA HD | C6: 3817.T | D6: 62727.258 | E6: 62797.258 | F6: 54700 | G6: 8490 | H6: 8300 | I6: 5000 | J6: =E6/G6 -> 7.3966146 | K6: =E6/F6 -> 1.1480303 | L6: =D6/I6 -> 12.545452 | M6: 2.0167591 | N6: =H6/F6 -> 0.15173675 | O6: 0.1607562
B7: CEC | C7: 9692.T | D7: 61359.772 | E7: 61709.772 | F7: 65000 | G7: 8018 | H7: 7200 | I7: 5150 | J7: =E7/G7 -> 7.6964045 | K7: =E7/F7 -> 0.9493811 | L7: =D7/I7 -> 11.914519 | M7: 1.5187686 | N7: =H7/F7 -> 0.11076923 | O7: 0.12747209
B8: Cube Systems | C8: 2335.T | D8: 16087.69 | E8: 16317.69 | F8: 19500 | G8: 1807 | H8: 1750 | I8: 1220 | J8: =E8/G8 -> 9.0302658 | K8: =E8/F8 -> 0.83680463 | L8: =D8/I8 -> 13.186631 | M8: 1.4794639 | N8: =H8/F8 -> 0.08974359 | O8: 0.11219422
B9: Sansan | C9: 4443.T | D9: 156880.95 | E9: 160452.95 | F9: 53651 | G9: 8992 | H9: 8052 | I9: 5364 | J9: =E9/G9 -> 17.843966 | K9: =E9/F9 -> 2.9906795 | L9: =D9/I9 -> 29.247007 | M9: 9.7806076 | N9: =H9/F9 -> 0.15008108 | O9: 0.33441397
B14: Statistics
B15: 25th Percentile | D15: =PERCENTILE(J5:J9,0.25) -> 7.6964045 | E15: =PERCENTILE(K5:K9,0.25) -> 0.9493811 | F15: =PERCENTILE(L5:L9,0.25) -> 12.545452 | G15: =PERCENTILE(M5:M9,0.25) -> 1.5187686 | H15: =PERCENTILE(N5:N9,0.25) -> 0.11076923 | I15: =PERCENTILE(O5:O9,0.25) -> 0.12747209
B16: Median (50th) | D16: =MEDIAN(J5:J9) -> 9.0302658 | E16: =MEDIAN(K5:K9) -> 1.1480303 | F16: =MEDIAN(L5:L9) -> 13.186631 | G16: =MEDIAN(M5:M9) -> 2.0167591 | H16: =MEDIAN(N5:N9) -> 0.15008108 | I16: =MEDIAN(O5:O9) -> 0.1607562
B17: 75th Percentile | D17: =PERCENTILE(J5:J9,0.75) -> 9.7687171 | E17: =PERCENTILE(K5:K9,0.75) -> 1.6723418 | F17: =PERCENTILE(L5:L9,0.75) -> 13.599209 | G17: =PERCENTILE(M5:M9,0.75) -> 4.6431291 | H17: =PERCENTILE(N5:N9,0.75) -> 0.15173675 | I17: =PERCENTILE(O5:O9,0.75) -> 0.33441397
B19: Implied Valuation for Core Corporation
B20: Core Corporation Financials
B21: EBITDA (JPY mn) | C21: 2535
B22: Net Income (JPY mn) | C22: 1550
B23: Shares Outstanding | C23: 14368501
B24: Net Debt (JPY mn) | C24: -10257
B26: Implied Share Price (Median Multiples)
B27: Via EV/EBITDA (Median) | C27: =ROUND((C21*D16-C24)*1000000/C23,0) -> 2307
B28: Via PER (Median) | C28: =ROUND(C22*F16*1000000/C23,0) -> 1423

Sheet Sensitivity Analysis
B2: Sensitivity Analysis
B3: Current WACC: | C3: ='DCF Model'!C24 -> 0.10980952 | E3: Terminal g: | F3: ='DCF Model'!C13 -> 0.01 | H3: Exit Multiple: | I3: ='DCF Model'!C14 -> 9.3
B5: Table 1: WACC vs Terminal Growth Rate (PGM - Implied Share Price, JPY)
B6: WACC \ Terminal g | C6: =$F$3-0.0075 -> 0.0025 | D6: =$F$3-0.005 -> 0.005 | E6: =$F$3-0.0025 -> 0.0075 | F6: =$F$3 -> 0.01 | G6: =$F$3+0.0025 -> 0.0125 | H6: =$F$3+0.005 -> 0.015 | I6: =$F$3+0.0075 -> 0.0175
B7: =$C$3-0.015 -> 0.094809524 | C7: =IFERROR(ROUND(('DCF Model'!C43/(1+$B7)^1+'DCF Model'!D43/(1+$B7)^2+'DCF Model'!E43/(1+$B7)^3+'DCF Model'!F43/(1+$B7)^4+'DCF Model'!G43/(1+$B7)^5+'DCF Model'!G43*(1+C$6)/($B7-C$6)/(1+$B7)^5-'DCF Model'!C16)*1000000/'DCF Model'!C15,0),"") -> 3040 | D7: =IFERROR(ROUND(('DCF Model'!C43/(1+$B7)^1+'DCF Model'!D43/(1+$B7)^2+'DCF Model'!E43/(1+$B7)^3+'DCF Model'!F43/(1+$B7)^4+'DCF Model'!G43/(1+$B7)^5+'DCF Model'!G43*(1+D$6)/($B7-D$6)/(1+$B7)^5-'DCF Model'!C16)*1000000/'DCF Model'!C15,0),"") -> 3089 | E7: =IFERROR(ROUND(('DCF Model'!C43/(1+$B7)^1+'DCF Model'!D43/(1+$B7)^2+'DCF Model'!E43/(1+$B7)^3+'DCF Model'!F43/(1+$B7)^4+'DCF Model'!G43/(1+$B7)^5+'DCF Model'!G43*(1+E$6)/($B7-E$6)/(1+$B7)^5-'DCF Model'!C16)*1000000/'DCF Model'!C15,0),"") -> 3140 | F7: =IFERROR(ROUND(('DCF Model'!C43/(1+$B7)^1+'DCF Model'!D43/(1+$B7)^2+'DCF Model'!E43/(1+$B7)^3+'DCF Model'!F43/(1+$B7)^4+'DCF Model'!G43/(1+$B7)^5+'DCF Model'!G43*(1+F$6)/($B7-F$6)/(1+$B7)^5-'DCF Model'!C16)*1000000/'DCF Model'!C15,0),"") -> 3194 | G7: =IFERROR(ROUND(('DCF Model'!C43/(1+$B7)^1+'DCF Model'!D43/(1+$B7)^2+'DCF Model'!E43/(1+$B7)^3+'DCF Model'!F43/(1+$B7)^4+'DCF Model'!G43/(1+$B7)^5+'DCF Model'!G43*(1+G$6)/($B7-G$6)/(1+$B7)^5-'DCF Model'!C16)*1000000/'DCF Model'!C15,0),"") -> 3252 | H7: =IFERROR(ROUND(('DCF Model'!C43/(1+$B7)^1+'DCF Model'!D43/(1+$B7)^2+'DCF Model'!E43/(1+$B7)^3+'DCF Model'!F43/(1+$B7)^4+'DCF Model'!G43/(1+$B7)^5+'DCF Model'!G43*(1+H$6)/($B7-H$6)/(1+$B7)^5-'DCF Model'!C16)*1000000/'DCF Model'!C15,0),"") -> 3313 | I7: =IFERROR(ROUND(('DCF Model'!C43/(1+$B7)^1+'DCF Model'!D43/(1+$B7)^2+'DCF Model'!E43/(1+$B7)^3+'DCF Model'!F43/(1+$B7)^4+'DCF Model'!G43/(1+$B7)^5+'DCF Model'!G43*(1+I$6)/($B7-I$6)/(1+$B7)^5-'DCF Model'!C16)*1000000/'DCF Model'!C15,0),"") -> 3379
B8: =$C$3-0.01 -> 0.099809524 | C8: =IFERROR(ROUND(('DCF Model'!C43/(1+$B8)^1+'DCF Model'!D43/(1+$B8)^2+'DCF Model'!E43/(1+$B8)^3+'DCF Model'!F43/(1+$B8)^4+'DCF Model'!G43/(1+$B8)^5+'DCF Model'!G43*(1+C$6)/($B8-C$6)/(1+$B8)^5-'DCF Model'!C16)*1000000/'DCF Model'!C15,0),"") -> 2914 | D8: =IFERROR(ROUND(('DCF Model'!C43/(1+$B8)^1+'DCF Model'!D43/(1+$B8)^2+'DCF Model'!E43/(1+$B8)^3+'DCF Model'!F43/(1+$B8)^4+'DCF Model'!G43/(1+$B8)^5+'DCF Model'!G43*(1+D$6)/($B8-D$6)/(1+$B8)^5-'DCF Model'!C16)*1000000/'DCF Model'!C15,0),"") -> 2957 | E8: =IFERROR(ROUND(('DCF Model'!C43/(1+$B8)^1+'DCF Model'!D43/(1+$B8)^2+'DCF Model'!E43/(1+$B8)^3+'DCF Model'!F43/(1+$B8)^4+'DCF Model'!G43/(1+$B8)^5+'DCF Model'!G43*(1+E$6)/($B8-E$6)/(1+$B8)^5-'DCF Model'!C16)*1000000/'DCF Model'!C15,0),"") -> 3002 | F8: =IFERROR(ROUND(('DCF Model'!C43/(1+$B8)^1+'DCF Model'!D43/(1+$B8)^2+'DCF Model'!E43/(1+$B8)^3+'DCF Model'!F43/(1+$B8)^4+'DCF Model'!G43/(1+$B8)^5+'DCF Model'!G43*(1+F$6)/($B8-F$6)/(1+$B8)^5-'DCF Model'!C16)*1000000/'DCF Model'!C15,0),"") -> 3050 | G8: =IFERROR(ROUND(('DCF Model'!C43/(1+$B8)^1+'DCF Model'!D43/(1+$B8)^2+'DCF Model'!E43/(1+$B8)^3+'DCF Model'!F43/(1+$B8)^4+'DCF Model'!G43/(1+$B8)^5+'DCF Model'!G43*(1+G$6)/($B8-G$6)/(1+$B8)^5-'DCF Model'!C16)*1000000/'DCF Model'!C15,0),"") -> 3100 | H8: =IFERROR(ROUND(('DCF Model'!C43/(1+$B8)^1+'DCF Model'!D43/(1+$B8)^2+'DCF Model'!E43/(1+$B8)^3+'DCF Model'!F43/(1+$B8)^4+'DCF Model'!G43/(1+$B8)^5+'DCF Model'!G43*(1+H$6)/($B8-H$6)/(1+$B8)^5-'DCF Model'!C16)*1000000/'DCF Model'!C15,0),"") -> 3153 | I8: =IFERROR(ROUND(('DCF Model'!C43/(1+$B8)^1+'DCF Model'!D43/(1+$B8)^2+'DCF Model'!E43/(1+$B8)^3+'DCF Model'!F43/(1+$B8)^4+'DCF Model'!G43/(1+$B8)^5+'DCF Model'!G43*(1+I$6)/($B8-I$6)/(1+$B8)^5-'DCF Model'!C16)*1000000/'DCF Model'!C15,0),"") -> 3210
B9: =$C$3-0.005 -> 0.10480952 | C9: =IFERROR(ROUND(('DCF Model'!C43/(1+$B9)^1+'DCF Model'!D43/(1+$B9)^2+'DCF Model'!E43/(1+$B9)^3+'DCF Model'!F43/(1+$B9)^4+'DCF Model'!G43/(1+$B9)^5+'DCF Model'!G43*(1+C$6)/($B9-C$6)/(1+$B9)^5-'DCF Model'!C16)*1000000/'DCF Model'!C15,0),"") -> 2800 | D9: =IFERROR(ROUND(('DCF Model'!C43/(1+$B9)^1+'DCF Model'!D43/(1+$B9)^2+'DCF Model'!E43/(1+$B9)^3+'DCF Model'!F43/(1+$B9)^4+'DCF Model'!G43/(1+$B9)^5+'DCF Model'!G43*(1+D$6)/($B9-D$6)/(1+$B9)^5-'DCF Model'!C16)*1000000/'DCF Model'!C15,0),"") -> 2838 | E9: =IFERROR(ROUND(('DCF Model'!C43/(1+$B9)^1+'DCF Model'!D43/(1+$B9)^2+'DCF Model'!E43/(1+$B9)^3+'DCF Model'!F43/(1+$B9)^4+'DCF Model'!G43/(1+$B9)^5+'DCF Model'!G43*(1+E$6)/($B9-E$6)/(1+$B9)^5-'DCF Model'!C16)*1000000/'DCF Model'!C15,0),"") -> 2878 | F9: =IFERROR(ROUND(('DCF Model'!C43/(1+$B9)^1+'DCF Model'!D43/(1+$B9)^2+'DCF Model'!E43/(1+$B9)^3+'DCF Model'!F43/(1+$B9)^4+'DCF Model'!G43/(1+$B9)^5+'DCF Model'!G43*(1+F$6)/($B9-F$6)/(1+$B9)^5-'DCF Model'!C16)*1000000/'DCF Model'!C15,0),"") -> 2920 | G9: =IFERROR(ROUND(('DCF Model'!C43/(1+$B9)^1+'DCF Model'!D43/(1+$B9)^2+'DCF Model'!E43/(1+$B9)^3+'DCF Model'!F43/(1+$B9)^4+'DCF Model'!G43/(1+$B9)^5+'DCF Model'!G43*(1+G$6)/($B9-G$6)/(1+$B9)^5-'DCF Model'!C16)*1000000/'DCF Model'!C15,0),"") -> 2965 | H9: =IFERROR(ROUND(('DCF Model'!C43/(1+$B9)^1+'DCF Model'!D43/(1+$B9)^2+'DCF Model'!E43/(1+$B9)^3+'DCF Model'!F43/(1+$B9)^4+'DCF Model'!G43/(1+$B9)^5+'DCF Model'!G43*(1+H$6)/($B9-H$6)/(1+$B9)^5-'DCF Model'!C16)*1000000/'DCF Model'!C15,0),"") -> 3011 | I9: =IFERROR(ROUND(('DCF Model'!C43/(1+$B9)^1+'DCF Model'!D43/(1+$B9)^2+'DCF Model'!E43/(1+$B9)^3+'DCF Model'!F43/(1+$B9)^4+'DCF Model'!G43/(1+$B9)^5+'DCF Model'!G43*(1+I$6)/($B9-I$6)/(1+$B9)^5-'DCF Model'!C16)*1000000/'DCF Model'!C15,0),"") -> 3061
B10: =$C$3 -> 0.10980952 | C10: =IFERROR(ROUND(('DCF Model'!C43/(1+$B10)^1+'DCF Model'!D43/(1+$B10)^2+'DCF Model'!E43/(1+$B10)^3+'DCF Model'!F43/(1+$B10)^4+'DCF Model'!G43/(1+$B10)^5+'DCF Model'!G43*(1+C$6)/($B10-C$6)/(1+$B10)^5-'DCF Model'!C16)*1000000/'DCF Model'!C15,0),"") -> 2697 | D10: =IFERROR(ROUND(('DCF Model'!C43/(1+$B10)^1+'DCF Model'!D43/(1+$B10)^2+'DCF Model'!E43/(1+$B10)^3+'DCF Model'!F43/(1+$B10)^4+'DCF Model'!G43/(1+$B10)^5+'DCF Model'!G43*(1+D$6)/($B10-D$6)/(1+$B10)^5-'DCF Model'!C16)*1000000/'DCF Model'!C15,0),"") -> 2731 | E10: =IFERROR(ROUND(('DCF Model'!C43/(1+$B10)^1+'DCF Model'!D43/(1+$B10)^2+'DCF Model'!E43/(1+$B10)^3+'DCF Model'!F43/(1+$B10)^4+'DCF Model'!G43/(1+$B10)^5+'DCF Model'!G43*(1+E$6)/($B10-E$6)/(1+$B10)^5-'DCF Model'!C16)*1000000/'DCF Model'!C15,0),"") -> 2767 | F10: =IFERROR(ROUND(('DCF Model'!C43/(1+$B10)^1+'DCF Model'!D43/(1+$B10)^2+'DCF Model'!E43/(1+$B10)^3+'DCF Model'!F43/(1+$B10)^4+'DCF Model'!G43/(1+$B10)^5+'DCF Model'!G43*(1+F$6)/($B10-F$6)/(1+$B10)^5-'DCF Model'!C16)*1000000/'DCF Model'!C15,0),"") -> 2804 | G10: =IFERROR(ROUND(('DCF Model'!C43/(1+$B10)^1+'DCF Model'!D43/(1+$B10)^2+'DCF Model'!E43/(1+$B10)^3+'DCF Model'!F43/(1+$B10)^4+'DCF Model'!G43/(1+$B10)^5+'DCF Model'!G43*(1+G$6)/($B10-G$6)/(1+$B10)^5-'DCF Model'!C16)*1000000/'DCF Model'!C15,0),"") -> 2843 | H10: =IFERROR(ROUND(('DCF Model'!C43/(1+$B10)^1+'DCF Model'!D43/(1+$B10)^2+'DCF Model'!E43/(1+$B10)^3+'DCF Model'!F43/(1+$B10)^4+'DCF Model'!G43/(1+$B10)^5+'DCF Model'!G43*(1+H$6)/($B10-H$6)/(1+$B10)^5-'DCF Model'!C16)*1000000/'DCF Model'!C15,0),"") -> 2884 | I10: =IFERROR(ROUND(('DCF Model'!C43/(1+$B10)^1+'DCF Model'!D43/(1+$B10)^2+'DCF Model'!E43/(1+$B10)^3+'DCF Model'!F43/(1+$B10)^4+'DCF Model'!G43/(1+$B10)^5+'DCF Model'!G43*(1+I$6)/($B10-I$6)/(1+$B10)^5-'DCF Model'!C16)*1000000/'DCF Model'!C15,0),"") -> 2928
B11: =$C$3+0.005 -> 0.11480952 | C11: =IFERROR(ROUND(('DCF Model'!C43/(1+$B11)^1+'DCF Model'!D43/(1+$B11)^2+'DCF Model'!E43/(1+$B11)^3+'DCF Model'!F43/(1+$B11)^4+'DCF Model'!G43/(1+$B11)^5+'DCF Model'!G43*(1+C$6)/($B11-C$6)/(1+$B11)^5-'DCF Model'!C16)*1000000/'DCF Model'!C15,0),"") -> 2603 | D11: =IFERROR(ROUND(('DCF Model'!C43/(1+$B11)^1+'DCF Model'!D43/(1+$B11)^2+'DCF Model'!E43/(1+$B11)^3+'DCF Model'!F43/(1+$B11)^4+'DCF Model'!G43/(1+$B11)^5+'DCF Model'!G43*(1+D$6)/($B11-D$6)/(1+$B11)^5-'DCF Model'!C16)*1000000/'DCF Model'!C15,0),"") -> 2634 | E11: =IFERROR(ROUND(('DCF Model'!C43/(1+$B11)^1+'DCF Model'!D43/(1+$B11)^2+'DCF Model'!E43/(1+$B11)^3+'DCF Model'!F43/(1+$B11)^4+'DCF Model'!G43/(1+$B11)^5+'DCF Model'!G43*(1+E$6)/($B11-E$6)/(1+$B11)^5-'DCF Model'!C16)*1000000/'DCF Model'!C15,0),"") -> 2665 | F11: =IFERROR(ROUND(('DCF Model'!C43/(1+$B11)^1+'DCF Model'!D43/(1+$B11)^2+'DCF Model'!E43/(1+$B11)^3+'DCF Model'!F43/(1+$B11)^4+'DCF Model'!G43/(1+$B11)^5+'DCF Model'!G43*(1+F$6)/($B11-F$6)/(1+$B11)^5-'DCF Model'!C16)*1000000/'DCF Model'!C15,0),"") -> 2699 | G11: =IFERROR(ROUND(('DCF Model'!C43/(1+$B11)^1+'DCF Model'!D43/(1+$B11)^2+'DCF Model'!E43/(1+$B11)^3+'DCF Model'!F43/(1+$B11)^4+'DCF Model'!G43/(1+$B11)^5+'DCF Model'!G43*(1+G$6)/($B11-G$6)/(1+$B11)^5-'DCF Model'!C16)*1000000/'DCF Model'!C15,0),"") -> 2734 | H11: =IFERROR(ROUND(('DCF Model'!C43/(1+$B11)^1+'DCF Model'!D43/(1+$B11)^2+'DCF Model'!E43/(1+$B11)^3+'DCF Model'!F43/(1+$B11)^4+'DCF Model'!G43/(1+$B11)^5+'DCF Model'!G43*(1+H$6)/($B11-H$6)/(1+$B11)^5-'DCF Model'!C16)*1000000/'DCF Model'!C15,0),"") -> 2770 | I11: =IFERROR(ROUND(('DCF Model'!C43/(1+$B11)^1+'DCF Model'!D43/(1+$B11)^2+'DCF Model'!E43/(1+$B11)^3+'DCF Model'!F43/(1+$B11)^4+'DCF Model'!G43/(1+$B11)^5+'DCF Model'!G43*(1+I$6)/($B11-I$6)/(1+$B11)^5-'DCF Model'!C16)*1000000/'DCF Model'!C15,0),"") -> 2809
B12: =$C$3+0.01 -> 0.11980952 | C12: =IFERROR(ROUND(('DCF Model'!C43/(1+$B12)^1+'DCF Model'!D43/(1+$B12)^2+'DCF Model'!E43/(1+$B12)^3+'DCF Model'!F43/(1+$B12)^4+'DCF Model'!G43/(1+$B12)^5+'DCF Model'!G43*(1+C$6)/($B12-C$6)/(1+$B12)^5-'DCF Model'!C16)*1000000/'DCF Model'!C15,0),"") -> 2518 | D12: =IFERROR(ROUND(('DCF Model'!C43/(1+$B12)^1+'DCF Model'!D43/(1+$B12)^2+'DCF Model'!E43/(1+$B12)^3+'DCF Model'!F43/(1+$B12)^4+'DCF Model'!G43/(1+$B12)^5+'DCF Model'!G43*(1+D$6)/($B12-D$6)/(1+$B12)^5-'DCF Model'!C16)*1000000/'DCF Model'!C15,0),"") -> 2545 | E12: =IFERROR(ROUND(('DCF Model'!C43/(1+$B12)^1+'DCF Model'!D43/(1+$B12)^2+'DCF Model'!E43/(1+$B12)^3+'DCF Model'!F43/(1+$B12)^4+'DCF Model'!G43/(1+$B12)^5+'DCF Model'!G43*(1+E$6)/($B12-E$6)/(1+$B12)^5-'DCF Model'!C16)*1000000/'DCF Model'!C15,0),"") -> 2573 | F12: =IFERROR(ROUND(('DCF Model'!C43/(1+$B12)^1+'DCF Model'!D43/(1+$B12)^2+'DCF Model'!E43/(1+$B12)^3+'DCF Model'!F43/(1+$B12)^4+'DCF Model'!G43/(1+$B12)^5+'DCF Model'!G43*(1+F$6)/($B12-F$6)/(1+$B12)^5-'DCF Model'!C16)*1000000/'DCF Model'!C15,0),"") -> 2603 | G12: =IFERROR(ROUND(('DCF Model'!C43/(1+$B12)^1+'DCF Model'!D43/(1+$B12)^2+'DCF Model'!E43/(1+$B12)^3+'DCF Model'!F43/(1+$B12)^4+'DCF Model'!G43/(1+$B12)^5+'DCF Model'!G43*(1+G$6)/($B12-G$6)/(1+$B12)^5-'DCF Model'!C16)*1000000/'DCF Model'!C15,0),"") -> 2634 | H12: =IFERROR(ROUND(('DCF Model'!C43/(1+$B12)^1+'DCF Model'!D43/(1+$B12)^2+'DCF Model'!E43/(1+$B12)^3+'DCF Model'!F43/(1+$B12)^4+'DCF Model'!G43/(1+$B12)^5+'DCF Model'!G43*(1+H$6)/($B12-H$6)/(1+$B12)^5-'DCF Model'!C16)*1000000/'DCF Model'!C15,0),"") -> 2667 | I12: =IFERROR(ROUND(('DCF Model'!C43/(1+$B12)^1+'DCF Model'!D43/(1+$B12)^2+'DCF Model'!E43/(1+$B12)^3+'DCF Model'!F43/(1+$B12)^4+'DCF Model'!G43/(1+$B12)^5+'DCF Model'!G43*(1+I$6)/($B12-I$6)/(1+$B12)^5-'DCF Model'!C16)*1000000/'DCF Model'!C15,0),"") -> 2701
B13: =$C$3+0.015 -> 0.12480952 | C13: =IFERROR(ROUND(('DCF Model'!C43/(1+$B13)^1+'DCF Model'!D43/(1+$B13)^2+'DCF Model'!E43/(1+$B13)^3+'DCF Model'!F43/(1+$B13)^4+'DCF Model'!G43/(1+$B13)^5+'DCF Model'!G43*(1+C$6)/($B13-C$6)/(1+$B13)^5-'DCF Model'!C16)*1000000/'DCF Model'!C15,0),"") -> 2439 | D13: =IFERROR(ROUND(('DCF Model'!C43/(1+$B13)^1+'DCF Model'!D43/(1+$B13)^2+'DCF Model'!E43/(1+$B13)^3+'DCF Model'!F43/(1+$B13)^4+'DCF Model'!G43/(1+$B13)^5+'DCF Model'!G43*(1+D$6)/($B13-D$6)/(1+$B13)^5-'DCF Model'!C16)*1000000/'DCF Model'!C15,0),"") -> 2464 | E13: =IFERROR(ROUND(('DCF Model'!C43/(1+$B13)^1+'DCF Model'!D43/(1+$B13)^2+'DCF Model'!E43/(1+$B13)^3+'DCF Model'!F43/(1+$B13)^4+'DCF Model'!G43/(1+$B13)^5+'DCF Model'!G43*(1+E$6)/($B13-E$6)/(1+$B13)^5-'DCF Model'!C16)*1000000/'DCF Model'!C15,0),"") -> 2489 | F13: =IFERROR(ROUND(('DCF Model'!C43/(1+$B13)^1+'DCF Model'!D43/(1+$B13)^2+'DCF Model'!E43/(1+$B13)^3+'DCF Model'!F43/(1+$B13)^4+'DCF Model'!G43/(1+$B13)^5+'DCF Model'!G43*(1+F$6)/($B13-F$6)/(1+$B13)^5-'DCF Model'!C16)*1000000/'DCF Model'!C15,0),"") -> 2516 | G13: =IFERROR(ROUND(('DCF Model'!C43/(1+$B13)^1+'DCF Model'!D43/(1+$B13)^2+'DCF Model'!E43/(1+$B13)^3+'DCF Model'!F43/(1+$B13)^4+'DCF Model'!G43/(1+$B13)^5+'DCF Model'!G43*(1+G$6)/($B13-G$6)/(1+$B13)^5-'DCF Model'!C16)*1000000/'DCF Model'!C15,0),"") -> 2544 | H13: =IFERROR(ROUND(('DCF Model'!C43/(1+$B13)^1+'DCF Model'!D43/(1+$B13)^2+'DCF Model'!E43/(1+$B13)^3+'DCF Model'!F43/(1+$B13)^4+'DCF Model'!G43/(1+$B13)^5+'DCF Model'!G43*(1+H$6)/($B13-H$6)/(1+$B13)^5-'DCF Model'!C16)*1000000/'DCF Model'!C15,0),"") -> 2573 | I13: =IFERROR(ROUND(('DCF Model'!C43/(1+$B13)^1+'DCF Model'!D43/(1+$B13)^2+'DCF Model'!E43/(1+$B13)^3+'DCF Model'!F43/(1+$B13)^4+'DCF Model'!G43/(1+$B13)^5+'DCF Model'!G43*(1+I$6)/($B13-I$6)/(1+$B13)^5-'DCF Model'!C16)*1000000/'DCF Model'!C15,0),"") -> 2604
B16: Table 2: WACC vs Exit Multiple (Exit Multiple - Implied Share Price, JPY)
B17: WACC \ Exit Multiple | C17: =$I$3-3 -> 6.3 | D17: =$I$3-2 -> 7.3 | E17: =$I$3-1 -> 8.3 | F17: =$I$3 -> 9.3 | G17: =$I$3+1 -> 10.3 | H17: =$I$3+2 -> 11.3 | I17: =$I$3+3 -> 12.3
B18: =$C$3-0.015 -> 0.094809524 | C18: =IFERROR(ROUND(('DCF Model'!C43/(1+$B18)^1+'DCF Model'!D43/(1+$B18)^2+'DCF Model'!E43/(1+$B18)^3+'DCF Model'!F43/(1+$B18)^4+'DCF Model'!G43/(1+$B18)^5+('DCF Model'!G37+'DCF Model'!G40)*C$17/(1+$B18)^5-'DCF Model'!C16)*1000000/'DCF Model'!C15,0),"") -> 2990 | D18: =IFERROR(ROUND(('DCF Model'!C43/(1+$B18)^1+'DCF Model'!D43/(1+$B18)^2+'DCF Model'!E43/(1+$B18)^3+'DCF Model'!F43/(1+$B18)^4+'DCF Model'!G43/(1+$B18)^5+('DCF Model'!G37+'DCF Model'!G40)*D$17/(1+$B18)^5-'DCF Model'!C16)*1000000/'DCF Model'!C15,0),"") -> 3235 | E18: =IFERROR(ROUND(('DCF Model'!C43/(1+$B18)^1+'DCF Model'!D43/(1+$B18)^2+'DCF Model'!E43/(1+$B18)^3+'DCF Model'!F43/(1+$B18)^4+'DCF Model'!G43/(1+$B18)^5+('DCF Model'!G37+'DCF Model'!G40)*E$17/(1+$B18)^5-'DCF Model'!C16)*1000000/'DCF Model'!C15,0),"") -> 3480 | F18: =IFERROR(ROUND(('DCF Model'!C43/(1+$B18)^1+'DCF Model'!D43/(1+$B18)^2+'DCF Model'!E43/(1+$B18)^3+'DCF Model'!F43/(1+$B18)^4+'DCF Model'!G43/(1+$B18)^5+('DCF Model'!G37+'DCF Model'!G40)*F$17/(1+$B18)^5-'DCF Model'!C16)*1000000/'DCF Model'!C15,0),"") -> 3726 | G18: =IFERROR(ROUND(('DCF Model'!C43/(1+$B18)^1+'DCF Model'!D43/(1+$B18)^2+'DCF Model'!E43/(1+$B18)^3+'DCF Model'!F43/(1+$B18)^4+'DCF Model'!G43/(1+$B18)^5+('DCF Model'!G37+'DCF Model'!G40)*G$17/(1+$B18)^5-'DCF Model'!C16)*1000000/'DCF Model'!C15,0),"") -> 3971 | H18: =IFERROR(ROUND(('DCF Model'!C43/(1+$B18)^1+'DCF Model'!D43/(1+$B18)^2+'DCF Model'!E43/(1+$B18)^3+'DCF Model'!F43/(1+$B18)^4+'DCF Model'!G43/(1+$B18)^5+('DCF Model'!G37+'DCF Model'!G40)*H$17/(1+$B18)^5-'DCF Model'!C16)*1000000/'DCF Model'!C15,0),"") -> 4216 | I18: =IFERROR(ROUND(('DCF Model'!C43/(1+$B18)^1+'DCF Model'!D43/(1+$B18)^2+'DCF Model'!E43/(1+$B18)^3+'DCF Model'!F43/(1+$B18)^4+'DCF Model'!G43/(1+$B18)^5+('DCF Model'!G37+'DCF Model'!G40)*I$17/(1+$B18)^5-'DCF Model'!C16)*1000000/'DCF Model'!C15,0),"") -> 4461
B19: =$C$3-0.01 -> 0.099809524 | C19: =IFERROR(ROUND(('DCF Model'!C43/(1+$B19)^1+'DCF Model'!D43/(1+$B19)^2+'DCF Model'!E43/(1+$B19)^3+'DCF Model'!F43/(1+$B19)^4+'DCF Model'!G43/(1+$B19)^5+('DCF Model'!G37+'DCF Model'!G40)*C$17/(1+$B19)^5-'DCF Model'!C16)*1000000/'DCF Model'!C15,0),"") -> 2945 | D19: =IFERROR(ROUND(('DCF Model'!C43/(1+$B19)^1+'DCF Model'!D43/(1+$B19)^2+'DCF Model'!E43/(1+$B19)^3+'DCF Model'!F43/(1+$B19)^4+'DCF Model'!G43/(1+$B19)^5+('DCF Model'!G37+'DCF Model'!G40)*D$17/(1+$B19)^5-'DCF Model'!C16)*1000000/'DCF Model'!C15,0),"") -> 3184 | E19: =IFERROR(ROUND(('DCF Model'!C43/(1+$B19)^1+'DCF Model'!D43/(1+$B19)^2+'DCF Model'!E43/(1+$B19)^3+'DCF Model'!F43/(1+$B19)^4+'DCF Model'!G43/(1+$B19)^5+('DCF Model'!G37+'DCF Model'!G40)*E$17/(1+$B19)^5-'DCF Model'!C16)*1000000/'DCF Model'!C15,0),"") -> 3424 | F19: =IFERROR(ROUND(('DCF Model'!C43/(1+$B19)^1+'DCF Model'!D43/(1+$B19)^2+'DCF Model'!E43/(1+$B19)^3+'DCF Model'!F43/(1+$B19)^4+'DCF Model'!G43/(1+$B19)^5+('DCF Model'!G37+'DCF Model'!G40)*F$17/(1+$B19)^5-'DCF Model'!C16)*1000000/'DCF Model'!C15,0),"") -> 3664 | G19: =IFERROR(ROUND(('DCF Model'!C43/(1+$B19)^1+'DCF Model'!D43/(1+$B19)^2+'DCF Model'!E43/(1+$B19)^3+'DCF Model'!F43/(1+$B19)^4+'DCF Model'!G43/(1+$B19)^5+('DCF Model'!G37+'DCF Model'!G40)*G$17/(1+$B19)^5-'DCF Model'!C16)*1000000/'DCF Model'!C15,0),"") -> 3904 | H19: =IFERROR(ROUND(('DCF Model'!C43/(1+$B19)^1+'DCF Model'!D43/(1+$B19)^2+'DCF Model'!E43/(1+$B19)^3+'DCF Model'!F43/(1+$B19)^4+'DCF Model'!G43/(1+$B19)^5+('DCF Model'!G37+'DCF Model'!G40)*H$17/(1+$B19)^5-'DCF Model'!C16)*1000000/'DCF Model'!C15,0),"") -> 4144 | I19: =IFERROR(ROUND(('DCF Model'!C43/(1+$B19)^1+'DCF Model'!D43/(1+$B19)^2+'DCF Model'!E43/(1+$B19)^3+'DCF Model'!F43/(1+$B19)^4+'DCF Model'!G43/(1+$B19)^5+('DCF Model'!G37+'DCF Model'!G40)*I$17/(1+$B19)^5-'DCF Model'!C16)*1000000/'DCF Model'!C15,0),"") -> 4383
B20: =$C$3-0.005 -> 0.10480952 | C20: =IFERROR(ROUND(('DCF Model'!C43/(1+$B20)^1+'DCF Model'!D43/(1+$B20)^2+'DCF Model'!E43/(1+$B20)^3+'DCF Model'!F43/(1+$B20)^4+'DCF Model'!G43/(1+$B20)^5+('DCF Model'!G37+'DCF Model'!G40)*C$17/(1+$B20)^5-'DCF Model'!C16)*1000000/'DCF Model'!C15,0),"") -> 2901 | D20: =IFERROR(ROUND(('DCF Model'!C43/(1+$B20)^1+'DCF Model'!D43/(1+$B20)^2+'DCF Model'!E43/(1+$B20)^3+'DCF Model'!F43/(1+$B20)^4+'DCF Model'!G43/(1+$B20)^5+('DCF Model'!G37+'DCF Model'!G40)*D$17/(1+$B20)^5-'DCF Model'!C16)*1000000/'DCF Model'!C15,0),"") -> 3135 | E20: =IFERROR(ROUND(('DCF Model'!C43/(1+$B20)^1+'DCF Model'!D43/(1+$B20)^2+'DCF Model'!E43/(1+$B20)^3+'DCF Model'!F43/(1+$B20)^4+'DCF Model'!G43/(1+$B20)^5+('DCF Model'!G37+'DCF Model'!G40)*E$17/(1+$B20)^5-'DCF Model'!C16)*1000000/'DCF Model'!C15,0),"") -> 3370 | F20: =IFERROR(ROUND(('DCF Model'!C43/(1+$B20)^1+'DCF Model'!D43/(1+$B20)^2+'DCF Model'!E43/(1+$B20)^3+'DCF Model'!F43/(1+$B20)^4+'DCF Model'!G43/(1+$B20)^5+('DCF Model'!G37+'DCF Model'!G40)*F$17/(1+$B20)^5-'DCF Model'!C16)*1000000/'DCF Model'!C15,0),"") -> 3604 | G20: =IFERROR(ROUND(('DCF Model'!C43/(1+$B20)^1+'DCF Model'!D43/(1+$B20)^2+'DCF Model'!E43/(1+$B20)^3+'DCF Model'!F43/(1+$B20)^4+'DCF Model'!G43/(1+$B20)^5+('DCF Model'!G37+'DCF Model'!G40)*G$17/(1+$B20)^5-'DCF Model'!C16)*1000000/'DCF Model'!C15,0),"") -> 3838 | H20: =IFERROR(ROUND(('DCF Model'!C43/(1+$B20)^1+'DCF Model'!D43/(1+$B20)^2+'DCF Model'!E43/(1+$B20)^3+'DCF Model'!F43/(1+$B20)^4+'DCF Model'!G43/(1+$B20)^5+('DCF Model'!G37+'DCF Model'!G40)*H$17/(1+$B20)^5-'DCF Model'!C16)*1000000/'DCF Model'!C15,0),"") -> 4073 | I20: =IFERROR(ROUND(('DCF Model'!C43/(1+$B20)^1+'DCF Model'!D43/(1+$B20)^2+'DCF Model'!E43/(1+$B20)^3+'DCF Model'!F43/(1+$B20)^4+'DCF Model'!G43/(1+$B20)^5+('DCF Model'!G37+'DCF Model'!G40)*I$17/(1+$B20)^5-'DCF Model'!C16)*1000000/'DCF Model'!C15,0),"") -> 4307
B21: =$C$3 -> 0.10980952 | C21: =IFERROR(ROUND(('DCF Model'!C43/(1+$B21)^1+'DCF Model'!D43/(1+$B21)^2+'DCF Model'!E43/(1+$B21)^3+'DCF Model'!F43/(1+$B21)^4+'DCF Model'!G43/(1+$B21)^5+('DCF Model'!G37+'DCF Model'!G40)*C$17/(1+$B21)^5-'DCF Model'!C16)*1000000/'DCF Model'!C15,0),"") -> 2858 | D21: =IFERROR(ROUND(('DCF Model'!C43/(1+$B21)^1+'DCF Model'!D43/(1+$B21)^2+'DCF Model'!E43/(1+$B21)^3+'DCF Model'!F43/(1+$B21)^4+'DCF Model'!G43/(1+$B21)^5+('DCF Model'!G37+'DCF Model'!G40)*D$17/(1+$B21)^5-'DCF Model'!C16)*1000000/'DCF Model'!C15,0),"") -> 3087 | E21: =IFERROR(ROUND(('DCF Model'!C43/(1+$B21)^1+'DCF Model'!D43/(1+$B21)^2+'DCF Model'!E43/(1+$B21)^3+'DCF Model'!F43/(1+$B21)^4+'DCF Model'!G43/(1+$B21)^5+('DCF Model'!G37+'DCF Model'!G40)*E$17/(1+$B21)^5-'DCF Model'!C16)*1000000/'DCF Model'!C15,0),"") -> 3317 | F21: =IFERROR(ROUND(('DCF Model'!C43/(1+$B21)^1+'DCF Model'!D43/(1+$B21)^2+'DCF Model'!E43/(1+$B21)^3+'DCF Model'!F43/(1+$B21)^4+'DCF Model'!G43/(1+$B21)^5+('DCF Model'!G37+'DCF Model'!G40)*F$17/(1+$B21)^5-'DCF Model'!C16)*1000000/'DCF Model'!C15,0),"") -> 3546 | G21: =IFERROR(ROUND(('DCF Model'!C43/(1+$B21)^1+'DCF Model'!D43/(1+$B21)^2+'DCF Model'!E43/(1+$B21)^3+'DCF Model'!F43/(1+$B21)^4+'DCF Model'!G43/(1+$B21)^5+('DCF Model'!G37+'DCF Model'!G40)*G$17/(1+$B21)^5-'DCF Model'!C16)*1000000/'DCF Model'!C15,0),"") -> 3775 | H21: =IFERROR(ROUND(('DCF Model'!C43/(1+$B21)^1+'DCF Model'!D43/(1+$B21)^2+'DCF Model'!E43/(1+$B21)^3+'DCF Model'!F43/(1+$B21)^4+'DCF Model'!G43/(1+$B21)^5+('DCF Model'!G37+'DCF Model'!G40)*H$17/(1+$B21)^5-'DCF Model'!C16)*1000000/'DCF Model'!C15,0),"") -> 4004 | I21: =IFERROR(ROUND(('DCF Model'!C43/(1+$B21)^1+'DCF Model'!D43/(1+$B21)^2+'DCF Model'!E43/(1+$B21)^3+'DCF Model'!F43/(1+$B21)^4+'DCF Model'!G43/(1+$B21)^5+('DCF Model'!G37+'DCF Model'!G40)*I$17/(1+$B21)^5-'DCF Model'!C16)*1000000/'DCF Model'!C15,0),"") -> 4233
B22: =$C$3+0.005 -> 0.11480952 | C22: =IFERROR(ROUND(('DCF Model'!C43/(1+$B22)^1+'DCF Model'!D43/(1+$B22)^2+'DCF Model'!E43/(1+$B22)^3+'DCF Model'!F43/(1+$B22)^4+'DCF Model'!G43/(1+$B22)^5+('DCF Model'!G37+'DCF Model'!G40)*C$17/(1+$B22)^5-'DCF Model'!C16)*1000000/'DCF Model'!C15,0),"") -> 2817 | D22: =IFERROR(ROUND(('DCF Model'!C43/(1+$B22)^1+'DCF Model'!D43/(1+$B22)^2+'DCF Model'!E43/(1+$B22)^3+'DCF Model'!F43/(1+$B22)^4+'DCF Model'!G43/(1+$B22)^5+('DCF Model'!G37+'DCF Model'!G40)*D$17/(1+$B22)^5-'DCF Model'!C16)*1000000/'DCF Model'!C15,0),"") -> 3041 | E22: =IFERROR(ROUND(('DCF Model'!C43/(1+$B22)^1+'DCF Model'!D43/(1+$B22)^2+'DCF Model'!E43/(1+$B22)^3+'DCF Model'!F43/(1+$B22)^4+'DCF Model'!G43/(1+$B22)^5+('DCF Model'!G37+'DCF Model'!G40)*E$17/(1+$B22)^5-'DCF Model'!C16)*1000000/'DCF Model'!C15,0),"") -> 3265 | F22: =IFERROR(ROUND(('DCF Model'!C43/(1+$B22)^1+'DCF Model'!D43/(1+$B22)^2+'DCF Model'!E43/(1+$B22)^3+'DCF Model'!F43/(1+$B22)^4+'DCF Model'!G43/(1+$B22)^5+('DCF Model'!G37+'DCF Model'!G40)*F$17/(1+$B22)^5-'DCF Model'!C16)*1000000/'DCF Model'!C15,0),"") -> 3489 | G22: =IFERROR(ROUND(('DCF Model'!C43/(1+$B22)^1+'DCF Model'!D43/(1+$B22)^2+'DCF Model'!E43/(1+$B22)^3+'DCF Model'!F43/(1+$B22)^4+'DCF Model'!G43/(1+$B22)^5+('DCF Model'!G37+'DCF Model'!G40)*G$17/(1+$B22)^5-'DCF Model'!C16)*1000000/'DCF Model'!C15,0),"") -> 3713 | H22: =IFERROR(ROUND(('DCF Model'!C43/(1+$B22)^1+'DCF Model'!D43/(1+$B22)^2+'DCF Model'!E43/(1+$B22)^3+'DCF Model'!F43/(1+$B22)^4+'DCF Model'!G43/(1+$B22)^5+('DCF Model'!G37+'DCF Model'!G40)*H$17/(1+$B22)^5-'DCF Model'!C16)*1000000/'DCF Model'!C15,0),"") -> 3937 | I22: =IFERROR(ROUND(('DCF Model'!C43/(1+$B22)^1+'DCF Model'!D43/(1+$B22)^2+'DCF Model'!E43/(1+$B22)^3+'DCF Model'!F43/(1+$B22)^4+'DCF Model'!G43/(1+$B22)^5+('DCF Model'!G37+'DCF Model'!G40)*I$17/(1+$B22)^5-'DCF Model'!C16)*1000000/'DCF Model'!C15,0),"") -> 4161
B23: =$C$3+0.01 -> 0.11980952 | C23: =IFERROR(ROUND(('DCF Model'!C43/(1+$B23)^1+'DCF Model'!D43/(1+$B23)^2+'DCF Model'!E43/(1+$B23)^3+'DCF Model'!F43/(1+$B23)^4+'DCF Model'!G43/(1+$B23)^5+('DCF Model'!G37+'DCF Model'!G40)*C$17/(1+$B23)^5-'DCF Model'!C16)*1000000/'DCF Model'!C15,0),"") -> 2776 | D23: =IFERROR(ROUND(('DCF Model'!C43/(1+$B23)^1+'DCF Model'!D43/(1+$B23)^2+'DCF Model'!E43/(1+$B23)^3+'DCF Model'!F43/(1+$B23)^4+'DCF Model'!G43/(1+$B23)^5+('DCF Model'!G37+'DCF Model'!G40)*D$17/(1+$B23)^5-'DCF Model'!C16)*1000000/'DCF Model'!C15,0),"") -> 2995 | E23: =IFERROR(ROUND(('DCF Model'!C43/(1+$B23)^1+'DCF Model'!D43/(1+$B23)^2+'DCF Model'!E43/(1+$B23)^3+'DCF Model'!F43/(1+$B23)^4+'DCF Model'!G43/(1+$B23)^5+('DCF Model'!G37+'DCF Model'!G40)*E$17/(1+$B23)^5-'DCF Model'!C16)*1000000/'DCF Model'!C15,0),"") -> 3214 | F23: =IFERROR(ROUND(('DCF Model'!C43/(1+$B23)^1+'DCF Model'!D43/(1+$B23)^2+'DCF Model'!E43/(1+$B23)^3+'DCF Model'!F43/(1+$B23)^4+'DCF Model'!G43/(1+$B23)^5+('DCF Model'!G37+'DCF Model'!G40)*F$17/(1+$B23)^5-'DCF Model'!C16)*1000000/'DCF Model'!C15,0),"") -> 3433 | G23: =IFERROR(ROUND(('DCF Model'!C43/(1+$B23)^1+'DCF Model'!D43/(1+$B23)^2+'DCF Model'!E43/(1+$B23)^3+'DCF Model'!F43/(1+$B23)^4+'DCF Model'!G43/(1+$B23)^5+('DCF Model'!G37+'DCF Model'!G40)*G$17/(1+$B23)^5-'DCF Model'!C16)*1000000/'DCF Model'!C15,0),"") -> 3653 | H23: =IFERROR(ROUND(('DCF Model'!C43/(1+$B23)^1+'DCF Model'!D43/(1+$B23)^2+'DCF Model'!E43/(1+$B23)^3+'DCF Model'!F43/(1+$B23)^4+'DCF Model'!G43/(1+$B23)^5+('DCF Model'!G37+'DCF Model'!G40)*H$17/(1+$B23)^5-'DCF Model'!C16)*1000000/'DCF Model'!C15,0),"") -> 3872 | I23: =IFERROR(ROUND(('DCF Model'!C43/(1+$B23)^1+'DCF Model'!D43/(1+$B23)^2+'DCF Model'!E43/(1+$B23)^3+'DCF Model'!F43/(1+$B23)^4+'DCF Model'!G43/(1+$B23)^5+('DCF Model'!G37+'DCF Model'!G40)*I$17/(1+$B23)^5-'DCF Model'!C16)*1000000/'DCF Model'!C15,0),"") -> 4091
B24: =$C$3+0.015 -> 0.12480952 | C24: =IFERROR(ROUND(('DCF Model'!C43/(1+$B24)^1+'DCF Model'!D43/(1+$B24)^2+'DCF Model'!E43/(1+$B24)^3+'DCF Model'!F43/(1+$B24)^4+'DCF Model'!G43/(1+$B24)^5+('DCF Model'!G37+'DCF Model'!G40)*C$17/(1+$B24)^5-'DCF Model'!C16)*1000000/'DCF Model'!C15,0),"") -> 2737 | D24: =IFERROR(ROUND(('DCF Model'!C43/(1+$B24)^1+'DCF Model'!D43/(1+$B24)^2+'DCF Model'!E43/(1+$B24)^3+'DCF Model'!F43/(1+$B24)^4+'DCF Model'!G43/(1+$B24)^5+('DCF Model'!G37+'DCF Model'!G40)*D$17/(1+$B24)^5-'DCF Model'!C16)*1000000/'DCF Model'!C15,0),"") -> 2951 | E24: =IFERROR(ROUND(('DCF Model'!C43/(1+$B24)^1+'DCF Model'!D43/(1+$B24)^2+'DCF Model'!E43/(1+$B24)^3+'DCF Model'!F43/(1+$B24)^4+'DCF Model'!G43/(1+$B24)^5+('DCF Model'!G37+'DCF Model'!G40)*E$17/(1+$B24)^5-'DCF Model'!C16)*1000000/'DCF Model'!C15,0),"") -> 3165 | F24: =IFERROR(ROUND(('DCF Model'!C43/(1+$B24)^1+'DCF Model'!D43/(1+$B24)^2+'DCF Model'!E43/(1+$B24)^3+'DCF Model'!F43/(1+$B24)^4+'DCF Model'!G43/(1+$B24)^5+('DCF Model'!G37+'DCF Model'!G40)*F$17/(1+$B24)^5-'DCF Model'!C16)*1000000/'DCF Model'!C15,0),"") -> 3379 | G24: =IFERROR(ROUND(('DCF Model'!C43/(1+$B24)^1+'DCF Model'!D43/(1+$B24)^2+'DCF Model'!E43/(1+$B24)^3+'DCF Model'!F43/(1+$B24)^4+'DCF Model'!G43/(1+$B24)^5+('DCF Model'!G37+'DCF Model'!G40)*G$17/(1+$B24)^5-'DCF Model'!C16)*1000000/'DCF Model'!C15,0),"") -> 3594 | H24: =IFERROR(ROUND(('DCF Model'!C43/(1+$B24)^1+'DCF Model'!D43/(1+$B24)^2+'DCF Model'!E43/(1+$B24)^3+'DCF Model'!F43/(1+$B24)^4+'DCF Model'!G43/(1+$B24)^5+('DCF Model'!G37+'DCF Model'!G40)*H$17/(1+$B24)^5-'DCF Model'!C16)*1000000/'DCF Model'!C15,0),"") -> 3808 | I24: =IFERROR(ROUND(('DCF Model'!C43/(1+$B24)^1+'DCF Model'!D43/(1+$B24)^2+'DCF Model'!E43/(1+$B24)^3+'DCF Model'!F43/(1+$B24)^4+'DCF Model'!G43/(1+$B24)^5+('DCF Model'!G37+'DCF Model'!G40)*I$17/(1+$B24)^5-'DCF Model'!C16)*1000000/'DCF Model'!C15,0),"") -> 4022
B26: All values dynamically linked to DCF Model. Headers auto-center on current WACC / Terminal g / Exit Multiple.
