Workbook

Sheet Executive Summary
B1: DISCLAIMER: This is a sample analysis for demonstration purposes only. It does not constitute investment advice.
B3: 株式会社コア (2359.T)
B4: Equity Research Report
B6: Company | C6: 株式会社コア
B7: Ticker | C7: 2359.T (TSE)
B8: Sector | C8: Information & Communication
B9: Current Price | C9: 2276
B10: Target Price (Mid) | C10: =ROUND(AVERAGE(C16:C19),0)
B11: Recommendation | C11: =IF(C12>0.15,"BUY",IF(C12>0.05,"HOLD","SELL"))
B12: Upside / Downside | C12: =(C10-C9)/C9
B14: Valuation Summary
B15: Methodology | C15: Implied Value (JPY) | D15: vs Current Price
B16: DCF - Perpetuity Growth | C16: ='DCF Model'!C55 | D16: =(C16-C9)/C9
B17: DCF - Exit Multiple | C17: ='DCF Model'!C64 | D17: =(C17-C9)/C9
B18: Comps - EV/EBITDA Median | C18: ='Comps Analysis'!C27 | D18: =(C18-C9)/C9
B19: Comps - PER Median | C19: ='Comps Analysis'!C28 | D19: =(C19-C9)/C9
B21: Integrated Valuation Range | C21: =MIN(C16:C19)&" - "&MAX(C16:C19)
B23: Key Investment Thesis
B24: 1. Defense Tech: GNSS anti-spoofing tech for JASDF; 4-layer moat (proprietary receiver + QZSS auth + security clearance + space tech track record)
B25: 2. AX Transformation: Layer 2 (solution) ratio rising 25.9% → 33.3%, structurally improving OPM
B26: 3. Earnings Surprise: Base case EPS >¥200 vs consensus ~¥174; Q3 OP progress rate 82.5% implies ~¥4,050M OP
B28: Key Risks
B29: 1. Defense contracts still in R&D/validation phase — mass production orders unconfirmed
B30: 2. Key person risk in specialized GNSS/space technology division
B31: 3. Revenue concentration in Japanese domestic IT services market

Sheet Financial Statements
B2: 株式会社コア - Historical Financials (JPY mn)
C4: FY2020 | D4: FY2021 | E4: FY2022 | F4: FY2023 | G4: FY2024 | H4: FY2025
B5: Income Statement
B6: Revenue | C6: 20997.367 | D6: 20785.262 | E6: 21798.077 | F6: 22848.129 | G6: 23998.562 | H6: 24599.166
B7: COGS | C7: 15781.969 | D7: 15524.609 | E7: 16231.035 | F7: 16853.21 | G7: 17407.88 | H7: 17821.475
B8: Gross Profit | C8: =C6-C7 | D8: =D6-D7 | E8: =E6-E7 | F8: =F6-F7 | G8: =G6-G7 | H8: =H6-H7
B9: Gross Margin | C9: =C8/C6 | D9: =D8/D6 | E9: =E8/E6 | F9: =F8/F6 | G9: =G8/G6 | H9: =H8/H6
B10: SGA | C10: 3414.673 | D10: 3228.568 | E10: 3199.384 | F10: 3251.051 | G10: 3450.098 | H10: 3602.229
B11: Operating Income | C11: 1800.724 | D11: 2032.084 | E11: 2367.658 | F11: 2743.867 | G11: 3140.583 | H11: 3175.462
B12: Net Income | C12: 1172.735 | D12: 1423.358 | E12: 1622.716 | F12: 1968.404 | G12: 2270.704 | H12: 2242.34
B13: Operating Margin | C13: =C11/C6 | D13: =D11/D6 | E13: =E11/E6 | F13: =F11/F6 | G13: =G11/G6 | H13: =H11/H6
B14: Net Margin | C14: =C12/C6 | D14: =D12/D6 | E14: =E12/E6 | F14: =F12/F6 | G14: =G12/G6 | H14: =H12/H6
B15: Revenue Growth (YoY) | C15: n/a | D15: =(D6-C6)/C6 | E15: =(E6-D6)/D6 | F15: =(F6-E6)/E6 | G15: =(G6-F6)/F6 | H15: =(H6-G6)/G6
B16: Operating Income Growth (YoY) | C16: n/a | D16: =(D11-C11)/C11 | E16: =(E11-D11)/D11 | F16: =(F11-E11)/E11 | G16: =(G11-F11)/F11 | H16: =(H11-G11)/G11
B18: Cash Flow Statement
B19: Operating Cash Flow | C19: 1325.726 | D19: 1851.105 | E19: 1799.231 | F19: 1943.795 | G19: 2190.094 | H19: 2372.799
B20: Capex | C20: 166.493 | D20: 93.543 | E20: 72.084 | F20: 85.455 | G20: 93.4 | H20: 95.32
B21: Free Cash Flow | C21: =C19-C20 | D21: =D19-D20 | E21: =E19-E20 | F21: =F19-F20 | G21: =G19-G20 | H21: =H19-H20
B22: FCF Margin | C22: =C21/C6 | D22: =D21/D6 | E22: =E21/E6 | F22: =F21/F6 | G22: =G21/G6 | H22: =H21/H6
B23: Capex / Revenue | C23: =C20/C6 | D23: =D20/D6 | E23: =E20/E6 | F23: =F20/F6 | G23: =G20/G6 | H23: =H20/H6
B25: Balance Sheet Highlights
B26: Cash & Deposits | C26: 2658.886 | D26: 3636.219 | E26: 4700.235 | F26: 5586.934 | G26: 6300.075 | H26: 7586.071
B27: Short-term Debt | C27: 2592.9 | D27: 2109.7 | E27: 1963.6 | F27: 1812 | G27: 1734.8 | H27: 1412.4
B28: Net Debt (Cash) | C28: =C27-C26 | D28: =D27-D26 | E28: =E27-E26 | F28: =F27-F26 | G28: =G27-G26 | H28: =H27-H26

Sheet DCF Model
B2: DCF Valuation Model - 株式会社コア
B4: Assumptions
B5: Capex / Revenue | C5: 0.0041668079
B6: Effective Tax Rate | C6: 0.305
B7: Risk-Free Rate | C7: 0.022
B8: Beta | C8: 1
B9: Equity Risk Premium | C9: 0.065
B10: Size Premium | C10: 0.03
B11: After-tax Cost of Debt | C11: 0.005
B12: D/E Ratio | C12: 0
B13: Terminal Growth Rate | C13: 0.015
B14: Exit Multiple (EV/EBITDA) | C14: 10
B15: Fully Diluted Shares | C15: 14368501
B16: Net Debt (JPY mn) | C16: -7296.8
... B20: LTM Revenue (JPY mn) | C20: 24599
B22: WACC Calculation
B23: Cost of Equity (Ke) | C23: =C7+C8*C9+C10
B24: Weight of Equity | C24: =1/(1+C12)
B25: Weight of Debt | C25: =C12/(1+C12)
B26: WACC | C26: =C23*C24+C11*C25
B27: Active Scenario | C27: Base | D27: =MATCH(C27,{"Base","Upside","Management","Downside 1","Downside 2"},0)
B28: Projected Free Cash Flow
C29: FY2026(E) | D29: FY2027(E) | E29: FY2028(E) | F29: FY2029(E) | G29: FY2030(E)
B30: Revenue Growth (YoY) | C30: =(C33/C17)-1 | D30: =(D33/C33)-1 | E30: =(E33/D33)-1 | F30: =(F33/E33)-1 | G30: =(G33/F33)-1
B31: COGS % of Revenue | C31: =CHOOSE($D$27,'Segment Analysis'!F79,'Segment Analysis'!F80,'Segment Analysis'!F81,'Segment Analysis'!F82,'Segment Analysis'!F83) | D31: =CHOOSE($D$27,'Segment Analysis'!G79,'Segment Analysis'!G80,'Segment Analysis'!G81,'Segment Analysis'!G82,'Segment Analysis'!G83) | E31: =CHOOSE($D$27,'Segment Analysis'!H79,'Segment Analysis'!H80,'Segment Analysis'!H81,'Segment Analysis'!H82,'Segment Analysis'!H83) | F31: =CHOOSE($D$27,'Segment Analysis'!I79,'Segment Analysis'!I80,'Segment Analysis'!I81,'Segment Analysis'!I82,'Segment Analysis'!I83) | G31: =CHOOSE($D$27,'Segment Analysis'!J79,'Segment Analysis'!J80,'Segment Analysis'!J81,'Segment Analysis'!J82,'Segment Analysis'!J83)
B32: SGA % of Revenue | C32: =CHOOSE($D$27,'Segment Analysis'!F86,'Segment Analysis'!F87,'Segment Analysis'!F88,'Segment Analysis'!F89,'Segment Analysis'!F90) | D32: =CHOOSE($D$27,'Segment Analysis'!G86,'Segment Analysis'!G87,'Segment Analysis'!G88,'Segment Analysis'!G89,'Segment Analysis'!G90) | E32: =CHOOSE($D$27,'Segment Analysis'!H86,'Segment Analysis'!H87,'Segment Analysis'!H88,'Segment Analysis'!H89,'Segment Analysis'!H90) | F32: =CHOOSE($D$27,'Segment Analysis'!I86,'Segment Analysis'!I87,'Segment Analysis'!I88,'Segment Analysis'!I89,'Segment Analysis'!I90) | G32: =CHOOSE($D$27,'Segment Analysis'!J86,'Segment Analysis'!J87,'Segment Analysis'!J88,'Segment Analysis'!J89,'Segment Analysis'!J90)
B33: Revenue | C33: ='Segment Analysis'!F21 | D33: ='Segment Analysis'!G21 | E33: ='Segment Analysis'!H21 | F33: ='Segment Analysis'!I21 | G33: ='Segment Analysis'!J21
B34: COGS | C34: =C33*C31 | D34: =D33*D31 | E34: =E33*E31 | F34: =F33*F31 | G34: =G33*G31
B35: Gross Profit | C35: =C33-C34 | D35: =D33-D34 | E35: =E33-E34 | F35: =F33-F34 | G35: =G33-G34
B36: Gross Margin | C36: =C35/C33 | D36: =D35/D33 | E36: =E35/E33 | F36: =F35/F33 | G36: =G35/G33
B37: SGA Expense | C37: =C33*C32 | D37: =D33*D32 | E37: =E33*E32 | F37: =F33*F32 | G37: =G33*G32
B38: Implied Operating Margin | C38: =C39/C33 | D38: =D39/D33 | E38: =E39/E33 | F38: =F39/F33 | G38: =G39/G33
B39: Operating Income (EBIT) | C39: =C35-C37 | D39: =D35-D37 | E39: =E35-E37 | F39: =F35-F37 | G39: =G35-G37
B40: Less: Tax | C40: =MAX(0,C39*C6) | D40: =MAX(0,D39*C6) | E40: =MAX(0,E39*C6) | F40: =MAX(0,F39*C6) | G40: =MAX(0,G39*C6)
B41: NOPAT | C41: =C39-C40 | D41: =D39-D40 | E41: =E39-E40 | F41: =F39-F40 | G41: =G39-G40
B42: Plus: D&A | C42: 210 | D42: 210 | E42: 210 | F42: 215 | G42: =G33*C18
B43: Less: Capex | C43: 100 | D43: 100 | E43: 105 | F43: 105 | G43: =G33*C5
B44: Change in NWC | C44: ='NWC Schedule'!D19 | D44: ='NWC Schedule'!E19 | E44: ='NWC Schedule'!F19 | F44: ='NWC Schedule'!G19 | G44: ='NWC Schedule'!H19
B45: Unlevered Free Cash Flow | C45: =C41+C42-C43-C44 | D45: =D41+D42-D43-D44 | E45: =E41+E42-E43-E44 | F45: =F41+F42-F43-F44 | G45: =G41+G42-G43-G44
B46: Discount Factor | C46: =1/(1+C26)^(C19+0) | D46: =1/(1+C26)^(C19+1) | E46: =1/(1+C26)^(C19+2) | F46: =1/(1+C26)^(C19+3) | G46: =1/(1+C26)^(C19+4)
...

Sheet NWC Schedule
B2: NWC Schedule - 株式会社コア
B4: Working Capital Drivers (Days) | C4: Base Year | D4: FY2026(E) | E4: FY2027(E) | F4: FY2028(E) | G4: FY2029(E) | H4: FY2030(E)
B5: DSO (Days Sales Outstanding) | C5: =C12/C9*365 | D5: =CHOOSE('DCF Model'!$D$27,D25,D26,D27,D28,D29) | E5: =CHOOSE('DCF Model'!$D$27,E25,E26,E27,E28,E29) | F5: =CHOOSE('DCF Model'!$D$27,F25,F26,F27,F28,F29) | G5: =CHOOSE('DCF Model'!$D$27,G25,G26,G27,G28,G29) | H5: =CHOOSE('DCF Model'!$D$27,H25,H26,H27,H28,H29)
B6: DIH (Days Inventory Held) | C6: =C13/C10*365 | D6: =CHOOSE('DCF Model'!$D$27,D32,D33,D34,D35,D36) | E6: =CHOOSE('DCF Model'!$D$27,E32,E33,E34,E35,E36) | F6: =CHOOSE('DCF Model'!$D$27,F32,F33,F34,F35,F36) | G6: =CHOOSE('DCF Model'!$D$27,G32,G33,G34,G35,G36) | H6: =CHOOSE('DCF Model'!$D$27,H32,H33,H34,H35,H36)
B7: DPO (Days Payable Outstanding) | C7: =C15/C10*365 | D7: =CHOOSE('DCF Model'!$D$27,D39,D40,D41,D42,D43) | E7: =CHOOSE('DCF Model'!$D$27,E39,E40,E41,E42,E43) | F7: =CHOOSE('DCF Model'!$D$27,F39,F40,F41,F42,F43) | G7: =CHOOSE('DCF Model'!$D$27,G39,G40,G41,G42,G43) | H7: =CHOOSE('DCF Model'!$D$27,H39,H40,H41,H42,H43)
B8: P&L Reference (JPY mn)
B9: Revenue | C9: 24599.166 | D9: ='DCF Model'!C33 | E9: ='DCF Model'!D33 | F9: ='DCF Model'!E33 | G9: ='DCF Model'!F33 | H9: ='DCF Model'!G33
B10: COGS | C10: 17821.475 | D10: ='DCF Model'!C34 | E10: ='DCF Model'!D34 | F10: ='DCF Model'!E34 | G10: ='DCF Model'!F34 | H10: ='DCF Model'!G34
B11: Working Capital Items (JPY mn)
B12: Accounts Receivable | C12: 7878 | D12: =D9*D5/365 | E12: =E9*E5/365 | F12: =F9*F5/365 | G12: =G9*G5/365 | H12: =H9*H5/365
B13: Inventory | C13: 269 | D13: =D10*D6/365 | E13: =E10*E6/365 | F13: =F10*F6/365 | G13: =G10*G6/365 | H13: =H10*H6/365
B14: Current Assets (AR + Inv) | C14: =C12+C13 | D14: =D12+D13 | E14: =E12+E13 | F14: =F12+F13 | G14: =G12+G13 | H14: =H12+H13
B15: Accounts Payable | C15: 1738 | D15: =D10*D7/365 | E15: =E10*E7/365 | F15: =F10*F7/365 | G15: =G10*G7/365 | H15: =H10*H7/365
B16: Current Liabilities (AP) | C16: =C15 | D16: =D15 | E16: =E15 | F16: =F15 | G16: =G15 | H16: =H15
B17: Net Working Capital (JPY mn)
B18: Net Working Capital | C18: =C14-C16 | D18: =D14-D16 | E18: =E14-E16 | F18: =F14-F16 | G18: =G14-G16 | H18: =H14-H16
B19: Change in NWC | C19: n/a | D19: =D18-C18 | E19: =E18-D18 | F19: =F18-E18 | G19: =G18-F18 | H19: =H18-G18
B22: Scenario Input Matrix (Working Capital Days)
D23: FY2026(E) | E23: FY2027(E) | F23: FY2028(E) | G23: FY2029(E) | H23: FY2030(E)
B24: DSO (Days)
B25: Base | D25: 115 | E25: 114 | F25: 114 | G25: 114 | H25: 114
B26: Upside | D26: 113 | E26: 111 | F26: 109 | G26: 107 | H26: 107
B27: Management | D27: 116 | E27: 115 | F27: 115 | G27: 115 | H27: 115
B28: Downside 1 | D28: 118 | E28: 119 | F28: 120 | G28: 120 | H28: 120
B29: Downside 2 | D29: 120 | E29: 122 | F29: 124 | G29: 125 | H29: 125
B31: DIH (Days)
B32: Base | D32: 6 | E32: 6 | F32: 6 | G32: 6 | H32: 6
B33: Upside | D33: 5.5 | E33: 5.5 | F33: 5.5 | G33: 5.5 | H33: 5.5
B34: Management | D34: 6 | E34: 6 | F34: 6 | G34: 6 | H34: 6
B35: Downside 1 | D35: 6.5 | E35: 6.5 | F35: 7 | G35: 7 | H35: 7
B36: Downside 2 | D36: 7 | E36: 7 | F36: 7.5 | G36: 7.5 | H36: 7.5
B38: DPO (Days)
B39: Base | D39: 35 | E39: 34 | F39: 34 | G39: 34 | H39: 34
B40: Upside | D40: 36 | E40: 37 | F40: 38 | G40: 38 | H40: 38
B41: Management | D41: 35 | E41: 35 | F41: 35 | G41: 35 | H41: 35
B42: Downside 1 | D42: 34 | E42: 33 | F42: 33 | G42: 33 | H42: 33
B43: Downside 2 | D43: 33 | E43: 32 | F43: 32 | G43: 32 | H43: 32

Sheet Comps Analysis
B2: Comparable Company Analysis
B4: Company | C4: Ticker | D4: Mkt Cap (JPY mn) | E4: EV (JPY mn) | F4: Revenue (JPY mn) | G4: EBITDA (JPY mn) | H4: Op Income (JPY mn) | I4: Net Income (JPY mn) | J4: EV/EBITDA | K4: EV/Revenue | L4: PER | M4: PBR | N4: Op Margin | O4: ROE
B5: Systena | C5: 2317.T | D5: 150488.91 | E5: 152038.91 | F5: 92410 | G5: 15820 | H5: 15360 | I5: 11250 | J5: =E5/G5 | K5: =E5/F5 | L5: =D5/I5 | M5: 4.5671899 | N5: =H5/F5 | O5: 0.3414264
B6: SRA HD | C6: 3817.T | D6: 60769.006 | E6: 60839.006 | F6: 54700 | G6: 8490 | H6: 8300 | I6: 5000 | J6: =E6/G6 | K6: =E6/F6 | L6: =D6/I6 | M6: 1.9537988 | N6: =H6/F6 | O6: 0.1607562
B7: CEC | C7: 9692.T | D7: 62701.822 | E7: 63051.822 | F7: 65000 | G7: 8018 | H7: 7200 | I7: 5150 | J7: =E7/G7 | K7: =E7/F7 | L7: =D7/I7 | M7: 1.5519869 | N7: =H7/F7 | O7: 0.12747209
B8: Cresco | C8: 4674.T | D8: 59213.136 | E8: 56713.136 | F8: 48000 | G8: 6800 | H8: 5200 | I8: 3600 | J8: =E8/G8 | K8: =E8/F8 | L8: =D8/I8 | M8: 2.6915062 | N8: =H8/F8 | O8: 0.16363636
B9: DTS | C9: 9682.T | D9: 169865.89 | E9: 166865.89 | F9: 47000 | G9: 7500 | H9: 5700 | I9: 3900 | J9: =E9/G9 | K9: =E9/F9 | L9: =D9/I9 | M9: 6.0666388 | N9: =H9/F9 | O9: 0.13928571
B14: Statistics
B15: 25th Percentile | D15: =PERCENTILE(J5:J9,0.25) | E15: =PERCENTILE(K5:K9,0.25) | F15: =PERCENTILE(L5:L9,0.25) | G15: =PERCENTILE(M5:M9,0.25) | H15: =PERCENTILE(N5:N9,0.25) | I15: =PERCENTILE(O5:O9,0.25)
B16: Median (50th) | D16: =MEDIAN(J5:J9) | E16: =MEDIAN(K5:K9) | F16: =MEDIAN(L5:L9) | G16: =MEDIAN(M5:M9) | H16: =MEDIAN(N5:N9) | I16: =MEDIAN(O5:O9)
B17: 75th Percentile | D17: =PERCENTILE(J5:J9,0.75) | E17: =PERCENTILE(K5:K9,0.75) | F17: =PERCENTILE(L5:L9,0.75) | G17: =PERCENTILE(M5:M9,0.75) | H17: =PERCENTILE(N5:N9,0.75) | I17: =PERCENTILE(O5:O9,0.75)
B19: Implied Valuation for 株式会社コア
B20: 株式会社コア Financials
B21: EBITDA (JPY mn) | C21: 3391
B22: Net Income (JPY mn) | C22: 2207
B23: Shares Outstanding | C23: 14368501
B24: Net Debt (JPY mn) | C24: -7296.8
B26: Implied Share Price (Median Multiples)
B27: Via EV/EBITDA (Median) | C27: =ROUND((C21*D16-C24)*1000000/C23,0)
B28: Via PER (Median) | C28: =ROUND(C22*F16*1000000/C23,0)

Sheet Sensitivity Analysis
B2: Sensitivity Analysis
B3: Current WACC: | C3: ='DCF Model'!C26 | E3: Terminal g: | F3: ='DCF Model'!C13 | H3: Exit Multiple: | I3: ='DCF Model'!C14
B5: Table 1: WACC vs Terminal Growth Rate (PGM - Implied Share Price, JPY)
B6: WACC \ Terminal g | C6: =$F$3-0.0075 | D6: =$F$3-0.005 | E6: =$F$3-0.0025 | F6: =$F$3 | G6: =$F$3+0.0025 | H6: =$F$3+0.005 | I6: =$F$3+0.0075
B7: =$C$3-0.015 | C7: =IFERROR(ROUND(('DCF Model'!C45/(1+$B7)^('DCF Model'!C19+0)+'DCF Model'!D45/(1+$B7)^('DCF Model'!C19+1)+'DCF Model'!E45/(1+$B7)^('DCF Model'!C19+2)+'DCF Model'!F45/(1+$B7)^('DCF Model'!C19+3)+'DCF Model'!G45/(1+$B7)^('DCF Model'!C19+4)+'DCF Model'!G45*(1+C$6)/($B7-C$6)/(1+$B7)^('DCF Model'!C19+4)-'DCF Model'!C16)*1000000/'DCF Model'!C15,0),"") | D7: =IFERROR(ROUND(('DCF Model'!C45/(1+$B7)^('DCF Model'!C19+0)+'DCF Model'!D45/(1+$B7)^('DCF Model'!C19+1)+'DCF Model'!E45/(1+$B7)^('DCF Model'!C19+2)+'DCF Model'!F45/(1+$B7)^('DCF Model'!C19+3)+'DCF Model'!G45/(1+$B7)^('DCF Model'!C19+4)+'DCF Model'!G45*(1+D$6)/($B7-D$6)/(1+$B7)^('DCF Model'!C19+4)-'DCF Model'!C16)*1000000/'DCF Model'!C15,0),"") | E7: =IFERROR(ROUND(('DCF Model'!C45/(1+$B7)^('DCF Model'!C19+0)+'DCF Model'!D45/(1+$B7)^('DCF Model'!C19+1)+'DCF Model'!E45/(1+$B7)^('DCF Model'!C19+2)+'DCF Model'!F45/(1+$B7)^('DCF Model'!C19+3)+'DCF Model'!G45/(1+$B7)^('DCF Model'!C19+4)+'DCF Model'!G45*(1+E$6)/($B7-E$6)/(1+$B7)^('DCF Model'!C19+4)-'DCF Model'!C16)*1000000/'DCF Model'!C15,0),"") | F7: =IFERROR(ROUND(('DCF Model'!C45/(1+$B7)^('DCF Model'!C19+0)+'DCF Model'!D45/(1+$B7)^('DCF Model'!C19+1)+'DCF Model'!E45/(1+$B7)^('DCF Model'!C19+2)+'DCF Model'!F45/(1+$B7)^('DCF Model'!C19+3)+'DCF Model'!G45/(1+$B7)^('DCF Model'!C19+4)+'DCF Model'!G45*(1+F$6)/($B7-F$6)/(1+$B7)^('DCF Model'!C19+4)-'DCF Model'!C16)*1000000/'DCF Model'!C15,0),"") | G7: =IFERROR(ROUND(('DCF Model'!C45/(1+$B7)^('DCF Model'!C19+0)+'DCF Model'!D45/(1+$B7)^('DCF Model'!C19+1)+'DCF Model'!E45/(1+$B7)^('DCF Model'!C19+2)+'DCF Model'!F45/(1+$B7)^('DCF Model'!C19+3)+'DCF Model'!G45/(1+$B7)^('DCF Model'!C19+4)+'DCF Model'!G45*(1+G$6)/($B7-G$6)/(1+$B7)^('DCF Model'!C19+4)-'DCF Model'!C16)*1000000/'DCF Model'!C15,0),"") | H7: =IFERROR(ROUND(('DCF Model'!C45/(1+$B7)^('DCF Model'!C19+0)+'DCF Model'!D45/(1+$B7)^('DCF Model'!C19+1)+'DCF Model'!E45/(1+$B7)^('DCF Model'!C19+2)+'DCF Model'!F45/(1+$B7)^('DCF Model'!C19+3)+'DCF Model'!G45/(1+$B7)^('DCF Model'!C19+4)+'DCF Model'!G45*(1+H$6)/($B7-H$6)/(1+$B7)^('DCF Model'!C19+4)-'DCF Model'!C16)*1000000/'DCF Model'!C15,0),"") | I7: =IFERROR(ROUND(('DCF Model'!C45/(1+$B7)^('DCF Model'!C19+0)+'DCF Model'!D45/(1+$B7)^('DCF Model'!C19+1)+'DCF Model'!E45/(1+$B7)^('DCF Model'!C19+2)+'DCF Model'!F45/(1+$B7)^('DCF Model'!C19+3)+'DCF Model'!G45/(1+$B7)^('DCF Model'!C19+4)+'DCF Model'!G45*(1+I$6)/($B7-I$6)/(1+$B7)^('DCF Model'!C19+4)-'DCF Model'!C16)*1000000/'DCF Model'!C15,0),"")
B8: =$C$3-0.01 | C8: =IFERROR(ROUND(('DCF Model'!C45/(1+$B8)^('DCF Model'!C19+0)+'DCF Model'!D45/(1+$B8)^('DCF Model'!C19+1)+'DCF Model'!E45/(1+$B8)^('DCF Model'!C19+2)+'DCF Model'!F45/(1+$B8)^('DCF Model'!C19+3)+'DCF Model'!G45/(1+$B8)^('DCF Model'!C19+4)+'DCF Model'!G45*(1+C$6)/($B8-C$6)/(1+$B8)^('DCF Model'!C19+4)-'DCF Model'!C16)*1000000/'DCF Model'!C15,0),"") | D8: =IFERROR(ROUND(('DCF Model'!C45/(1+$B8)^('DCF Model'!C19+0)+'DCF Model'!D45/(1+$B8)^('DCF Model'!C19+1)+'DCF Model'!E45/(1+$B8)^('DCF Model'!C19+2)+'DCF Model'!F45/(1+$B8)^('DCF Model'!C19+3)+'DCF Model'!G45/(1+$B8)^('DCF Model'!C19+4)+'DCF Model'!G45*(1+D$6)/($B8-D$6)/(1+$B8)^('DCF Model'!C19+4)-'DCF Model'!C16)*1000000/'DCF Model'!C15,0),"") | E8: =IFERROR(ROUND(('DCF Model'!C45/(1+$B8)^('DCF Model'!C19+0)+'DCF Model'!D45/(1+$B8)^('DCF Model'!C19+1)+'DCF Model'!E45/(1+$B8)^('DCF Model'!C19+2)+'DCF Model'!F45/(1+$B8)^('DCF Model'!C19+3)+'DCF Model'!G45/(1+$B8)^('DCF Model'!C19+4)+'DCF Model'!G45*(1+E$6)/($B8-E$6)/(1+$B8)^('DCF Model'!C19+4)-'DCF Model'!C16)*1000000/'DCF Model'!C15,0),"") | F8: =IFERROR(ROUND(('DCF Model'!C45/(1+$B8)^('DCF Model'!C19+0)+'DCF Model'!D45/(1+$B8)^('DCF Model'!C19+1)+'DCF Model'!E45/(1+$B8)^('DCF Model'!C19+2)+'DCF Model'!F45/(1+$B8)^('DCF Model'!C19+3)+'DCF Model'!G45/(1+$B8)^('DCF Model'!C19+4)+'DCF Model'!G45*(1+F$6)/($B8-F$6)/(1+$B8)^('DCF Model'!C19+4)-'DCF Model'!C16)*1000000/'DCF Model'!C15,0),"") | G8: =IFERROR(ROUND(('DCF Model'!C45/(1+$B8)^('DCF Model'!C19+0)+'DCF Model'!D45/(1+$B8)^('DCF Model'!C19+1)+'DCF Model'!E45/(1+$B8)^('DCF Model'!C19+2)+'DCF Model'!F45/(1+$B8)^('DCF Model'!C19+3)+'DCF Model'!G45/(1+$B8)^('DCF Model'!C19+4)+'DCF Model'!G45*(1+G$6)/($B8-G$6)/(1+$B8)^('DCF Model'!C19+4)-'DCF Model'!C16)*1000000/'DCF Model'!C15,0),"") | H8: =IFERROR(ROUND(('DCF Model'!C45/(1+$B8)^('DCF Model'!C19+0)+'DCF Model'!D45/(1+$B8)^('DCF Model'!C19+1)+'DCF Model'!E45/(1+$B8)^('DCF Model'!C19+2)+'DCF Model'!F45/(1+$B8)^('DCF Model'!C19+3)+'DCF Model'!G45/(1+$B8)^('DCF Model'!C19+4)+'DCF Model'!G45*(1+H$6)/($B8-H$6)/(1+$B8)^('DCF Model'!C19+4)-'DCF Model'!C16)*1000000/'DCF Model'!C15,0),"") | I8: =IFERROR(ROUND(('DCF Model'!C45/(1+$B8)^('DCF Model'!C19+0)+'DCF Model'!D45/(1+$B8)^('DCF Model'!C19+1)+'DCF Model'!E45/(1+$B8)^('DCF Model'!C19+2)+'DCF Model'!F45/(1+$B8)^('DCF Model'!C19+3)+'DCF Model'!G45/(1+$B8)^('DCF Model'!C19+4)+'DCF Model'!G45*(1+I$6)/($B8-I$6)/(1+$B8)^('DCF Model'!C19+4)-'DCF Model'!C16)*1000000/'DCF Model'!C15,0),"")
B9: =$C$3-0.005 | C9: =IFERROR(ROUND(('DCF Model'!C45/(1+$B9)^('DCF Model'!C19+0)+'DCF Model'!D45/(1+$B9)^('DCF Model'!C19+1)+'DCF Model'!E45/(1+$B9)^('DCF Model'!C19+2)+'DCF Model'!F45/(1+$B9)^('DCF Model'!C19+3)+'DCF Model'!G45/(1+$B9)^('DCF Model'!C19+4)+'DCF Model'!G45*(1+C$6)/($B9-C$6)/(1+$B9)^('DCF Model'!C19+4)-'DCF Model'!C16)*1000000/'DCF Model'!C15,0),"") | D9: =IFERROR(ROUND(('DCF Model'!C45/(1+$B9)^('DCF Model'!C19+0)+'DCF Model'!D45/(1+$B9)^('DCF Model'!C19+1)+'DCF Model'!E45/(1+$B9)^('DCF Model'!C19+2)+'DCF Model'!F45/(1+$B9)^('DCF Model'!C19+3)+'DCF Model'!G45/(1+$B9)^('DCF Model'!C19+4)+'DCF Model'!G45*(1+D$6)/($B9-D$6)/(1+$B9)^('DCF Model'!C19+4)-'DCF Model'!C16)*1000000/'DCF Model'!C15,0),"") | E9: =IFERROR(ROUND(('DCF Model'!C45/(1+$B9)^('DCF Model'!C19+0)+'DCF Model'!D45/(1+$B9)^('DCF Model'!C19+1)+'DCF Model'!E45/(1+$B9)^('DCF Model'!C19+2)+'DCF Model'!F45/(1+$B9)^('DCF Model'!C19+3)+'DCF Model'!G45/(1+$B9)^('DCF Model'!C19+4)+'DCF Model'!G45*(1+E$6)/($B9-E$6)/(1+$B9)^('DCF Model'!C19+4)-'DCF Model'!C16)*1000000/'DCF Model'!C15,0),"") | F9: =IFERROR(ROUND(('DCF Model'!C45/(1+$B9)^('DCF Model'!C19+0)+'DCF Model'!D45/(1+$B9)^('DCF Model'!C19+1)+'DCF Model'!E45/(1+$B9)^('DCF Model'!C19+2)+'DCF Model'!F45/(1+$B9)^('DCF Model'!C19+3)+'DCF Model'!G45/(1+$B9)^('DCF Model'!C19+4)+'DCF Model'!G45*(1+F$6)/($B9-F$6)/(1+$B9)^('DCF Model'!C19+4)-'DCF Model'!C16)*1000000/'DCF Model'!C15,0),"") | G9: =IFERROR(ROUND(('DCF Model'!C45/(1+$B9)^('DCF Model'!C19+0)+'DCF Model'!D45/(1+$B9)^('DCF Model'!C19+1)+'DCF Model'!E45/(1+$B9)^('DCF Model'!C19+2)+'DCF Model'!F45/(1+$B9)^('DCF Model'!C19+3)+'DCF Model'!G45/(1+$B9)^('DCF Model'!C19+4)+'DCF Model'!G45*(1+G$6)/($B9-G$6)/(1+$B9)^('DCF Model'!C19+4)-'DCF Model'!C16)*1000000/'DCF Model'!C15,0),"") | H9: =IFERROR(ROUND(('DCF Model'!C45/(1+$B9)^('DCF Model'!C19+0)+'DCF Model'!D45/(1+$B9)^('DCF Model'!C19+1)+'DCF Model'!E45/(1+$B9)^('DCF Model'!C19+2)+'DCF Model'!F45/(1+$B9)^('DCF Model'!C19+3)+'DCF Model'!G45/(1+$B9)^('DCF Model'!C19+4)+'DCF Model'!G45*(1+H$6)/($B9-H$6)/(1+$B9)^('DCF Model'!C19+4)-'DCF Model'!C16)*1000000/'DCF Model'!C15,0),"") | I9: =IFERROR(ROUND(('DCF Model'!C45/(1+$B9)^('DCF Model'!C19+0)+'DCF Model'!D45/(1+$B9)^('DCF Model'!C19+1)+'DCF Model'!E45/(1+$B9)^('DCF Model'!C19+2)+'DCF Model'!F45/(1+$B9)^('DCF Model'!C19+3)+'DCF Model'!G45/(1+$B9)^('DCF Model'!C19+4)+'DCF Model'!G45*(1+I$6)/($B9-I$6)/(1+$B9)^('DCF Model'!C19+4)-'DCF Model'!C16)*1000000/'DCF Model'!C15,0),"")
B10: =$C$3 | C10: =IFERROR(ROUND(('DCF Model'!C45/(1+$B10)^('DCF Model'!C19+0)+'DCF Model'!D45/(1+$B10)^('DCF Model'!C19+1)+'DCF Model'!E45/(1+$B10)^('DCF Model'!C19+2)+'DCF Model'!F45/(1+$B10)^('DCF Model'!C19+3)+'DCF Model'!G45/(1+$B10)^('DCF Model'!C19+4)+'DCF Model'!G45*(1+C$6)/($B10-C$6)/(1+$B10)^('DCF Model'!C19+4)-'DCF Model'!C16)*1000000/'DCF Model'!C15,0),"") | D10: =IFERROR(ROUND(('DCF Model'!C45/(1+$B10)^('DCF Model'!C19+0)+'DCF Model'!D45/(1+$B10)^('DCF Model'!C19+1)+'DCF Model'!E45/(1+$B10)^('DCF Model'!C19+2)+'DCF Model'!F45/(1+$B10)^('DCF Model'!C19+3)+'DCF Model'!G45/(1+$B10)^('DCF Model'!C19+4)+'DCF Model'!G45*(1+D$6)/($B10-D$6)/(1+$B10)^('DCF Model'!C19+4)-'DCF Model'!C16)*1000000/'DCF Model'!C15,0),"") | E10: =IFERROR(ROUND(('DCF Model'!C45/(1+$B10)^('DCF Model'!C19+0)+'DCF Model'!D45/(1+$B10)^('DCF Model'!C19+1)+'DCF Model'!E45/(1+$B10)^('DCF Model'!C19+2)+'DCF Model'!F45/(1+$B10)^('DCF Model'!C19+3)+'DCF Model'!G45/(1+$B10)^('DCF Model'!C19+4)+'DCF Model'!G45*(1+E$6)/($B10-E$6)/(1+$B10)^('DCF Model'!C19+4)-'DCF Model'!C16)*1000000/'DCF Model'!C15,0),"") | F10: =IFERROR(ROUND(('DCF Model'!C45/(1+$B10)^('DCF Model'!C19+0)+'DCF Model'!D45/(1+$B10)^('DCF Model'!C19+1)+'DCF Model'!E45/(1+$B10)^('DCF Model'!C19+2)+'DCF Model'!F45/(1+$B10)^('DCF Model'!C19+3)+'DCF Model'!G45/(1+$B10)^('DCF Model'!C19+4)+'DCF Model'!G45*(1+F$6)/($B10-F$6)/(1+$B10)^('DCF Model'!C19+4)-'DCF Model'!C16)*1000000/'DCF Model'!C15,0),"") | G10: =IFERROR(ROUND(('DCF Model'!C45/(1+$B10)^('DCF Model'!C19+0)+'DCF Model'!D45/(1+$B10)^('DCF Model'!C19+1)+'DCF Model'!E45/(1+$B10)^('DCF Model'!C19+2)+'DCF Model'!F45/(1+$B10)^('DCF Model'!C19+3)+'DCF Model'!G45/(1+$B10)^('DCF Model'!C19+4)+'DCF Model'!G45*(1+G$6)/($B10-G$6)/(1+$B10)^('DCF Model'!C19+4)-'DCF Model'!C16)*1000000/'DCF Model'!C15,0),"") | H10: =IFERROR(ROUND(('DCF Model'!C45/(1+$B10)^('DCF Model'!C19+0)+'DCF Model'!D45/(1+$B10)^('DCF Model'!C19+1)+'DCF Model'!E45/(1+$B10)^('DCF Model'!C19+2)+'DCF Model'!F45/(1+$B10)^('DCF Model'!C19+3)+'DCF Model'!G45/(1+$B10)^('DCF Model'!C19+4)+'DCF Model'!G45*(1+H$6)/($B10-H$6)/(1+$B10)^('DCF Model'!C19+4)-'DCF Model'!C16)*1000000/'DCF Model'!C15,0),"") | I10: =IFERROR(ROUND(('DCF Model'!C45/(1+$B10)^('DCF Model'!C19+0)+'DCF Model'!D45/(1+$B10)^('DCF Model'!C19+1)+'DCF Model'!E45/(1+$B10)^('DCF Model'!C19+2)+'DCF Model'!F45/(1+$B10)^('DCF Model'!C19+3)+'DCF Model'!G45/(1+$B10)^('DCF Model'!C19+4)+'DCF Model'!G45*(1+I$6)/($B10-I$6)/(1+$B10)^('DCF Model'!C19+4)-'DCF Model'!C16)*1000000/'DCF Model'!C15,0),"")
B11: =$C$3+0.005 | C11: =IFERROR(ROUND(('DCF Model'!C45/(1+$B11)^('DCF Model'!C19+0)+'DCF Model'!D45/(1+$B11)^('DCF Model'!C19+1)+'DCF Model'!E45/(1+$B11)^('DCF Model'!C19+2)+'DCF Model'!F45/(1+$B11)^('DCF Model'!C19+3)+'DCF Model'!G45/(1+$B11)^('DCF Model'!C19+4)+'DCF Model'!G45*(1+C$6)/($B11-C$6)/(1+$B11)^('DCF Model'!C19+4)-'DCF Model'!C16)*1000000/'DCF Model'!C15,0),"") | D11: =IFERROR(ROUND(('DCF Model'!C45/(1+$B11)^('DCF Model'!C19+0)+'DCF Model'!D45/(1+$B11)^('DCF Model'!C19+1)+'DCF Model'!E45/(1+$B11)^('DCF Model'!C19+2)+'DCF Model'!F45/(1+$B11)^('DCF Model'!C19+3)+'DCF Model'!G45/(1+$B11)^('DCF Model'!C19+4)+'DCF Model'!G45*(1+D$6)/($B11-D$6)/(1+$B11)^('DCF Model'!C19+4)-'DCF Model'!C16)*1000000/'DCF Model'!C15,0),"") | E11: =IFERROR(ROUND(('DCF Model'!C45/(1+$B11)^('DCF Model'!C19+0)+'DCF Model'!D45/(1+$B11)^('DCF Model'!C19+1)+'DCF Model'!E45/(1+$B11)^('DCF Model'!C19+2)+'DCF Model'!F45/(1+$B11)^('DCF Model'!C19+3)+'DCF Model'!G45/(1+$B11)^('DCF Model'!C19+4)+'DCF Model'!G45*(1+E$6)/($B11-E$6)/(1+$B11)^('DCF Model'!C19+4)-'DCF Model'!C16)*1000000/'DCF Model'!C15,0),"") | F11: =IFERROR(ROUND(('DCF Model'!C45/(1+$B11)^('DCF Model'!C19+0)+'DCF Model'!D45/(1+$B11)^('DCF Model'!C19+1)+'DCF Model'!E45/(1+$B11)^('DCF Model'!C19+2)+'DCF Model'!F45/(1+$B11)^('DCF Model'!C19+3)+'DCF Model'!G45/(1+$B11)^('DCF Model'!C19+4)+'DCF Model'!G45*(1+F$6)/($B11-F$6)/(1+$B11)^('DCF Model'!C19+4)-'DCF Model'!C16)*1000000/'DCF Model'!C15,0),"") | G11: =IFERROR(ROUND(('DCF Model'!C45/(1+$B11)^('DCF Model'!C19+0)+'DCF Model'!D45/(1+$B11)^('DCF Model'!C19+1)+'DCF Model'!E45/(1+$B11)^('DCF Model'!C19+2)+'DCF Model'!F45/(1+$B11)^('DCF Model'!C19+3)+'DCF Model'!G45/(1+$B11)^('DCF Model'!C19+4)+'DCF Model'!G45*(1+G$6)/($B11-G$6)/(1+$B11)^('DCF Model'!C19+4)-'DCF Model'!C16)*1000000/'DCF Model'!C15,0),"") | H11: =IFERROR(ROUND(('DCF Model'!C45/(1+$B11)^('DCF Model'!C19+0)+'DCF Model'!D45/(1+$B11)^('DCF Model'!C19+1)+'DCF Model'!E45/(1+$B11)^('DCF Model'!C19+2)+'DCF Model'!F45/(1+$B11)^('DCF Model'!C19+3)+'DCF Model'!G45/(1+$B11)^('DCF Model'!C19+4)+'DCF Model'!G45*(1+H$6)/($B11-H$6)/(1+$B11)^('DCF Model'!C19+4)-'DCF Model'!C16)*1000000/'DCF Model'!C15,0),"") | I11: =IFERROR(ROUND(('DCF Model'!C45/(1+$B11)^('DCF Model'!C19+0)+'DCF Model'!D45/(1+$B11)^('DCF Model'!C19+1)+'DCF Model'!E45/(1+$B11)^('DCF Model'!C19+2)+'DCF Model'!F45/(1+$B11)^('DCF Model'!C19+3)+'DCF Model'!G45/(1+$B11)^('DCF Model'!C19+4)+'DCF Model'!G45*(1+I$6)/($B11-I$6)/(1+$B11)^('DCF Model'!C19+4)-'DCF Model'!C16)*1000000/'DCF Model'!C15,0),"")
B12: =$C$3+0.01 | C12: =IFERROR(ROUND(('DCF Model'!C45/(1+$B12)^('DCF Model'!C19+0)+'DCF Model'!D45/(1+$B12)^('DCF Model'!C19+1)+'DCF Model'!E45/(1+$B12)^('DCF Model'!C19+2)+'DCF Model'!F45/(1+$B12)^('DCF Model'!C19+3)+'DCF Model'!G45/(1+$B12)^('DCF Model'!C19+4)+'DCF Model'!G45*(1+C$6)/($B12-C$6)/(1+$B12)^('DCF Model'!C19+4)-'DCF Model'!C16)*1000000/'DCF Model'!C15,0),"") | D12: =IFERROR(ROUND(('DCF Model'!C45/(1+$B12)^('DCF Model'!C19+0)+'DCF Model'!D45/(1+$B12)^('DCF Model'!C19+1)+'DCF Model'!E45/(1+$B12)^('DCF Model'!C19+2)+'DCF Model'!F45/(1+$B12)^('DCF Model'!C19+3)+'DCF Model'!G45/(1+$B12)^('DCF Model'!C19+4)+'DCF Model'!G45*(1+D$6)/($B12-D$6)/(1+$B12)^('DCF Model'!C19+4)-'DCF Model'!C16)*1000000/'DCF Model'!C15,0),"") | E12: =IFERROR(ROUND(('DCF Model'!C45/(1+$B12)^('DCF Model'!C19+0)+'DCF Model'!D45/(1+$B12)^('DCF Model'!C19+1)+'DCF Model'!E45/(1+$B12)^('DCF Model'!C19+2)+'DCF Model'!F45/(1+$B12)^('DCF Model'!C19+3)+'DCF Model'!G45/(1+$B12)^('DCF Model'!C19+4)+'DCF Model'!G45*(1+E$6)/($B12-E$6)/(1+$B12)^('DCF Model'!C19+4)-'DCF Model'!C16)*1000000/'DCF Model'!C15,0),"") | F12: =IFERROR(ROUND(('DCF Model'!C45/(1+$B12)^('DCF Model'!C19+0)+'DCF Model'!D45/(1+$B12)^('DCF Model'!C19+1)+'DCF Model'!E45/(1+$B12)^('DCF Model'!C19+2)+'DCF Model'!F45/(1+$B12)^('DCF Model'!C19+3)+'DCF Model'!G45/(1+$B12)^('DCF Model'!C19+4)+'DCF Model'!G45*(1+F$6)/($B12-F$6)/(1+$B12)^('DCF Model'!C19+4)-'DCF Model'!C16)*1000000/'DCF Model'!C15,0),"") | G12: =IFERROR(ROUND(('DCF Model'!C45/(1+$B12)^('DCF Model'!C19+0)+'DCF Model'!D45/(1+$B12)^('DCF Model'!C19+1)+'DCF Model'!E45/(1+$B12)^('DCF Model'!C19+2)+'DCF Model'!F45/(1+$B12)^('DCF Model'!C19+3)+'DCF Model'!G45/(1+$B12)^('DCF Model'!C19+4)+'DCF Model'!G45*(1+G$6)/($B12-G$6)/(1+$B12)^('DCF Model'!C19+4)-'DCF Model'!C16)*1000000/'DCF Model'!C15,0),"") | H12: =IFERROR(ROUND(('DCF Model'!C45/(1+$B12)^('DCF Model'!C19+0)+'DCF Model'!D45/(1+$B12)^('DCF Model'!C19+1)+'DCF Model'!E45/(1+$B12)^('DCF Model'!C19+2)+'DCF Model'!F45/(1+$B12)^('DCF Model'!C19+3)+'DCF Model'!G45/(1+$B12)^('DCF Model'!C19+4)+'DCF Model'!G45*(1+H$6)/($B12-H$6)/(1+$B12)^('DCF Model'!C19+4)-'DCF Model'!C16)*1000000/'DCF Model'!C15,0),"") | I12: =IFERROR(ROUND(('DCF Model'!C45/(1+$B12)^('DCF Model'!C19+0)+'DCF Model'!D45/(1+$B12)^('DCF Model'!C19+1)+'DCF Model'!E45/(1+$B12)^('DCF Model'!C19+2)+'DCF Model'!F45/(1+$B12)^('DCF Model'!C19+3)+'DCF Model'!G45/(1+$B12)^('DCF Model'!C19+4)+'DCF Model'!G45*(1+I$6)/($B12-I$6)/(1+$B12)^('DCF Model'!C19+4)-'DCF Model'!C16)*1000000/'DCF Model'!C15,0),"")
B13: =$C$3+0.015 | C13: =IFERROR(ROUND(('DCF Model'!C45/(1+$B13)^('DCF Model'!C19+0)+'DCF Model'!D45/(1+$B13)^('DCF Model'!C19+1)+'DCF Model'!E45/(1+$B13)^('DCF Model'!C19+2)+'DCF Model'!F45/(1+$B13)^('DCF Model'!C19+3)+'DCF Model'!G45/(1+$B13)^('DCF Model'!C19+4)+'DCF Model'!G45*(1+C$6)/($B13-C$6)/(1+$B13)^('DCF Model'!C19+4)-'DCF Model'!C16)*1000000/'DCF Model'!C15,0),"") | D13: =IFERROR(ROUND(('DCF Model'!C45/(1+$B13)^('DCF Model'!C19+0)+'DCF Model'!D45/(1+$B13)^('DCF Model'!C19+1)+'DCF Model'!E45/(1+$B13)^('DCF Model'!C19+2)+'DCF Model'!F45/(1+$B13)^('DCF Model'!C19+3)+'DCF Model'!G45/(1+$B13)^('DCF Model'!C19+4)+'DCF Model'!G45*(1+D$6)/($B13-D$6)/(1+$B13)^('DCF Model'!C19+4)-'DCF Model'!C16)*1000000/'DCF Model'!C15,0),"") | E13: =IFERROR(ROUND(('DCF Model'!C45/(1+$B13)^('DCF Model'!C19+0)+'DCF Model'!D45/(1+$B13)^('DCF Model'!C19+1)+'DCF Model'!E45/(1+$B13)^('DCF Model'!C19+2)+'DCF Model'!F45/(1+$B13)^('DCF Model'!C19+3)+'DCF Model'!G45/(1+$B13)^('DCF Model'!C19+4)+'DCF Model'!G45*(1+E$6)/($B13-E$6)/(1+$B13)^('DCF Model'!C19+4)-'DCF Model'!C16)*1000000/'DCF Model'!C15,0),"") | F13: =IFERROR(ROUND(('DCF Model'!C45/(1+$B13)^('DCF Model'!C19+0)+'DCF Model'!D45/(1+$B13)^('DCF Model'!C19+1)+'DCF Model'!E45/(1+$B13)^('DCF Model'!C19+2)+'DCF Model'!F45/(1+$B13)^('DCF Model'!C19+3)+'DCF Model'!G45/(1+$B13)^('DCF Model'!C19+4)+'DCF Model'!G45*(1+F$6)/($B13-F$6)/(1+$B13)^('DCF Model'!C19+4)-'DCF Model'!C16)*1000000/'DCF Model'!C15,0),"") | G13: =IFERROR(ROUND(('DCF Model'!C45/(1+$B13)^('DCF Model'!C19+0)+'DCF Model'!D45/(1+$B13)^('DCF Model'!C19+1)+'DCF Model'!E45/(1+$B13)^('DCF Model'!C19+2)+'DCF Model'!F45/(1+$B13)^('DCF Model'!C19+3)+'DCF Model'!G45/(1+$B13)^('DCF Model'!C19+4)+'DCF Model'!G45*(1+G$6)/($B13-G$6)/(1+$B13)^('DCF Model'!C19+4)-'DCF Model'!C16)*1000000/'DCF Model'!C15,0),"") | H13: =IFERROR(ROUND(('DCF Model'!C45/(1+$B13)^('DCF Model'!C19+0)+'DCF Model'!D45/(1+$B13)^('DCF Model'!C19+1)+'DCF Model'!E45/(1+$B13)^('DCF Model'!C19+2)+'DCF Model'!F45/(1+$B13)^('DCF Model'!C19+3)+'DCF Model'!G45/(1+$B13)^('DCF Model'!C19+4)+'DCF Model'!G45*(1+H$6)/($B13-H$6)/(1+$B13)^('DCF Model'!C19+4)-'DCF Model'!C16)*1000000/'DCF Model'!C15,0),"") | I13: =IFERROR(ROUND(('DCF Model'!C45/(1+$B13)^('DCF Model'!C19+0)+'DCF Model'!D45/(1+$B13)^('DCF Model'!C19+1)+'DCF Model'!E45/(1+$B13)^('DCF Model'!C19+2)+'DCF Model'!F45/(1+$B13)^('DCF Model'!C19+3)+'DCF Model'!G45/(1+$B13)^('DCF Model'!C19+4)+'DCF Model'!G45*(1+I$6)/($B13-I$6)/(1+$B13)^('DCF Model'!C19+4)-'DCF Model'!C16)*1000000/'DCF Model'!C15,0),"")
B16: Table 2: WACC vs Exit Multiple (Exit Multiple - Implied Share Price, JPY)
B17: WACC \ Exit Multiple | C17: =$I$3-3.0 | D17: =$I$3-2.0 | E17: =$I$3-1.0 | F17: =$I$3 | G17: =$I$3+1.0 | H17: =$I$3+2.0 | I17: =$I$3+3.0
B18: =$C$3-0.015 | C18: =IFERROR(ROUND(('DCF Model'!C45/(1+$B18)^('DCF Model'!C19+0)+'DCF Model'!D45/(1+$B18)^('DCF Model'!C19+1)+'DCF Model'!E45/(1+$B18)^('DCF Model'!C19+2)+'DCF Model'!F45/(1+$B18)^('DCF Model'!C19+3)+'DCF Model'!G45/(1+$B18)^('DCF Model'!C19+4)+('DCF Model'!G39+'DCF Model'!G42)*C$17/(1+$B18)^('DCF Model'!C19+4)-'DCF Model'!C16)*1000000/'DCF Model'!C15,0),"") | D18: =IFERROR(ROUND(('DCF Model'!C45/(1+$B18)^('DCF Model'!C19+0)+'DCF Model'!D45/(1+$B18)^('DCF Model'!C19+1)+'DCF Model'!E45/(1+$B18)^('DCF Model'!C19+2)+'DCF Model'!F45/(1+$B18)^('DCF Model'!C19+3)+'DCF Model'!G45/(1+$B18)^('DCF Model'!C19+4)+('DCF Model'!G39+'DCF Model'!G42)*D$17/(1+$B18)^('DCF Model'!C19+4)-'DCF Model'!C16)*1000000/'DCF Model'!C15,0),"") | E18: =IFERROR(ROUND(('DCF Model'!C45/(1+$B18)^('DCF Model'!C19+0)+'DCF Model'!D45/(1+$B18)^('DCF Model'!C19+1)+'DCF Model'!E45/(1+$B18)^('DCF Model'!C19+2)+'DCF Model'!F45/(1+$B18)^('DCF Model'!C19+3)+'DCF Model'!G45/(1+$B18)^('DCF Model'!C19+4)+('DCF Model'!G39+'DCF Model'!G42)*E$17/(1+$B18)^('DCF Model'!C19+4)-'DCF Model'!C16)*1000000/'DCF Model'!C15,0),"") | F18: =IFERROR(ROUND(('DCF Model'!C45/(1+$B18)^('DCF Model'!C19+0)+'DCF Model'!D45/(1+$B18)^('DCF Model'!C19+1)+'DCF Model'!E45/(1+$B18)^('DCF Model'!C19+2)+'DCF Model'!F45/(1+$B18)^('DCF Model'!C19+3)+'DCF Model'!G45/(1+$B18)^('DCF Model'!C19+4)+('DCF Model'!G39+'DCF Model'!G42)*F$17/(1+$B18)^('DCF Model'!C19+4)-'DCF Model'!C16)*1000000/'DCF Model'!C15,0),"") | G18: =IFERROR(ROUND(('DCF Model'!C45/(1+$B18)^('DCF Model'!C19+0)+'DCF Model'!D45/(1+$B18)^('DCF Model'!C19+1)+'DCF Model'!E45/(1+$B18)^('DCF Model'!C19+2)+'DCF Model'!F45/(1+$B18)^('DCF Model'!C19+3)+'DCF Model'!G45/(1+$B18)^('DCF Model'!C19+4)+('DCF Model'!G39+'DCF Model'!G42)*G$17/(1+$B18)^('DCF Model'!C19+4)-'DCF Model'!C16)*1000000/'DCF Model'!C15,0),"") | H18: =IFERROR(ROUND(('DCF Model'!C45/(1+$B18)^('DCF Model'!C19+0)+'DCF Model'!D45/(1+$B18)^('DCF Model'!C19+1)+'DCF Model'!E45/(1+$B18)^('DCF Model'!C19+2)+'DCF Model'!F45/(1+$B18)^('DCF Model'!C19+3)+'DCF Model'!G45/(1+$B18)^('DCF Model'!C19+4)+('DCF Model'!G39+'DCF Model'!G42)*H$17/(1+$B18)^('DCF Model'!C19+4)-'DCF Model'!C16)*1000000/'DCF Model'!C15,0),"") | I18: =IFERROR(ROUND(('DCF Model'!C45/(1+$B18)^('DCF Model'!C19+0)+'DCF Model'!D45/(1+$B18)^('DCF Model'!C19+1)+'DCF Model'!E45/(1+$B18)^('DCF Model'!C19+2)+'DCF Model'!F45/(1+$B18)^('DCF Model'!C19+3)+'DCF Model'!G45/(1+$B18)^('DCF Model'!C19+4)+('DCF Model'!G39+'DCF Model'!G42)*I$17/(1+$B18)^('DCF Model'!C19+4)-'DCF Model'!C16)*1000000/'DCF Model'!C15,0),"")
B19: =$C$3-0.01 | C19: =IFERROR(ROUND(('DCF Model'!C45/(1+$B19)^('DCF Model'!C19+0)+'DCF Model'!D45/(1+$B19)^('DCF Model'!C19+1)+'DCF Model'!E45/(1+$B19)^('DCF Model'!C19+2)+'DCF Model'!F45/(1+$B19)^('DCF Model'!C19+3)+'DCF Model'!G45/(1+$B19)^('DCF Model'!C19+4)+('DCF Model'!G39+'DCF Model'!G42)*C$17/(1+$B19)^('DCF Model'!C19+4)-'DCF Model'!C16)*1000000/'DCF Model'!C15,0),"") | D19: =IFERROR(ROUND(('DCF Model'!C45/(1+$B19)^('DCF Model'!C19+0)+'DCF Model'!D45/(1+$B19)^('DCF Model'!C19+1)+'DCF Model'!E45/(1+$B19)^('DCF Model'!C19+2)+'DCF Model'!F45/(1+$B19)^('DCF Model'!C19+3)+'DCF Model'!G45/(1+$B19)^('DCF Model'!C19+4)+('DCF Model'!G39+'DCF Model'!G42)*D$17/(1+$B19)^('DCF Model'!C19+4)-'DCF Model'!C16)*1000000/'DCF Model'!C15,0),"") | E19: =IFERROR(ROUND(('DCF Model'!C45/(1+$B19)^('DCF Model'!C19+0)+'DCF Model'!D45/(1+$B19)^('DCF Model'!C19+1)+'DCF Model'!E45/(1+$B19)^('DCF Model'!C19+2)+'DCF Model'!F45/(1+$B19)^('DCF Model'!C19+3)+'DCF Model'!G45/(1+$B19)^('DCF Model'!C19+4)+('DCF Model'!G39+'DCF Model'!G42)*E$17/(1+$B19)^('DCF Model'!C19+4)-'DCF Model'!C16)*1000000/'DCF Model'!C15,0),"") | F19: =IFERROR(ROUND(('DCF Model'!C45/(1+$B19)^('DCF Model'!C19+0)+'DCF Model'!D45/(1+$B19)^('DCF Model'!C19+1)+'DCF Model'!E45/(1+$B19)^('DCF Model'!C19+2)+'DCF Model'!F45/(1+$B19)^('DCF Model'!C19+3)+'DCF Model'!G45/(1+$B19)^('DCF Model'!C19+4)+('DCF Model'!G39+'DCF Model'!G42)*F$17/(1+$B19)^('DCF Model'!C19+4)-'DCF Model'!C16)*1000000/'DCF Model'!C15,0),"") | G19: =IFERROR(ROUND(('DCF Model'!C45/(1+$B19)^('DCF Model'!C19+0)+'DCF Model'!D45/(1+$B19)^('DCF Model'!C19+1)+'DCF Model'!E45/(1+$B19)^('DCF Model'!C19+2)+'DCF Model'!F45/(1+$B19)^('DCF Model'!C19+3)+'DCF Model'!G45/(1+$B19)^('DCF Model'!C19+4)+('DCF Model'!G39+'DCF Model'!G42)*G$17/(1+$B19)^('DCF Model'!C19+4)-'DCF Model'!C16)*1000000/'DCF Model'!C15,0),"") | H19: =IFERROR(ROUND(('DCF Model'!C45/(1+$B19)^('DCF Model'!C19+0)+'DCF Model'!D45/(1+$B19)^('DCF Model'!C19+1)+'DCF Model'!E45/(1+$B19)^('DCF Model'!C19+2)+'DCF Model'!F45/(1+$B19)^('DCF Model'!C19+3)+'DCF Model'!G45/(1+$B19)^('DCF Model'!C19+4)+('DCF Model'!G39+'DCF Model'!G42)*H$17/(1+$B19)^('DCF Model'!C19+4)-'DCF Model'!C16)*1000000/'DCF Model'!C15,0),"") | I19: =IFERROR(ROUND(('DCF Model'!C45/(1+$B19)^('DCF Model'!C19+0)+'DCF Model'!D45/(1+$B19)^('DCF Model'!C19+1)+'DCF Model'!E45/(1+$B19)^('DCF Model'!C19+2)+'DCF Model'!F45/(1+$B19)^('DCF Model'!C19+3)+'DCF Model'!G45/(1+$B19)^('DCF Model'!C19+4)+('DCF Model'!G39+'DCF Model'!G42)*I$17/(1+$B19)^('DCF Model'!C19+4)-'DCF Model'!C16)*1000000/'DCF Model'!C15,0),"")
B20: =$C$3-0.005 | C20: =IFERROR(ROUND(('DCF Model'!C45/(1+$B20)^('DCF Model'!C19+0)+'DCF Model'!D45/(1+$B20)^('DCF Model'!C19+1)+'DCF Model'!E45/(1+$B20)^('DCF Model'!C19+2)+'DCF Model'!F45/(1+$B20)^('DCF Model'!C19+3)+'DCF Model'!G45/(1+$B20)^('DCF Model'!C19+4)+('DCF Model'!G39+'DCF Model'!G42)*C$17/(1+$B20)^('DCF Model'!C19+4)-'DCF Model'!C16)*1000000/'DCF Model'!C15,0),"") | D20: =IFERROR(ROUND(('DCF Model'!C45/(1+$B20)^('DCF Model'!C19+0)+'DCF Model'!D45/(1+$B20)^('DCF Model'!C19+1)+'DCF Model'!E45/(1+$B20)^('DCF Model'!C19+2)+'DCF Model'!F45/(1+$B20)^('DCF Model'!C19+3)+'DCF Model'!G45/(1+$B20)^('DCF Model'!C19+4)+('DCF Model'!G39+'DCF Model'!G42)*D$17/(1+$B20)^('DCF Model'!C19+4)-'DCF Model'!C16)*1000000/'DCF Model'!C15,0),"") | E20: =IFERROR(ROUND(('DCF Model'!C45/(1+$B20)^('DCF Model'!C19+0)+'DCF Model'!D45/(1+$B20)^('DCF Model'!C19+1)+'DCF Model'!E45/(1+$B20)^('DCF Model'!C19+2)+'DCF Model'!F45/(1+$B20)^('DCF Model'!C19+3)+'DCF Model'!G45/(1+$B20)^('DCF Model'!C19+4)+('DCF Model'!G39+'DCF Model'!G42)*E$17/(1+$B20)^('DCF Model'!C19+4)-'DCF Model'!C16)*1000000/'DCF Model'!C15,0),"") | F20: =IFERROR(ROUND(('DCF Model'!C45/(1+$B20)^('DCF Model'!C19+0)+'DCF Model'!D45/(1+$B20)^('DCF Model'!C19+1)+'DCF Model'!E45/(1+$B20)^('DCF Model'!C19+2)+'DCF Model'!F45/(1+$B20)^('DCF Model'!C19+3)+'DCF Model'!G45/(1+$B20)^('DCF Model'!C19+4)+('DCF Model'!G39+'DCF Model'!G42)*F$17/(1+$B20)^('DCF Model'!C19+4)-'DCF Model'!C16)*1000000/'DCF Model'!C15,0),"") | G20: =IFERROR(ROUND(('DCF Model'!C45/(1+$B20)^('DCF Model'!C19+0)+'DCF Model'!D45/(1+$B20)^('DCF Model'!C19+1)+'DCF Model'!E45/(1+$B20)^('DCF Model'!C19+2)+'DCF Model'!F45/(1+$B20)^('DCF Model'!C19+3)+'DCF Model'!G45/(1+$B20)^('DCF Model'!C19+4)+('DCF Model'!G39+'DCF Model'!G42)*G$17/(1+$B20)^('DCF Model'!C19+4)-'DCF Model'!C16)*1000000/'DCF Model'!C15,0),"") | H20: =IFERROR(ROUND(('DCF Model'!C45/(1+$B20)^('DCF Model'!C19+0)+'DCF Model'!D45/(1+$B20)^('DCF Model'!C19+1)+'DCF Model'!E45/(1+$B20)^('DCF Model'!C19+2)+'DCF Model'!F45/(1+$B20)^('DCF Model'!C19+3)+'DCF Model'!G45/(1+$B20)^('DCF Model'!C19+4)+('DCF Model'!G39+'DCF Model'!G42)*H$17/(1+$B20)^('DCF Model'!C19+4)-'DCF Model'!C16)*1000000/'DCF Model'!C15,0),"") | I20: =IFERROR(ROUND(('DCF Model'!C45/(1+$B20)^('DCF Model'!C19+0)+'DCF Model'!D45/(1+$B20)^('DCF Model'!C19+1)+'DCF Model'!E45/(1+$B20)^('DCF Model'!C19+2)+'DCF Model'!F45/(1+$B20)^('DCF Model'!C19+3)+'DCF Model'!G45/(1+$B20)^('DCF Model'!C19+4)+('DCF Model'!G39+'DCF Model'!G42)*I$17/(1+$B20)^('DCF Model'!C19+4)-'DCF Model'!C16)*1000000/'DCF Model'!C15,0),"")
B21: =$C$3 | C21: =IFERROR(ROUND(('DCF Model'!C45/(1+$B21)^('DCF Model'!C19+0)+'DCF Model'!D45/(1+$B21)^('DCF Model'!C19+1)+'DCF Model'!E45/(1+$B21)^('DCF Model'!C19+2)+'DCF Model'!F45/(1+$B21)^('DCF Model'!C19+3)+'DCF Model'!G45/(1+$B21)^('DCF Model'!C19+4)+('DCF Model'!G39+'DCF Model'!G42)*C$17/(1+$B21)^('DCF Model'!C19+4)-'DCF Model'!C16)*1000000/'DCF Model'!C15,0),"") | D21: =IFERROR(ROUND(('DCF Model'!C45/(1+$B21)^('DCF Model'!C19+0)+'DCF Model'!D45/(1+$B21)^('DCF Model'!C19+1)+'DCF Model'!E45/(1+$B21)^('DCF Model'!C19+2)+'DCF Model'!F45/(1+$B21)^('DCF Model'!C19+3)+'DCF Model'!G45/(1+$B21)^('DCF Model'!C19+4)+('DCF Model'!G39+'DCF Model'!G42)*D$17/(1+$B21)^('DCF Model'!C19+4)-'DCF Model'!C16)*1000000/'DCF Model'!C15,0),"") | E21: =IFERROR(ROUND(('DCF Model'!C45/(1+$B21)^('DCF Model'!C19+0)+'DCF Model'!D45/(1+$B21)^('DCF Model'!C19+1)+'DCF Model'!E45/(1+$B21)^('DCF Model'!C19+2)+'DCF Model'!F45/(1+$B21)^('DCF Model'!C19+3)+'DCF Model'!G45/(1+$B21)^('DCF Model'!C19+4)+('DCF Model'!G39+'DCF Model'!G42)*E$17/(1+$B21)^('DCF Model'!C19+4)-'DCF Model'!C16)*1000000/'DCF Model'!C15,0),"") | F21: =IFERROR(ROUND(('DCF Model'!C45/(1+$B21)^('DCF Model'!C19+0)+'DCF Model'!D45/(1+$B21)^('DCF Model'!C19+1)+'DCF Model'!E45/(1+$B21)^('DCF Model'!C19+2)+'DCF Model'!F45/(1+$B21)^('DCF Model'!C19+3)+'DCF Model'!G45/(1+$B21)^('DCF Model'!C19+4)+('DCF Model'!G39+'DCF Model'!G42)*F$17/(1+$B21)^('DCF Model'!C19+4)-'DCF Model'!C16)*1000000/'DCF Model'!C15,0),"") | G21: =IFERROR(ROUND(('DCF Model'!C45/(1+$B21)^('DCF Model'!C19+0)+'DCF Model'!D45/(1+$B21)^('DCF Model'!C19+1)+'DCF Model'!E45/(1+$B21)^('DCF Model'!C19+2)+'DCF Model'!F45/(1+$B21)^('DCF Model'!C19+3)+'DCF Model'!G45/(1+$B21)^('DCF Model'!C19+4)+('DCF Model'!G39+'DCF Model'!G42)*G$17/(1+$B21)^('DCF Model'!C19+4)-'DCF Model'!C16)*1000000/'DCF Model'!C15,0),"") | H21: =IFERROR(ROUND(('DCF Model'!C45/(1+$B21)^('DCF Model'!C19+0)+'DCF Model'!D45/(1+$B21)^('DCF Model'!C19+1)+'DCF Model'!E45/(1+$B21)^('DCF Model'!C19+2)+'DCF Model'!F45/(1+$B21)^('DCF Model'!C19+3)+'DCF Model'!G45/(1+$B21)^('DCF Model'!C19+4)+('DCF Model'!G39+'DCF Model'!G42)*H$17/(1+$B21)^('DCF Model'!C19+4)-'DCF Model'!C16)*1000000/'DCF Model'!C15,0),"") | I21: =IFERROR(ROUND(('DCF Model'!C45/(1+$B21)^('DCF Model'!C19+0)+'DCF Model'!D45/(1+$B21)^('DCF Model'!C19+1)+'DCF Model'!E45/(1+$B21)^('DCF Model'!C19+2)+'DCF Model'!F45/(1+$B21)^('DCF Model'!C19+3)+'DCF Model'!G45/(1+$B21)^('DCF Model'!C19+4)+('DCF Model'!G39+'DCF Model'!G42)*I$17/(1+$B21)^('DCF Model'!C19+4)-'DCF Model'!C16)*1000000/'DCF Model'!C15,0),"")
B22: =$C$3+0.005 | C22: =IFERROR(ROUND(('DCF Model'!C45/(1+$B22)^('DCF Model'!C19+0)+'DCF Model'!D45/(1+$B22)^('DCF Model'!C19+1)+'DCF Model'!E45/(1+$B22)^('DCF Model'!C19+2)+'DCF Model'!F45/(1+$B22)^('DCF Model'!C19+3)+'DCF Model'!G45/(1+$B22)^('DCF Model'!C19+4)+('DCF Model'!G39+'DCF Model'!G42)*C$17/(1+$B22)^('DCF Model'!C19+4)-'DCF Model'!C16)*1000000/'DCF Model'!C15,0),"") | D22: =IFERROR(ROUND(('DCF Model'!C45/(1+$B22)^('DCF Model'!C19+0)+'DCF Model'!D45/(1+$B22)^('DCF Model'!C19+1)+'DCF Model'!E45/(1+$B22)^('DCF Model'!C19+2)+'DCF Model'!F45/(1+$B22)^('DCF Model'!C19+3)+'DCF Model'!G45/(1+$B22)^('DCF Model'!C19+4)+('DCF Model'!G39+'DCF Model'!G42)*D$17/(1+$B22)^('DCF Model'!C19+4)-'DCF Model'!C16)*1000000/'DCF Model'!C15,0),"") | E22: =IFERROR(ROUND(('DCF Model'!C45/(1+$B22)^('DCF Model'!C19+0)+'DCF Model'!D45/(1+$B22)^('DCF Model'!C19+1)+'DCF Model'!E45/(1+$B22)^('DCF Model'!C19+2)+'DCF Model'!F45/(1+$B22)^('DCF Model'!C19+3)+'DCF Model'!G45/(1+$B22)^('DCF Model'!C19+4)+('DCF Model'!G39+'DCF Model'!G42)*E$17/(1+$B22)^('DCF Model'!C19+4)-'DCF Model'!C16)*1000000/'DCF Model'!C15,0),"") | F22: =IFERROR(ROUND(('DCF Model'!C45/(1+$B22)^('DCF Model'!C19+0)+'DCF Model'!D45/(1+$B22)^('DCF Model'!C19+1)+'DCF Model'!E45/(1+$B22)^('DCF Model'!C19+2)+'DCF Model'!F45/(1+$B22)^('DCF Model'!C19+3)+'DCF Model'!G45/(1+$B22)^('DCF Model'!C19+4)+('DCF Model'!G39+'DCF Model'!G42)*F$17/(1+$B22)^('DCF Model'!C19+4)-'DCF Model'!C16)*1000000/'DCF Model'!C15,0),"") | G22: =IFERROR(ROUND(('DCF Model'!C45/(1+$B22)^('DCF Model'!C19+0)+'DCF Model'!D45/(1+$B22)^('DCF Model'!C19+1)+'DCF Model'!E45/(1+$B22)^('DCF Model'!C19+2)+'DCF Model'!F45/(1+$B22)^('DCF Model'!C19+3)+'DCF Model'!G45/(1+$B22)^('DCF Model'!C19+4)+('DCF Model'!G39+'DCF Model'!G42)*G$17/(1+$B22)^('DCF Model'!C19+4)-'DCF Model'!C16)*1000000/'DCF Model'!C15,0),"") | H22: =IFERROR(ROUND(('DCF Model'!C45/(1+$B22)^('DCF Model'!C19+0)+'DCF Model'!D45/(1+$B22)^('DCF Model'!C19+1)+'DCF Model'!E45/(1+$B22)^('DCF Model'!C19+2)+'DCF Model'!F45/(1+$B22)^('DCF Model'!C19+3)+'DCF Model'!G45/(1+$B22)^('DCF Model'!C19+4)+('DCF Model'!G39+'DCF Model'!G42)*H$17/(1+$B22)^('DCF Model'!C19+4)-'DCF Model'!C16)*1000000/'DCF Model'!C15,0),"") | I22: =IFERROR(ROUND(('DCF Model'!C45/(1+$B22)^('DCF Model'!C19+0)+'DCF Model'!D45/(1+$B22)^('DCF Model'!C19+1)+'DCF Model'!E45/(1+$B22)^('DCF Model'!C19+2)+'DCF Model'!F45/(1+$B22)^('DCF Model'!C19+3)+'DCF Model'!G45/(1+$B22)^('DCF Model'!C19+4)+('DCF Model'!G39+'DCF Model'!G42)*I$17/(1+$B22)^('DCF Model'!C19+4)-'DCF Model'!C16)*1000000/'DCF Model'!C15,0),"")
B23: =$C$3+0.01 | C23: =IFERROR(ROUND(('DCF Model'!C45/(1+$B23)^('DCF Model'!C19+0)+'DCF Model'!D45/(1+$B23)^('DCF Model'!C19+1)+'DCF Model'!E45/(1+$B23)^('DCF Model'!C19+2)+'DCF Model'!F45/(1+$B23)^('DCF Model'!C19+3)+'DCF Model'!G45/(1+$B23)^('DCF Model'!C19+4)+('DCF Model'!G39+'DCF Model'!G42)*C$17/(1+$B23)^('DCF Model'!C19+4)-'DCF Model'!C16)*1000000/'DCF Model'!C15,0),"") | D23: =IFERROR(ROUND(('DCF Model'!C45/(1+$B23)^('DCF Model'!C19+0)+'DCF Model'!D45/(1+$B23)^('DCF Model'!C19+1)+'DCF Model'!E45/(1+$B23)^('DCF Model'!C19+2)+'DCF Model'!F45/(1+$B23)^('DCF Model'!C19+3)+'DCF Model'!G45/(1+$B23)^('DCF Model'!C19+4)+('DCF Model'!G39+'DCF Model'!G42)*D$17/(1+$B23)^('DCF Model'!C19+4)-'DCF Model'!C16)*1000000/'DCF Model'!C15,0),"") | E23: =IFERROR(ROUND(('DCF Model'!C45/(1+$B23)^('DCF Model'!C19+0)+'DCF Model'!D45/(1+$B23)^('DCF Model'!C19+1)+'DCF Model'!E45/(1+$B23)^('DCF Model'!C19+2)+'DCF Model'!F45/(1+$B23)^('DCF Model'!C19+3)+'DCF Model'!G45/(1+$B23)^('DCF Model'!C19+4)+('DCF Model'!G39+'DCF Model'!G42)*E$17/(1+$B23)^('DCF Model'!C19+4)-'DCF Model'!C16)*1000000/'DCF Model'!C15,0),"") | F23: =IFERROR(ROUND(('DCF Model'!C45/(1+$B23)^('DCF Model'!C19+0)+'DCF Model'!D45/(1+$B23)^('DCF Model'!C19+1)+'DCF Model'!E45/(1+$B23)^('DCF Model'!C19+2)+'DCF Model'!F45/(1+$B23)^('DCF Model'!C19+3)+'DCF Model'!G45/(1+$B23)^('DCF Model'!C19+4)+('DCF Model'!G39+'DCF Model'!G42)*F$17/(1+$B23)^('DCF Model'!C19+4)-'DCF Model'!C16)*1000000/'DCF Model'!C15,0),"") | G23: =IFERROR(ROUND(('DCF Model'!C45/(1+$B23)^('DCF Model'!C19+0)+'DCF Model'!D45/(1+$B23)^('DCF Model'!C19+1)+'DCF Model'!E45/(1+$B23)^('DCF Model'!C19+2)+'DCF Model'!F45/(1+$B23)^('DCF Model'!C19+3)+'DCF Model'!G45/(1+$B23)^('DCF Model'!C19+4)+('DCF Model'!G39+'DCF Model'!G42)*G$17/(1+$B23)^('DCF Model'!C19+4)-'DCF Model'!C16)*1000000/'DCF Model'!C15,0),"") | H23: =IFERROR(ROUND(('DCF Model'!C45/(1+$B23)^('DCF Model'!C19+0)+'DCF Model'!D45/(1+$B23)^('DCF Model'!C19+1)+'DCF Model'!E45/(1+$B23)^('DCF Model'!C19+2)+'DCF Model'!F45/(1+$B23)^('DCF Model'!C19+3)+'DCF Model'!G45/(1+$B23)^('DCF Model'!C19+4)+('DCF Model'!G39+'DCF Model'!G42)*H$17/(1+$B23)^('DCF Model'!C19+4)-'DCF Model'!C16)*1000000/'DCF Model'!C15,0),"") | I23: =IFERROR(ROUND(('DCF Model'!C45/(1+$B23)^('DCF Model'!C19+0)+'DCF Model'!D45/(1+$B23)^('DCF Model'!C19+1)+'DCF Model'!E45/(1+$B23)^('DCF Model'!C19+2)+'DCF Model'!F45/(1+$B23)^('DCF Model'!C19+3)+'DCF Model'!G45/(1+$B23)^('DCF Model'!C19+4)+('DCF Model'!G39+'DCF Model'!G42)*I$17/(1+$B23)^('DCF Model'!C19+4)-'DCF Model'!C16)*1000000/'DCF Model'!C15,0),"")
B24: =$C$3+0.015 | C24: =IFERROR(ROUND(('DCF Model'!C45/(1+$B24)^('DCF Model'!C19+0)+'DCF Model'!D45/(1+$B24)^('DCF Model'!C19+1)+'DCF Model'!E45/(1+$B24)^('DCF Model'!C19+2)+'DCF Model'!F45/(1+$B24)^('DCF Model'!C19+3)+'DCF Model'!G45/(1+$B24)^('DCF Model'!C19+4)+('DCF Model'!G39+'DCF Model'!G42)*C$17/(1+$B24)^('DCF Model'!C19+4)-'DCF Model'!C16)*1000000/'DCF Model'!C15,0),"") | D24: =IFERROR(ROUND(('DCF Model'!C45/(1+$B24)^('DCF Model'!C19+0)+'DCF Model'!D45/(1+$B24)^('DCF Model'!C19+1)+'DCF Model'!E45/(1+$B24)^('DCF Model'!C19+2)+'DCF Model'!F45/(1+$B24)^('DCF Model'!C19+3)+'DCF Model'!G45/(1+$B24)^('DCF Model'!C19+4)+('DCF Model'!G39+'DCF Model'!G42)*D$17/(1+$B24)^('DCF Model'!C19+4)-'DCF Model'!C16)*1000000/'DCF Model'!C15,0),"") | E24: =IFERROR(ROUND(('DCF Model'!C45/(1+$B24)^('DCF Model'!C19+0)+'DCF Model'!D45/(1+$B24)^('DCF Model'!C19+1)+'DCF Model'!E45/(1+$B24)^('DCF Model'!C19+2)+'DCF Model'!F45/(1+$B24)^('DCF Model'!C19+3)+'DCF Model'!G45/(1+$B24)^('DCF Model'!C19+4)+('DCF Model'!G39+'DCF Model'!G42)*E$17/(1+$B24)^('DCF Model'!C19+4)-'DCF Model'!C16)*1000000/'DCF Model'!C15,0),"") | F24: =IFERROR(ROUND(('DCF Model'!C45/(1+$B24)^('DCF Model'!C19+0)+'DCF Model'!D45/(1+$B24)^('DCF Model'!C19+1)+'DCF Model'!E45/(1+$B24)^('DCF Model'!C19+2)+'DCF Model'!F45/(1+$B24)^('DCF Model'!C19+3)+'DCF Model'!G45/(1+$B24)^('DCF Model'!C19+4)+('DCF Model'!G39+'DCF Model'!G42)*F$17/(1+$B24)^('DCF Model'!C19+4)-'DCF Model'!C16)*1000000/'DCF Model'!C15,0),"") | G24: =IFERROR(ROUND(('DCF Model'!C45/(1+$B24)^('DCF Model'!C19+0)+'DCF Model'!D45/(1+$B24)^('DCF Model'!C19+1)+'DCF Model'!E45/(1+$B24)^('DCF Model'!C19+2)+'DCF Model'!F45/(1+$B24)^('DCF Model'!C19+3)+'DCF Model'!G45/(1+$B24)^('DCF Model'!C19+4)+('DCF Model'!G39+'DCF Model'!G42)*G$17/(1+$B24)^('DCF Model'!C19+4)-'DCF Model'!C16)*1000000/'DCF Model'!C15,0),"") | H24: =IFERROR(ROUND(('DCF Model'!C45/(1+$B24)^('DCF Model'!C19+0)+'DCF Model'!D45/(1+$B24)^('DCF Model'!C19+1)+'DCF Model'!E45/(1+$B24)^('DCF Model'!C19+2)+'DCF Model'!F45/(1+$B24)^('DCF Model'!C19+3)+'DCF Model'!G45/(1+$B24)^('DCF Model'!C19+4)+('DCF Model'!G39+'DCF Model'!G42)*H$17/(1+$B24)^('DCF Model'!C19+4)-'DCF Model'!C16)*1000000/'DCF Model'!C15,0),"") | I24: =IFERROR(ROUND(('DCF Model'!C45/(1+$B24)^('DCF Model'!C19+0)+'DCF Model'!D45/(1+$B24)^('DCF Model'!C19+1)+'DCF Model'!E45/(1+$B24)^('DCF Model'!C19+2)+'DCF Model'!F45/(1+$B24)^('DCF Model'!C19+3)+'DCF Model'!G45/(1+$B24)^('DCF Model'!C19+4)+('DCF Model'!G39+'DCF Model'!G42)*I$17/(1+$B24)^('DCF Model'!C19+4)-'DCF Model'!C16)*1000000/'DCF Model'!C15,0),"")
B26: All values dynamically linked to DCF Model. Headers auto-center on current WACC / Terminal g / Exit Multiple.

Sheet Segment Analysis
B2: Segment Analysis - 株式会社コア
C4: FY2024 | D4: FY2025 | E4: FY2026 | F4: FY2026(E) | G4: FY2027(E) | H4: FY2028(E) | I4: FY2029(E) | J4: FY2030(E)
B5: Future Society Solutions (未来社会ソリューション)
B6: Revenue | C6: — | D6: 4771 | E6: 4570 | F6: =E6*(1+CHOOSE('DCF Model'!$D$27,F34,F35,F36,F37,F38)) | G6: =F6*(1+CHOOSE('DCF Model'!$D$27,G34,G35,G36,G37,G38)) | H6: =G6*(1+CHOOSE('DCF Model'!$D$27,H34,H35,H36,H37,H38)) | I6: =H6*(1+CHOOSE('DCF Model'!$D$27,I34,I35,I36,I37,I38)) | J6: =I6*(1+CHOOSE('DCF Model'!$D$27,J34,J35,J36,J37,J38))
B7: Operating Profit | C7: — | D7: 675 | E7: 461 | F7: =F6*CHOOSE('DCF Model'!$D$27,F41,F42,F43,F44,F45) | G7: =G6*CHOOSE('DCF Model'!$D$27,G41,G42,G43,G44,G45) | H7: =H6*CHOOSE('DCF Model'!$D$27,H41,H42,H43,H44,H45) | I7: =I6*CHOOSE('DCF Model'!$D$27,I41,I42,I43,I44,I45) | J7: =J6*CHOOSE('DCF Model'!$D$27,J41,J42,J43,J44,J45)
B8: OP Margin | C8: — | D8: =D7/D6 | E8: =E7/E6 | F8: =CHOOSE('DCF Model'!$D$27,F41,F42,F43,F44,F45) | G8: =CHOOSE('DCF Model'!$D$27,G41,G42,G43,G44,G45) | H8: =CHOOSE('DCF Model'!$D$27,H41,H42,H43,H44,H45) | I8: =CHOOSE('DCF Model'!$D$27,I41,I42,I43,I44,I45) | J8: =CHOOSE('DCF Model'!$D$27,J41,J42,J43,J44,J45)
B10: Industrial Technology Solutions (産業技術ソリューション)
B11: Revenue | C11: — | D11: 10546 | E11: 12035 | F11: =E11*(1+CHOOSE('DCF Model'!$D$27,F48,F49,F50,F51,F52)) | G11: =F11*(1+CHOOSE('DCF Model'!$D$27,G48,G49,G50,G51,G52)) | H11: =G11*(1+CHOOSE('DCF Model'!$D$27,H48,H49,H50,H51,H52)) | I11: =H11*(1+CHOOSE('DCF Model'!$D$27,I48,I49,I50,I51,I52)) | J11: =I11*(1+CHOOSE('DCF Model'!$D$27,J48,J49,J50,J51,J52))
B12: Operating Profit | C12: — | D12: 1641 | E12: 1884 | F12: =F11*CHOOSE('DCF Model'!$D$27,F55,F56,F57,F58,F59) | G12: =G11*CHOOSE('DCF Model'!$D$27,G55,G56,G57,G58,G59) | H12: =H11*CHOOSE('DCF Model'!$D$27,H55,H56,H57,H58,H59) | I12: =I11*CHOOSE('DCF Model'!$D$27,I55,I56,I57,I58,I59) | J12: =J11*CHOOSE('DCF Model'!$D$27,J55,J56,J57,J58,J59)
B13: OP Margin | C13: — | D13: =D12/D11 | E13: =E12/E11 | F13: =CHOOSE('DCF Model'!$D$27,F55,F56,F57,F58,F59) | G13: =CHOOSE('DCF Model'!$D$27,G55,G56,G57,G58,G59) | H13: =CHOOSE('DCF Model'!$D$27,H55,H56,H57,H58,H59) | I13: =CHOOSE('DCF Model'!$D$27,I55,I56,I57,I58,I59) | J13: =CHOOSE('DCF Model'!$D$27,J55,J56,J57,J58,J59)
B15: Customer Business Integration (顧客業務インテグレーション)
B16: Revenue | C16: — | D16: 8680 | E16: 7993 | F16: =E16*(1+CHOOSE('DCF Model'!$D$27,F62,F63,F64,F65,F66)) | G16: =F16*(1+CHOOSE('DCF Model'!$D$27,G62,G63,G64,G65,G66)) | H16: =G16*(1+CHOOSE('DCF Model'!$D$27,H62,H63,H64,H65,H66)) | I16: =H16*(1+CHOOSE('DCF Model'!$D$27,I62,I63,I64,I65,I66)) | J16: =I16*(1+CHOOSE('DCF Model'!$D$27,J62,J63,J64,J65,J66))
B17: Operating Profit | C17: — | D17: 823 | E17: 829 | F17: =F16*CHOOSE('DCF Model'!$D$27,F69,F70,F71,F72,F73) | G17: =G16*CHOOSE('DCF Model'!$D$27,G69,G70,G71,G72,G73) | H17: =H16*CHOOSE('DCF Model'!$D$27,H69,H70,H71,H72,H73) | I17: =I16*CHOOSE('DCF Model'!$D$27,I69,I70,I71,I72,I73) | J17: =J16*CHOOSE('DCF Model'!$D$27,J69,J70,J71,J72,J73)
B18: OP Margin | C18: — | D18: =D17/D16 | E18: =E17/E16 | F18: =CHOOSE('DCF Model'!$D$27,F69,F70,F71,F72,F73) | G18: =CHOOSE('DCF Model'!$D$27,G69,G70,G71,G72,G73) | H18: =CHOOSE('DCF Model'!$D$27,H69,H70,H71,H72,H73) | I18: =CHOOSE('DCF Model'!$D$27,I69,I70,I71,I72,I73) | J18: =CHOOSE('DCF Model'!$D$27,J69,J70,J71,J72,J73)
B20: Consolidated Total
B21: Total Revenue | C21: =C6+C11+C16 | D21: =D6+D11+D16 | E21: =E6+E11+E16 | F21: =F6+F11+F16 | G21: =G6+G11+G16 | H21: =H6+H11+H16 | I21: =I6+I11+I16 | J21: =J6+J11+J16
B22: Total Operating Profit | C22: =C7+C12+C17 | D22: =D7+D12+D17 | E22: =E7+E12+E17 | F22: =F7+F12+F17 | G22: =G7+G12+G17 | H22: =H7+H12+H17 | I22: =I7+I12+I17 | J22: =J7+J12+J17
B23: Total OP Margin | C23: =IFERROR(C22/C21,"—") | D23: =IFERROR(D22/D21,"—") | E23: =IFERROR(E22/E21,"—") | F23: =IFERROR(F22/F21,"—") | G23: =IFERROR(G22/G21,"—") | H23: =IFERROR(H22/H21,"—") | I23: =IFERROR(I22/I21,"—") | J23: =IFERROR(J22/J21,"—")
B25: Reconciliation vs DCF Model
B26: DCF Model Revenue | F26: ='DCF Model'!C33 | G26: ='DCF Model'!D33 | H26: ='DCF Model'!E33 | I26: ='DCF Model'!F33 | J26: ='DCF Model'!G33
B27: Segment Total Revenue | F27: =F21 | G27: =G21 | H27: =H21 | I27: =I21 | J27: =J21
B28: Difference | F28: =F27-F26 | G28: =G27-G26 | H28: =H27-H26 | I28: =I27-I26 | J28: =J27-J26
B31: Segment Scenario Input Matrix
F32: FY2026(E) | G32: FY2027(E) | H32: FY2028(E) | I32: FY2029(E) | J32: FY2030(E)
B33: Future Society Solutions - Revenue Growth (YoY)
B34: Base | F34: 0.105 | G34: 0.1287 | H34: 0.0877 | I34: 0.0806 | J34: 0.0448
B35: Upside | F35: 0.105 | G35: 0.1287 | H35: 0.0877 | I35: 0.0806 | J35: 0.0448
B36: Management | F36: 0.105 | G36: 0.1287 | H36: 0.0877 | I36: 0.0806 | J36: 0.0448
B37: Downside 1 | F37: 0.105 | G37: 0.1287 | H37: 0.0877 | I37: 0.0806 | J37: 0.0448
B38: Downside 2 | F38: 0.105 | G38: 0.1287 | H38: 0.0877 | I38: 0.0806 | J38: 0.0448
B40: Future Society Solutions - OP Margin
B41: Base | F41: 0.149 | G41: 0.14 | H41: 0.145 | I41: 0.15 | J41: 0.152
B42: Upside | F42: 0.149 | G42: 0.14 | H42: 0.145 | I42: 0.15 | J42: 0.152
B43: Management | F43: 0.149 | G43: 0.14 | H43: 0.145 | I43: 0.15 | J43: 0.152
B44: Downside 1 | F44: 0.149 | G44: 0.14 | H44: 0.145 | I44: 0.15 | J44: 0.152
B45: Downside 2 | F45: 0.149 | G45: 0.14 | H45: 0.145 | I45: 0.15 | J45: 0.152
B47: Industrial Technology Solutions - Revenue Growth (YoY)
B48: Base | F48: 0.1591 | G48: 0.147 | H48: 0.125 | I48: 0.1111 | J48: 0.05
B49: Upside | F49: 0.1591 | G49: 0.147 | H49: 0.125 | I49: 0.1111 | J49: 0.05
B50: Management | F50: 0.1591 | G50: 0.147 | H50: 0.125 | I50: 0.1111 | J50: 0.05
...

Sheet Driver Analysis
B2: Driver Analysis - 株式会社コア
C4: FY2024 | D4: FY2025 | E4: FY2026 | F4: FY2026(E) | G4: FY2027(E) | H4: FY2028(E) | I4: FY2029(E) | J4: FY2030(E)
B5: Future Society Solutions (未来社会ソリューション) [manual]
B6: Revenue (Direct Input) | C6: — | D6: 4771 | E6: 4570 | F6: 5050 | G6: 5700 | H6: 6200 | I6: 6700 | J6: 7000
B7: YoY Growth | C7: — | D7: =IFERROR((D6-C6)/C6,"—") | E7: =IFERROR((E6-D6)/D6,"—") | F7: =IFERROR((F6-E6)/E6,"—") | G7: =IFERROR((G6-F6)/F6,"—") | H7: =IFERROR((H6-G6)/G6,"—") | I7: =IFERROR((I6-H6)/H6,"—") | J7: =IFERROR((J6-I6)/I6,"—")
B9: Industrial Technology Solutions (産業技術ソリューション) [manmonth]
B10: Headcount | C10: — | D10: — | E10: — | F10: 820 | G10: 850 | H10: 880 | I10: 910 | J10: 940
B11: × Utilization | C11: — | D11: — | E11: — | F11: 0.92 | G11: 0.93 | H11: 0.93 | I11: 0.94 | J11: 0.94
B12: × Unit Price (JPY mn/month) | C12: — | D12: — | E12: — | F12: 0.7 | G12: 0.72 | H12: 0.74 | I12: 0.76 | J12: 0.78
B13: Layer 1 Revenue | C13: — | D13: — | E13: — | F13: =F10*F11*F12*12 | G13: =G10*G11*G12*12 | H13: =H10*H11*H12*12 | I13: =I10*I11*I12*12 | J13: =J10*J11*J12*12
B14: + Layer 2 (Solution) Revenue | C14: — | D14: — | E14: 6058 | F14: 7400 | G14: 9238 | H14: 11000 | I14: 13000 | J14: 14500
B15: Segment Revenue | C15: — | D15: 10546 | E15: 12035 | F15: =F13+F14 | G15: =G13+G14 | H15: =H13+H14 | I15: =I13+I14 | J15: =J13+J14
B16: Layer 2 Mix % | C16: =IFERROR(C14/C15,"—") | D16: =IFERROR(D14/D15,"—") | E16: =IFERROR(E14/E15,"—") | F16: =IFERROR(F14/F15,"—") | G16: =IFERROR(G14/G15,"—") | H16: =IFERROR(H14/H15,"—") | I16: =IFERROR(I14/I15,"—") | J16: =IFERROR(J14/J15,"—")
B18: Customer Business Integration (顧客業務インテグレーション) [manual]
B19: Revenue (Direct Input) | C19: — | D19: 8680 | E19: 7993 | F19: 8000 | G19: 8100 | H19: 8200 | I19: 8300 | J19: 8400
B20: YoY Growth | C20: — | D20: =IFERROR((D19-C19)/C19,"—") | E20: =IFERROR((E19-D19)/D19,"—") | F20: =IFERROR((F19-E19)/E19,"—") | G20: =IFERROR((G19-F19)/F19,"—") | H20: =IFERROR((H19-G19)/G19,"—") | I20: =IFERROR((I19-H19)/H19,"—") | J20: =IFERROR((J19-I19)/I19,"—")
