Workbook

Sheet Executive Summary
B1: DISCLAIMER: This is a sample analysis for demonstration purposes only. It does not constitute investment advice.
B3: 株式会社ＩＨＩ (7013.T)
B4: Equity Research Report
B6: Company | C6: 株式会社ＩＨＩ
B7: Ticker | C7: 7013.T (TSE)
B8: Sector | C8: Heavy Industry / Machinery
B9: Current Price | C9: 3391
B10: Target Price (Mid) | C10: =ROUND(AVERAGE(C16:C19),0)
B11: Recommendation | C11: =IF(C12>0.15,"BUY",IF(C12>0.05,"HOLD","SELL"))
B12: Upside / Downside | C12: =(C10-C9)/C9
B14: Valuation Summary
B15: Methodology | C15: Implied Value (JPY) | D15: vs Current Price
B16: DCF - Perpetuity Growth | C16: ='DCF Model'!C55 | D16: =(C16-C9)/C9
B17: DCF - Exit Multiple | C17: ='DCF Model'!C64 | D17: =(C17-C9)/C9
B18: Comps - EV/EBITDA Median | C18: ='Comps Analysis'!C27 | D18: =(C18-C9)/C9
B19: Comps - PER Median | C19: ='Comps Analysis'!C28 | D19: =(C19-C9)/C9
B21: Integrated Valuation Range | C21: =MIN(C16:C19)&" - "&MAX(C16:C19)
B23: Key Investment Thesis
B24: 1. Aero Engine: V2500/PW1100G aftermarket revenue accelerating; installed base of 5,000+ engines drives recurring high-margin MRO demand
B25: 2. Defense upside: Japan defense budget doubling (1%→2% GDP by FY2027); IHI is sole supplier of F110/F135 engine MRO for JASDF F-15/F-35 fleet
B26: 3. Margin recovery: FY2025 OPM 8.8% recovering from FY2024 trough (-9.2%); structural improvement from aero engine mix shift and turbocharger restructuring
B28: Key Risks
B29: 1. Aero engine concentration: 70%+ of OP from single segment; Boeing/Airbus delivery delays reduce new engine shipments
B30: 2. Civil aero engine PBH contracts: long-term risk-sharing partnerships expose IHI to OEM production cycle downturns
B31: 3. Legacy segments (Social Infrastructure, Industrial Systems) remain low-margin; turnaround execution risk

Sheet Financial Statements
B2: 株式会社ＩＨＩ - Historical Financials (JPY mn)
C4: FY2020 | D4: FY2021 | E4: FY2022 | F4: FY2023 | G4: FY2024 | H4: FY2025
B5: Income Statement
B6: Revenue | C6: 1263178 | D6: 1112906 | E6: 1172904 | F6: 1352940 | G6: 1322591 | H6: 1626831
B7: COGS | C7: 1030585 | D7: 932932 | E7: 963497 | F7: 1070935 | G7: 1177736 | H7: 1252317
B8: Gross Profit | C8: =C6-C7 | D8: =D6-D7 | E8: =E6-E7 | F8: =F6-F7 | G8: =G6-G7 | H8: =H6-H7
B9: Gross Margin | C9: =C8/C6 | D9: =D8/D6 | E9: =E8/E6 | F9: =F8/F6 | G9: =G8/G6 | H9: =H8/H6
B10: SGA | C10: 188104 | D10: 164225 | E10: 176600 | F10: 201158 | G10: 212837 | H10: 223638
B11: Operating Income | C11: 47859 | D11: 27961 | E11: 81497 | F11: 81985 | G11: -70138 | H11: 143517
B12: Net Income | C12: 8204 | D12: 13093 | E12: 66065 | F12: 44545 | G12: -68214 | H12: 112740
B13: Operating Margin | C13: =C11/C6 | D13: =D11/D6 | E13: =E11/E6 | F13: =F11/F6 | G13: =G11/G6 | H13: =H11/H6
B14: Net Margin | C14: =C12/C6 | D14: =D12/D6 | E14: =E12/E6 | F14: =F12/F6 | G14: =G12/G6 | H14: =H12/H6
B15: Revenue Growth (YoY) | C15: n/a | D15: =(D6-C6)/C6 | E15: =(E6-D6)/D6 | F15: =(F6-E6)/E6 | G15: =(G6-F6)/F6 | H15: =(H6-G6)/G6
B16: Operating Income Growth (YoY) | C16: n/a | D16: =(D11-C11)/C11 | E16: =(E11-D11)/D11 | F16: =(F11-E11)/E11 | G16: =(G11-F11)/F11 | H16: =(H11-G11)/G11
B18: Cash Flow Statement
B19: Operating Cash Flow | C19: 42484 | D19: 36380 | E19: 114155 | F19: 54116 | G19: 62117 | H19: 177634
B20: Capex | C20: 72293 | D20: 57458 | E20: 45574 | F20: 62577 | G20: 60993 | H20: 60249
B21: Free Cash Flow | C21: =C19-C20 | D21: =D19-D20 | E21: =E19-E20 | F21: =F19-F20 | G21: =G19-G20 | H21: =H19-H20
B22: FCF Margin | C22: =C21/C6 | D22: =D21/D6 | E22: =E21/E6 | F22: =F21/F6 | G22: =G21/G6 | H22: =H21/H6
B23: Capex / Revenue | C23: =C20/C6 | D23: =D20/D6 | E23: =E20/E6 | F23: =F20/F6 | G23: =G20/G6 | H23: =H20/H6
B25: Balance Sheet Highlights
B26: Cash & Deposits | C26: 145738 | D26: 120766 | E26: 145489 | F26: 124749 | G26: 138805 | H26: 136809
B27: Short-term Debt | C27: 463361 | D27: 463112 | E27: 372207 | F27: 393661 | G27: 449153 | H27: 389396
B28: Net Debt (Cash) | C28: =C27-C26 | D28: =D27-D26 | E28: =E27-E26 | F28: =F27-F26 | G28: =G27-G26 | H28: =H27-H26

Sheet DCF Model
B2: DCF Valuation Model - 株式会社ＩＨＩ
B4: Assumptions
B5: Capex / Revenue | C5: 0.065
B6: Effective Tax Rate | C6: 0.305
B7: Risk-Free Rate | C7: 0.023
B8: Beta | C8: 1.2
B9: Equity Risk Premium | C9: 0.065
B10: Size Premium | C10: 0
B11: After-tax Cost of Debt | C11: 0.008
B12: D/E Ratio | C12: 0.98
B13: Terminal Growth Rate | C13: 0.015
B14: Exit Multiple (EV/EBITDA) | C14: 15
B15: Fully Diluted Shares | C15: 1060152314
B16: Net Debt (JPY mn) | C16: 360593
... B20: LTM Revenue (JPY mn) | C20: 1582994
B22: WACC Calculation
B23: Cost of Equity (Ke) | C23: =C7+C8*C9+C10
B24: Weight of Equity | C24: =1/(1+C12)
B25: Weight of Debt | C25: =C12/(1+C12)
B26: WACC | C26: =C23*C24+C11*C25
B27: Active Scenario | C27: Base | D27: =MATCH(C27,{"Base","Upside","Management","Downside 1","Downside 2"},0)
B28: Projected Free Cash Flow
C29: FY2026(E) | D29: FY2027(E) | E29: FY2028(E) | F29: FY2029(E) | G29: FY2030(E)
B30: Revenue Growth (YoY) | C30: =(C33/C17)-1 | D30: =(D33/C33)-1 | E30: =(E33/D33)-1 | F30: =(F33/E33)-1 | G30: =(G33/F33)-1
B31: COGS % of Revenue | C31: =CHOOSE($D$27,'Segment Analysis'!F98,'Segment Analysis'!F99,'Segment Analysis'!F100,'Segment Analysis'!F101,'Segment Analysis'!F102) | D31: =CHOOSE($D$27,'Segment Analysis'!G98,'Segment Analysis'!G99,'Segment Analysis'!G100,'Segment Analysis'!G101,'Segment Analysis'!G102) | E31: =CHOOSE($D$27,'Segment Analysis'!H98,'Segment Analysis'!H99,'Segment Analysis'!H100,'Segment Analysis'!H101,'Segment Analysis'!H102) | F31: =CHOOSE($D$27,'Segment Analysis'!I98,'Segment Analysis'!I99,'Segment Analysis'!I100,'Segment Analysis'!I101,'Segment Analysis'!I102) | G31: =CHOOSE($D$27,'Segment Analysis'!J98,'Segment Analysis'!J99,'Segment Analysis'!J100,'Segment Analysis'!J101,'Segment Analysis'!J102)
B32: SGA % of Revenue | C32: =CHOOSE($D$27,'Segment Analysis'!F105,'Segment Analysis'!F106,'Segment Analysis'!F107,'Segment Analysis'!F108,'Segment Analysis'!F109) | D32: =CHOOSE($D$27,'Segment Analysis'!G105,'Segment Analysis'!G106,'Segment Analysis'!G107,'Segment Analysis'!G108,'Segment Analysis'!G109) | E32: =CHOOSE($D$27,'Segment Analysis'!H105,'Segment Analysis'!H106,'Segment Analysis'!H107,'Segment Analysis'!H108,'Segment Analysis'!H109) | F32: =CHOOSE($D$27,'Segment Analysis'!I105,'Segment Analysis'!I106,'Segment Analysis'!I107,'Segment Analysis'!I108,'Segment Analysis'!I109) | G32: =CHOOSE($D$27,'Segment Analysis'!J105,'Segment Analysis'!J106,'Segment Analysis'!J107,'Segment Analysis'!J108,'Segment Analysis'!J109)
B33: Revenue | C33: ='Segment Analysis'!F26 | D33: ='Segment Analysis'!G26 | E33: ='Segment Analysis'!H26 | F33: ='Segment Analysis'!I26 | G33: ='Segment Analysis'!J26
B34: COGS | C34: =C33*C31 | D34: =D33*D31 | E34: =E33*E31 | F34: =F33*F31 | G34: =G33*G31
B35: Gross Profit | C35: =C33-C34 | D35: =D33-D34 | E35: =E33-E34 | F35: =F33-F34 | G35: =G33-G34
B36: Gross Margin | C36: =C35/C33 | D36: =D35/D33 | E36: =E35/E33 | F36: =F35/F33 | G36: =G35/G33
B37: SGA Expense | C37: =C33*C32 | D37: =D33*D32 | E37: =E33*E32 | F37: =F33*F32 | G37: =G33*G32
B38: Implied Operating Margin | C38: =C39/C33 | D38: =D39/D33 | E38: =E39/E33 | F38: =F39/F33 | G38: =G39/G33
B39: Operating Income (EBIT) | C39: =C35-C37 | D39: =D35-D37 | E39: =E35-E37 | F39: =F35-F37 | G39: =G35-G37
B40: Less: Tax | C40: =MAX(0,C39*C6) | D40: =MAX(0,D39*C6) | E40: =MAX(0,E39*C6) | F40: =MAX(0,F39*C6) | G40: =MAX(0,G39*C6)
B41: NOPAT | C41: =C39-C40 | D41: =D39-D40 | E41: =E39-E40 | F41: =F39-F40 | G41: =G39-G40
B42: Plus: D&A | C42: =C33*C18 | D42: =D33*C18 | E42: =E33*C18 | F42: =F33*C18 | G42: =G33*C18
B43: Less: Capex | C43: =C33*C5 | D43: =D33*C5 | E43: =E33*C5 | F43: =F33*C5 | G43: =G33*C5
B44: Change in NWC | C44: ='NWC Schedule'!D19 | D44: ='NWC Schedule'!E19 | E44: ='NWC Schedule'!F19 | F44: ='NWC Schedule'!G19 | G44: ='NWC Schedule'!H19
B45: Unlevered Free Cash Flow | C45: =C41+C42-C43-C44 | D45: =D41+D42-D43-D44 | E45: =E41+E42-E43-E44 | F45: =F41+F42-F43-F44 | G45: =G41+G42-G43-G44
B46: Discount Factor | C46: =1/(1+C26)^(C19+0) | D46: =1/(1+C26)^(C19+1) | E46: =1/(1+C26)^(C19+2) | F46: =1/(1+C26)^(C19+3) | G46: =1/(1+C26)^(C19+4)
...

Sheet NWC Schedule
B2: NWC Schedule - 株式会社ＩＨＩ
B4: Working Capital Drivers (% of Revenue) | C4: Base Year | D4: FY2026(E) | E4: FY2027(E) | F4: FY2028(E) | G4: FY2029(E) | H4: FY2030(E)
B5: NWC % of Revenue | C5: =C18/C9 | D5: =CHOOSE('DCF Model'!$D$27,'Segment Analysis'!F112,'Segment Analysis'!F113,'Segment Analysis'!F114,'Segment Analysis'!F115,'Segment Analysis'!F116) | E5: =CHOOSE('DCF Model'!$D$27,'Segment Analysis'!G112,'Segment Analysis'!G113,'Segment Analysis'!G114,'Segment Analysis'!G115,'Segment Analysis'!G116) | F5: =CHOOSE('DCF Model'!$D$27,'Segment Analysis'!H112,'Segment Analysis'!H113,'Segment Analysis'!H114,'Segment Analysis'!H115,'Segment Analysis'!H116) | G5: =CHOOSE('DCF Model'!$D$27,'Segment Analysis'!I112,'Segment Analysis'!I113,'Segment Analysis'!I114,'Segment Analysis'!I115,'Segment Analysis'!I116) | H5: =CHOOSE('DCF Model'!$D$27,'Segment Analysis'!J112,'Segment Analysis'!J113,'Segment Analysis'!J114,'Segment Analysis'!J115,'Segment Analysis'!J116)
B6: — | C6: — | D6: — | E6: — | F6: — | G6: — | H6: —
B7: — | C7: — | D7: — | E7: — | F7: — | G7: — | H7: —
B8: P&L Reference (JPY mn)
B9: Revenue | C9: 1626831 | D9: ='DCF Model'!C33 | E9: ='DCF Model'!D33 | F9: ='DCF Model'!E33 | G9: ='DCF Model'!F33 | H9: ='DCF Model'!G33
B10: — | C10: — | D10: — | E10: — | F10: — | G10: — | H10: —
B11: Working Capital Items (JPY mn)
B12: — | C12: — | D12: — | E12: — | F12: — | G12: — | H12: —
B13: — | C13: — | D13: — | E13: — | F13: — | G13: — | H13: —
B14: — | C14: — | D14: — | E14: — | F14: — | G14: — | H14: —
B15: — | C15: — | D15: — | E15: — | F15: — | G15: — | H15: —
B16: — | C16: — | D16: — | E16: — | F16: — | G16: — | H16: —
B17: Net Working Capital (JPY mn)
B18: Net Working Capital | C18: 663583 | D18: =D9*D5 | E18: =E9*E5 | F18: =F9*F5 | G18: =G9*G5 | H18: =H9*H5
B19: Change in NWC | C19: n/a | D19: =D18-C18 | E19: =E18-D18 | F19: =F18-E18 | G19: =G18-F18 | H19: =H18-G18
B22: NWC inputs are in Segment Analysis sheet.

Sheet Comps Analysis
B2: Comparable Company Analysis
B4: Company | C4: Ticker | D4: Mkt Cap (JPY mn) | E4: EV (JPY mn) | F4: Revenue (JPY mn) | G4: EBITDA (JPY mn) | H4: Op Income (JPY mn) | I4: Net Income (JPY mn) | J4: EV/EBITDA | K4: EV/Revenue | L4: PER | M4: PBR | N4: Op Margin | O4: ROE
B5: Mitsubishi Heavy Industries | C5: 7011.T | D5: 16064713 | E5: 16064713 | F5: 4800000 | G5: 540643 | H5: 380000 | I5: 261997 | J5: =E5/G5 | K5: =E5/F5 | L5: =D5/I5 | M5: 6.5043984 | N5: =H5/F5 | O5: 0.10607926
B6: Kawasaki Heavy Industries | C6: 7012.T | D6: 2772502.6 | E6: 2772502.6 | F6: 2340000 | G6: 243431 | H6: 150000 | I6: 95000 | J6: =E6/G6 | K6: =E6/F6 | L6: =D6/I6 | M6: 3.8238039 | N6: =H6/F6 | O6: 0.13102292
B7: Sumitomo Heavy Industries | C7: 6302.T | D7: 626145.1 | E7: 878848.1 | F7: 1090000 | G7: 98596 | H7: 60000 | I7: 34000 | J7: =E7/G7 | K7: =E7/F7 | L7: =D7/I7 | M7: 0.91245135 | N7: =H7/F7 | O7: 0.049546576
B8: Kanadevia | C8: 7004.T | D8: 204753.99 | E8: 340516.99 | F8: 620000 | G8: 25413 | H8: 13500 | I8: 5000 | J8: =E8/G8 | K8: =E8/F8 | L8: =D8/I8 | M8: 1.0346598 | N8: =H8/F8 | O8: 0.025265924
B14: Statistics
B15: 25th Percentile | D15: =PERCENTILE(J5:J8,0.25) | E15: =PERCENTILE(K5:K8,0.25) | F15: =PERCENTILE(L5:L8,0.25) | G15: =PERCENTILE(M5:M8,0.25) | H15: =PERCENTILE(N5:N8,0.25) | I15: =PERCENTILE(O5:O8,0.25)
B16: Median (50th) | D16: =MEDIAN(J5:J8) | E16: =MEDIAN(K5:K8) | F16: =MEDIAN(L5:L8) | G16: =MEDIAN(M5:M8) | H16: =MEDIAN(N5:N8) | I16: =MEDIAN(O5:O8)
B17: 75th Percentile | D17: =PERCENTILE(J5:J8,0.75) | E17: =PERCENTILE(K5:K8,0.75) | F17: =PERCENTILE(L5:L8,0.75) | G17: =PERCENTILE(M5:M8,0.75) | H17: =PERCENTILE(N5:N8,0.75) | I17: =PERCENTILE(O5:O8,0.75)
B19: Implied Valuation for 株式会社ＩＨＩ
B20: 株式会社ＩＨＩ Financials
B21: EBITDA (JPY mn) | C21: 215669
B22: Net Income (JPY mn) | C22: 112740
B23: Shares Outstanding | C23: 1060152314
B24: Net Debt (JPY mn) | C24: 360593
B26: Implied Share Price (Median Multiples)
B27: Via EV/EBITDA (Median) | C27: =ROUND((C21*D16-C24)*1000000/C23,0)
B28: Via PER (Median) | C28: =ROUND(C22*F16*1000000/C23,0)

Sheet Sensitivity Analysis
B2: Sensitivity Analysis
B3: Current WACC: | C3: ='DCF Model'!C26 | E3: Terminal g: | F3: ='DCF Model'!C13 | H3: Exit Multiple: | I3: ='DCF Model'!C14
B5: Table 1: WACC vs Terminal Growth Rate (PGM - Implied Share Price, JPY)
B6: WACC \ Terminal g | C6: =$F$3-0.0075 | D6: =$F$3-0.005 | E6: =$F$3-0.0025 | F6: =$F$3 | G6: =$F$3+0.0025 | H6: =$F$3+0.005 | I6: =$F$3+0.0075
B7: =$C$3-0.015 | C7: =IFERROR(ROUND(('DCF Model'!C45/(1+$B7)^('DCF Model'!C19+0)+'DCF Model'!D45/(1+$B7)^('DCF Model'!C19+1)+'DCF Model'!E45/(1+$B7)^('DCF Model'!C19+2)+'DCF Model'!F45/(1+$B7)^('DCF Model'!C19+3)+'DCF Model'!G45/(1+$B7)^('DCF Model'!C19+4)+'DCF Model'!G45*(1+C$6)/($B7-C$6)/(1+$B7)^('DCF Model'!C19+4)-'DCF Model'!C16)*1000000/'DCF Model'!C15,0),"") | D7: =IFERROR(ROUND(('DCF Model'!C45/(1+$B7)^('DCF Model'!C19+0)+'DCF Model'!D45/(1+$B7)^('DCF Model'!C19+1)+'DCF Model'!E45/(1+$B7)^('DCF Model'!C19+2)+'DCF Model'!F45/(1+$B7)^('DCF Model'!C19+3)+'DCF Model'!G45/(1+$B7)^('DCF Model'!C19+4)+'DCF Model'!G45*(1+D$6)/($B7-D$6)/(1+$B7)^('DCF Model'!C19+4)-'DCF Model'!C16)*1000000/'DCF Model'!C15,0),"") | E7: =IFERROR(ROUND(('DCF Model'!C45/(1+$B7)^('DCF Model'!C19+0)+'DCF Model'!D45/(1+$B7)^('DCF Model'!C19+1)+'DCF Model'!E45/(1+$B7)^('DCF Model'!C19+2)+'DCF Model'!F45/(1+$B7)^('DCF Model'!C19+3)+'DCF Model'!G45/(1+$B7)^('DCF Model'!C19+4)+'DCF Model'!G45*(1+E$6)/($B7-E$6)/(1+$B7)^('DCF Model'!C19+4)-'DCF Model'!C16)*1000000/'DCF Model'!C15,0),"") | F7: =IFERROR(ROUND(('DCF Model'!C45/(1+$B7)^('DCF Model'!C19+0)+'DCF Model'!D45/(1+$B7)^('DCF Model'!C19+1)+'DCF Model'!E45/(1+$B7)^('DCF Model'!C19+2)+'DCF Model'!F45/(1+$B7)^('DCF Model'!C19+3)+'DCF Model'!G45/(1+$B7)^('DCF Model'!C19+4)+'DCF Model'!G45*(1+F$6)/($B7-F$6)/(1+$B7)^('DCF Model'!C19+4)-'DCF Model'!C16)*1000000/'DCF Model'!C15,0),"") | G7: =IFERROR(ROUND(('DCF Model'!C45/(1+$B7)^('DCF Model'!C19+0)+'DCF Model'!D45/(1+$B7)^('DCF Model'!C19+1)+'DCF Model'!E45/(1+$B7)^('DCF Model'!C19+2)+'DCF Model'!F45/(1+$B7)^('DCF Model'!C19+3)+'DCF Model'!G45/(1+$B7)^('DCF Model'!C19+4)+'DCF Model'!G45*(1+G$6)/($B7-G$6)/(1+$B7)^('DCF Model'!C19+4)-'DCF Model'!C16)*1000000/'DCF Model'!C15,0),"") | H7: =IFERROR(ROUND(('DCF Model'!C45/(1+$B7)^('DCF Model'!C19+0)+'DCF Model'!D45/(1+$B7)^('DCF Model'!C19+1)+'DCF Model'!E45/(1+$B7)^('DCF Model'!C19+2)+'DCF Model'!F45/(1+$B7)^('DCF Model'!C19+3)+'DCF Model'!G45/(1+$B7)^('DCF Model'!C19+4)+'DCF Model'!G45*(1+H$6)/($B7-H$6)/(1+$B7)^('DCF Model'!C19+4)-'DCF Model'!C16)*1000000/'DCF Model'!C15,0),"") | I7: =IFERROR(ROUND(('DCF Model'!C45/(1+$B7)^('DCF Model'!C19+0)+'DCF Model'!D45/(1+$B7)^('DCF Model'!C19+1)+'DCF Model'!E45/(1+$B7)^('DCF Model'!C19+2)+'DCF Model'!F45/(1+$B7)^('DCF Model'!C19+3)+'DCF Model'!G45/(1+$B7)^('DCF Model'!C19+4)+'DCF Model'!G45*(1+I$6)/($B7-I$6)/(1+$B7)^('DCF Model'!C19+4)-'DCF Model'!C16)*1000000/'DCF Model'!C15,0),"")
B8: =$C$3-0.01 | C8: =IFERROR(ROUND(('DCF Model'!C45/(1+$B8)^('DCF Model'!C19+0)+'DCF Model'!D45/(1+$B8)^('DCF Model'!C19+1)+'DCF Model'!E45/(1+$B8)^('DCF Model'!C19+2)+'DCF Model'!F45/(1+$B8)^('DCF Model'!C19+3)+'DCF Model'!G45/(1+$B8)^('DCF Model'!C19+4)+'DCF Model'!G45*(1+C$6)/($B8-C$6)/(1+$B8)^('DCF Model'!C19+4)-'DCF Model'!C16)*1000000/'DCF Model'!C15,0),"") | D8: =IFERROR(ROUND(('DCF Model'!C45/(1+$B8)^('DCF Model'!C19+0)+'DCF Model'!D45/(1+$B8)^('DCF Model'!C19+1)+'DCF Model'!E45/(1+$B8)^('DCF Model'!C19+2)+'DCF Model'!F45/(1+$B8)^('DCF Model'!C19+3)+'DCF Model'!G45/(1+$B8)^('DCF Model'!C19+4)+'DCF Model'!G45*(1+D$6)/($B8-D$6)/(1+$B8)^('DCF Model'!C19+4)-'DCF Model'!C16)*1000000/'DCF Model'!C15,0),"") | E8: =IFERROR(ROUND(('DCF Model'!C45/(1+$B8)^('DCF Model'!C19+0)+'DCF Model'!D45/(1+$B8)^('DCF Model'!C19+1)+'DCF Model'!E45/(1+$B8)^('DCF Model'!C19+2)+'DCF Model'!F45/(1+$B8)^('DCF Model'!C19+3)+'DCF Model'!G45/(1+$B8)^('DCF Model'!C19+4)+'DCF Model'!G45*(1+E$6)/($B8-E$6)/(1+$B8)^('DCF Model'!C19+4)-'DCF Model'!C16)*1000000/'DCF Model'!C15,0),"") | F8: =IFERROR(ROUND(('DCF Model'!C45/(1+$B8)^('DCF Model'!C19+0)+'DCF Model'!D45/(1+$B8)^('DCF Model'!C19+1)+'DCF Model'!E45/(1+$B8)^('DCF Model'!C19+2)+'DCF Model'!F45/(1+$B8)^('DCF Model'!C19+3)+'DCF Model'!G45/(1+$B8)^('DCF Model'!C19+4)+'DCF Model'!G45*(1+F$6)/($B8-F$6)/(1+$B8)^('DCF Model'!C19+4)-'DCF Model'!C16)*1000000/'DCF Model'!C15,0),"") | G8: =IFERROR(ROUND(('DCF Model'!C45/(1+$B8)^('DCF Model'!C19+0)+'DCF Model'!D45/(1+$B8)^('DCF Model'!C19+1)+'DCF Model'!E45/(1+$B8)^('DCF Model'!C19+2)+'DCF Model'!F45/(1+$B8)^('DCF Model'!C19+3)+'DCF Model'!G45/(1+$B8)^('DCF Model'!C19+4)+'DCF Model'!G45*(1+G$6)/($B8-G$6)/(1+$B8)^('DCF Model'!C19+4)-'DCF Model'!C16)*1000000/'DCF Model'!C15,0),"") | H8: =IFERROR(ROUND(('DCF Model'!C45/(1+$B8)^('DCF Model'!C19+0)+'DCF Model'!D45/(1+$B8)^('DCF Model'!C19+1)+'DCF Model'!E45/(1+$B8)^('DCF Model'!C19+2)+'DCF Model'!F45/(1+$B8)^('DCF Model'!C19+3)+'DCF Model'!G45/(1+$B8)^('DCF Model'!C19+4)+'DCF Model'!G45*(1+H$6)/($B8-H$6)/(1+$B8)^('DCF Model'!C19+4)-'DCF Model'!C16)*1000000/'DCF Model'!C15,0),"") | I8: =IFERROR(ROUND(('DCF Model'!C45/(1+$B8)^('DCF Model'!C19+0)+'DCF Model'!D45/(1+$B8)^('DCF Model'!C19+1)+'DCF Model'!E45/(1+$B8)^('DCF Model'!C19+2)+'DCF Model'!F45/(1+$B8)^('DCF Model'!C19+3)+'DCF Model'!G45/(1+$B8)^('DCF Model'!C19+4)+'DCF Model'!G45*(1+I$6)/($B8-I$6)/(1+$B8)^('DCF Model'!C19+4)-'DCF Model'!C16)*1000000/'DCF Model'!C15,0),"")
B9: =$C$3-0.005 | C9: =IFERROR(ROUND(('DCF Model'!C45/(1+$B9)^('DCF Model'!C19+0)+'DCF Model'!D45/(1+$B9)^('DCF Model'!C19+1)+'DCF Model'!E45/(1+$B9)^('DCF Model'!C19+2)+'DCF Model'!F45/(1+$B9)^('DCF Model'!C19+3)+'DCF Model'!G45/(1+$B9)^('DCF Model'!C19+4)+'DCF Model'!G45*(1+C$6)/($B9-C$6)/(1+$B9)^('DCF Model'!C19+4)-'DCF Model'!C16)*1000000/'DCF Model'!C15,0),"") | D9: =IFERROR(ROUND(('DCF Model'!C45/(1+$B9)^('DCF Model'!C19+0)+'DCF Model'!D45/(1+$B9)^('DCF Model'!C19+1)+'DCF Model'!E45/(1+$B9)^('DCF Model'!C19+2)+'DCF Model'!F45/(1+$B9)^('DCF Model'!C19+3)+'DCF Model'!G45/(1+$B9)^('DCF Model'!C19+4)+'DCF Model'!G45*(1+D$6)/($B9-D$6)/(1+$B9)^('DCF Model'!C19+4)-'DCF Model'!C16)*1000000/'DCF Model'!C15,0),"") | E9: =IFERROR(ROUND(('DCF Model'!C45/(1+$B9)^('DCF Model'!C19+0)+'DCF Model'!D45/(1+$B9)^('DCF Model'!C19+1)+'DCF Model'!E45/(1+$B9)^('DCF Model'!C19+2)+'DCF Model'!F45/(1+$B9)^('DCF Model'!C19+3)+'DCF Model'!G45/(1+$B9)^('DCF Model'!C19+4)+'DCF Model'!G45*(1+E$6)/($B9-E$6)/(1+$B9)^('DCF Model'!C19+4)-'DCF Model'!C16)*1000000/'DCF Model'!C15,0),"") | F9: =IFERROR(ROUND(('DCF Model'!C45/(1+$B9)^('DCF Model'!C19+0)+'DCF Model'!D45/(1+$B9)^('DCF Model'!C19+1)+'DCF Model'!E45/(1+$B9)^('DCF Model'!C19+2)+'DCF Model'!F45/(1+$B9)^('DCF Model'!C19+3)+'DCF Model'!G45/(1+$B9)^('DCF Model'!C19+4)+'DCF Model'!G45*(1+F$6)/($B9-F$6)/(1+$B9)^('DCF Model'!C19+4)-'DCF Model'!C16)*1000000/'DCF Model'!C15,0),"") | G9: =IFERROR(ROUND(('DCF Model'!C45/(1+$B9)^('DCF Model'!C19+0)+'DCF Model'!D45/(1+$B9)^('DCF Model'!C19+1)+'DCF Model'!E45/(1+$B9)^('DCF Model'!C19+2)+'DCF Model'!F45/(1+$B9)^('DCF Model'!C19+3)+'DCF Model'!G45/(1+$B9)^('DCF Model'!C19+4)+'DCF Model'!G45*(1+G$6)/($B9-G$6)/(1+$B9)^('DCF Model'!C19+4)-'DCF Model'!C16)*1000000/'DCF Model'!C15,0),"") | H9: =IFERROR(ROUND(('DCF Model'!C45/(1+$B9)^('DCF Model'!C19+0)+'DCF Model'!D45/(1+$B9)^('DCF Model'!C19+1)+'DCF Model'!E45/(1+$B9)^('DCF Model'!C19+2)+'DCF Model'!F45/(1+$B9)^('DCF Model'!C19+3)+'DCF Model'!G45/(1+$B9)^('DCF Model'!C19+4)+'DCF Model'!G45*(1+H$6)/($B9-H$6)/(1+$B9)^('DCF Model'!C19+4)-'DCF Model'!C16)*1000000/'DCF Model'!C15,0),"") | I9: =IFERROR(ROUND(('DCF Model'!C45/(1+$B9)^('DCF Model'!C19+0)+'DCF Model'!D45/(1+$B9)^('DCF Model'!C19+1)+'DCF Model'!E45/(1+$B9)^('DCF Model'!C19+2)+'DCF Model'!F45/(1+$B9)^('DCF Model'!C19+3)+'DCF Model'!G45/(1+$B9)^('DCF Model'!C19+4)+'DCF Model'!G45*(1+I$6)/($B9-I$6)/(1+$B9)^('DCF Model'!C19+4)-'DCF Model'!C16)*1000000/'DCF Model'!C15,0),"")
B10: =$C$3 | C10: =IFERROR(ROUND(('DCF Model'!C45/(1+$B10)^('DCF Model'!C19+0)+'DCF Model'!D45/(1+$B10)^('DCF Model'!C19+1)+'DCF Model'!E45/(1+$B10)^('DCF Model'!C19+2)+'DCF Model'!F45/(1+$B10)^('DCF Model'!C19+3)+'DCF Model'!G45/(1+$B10)^('DCF Model'!C19+4)+'DCF Model'!G45*(1+C$6)/($B10-C$6)/(1+$B10)^('DCF Model'!C19+4)-'DCF Model'!C16)*1000000/'DCF Model'!C15,0),"") | D10: =IFERROR(ROUND(('DCF Model'!C45/(1+$B10)^('DCF Model'!C19+0)+'DCF Model'!D45/(1+$B10)^('DCF Model'!C19+1)+'DCF Model'!E45/(1+$B10)^('DCF Model'!C19+2)+'DCF Model'!F45/(1+$B10)^('DCF Model'!C19+3)+'DCF Model'!G45/(1+$B10)^('DCF Model'!C19+4)+'DCF Model'!G45*(1+D$6)/($B10-D$6)/(1+$B10)^('DCF Model'!C19+4)-'DCF Model'!C16)*1000000/'DCF Model'!C15,0),"") | E10: =IFERROR(ROUND(('DCF Model'!C45/(1+$B10)^('DCF Model'!C19+0)+'DCF Model'!D45/(1+$B10)^('DCF Model'!C19+1)+'DCF Model'!E45/(1+$B10)^('DCF Model'!C19+2)+'DCF Model'!F45/(1+$B10)^('DCF Model'!C19+3)+'DCF Model'!G45/(1+$B10)^('DCF Model'!C19+4)+'DCF Model'!G45*(1+E$6)/($B10-E$6)/(1+$B10)^('DCF Model'!C19+4)-'DCF Model'!C16)*1000000/'DCF Model'!C15,0),"") | F10: =IFERROR(ROUND(('DCF Model'!C45/(1+$B10)^('DCF Model'!C19+0)+'DCF Model'!D45/(1+$B10)^('DCF Model'!C19+1)+'DCF Model'!E45/(1+$B10)^('DCF Model'!C19+2)+'DCF Model'!F45/(1+$B10)^('DCF Model'!C19+3)+'DCF Model'!G45/(1+$B10)^('DCF Model'!C19+4)+'DCF Model'!G45*(1+F$6)/($B10-F$6)/(1+$B10)^('DCF Model'!C19+4)-'DCF Model'!C16)*1000000/'DCF Model'!C15,0),"") | G10: =IFERROR(ROUND(('DCF Model'!C45/(1+$B10)^('DCF Model'!C19+0)+'DCF Model'!D45/(1+$B10)^('DCF Model'!C19+1)+'DCF Model'!E45/(1+$B10)^('DCF Model'!C19+2)+'DCF Model'!F45/(1+$B10)^('DCF Model'!C19+3)+'DCF Model'!G45/(1+$B10)^('DCF Model'!C19+4)+'DCF Model'!G45*(1+G$6)/($B10-G$6)/(1+$B10)^('DCF Model'!C19+4)-'DCF Model'!C16)*1000000/'DCF Model'!C15,0),"") | H10: =IFERROR(ROUND(('DCF Model'!C45/(1+$B10)^('DCF Model'!C19+0)+'DCF Model'!D45/(1+$B10)^('DCF Model'!C19+1)+'DCF Model'!E45/(1+$B10)^('DCF Model'!C19+2)+'DCF Model'!F45/(1+$B10)^('DCF Model'!C19+3)+'DCF Model'!G45/(1+$B10)^('DCF Model'!C19+4)+'DCF Model'!G45*(1+H$6)/($B10-H$6)/(1+$B10)^('DCF Model'!C19+4)-'DCF Model'!C16)*1000000/'DCF Model'!C15,0),"") | I10: =IFERROR(ROUND(('DCF Model'!C45/(1+$B10)^('DCF Model'!C19+0)+'DCF Model'!D45/(1+$B10)^('DCF Model'!C19+1)+'DCF Model'!E45/(1+$B10)^('DCF Model'!C19+2)+'DCF Model'!F45/(1+$B10)^('DCF Model'!C19+3)+'DCF Model'!G45/(1+$B10)^('DCF Model'!C19+4)+'DCF Model'!G45*(1+I$6)/($B10-I$6)/(1+$B10)^('DCF Model'!C19+4)-'DCF Model'!C16)*1000000/'DCF Model'!C15,0),"")
B11: =$C$3+0.005 | C11: =IFERROR(ROUND(('DCF Model'!C45/(1+$B11)^('DCF Model'!C19+0)+'DCF Model'!D45/(1+$B11)^('DCF Model'!C19+1)+'DCF Model'!E45/(1+$B11)^('DCF Model'!C19+2)+'DCF Model'!F45/(1+$B11)^('DCF Model'!C19+3)+'DCF Model'!G45/(1+$B11)^('DCF Model'!C19+4)+'DCF Model'!G45*(1+C$6)/($B11-C$6)/(1+$B11)^('DCF Model'!C19+4)-'DCF Model'!C16)*1000000/'DCF Model'!C15,0),"") | D11: =IFERROR(ROUND(('DCF Model'!C45/(1+$B11)^('DCF Model'!C19+0)+'DCF Model'!D45/(1+$B11)^('DCF Model'!C19+1)+'DCF Model'!E45/(1+$B11)^('DCF Model'!C19+2)+'DCF Model'!F45/(1+$B11)^('DCF Model'!C19+3)+'DCF Model'!G45/(1+$B11)^('DCF Model'!C19+4)+'DCF Model'!G45*(1+D$6)/($B11-D$6)/(1+$B11)^('DCF Model'!C19+4)-'DCF Model'!C16)*1000000/'DCF Model'!C15,0),"") | E11: =IFERROR(ROUND(('DCF Model'!C45/(1+$B11)^('DCF Model'!C19+0)+'DCF Model'!D45/(1+$B11)^('DCF Model'!C19+1)+'DCF Model'!E45/(1+$B11)^('DCF Model'!C19+2)+'DCF Model'!F45/(1+$B11)^('DCF Model'!C19+3)+'DCF Model'!G45/(1+$B11)^('DCF Model'!C19+4)+'DCF Model'!G45*(1+E$6)/($B11-E$6)/(1+$B11)^('DCF Model'!C19+4)-'DCF Model'!C16)*1000000/'DCF Model'!C15,0),"") | F11: =IFERROR(ROUND(('DCF Model'!C45/(1+$B11)^('DCF Model'!C19+0)+'DCF Model'!D45/(1+$B11)^('DCF Model'!C19+1)+'DCF Model'!E45/(1+$B11)^('DCF Model'!C19+2)+'DCF Model'!F45/(1+$B11)^('DCF Model'!C19+3)+'DCF Model'!G45/(1+$B11)^('DCF Model'!C19+4)+'DCF Model'!G45*(1+F$6)/($B11-F$6)/(1+$B11)^('DCF Model'!C19+4)-'DCF Model'!C16)*1000000/'DCF Model'!C15,0),"") | G11: =IFERROR(ROUND(('DCF Model'!C45/(1+$B11)^('DCF Model'!C19+0)+'DCF Model'!D45/(1+$B11)^('DCF Model'!C19+1)+'DCF Model'!E45/(1+$B11)^('DCF Model'!C19+2)+'DCF Model'!F45/(1+$B11)^('DCF Model'!C19+3)+'DCF Model'!G45/(1+$B11)^('DCF Model'!C19+4)+'DCF Model'!G45*(1+G$6)/($B11-G$6)/(1+$B11)^('DCF Model'!C19+4)-'DCF Model'!C16)*1000000/'DCF Model'!C15,0),"") | H11: =IFERROR(ROUND(('DCF Model'!C45/(1+$B11)^('DCF Model'!C19+0)+'DCF Model'!D45/(1+$B11)^('DCF Model'!C19+1)+'DCF Model'!E45/(1+$B11)^('DCF Model'!C19+2)+'DCF Model'!F45/(1+$B11)^('DCF Model'!C19+3)+'DCF Model'!G45/(1+$B11)^('DCF Model'!C19+4)+'DCF Model'!G45*(1+H$6)/($B11-H$6)/(1+$B11)^('DCF Model'!C19+4)-'DCF Model'!C16)*1000000/'DCF Model'!C15,0),"") | I11: =IFERROR(ROUND(('DCF Model'!C45/(1+$B11)^('DCF Model'!C19+0)+'DCF Model'!D45/(1+$B11)^('DCF Model'!C19+1)+'DCF Model'!E45/(1+$B11)^('DCF Model'!C19+2)+'DCF Model'!F45/(1+$B11)^('DCF Model'!C19+3)+'DCF Model'!G45/(1+$B11)^('DCF Model'!C19+4)+'DCF Model'!G45*(1+I$6)/($B11-I$6)/(1+$B11)^('DCF Model'!C19+4)-'DCF Model'!C16)*1000000/'DCF Model'!C15,0),"")
B12: =$C$3+0.01 | C12: =IFERROR(ROUND(('DCF Model'!C45/(1+$B12)^('DCF Model'!C19+0)+'DCF Model'!D45/(1+$B12)^('DCF Model'!C19+1)+'DCF Model'!E45/(1+$B12)^('DCF Model'!C19+2)+'DCF Model'!F45/(1+$B12)^('DCF Model'!C19+3)+'DCF Model'!G45/(1+$B12)^('DCF Model'!C19+4)+'DCF Model'!G45*(1+C$6)/($B12-C$6)/(1+$B12)^('DCF Model'!C19+4)-'DCF Model'!C16)*1000000/'DCF Model'!C15,0),"") | D12: =IFERROR(ROUND(('DCF Model'!C45/(1+$B12)^('DCF Model'!C19+0)+'DCF Model'!D45/(1+$B12)^('DCF Model'!C19+1)+'DCF Model'!E45/(1+$B12)^('DCF Model'!C19+2)+'DCF Model'!F45/(1+$B12)^('DCF Model'!C19+3)+'DCF Model'!G45/(1+$B12)^('DCF Model'!C19+4)+'DCF Model'!G45*(1+D$6)/($B12-D$6)/(1+$B12)^('DCF Model'!C19+4)-'DCF Model'!C16)*1000000/'DCF Model'!C15,0),"") | E12: =IFERROR(ROUND(('DCF Model'!C45/(1+$B12)^('DCF Model'!C19+0)+'DCF Model'!D45/(1+$B12)^('DCF Model'!C19+1)+'DCF Model'!E45/(1+$B12)^('DCF Model'!C19+2)+'DCF Model'!F45/(1+$B12)^('DCF Model'!C19+3)+'DCF Model'!G45/(1+$B12)^('DCF Model'!C19+4)+'DCF Model'!G45*(1+E$6)/($B12-E$6)/(1+$B12)^('DCF Model'!C19+4)-'DCF Model'!C16)*1000000/'DCF Model'!C15,0),"") | F12: =IFERROR(ROUND(('DCF Model'!C45/(1+$B12)^('DCF Model'!C19+0)+'DCF Model'!D45/(1+$B12)^('DCF Model'!C19+1)+'DCF Model'!E45/(1+$B12)^('DCF Model'!C19+2)+'DCF Model'!F45/(1+$B12)^('DCF Model'!C19+3)+'DCF Model'!G45/(1+$B12)^('DCF Model'!C19+4)+'DCF Model'!G45*(1+F$6)/($B12-F$6)/(1+$B12)^('DCF Model'!C19+4)-'DCF Model'!C16)*1000000/'DCF Model'!C15,0),"") | G12: =IFERROR(ROUND(('DCF Model'!C45/(1+$B12)^('DCF Model'!C19+0)+'DCF Model'!D45/(1+$B12)^('DCF Model'!C19+1)+'DCF Model'!E45/(1+$B12)^('DCF Model'!C19+2)+'DCF Model'!F45/(1+$B12)^('DCF Model'!C19+3)+'DCF Model'!G45/(1+$B12)^('DCF Model'!C19+4)+'DCF Model'!G45*(1+G$6)/($B12-G$6)/(1+$B12)^('DCF Model'!C19+4)-'DCF Model'!C16)*1000000/'DCF Model'!C15,0),"") | H12: =IFERROR(ROUND(('DCF Model'!C45/(1+$B12)^('DCF Model'!C19+0)+'DCF Model'!D45/(1+$B12)^('DCF Model'!C19+1)+'DCF Model'!E45/(1+$B12)^('DCF Model'!C19+2)+'DCF Model'!F45/(1+$B12)^('DCF Model'!C19+3)+'DCF Model'!G45/(1+$B12)^('DCF Model'!C19+4)+'DCF Model'!G45*(1+H$6)/($B12-H$6)/(1+$B12)^('DCF Model'!C19+4)-'DCF Model'!C16)*1000000/'DCF Model'!C15,0),"") | I12: =IFERROR(ROUND(('DCF Model'!C45/(1+$B12)^('DCF Model'!C19+0)+'DCF Model'!D45/(1+$B12)^('DCF Model'!C19+1)+'DCF Model'!E45/(1+$B12)^('DCF Model'!C19+2)+'DCF Model'!F45/(1+$B12)^('DCF Model'!C19+3)+'DCF Model'!G45/(1+$B12)^('DCF Model'!C19+4)+'DCF Model'!G45*(1+I$6)/($B12-I$6)/(1+$B12)^('DCF Model'!C19+4)-'DCF Model'!C16)*1000000/'DCF Model'!C15,0),"")
B13: =$C$3+0.015 | C13: =IFERROR(ROUND(('DCF Model'!C45/(1+$B13)^('DCF Model'!C19+0)+'DCF Model'!D45/(1+$B13)^('DCF Model'!C19+1)+'DCF Model'!E45/(1+$B13)^('DCF Model'!C19+2)+'DCF Model'!F45/(1+$B13)^('DCF Model'!C19+3)+'DCF Model'!G45/(1+$B13)^('DCF Model'!C19+4)+'DCF Model'!G45*(1+C$6)/($B13-C$6)/(1+$B13)^('DCF Model'!C19+4)-'DCF Model'!C16)*1000000/'DCF Model'!C15,0),"") | D13: =IFERROR(ROUND(('DCF Model'!C45/(1+$B13)^('DCF Model'!C19+0)+'DCF Model'!D45/(1+$B13)^('DCF Model'!C19+1)+'DCF Model'!E45/(1+$B13)^('DCF Model'!C19+2)+'DCF Model'!F45/(1+$B13)^('DCF Model'!C19+3)+'DCF Model'!G45/(1+$B13)^('DCF Model'!C19+4)+'DCF Model'!G45*(1+D$6)/($B13-D$6)/(1+$B13)^('DCF Model'!C19+4)-'DCF Model'!C16)*1000000/'DCF Model'!C15,0),"") | E13: =IFERROR(ROUND(('DCF Model'!C45/(1+$B13)^('DCF Model'!C19+0)+'DCF Model'!D45/(1+$B13)^('DCF Model'!C19+1)+'DCF Model'!E45/(1+$B13)^('DCF Model'!C19+2)+'DCF Model'!F45/(1+$B13)^('DCF Model'!C19+3)+'DCF Model'!G45/(1+$B13)^('DCF Model'!C19+4)+'DCF Model'!G45*(1+E$6)/($B13-E$6)/(1+$B13)^('DCF Model'!C19+4)-'DCF Model'!C16)*1000000/'DCF Model'!C15,0),"") | F13: =IFERROR(ROUND(('DCF Model'!C45/(1+$B13)^('DCF Model'!C19+0)+'DCF Model'!D45/(1+$B13)^('DCF Model'!C19+1)+'DCF Model'!E45/(1+$B13)^('DCF Model'!C19+2)+'DCF Model'!F45/(1+$B13)^('DCF Model'!C19+3)+'DCF Model'!G45/(1+$B13)^('DCF Model'!C19+4)+'DCF Model'!G45*(1+F$6)/($B13-F$6)/(1+$B13)^('DCF Model'!C19+4)-'DCF Model'!C16)*1000000/'DCF Model'!C15,0),"") | G13: =IFERROR(ROUND(('DCF Model'!C45/(1+$B13)^('DCF Model'!C19+0)+'DCF Model'!D45/(1+$B13)^('DCF Model'!C19+1)+'DCF Model'!E45/(1+$B13)^('DCF Model'!C19+2)+'DCF Model'!F45/(1+$B13)^('DCF Model'!C19+3)+'DCF Model'!G45/(1+$B13)^('DCF Model'!C19+4)+'DCF Model'!G45*(1+G$6)/($B13-G$6)/(1+$B13)^('DCF Model'!C19+4)-'DCF Model'!C16)*1000000/'DCF Model'!C15,0),"") | H13: =IFERROR(ROUND(('DCF Model'!C45/(1+$B13)^('DCF Model'!C19+0)+'DCF Model'!D45/(1+$B13)^('DCF Model'!C19+1)+'DCF Model'!E45/(1+$B13)^('DCF Model'!C19+2)+'DCF Model'!F45/(1+$B13)^('DCF Model'!C19+3)+'DCF Model'!G45/(1+$B13)^('DCF Model'!C19+4)+'DCF Model'!G45*(1+H$6)/($B13-H$6)/(1+$B13)^('DCF Model'!C19+4)-'DCF Model'!C16)*1000000/'DCF Model'!C15,0),"") | I13: =IFERROR(ROUND(('DCF Model'!C45/(1+$B13)^('DCF Model'!C19+0)+'DCF Model'!D45/(1+$B13)^('DCF Model'!C19+1)+'DCF Model'!E45/(1+$B13)^('DCF Model'!C19+2)+'DCF Model'!F45/(1+$B13)^('DCF Model'!C19+3)+'DCF Model'!G45/(1+$B13)^('DCF Model'!C19+4)+'DCF Model'!G45*(1+I$6)/($B13-I$6)/(1+$B13)^('DCF Model'!C19+4)-'DCF Model'!C16)*1000000/'DCF Model'!C15,0),"")
B16: Table 2: WACC vs Exit Multiple (Exit Multiple - Implied Share Price, JPY)
B17: WACC \ Exit Multiple | C17: =$I$3-3.0 | D17: =$I$3-2.0 | E17: =$I$3-1.0 | F17: =$I$3 | G17: =$I$3+1.0 | H17: =$I$3+2.0 | I17: =$I$3+3.0
B18: =$C$3-0.015 | C18: =IFERROR(ROUND(('DCF Model'!C45/(1+$B18)^('DCF Model'!C19+0)+'DCF Model'!D45/(1+$B18)^('DCF Model'!C19+1)+'DCF Model'!E45/(1+$B18)^('DCF Model'!C19+2)+'DCF Model'!F45/(1+$B18)^('DCF Model'!C19+3)+'DCF Model'!G45/(1+$B18)^('DCF Model'!C19+4)+('DCF Model'!G39+'DCF Model'!G42)*C$17/(1+$B18)^('DCF Model'!C19+4)-'DCF Model'!C16)*1000000/'DCF Model'!C15,0),"") | D18: =IFERROR(ROUND(('DCF Model'!C45/(1+$B18)^('DCF Model'!C19+0)+'DCF Model'!D45/(1+$B18)^('DCF Model'!C19+1)+'DCF Model'!E45/(1+$B18)^('DCF Model'!C19+2)+'DCF Model'!F45/(1+$B18)^('DCF Model'!C19+3)+'DCF Model'!G45/(1+$B18)^('DCF Model'!C19+4)+('DCF Model'!G39+'DCF Model'!G42)*D$17/(1+$B18)^('DCF Model'!C19+4)-'DCF Model'!C16)*1000000/'DCF Model'!C15,0),"") | E18: =IFERROR(ROUND(('DCF Model'!C45/(1+$B18)^('DCF Model'!C19+0)+'DCF Model'!D45/(1+$B18)^('DCF Model'!C19+1)+'DCF Model'!E45/(1+$B18)^('DCF Model'!C19+2)+'DCF Model'!F45/(1+$B18)^('DCF Model'!C19+3)+'DCF Model'!G45/(1+$B18)^('DCF Model'!C19+4)+('DCF Model'!G39+'DCF Model'!G42)*E$17/(1+$B18)^('DCF Model'!C19+4)-'DCF Model'!C16)*1000000/'DCF Model'!C15,0),"") | F18: =IFERROR(ROUND(('DCF Model'!C45/(1+$B18)^('DCF Model'!C19+0)+'DCF Model'!D45/(1+$B18)^('DCF Model'!C19+1)+'DCF Model'!E45/(1+$B18)^('DCF Model'!C19+2)+'DCF Model'!F45/(1+$B18)^('DCF Model'!C19+3)+'DCF Model'!G45/(1+$B18)^('DCF Model'!C19+4)+('DCF Model'!G39+'DCF Model'!G42)*F$17/(1+$B18)^('DCF Model'!C19+4)-'DCF Model'!C16)*1000000/'DCF Model'!C15,0),"") | G18: =IFERROR(ROUND(('DCF Model'!C45/(1+$B18)^('DCF Model'!C19+0)+'DCF Model'!D45/(1+$B18)^('DCF Model'!C19+1)+'DCF Model'!E45/(1+$B18)^('DCF Model'!C19+2)+'DCF Model'!F45/(1+$B18)^('DCF Model'!C19+3)+'DCF Model'!G45/(1+$B18)^('DCF Model'!C19+4)+('DCF Model'!G39+'DCF Model'!G42)*G$17/(1+$B18)^('DCF Model'!C19+4)-'DCF Model'!C16)*1000000/'DCF Model'!C15,0),"") | H18: =IFERROR(ROUND(('DCF Model'!C45/(1+$B18)^('DCF Model'!C19+0)+'DCF Model'!D45/(1+$B18)^('DCF Model'!C19+1)+'DCF Model'!E45/(1+$B18)^('DCF Model'!C19+2)+'DCF Model'!F45/(1+$B18)^('DCF Model'!C19+3)+'DCF Model'!G45/(1+$B18)^('DCF Model'!C19+4)+('DCF Model'!G39+'DCF Model'!G42)*H$17/(1+$B18)^('DCF Model'!C19+4)-'DCF Model'!C16)*1000000/'DCF Model'!C15,0),"") | I18: =IFERROR(ROUND(('DCF Model'!C45/(1+$B18)^('DCF Model'!C19+0)+'DCF Model'!D45/(1+$B18)^('DCF Model'!C19+1)+'DCF Model'!E45/(1+$B18)^('DCF Model'!C19+2)+'DCF Model'!F45/(1+$B18)^('DCF Model'!C19+3)+'DCF Model'!G45/(1+$B18)^('DCF Model'!C19+4)+('DCF Model'!G39+'DCF Model'!G42)*I$17/(1+$B18)^('DCF Model'!C19+4)-'DCF Model'!C16)*1000000/'DCF Model'!C15,0),"")
B19: =$C$3-0.01 | C19: =IFERROR(ROUND(('DCF Model'!C45/(1+$B19)^('DCF Model'!C19+0)+'DCF Model'!D45/(1+$B19)^('DCF Model'!C19+1)+'DCF Model'!E45/(1+$B19)^('DCF Model'!C19+2)+'DCF Model'!F45/(1+$B19)^('DCF Model'!C19+3)+'DCF Model'!G45/(1+$B19)^('DCF Model'!C19+4)+('DCF Model'!G39+'DCF Model'!G42)*C$17/(1+$B19)^('DCF Model'!C19+4)-'DCF Model'!C16)*1000000/'DCF Model'!C15,0),"") | D19: =IFERROR(ROUND(('DCF Model'!C45/(1+$B19)^('DCF Model'!C19+0)+'DCF Model'!D45/(1+$B19)^('DCF Model'!C19+1)+'DCF Model'!E45/(1+$B19)^('DCF Model'!C19+2)+'DCF Model'!F45/(1+$B19)^('DCF Model'!C19+3)+'DCF Model'!G45/(1+$B19)^('DCF Model'!C19+4)+('DCF Model'!G39+'DCF Model'!G42)*D$17/(1+$B19)^('DCF Model'!C19+4)-'DCF Model'!C16)*1000000/'DCF Model'!C15,0),"") | E19: =IFERROR(ROUND(('DCF Model'!C45/(1+$B19)^('DCF Model'!C19+0)+'DCF Model'!D45/(1+$B19)^('DCF Model'!C19+1)+'DCF Model'!E45/(1+$B19)^('DCF Model'!C19+2)+'DCF Model'!F45/(1+$B19)^('DCF Model'!C19+3)+'DCF Model'!G45/(1+$B19)^('DCF Model'!C19+4)+('DCF Model'!G39+'DCF Model'!G42)*E$17/(1+$B19)^('DCF Model'!C19+4)-'DCF Model'!C16)*1000000/'DCF Model'!C15,0),"") | F19: =IFERROR(ROUND(('DCF Model'!C45/(1+$B19)^('DCF Model'!C19+0)+'DCF Model'!D45/(1+$B19)^('DCF Model'!C19+1)+'DCF Model'!E45/(1+$B19)^('DCF Model'!C19+2)+'DCF Model'!F45/(1+$B19)^('DCF Model'!C19+3)+'DCF Model'!G45/(1+$B19)^('DCF Model'!C19+4)+('DCF Model'!G39+'DCF Model'!G42)*F$17/(1+$B19)^('DCF Model'!C19+4)-'DCF Model'!C16)*1000000/'DCF Model'!C15,0),"") | G19: =IFERROR(ROUND(('DCF Model'!C45/(1+$B19)^('DCF Model'!C19+0)+'DCF Model'!D45/(1+$B19)^('DCF Model'!C19+1)+'DCF Model'!E45/(1+$B19)^('DCF Model'!C19+2)+'DCF Model'!F45/(1+$B19)^('DCF Model'!C19+3)+'DCF Model'!G45/(1+$B19)^('DCF Model'!C19+4)+('DCF Model'!G39+'DCF Model'!G42)*G$17/(1+$B19)^('DCF Model'!C19+4)-'DCF Model'!C16)*1000000/'DCF Model'!C15,0),"") | H19: =IFERROR(ROUND(('DCF Model'!C45/(1+$B19)^('DCF Model'!C19+0)+'DCF Model'!D45/(1+$B19)^('DCF Model'!C19+1)+'DCF Model'!E45/(1+$B19)^('DCF Model'!C19+2)+'DCF Model'!F45/(1+$B19)^('DCF Model'!C19+3)+'DCF Model'!G45/(1+$B19)^('DCF Model'!C19+4)+('DCF Model'!G39+'DCF Model'!G42)*H$17/(1+$B19)^('DCF Model'!C19+4)-'DCF Model'!C16)*1000000/'DCF Model'!C15,0),"") | I19: =IFERROR(ROUND(('DCF Model'!C45/(1+$B19)^('DCF Model'!C19+0)+'DCF Model'!D45/(1+$B19)^('DCF Model'!C19+1)+'DCF Model'!E45/(1+$B19)^('DCF Model'!C19+2)+'DCF Model'!F45/(1+$B19)^('DCF Model'!C19+3)+'DCF Model'!G45/(1+$B19)^('DCF Model'!C19+4)+('DCF Model'!G39+'DCF Model'!G42)*I$17/(1+$B19)^('DCF Model'!C19+4)-'DCF Model'!C16)*1000000/'DCF Model'!C15,0),"")
B20: =$C$3-0.005 | C20: =IFERROR(ROUND(('DCF Model'!C45/(1+$B20)^('DCF Model'!C19+0)+'DCF Model'!D45/(1+$B20)^('DCF Model'!C19+1)+'DCF Model'!E45/(1+$B20)^('DCF Model'!C19+2)+'DCF Model'!F45/(1+$B20)^('DCF Model'!C19+3)+'DCF Model'!G45/(1+$B20)^('DCF Model'!C19+4)+('DCF Model'!G39+'DCF Model'!G42)*C$17/(1+$B20)^('DCF Model'!C19+4)-'DCF Model'!C16)*1000000/'DCF Model'!C15,0),"") | D20: =IFERROR(ROUND(('DCF Model'!C45/(1+$B20)^('DCF Model'!C19+0)+'DCF Model'!D45/(1+$B20)^('DCF Model'!C19+1)+'DCF Model'!E45/(1+$B20)^('DCF Model'!C19+2)+'DCF Model'!F45/(1+$B20)^('DCF Model'!C19+3)+'DCF Model'!G45/(1+$B20)^('DCF Model'!C19+4)+('DCF Model'!G39+'DCF Model'!G42)*D$17/(1+$B20)^('DCF Model'!C19+4)-'DCF Model'!C16)*1000000/'DCF Model'!C15,0),"") | E20: =IFERROR(ROUND(('DCF Model'!C45/(1+$B20)^('DCF Model'!C19+0)+'DCF Model'!D45/(1+$B20)^('DCF Model'!C19+1)+'DCF Model'!E45/(1+$B20)^('DCF Model'!C19+2)+'DCF Model'!F45/(1+$B20)^('DCF Model'!C19+3)+'DCF Model'!G45/(1+$B20)^('DCF Model'!C19+4)+('DCF Model'!G39+'DCF Model'!G42)*E$17/(1+$B20)^('DCF Model'!C19+4)-'DCF Model'!C16)*1000000/'DCF Model'!C15,0),"") | F20: =IFERROR(ROUND(('DCF Model'!C45/(1+$B20)^('DCF Model'!C19+0)+'DCF Model'!D45/(1+$B20)^('DCF Model'!C19+1)+'DCF Model'!E45/(1+$B20)^('DCF Model'!C19+2)+'DCF Model'!F45/(1+$B20)^('DCF Model'!C19+3)+'DCF Model'!G45/(1+$B20)^('DCF Model'!C19+4)+('DCF Model'!G39+'DCF Model'!G42)*F$17/(1+$B20)^('DCF Model'!C19+4)-'DCF Model'!C16)*1000000/'DCF Model'!C15,0),"") | G20: =IFERROR(ROUND(('DCF Model'!C45/(1+$B20)^('DCF Model'!C19+0)+'DCF Model'!D45/(1+$B20)^('DCF Model'!C19+1)+'DCF Model'!E45/(1+$B20)^('DCF Model'!C19+2)+'DCF Model'!F45/(1+$B20)^('DCF Model'!C19+3)+'DCF Model'!G45/(1+$B20)^('DCF Model'!C19+4)+('DCF Model'!G39+'DCF Model'!G42)*G$17/(1+$B20)^('DCF Model'!C19+4)-'DCF Model'!C16)*1000000/'DCF Model'!C15,0),"") | H20: =IFERROR(ROUND(('DCF Model'!C45/(1+$B20)^('DCF Model'!C19+0)+'DCF Model'!D45/(1+$B20)^('DCF Model'!C19+1)+'DCF Model'!E45/(1+$B20)^('DCF Model'!C19+2)+'DCF Model'!F45/(1+$B20)^('DCF Model'!C19+3)+'DCF Model'!G45/(1+$B20)^('DCF Model'!C19+4)+('DCF Model'!G39+'DCF Model'!G42)*H$17/(1+$B20)^('DCF Model'!C19+4)-'DCF Model'!C16)*1000000/'DCF Model'!C15,0),"") | I20: =IFERROR(ROUND(('DCF Model'!C45/(1+$B20)^('DCF Model'!C19+0)+'DCF Model'!D45/(1+$B20)^('DCF Model'!C19+1)+'DCF Model'!E45/(1+$B20)^('DCF Model'!C19+2)+'DCF Model'!F45/(1+$B20)^('DCF Model'!C19+3)+'DCF Model'!G45/(1+$B20)^('DCF Model'!C19+4)+('DCF Model'!G39+'DCF Model'!G42)*I$17/(1+$B20)^('DCF Model'!C19+4)-'DCF Model'!C16)*1000000/'DCF Model'!C15,0),"")
B21: =$C$3 | C21: =IFERROR(ROUND(('DCF Model'!C45/(1+$B21)^('DCF Model'!C19+0)+'DCF Model'!D45/(1+$B21)^('DCF Model'!C19+1)+'DCF Model'!E45/(1+$B21)^('DCF Model'!C19+2)+'DCF Model'!F45/(1+$B21)^('DCF Model'!C19+3)+'DCF Model'!G45/(1+$B21)^('DCF Model'!C19+4)+('DCF Model'!G39+'DCF Model'!G42)*C$17/(1+$B21)^('DCF Model'!C19+4)-'DCF Model'!C16)*1000000/'DCF Model'!C15,0),"") | D21: =IFERROR(ROUND(('DCF Model'!C45/(1+$B21)^('DCF Model'!C19+0)+'DCF Model'!D45/(1+$B21)^('DCF Model'!C19+1)+'DCF Model'!E45/(1+$B21)^('DCF Model'!C19+2)+'DCF Model'!F45/(1+$B21)^('DCF Model'!C19+3)+'DCF Model'!G45/(1+$B21)^('DCF Model'!C19+4)+('DCF Model'!G39+'DCF Model'!G42)*D$17/(1+$B21)^('DCF Model'!C19+4)-'DCF Model'!C16)*1000000/'DCF Model'!C15,0),"") | E21: =IFERROR(ROUND(('DCF Model'!C45/(1+$B21)^('DCF Model'!C19+0)+'DCF Model'!D45/(1+$B21)^('DCF Model'!C19+1)+'DCF Model'!E45/(1+$B21)^('DCF Model'!C19+2)+'DCF Model'!F45/(1+$B21)^('DCF Model'!C19+3)+'DCF Model'!G45/(1+$B21)^('DCF Model'!C19+4)+('DCF Model'!G39+'DCF Model'!G42)*E$17/(1+$B21)^('DCF Model'!C19+4)-'DCF Model'!C16)*1000000/'DCF Model'!C15,0),"") | F21: =IFERROR(ROUND(('DCF Model'!C45/(1+$B21)^('DCF Model'!C19+0)+'DCF Model'!D45/(1+$B21)^('DCF Model'!C19+1)+'DCF Model'!E45/(1+$B21)^('DCF Model'!C19+2)+'DCF Model'!F45/(1+$B21)^('DCF Model'!C19+3)+'DCF Model'!G45/(1+$B21)^('DCF Model'!C19+4)+('DCF Model'!G39+'DCF Model'!G42)*F$17/(1+$B21)^('DCF Model'!C19+4)-'DCF Model'!C16)*1000000/'DCF Model'!C15,0),"") | G21: =IFERROR(ROUND(('DCF Model'!C45/(1+$B21)^('DCF Model'!C19+0)+'DCF Model'!D45/(1+$B21)^('DCF Model'!C19+1)+'DCF Model'!E45/(1+$B21)^('DCF Model'!C19+2)+'DCF Model'!F45/(1+$B21)^('DCF Model'!C19+3)+'DCF Model'!G45/(1+$B21)^('DCF Model'!C19+4)+('DCF Model'!G39+'DCF Model'!G42)*G$17/(1+$B21)^('DCF Model'!C19+4)-'DCF Model'!C16)*1000000/'DCF Model'!C15,0),"") | H21: =IFERROR(ROUND(('DCF Model'!C45/(1+$B21)^('DCF Model'!C19+0)+'DCF Model'!D45/(1+$B21)^('DCF Model'!C19+1)+'DCF Model'!E45/(1+$B21)^('DCF Model'!C19+2)+'DCF Model'!F45/(1+$B21)^('DCF Model'!C19+3)+'DCF Model'!G45/(1+$B21)^('DCF Model'!C19+4)+('DCF Model'!G39+'DCF Model'!G42)*H$17/(1+$B21)^('DCF Model'!C19+4)-'DCF Model'!C16)*1000000/'DCF Model'!C15,0),"") | I21: =IFERROR(ROUND(('DCF Model'!C45/(1+$B21)^('DCF Model'!C19+0)+'DCF Model'!D45/(1+$B21)^('DCF Model'!C19+1)+'DCF Model'!E45/(1+$B21)^('DCF Model'!C19+2)+'DCF Model'!F45/(1+$B21)^('DCF Model'!C19+3)+'DCF Model'!G45/(1+$B21)^('DCF Model'!C19+4)+('DCF Model'!G39+'DCF Model'!G42)*I$17/(1+$B21)^('DCF Model'!C19+4)-'DCF Model'!C16)*1000000/'DCF Model'!C15,0),"")
B22: =$C$3+0.005 | C22: =IFERROR(ROUND(('DCF Model'!C45/(1+$B22)^('DCF Model'!C19+0)+'DCF Model'!D45/(1+$B22)^('DCF Model'!C19+1)+'DCF Model'!E45/(1+$B22)^('DCF Model'!C19+2)+'DCF Model'!F45/(1+$B22)^('DCF Model'!C19+3)+'DCF Model'!G45/(1+$B22)^('DCF Model'!C19+4)+('DCF Model'!G39+'DCF Model'!G42)*C$17/(1+$B22)^('DCF Model'!C19+4)-'DCF Model'!C16)*1000000/'DCF Model'!C15,0),"") | D22: =IFERROR(ROUND(('DCF Model'!C45/(1+$B22)^('DCF Model'!C19+0)+'DCF Model'!D45/(1+$B22)^('DCF Model'!C19+1)+'DCF Model'!E45/(1+$B22)^('DCF Model'!C19+2)+'DCF Model'!F45/(1+$B22)^('DCF Model'!C19+3)+'DCF Model'!G45/(1+$B22)^('DCF Model'!C19+4)+('DCF Model'!G39+'DCF Model'!G42)*D$17/(1+$B22)^('DCF Model'!C19+4)-'DCF Model'!C16)*1000000/'DCF Model'!C15,0),"") | E22: =IFERROR(ROUND(('DCF Model'!C45/(1+$B22)^('DCF Model'!C19+0)+'DCF Model'!D45/(1+$B22)^('DCF Model'!C19+1)+'DCF Model'!E45/(1+$B22)^('DCF Model'!C19+2)+'DCF Model'!F45/(1+$B22)^('DCF Model'!C19+3)+'DCF Model'!G45/(1+$B22)^('DCF Model'!C19+4)+('DCF Model'!G39+'DCF Model'!G42)*E$17/(1+$B22)^('DCF Model'!C19+4)-'DCF Model'!C16)*1000000/'DCF Model'!C15,0),"") | F22: =IFERROR(ROUND(('DCF Model'!C45/(1+$B22)^('DCF Model'!C19+0)+'DCF Model'!D45/(1+$B22)^('DCF Model'!C19+1)+'DCF Model'!E45/(1+$B22)^('DCF Model'!C19+2)+'DCF Model'!F45/(1+$B22)^('DCF Model'!C19+3)+'DCF Model'!G45/(1+$B22)^('DCF Model'!C19+4)+('DCF Model'!G39+'DCF Model'!G42)*F$17/(1+$B22)^('DCF Model'!C19+4)-'DCF Model'!C16)*1000000/'DCF Model'!C15,0),"") | G22: =IFERROR(ROUND(('DCF Model'!C45/(1+$B22)^('DCF Model'!C19+0)+'DCF Model'!D45/(1+$B22)^('DCF Model'!C19+1)+'DCF Model'!E45/(1+$B22)^('DCF Model'!C19+2)+'DCF Model'!F45/(1+$B22)^('DCF Model'!C19+3)+'DCF Model'!G45/(1+$B22)^('DCF Model'!C19+4)+('DCF Model'!G39+'DCF Model'!G42)*G$17/(1+$B22)^('DCF Model'!C19+4)-'DCF Model'!C16)*1000000/'DCF Model'!C15,0),"") | H22: =IFERROR(ROUND(('DCF Model'!C45/(1+$B22)^('DCF Model'!C19+0)+'DCF Model'!D45/(1+$B22)^('DCF Model'!C19+1)+'DCF Model'!E45/(1+$B22)^('DCF Model'!C19+2)+'DCF Model'!F45/(1+$B22)^('DCF Model'!C19+3)+'DCF Model'!G45/(1+$B22)^('DCF Model'!C19+4)+('DCF Model'!G39+'DCF Model'!G42)*H$17/(1+$B22)^('DCF Model'!C19+4)-'DCF Model'!C16)*1000000/'DCF Model'!C15,0),"") | I22: =IFERROR(ROUND(('DCF Model'!C45/(1+$B22)^('DCF Model'!C19+0)+'DCF Model'!D45/(1+$B22)^('DCF Model'!C19+1)+'DCF Model'!E45/(1+$B22)^('DCF Model'!C19+2)+'DCF Model'!F45/(1+$B22)^('DCF Model'!C19+3)+'DCF Model'!G45/(1+$B22)^('DCF Model'!C19+4)+('DCF Model'!G39+'DCF Model'!G42)*I$17/(1+$B22)^('DCF Model'!C19+4)-'DCF Model'!C16)*1000000/'DCF Model'!C15,0),"")
B23: =$C$3+0.01 | C23: =IFERROR(ROUND(('DCF Model'!C45/(1+$B23)^('DCF Model'!C19+0)+'DCF Model'!D45/(1+$B23)^('DCF Model'!C19+1)+'DCF Model'!E45/(1+$B23)^('DCF Model'!C19+2)+'DCF Model'!F45/(1+$B23)^('DCF Model'!C19+3)+'DCF Model'!G45/(1+$B23)^('DCF Model'!C19+4)+('DCF Model'!G39+'DCF Model'!G42)*C$17/(1+$B23)^('DCF Model'!C19+4)-'DCF Model'!C16)*1000000/'DCF Model'!C15,0),"") | D23: =IFERROR(ROUND(('DCF Model'!C45/(1+$B23)^('DCF Model'!C19+0)+'DCF Model'!D45/(1+$B23)^('DCF Model'!C19+1)+'DCF Model'!E45/(1+$B23)^('DCF Model'!C19+2)+'DCF Model'!F45/(1+$B23)^('DCF Model'!C19+3)+'DCF Model'!G45/(1+$B23)^('DCF Model'!C19+4)+('DCF Model'!G39+'DCF Model'!G42)*D$17/(1+$B23)^('DCF Model'!C19+4)-'DCF Model'!C16)*1000000/'DCF Model'!C15,0),"") | E23: =IFERROR(ROUND(('DCF Model'!C45/(1+$B23)^('DCF Model'!C19+0)+'DCF Model'!D45/(1+$B23)^('DCF Model'!C19+1)+'DCF Model'!E45/(1+$B23)^('DCF Model'!C19+2)+'DCF Model'!F45/(1+$B23)^('DCF Model'!C19+3)+'DCF Model'!G45/(1+$B23)^('DCF Model'!C19+4)+('DCF Model'!G39+'DCF Model'!G42)*E$17/(1+$B23)^('DCF Model'!C19+4)-'DCF Model'!C16)*1000000/'DCF Model'!C15,0),"") | F23: =IFERROR(ROUND(('DCF Model'!C45/(1+$B23)^('DCF Model'!C19+0)+'DCF Model'!D45/(1+$B23)^('DCF Model'!C19+1)+'DCF Model'!E45/(1+$B23)^('DCF Model'!C19+2)+'DCF Model'!F45/(1+$B23)^('DCF Model'!C19+3)+'DCF Model'!G45/(1+$B23)^('DCF Model'!C19+4)+('DCF Model'!G39+'DCF Model'!G42)*F$17/(1+$B23)^('DCF Model'!C19+4)-'DCF Model'!C16)*1000000/'DCF Model'!C15,0),"") | G23: =IFERROR(ROUND(('DCF Model'!C45/(1+$B23)^('DCF Model'!C19+0)+'DCF Model'!D45/(1+$B23)^('DCF Model'!C19+1)+'DCF Model'!E45/(1+$B23)^('DCF Model'!C19+2)+'DCF Model'!F45/(1+$B23)^('DCF Model'!C19+3)+'DCF Model'!G45/(1+$B23)^('DCF Model'!C19+4)+('DCF Model'!G39+'DCF Model'!G42)*G$17/(1+$B23)^('DCF Model'!C19+4)-'DCF Model'!C16)*1000000/'DCF Model'!C15,0),"") | H23: =IFERROR(ROUND(('DCF Model'!C45/(1+$B23)^('DCF Model'!C19+0)+'DCF Model'!D45/(1+$B23)^('DCF Model'!C19+1)+'DCF Model'!E45/(1+$B23)^('DCF Model'!C19+2)+'DCF Model'!F45/(1+$B23)^('DCF Model'!C19+3)+'DCF Model'!G45/(1+$B23)^('DCF Model'!C19+4)+('DCF Model'!G39+'DCF Model'!G42)*H$17/(1+$B23)^('DCF Model'!C19+4)-'DCF Model'!C16)*1000000/'DCF Model'!C15,0),"") | I23: =IFERROR(ROUND(('DCF Model'!C45/(1+$B23)^('DCF Model'!C19+0)+'DCF Model'!D45/(1+$B23)^('DCF Model'!C19+1)+'DCF Model'!E45/(1+$B23)^('DCF Model'!C19+2)+'DCF Model'!F45/(1+$B23)^('DCF Model'!C19+3)+'DCF Model'!G45/(1+$B23)^('DCF Model'!C19+4)+('DCF Model'!G39+'DCF Model'!G42)*I$17/(1+$B23)^('DCF Model'!C19+4)-'DCF Model'!C16)*1000000/'DCF Model'!C15,0),"")
B24: =$C$3+0.015 | C24: =IFERROR(ROUND(('DCF Model'!C45/(1+$B24)^('DCF Model'!C19+0)+'DCF Model'!D45/(1+$B24)^('DCF Model'!C19+1)+'DCF Model'!E45/(1+$B24)^('DCF Model'!C19+2)+'DCF Model'!F45/(1+$B24)^('DCF Model'!C19+3)+'DCF Model'!G45/(1+$B24)^('DCF Model'!C19+4)+('DCF Model'!G39+'DCF Model'!G42)*C$17/(1+$B24)^('DCF Model'!C19+4)-'DCF Model'!C16)*1000000/'DCF Model'!C15,0),"") | D24: =IFERROR(ROUND(('DCF Model'!C45/(1+$B24)^('DCF Model'!C19+0)+'DCF Model'!D45/(1+$B24)^('DCF Model'!C19+1)+'DCF Model'!E45/(1+$B24)^('DCF Model'!C19+2)+'DCF Model'!F45/(1+$B24)^('DCF Model'!C19+3)+'DCF Model'!G45/(1+$B24)^('DCF Model'!C19+4)+('DCF Model'!G39+'DCF Model'!G42)*D$17/(1+$B24)^('DCF Model'!C19+4)-'DCF Model'!C16)*1000000/'DCF Model'!C15,0),"") | E24: =IFERROR(ROUND(('DCF Model'!C45/(1+$B24)^('DCF Model'!C19+0)+'DCF Model'!D45/(1+$B24)^('DCF Model'!C19+1)+'DCF Model'!E45/(1+$B24)^('DCF Model'!C19+2)+'DCF Model'!F45/(1+$B24)^('DCF Model'!C19+3)+'DCF Model'!G45/(1+$B24)^('DCF Model'!C19+4)+('DCF Model'!G39+'DCF Model'!G42)*E$17/(1+$B24)^('DCF Model'!C19+4)-'DCF Model'!C16)*1000000/'DCF Model'!C15,0),"") | F24: =IFERROR(ROUND(('DCF Model'!C45/(1+$B24)^('DCF Model'!C19+0)+'DCF Model'!D45/(1+$B24)^('DCF Model'!C19+1)+'DCF Model'!E45/(1+$B24)^('DCF Model'!C19+2)+'DCF Model'!F45/(1+$B24)^('DCF Model'!C19+3)+'DCF Model'!G45/(1+$B24)^('DCF Model'!C19+4)+('DCF Model'!G39+'DCF Model'!G42)*F$17/(1+$B24)^('DCF Model'!C19+4)-'DCF Model'!C16)*1000000/'DCF Model'!C15,0),"") | G24: =IFERROR(ROUND(('DCF Model'!C45/(1+$B24)^('DCF Model'!C19+0)+'DCF Model'!D45/(1+$B24)^('DCF Model'!C19+1)+'DCF Model'!E45/(1+$B24)^('DCF Model'!C19+2)+'DCF Model'!F45/(1+$B24)^('DCF Model'!C19+3)+'DCF Model'!G45/(1+$B24)^('DCF Model'!C19+4)+('DCF Model'!G39+'DCF Model'!G42)*G$17/(1+$B24)^('DCF Model'!C19+4)-'DCF Model'!C16)*1000000/'DCF Model'!C15,0),"") | H24: =IFERROR(ROUND(('DCF Model'!C45/(1+$B24)^('DCF Model'!C19+0)+'DCF Model'!D45/(1+$B24)^('DCF Model'!C19+1)+'DCF Model'!E45/(1+$B24)^('DCF Model'!C19+2)+'DCF Model'!F45/(1+$B24)^('DCF Model'!C19+3)+'DCF Model'!G45/(1+$B24)^('DCF Model'!C19+4)+('DCF Model'!G39+'DCF Model'!G42)*H$17/(1+$B24)^('DCF Model'!C19+4)-'DCF Model'!C16)*1000000/'DCF Model'!C15,0),"") | I24: =IFERROR(ROUND(('DCF Model'!C45/(1+$B24)^('DCF Model'!C19+0)+'DCF Model'!D45/(1+$B24)^('DCF Model'!C19+1)+'DCF Model'!E45/(1+$B24)^('DCF Model'!C19+2)+'DCF Model'!F45/(1+$B24)^('DCF Model'!C19+3)+'DCF Model'!G45/(1+$B24)^('DCF Model'!C19+4)+('DCF Model'!G39+'DCF Model'!G42)*I$17/(1+$B24)^('DCF Model'!C19+4)-'DCF Model'!C16)*1000000/'DCF Model'!C15,0),"")
B26: All values dynamically linked to DCF Model. Headers auto-center on current WACC / Terminal g / Exit Multiple.

Sheet Segment Analysis
B2: Segment Analysis - 株式会社ＩＨＩ
C4: FY2024 | D4: FY2025 | E4: FY2026 | F4: FY2026(E) | G4: FY2027(E) | H4: FY2028(E) | I4: FY2029(E) | J4: FY2030(E)
B5: Resources, Energy & Environment (資源・エネルギー・環境)
B6: Revenue | C6: 369721 | D6: 402503 | E6: 408301 | F6: =E6*(1+CHOOSE('DCF Model'!$D$27,F39,F40,F41,F42,F43)) | G6: =F6*(1+CHOOSE('DCF Model'!$D$27,G39,G40,G41,G42,G43)) | H6: =G6*(1+CHOOSE('DCF Model'!$D$27,H39,H40,H41,H42,H43)) | I6: =H6*(1+CHOOSE('DCF Model'!$D$27,I39,I40,I41,I42,I43)) | J6: =I6*(1+CHOOSE('DCF Model'!$D$27,J39,J40,J41,J42,J43))
B7: Operating Profit | C7: 26264 | D7: 17715 | E7: 16136 | F7: =F6*CHOOSE('DCF Model'!$D$27,F46,F47,F48,F49,F50) | G7: =G6*CHOOSE('DCF Model'!$D$27,G46,G47,G48,G49,G50) | H7: =H6*CHOOSE('DCF Model'!$D$27,H46,H47,H48,H49,H50) | I7: =I6*CHOOSE('DCF Model'!$D$27,I46,I47,I48,I49,I50) | J7: =J6*CHOOSE('DCF Model'!$D$27,J46,J47,J48,J49,J50)
B8: OP Margin | C8: =C7/C6 | D8: =D7/D6 | E8: =E7/E6 | F8: =CHOOSE('DCF Model'!$D$27,F46,F47,F48,F49,F50) | G8: =CHOOSE('DCF Model'!$D$27,G46,G47,G48,G49,G50) | H8: =CHOOSE('DCF Model'!$D$27,H46,H47,H48,H49,H50) | I8: =CHOOSE('DCF Model'!$D$27,I46,I47,I48,I49,I50) | J8: =CHOOSE('DCF Model'!$D$27,J46,J47,J48,J49,J50)
B10: Social Infrastructure (社会基盤)
B11: Revenue | C11: 166155 | D11: 165394 | E11: 155910 | F11: =E11*(1+CHOOSE('DCF Model'!$D$27,F53,F54,F55,F56,F57)) | G11: =F11*(1+CHOOSE('DCF Model'!$D$27,G53,G54,G55,G56,G57)) | H11: =G11*(1+CHOOSE('DCF Model'!$D$27,H53,H54,H55,H56,H57)) | I11: =H11*(1+CHOOSE('DCF Model'!$D$27,I53,I54,I55,I56,I57)) | J11: =I11*(1+CHOOSE('DCF Model'!$D$27,J53,J54,J55,J56,J57))
B12: Operating Profit | C12: 17089 | D12: 15066 | E12: 9442 | F12: =F11*CHOOSE('DCF Model'!$D$27,F60,F61,F62,F63,F64) | G12: =G11*CHOOSE('DCF Model'!$D$27,G60,G61,G62,G63,G64) | H12: =H11*CHOOSE('DCF Model'!$D$27,H60,H61,H62,H63,H64) | I12: =I11*CHOOSE('DCF Model'!$D$27,I60,I61,I62,I63,I64) | J12: =J11*CHOOSE('DCF Model'!$D$27,J60,J61,J62,J63,J64)
B13: OP Margin | C13: =C12/C11 | D13: =D12/D11 | E13: =E12/E11 | F13: =CHOOSE('DCF Model'!$D$27,F60,F61,F62,F63,F64) | G13: =CHOOSE('DCF Model'!$D$27,G60,G61,G62,G63,G64) | H13: =CHOOSE('DCF Model'!$D$27,H60,H61,H62,H63,H64) | I13: =CHOOSE('DCF Model'!$D$27,I60,I61,I62,I63,I64) | J13: =CHOOSE('DCF Model'!$D$27,J60,J61,J62,J63,J64)
B15: Industrial Systems & General-Purpose Machinery (産業システム・汎用機械)
B16: Revenue | C16: 428195 | D16: 457132 | E16: 475644 | F16: =E16*(1+CHOOSE('DCF Model'!$D$27,F67,F68,F69,F70,F71)) | G16: =F16*(1+CHOOSE('DCF Model'!$D$27,G67,G68,G69,G70,G71)) | H16: =G16*(1+CHOOSE('DCF Model'!$D$27,H67,H68,H69,H70,H71)) | I16: =H16*(1+CHOOSE('DCF Model'!$D$27,I67,I68,I69,I70,I71)) | J16: =I16*(1+CHOOSE('DCF Model'!$D$27,J67,J68,J69,J70,J71))
B17: Operating Profit | C17: 18000 | D17: 12800 | E17: 10800 | F17: =F16*CHOOSE('DCF Model'!$D$27,F74,F75,F76,F77,F78) | G17: =G16*CHOOSE('DCF Model'!$D$27,G74,G75,G76,G77,G78) | H17: =H16*CHOOSE('DCF Model'!$D$27,H74,H75,H76,H77,H78) | I17: =I16*CHOOSE('DCF Model'!$D$27,I74,I75,I76,I77,I78) | J17: =J16*CHOOSE('DCF Model'!$D$27,J74,J75,J76,J77,J78)
B18: OP Margin | C18: =C17/C16 | D18: =D17/D16 | E18: =E17/E16 | F18: =CHOOSE('DCF Model'!$D$27,F74,F75,F76,F77,F78) | G18: =CHOOSE('DCF Model'!$D$27,G74,G75,G76,G77,G78) | H18: =CHOOSE('DCF Model'!$D$27,H74,H75,H76,H77,H78) | I18: =CHOOSE('DCF Model'!$D$27,I74,I75,I76,I77,I78) | J18: =CHOOSE('DCF Model'!$D$27,J74,J75,J76,J77,J78)
B20: Aero Engine, Space & Defense (航空・宇宙・防衛)
B21: Revenue | C21: 360272 | D21: 266896 | E21: 552700 | F21: =E21*(1+CHOOSE('DCF Model'!$D$27,F81,F82,F83,F84,F85)) | G21: =F21*(1+CHOOSE('DCF Model'!$D$27,G81,G82,G83,G84,G85)) | H21: =G21*(1+CHOOSE('DCF Model'!$D$27,H81,H82,H83,H84,H85)) | I21: =H21*(1+CHOOSE('DCF Model'!$D$27,I81,I82,I83,I84,I85)) | J21: =I21*(1+CHOOSE('DCF Model'!$D$27,J81,J82,J83,J84,J85))
B22: Operating Profit | C22: 36171 | D22: -102897 | E22: 122791 | F22: =F21*CHOOSE('DCF Model'!$D$27,F88,F89,F90,F91,F92) | G22: =G21*CHOOSE('DCF Model'!$D$27,G88,G89,G90,G91,G92) | H22: =H21*CHOOSE('DCF Model'!$D$27,H88,H89,H90,H91,H92) | I22: =I21*CHOOSE('DCF Model'!$D$27,I88,I89,I90,I91,I92) | J22: =J21*CHOOSE('DCF Model'!$D$27,J88,J89,J90,J91,J92)
B23: OP Margin | C23: =C22/C21 | D23: =D22/D21 | E23: =E22/E21 | F23: =CHOOSE('DCF Model'!$D$27,F88,F89,F90,F91,F92) | G23: =CHOOSE('DCF Model'!$D$27,G88,G89,G90,G91,G92) | H23: =CHOOSE('DCF Model'!$D$27,H88,H89,H90,H91,H92) | I23: =CHOOSE('DCF Model'!$D$27,I88,I89,I90,I91,I92) | J23: =CHOOSE('DCF Model'!$D$27,J88,J89,J90,J91,J92)
B25: Consolidated Total
B26: Total Revenue | C26: =C6+C11+C16+C21 | D26: =D6+D11+D16+D21 | E26: =E6+E11+E16+E21 | F26: =F6+F11+F16+F21 | G26: =G6+G11+G16+G21 | H26: =H6+H11+H16+H21 | I26: =I6+I11+I16+I21 | J26: =J6+J11+J16+J21
B27: Total Operating Profit | C27: =C7+C12+C17+C22 | D27: =D7+D12+D17+D22 | E27: =E7+E12+E17+E22 | F27: =F7+F12+F17+F22 | G27: =G7+G12+G17+G22 | H27: =H7+H12+H17+H22 | I27: =I7+I12+I17+I22 | J27: =J7+J12+J17+J22
B28: Total OP Margin | C28: =IFERROR(C27/C26,"—") | D28: =IFERROR(D27/D26,"—") | E28: =IFERROR(E27/E26,"—") | F28: =IFERROR(F27/F26,"—") | G28: =IFERROR(G27/G26,"—") | H28: =IFERROR(H27/H26,"—") | I28: =IFERROR(I27/I26,"—") | J28: =IFERROR(J27/J26,"—")
B30: Reconciliation vs DCF Model
B31: DCF Model Revenue | F31: ='DCF Model'!C33 | G31: ='DCF Model'!D33 | H31: ='DCF Model'!E33 | I31: ='DCF Model'!F33 | J31: ='DCF Model'!G33
B32: Segment Total Revenue | F32: =F26 | G32: =G26 | H32: =H26 | I32: =I26 | J32: =J26
B33: Difference | F33: =F32-F31 | G33: =G32-G31 | H33: =H32-H31 | I33: =I32-I31 | J33: =J32-J31
B36: Segment Scenario Input Matrix
F37: FY2026(E) | G37: FY2027(E) | H37: FY2028(E) | I37: FY2029(E) | J37: FY2030(E)
B38: Resources, Energy & Environment - Revenue Growth (YoY)
B39: Base | F39: 0.035 | G39: 0.04 | H39: 0.05 | I39: 0.06 | J39: 0.065
B40: Upside | F40: 0.06 | G40: 0.065 | H40: 0.075 | I40: 0.085 | J40: 0.09
B41: Management | F41: 0.04 | G41: 0.045 | H41: 0.055 | I41: 0.065 | J41: 0.07
B42: Downside 1 | F42: 0.005 | G42: 0.01 | H42: 0.02 | I42: 0.03 | J42: 0.035
B43: Downside 2 | F43: -0.02 | G43: -0.015 | H43: -0.005 | I43: 0.005 | J43: 0.01
B45: Resources, Energy & Environment - OP Margin
B46: Base | F46: 0.05 | G46: 0.055 | H46: 0.06 | I46: 0.065 | J46: 0.07
B47: Upside | F47: 0.065 | G47: 0.07 | H47: 0.075 | I47: 0.08 | J47: 0.085
B48: Management | F48: 0.05 | G48: 0.055 | H48: 0.06 | I48: 0.065 | J48: 0.07
B49: Downside 1 | F49: 0.03 | G49: 0.035 | H49: 0.04 | I49: 0.045 | J49: 0.05
B50: Downside 2 | F50: 0.015 | G50: 0.02 | H50: 0.025 | I50: 0.03 | J50: 0.035
...

Sheet Driver Analysis
B2: Driver Analysis - 株式会社ＩＨＩ
C4: FY2024 | D4: FY2025 | E4: FY2026 | F4: FY2026(E) | G4: FY2027(E) | H4: FY2028(E) | I4: FY2029(E) | J4: FY2030(E)
B5: Resources, Energy & Environment (資源・エネルギー・環境) [manual]
B6: Revenue (Direct Input) | C6: 369721 | D6: 402503 | E6: 408301 | F6: — | G6: — | H6: — | I6: — | J6: —
B7: YoY Growth | C7: — | D7: =IFERROR((D6-C6)/C6,"—") | E7: =IFERROR((E6-D6)/D6,"—") | F7: =IFERROR((F6-E6)/E6,"—") | G7: =IFERROR((G6-F6)/F6,"—") | H7: =IFERROR((H6-G6)/G6,"—") | I7: =IFERROR((I6-H6)/H6,"—") | J7: =IFERROR((J6-I6)/I6,"—")
B9: Social Infrastructure (社会基盤) [manual]
B10: Revenue (Direct Input) | C10: 166155 | D10: 165394 | E10: 155910 | F10: — | G10: — | H10: — | I10: — | J10: —
B11: YoY Growth | C11: — | D11: =IFERROR((D10-C10)/C10,"—") | E11: =IFERROR((E10-D10)/D10,"—") | F11: =IFERROR((F10-E10)/E10,"—") | G11: =IFERROR((G10-F10)/F10,"—") | H11: =IFERROR((H10-G10)/G10,"—") | I11: =IFERROR((I10-H10)/H10,"—") | J11: =IFERROR((J10-I10)/I10,"—")
B13: Industrial Systems & General-Purpose Machinery (産業システム・汎用機械) [growth_rate]
B14: Revenue Growth (YoY) | C14: — | D14: =(D15-C15)/C15 | E14: =(E15-D15)/D15 | F14: -0.02 | G14: 0.01 | H14: 0.02 | I14: 0.02 | J14: 0.025
B15: Revenue | C15: 428195 | D15: 457132 | E15: 475644 | F15: =E15*(1+F14) | G15: =F15*(1+G14) | H15: =G15*(1+H14) | I15: =H15*(1+I14) | J15: =I15*(1+J14)
B17: Aero Engine, Space & Defense (航空・宇宙・防衛) [manual]
B18: Revenue (Direct Input) | C18: 360272 | D18: 266896 | E18: 552700 | F18: — | G18: — | H18: — | I18: — | J18: —
B19: YoY Growth | C19: — | D19: =IFERROR((D18-C18)/C18,"—") | E19: =IFERROR((E18-D18)/D18,"—") | F19: =IFERROR((F18-E18)/E18,"—") | G19: =IFERROR((G18-F18)/F18,"—") | H19: =IFERROR((H18-G18)/G18,"—") | I19: =IFERROR((I18-H18)/H18,"—") | J19: =IFERROR((J18-I18)/I18,"—")
