Workbook

Sheet Cover
B4: KFC Holdings Japan, Ltd.
B6: Leveraged Buyout Analysis
B8: Reconstruction of Carlyle Group's Take-Private Transaction
B11: Target: | C11: KFC Holdings Japan (TSE: 9873)
B12: Acquirer: | C12: The Carlyle Group
B13: Announcement Date: | C13: May 20, 2024
B14: Closing Date: | C14: September 2024
B15: Units: | C15: JPY millions (March 31 fiscal year-end)
B17: Prepared by: Ryosuke Sato
B18: github.com/Ryosuke0369/ryosuke-japanese-equity-research
B21: Disclaimer
B22: This analysis is prepared solely for portfolio demonstration purposes and does not constitute investment advice, a recommendation, or an offer to buy or sell any securities. All financial data and projections are based on publicly available information and hypothetical assumptions. The author assumes no responsibility for any investment decisions made based on this material.

Sheet Transaction Assumptions
B1: KFC Holdings Japan — Transaction Assumptions
B2: (JPY millions, March 31 FYE)
B4: Transaction Structure
B6: TOB Price (JPY/share) | D6: 6500
B7: Pre-TOB Closing Price (JPY/share) | D7: 5398
B8: Acquisition Premium | D8: =D6/D7-1 -> 0.20414969
B10: Shares Outstanding (thousands) | D10: 22354
B11: Equity Value (JPY mm) | D11: =D6*D10/1000 -> 145301
B13: (+) Total Debt (JPY mm) | D13: 2845
B14: (-) Cash & Equivalents (JPY mm) | D14: 24636
B15: Enterprise Value (JPY mm) | D15: =D11+D13-D14 -> 123510
B17: Valuation Multiples
B19: LTM EBITDA (FY2024) | D19: 8275
B20: LTM Operating Income (FY2024) | D20: 5864
B21: LTM Net Income (FY2024) | D21: 4332
B23: EV / EBITDA | D23: =D15/D19 -> 14.92568
B24: EV / EBIT | D24: =D15/D20 -> 21.062415
B25: P / E | D25: =D11/D21 -> 33.54132
B28: Sources & Uses
B30: Sources | D30: Amount | E30: % | G30: Uses | I30: Amount
B31: Senior Loan (Term Loan A) | D31: 50000 | E31: =D31/$D$35 -> 0.32755526 | G31: Equity Value (Share Acquisition) | I31: ='Transaction Assumptions'!D11 -> 145301
B32: Senior Loan (Term Loan B) | D32: 25000 | E32: =D32/$D$35 -> 0.16377763 | G32: Existing Debt Refinancing | I32: ='Transaction Assumptions'!D13 -> 2845
B33: Mezzanine | D33: 0 | E33: =D33/$D$35 -> 0 | G33: Transaction Fees & Advisory | I33: 3000
B34: Sponsor Equity | D34: =D35-D31-D32-D33 -> 77646 | E34: =D34/$D$35 -> 0.50866711 | G34: Financing Fees | I34: 1500
B35: Total Sources | D35: =I35 -> 152646 | E35: 1 | G35: Total Uses | I35: =SUM(I31:I34) -> 152646
B38: Debt Terms
D40: Amount | E40: Rate | G40: Repayment | I40: Maturity (Yrs)
B41: Term Loan A | D41: =D31 -> 50000 | E41: 0.025 | G41: Amortizing | I41: 7
B42: Term Loan B | D42: =D32 -> 25000 | E42: 0.035 | G42: Bullet | I42: 7
B44: Total Debt | D44: =D41+D42 -> 75000
B46: Total Debt / EBITDA | D46: =D44/D19 -> 9.0634441
B47: Equity / Total Sources | D47: =D34/D35 -> 0.50866711

Sheet Income Statement
B1: (JPY millions, March 31 FYE)
B2: Income Statement
D4: Actual | J4: Projected
D5: FY2020 | E5: FY2021 | F5: FY2022 | G5: FY2023 | H5: FY2024 | J5: FY2025E | K5: FY2026E | L5: FY2027E | M5: FY2028E | N5: FY2029E
B7: Revenue | D7: 79634 | E7: 89652 | F7: 97520 | G7: 99926 | H7: 110685 | J7: =H7*(1+J8) -> 115112.4 | K7: =J7*(1+K8) -> 119141.33 | L7: =K7*(1+L8) -> 122715.57 | M7: =L7*(1+M8) -> 126397.04 | N7: =M7*(1+N8) -> 130188.95
B8: Revenue Growth | E8: =E7/D7-1 -> 0.12580054 | F8: =F7/E7-1 -> 0.087761567 | G8: =G7/F7-1 -> 0.024671862 | H8: =H7/G7-1 -> 0.10766968 | J8: 0.04 | K8: 0.035 | L8: 0.03 | M8: 0.03 | N8: 0.03
B10: Cost of Goods Sold | D10: 44674 | E10: 50954 | F10: 56610 | G10: 59395 | H10: 65367 | J10: =J7*J11 -> 67916.316 | K10: =K7*K11 -> 70055.104 | L10: =L7*L11 -> 71911.326 | M10: =M7*M11 -> 73942.269 | N10: =N7*N11 -> 76160.537
B11: COGS % Revenue | D11: =D10/D7 -> 0.56099154 | E11: =E10/E7 -> 0.56835319 | F11: =F10/F7 -> 0.58049631 | G11: =G10/G7 -> 0.59438985 | H11: =H10/H7 -> 0.59056783 | J11: 0.59 | K11: 0.588 | L11: 0.586 | M11: 0.585 | N11: 0.585
B13: Gross Profit | D13: =D7-D10 -> 34960 | E13: =E7-E10 -> 38698 | F13: =F7-F10 -> 40910 | G13: =G7-G10 -> 40531 | H13: =H7-H10 -> 45318 | J13: =J7-J10 -> 47196.084 | K13: =K7-K10 -> 49086.23 | L13: =L7-L10 -> 50804.248 | M13: =M7-M10 -> 52454.772 | N13: =N7-N10 -> 54028.415
B14: Gross Margin | D14: =D13/D7 -> 0.43900846 | E14: =E13/E7 -> 0.43164681 | F14: =F13/F7 -> 0.41950369 | G14: =G13/G7 -> 0.40561015 | H14: =H13/H7 -> 0.40943217 | J14: =J13/J7 -> 0.41 | K14: =K13/K7 -> 0.412 | L14: =L13/L7 -> 0.414 | M14: =M13/M7 -> 0.415 | N14: =N13/N7 -> 0.415
B16: SG&A Expenses | D16: 30173 | E16: 32344 | F16: 34802 | G16: 36909 | H16: 39454 | J16: =J7*J17 -> 39713.778 | K16: =K7*K17 -> 40508.054 | L16: =L7*L17 -> 41109.717 | M16: =M7*M17 -> 41711.024 | N16: =N7*N17 -> 42701.976
B17: SG&A % Revenue | D17: =D16/D7 -> 0.37889595 | E17: =E16/E7 -> 0.36077277 | F17: =F16/F7 -> 0.35687039 | G17: =G16/G7 -> 0.36936333 | H17: =H16/H7 -> 0.356453 | J17: 0.345 | K17: 0.34 | L17: 0.335 | M17: 0.33 | N17: 0.328
B19: Operating Income (EBIT) | D19: =D13-D16 -> 4787 | E19: =E13-E16 -> 6354 | F19: =F13-F16 -> 6108 | G19: =G13-G16 -> 3622 | H19: =H13-H16 -> 5864 | J19: =J13-J16 -> 7482.306 | K19: =K13-K16 -> 8578.176 | L19: =L13-L16 -> 9694.5303 | M19: =M13-M16 -> 10743.749 | N19: =N13-N16 -> 11326.439
B20: Operating Margin | D20: =D19/D7 -> 0.060112515 | E20: =E19/E7 -> 0.070874046 | F20: =F19/F7 -> 0.062633306 | G20: =G19/G7 -> 0.036246823 | H20: =H19/H7 -> 0.052979175 | J20: =J19/J7 -> 0.065 | K20: =K19/K7 -> 0.072 | L20: =L19/L7 -> 0.079 | M20: =M19/M7 -> 0.085 | N20: =N19/N7 -> 0.087
B22: Depreciation & Amortization | D22: 1955 | E22: 1477 | F22: 1463 | G22: 1924 | H22: 2411 | J22: =J7*J23 -> 2532.4728 | K22: =K7*K23 -> 2621.1093 | L22: =L7*L23 -> 2577.0271 | M22: =M7*M23 -> 2654.3379 | N22: =N7*N23 -> 2603.779
B23: D&A % Revenue | D23: =D22/D7 -> 0.024549815 | E23: =E22/E7 -> 0.016474814 | F23: =F22/F7 -> 0.015002051 | G23: =G22/G7 -> 0.019254248 | H23: =H22/H7 -> 0.021782536 | J23: 0.022 | K23: 0.022 | L23: 0.021 | M23: 0.021 | N23: 0.02
B25: EBITDA | D25: =D19+D22 -> 6742 | E25: =E19+E22 -> 7831 | F25: =F19+F22 -> 7571 | G25: =G19+G22 -> 5546 | H25: =H19+H22 -> 8275 | J25: =J19+J22 -> 10014.779 | K25: =K19+K22 -> 11199.285 | L25: =L19+L22 -> 12271.557 | M25: =M19+M22 -> 13398.086 | N25: =N19+N22 -> 13930.218
B26: EBITDA Margin | D26: =D25/D7 -> 0.08466233 | E26: =E25/E7 -> 0.08734886 | F26: =F25/F7 -> 0.077635357 | G26: =G25/G7 -> 0.055501071 | H26: =H25/H7 -> 0.074761711 | J26: =J25/J7 -> 0.087 | K26: =K25/K7 -> 0.094 | L26: =L25/L7 -> 0.1 | M26: =M25/M7 -> 0.106 | N26: =N25/N7 -> 0.107
B28: Interest Expense | D28: 10 | E28: 5 | F28: 5 | G28: 11 | H28: 55 | J28: ='Debt Schedule'!E34 -> 1857.1429 | K28: ='Debt Schedule'!F34 -> 1678.5714 | L28: ='Debt Schedule'!G34 -> 1500 | M28: ='Debt Schedule'!H34 -> 1321.4286 | N28: ='Debt Schedule'!I34 -> 1142.8571
B30: Earnings Before Tax (EBT) | D30: =D19-D28 -> 4777 | E30: =E19-E28 -> 6349 | F30: =F19-F28 -> 6103 | G30: =G19-G28 -> 3611 | H30: =H19-H28 -> 5809 | J30: =J19-J28 -> 5625.1631 | K30: =K19-K28 -> 6899.6046 | L30: =L19-L28 -> 8194.5303 | M30: =M19-M28 -> 9422.3199 | N30: =N19-N28 -> 10183.582
B32: Income Taxes | D32: 1854 | E32: 2316 | F32: 1952 | G32: 1757 | H32: 2646 | J32: =J30*J33 -> 1968.8071 | K32: =K30*K33 -> 2414.8616 | L32: =L30*L33 -> 2868.0856 | M32: =M30*M33 -> 3297.812 | N32: =N30*N33 -> 3564.2536
B33: Effective Tax Rate | D33: =D32/D30 -> 0.38810969 | E33: =E32/E30 -> 0.36478186 | F33: =F32/F30 -> 0.3198427 | G33: =G32/G30 -> 0.48656882 | H33: =H32/H30 -> 0.45550009 | J33: 0.35 | K33: 0.35 | L33: 0.35 | M33: 0.35 | N33: 0.35
B35: Net Income | D35: =D30-D32 -> 2923 | E35: =E30-E32 -> 4033 | F35: =F30-F32 -> 4151 | G35: =G30-G32 -> 1854 | H35: =H30-H32 -> 3163 | J35: =J30-J32 -> 3656.356 | K35: =K30-K32 -> 4484.743 | L35: =L30-L32 -> 5326.4447 | M35: =M30-M32 -> 6124.508 | N35: =N30-N32 -> 6619.3281
B36: Net Margin | D36: =D35/D7 -> 0.036705427 | E36: =E35/E7 -> 0.044985053 | F36: =F35/F7 -> 0.042565628 | G36: =G35/G7 -> 0.01855373 | H36: =H35/H7 -> 0.028576591 | J36: =J35/J7 -> 0.031763355 | K36: =K35/K7 -> 0.037642209 | L36: =L35/L7 -> 0.043404798 | M36: =M35/M7 -> 0.04845452 | N36: =N35/N7 -> 0.050844008
B38: Free Cash Flow Summary
B40: EBITDA | D40: =D25 -> 6742 | E40: =E25 -> 7831 | F40: =F25 -> 7571 | G40: =G25 -> 5546 | H40: =H25 -> 8275 | J40: =J25 -> 10014.779 | K40: =K25 -> 11199.285 | L40: =L25 -> 12271.557 | M40: =M25 -> 13398.086 | N40: =N25 -> 13930.218
B41: (-) Income Taxes | D41: =D32 -> 1854 | E41: =E32 -> 2316 | F41: =F32 -> 1952 | G41: =G32 -> 1757 | H41: =H32 -> 2646 | J41: =J32 -> 1968.8071 | K41: =K32 -> 2414.8616 | L41: =L32 -> 2868.0856 | M41: =M32 -> 3297.812 | N41: =N32 -> 3564.2536
B42: (-) Capital Expenditure | D42: 1867 | E42: 1740 | F42: 1853 | G42: 4360 | H42: 2550 | J42: =J7*J43 -> 2877.81 | K42: =K7*K43 -> 2978.5334 | L42: =L7*L43 -> 2945.1738 | M42: =M7*M43 -> 2907.1319 | N42: =N7*N43 -> 2994.3459
B43: Capex % Revenue | D43: =D42/D7 -> 0.02344476 | E43: =E42/E7 -> 0.019408379 | F43: =F42/F7 -> 0.019001231 | G43: =G42/G7 -> 0.043632288 | H43: =H42/H7 -> 0.023038352 | J43: 0.025 | K43: 0.025 | L43: 0.024 | M43: 0.023 | N43: 0.023
B44: (-) Change in Working Capital | D44: 500 | E44: 800 | F44: 600 | G44: 1200 | H44: 1000 | J44: 500 | K44: 500 | L44: 500 | M44: 500 | N44: 500
B46: Levered Free Cash Flow | D46: =D40-D41-D42-D44 -> 2521 | E46: =E40-E41-E42-E44 -> 2975 | F46: =F40-F41-F42-F44 -> 3166 | G46: =G40-G41-G42-G44 -> -1771 | H46: =H40-H41-H42-H44 -> 2079 | J46: =J40-J41-J42-J44 -> 4668.1617 | K46: =K40-K41-K42-K44 -> 5305.8904 | L46: =L40-L41-L42-L44 -> 5958.298 | M46: =M40-M41-M42-M44 -> 6693.1424 | N46: =N40-N41-N42-N44 -> 6871.6184

Sheet Transaction Summary
B1: KFC Holdings Japan — Transaction Summary
B2: (JPY millions)
B4: Company Overview
B6: Company | D6: KFC Holdings Japan, Ltd.
B7: Ticker | D7: TSE: 9873 (Delisted)
B8: Sector | D8: Quick-Service Restaurant (QSR)
B9: Brand | D9: Kentucky Fried Chicken
B10: Franchisor | D10: Yum! Brands, Inc.
B11: Major Shareholder (Pre-Deal) | D11: Mitsubishi Corporation 35.12%
B12: Acquirer | D12: The Carlyle Group
B13: Fiscal Year End | D13: March 31
B15: Key Financial Metrics (FY2024)
B17: Revenue | D17: ='Income Statement'!H7 -> 110685
B18: EBITDA | D18: ='Income Statement'!H25 -> 8275
B19: EBITDA Margin | D19: ='Income Statement'!H26 -> 0.074761711
B20: Operating Income | D20: ='Income Statement'!H19 -> 5864
B21: Net Income | D21: ='Income Statement'!H35 -> 3163
B23: Transaction Terms
B25: TOB Price | D25: ='Transaction Assumptions'!D6 -> 6500
B26: Acquisition Premium | D26: ='Transaction Assumptions'!D8 -> 0.20414969
B27: Equity Value | D27: ='Transaction Assumptions'!D11 -> 145301
B28: Enterprise Value | D28: ='Transaction Assumptions'!D15 -> 123510
B29: EV/EBITDA | D29: ='Transaction Assumptions'!D23 -> 14.92568
B30: P/E | D30: ='Transaction Assumptions'!D25 -> 33.54132
B32: Financing
B34: Total Debt | D34: ='Transaction Assumptions'!D44 -> 75000
B35: Sponsor Equity | D35: ='Transaction Assumptions'!D34 -> 77646
B36: Debt/EBITDA | D36: ='Transaction Assumptions'!D46 -> 9.0634441

Sheet Balance Sheet
B1: (JPY millions, March 31 FYE)
B2: Balance Sheet
D4: Pre-Deal | E4: Adj. | F4: Pro Forma | G4: FY2025E | H4: FY2026E | I4: FY2027E | J4: FY2028E | K4: FY2029E
D5: FY2024 | E5: +/- | F5: FY2024
B7: Assets
B8: Current Assets:
B9: Cash & Equivalents | D9: 24636 | E9: =-'Transaction Assumptions'!I33-'Transaction Assumptions'!I34 -> -4500 | F9: =D9+E9 -> 20136 | G9: ='Cash Flow Statement'!E47 -> 16364.089 | H9: ='Cash Flow Statement'!F47 -> 13319.318 | I9: ='Cash Flow Statement'!G47 -> 11104.651 | J9: ='Cash Flow Statement'!H47 -> 9814.562 | K9: ='Cash Flow Statement'!I47 -> 8893.7653
B10: Accounts Receivable | D10: 12805 | F10: =D10 -> 12805 | G10: ='Income Statement'!J7*$D$55/365 -> 13245.81 | H10: ='Income Statement'!K7*$D$55/365 -> 13709.414 | I10: ='Income Statement'!L7*$D$55/365 -> 14120.696 | J10: ='Income Statement'!M7*$D$55/365 -> 14544.317 | K10: ='Income Statement'!N7*$D$55/365 -> 14980.647
B11: Inventory | D11: 3200 | F11: =D11 -> 3200 | G11: ='Income Statement'!J10*$D$56/365 -> 3349.2978 | H11: ='Income Statement'!K10*$D$56/365 -> 3454.7723 | I11: ='Income Statement'!L10*$D$56/365 -> 3546.312 | J11: ='Income Statement'!M10*$D$56/365 -> 3646.4681 | K11: ='Income Statement'!N10*$D$56/365 -> 3755.8621
B12: Other Current Assets | D12: 2500 | F12: =D12 -> 2500 | G12: ='Income Statement'!J7*$D$58 -> 2647.5852 | H12: ='Income Statement'!K7*$D$58 -> 2740.2507 | I12: ='Income Statement'!L7*$D$58 -> 2822.4582 | J12: ='Income Statement'!M7*$D$58 -> 2907.1319 | K12: ='Income Statement'!N7*$D$58 -> 2994.3459
B13: Total Current Assets | D13: =SUM(D9:D12) -> 43141 | E13: =SUM(E9:E12) -> -4500 | F13: =SUM(F9:F12) -> 38641 | G13: =SUM(G9:G12) -> 35606.782 | H13: =SUM(H9:H12) -> 33223.755 | I13: =SUM(I9:I12) -> 31594.117 | J13: =SUM(J9:J12) -> 30912.479 | K13: =SUM(K9:K12) -> 30624.62
B15: Non-Current Assets:
B16: PP&E (Net) | D16: 8500 | F16: =D16 -> 8500 | G16: =F16+'Income Statement'!J42-'Income Statement'!J22 -> 8845.3372 | H16: =G16+'Income Statement'!K42-'Income Statement'!K22 -> 9202.7612 | I16: =H16+'Income Statement'!L42-'Income Statement'!L22 -> 9570.9079 | J16: =I16+'Income Statement'!M42-'Income Statement'!M22 -> 9823.702 | K16: =J16+'Income Statement'!N42-'Income Statement'!N22 -> 10214.269
B17: Intangible Assets | D17: 1200 | F17: =D17 -> 1200 | G17: =F17 -> 1200 | H17: =G17 -> 1200 | I17: =H17 -> 1200 | J17: =I17 -> 1200 | K17: =J17 -> 1200
B18: Goodwill | D18: 0 | E18: =E33-E9 -> 69512.143 | F18: =D18+E18 -> 69512.143 | G18: =F18 -> 69512.143 | H18: =F18 -> 69512.143 | I18: =F18 -> 69512.143 | J18: =F18 -> 69512.143 | K18: =F18 -> 69512.143
B19: Other Non-Current Assets | D19: 5900 | F19: =D19 -> 5900 | G19: =F19 -> 5900 | H19: =G19 -> 5900 | I19: =H19 -> 5900 | J19: =I19 -> 5900 | K19: =J19 -> 5900
B20: Total Non-Current Assets | D20: =SUM(D16:D19) -> 15600 | E20: =SUM(E16:E19) -> 69512.143 | F20: =SUM(F16:F19) -> 85112.143 | G20: =SUM(G16:G19) -> 85457.48 | H20: =SUM(H16:H19) -> 85814.904 | I20: =SUM(I16:I19) -> 86183.051 | J20: =SUM(J16:J19) -> 86435.845 | K20: =SUM(K16:K19) -> 86826.412
B22: Total Assets | D22: =D13+D20 -> 58741 | E22: =E13+E20 -> 65012.143 | F22: =F13+F20 -> 123753.14 | G22: =G13+G20 -> 121064.26 | H22: =H13+H20 -> 119038.66 | I22: =I13+I20 -> 117777.17 | J22: =J13+J20 -> 117348.32 | K22: =K13+K20 -> 117451.03
B24: Liabilities
B25: Current Liabilities:
B26: Accounts Payable | D26: 9800 | F26: =D26 -> 9800 | G26: ='Income Statement'!J10*$D$57/365 -> 10233.965 | H26: ='Income Statement'!K10*$D$57/365 -> 10556.249 | I26: ='Income Statement'!L10*$D$57/365 -> 10835.953 | J26: ='Income Statement'!M10*$D$57/365 -> 11141.986 | K26: ='Income Statement'!N10*$D$57/365 -> 11476.245
B27: Accrued Expenses | D27: 8500 | F27: =D27 -> 8500 | G27: ='Income Statement'!J7*$D$59 -> 8863.6548 | H27: ='Income Statement'!K7*$D$59 -> 9173.8827 | I27: ='Income Statement'!L7*$D$59 -> 9449.0992 | J27: ='Income Statement'!M7*$D$59 -> 9732.5722 | K27: ='Income Statement'!N7*$D$59 -> 10024.549
B28: Current Portion of LT Debt | D28: 0 | F28: ='Debt Schedule'!D10 -> 7142.8571 | G28: ='Debt Schedule'!E10 -> 7142.8571 | H28: ='Debt Schedule'!F10 -> 7142.8571 | I28: ='Debt Schedule'!G10 -> 7142.8571 | J28: ='Debt Schedule'!H10 -> 7142.8571 | K28: ='Debt Schedule'!I10 -> 7142.8571
B29: Other Current Liabilities | D29: 3700 | F29: =D29 -> 3700 | G29: =F29 -> 3700 | H29: =G29 -> 3700 | I29: =H29 -> 3700 | J29: =I29 -> 3700 | K29: =J29 -> 3700
B30: Total Current Liabilities | D30: =SUM(D26:D29) -> 22000 | E30: =SUM(E26:E29) -> 0 | F30: =SUM(F26:F29) -> 29142.857 | G30: =SUM(G26:G29) -> 29940.477 | H30: =SUM(H26:H29) -> 30572.988 | I30: =SUM(I26:I29) -> 31127.91 | J30: =SUM(J26:J29) -> 31717.415 | K30: =SUM(K26:K29) -> 32343.652
B32: Non-Current Liabilities:
B33: Long-Term Debt | D33: 2845 | E33: ='Debt Schedule'!D32-D33 -> 65012.143 | F33: ='Debt Schedule'!D32-F28 -> 60714.286 | G33: ='Debt Schedule'!E32-G28 -> 53571.429 | H33: ='Debt Schedule'!F32-H28 -> 46428.571 | I33: ='Debt Schedule'!G32-I28 -> 39285.714 | J33: ='Debt Schedule'!H32-J28 -> 32142.857 | K33: ='Debt Schedule'!I32-K28 -> 25000
B34: Other Non-Current Liabilities | D34: 3200 | F34: =D34 -> 3200 | G34: =F34 -> 3200 | H34: =G34 -> 3200 | I34: =H34 -> 3200 | J34: =I34 -> 3200 | K34: =J34 -> 3200
B35: Total Non-Current Liabilities | D35: =SUM(D33:D34) -> 6045 | E35: =SUM(E33:E34) -> 65012.143 | F35: =SUM(F33:F34) -> 63914.286 | G35: =SUM(G33:G34) -> 56771.429 | H35: =SUM(H33:H34) -> 49628.571 | I35: =SUM(I33:I34) -> 42485.714 | J35: =SUM(J33:J34) -> 35342.857 | K35: =SUM(K33:K34) -> 28200
B37: Total Liabilities | D37: =D30+D35 -> 28045 | E37: =E30+E35 -> 65012.143 | F37: =F30+F35 -> 93057.143 | G37: =G30+G35 -> 86711.906 | H37: =H30+H35 -> 80201.56 | I37: =I30+I35 -> 73613.624 | J37: =J30+J35 -> 67060.272 | K37: =K30+K35 -> 60543.652
B39: Shareholders' Equity
B40: Share Capital | D40: 7769 | F40: =D40 -> 7769 | G40: =F40 -> 7769 | H40: =G40 -> 7769 | I40: =H40 -> 7769 | J40: =I40 -> 7769 | K40: =J40 -> 7769
B41: Retained Earnings | D41: 23000 | F41: =D41 -> 23000 | G41: =F41+'Income Statement'!J35 -> 26656.356 | H41: =G41+'Income Statement'!K35 -> 31141.099 | I41: =H41+'Income Statement'!L35 -> 36467.544 | J41: =I41+'Income Statement'!M35 -> 42592.052 | K41: =J41+'Income Statement'!N35 -> 49211.38
B42: Other | D42: -73 | F42: =D42 -> -73 | G42: =F42 -> -73 | H42: =G42 -> -73 | I42: =H42 -> -73 | J42: =I42 -> -73 | K42: =J42 -> -73
B43: Total Shareholders' Equity | D43: =SUM(D40:D42) -> 30696 | E43: =SUM(E40:E42) -> 0 | F43: =SUM(F40:F42) -> 30696 | G43: =SUM(G40:G42) -> 34352.356 | H43: =SUM(H40:H42) -> 38837.099 | I43: =SUM(I40:I42) -> 44163.544 | J43: =SUM(J40:J42) -> 50288.052 | K43: =SUM(K40:K42) -> 56907.38
B45: Total Liabilities & Equity | D45: =D37+D43 -> 58741 | E45: =E37+E43 -> 65012.143 | F45: =F37+F43 -> 123753.14 | G45: =G37+G43 -> 121064.26 | H45: =H37+H43 -> 119038.66 | I45: =I37+I43 -> 117777.17 | J45: =J37+J43 -> 117348.32 | K45: =K37+K43 -> 117451.03
B47: Balance Check
B48: Total Assets - Total L&E | D48: =D22-D45 -> 0 | E48: =E22-E45 -> 0 | F48: =F22-F45 -> 0 | G48: =G22-G45 -> 0 | H48: =H22-H45 -> 0 | I48: =I22-I45 -> 0 | J48: =J22-J45 -> 0 | K48: =K22-K45 -> 0
B49: Check | D49: =IF(ABS(D48)<1,"✓ Balance","✗ Error") -> ✓ Balance | E49: =IF(ABS(E48)<1,"✓ Balance","✗ Error") -> ✓ Balance | F49: =IF(ABS(F48)<1,"✓ Balance","✗ Error") -> ✓ Balance | G49: =IF(ABS(G48)<1,"✓ Balance","✗ Error") -> ✓ Balance | H49: =IF(ABS(H48)<1,"✓ Balance","✗ Error") -> ✓ Balance | I49: =IF(ABS(I48)<1,"✓ Balance","✗ Error") -> ✓ Balance | J49: =IF(ABS(J48)<1,"✓ Balance","✗ Error") -> ✓ Balance | K49: =IF(ABS(K48)<1,"✓ Balance","✗ Error") -> ✓ Balance
B52: Working Capital Assumptions
...

Sheet Cash Flow Statement
B1: (JPY millions, March 31 FYE)
B2: Cash Flow Statement
D4: Pro Forma | E4: Year 1 | F4: Year 2 | G4: Year 3 | H4: Year 4 | I4: Year 5
D5: FY2024 | E5: FY2025E | F5: FY2026E | G5: FY2027E | H5: FY2028E | I5: FY2029E
B7: Cash Flow from Operations
B9: Net Income | D9: ='Income Statement'!H35 -> 3163 | E9: ='Income Statement'!J35 -> 3656.356 | F9: ='Income Statement'!K35 -> 4484.743 | G9: ='Income Statement'!L35 -> 5326.4447 | H9: ='Income Statement'!M35 -> 6124.508 | I9: ='Income Statement'!N35 -> 6619.3281
B10: (+) Interest Expense | D10: ='Debt Schedule'!D34 -> 2125 | E10: ='Debt Schedule'!E34 -> 1857.1429 | F10: ='Debt Schedule'!F34 -> 1678.5714 | G10: ='Debt Schedule'!G34 -> 1500 | H10: ='Debt Schedule'!H34 -> 1321.4286 | I10: ='Debt Schedule'!I34 -> 1142.8571
B11: (+) Depreciation & Amortization | D11: ='Income Statement'!H22 -> 2411 | E11: ='Income Statement'!J22 -> 2532.4728 | F11: ='Income Statement'!K22 -> 2621.1093 | G11: ='Income Statement'!L22 -> 2577.0271 | H11: ='Income Statement'!M22 -> 2654.3379 | I11: ='Income Statement'!N22 -> 2603.779
B12: (+) Goodwill Amortization | D12: 0 | E12: 0 | F12: 0 | G12: 0 | H12: 0 | I12: 0
B14: Working Capital Changes:
B15: Change in A/R | D15: =-('Balance Sheet'!F10-'Balance Sheet'!D10) -> 0 | E15: =-('Balance Sheet'!G10-'Balance Sheet'!F10) -> -440.81041 | F15: =-('Balance Sheet'!H10-'Balance Sheet'!G10) -> -463.60336 | G15: =-('Balance Sheet'!I10-'Balance Sheet'!H10) -> -411.28241 | H15: =-('Balance Sheet'!J10-'Balance Sheet'!I10) -> -423.62089 | I15: =-('Balance Sheet'!K10-'Balance Sheet'!J10) -> -436.32951
B16: Change in Inventory | D16: =-('Balance Sheet'!F11-'Balance Sheet'!D11) -> 0 | E16: =-('Balance Sheet'!G11-'Balance Sheet'!F11) -> -149.29778 | F16: =-('Balance Sheet'!H11-'Balance Sheet'!G11) -> -105.4745 | G16: =-('Balance Sheet'!I11-'Balance Sheet'!H11) -> -91.539714 | H16: =-('Balance Sheet'!J11-'Balance Sheet'!I11) -> -100.15608 | I16: =-('Balance Sheet'!K11-'Balance Sheet'!J11) -> -109.39404
B17: Change in Other Current Assets | D17: =-('Balance Sheet'!F12-'Balance Sheet'!D12) -> 0 | E17: =-('Balance Sheet'!G12-'Balance Sheet'!F12) -> -147.5852 | F17: =-('Balance Sheet'!H12-'Balance Sheet'!G12) -> -92.665482 | G17: =-('Balance Sheet'!I12-'Balance Sheet'!H12) -> -82.20752 | H17: =-('Balance Sheet'!J12-'Balance Sheet'!I12) -> -84.673746 | I17: =-('Balance Sheet'!K12-'Balance Sheet'!J12) -> -87.213958
B18: Change in A/P | D18: ='Balance Sheet'!F26-'Balance Sheet'!D26 -> 0 | E18: ='Balance Sheet'!G26-'Balance Sheet'!F26 -> 433.96542 | F18: ='Balance Sheet'!H26-'Balance Sheet'!G26 -> 322.28318 | G18: ='Balance Sheet'!I26-'Balance Sheet'!H26 -> 279.70468 | H18: ='Balance Sheet'!J26-'Balance Sheet'!I26 -> 306.03247 | I18: ='Balance Sheet'!K26-'Balance Sheet'!J26 -> 334.25957
B19: Change in Accrued Expenses | D19: ='Balance Sheet'!F27-'Balance Sheet'!D27 -> 0 | E19: ='Balance Sheet'!G27-'Balance Sheet'!F27 -> 363.6548 | F19: ='Balance Sheet'!H27-'Balance Sheet'!G27 -> 310.22792 | G19: ='Balance Sheet'!I27-'Balance Sheet'!H27 -> 275.21648 | H19: ='Balance Sheet'!J27-'Balance Sheet'!I27 -> 283.47298 | I19: ='Balance Sheet'!K27-'Balance Sheet'!J27 -> 291.97717
B20: Total Working Capital Change | D20: =SUM(D15:D19) -> 0 | E20: =SUM(E15:E19) -> 59.926838 | F20: =SUM(F15:F19) -> -29.232242 | G20: =SUM(G15:G19) -> -30.108484 | H20: =SUM(H15:H19) -> -18.945267 | I20: =SUM(I15:I19) -> -6.7007747
B22: Total Operating Cash Flow | D22: =D9+D10+D11+D12+D20 -> 7699 | E22: =E9+E10+E11+E12+E20 -> 8105.8985 | F22: =F9+F10+F11+F12+F20 -> 8755.1915 | G22: =G9+G10+G11+G12+G20 -> 9373.3633 | H22: =H9+H10+H11+H12+H20 -> 10081.329 | I22: =I9+I10+I11+I12+I20 -> 10359.264
B25: Cash Flow from Investing
B27: Capital Expenditure | D27: =-'Income Statement'!H42 -> -2550 | E27: =-'Income Statement'!J42 -> -2877.81 | F27: =-'Income Statement'!K42 -> -2978.5334 | G27: =-'Income Statement'!L42 -> -2945.1738 | H27: =-'Income Statement'!M42 -> -2907.1319 | I27: =-'Income Statement'!N42 -> -2994.3459
B29: Total Investing Cash Flow | D29: =D27 -> -2550 | E29: =E27 -> -2877.81 | F29: =F27 -> -2978.5334 | G29: =G27 -> -2945.1738 | H29: =H27 -> -2907.1319 | I29: =I27 -> -2994.3459
B32: Cash Flow from Financing
B34: TLA Repayment (Scheduled) | D34: =-'Debt Schedule'!D10 -> -7142.8571 | E34: =-'Debt Schedule'!E10 -> -7142.8571 | F34: =-'Debt Schedule'!F10 -> -7142.8571 | G34: =-'Debt Schedule'!G10 -> -7142.8571 | H34: =-'Debt Schedule'!H10 -> -7142.8571 | I34: =-'Debt Schedule'!I10 -> -7142.8571
B35: TLA Voluntary Prepayment | D35: =-'Debt Schedule'!D11 -> 0 | E35: =-'Debt Schedule'!E11 -> 0 | F35: =-'Debt Schedule'!F11 -> 0 | G35: =-'Debt Schedule'!G11 -> 0 | H35: =-'Debt Schedule'!H11 -> 0 | I35: =-'Debt Schedule'!I11 -> 0
B36: TLB Repayment | D36: =-'Debt Schedule'!D22 -> 0 | E36: =-'Debt Schedule'!E22 -> 0 | F36: =-'Debt Schedule'!F22 -> 0 | G36: =-'Debt Schedule'!G22 -> 0 | H36: =-'Debt Schedule'!H22 -> 0 | I36: =-'Debt Schedule'!I22 -> 0
B37: Interest Payments | D37: =-'Debt Schedule'!D34 -> -2125 | E37: =-'Debt Schedule'!E34 -> -1857.1429 | F37: =-'Debt Schedule'!F34 -> -1678.5714 | G37: =-'Debt Schedule'!G34 -> -1500 | H37: =-'Debt Schedule'!H34 -> -1321.4286 | I37: =-'Debt Schedule'!I34 -> -1142.8571
B38: Dividends | D38: 0 | E38: 0 | F38: 0 | G38: 0 | H38: 0 | I38: 0
B40: Total Financing Cash Flow | D40: =SUM(D34:D38) -> -9267.8571 | E40: =SUM(E34:E38) -> -9000 | F40: =SUM(F34:F38) -> -8821.4286 | G40: =SUM(G34:G38) -> -8642.8571 | H40: =SUM(H34:H38) -> -8464.2857 | I40: =SUM(I34:I38) -> -8285.7143
B43: Cash Summary
B45: Beginning Cash Balance | D45: ='Balance Sheet'!F9 -> 20136 | E45: ='Balance Sheet'!F9 -> 20136 | F45: =E47 -> 16364.089 | G45: =F47 -> 13319.318 | H45: =G47 -> 11104.651 | I45: =H47 -> 9814.562
B46: Net Change in Cash | D46: =D22+D29+D40 -> -4118.8571 | E46: =E22+E29+E40 -> -3771.9115 | F46: =F22+F29+F40 -> -3044.7704 | G46: =G22+G29+G40 -> -2214.6676 | H46: =H22+H29+H40 -> -1290.0885 | I46: =I22+I29+I40 -> -920.79666
B47: Ending Cash Balance | D47: =D45+D46 -> 16017.143 | E47: =E45+E46 -> 16364.089 | F47: =F45+F46 -> 13319.318 | G47: =G45+G46 -> 11104.651 | H47: =H45+H46 -> 9814.562 | I47: =I45+I46 -> 8893.7653
B50: Consistency Check
B52: CF Statement Ending Cash | D52: =D47 -> 16017.143 | E52: =E47 -> 16364.089 | F52: =F47 -> 13319.318 | G52: =G47 -> 11104.651 | H52: =H47 -> 9814.562 | I52: =I47 -> 8893.7653
B53: BS Cash & Equivalents | D53: ='Balance Sheet'!F9 -> 20136 | E53: ='Balance Sheet'!G9 -> 16364.089 | F53: ='Balance Sheet'!H9 -> 13319.318 | G53: ='Balance Sheet'!I9 -> 11104.651 | H53: ='Balance Sheet'!J9 -> 9814.562 | I53: ='Balance Sheet'!K9 -> 8893.7653
B54: Difference | D54: =D52-D53 -> -4118.8571 | E54: =E52-E53 -> 0 | F54: =F52-F53 -> 0 | G54: =G52-G53 -> 0 | H54: =H52-H53 -> 0 | I54: =I52-I53 -> 0
B55: Check | D55: =IF(ABS(D54)<1,"✓ Match","✗ Error") -> ✗ Error | E55: =IF(ABS(E54)<1,"✓ Match","✗ Error") -> ✓ Match | F55: =IF(ABS(F54)<1,"✓ Match","✗ Error") -> ✓ Match | G55: =IF(ABS(G54)<1,"✓ Match","✗ Error") -> ✓ Match | H55: =IF(ABS(H54)<1,"✓ Match","✗ Error") -> ✓ Match | I55: =IF(ABS(I54)<1,"✓ Match","✗ Error") -> ✓ Match

Sheet Debt Schedule
B1: (JPY millions, March 31 FYE)
B2: Debt Schedule
D4: Pro Forma | E4: Year 1 | F4: Year 2 | G4: Year 3 | H4: Year 4 | I4: Year 5
D5: FY2024 | E5: FY2025E | F5: FY2026E | G5: FY2027E | H5: FY2028E | I5: FY2029E
B7: Term Loan A (Amortizing)
B9: Beginning Balance | D9: ='Transaction Assumptions'!D31 -> 50000 | E9: =D13 -> 42857.143 | F9: =E13 -> 35714.286 | G9: =F13 -> 28571.429 | H9: =G13 -> 21428.571 | I9: =H13 -> 14285.714
B10: Scheduled Repayment | D10: ='Transaction Assumptions'!D31/'Transaction Assumptions'!I41 -> 7142.8571 | E10: ='Transaction Assumptions'!D31/'Transaction Assumptions'!I41 -> 7142.8571 | F10: ='Transaction Assumptions'!D31/'Transaction Assumptions'!I41 -> 7142.8571 | G10: ='Transaction Assumptions'!D31/'Transaction Assumptions'!I41 -> 7142.8571 | H10: ='Transaction Assumptions'!D31/'Transaction Assumptions'!I41 -> 7142.8571 | I10: ='Transaction Assumptions'!D31/'Transaction Assumptions'!I41 -> 7142.8571
B11: Voluntary Prepayment | D11: 0 | E11: 0 | F11: 0 | G11: 0 | H11: 0 | I11: 0
B13: Ending Balance | D13: =D9-D10-D11 -> 42857.143 | E13: =E9-E10-E11 -> 35714.286 | F13: =F9-F10-F11 -> 28571.429 | G13: =G9-G10-G11 -> 21428.571 | H13: =H9-H10-H11 -> 14285.714 | I13: =I9-I10-I11 -> 7142.8571
B15: Interest Rate | D15: ='Transaction Assumptions'!E41 -> 0.025 | E15: =$D$15 -> 0.025 | F15: =$D$15 -> 0.025 | G15: =$D$15 -> 0.025 | H15: =$D$15 -> 0.025 | I15: =$D$15 -> 0.025
B16: Interest Expense (TLA) | D16: =D9*D15 -> 1250 | E16: =(E9+E13)/2*E15 -> 982.14286 | F16: =(F9+F13)/2*F15 -> 803.57143 | G16: =(G9+G13)/2*G15 -> 625 | H16: =(H9+H13)/2*H15 -> 446.42857 | I16: =(I9+I13)/2*I15 -> 267.85714
B19: Term Loan B (Bullet)
B21: Beginning Balance | D21: ='Transaction Assumptions'!D32 -> 25000 | E21: =D24 -> 25000 | F21: =E24 -> 25000 | G21: =F24 -> 25000 | H21: =G24 -> 25000 | I21: =H24 -> 25000
B22: Repayment | D22: 0 | E22: 0 | F22: 0 | G22: 0 | H22: 0 | I22: 0
B24: Ending Balance | D24: =D21-D22 -> 25000 | E24: =E21-E22 -> 25000 | F24: =F21-F22 -> 25000 | G24: =G21-G22 -> 25000 | H24: =H21-H22 -> 25000 | I24: =I21-I22 -> 25000
B26: Interest Rate | D26: ='Transaction Assumptions'!E42 -> 0.035 | E26: =$D$26 -> 0.035 | F26: =$D$26 -> 0.035 | G26: =$D$26 -> 0.035 | H26: =$D$26 -> 0.035 | I26: =$D$26 -> 0.035
B27: Interest Expense (TLB) | D27: =D21*D26 -> 875 | E27: =E21*E26 -> 875 | F27: =F21*F26 -> 875 | G27: =G21*G26 -> 875 | H27: =H21*H26 -> 875 | I27: =I21*I26 -> 875
B30: Debt Summary
B32: Total Debt Outstanding | D32: =D13+D24 -> 67857.143 | E32: =E13+E24 -> 60714.286 | F32: =F13+F24 -> 53571.429 | G32: =G13+G24 -> 46428.571 | H32: =H13+H24 -> 39285.714 | I32: =I13+I24 -> 32142.857
B33: Total Principal Repayment | D33: =D10+D11+D22 -> 7142.8571 | E33: =E10+E11+E22 -> 7142.8571 | F33: =F10+F11+F22 -> 7142.8571 | G33: =G10+G11+G22 -> 7142.8571 | H33: =H10+H11+H22 -> 7142.8571 | I33: =I10+I11+I22 -> 7142.8571
B34: Total Interest Expense | D34: =D16+D27 -> 2125 | E34: =E16+E27 -> 1857.1429 | F34: =F16+F27 -> 1678.5714 | G34: =G16+G27 -> 1500 | H34: =H16+H27 -> 1321.4286 | I34: =I16+I27 -> 1142.8571
B36: Credit Metrics
B38: EBITDA | D38: ='Income Statement'!H25 -> 8275 | E38: ='Income Statement'!J25 -> 10014.779 | F38: ='Income Statement'!K25 -> 11199.285 | G38: ='Income Statement'!L25 -> 12271.557 | H38: ='Income Statement'!M25 -> 13398.086 | I38: ='Income Statement'!N25 -> 13930.218
B39: Total Debt / EBITDA | D39: =D32/D38 -> 8.200259 | E39: =E32/E38 -> 6.062469 | F39: =F32/F38 -> 4.7834685 | G39: =G32/G38 -> 3.7834294 | H39: =H32/H38 -> 2.9321885 | I39: =I32/I38 -> 2.3074195
B40: EBITDA / Interest (ICR) | D40: =IF(D34=0,"-",D38/D34) -> 3.8941176 | E40: =IF(E34=0,"-",E38/E34) -> 5.3925732 | F40: =IF(F34=0,"-",F38/F34) -> 6.6719147 | G40: =IF(G34=0,"-",G38/G34) -> 8.1810383 | H40: =IF(H34=0,"-",H38/H34) -> 10.139092 | I40: =IF(I34=0,"-",I38/I34) -> 12.188941
B41: (EBITDA - Capex) / Interest | D41: =IF(D34=0,"-",(D38-'Income Statement'!H42)/D34) -> 2.6941176 | E41: =IF(E34=0,"-",(E38-'Income Statement'!J42)/E34) -> 3.8429832 | F41: =IF(F34=0,"-",(F38-'Income Statement'!K42)/F34) -> 4.8974693 | G41: =IF(G34=0,"-",(G38-'Income Statement'!L42)/G34) -> 6.2175891 | H41: =IF(H34=0,"-",(H38-'Income Statement'!M42)/H34) -> 7.9391006 | I41: =IF(I34=0,"-",(I38-'Income Statement'!N42)/I34) -> 9.568888

Sheet Returns Analysis
B1: (JPY millions, March 31 FYE)
B2: Returns Analysis
D4: Entry | E4: Year 1 | F4: Year 2 | G4: Year 3 | H4: Year 4 | I4: Year 5
D5: FY2024 | E5: FY2025E | F5: FY2026E | G5: FY2027E | H5: FY2028E | I5: FY2029E
B7: Exit Assumptions
B9: Exit EV/EBITDA Multiple | E9: 15 | F9: 15 | G9: 15 | H9: 15 | I9: 15
B11: EBITDA (Exit Year) | E11: ='Debt Schedule'!E38 -> 10014.779 | F11: ='Debt Schedule'!F38 -> 11199.285 | G11: ='Debt Schedule'!G38 -> 12271.557 | H11: ='Debt Schedule'!H38 -> 13398.086 | I11: ='Debt Schedule'!I38 -> 13930.218
B13: Exit Enterprise Value | E13: =E9*E11 -> 150221.68 | F13: =F9*F11 -> 167989.28 | G13: =G9*G11 -> 184073.36 | H13: =H9*H11 -> 200971.3 | I13: =I9*I11 -> 208953.27
B15: (-) Exit Debt Outstanding | E15: ='Debt Schedule'!E32 -> 60714.286 | F15: ='Debt Schedule'!F32 -> 53571.429 | G15: ='Debt Schedule'!G32 -> 46428.571 | H15: ='Debt Schedule'!H32 -> 39285.714 | I15: ='Debt Schedule'!I32 -> 32142.857
B16: (+) Exit Cash | E16: 10000 | F16: 10000 | G16: 10000 | H16: 10000 | I16: 10000
B18: Exit Equity Value | E18: =E13-E15+E16 -> 99507.396 | F18: =F13-F15+F16 -> 124417.85 | G18: =G13-G15+G16 -> 147644.79 | H18: =H13-H15+H16 -> 171685.58 | I18: =I13-I15+I16 -> 186810.41
B21: Return Metrics
B23: Sponsor Equity (Investment) | D23: ='Transaction Assumptions'!D34 -> 77646
B25: MOIC | E25: =E18/$D$23 -> 1.2815521 | F25: =F18/$D$23 -> 1.602373 | G25: =G18/$D$23 -> 1.9015119 | H25: =H18/$D$23 -> 2.2111323 | I25: =I18/$D$23 -> 2.4059245
B27: IRR | E27: =IFERROR(E18/$D$23-1,"-") -> 0.28155212 | F27: =IFERROR((F18/$D$23)^(1/2)-1,"-") -> 0.26584872 | G27: =IFERROR((G18/$D$23)^(1/3)-1,"-") -> 0.23889076 | H27: =IFERROR((H18/$D$23)^(1/4)-1,"-") -> 0.21942104 | I27: =IFERROR((I18/$D$23)^(1/5)-1,"-") -> 0.1919455
B30: Sensitivity Analysis: Exit MOIC
B32: Exit EV/EBITDA → | D32: 12 | E32: 13 | F32: 14 | G32: 15 | H32: 16 | I32: 17
B33: Exit Year ↓
B34: Year 3 | D34: =(G11*D32-G15+G16)/$D$23 -> 1.427377 | E34: =(G11*E32-G15+G16)/$D$23 -> 1.585422 | F34: =(G11*F32-G15+G16)/$D$23 -> 1.7434669 | G34: =(G11*G32-G15+G16)/$D$23 -> 1.9015119 | H34: =(G11*H32-G15+G16)/$D$23 -> 2.0595568 | I34: =(G11*I32-G15+G16)/$D$23 -> 2.2176017
B35: Year 4 | D35: =(H11*D32-H15+H16)/$D$23 -> 1.6934719 | E35: =(H11*E32-H15+H16)/$D$23 -> 1.8660254 | F35: =(H11*F32-H15+H16)/$D$23 -> 2.0385789 | G35: =(H11*G32-H15+H16)/$D$23 -> 2.2111323 | H35: =(H11*H32-H15+H16)/$D$23 -> 2.3836858 | I35: =(H11*I32-H15+H16)/$D$23 -> 2.5562393
B36: Year 5 | D36: =(I11*D32-I15+I16)/$D$23 -> 1.8677042 | E36: =(I11*E32-I15+I16)/$D$23 -> 2.0471109 | F36: =(I11*F32-I15+I16)/$D$23 -> 2.2265177 | G36: =(I11*G32-I15+I16)/$D$23 -> 2.4059245 | H36: =(I11*H32-I15+I16)/$D$23 -> 2.5853312 | I36: =(I11*I32-I15+I16)/$D$23 -> 2.764738
B39: Sensitivity Analysis: IRR
B41: Exit EV/EBITDA → | D41: 12 | E41: 13 | F41: 14 | G41: 15 | H41: 16 | I41: 17
B42: Exit Year ↓
B43: Year 3 | D43: =IFERROR((D34^(1/3)-1),"-") -> 0.12593392 | E43: =IFERROR((E34^(1/3)-1),"-") -> 0.16604405 | F43: =IFERROR((F34^(1/3)-1),"-") -> 0.20356968 | G43: =IFERROR((G34^(1/3)-1),"-") -> 0.23889076 | H43: =IFERROR((H34^(1/3)-1),"-") -> 0.27230507 | I43: =IFERROR((I34^(1/3)-1),"-") -> 0.30405082
B44: Year 4 | D44: =IFERROR((D35^(1/4)-1),"-") -> 0.14076057 | E44: =IFERROR((E35^(1/4)-1),"-") -> 0.16877089 | F44: =IFERROR((F35^(1/4)-1),"-") -> 0.19490088 | G44: =IFERROR((G35^(1/4)-1),"-") -> 0.21942104 | H44: =IFERROR((H35^(1/4)-1),"-") -> 0.24254536 | I44: =IFERROR((I35^(1/4)-1),"-") -> 0.26444626
B45: Year 5 | D45: =IFERROR((D36^(1/5)-1),"-") -> 0.13308272 | E45: =IFERROR((E36^(1/5)-1),"-") -> 0.1540597 | F45: =IFERROR((F36^(1/5)-1),"-") -> 0.17361386 | G45: =IFERROR((G36^(1/5)-1),"-") -> 0.1919455 | H45: =IFERROR((H36^(1/5)-1),"-") -> 0.2092142 | I45: =IFERROR((I36^(1/5)-1),"-") -> 0.22554933
B48: Investment Thesis Summary
B50: 1. Brand Power | D50: KFC is a dominant QSR brand in Japan with 55+ years of history. Unique cultural tie to Christmas season drives strong seasonal demand.
B51: 2. Margin Expansion | D51: Operating margin improvement from ~5% to 7-8% through menu diversification (lunch/afternoon), digitization, and operational efficiency.
B52: 3. Store Expansion | D52: Carlyle's capital enables accelerated store openings in untapped domestic markets across Japan.
B53: 4. Exit Optionality | D53: Multiple exit paths: IPO re-listing, strategic sale (Yum! Brands direct acquisition), or secondary sale to another PE fund.
B54: 5. Downside Protection | D54: Stable cash flow generation, low pre-deal leverage, and strong brand equity provide resilience.
