Workbook

Sheet Executive Summary
B1: DISCLAIMER: This is a sample analysis for demonstration purposes only. It does not constitute investment advice.
B3: 株式会社コア (2359.T)
B4: Equity Research Report
B6: Company | C6: 株式会社コア
B7: Ticker | C7: 2359.T (TSE)
B8: Sector | C8: Information & Communication
B9: Current Price | C9: 2006
B10: Target Price (Mid) | C10: =ROUND(AVERAGE(C16:C19),0) -> 2815
B11: Recommendation | C11: =IF(C12>0.15,"BUY",IF(C12>0.05,"HOLD","SELL")) -> BUY
B12: Upside / Downside | C12: =(C10-C9)/C9 -> 0.40329013
B14: Valuation Summary
B15: Methodology | C15: Implied Value (JPY) | D15: vs Current Price
B16: DCF - Perpetuity Growth | C16: ='DCF Model'!C55 -> 3132 | D16: =(C16-C9)/C9 -> 0.56131605
B17: DCF - Exit Multiple | C17: ='DCF Model'!C64 -> 3629 | D17: =(C17-C9)/C9 -> 0.80907278
B18: Comps - EV/EBITDA Median | C18: ='Comps Analysis'!C27 -> 2384 | D18: =(C18-C9)/C9 -> 0.1884347
B19: Comps - PER Median | C19: ='Comps Analysis'!C28 -> 2114 | D19: =(C19-C9)/C9 -> 0.053838485
B21: Integrated Valuation Range | C21: =MIN(C16:C19)&" - "&MAX(C16:C19) -> 2114 - 3629
B23: Key Investment Thesis
B24: 1. Vision2029 Mid-term Plan: FY29/3 targets of JPY35bn rev / JPY5.25bn OP imply +9.7% revenue CAGR and OPM expansion 14.4%->15.0%. Customer Business +8.9% CAGR is the biggest about-face vs FY26's -3.0% decline.
B25: 2. Defense/Space Tech: Vision2029 explicitly elevates 'Space Tech' (small-satellite GNSS systems) to a strategic pillar within Industrial Tech. 4-layer moat (proprietary receiver + QZSS auth + security clearance + space heritage) intact.
B26: 3. Stock Business Pivot: Stock revenue mix targeted to grow 7%->20% over 3 years (JPY1.7bn -> JPY7.0bn, 4x). This drives OPM expansion across all segments and structurally improves earnings quality.
B28: Key Risks
B29: 1. Customer Business growth pivot from -3% FY26 actual to +8.9% CAGR target is the most aggressive turnaround in the plan; execution risk is highest here.
B30: 2. Stock business 4x scale-up requires sales-model transformation (one-shot SI -> recurring services); transition could pressure near-term revenue recognition.
B31: 3. Market reaction post-plan (5/9 close ~JPY2,006, +0.0% from pre-plan) suggests investors are skeptical of plan execution. Implied alpha remains deeply pessimistic.

Sheet Financial Statements
B2: 株式会社コア - Historical Financials (JPY mn)
C4: FY2020 | D4: FY2021 | E4: FY2022 | F4: FY2023 | G4: FY2024 | H4: FY2025
B5: Income Statement
B6: Revenue | C6: 20997.367 | D6: 20785.262 | E6: 21798.077 | F6: 22848.129 | G6: 23998.562 | H6: 24599.166
B7: COGS | C7: 15781.969 | D7: 15524.609 | E7: 16231.035 | F7: 16853.21 | G7: 17407.88 | H7: 17821.475
B8: Gross Profit | C8: =C6-C7 -> 5215.398 | D8: =D6-D7 -> 5260.653 | E8: =E6-E7 -> 5567.042 | F8: =F6-F7 -> 5994.919 | G8: =G6-G7 -> 6590.682 | H8: =H6-H7 -> 6777.691
B9: Gross Margin | C9: =C8/C6 -> 0.24838343 | D9: =D8/D6 -> 0.25309534 | E9: =E8/E6 -> 0.25539143 | F9: =F8/F6 -> 0.26238118 | G9: =G8/G6 -> 0.2746282 | H9: =H8/H6 -> 0.27552524
B10: SGA | C10: 3414.673 | D10: 3228.568 | E10: 3199.384 | F10: 3251.051 | G10: 3450.098 | H10: 3602.229
B11: Operating Income | C11: 1800.724 | D11: 2032.084 | E11: 2367.658 | F11: 2743.867 | G11: 3140.583 | H11: 3175.462
B12: Net Income | C12: 1172.735 | D12: 1423.358 | E12: 1622.716 | F12: 1968.404 | G12: 2270.704 | H12: 2242.34
B13: Operating Margin | C13: =C11/C6 -> 0.085759515 | D13: =D11/D6 -> 0.097765619 | E13: =E11/E6 -> 0.10861775 | F13: =F11/F6 -> 0.12009154 | G13: =G11/G6 -> 0.13086547 | H13: =H11/H6 -> 0.1290882
B14: Net Margin | C14: =C12/C6 -> 0.055851527 | D14: =D12/D6 -> 0.068479195 | E14: =E12/E6 -> 0.07444308 | F14: =F12/F6 -> 0.086151649 | G14: =G12/G6 -> 0.094618336 | H14: =H12/H6 -> 0.091155123
B15: Revenue Growth (YoY) | C15: n/a | D15: =(D6-C6)/C6 -> -0.010101505 | E15: =(E6-D6)/D6 -> 0.048727555 | F15: =(F6-E6)/E6 -> 0.048171772 | G15: =(G6-F6)/F6 -> 0.0503513 | H15: =(H6-G6)/G6 -> 0.025026666
B16: Operating Income Growth (YoY) | C16: n/a | D16: =(D11-C11)/C11 -> 0.12848166 | E16: =(E11-D11)/D11 -> 0.16513786 | F16: =(F11-E11)/E11 -> 0.15889499 | G16: =(G11-F11)/F11 -> 0.14458281 | H16: =(H11-G11)/G11 -> 0.0111059
B18: Cash Flow Statement
B19: Operating Cash Flow | C19: 1325.726 | D19: 1851.105 | E19: 1799.231 | F19: 1943.795 | G19: 2190.094 | H19: 2372.799
B20: Capex | C20: 166.493 | D20: 93.543 | E20: 72.084 | F20: 85.455 | G20: 93.4 | H20: 95.32
B21: Free Cash Flow | C21: =C19-C20 -> 1159.233 | D21: =D19-D20 -> 1757.562 | E21: =E19-E20 -> 1727.147 | F21: =F19-F20 -> 1858.34 | G21: =G19-G20 -> 2096.694 | H21: =H19-H20 -> 2277.479
B22: FCF Margin | C22: =C21/C6 -> 0.055208494 | D22: =D21/D6 -> 0.084558087 | E22: =E21/E6 -> 0.079233916 | F22: =F21/F6 -> 0.08133445 | G22: =G21/G6 -> 0.087367485 | H22: =H21/H6 -> 0.092583586
B23: Capex / Revenue | C23: =C20/C6 -> 0.0079292323 | D23: =D20/D6 -> 0.0045004484 | E23: =E20/E6 -> 0.0033068972 | F23: =F20/F6 -> 0.0037401312 | G23: =G20/G6 -> 0.0038918999 | H23: =H20/H6 -> 0.0038749281
B25: Balance Sheet Highlights
B26: Cash & Deposits | C26: 2658.886 | D26: 3636.219 | E26: 4700.235 | F26: 5586.934 | G26: 6300.075 | H26: 7586.071
B27: Short-term Debt | C27: 2592.9 | D27: 2109.7 | E27: 1963.6 | F27: 1812 | G27: 1734.8 | H27: 1412.4
B28: Net Debt (Cash) | C28: =C27-C26 -> -65.986 | D28: =D27-D26 -> -1526.519 | E28: =E27-E26 -> -2736.635 | F28: =F27-F26 -> -3774.934 | G28: =G27-G26 -> -4565.275 | H28: =H27-H26 -> -6173.671

Sheet DCF Model
B2: DCF Valuation Model - 株式会社コア
B4: Assumptions
B5: Capex / Revenue | C5: 0.0043090892
B6: Effective Tax Rate | C6: 0.3062
B7: Risk-Free Rate | C7: 0.023
B8: Beta | C8: 0.9
B9: Equity Risk Premium | C9: 0.065
B10: Size Premium | C10: 0.04
B11: After-tax Cost of Debt | C11: 0.005
B12: D/E Ratio | C12: 0
B13: Terminal Growth Rate | C13: 0.02
B14: Exit Multiple (EV/EBITDA) | C14: 8
B15: Fully Diluted Shares | C15: 14366101
B16: Net Debt (JPY mn) | C16: -7296.8
... B20: LTM Revenue (JPY mn) | C20: 26532
B22: WACC Calculation
B23: Cost of Equity (Ke) | C23: =C7+C8*C9+C10 -> 0.1215
B24: Weight of Equity | C24: =1/(1+C12) -> 1
B25: Weight of Debt | C25: =C12/(1+C12) -> 0
B26: WACC | C26: =C23*C24+C11*C25 -> 0.1215
B27: Active Scenario | C27: Management | D27: =MATCH(C27,{"Base","Upside","Management","Downside 1","Downside 2"},0) -> 3
B28: Projected Free Cash Flow
C29: FY2027(E) | D29: FY2028(E) | E29: FY2029(E) | F29: FY2030(E) | G29: FY2031(E)
B30: Revenue Growth (YoY) | C30: =(C33/C17)-1 -> 0.18081349 | D30: =(D33/C33)-1 -> 0.096818851 | E30: =(E33/D33)-1 -> 0.098868133 | F30: =(F33/E33)-1 -> 0.05928425 | G30: =(G33/F33)-1 -> 0.041951699
B31: COGS % of Revenue | C31: =IFERROR(C34/C33,0) -> 0.71204362 | D31: =IFERROR(D34/D33,0) -> 0.71155962 | E31: =IFERROR(E34/E33,0) -> 0.70808213 | F31: =IFERROR(F34/F33,0) -> 0.70351415 | G31: =IFERROR(G34/G33,0) -> 0.70115055
B32: SGA % of Revenue | C32: =CHOOSE($D$27,'Segment Analysis'!G79,'Segment Analysis'!G80,'Segment Analysis'!G81,'Segment Analysis'!G82,'Segment Analysis'!G83) -> 0.146 | D32: =CHOOSE($D$27,'Segment Analysis'!H79,'Segment Analysis'!H80,'Segment Analysis'!H81,'Segment Analysis'!H82,'Segment Analysis'!H83) -> 0.143 | E32: =CHOOSE($D$27,'Segment Analysis'!I79,'Segment Analysis'!I80,'Segment Analysis'!I81,'Segment Analysis'!I82,'Segment Analysis'!I83) -> 0.14 | F32: =CHOOSE($D$27,'Segment Analysis'!J79,'Segment Analysis'!J80,'Segment Analysis'!J81,'Segment Analysis'!J82,'Segment Analysis'!J83) -> 0.138 | G32: =CHOOSE($D$27,'Segment Analysis'!K79,'Segment Analysis'!K80,'Segment Analysis'!K81,'Segment Analysis'!K82,'Segment Analysis'!K83) -> 0.135
B33: Revenue | C33: ='Segment Analysis'!G21 -> 29047.027 | D33: ='Segment Analysis'!H21 -> 31859.327 | E33: ='Segment Analysis'!I21 -> 35009.199 | F33: ='Segment Analysis'!J21 -> 37084.693 | G33: ='Segment Analysis'!K21 -> 38640.459
B34: COGS | C34: =C33-C37-C39 -> 20682.75 | D34: =D33-D37-D39 -> 22669.811 | E34: =E33-E37-E39 -> 24789.388 | F34: =F33-F37-F39 -> 26089.606 | G34: =G33-G37-G39 -> 27092.779
B35: Gross Profit | C35: =C33-C34 -> 8364.2767 | D35: =D33-D34 -> 9189.5162 | E35: =E33-E34 -> 10219.811 | F35: =F33-F34 -> 10995.087 | G35: =G33-G34 -> 11547.68
B36: Gross Margin | C36: =C35/C33 -> 0.28795638 | D36: =D35/D33 -> 0.28844038 | E36: =E35/E33 -> 0.29191787 | F36: =F35/F33 -> 0.29648585 | G36: =G35/G33 -> 0.29884945
B37: SGA Expense | C37: =C33*C32 -> 4240.8659 | D37: =D33*D32 -> 4555.8837 | E37: =E33*E32 -> 4901.2879 | F37: =F33*F32 -> 5117.6876 | G37: =G33*G32 -> 5216.462
B38: Implied Operating Margin | C38: =C39/C33 -> 0.14195638 | D38: =D39/D33 -> 0.14544038 | E38: =E39/E33 -> 0.15191787 | F38: =F39/F33 -> 0.15848585 | G38: =G39/G33 -> 0.16384945
B39: Operating Income (EBIT) | C39: ='Segment Analysis'!G22 -> 4123.4108 | D39: ='Segment Analysis'!H22 -> 4633.6325 | E39: ='Segment Analysis'!I22 -> 5318.523 | F39: ='Segment Analysis'!J22 -> 5877.3989 | G39: ='Segment Analysis'!K22 -> 6331.218
B40: Less: Tax | C40: =MAX(0,C39*C6) -> 1262.5884 | D40: =MAX(0,D39*C6) -> 1418.8183 | E40: =MAX(0,E39*C6) -> 1628.5317 | F40: =MAX(0,F39*C6) -> 1799.6596 | G40: =MAX(0,G39*C6) -> 1938.6189
B41: NOPAT | C41: =C39-C40 -> 2860.8224 | D41: =D39-D40 -> 3214.8142 | E41: =E39-E40 -> 3689.9913 | F41: =F39-F40 -> 4077.7394 | G41: =G39-G40 -> 4392.599
B42: Plus: D&A | C42: 210 | D42: 210 | E42: 215 | F42: 220 | G42: 220
B43: Less: Capex | C43: 100 | D43: 105 | E43: 105 | F43: 110 | G43: 110
B44: Change in NWC | C44: ='NWC Schedule'!D19 -> 1179.0969 | D44: ='NWC Schedule'!E19 -> 648.61014 | E44: ='NWC Schedule'!F19 -> 824.02068 | F44: ='NWC Schedule'!G19 -> 550.61778 | G44: ='NWC Schedule'!H19 -> 410.46869
B45: Unlevered Free Cash Flow | C45: =C41+C42-C43-C44 -> 1791.7255 | D45: =D41+D42-D43-D44 -> 2671.2041 | E45: =E41+E42-E43-E44 -> 2975.9706 | F45: =F41+F42-F43-F44 -> 3637.1216 | G45: =G41+G42-G43-G44 -> 4092.1303
B46: Discount Factor | C46: =1/(1+C26)^(C19+0) -> 1 | D46: =1/(1+C26)^(C19+1) -> 0.89166295 | E46: =1/(1+C26)^(C19+2) -> 0.79506282 | F46: =1/(1+C26)^(C19+3) -> 0.70892806 | G46: =1/(1+C26)^(C19+4) -> 0.63212489
...

Sheet NWC Schedule
B2: NWC Schedule - 株式会社コア
B4: Working Capital Drivers (Days) | C4: Base Year | D4: FY2027(E) | E4: FY2028(E) | F4: FY2029(E) | G4: FY2030(E) | H4: FY2031(E)
B5: DSO (Days Sales Outstanding) | C5: =C12/C9*365 -> 116.89299 | D5: =CHOOSE('DCF Model'!$D$27,D25,D26,D27,D28,D29) -> 116 | E5: =CHOOSE('DCF Model'!$D$27,E25,E26,E27,E28,E29) -> 115 | F5: =CHOOSE('DCF Model'!$D$27,F25,F26,F27,F28,F29) -> 115 | G5: =CHOOSE('DCF Model'!$D$27,G25,G26,G27,G28,G29) -> 115 | H5: =CHOOSE('DCF Model'!$D$27,H25,H26,H27,H28,H29) -> 115
B6: DIH (Days Inventory Held) | C6: =C13/C10*365 -> 5.5093644 | D6: =CHOOSE('DCF Model'!$D$27,D32,D33,D34,D35,D36) -> 6 | E6: =CHOOSE('DCF Model'!$D$27,E32,E33,E34,E35,E36) -> 6 | F6: =CHOOSE('DCF Model'!$D$27,F32,F33,F34,F35,F36) -> 6 | G6: =CHOOSE('DCF Model'!$D$27,G32,G33,G34,G35,G36) -> 6 | H6: =CHOOSE('DCF Model'!$D$27,H32,H33,H34,H35,H36) -> 6
B7: DPO (Days Payable Outstanding) | C7: =C15/C10*365 -> 35.595819 | D7: =CHOOSE('DCF Model'!$D$27,D39,D40,D41,D42,D43) -> 35 | E7: =CHOOSE('DCF Model'!$D$27,E39,E40,E41,E42,E43) -> 35 | F7: =CHOOSE('DCF Model'!$D$27,F39,F40,F41,F42,F43) -> 35 | G7: =CHOOSE('DCF Model'!$D$27,G39,G40,G41,G42,G43) -> 35 | H7: =CHOOSE('DCF Model'!$D$27,H39,H40,H41,H42,H43) -> 35
B8: P&L Reference (JPY mn)
B9: Revenue | C9: 24599.166 | D9: ='DCF Model'!C33 -> 29047.027 | E9: ='DCF Model'!D33 -> 31859.327 | F9: ='DCF Model'!E33 -> 35009.199 | G9: ='DCF Model'!F33 -> 37084.693 | H9: ='DCF Model'!G33 -> 38640.459
B10: COGS | C10: 17821.475 | D10: ='DCF Model'!C34 -> 20682.75 | E10: ='DCF Model'!D34 -> 22669.811 | F10: ='DCF Model'!E34 -> 24789.388 | G10: ='DCF Model'!F34 -> 26089.606 | H10: ='DCF Model'!G34 -> 27092.779
B11: Working Capital Items (JPY mn)
B12: Accounts Receivable | C12: 7878 | D12: =D9*D5/365 -> 9231.3839 | E12: =E9*E5/365 -> 10037.87 | F12: =F9*F5/365 -> 11030.296 | G12: =G9*G5/365 -> 11684.218 | H12: =H9*H5/365 -> 12174.391
B13: Inventory | C13: 269 | D13: =D10*D6/365 -> 339.99042 | E13: =E10*E6/365 -> 372.65442 | F13: =F10*F6/365 -> 407.49679 | G13: =G10*G6/365 -> 428.87024 | H13: =H10*H6/365 -> 445.36075
B14: Current Assets (AR + Inv) | C14: =C12+C13 -> 8147 | D14: =D12+D13 -> 9571.3743 | E14: =E12+E13 -> 10410.525 | F14: =F12+F13 -> 11437.792 | G14: =G12+G13 -> 12113.089 | H14: =H12+H13 -> 12619.752
B15: Accounts Payable | C15: 1738 | D15: =D10*D7/365 -> 1983.2774 | E15: =E10*E7/365 -> 2173.8174 | F15: =F10*F7/365 -> 2377.0646 | G15: =G10*G7/365 -> 2501.7431 | H15: =H10*H7/365 -> 2597.9377
B16: Current Liabilities (AP) | C16: =C15 -> 1738 | D16: =D15 -> 1983.2774 | E16: =E15 -> 2173.8174 | F16: =F15 -> 2377.0646 | G16: =G15 -> 2501.7431 | H16: =H15 -> 2597.9377
B17: Net Working Capital (JPY mn)
B18: Net Working Capital | C18: =C14-C16 -> 6409 | D18: =D14-D16 -> 7588.0969 | E18: =E14-E16 -> 8236.7071 | F18: =F14-F16 -> 9060.7277 | G18: =G14-G16 -> 9611.3455 | H18: =H14-H16 -> 10021.814
B19: Change in NWC | C19: n/a | D19: =D18-C18 -> 1179.0969 | E19: =E18-D18 -> 648.61014 | F19: =F18-E18 -> 824.02068 | G19: =G18-F18 -> 550.61778 | H19: =H18-G18 -> 410.46869
B22: Scenario Input Matrix (Working Capital Days)
D23: FY2027(E) | E23: FY2028(E) | F23: FY2029(E) | G23: FY2030(E) | H23: FY2031(E)
B24: DSO (Days)
B25: Base | D25: 115 | E25: 114 | F25: 114 | G25: 114 | H25: 114
B26: Upside | D26: 113 | E26: 111 | F26: 109 | G26: 107 | H26: 107
B27: Management | D27: 116 | E27: 115 | F27: 115 | G27: 115 | H27: 115
B28: Downside 1 | D28: 118 | E28: 119 | F28: 120 | G28: 120 | H28: 120
B29: Downside 2 | D29: 120 | E29: 122 | F29: 124 | G29: 125 | H29: 125
B31: DIH (Days)
B32: Base | D32: 6 | E32: 6 | F32: 6 | G32: 6 | H32: 6
B33: Upside | D33: 5.5 | E33: 5.5 | F33: 5.5 | G33: 5.5 | H33: 5.5
B34: Management | D34: 6 | E34: 6 | F34: 6 | G34: 6 | H34: 6
B35: Downside 1 | D35: 6.5 | E35: 6.5 | F35: 7 | G35: 7 | H35: 7
B36: Downside 2 | D36: 7 | E36: 7 | F36: 7.5 | G36: 7.5 | H36: 7.5
B38: DPO (Days)
B39: Base | D39: 35 | E39: 34 | F39: 34 | G39: 34 | H39: 34
B40: Upside | D40: 36 | E40: 37 | F40: 38 | G40: 38 | H40: 38
B41: Management | D41: 35 | E41: 35 | F41: 35 | G41: 35 | H41: 35
B42: Downside 1 | D42: 34 | E42: 33 | F42: 33 | G42: 33 | H42: 33
B43: Downside 2 | D43: 33 | E43: 32 | F43: 32 | G43: 32 | H43: 32

Sheet Comps Analysis
B2: Comparable Company Analysis
B4: Company | C4: Ticker | D4: Mkt Cap (JPY mn) | E4: EV (JPY mn) | F4: Revenue (JPY mn) | G4: EBITDA (JPY mn) | H4: Op Income (JPY mn) | I4: Net Income (JPY mn) | J4: EV/EBITDA | K4: EV/Revenue | L4: PER | M4: PBR | N4: Op Margin | O4: ROE
B5: Systena | C5: 2317.T | D5: 154778.39 | E5: 156328.39 | F5: 92410 | G5: 15820 | H5: 15360 | I5: 11250 | J5: =E5/G5 -> 9.8816932 | K5: =E5/F5 -> 1.6916826 | L5: =D5/I5 -> 13.758079 | M5: 4.6973714 | N5: =H5/F5 -> 0.16621578 | O5: 0.3414264
B6: SRA HD | C6: 3817.T | D6: 56599.822 | E6: 56669.822 | F6: 54700 | G6: 8490 | H6: 8300 | I6: 5000 | J6: =E6/G6 -> 6.6748907 | K6: =E6/F6 -> 1.0360114 | L6: =D6/I6 -> 11.319964 | M6: 1.8197544 | N6: =H6/F6 -> 0.15173675 | O6: 0.1607562
B7: CEC | C7: 9692.T | D7: 61547.037 | E7: 61897.037 | F7: 65000 | G7: 8018 | H7: 7200 | I7: 5150 | J7: =E7/G7 -> 7.7197601 | K7: =E7/F7 -> 0.9522621 | L7: =D7/I7 -> 11.950881 | M7: 1.5234038 | N7: =H7/F7 -> 0.11076923 | O7: 0.12747209
B8: Cresco | C8: 4674.T | D8: 56557.072 | E8: 54057.072 | F8: 48000 | G8: 6800 | H8: 5200 | I8: 3600 | J8: =E8/G8 -> 7.9495695 | K8: =E8/F8 -> 1.126189 | L8: =D8/I8 -> 15.710298 | M8: 2.570776 | N8: =H8/F8 -> 0.10833333 | O8: 0.16363636
B9: DTS | C9: 9682.T | D9: 157587.31 | E9: 154587.31 | F9: 47000 | G9: 7500 | H9: 5700 | I9: 3900 | J9: =E9/G9 -> 20.611641 | K9: =E9/F9 -> 3.2890917 | L9: =D9/I9 -> 40.407002 | M9: 5.6281182 | N9: =H9/F9 -> 0.1212766 | O9: 0.13928571
B14: Statistics
B15: 25th Percentile | D15: =PERCENTILE(J5:J9,0.25) -> 7.7197601 | E15: =PERCENTILE(K5:K9,0.25) -> 1.0360114 | F15: =PERCENTILE(L5:L9,0.25) -> 11.950881 | G15: =PERCENTILE(M5:M9,0.25) -> 1.8197544 | H15: =PERCENTILE(N5:N9,0.25) -> 0.11076923 | I15: =PERCENTILE(O5:O9,0.25) -> 0.13928571
B16: Median (50th) | D16: =MEDIAN(J5:J9) -> 7.9495695 | E16: =MEDIAN(K5:K9) -> 1.126189 | F16: =MEDIAN(L5:L9) -> 13.758079 | G16: =MEDIAN(M5:M9) -> 2.570776 | H16: =MEDIAN(N5:N9) -> 0.1212766 | I16: =MEDIAN(O5:O9) -> 0.1607562
B17: 75th Percentile | D17: =PERCENTILE(J5:J9,0.75) -> 9.8816932 | E17: =PERCENTILE(K5:K9,0.75) -> 1.6916826 | F17: =PERCENTILE(L5:L9,0.75) -> 15.710298 | G17: =PERCENTILE(M5:M9,0.75) -> 4.6973714 | H17: =PERCENTILE(N5:N9,0.75) -> 0.15173675 | I17: =PERCENTILE(O5:O9,0.75) -> 0.16363636
B19: Implied Valuation for 株式会社コア
B20: 株式会社コア Financials
B21: EBITDA (JPY mn) | C21: 3391
B22: Net Income (JPY mn) | C22: 2207
B23: Shares Outstanding | C23: 14366101
B24: Net Debt (JPY mn) | C24: -7296.8
B26: Implied Share Price (Median Multiples)
B27: Via EV/EBITDA (Median) | C27: =ROUND((C21*D16-C24)*1000000/C23,0) -> 2384
B28: Via PER (Median) | C28: =ROUND(C22*F16*1000000/C23,0) -> 2114

Sheet Sensitivity Analysis
B2: Sensitivity Analysis
B3: Current WACC: | C3: ='DCF Model'!C26 -> 0.1215 | E3: Terminal g: | F3: ='DCF Model'!C13 -> 0.02 | H3: Exit Multiple: | I3: ='DCF Model'!C14 -> 8
B5: Table 1: WACC vs Terminal Growth Rate (PGM - Implied Share Price, JPY)
B6: WACC \ Terminal g | C6: =$F$3-0.0075 -> 0.0125 | D6: =$F$3-0.005 -> 0.015 | E6: =$F$3-0.0025 -> 0.0175 | F6: =$F$3 -> 0.02 | G6: =$F$3+0.0025 -> 0.0225 | H6: =$F$3+0.005 -> 0.025 | I6: =$F$3+0.0075 -> 0.0275
B7: =$C$3-0.015 -> 0.1065 | C7: =IFERROR(ROUND(('DCF Model'!C45/(1+$B7)^('DCF Model'!C19+0)+'DCF Model'!D45/(1+$B7)^('DCF Model'!C19+1)+'DCF Model'!E45/(1+$B7)^('DCF Model'!C19+2)+'DCF Model'!F45/(1+$B7)^('DCF Model'!C19+3)+'DCF Model'!G45/(1+$B7)^('DCF Model'!C19+4)+'DCF Model'!G45*(1+C$6)/($B7-C$6)/(1+$B7)^('DCF Model'!C19+4)-'DCF Model'!C16)*1000000/'DCF Model'!C15,0),"") -> 3394 | D7: =IFERROR(ROUND(('DCF Model'!C45/(1+$B7)^('DCF Model'!C19+0)+'DCF Model'!D45/(1+$B7)^('DCF Model'!C19+1)+'DCF Model'!E45/(1+$B7)^('DCF Model'!C19+2)+'DCF Model'!F45/(1+$B7)^('DCF Model'!C19+3)+'DCF Model'!G45/(1+$B7)^('DCF Model'!C19+4)+'DCF Model'!G45*(1+D$6)/($B7-D$6)/(1+$B7)^('DCF Model'!C19+4)-'DCF Model'!C16)*1000000/'DCF Model'!C15,0),"") -> 3455 | E7: =IFERROR(ROUND(('DCF Model'!C45/(1+$B7)^('DCF Model'!C19+0)+'DCF Model'!D45/(1+$B7)^('DCF Model'!C19+1)+'DCF Model'!E45/(1+$B7)^('DCF Model'!C19+2)+'DCF Model'!F45/(1+$B7)^('DCF Model'!C19+3)+'DCF Model'!G45/(1+$B7)^('DCF Model'!C19+4)+'DCF Model'!G45*(1+E$6)/($B7-E$6)/(1+$B7)^('DCF Model'!C19+4)-'DCF Model'!C16)*1000000/'DCF Model'!C15,0),"") -> 3519 | F7: =IFERROR(ROUND(('DCF Model'!C45/(1+$B7)^('DCF Model'!C19+0)+'DCF Model'!D45/(1+$B7)^('DCF Model'!C19+1)+'DCF Model'!E45/(1+$B7)^('DCF Model'!C19+2)+'DCF Model'!F45/(1+$B7)^('DCF Model'!C19+3)+'DCF Model'!G45/(1+$B7)^('DCF Model'!C19+4)+'DCF Model'!G45*(1+F$6)/($B7-F$6)/(1+$B7)^('DCF Model'!C19+4)-'DCF Model'!C16)*1000000/'DCF Model'!C15,0),"") -> 3588 | G7: =IFERROR(ROUND(('DCF Model'!C45/(1+$B7)^('DCF Model'!C19+0)+'DCF Model'!D45/(1+$B7)^('DCF Model'!C19+1)+'DCF Model'!E45/(1+$B7)^('DCF Model'!C19+2)+'DCF Model'!F45/(1+$B7)^('DCF Model'!C19+3)+'DCF Model'!G45/(1+$B7)^('DCF Model'!C19+4)+'DCF Model'!G45*(1+G$6)/($B7-G$6)/(1+$B7)^('DCF Model'!C19+4)-'DCF Model'!C16)*1000000/'DCF Model'!C15,0),"") -> 3660 | H7: =IFERROR(ROUND(('DCF Model'!C45/(1+$B7)^('DCF Model'!C19+0)+'DCF Model'!D45/(1+$B7)^('DCF Model'!C19+1)+'DCF Model'!E45/(1+$B7)^('DCF Model'!C19+2)+'DCF Model'!F45/(1+$B7)^('DCF Model'!C19+3)+'DCF Model'!G45/(1+$B7)^('DCF Model'!C19+4)+'DCF Model'!G45*(1+H$6)/($B7-H$6)/(1+$B7)^('DCF Model'!C19+4)-'DCF Model'!C16)*1000000/'DCF Model'!C15,0),"") -> 3737 | I7: =IFERROR(ROUND(('DCF Model'!C45/(1+$B7)^('DCF Model'!C19+0)+'DCF Model'!D45/(1+$B7)^('DCF Model'!C19+1)+'DCF Model'!E45/(1+$B7)^('DCF Model'!C19+2)+'DCF Model'!F45/(1+$B7)^('DCF Model'!C19+3)+'DCF Model'!G45/(1+$B7)^('DCF Model'!C19+4)+'DCF Model'!G45*(1+I$6)/($B7-I$6)/(1+$B7)^('DCF Model'!C19+4)-'DCF Model'!C16)*1000000/'DCF Model'!C15,0),"") -> 3818
B8: =$C$3-0.01 -> 0.1115 | C8: =IFERROR(ROUND(('DCF Model'!C45/(1+$B8)^('DCF Model'!C19+0)+'DCF Model'!D45/(1+$B8)^('DCF Model'!C19+1)+'DCF Model'!E45/(1+$B8)^('DCF Model'!C19+2)+'DCF Model'!F45/(1+$B8)^('DCF Model'!C19+3)+'DCF Model'!G45/(1+$B8)^('DCF Model'!C19+4)+'DCF Model'!G45*(1+C$6)/($B8-C$6)/(1+$B8)^('DCF Model'!C19+4)-'DCF Model'!C16)*1000000/'DCF Model'!C15,0),"") -> 3247 | D8: =IFERROR(ROUND(('DCF Model'!C45/(1+$B8)^('DCF Model'!C19+0)+'DCF Model'!D45/(1+$B8)^('DCF Model'!C19+1)+'DCF Model'!E45/(1+$B8)^('DCF Model'!C19+2)+'DCF Model'!F45/(1+$B8)^('DCF Model'!C19+3)+'DCF Model'!G45/(1+$B8)^('DCF Model'!C19+4)+'DCF Model'!G45*(1+D$6)/($B8-D$6)/(1+$B8)^('DCF Model'!C19+4)-'DCF Model'!C16)*1000000/'DCF Model'!C15,0),"") -> 3302 | E8: =IFERROR(ROUND(('DCF Model'!C45/(1+$B8)^('DCF Model'!C19+0)+'DCF Model'!D45/(1+$B8)^('DCF Model'!C19+1)+'DCF Model'!E45/(1+$B8)^('DCF Model'!C19+2)+'DCF Model'!F45/(1+$B8)^('DCF Model'!C19+3)+'DCF Model'!G45/(1+$B8)^('DCF Model'!C19+4)+'DCF Model'!G45*(1+E$6)/($B8-E$6)/(1+$B8)^('DCF Model'!C19+4)-'DCF Model'!C16)*1000000/'DCF Model'!C15,0),"") -> 3359 | F8: =IFERROR(ROUND(('DCF Model'!C45/(1+$B8)^('DCF Model'!C19+0)+'DCF Model'!D45/(1+$B8)^('DCF Model'!C19+1)+'DCF Model'!E45/(1+$B8)^('DCF Model'!C19+2)+'DCF Model'!F45/(1+$B8)^('DCF Model'!C19+3)+'DCF Model'!G45/(1+$B8)^('DCF Model'!C19+4)+'DCF Model'!G45*(1+F$6)/($B8-F$6)/(1+$B8)^('DCF Model'!C19+4)-'DCF Model'!C16)*1000000/'DCF Model'!C15,0),"") -> 3419 | G8: =IFERROR(ROUND(('DCF Model'!C45/(1+$B8)^('DCF Model'!C19+0)+'DCF Model'!D45/(1+$B8)^('DCF Model'!C19+1)+'DCF Model'!E45/(1+$B8)^('DCF Model'!C19+2)+'DCF Model'!F45/(1+$B8)^('DCF Model'!C19+3)+'DCF Model'!G45/(1+$B8)^('DCF Model'!C19+4)+'DCF Model'!G45*(1+G$6)/($B8-G$6)/(1+$B8)^('DCF Model'!C19+4)-'DCF Model'!C16)*1000000/'DCF Model'!C15,0),"") -> 3483 | H8: =IFERROR(ROUND(('DCF Model'!C45/(1+$B8)^('DCF Model'!C19+0)+'DCF Model'!D45/(1+$B8)^('DCF Model'!C19+1)+'DCF Model'!E45/(1+$B8)^('DCF Model'!C19+2)+'DCF Model'!F45/(1+$B8)^('DCF Model'!C19+3)+'DCF Model'!G45/(1+$B8)^('DCF Model'!C19+4)+'DCF Model'!G45*(1+H$6)/($B8-H$6)/(1+$B8)^('DCF Model'!C19+4)-'DCF Model'!C16)*1000000/'DCF Model'!C15,0),"") -> 3550 | I8: =IFERROR(ROUND(('DCF Model'!C45/(1+$B8)^('DCF Model'!C19+0)+'DCF Model'!D45/(1+$B8)^('DCF Model'!C19+1)+'DCF Model'!E45/(1+$B8)^('DCF Model'!C19+2)+'DCF Model'!F45/(1+$B8)^('DCF Model'!C19+3)+'DCF Model'!G45/(1+$B8)^('DCF Model'!C19+4)+'DCF Model'!G45*(1+I$6)/($B8-I$6)/(1+$B8)^('DCF Model'!C19+4)-'DCF Model'!C16)*1000000/'DCF Model'!C15,0),"") -> 3621
B9: =$C$3-0.005 -> 0.1165 | C9: =IFERROR(ROUND(('DCF Model'!C45/(1+$B9)^('DCF Model'!C19+0)+'DCF Model'!D45/(1+$B9)^('DCF Model'!C19+1)+'DCF Model'!E45/(1+$B9)^('DCF Model'!C19+2)+'DCF Model'!F45/(1+$B9)^('DCF Model'!C19+3)+'DCF Model'!G45/(1+$B9)^('DCF Model'!C19+4)+'DCF Model'!G45*(1+C$6)/($B9-C$6)/(1+$B9)^('DCF Model'!C19+4)-'DCF Model'!C16)*1000000/'DCF Model'!C15,0),"") -> 3115 | D9: =IFERROR(ROUND(('DCF Model'!C45/(1+$B9)^('DCF Model'!C19+0)+'DCF Model'!D45/(1+$B9)^('DCF Model'!C19+1)+'DCF Model'!E45/(1+$B9)^('DCF Model'!C19+2)+'DCF Model'!F45/(1+$B9)^('DCF Model'!C19+3)+'DCF Model'!G45/(1+$B9)^('DCF Model'!C19+4)+'DCF Model'!G45*(1+D$6)/($B9-D$6)/(1+$B9)^('DCF Model'!C19+4)-'DCF Model'!C16)*1000000/'DCF Model'!C15,0),"") -> 3164 | E9: =IFERROR(ROUND(('DCF Model'!C45/(1+$B9)^('DCF Model'!C19+0)+'DCF Model'!D45/(1+$B9)^('DCF Model'!C19+1)+'DCF Model'!E45/(1+$B9)^('DCF Model'!C19+2)+'DCF Model'!F45/(1+$B9)^('DCF Model'!C19+3)+'DCF Model'!G45/(1+$B9)^('DCF Model'!C19+4)+'DCF Model'!G45*(1+E$6)/($B9-E$6)/(1+$B9)^('DCF Model'!C19+4)-'DCF Model'!C16)*1000000/'DCF Model'!C15,0),"") -> 3215 | F9: =IFERROR(ROUND(('DCF Model'!C45/(1+$B9)^('DCF Model'!C19+0)+'DCF Model'!D45/(1+$B9)^('DCF Model'!C19+1)+'DCF Model'!E45/(1+$B9)^('DCF Model'!C19+2)+'DCF Model'!F45/(1+$B9)^('DCF Model'!C19+3)+'DCF Model'!G45/(1+$B9)^('DCF Model'!C19+4)+'DCF Model'!G45*(1+F$6)/($B9-F$6)/(1+$B9)^('DCF Model'!C19+4)-'DCF Model'!C16)*1000000/'DCF Model'!C15,0),"") -> 3268 | G9: =IFERROR(ROUND(('DCF Model'!C45/(1+$B9)^('DCF Model'!C19+0)+'DCF Model'!D45/(1+$B9)^('DCF Model'!C19+1)+'DCF Model'!E45/(1+$B9)^('DCF Model'!C19+2)+'DCF Model'!F45/(1+$B9)^('DCF Model'!C19+3)+'DCF Model'!G45/(1+$B9)^('DCF Model'!C19+4)+'DCF Model'!G45*(1+G$6)/($B9-G$6)/(1+$B9)^('DCF Model'!C19+4)-'DCF Model'!C16)*1000000/'DCF Model'!C15,0),"") -> 3324 | H9: =IFERROR(ROUND(('DCF Model'!C45/(1+$B9)^('DCF Model'!C19+0)+'DCF Model'!D45/(1+$B9)^('DCF Model'!C19+1)+'DCF Model'!E45/(1+$B9)^('DCF Model'!C19+2)+'DCF Model'!F45/(1+$B9)^('DCF Model'!C19+3)+'DCF Model'!G45/(1+$B9)^('DCF Model'!C19+4)+'DCF Model'!G45*(1+H$6)/($B9-H$6)/(1+$B9)^('DCF Model'!C19+4)-'DCF Model'!C16)*1000000/'DCF Model'!C15,0),"") -> 3384 | I9: =IFERROR(ROUND(('DCF Model'!C45/(1+$B9)^('DCF Model'!C19+0)+'DCF Model'!D45/(1+$B9)^('DCF Model'!C19+1)+'DCF Model'!E45/(1+$B9)^('DCF Model'!C19+2)+'DCF Model'!F45/(1+$B9)^('DCF Model'!C19+3)+'DCF Model'!G45/(1+$B9)^('DCF Model'!C19+4)+'DCF Model'!G45*(1+I$6)/($B9-I$6)/(1+$B9)^('DCF Model'!C19+4)-'DCF Model'!C16)*1000000/'DCF Model'!C15,0),"") -> 3447
B10: =$C$3 -> 0.1215 | C10: =IFERROR(ROUND(('DCF Model'!C45/(1+$B10)^('DCF Model'!C19+0)+'DCF Model'!D45/(1+$B10)^('DCF Model'!C19+1)+'DCF Model'!E45/(1+$B10)^('DCF Model'!C19+2)+'DCF Model'!F45/(1+$B10)^('DCF Model'!C19+3)+'DCF Model'!G45/(1+$B10)^('DCF Model'!C19+4)+'DCF Model'!G45*(1+C$6)/($B10-C$6)/(1+$B10)^('DCF Model'!C19+4)-'DCF Model'!C16)*1000000/'DCF Model'!C15,0),"") -> 2995 | D10: =IFERROR(ROUND(('DCF Model'!C45/(1+$B10)^('DCF Model'!C19+0)+'DCF Model'!D45/(1+$B10)^('DCF Model'!C19+1)+'DCF Model'!E45/(1+$B10)^('DCF Model'!C19+2)+'DCF Model'!F45/(1+$B10)^('DCF Model'!C19+3)+'DCF Model'!G45/(1+$B10)^('DCF Model'!C19+4)+'DCF Model'!G45*(1+D$6)/($B10-D$6)/(1+$B10)^('DCF Model'!C19+4)-'DCF Model'!C16)*1000000/'DCF Model'!C15,0),"") -> 3039 | E10: =IFERROR(ROUND(('DCF Model'!C45/(1+$B10)^('DCF Model'!C19+0)+'DCF Model'!D45/(1+$B10)^('DCF Model'!C19+1)+'DCF Model'!E45/(1+$B10)^('DCF Model'!C19+2)+'DCF Model'!F45/(1+$B10)^('DCF Model'!C19+3)+'DCF Model'!G45/(1+$B10)^('DCF Model'!C19+4)+'DCF Model'!G45*(1+E$6)/($B10-E$6)/(1+$B10)^('DCF Model'!C19+4)-'DCF Model'!C16)*1000000/'DCF Model'!C15,0),"") -> 3084 | F10: =IFERROR(ROUND(('DCF Model'!C45/(1+$B10)^('DCF Model'!C19+0)+'DCF Model'!D45/(1+$B10)^('DCF Model'!C19+1)+'DCF Model'!E45/(1+$B10)^('DCF Model'!C19+2)+'DCF Model'!F45/(1+$B10)^('DCF Model'!C19+3)+'DCF Model'!G45/(1+$B10)^('DCF Model'!C19+4)+'DCF Model'!G45*(1+F$6)/($B10-F$6)/(1+$B10)^('DCF Model'!C19+4)-'DCF Model'!C16)*1000000/'DCF Model'!C15,0),"") -> 3132 | G10: =IFERROR(ROUND(('DCF Model'!C45/(1+$B10)^('DCF Model'!C19+0)+'DCF Model'!D45/(1+$B10)^('DCF Model'!C19+1)+'DCF Model'!E45/(1+$B10)^('DCF Model'!C19+2)+'DCF Model'!F45/(1+$B10)^('DCF Model'!C19+3)+'DCF Model'!G45/(1+$B10)^('DCF Model'!C19+4)+'DCF Model'!G45*(1+G$6)/($B10-G$6)/(1+$B10)^('DCF Model'!C19+4)-'DCF Model'!C16)*1000000/'DCF Model'!C15,0),"") -> 3182 | H10: =IFERROR(ROUND(('DCF Model'!C45/(1+$B10)^('DCF Model'!C19+0)+'DCF Model'!D45/(1+$B10)^('DCF Model'!C19+1)+'DCF Model'!E45/(1+$B10)^('DCF Model'!C19+2)+'DCF Model'!F45/(1+$B10)^('DCF Model'!C19+3)+'DCF Model'!G45/(1+$B10)^('DCF Model'!C19+4)+'DCF Model'!G45*(1+H$6)/($B10-H$6)/(1+$B10)^('DCF Model'!C19+4)-'DCF Model'!C16)*1000000/'DCF Model'!C15,0),"") -> 3235 | I10: =IFERROR(ROUND(('DCF Model'!C45/(1+$B10)^('DCF Model'!C19+0)+'DCF Model'!D45/(1+$B10)^('DCF Model'!C19+1)+'DCF Model'!E45/(1+$B10)^('DCF Model'!C19+2)+'DCF Model'!F45/(1+$B10)^('DCF Model'!C19+3)+'DCF Model'!G45/(1+$B10)^('DCF Model'!C19+4)+'DCF Model'!G45*(1+I$6)/($B10-I$6)/(1+$B10)^('DCF Model'!C19+4)-'DCF Model'!C16)*1000000/'DCF Model'!C15,0),"") -> 3291
B11: =$C$3+0.005 -> 0.1265 | C11: =IFERROR(ROUND(('DCF Model'!C45/(1+$B11)^('DCF Model'!C19+0)+'DCF Model'!D45/(1+$B11)^('DCF Model'!C19+1)+'DCF Model'!E45/(1+$B11)^('DCF Model'!C19+2)+'DCF Model'!F45/(1+$B11)^('DCF Model'!C19+3)+'DCF Model'!G45/(1+$B11)^('DCF Model'!C19+4)+'DCF Model'!G45*(1+C$6)/($B11-C$6)/(1+$B11)^('DCF Model'!C19+4)-'DCF Model'!C16)*1000000/'DCF Model'!C15,0),"") -> 2886 | D11: =IFERROR(ROUND(('DCF Model'!C45/(1+$B11)^('DCF Model'!C19+0)+'DCF Model'!D45/(1+$B11)^('DCF Model'!C19+1)+'DCF Model'!E45/(1+$B11)^('DCF Model'!C19+2)+'DCF Model'!F45/(1+$B11)^('DCF Model'!C19+3)+'DCF Model'!G45/(1+$B11)^('DCF Model'!C19+4)+'DCF Model'!G45*(1+D$6)/($B11-D$6)/(1+$B11)^('DCF Model'!C19+4)-'DCF Model'!C16)*1000000/'DCF Model'!C15,0),"") -> 2925 | E11: =IFERROR(ROUND(('DCF Model'!C45/(1+$B11)^('DCF Model'!C19+0)+'DCF Model'!D45/(1+$B11)^('DCF Model'!C19+1)+'DCF Model'!E45/(1+$B11)^('DCF Model'!C19+2)+'DCF Model'!F45/(1+$B11)^('DCF Model'!C19+3)+'DCF Model'!G45/(1+$B11)^('DCF Model'!C19+4)+'DCF Model'!G45*(1+E$6)/($B11-E$6)/(1+$B11)^('DCF Model'!C19+4)-'DCF Model'!C16)*1000000/'DCF Model'!C15,0),"") -> 2966 | F11: =IFERROR(ROUND(('DCF Model'!C45/(1+$B11)^('DCF Model'!C19+0)+'DCF Model'!D45/(1+$B11)^('DCF Model'!C19+1)+'DCF Model'!E45/(1+$B11)^('DCF Model'!C19+2)+'DCF Model'!F45/(1+$B11)^('DCF Model'!C19+3)+'DCF Model'!G45/(1+$B11)^('DCF Model'!C19+4)+'DCF Model'!G45*(1+F$6)/($B11-F$6)/(1+$B11)^('DCF Model'!C19+4)-'DCF Model'!C16)*1000000/'DCF Model'!C15,0),"") -> 3009 | G11: =IFERROR(ROUND(('DCF Model'!C45/(1+$B11)^('DCF Model'!C19+0)+'DCF Model'!D45/(1+$B11)^('DCF Model'!C19+1)+'DCF Model'!E45/(1+$B11)^('DCF Model'!C19+2)+'DCF Model'!F45/(1+$B11)^('DCF Model'!C19+3)+'DCF Model'!G45/(1+$B11)^('DCF Model'!C19+4)+'DCF Model'!G45*(1+G$6)/($B11-G$6)/(1+$B11)^('DCF Model'!C19+4)-'DCF Model'!C16)*1000000/'DCF Model'!C15,0),"") -> 3054 | H11: =IFERROR(ROUND(('DCF Model'!C45/(1+$B11)^('DCF Model'!C19+0)+'DCF Model'!D45/(1+$B11)^('DCF Model'!C19+1)+'DCF Model'!E45/(1+$B11)^('DCF Model'!C19+2)+'DCF Model'!F45/(1+$B11)^('DCF Model'!C19+3)+'DCF Model'!G45/(1+$B11)^('DCF Model'!C19+4)+'DCF Model'!G45*(1+H$6)/($B11-H$6)/(1+$B11)^('DCF Model'!C19+4)-'DCF Model'!C16)*1000000/'DCF Model'!C15,0),"") -> 3101 | I11: =IFERROR(ROUND(('DCF Model'!C45/(1+$B11)^('DCF Model'!C19+0)+'DCF Model'!D45/(1+$B11)^('DCF Model'!C19+1)+'DCF Model'!E45/(1+$B11)^('DCF Model'!C19+2)+'DCF Model'!F45/(1+$B11)^('DCF Model'!C19+3)+'DCF Model'!G45/(1+$B11)^('DCF Model'!C19+4)+'DCF Model'!G45*(1+I$6)/($B11-I$6)/(1+$B11)^('DCF Model'!C19+4)-'DCF Model'!C16)*1000000/'DCF Model'!C15,0),"") -> 3151
B12: =$C$3+0.01 -> 0.1315 | C12: =IFERROR(ROUND(('DCF Model'!C45/(1+$B12)^('DCF Model'!C19+0)+'DCF Model'!D45/(1+$B12)^('DCF Model'!C19+1)+'DCF Model'!E45/(1+$B12)^('DCF Model'!C19+2)+'DCF Model'!F45/(1+$B12)^('DCF Model'!C19+3)+'DCF Model'!G45/(1+$B12)^('DCF Model'!C19+4)+'DCF Model'!G45*(1+C$6)/($B12-C$6)/(1+$B12)^('DCF Model'!C19+4)-'DCF Model'!C16)*1000000/'DCF Model'!C15,0),"") -> 2786 | D12: =IFERROR(ROUND(('DCF Model'!C45/(1+$B12)^('DCF Model'!C19+0)+'DCF Model'!D45/(1+$B12)^('DCF Model'!C19+1)+'DCF Model'!E45/(1+$B12)^('DCF Model'!C19+2)+'DCF Model'!F45/(1+$B12)^('DCF Model'!C19+3)+'DCF Model'!G45/(1+$B12)^('DCF Model'!C19+4)+'DCF Model'!G45*(1+D$6)/($B12-D$6)/(1+$B12)^('DCF Model'!C19+4)-'DCF Model'!C16)*1000000/'DCF Model'!C15,0),"") -> 2821 | E12: =IFERROR(ROUND(('DCF Model'!C45/(1+$B12)^('DCF Model'!C19+0)+'DCF Model'!D45/(1+$B12)^('DCF Model'!C19+1)+'DCF Model'!E45/(1+$B12)^('DCF Model'!C19+2)+'DCF Model'!F45/(1+$B12)^('DCF Model'!C19+3)+'DCF Model'!G45/(1+$B12)^('DCF Model'!C19+4)+'DCF Model'!G45*(1+E$6)/($B12-E$6)/(1+$B12)^('DCF Model'!C19+4)-'DCF Model'!C16)*1000000/'DCF Model'!C15,0),"") -> 2858 | F12: =IFERROR(ROUND(('DCF Model'!C45/(1+$B12)^('DCF Model'!C19+0)+'DCF Model'!D45/(1+$B12)^('DCF Model'!C19+1)+'DCF Model'!E45/(1+$B12)^('DCF Model'!C19+2)+'DCF Model'!F45/(1+$B12)^('DCF Model'!C19+3)+'DCF Model'!G45/(1+$B12)^('DCF Model'!C19+4)+'DCF Model'!G45*(1+F$6)/($B12-F$6)/(1+$B12)^('DCF Model'!C19+4)-'DCF Model'!C16)*1000000/'DCF Model'!C15,0),"") -> 2897 | G12: =IFERROR(ROUND(('DCF Model'!C45/(1+$B12)^('DCF Model'!C19+0)+'DCF Model'!D45/(1+$B12)^('DCF Model'!C19+1)+'DCF Model'!E45/(1+$B12)^('DCF Model'!C19+2)+'DCF Model'!F45/(1+$B12)^('DCF Model'!C19+3)+'DCF Model'!G45/(1+$B12)^('DCF Model'!C19+4)+'DCF Model'!G45*(1+G$6)/($B12-G$6)/(1+$B12)^('DCF Model'!C19+4)-'DCF Model'!C16)*1000000/'DCF Model'!C15,0),"") -> 2937 | H12: =IFERROR(ROUND(('DCF Model'!C45/(1+$B12)^('DCF Model'!C19+0)+'DCF Model'!D45/(1+$B12)^('DCF Model'!C19+1)+'DCF Model'!E45/(1+$B12)^('DCF Model'!C19+2)+'DCF Model'!F45/(1+$B12)^('DCF Model'!C19+3)+'DCF Model'!G45/(1+$B12)^('DCF Model'!C19+4)+'DCF Model'!G45*(1+H$6)/($B12-H$6)/(1+$B12)^('DCF Model'!C19+4)-'DCF Model'!C16)*1000000/'DCF Model'!C15,0),"") -> 2980 | I12: =IFERROR(ROUND(('DCF Model'!C45/(1+$B12)^('DCF Model'!C19+0)+'DCF Model'!D45/(1+$B12)^('DCF Model'!C19+1)+'DCF Model'!E45/(1+$B12)^('DCF Model'!C19+2)+'DCF Model'!F45/(1+$B12)^('DCF Model'!C19+3)+'DCF Model'!G45/(1+$B12)^('DCF Model'!C19+4)+'DCF Model'!G45*(1+I$6)/($B12-I$6)/(1+$B12)^('DCF Model'!C19+4)-'DCF Model'!C16)*1000000/'DCF Model'!C15,0),"") -> 3024
B13: =$C$3+0.015 -> 0.1365 | C13: =IFERROR(ROUND(('DCF Model'!C45/(1+$B13)^('DCF Model'!C19+0)+'DCF Model'!D45/(1+$B13)^('DCF Model'!C19+1)+'DCF Model'!E45/(1+$B13)^('DCF Model'!C19+2)+'DCF Model'!F45/(1+$B13)^('DCF Model'!C19+3)+'DCF Model'!G45/(1+$B13)^('DCF Model'!C19+4)+'DCF Model'!G45*(1+C$6)/($B13-C$6)/(1+$B13)^('DCF Model'!C19+4)-'DCF Model'!C16)*1000000/'DCF Model'!C15,0),"") -> 2694 | D13: =IFERROR(ROUND(('DCF Model'!C45/(1+$B13)^('DCF Model'!C19+0)+'DCF Model'!D45/(1+$B13)^('DCF Model'!C19+1)+'DCF Model'!E45/(1+$B13)^('DCF Model'!C19+2)+'DCF Model'!F45/(1+$B13)^('DCF Model'!C19+3)+'DCF Model'!G45/(1+$B13)^('DCF Model'!C19+4)+'DCF Model'!G45*(1+D$6)/($B13-D$6)/(1+$B13)^('DCF Model'!C19+4)-'DCF Model'!C16)*1000000/'DCF Model'!C15,0),"") -> 2726 | E13: =IFERROR(ROUND(('DCF Model'!C45/(1+$B13)^('DCF Model'!C19+0)+'DCF Model'!D45/(1+$B13)^('DCF Model'!C19+1)+'DCF Model'!E45/(1+$B13)^('DCF Model'!C19+2)+'DCF Model'!F45/(1+$B13)^('DCF Model'!C19+3)+'DCF Model'!G45/(1+$B13)^('DCF Model'!C19+4)+'DCF Model'!G45*(1+E$6)/($B13-E$6)/(1+$B13)^('DCF Model'!C19+4)-'DCF Model'!C16)*1000000/'DCF Model'!C15,0),"") -> 2760 | F13: =IFERROR(ROUND(('DCF Model'!C45/(1+$B13)^('DCF Model'!C19+0)+'DCF Model'!D45/(1+$B13)^('DCF Model'!C19+1)+'DCF Model'!E45/(1+$B13)^('DCF Model'!C19+2)+'DCF Model'!F45/(1+$B13)^('DCF Model'!C19+3)+'DCF Model'!G45/(1+$B13)^('DCF Model'!C19+4)+'DCF Model'!G45*(1+F$6)/($B13-F$6)/(1+$B13)^('DCF Model'!C19+4)-'DCF Model'!C16)*1000000/'DCF Model'!C15,0),"") -> 2795 | G13: =IFERROR(ROUND(('DCF Model'!C45/(1+$B13)^('DCF Model'!C19+0)+'DCF Model'!D45/(1+$B13)^('DCF Model'!C19+1)+'DCF Model'!E45/(1+$B13)^('DCF Model'!C19+2)+'DCF Model'!F45/(1+$B13)^('DCF Model'!C19+3)+'DCF Model'!G45/(1+$B13)^('DCF Model'!C19+4)+'DCF Model'!G45*(1+G$6)/($B13-G$6)/(1+$B13)^('DCF Model'!C19+4)-'DCF Model'!C16)*1000000/'DCF Model'!C15,0),"") -> 2831 | H13: =IFERROR(ROUND(('DCF Model'!C45/(1+$B13)^('DCF Model'!C19+0)+'DCF Model'!D45/(1+$B13)^('DCF Model'!C19+1)+'DCF Model'!E45/(1+$B13)^('DCF Model'!C19+2)+'DCF Model'!F45/(1+$B13)^('DCF Model'!C19+3)+'DCF Model'!G45/(1+$B13)^('DCF Model'!C19+4)+'DCF Model'!G45*(1+H$6)/($B13-H$6)/(1+$B13)^('DCF Model'!C19+4)-'DCF Model'!C16)*1000000/'DCF Model'!C15,0),"") -> 2869 | I13: =IFERROR(ROUND(('DCF Model'!C45/(1+$B13)^('DCF Model'!C19+0)+'DCF Model'!D45/(1+$B13)^('DCF Model'!C19+1)+'DCF Model'!E45/(1+$B13)^('DCF Model'!C19+2)+'DCF Model'!F45/(1+$B13)^('DCF Model'!C19+3)+'DCF Model'!G45/(1+$B13)^('DCF Model'!C19+4)+'DCF Model'!G45*(1+I$6)/($B13-I$6)/(1+$B13)^('DCF Model'!C19+4)-'DCF Model'!C16)*1000000/'DCF Model'!C15,0),"") -> 2909
B16: Table 2: WACC vs Exit Multiple (Exit Multiple - Implied Share Price, JPY)
B17: WACC \ Exit Multiple | C17: =$I$3-3 -> 5 | D17: =$I$3-2 -> 6 | E17: =$I$3-1 -> 7 | F17: =$I$3 -> 8 | G17: =$I$3+1 -> 9 | H17: =$I$3+2 -> 10 | I17: =$I$3+3 -> 11
B18: =$C$3-0.015 -> 0.1065 | C18: =IFERROR(ROUND(('DCF Model'!C45/(1+$B18)^('DCF Model'!C19+0)+'DCF Model'!D45/(1+$B18)^('DCF Model'!C19+1)+'DCF Model'!E45/(1+$B18)^('DCF Model'!C19+2)+'DCF Model'!F45/(1+$B18)^('DCF Model'!C19+3)+'DCF Model'!G45/(1+$B18)^('DCF Model'!C19+4)+('DCF Model'!G39+'DCF Model'!G42)*C$17/(1+$B18)^('DCF Model'!C19+4)-'DCF Model'!C16)*1000000/'DCF Model'!C15,0),"") -> 2868 | D18: =IFERROR(ROUND(('DCF Model'!C45/(1+$B18)^('DCF Model'!C19+0)+'DCF Model'!D45/(1+$B18)^('DCF Model'!C19+1)+'DCF Model'!E45/(1+$B18)^('DCF Model'!C19+2)+'DCF Model'!F45/(1+$B18)^('DCF Model'!C19+3)+'DCF Model'!G45/(1+$B18)^('DCF Model'!C19+4)+('DCF Model'!G39+'DCF Model'!G42)*D$17/(1+$B18)^('DCF Model'!C19+4)-'DCF Model'!C16)*1000000/'DCF Model'!C15,0),"") -> 3172 | E18: =IFERROR(ROUND(('DCF Model'!C45/(1+$B18)^('DCF Model'!C19+0)+'DCF Model'!D45/(1+$B18)^('DCF Model'!C19+1)+'DCF Model'!E45/(1+$B18)^('DCF Model'!C19+2)+'DCF Model'!F45/(1+$B18)^('DCF Model'!C19+3)+'DCF Model'!G45/(1+$B18)^('DCF Model'!C19+4)+('DCF Model'!G39+'DCF Model'!G42)*E$17/(1+$B18)^('DCF Model'!C19+4)-'DCF Model'!C16)*1000000/'DCF Model'!C15,0),"") -> 3476 | F18: =IFERROR(ROUND(('DCF Model'!C45/(1+$B18)^('DCF Model'!C19+0)+'DCF Model'!D45/(1+$B18)^('DCF Model'!C19+1)+'DCF Model'!E45/(1+$B18)^('DCF Model'!C19+2)+'DCF Model'!F45/(1+$B18)^('DCF Model'!C19+3)+'DCF Model'!G45/(1+$B18)^('DCF Model'!C19+4)+('DCF Model'!G39+'DCF Model'!G42)*F$17/(1+$B18)^('DCF Model'!C19+4)-'DCF Model'!C16)*1000000/'DCF Model'!C15,0),"") -> 3780 | G18: =IFERROR(ROUND(('DCF Model'!C45/(1+$B18)^('DCF Model'!C19+0)+'DCF Model'!D45/(1+$B18)^('DCF Model'!C19+1)+'DCF Model'!E45/(1+$B18)^('DCF Model'!C19+2)+'DCF Model'!F45/(1+$B18)^('DCF Model'!C19+3)+'DCF Model'!G45/(1+$B18)^('DCF Model'!C19+4)+('DCF Model'!G39+'DCF Model'!G42)*G$17/(1+$B18)^('DCF Model'!C19+4)-'DCF Model'!C16)*1000000/'DCF Model'!C15,0),"") -> 4085 | H18: =IFERROR(ROUND(('DCF Model'!C45/(1+$B18)^('DCF Model'!C19+0)+'DCF Model'!D45/(1+$B18)^('DCF Model'!C19+1)+'DCF Model'!E45/(1+$B18)^('DCF Model'!C19+2)+'DCF Model'!F45/(1+$B18)^('DCF Model'!C19+3)+'DCF Model'!G45/(1+$B18)^('DCF Model'!C19+4)+('DCF Model'!G39+'DCF Model'!G42)*H$17/(1+$B18)^('DCF Model'!C19+4)-'DCF Model'!C16)*1000000/'DCF Model'!C15,0),"") -> 4389 | I18: =IFERROR(ROUND(('DCF Model'!C45/(1+$B18)^('DCF Model'!C19+0)+'DCF Model'!D45/(1+$B18)^('DCF Model'!C19+1)+'DCF Model'!E45/(1+$B18)^('DCF Model'!C19+2)+'DCF Model'!F45/(1+$B18)^('DCF Model'!C19+3)+'DCF Model'!G45/(1+$B18)^('DCF Model'!C19+4)+('DCF Model'!G39+'DCF Model'!G42)*I$17/(1+$B18)^('DCF Model'!C19+4)-'DCF Model'!C16)*1000000/'DCF Model'!C15,0),"") -> 4693
B19: =$C$3-0.01 -> 0.1115 | C19: =IFERROR(ROUND(('DCF Model'!C45/(1+$B19)^('DCF Model'!C19+0)+'DCF Model'!D45/(1+$B19)^('DCF Model'!C19+1)+'DCF Model'!E45/(1+$B19)^('DCF Model'!C19+2)+'DCF Model'!F45/(1+$B19)^('DCF Model'!C19+3)+'DCF Model'!G45/(1+$B19)^('DCF Model'!C19+4)+('DCF Model'!G39+'DCF Model'!G42)*C$17/(1+$B19)^('DCF Model'!C19+4)-'DCF Model'!C16)*1000000/'DCF Model'!C15,0),"") -> 2832 | D19: =IFERROR(ROUND(('DCF Model'!C45/(1+$B19)^('DCF Model'!C19+0)+'DCF Model'!D45/(1+$B19)^('DCF Model'!C19+1)+'DCF Model'!E45/(1+$B19)^('DCF Model'!C19+2)+'DCF Model'!F45/(1+$B19)^('DCF Model'!C19+3)+'DCF Model'!G45/(1+$B19)^('DCF Model'!C19+4)+('DCF Model'!G39+'DCF Model'!G42)*D$17/(1+$B19)^('DCF Model'!C19+4)-'DCF Model'!C16)*1000000/'DCF Model'!C15,0),"") -> 3131 | E19: =IFERROR(ROUND(('DCF Model'!C45/(1+$B19)^('DCF Model'!C19+0)+'DCF Model'!D45/(1+$B19)^('DCF Model'!C19+1)+'DCF Model'!E45/(1+$B19)^('DCF Model'!C19+2)+'DCF Model'!F45/(1+$B19)^('DCF Model'!C19+3)+'DCF Model'!G45/(1+$B19)^('DCF Model'!C19+4)+('DCF Model'!G39+'DCF Model'!G42)*E$17/(1+$B19)^('DCF Model'!C19+4)-'DCF Model'!C16)*1000000/'DCF Model'!C15,0),"") -> 3430 | F19: =IFERROR(ROUND(('DCF Model'!C45/(1+$B19)^('DCF Model'!C19+0)+'DCF Model'!D45/(1+$B19)^('DCF Model'!C19+1)+'DCF Model'!E45/(1+$B19)^('DCF Model'!C19+2)+'DCF Model'!F45/(1+$B19)^('DCF Model'!C19+3)+'DCF Model'!G45/(1+$B19)^('DCF Model'!C19+4)+('DCF Model'!G39+'DCF Model'!G42)*F$17/(1+$B19)^('DCF Model'!C19+4)-'DCF Model'!C16)*1000000/'DCF Model'!C15,0),"") -> 3729 | G19: =IFERROR(ROUND(('DCF Model'!C45/(1+$B19)^('DCF Model'!C19+0)+'DCF Model'!D45/(1+$B19)^('DCF Model'!C19+1)+'DCF Model'!E45/(1+$B19)^('DCF Model'!C19+2)+'DCF Model'!F45/(1+$B19)^('DCF Model'!C19+3)+'DCF Model'!G45/(1+$B19)^('DCF Model'!C19+4)+('DCF Model'!G39+'DCF Model'!G42)*G$17/(1+$B19)^('DCF Model'!C19+4)-'DCF Model'!C16)*1000000/'DCF Model'!C15,0),"") -> 4028 | H19: =IFERROR(ROUND(('DCF Model'!C45/(1+$B19)^('DCF Model'!C19+0)+'DCF Model'!D45/(1+$B19)^('DCF Model'!C19+1)+'DCF Model'!E45/(1+$B19)^('DCF Model'!C19+2)+'DCF Model'!F45/(1+$B19)^('DCF Model'!C19+3)+'DCF Model'!G45/(1+$B19)^('DCF Model'!C19+4)+('DCF Model'!G39+'DCF Model'!G42)*H$17/(1+$B19)^('DCF Model'!C19+4)-'DCF Model'!C16)*1000000/'DCF Model'!C15,0),"") -> 4326 | I19: =IFERROR(ROUND(('DCF Model'!C45/(1+$B19)^('DCF Model'!C19+0)+'DCF Model'!D45/(1+$B19)^('DCF Model'!C19+1)+'DCF Model'!E45/(1+$B19)^('DCF Model'!C19+2)+'DCF Model'!F45/(1+$B19)^('DCF Model'!C19+3)+'DCF Model'!G45/(1+$B19)^('DCF Model'!C19+4)+('DCF Model'!G39+'DCF Model'!G42)*I$17/(1+$B19)^('DCF Model'!C19+4)-'DCF Model'!C16)*1000000/'DCF Model'!C15,0),"") -> 4625
B20: =$C$3-0.005 -> 0.1165 | C20: =IFERROR(ROUND(('DCF Model'!C45/(1+$B20)^('DCF Model'!C19+0)+'DCF Model'!D45/(1+$B20)^('DCF Model'!C19+1)+'DCF Model'!E45/(1+$B20)^('DCF Model'!C19+2)+'DCF Model'!F45/(1+$B20)^('DCF Model'!C19+3)+'DCF Model'!G45/(1+$B20)^('DCF Model'!C19+4)+('DCF Model'!G39+'DCF Model'!G42)*C$17/(1+$B20)^('DCF Model'!C19+4)-'DCF Model'!C16)*1000000/'DCF Model'!C15,0),"") -> 2798 | D20: =IFERROR(ROUND(('DCF Model'!C45/(1+$B20)^('DCF Model'!C19+0)+'DCF Model'!D45/(1+$B20)^('DCF Model'!C19+1)+'DCF Model'!E45/(1+$B20)^('DCF Model'!C19+2)+'DCF Model'!F45/(1+$B20)^('DCF Model'!C19+3)+'DCF Model'!G45/(1+$B20)^('DCF Model'!C19+4)+('DCF Model'!G39+'DCF Model'!G42)*D$17/(1+$B20)^('DCF Model'!C19+4)-'DCF Model'!C16)*1000000/'DCF Model'!C15,0),"") -> 3091 | E20: =IFERROR(ROUND(('DCF Model'!C45/(1+$B20)^('DCF Model'!C19+0)+'DCF Model'!D45/(1+$B20)^('DCF Model'!C19+1)+'DCF Model'!E45/(1+$B20)^('DCF Model'!C19+2)+'DCF Model'!F45/(1+$B20)^('DCF Model'!C19+3)+'DCF Model'!G45/(1+$B20)^('DCF Model'!C19+4)+('DCF Model'!G39+'DCF Model'!G42)*E$17/(1+$B20)^('DCF Model'!C19+4)-'DCF Model'!C16)*1000000/'DCF Model'!C15,0),"") -> 3385 | F20: =IFERROR(ROUND(('DCF Model'!C45/(1+$B20)^('DCF Model'!C19+0)+'DCF Model'!D45/(1+$B20)^('DCF Model'!C19+1)+'DCF Model'!E45/(1+$B20)^('DCF Model'!C19+2)+'DCF Model'!F45/(1+$B20)^('DCF Model'!C19+3)+'DCF Model'!G45/(1+$B20)^('DCF Model'!C19+4)+('DCF Model'!G39+'DCF Model'!G42)*F$17/(1+$B20)^('DCF Model'!C19+4)-'DCF Model'!C16)*1000000/'DCF Model'!C15,0),"") -> 3678 | G20: =IFERROR(ROUND(('DCF Model'!C45/(1+$B20)^('DCF Model'!C19+0)+'DCF Model'!D45/(1+$B20)^('DCF Model'!C19+1)+'DCF Model'!E45/(1+$B20)^('DCF Model'!C19+2)+'DCF Model'!F45/(1+$B20)^('DCF Model'!C19+3)+'DCF Model'!G45/(1+$B20)^('DCF Model'!C19+4)+('DCF Model'!G39+'DCF Model'!G42)*G$17/(1+$B20)^('DCF Model'!C19+4)-'DCF Model'!C16)*1000000/'DCF Model'!C15,0),"") -> 3972 | H20: =IFERROR(ROUND(('DCF Model'!C45/(1+$B20)^('DCF Model'!C19+0)+'DCF Model'!D45/(1+$B20)^('DCF Model'!C19+1)+'DCF Model'!E45/(1+$B20)^('DCF Model'!C19+2)+'DCF Model'!F45/(1+$B20)^('DCF Model'!C19+3)+'DCF Model'!G45/(1+$B20)^('DCF Model'!C19+4)+('DCF Model'!G39+'DCF Model'!G42)*H$17/(1+$B20)^('DCF Model'!C19+4)-'DCF Model'!C16)*1000000/'DCF Model'!C15,0),"") -> 4265 | I20: =IFERROR(ROUND(('DCF Model'!C45/(1+$B20)^('DCF Model'!C19+0)+'DCF Model'!D45/(1+$B20)^('DCF Model'!C19+1)+'DCF Model'!E45/(1+$B20)^('DCF Model'!C19+2)+'DCF Model'!F45/(1+$B20)^('DCF Model'!C19+3)+'DCF Model'!G45/(1+$B20)^('DCF Model'!C19+4)+('DCF Model'!G39+'DCF Model'!G42)*I$17/(1+$B20)^('DCF Model'!C19+4)-'DCF Model'!C16)*1000000/'DCF Model'!C15,0),"") -> 4559
B21: =$C$3 -> 0.1215 | C21: =IFERROR(ROUND(('DCF Model'!C45/(1+$B21)^('DCF Model'!C19+0)+'DCF Model'!D45/(1+$B21)^('DCF Model'!C19+1)+'DCF Model'!E45/(1+$B21)^('DCF Model'!C19+2)+'DCF Model'!F45/(1+$B21)^('DCF Model'!C19+3)+'DCF Model'!G45/(1+$B21)^('DCF Model'!C19+4)+('DCF Model'!G39+'DCF Model'!G42)*C$17/(1+$B21)^('DCF Model'!C19+4)-'DCF Model'!C16)*1000000/'DCF Model'!C15,0),"") -> 2764 | D21: =IFERROR(ROUND(('DCF Model'!C45/(1+$B21)^('DCF Model'!C19+0)+'DCF Model'!D45/(1+$B21)^('DCF Model'!C19+1)+'DCF Model'!E45/(1+$B21)^('DCF Model'!C19+2)+'DCF Model'!F45/(1+$B21)^('DCF Model'!C19+3)+'DCF Model'!G45/(1+$B21)^('DCF Model'!C19+4)+('DCF Model'!G39+'DCF Model'!G42)*D$17/(1+$B21)^('DCF Model'!C19+4)-'DCF Model'!C16)*1000000/'DCF Model'!C15,0),"") -> 3052 | E21: =IFERROR(ROUND(('DCF Model'!C45/(1+$B21)^('DCF Model'!C19+0)+'DCF Model'!D45/(1+$B21)^('DCF Model'!C19+1)+'DCF Model'!E45/(1+$B21)^('DCF Model'!C19+2)+'DCF Model'!F45/(1+$B21)^('DCF Model'!C19+3)+'DCF Model'!G45/(1+$B21)^('DCF Model'!C19+4)+('DCF Model'!G39+'DCF Model'!G42)*E$17/(1+$B21)^('DCF Model'!C19+4)-'DCF Model'!C16)*1000000/'DCF Model'!C15,0),"") -> 3340 | F21: =IFERROR(ROUND(('DCF Model'!C45/(1+$B21)^('DCF Model'!C19+0)+'DCF Model'!D45/(1+$B21)^('DCF Model'!C19+1)+'DCF Model'!E45/(1+$B21)^('DCF Model'!C19+2)+'DCF Model'!F45/(1+$B21)^('DCF Model'!C19+3)+'DCF Model'!G45/(1+$B21)^('DCF Model'!C19+4)+('DCF Model'!G39+'DCF Model'!G42)*F$17/(1+$B21)^('DCF Model'!C19+4)-'DCF Model'!C16)*1000000/'DCF Model'!C15,0),"") -> 3629 | G21: =IFERROR(ROUND(('DCF Model'!C45/(1+$B21)^('DCF Model'!C19+0)+'DCF Model'!D45/(1+$B21)^('DCF Model'!C19+1)+'DCF Model'!E45/(1+$B21)^('DCF Model'!C19+2)+'DCF Model'!F45/(1+$B21)^('DCF Model'!C19+3)+'DCF Model'!G45/(1+$B21)^('DCF Model'!C19+4)+('DCF Model'!G39+'DCF Model'!G42)*G$17/(1+$B21)^('DCF Model'!C19+4)-'DCF Model'!C16)*1000000/'DCF Model'!C15,0),"") -> 3917 | H21: =IFERROR(ROUND(('DCF Model'!C45/(1+$B21)^('DCF Model'!C19+0)+'DCF Model'!D45/(1+$B21)^('DCF Model'!C19+1)+'DCF Model'!E45/(1+$B21)^('DCF Model'!C19+2)+'DCF Model'!F45/(1+$B21)^('DCF Model'!C19+3)+'DCF Model'!G45/(1+$B21)^('DCF Model'!C19+4)+('DCF Model'!G39+'DCF Model'!G42)*H$17/(1+$B21)^('DCF Model'!C19+4)-'DCF Model'!C16)*1000000/'DCF Model'!C15,0),"") -> 4205 | I21: =IFERROR(ROUND(('DCF Model'!C45/(1+$B21)^('DCF Model'!C19+0)+'DCF Model'!D45/(1+$B21)^('DCF Model'!C19+1)+'DCF Model'!E45/(1+$B21)^('DCF Model'!C19+2)+'DCF Model'!F45/(1+$B21)^('DCF Model'!C19+3)+'DCF Model'!G45/(1+$B21)^('DCF Model'!C19+4)+('DCF Model'!G39+'DCF Model'!G42)*I$17/(1+$B21)^('DCF Model'!C19+4)-'DCF Model'!C16)*1000000/'DCF Model'!C15,0),"") -> 4494
B22: =$C$3+0.005 -> 0.1265 | C22: =IFERROR(ROUND(('DCF Model'!C45/(1+$B22)^('DCF Model'!C19+0)+'DCF Model'!D45/(1+$B22)^('DCF Model'!C19+1)+'DCF Model'!E45/(1+$B22)^('DCF Model'!C19+2)+'DCF Model'!F45/(1+$B22)^('DCF Model'!C19+3)+'DCF Model'!G45/(1+$B22)^('DCF Model'!C19+4)+('DCF Model'!G39+'DCF Model'!G42)*C$17/(1+$B22)^('DCF Model'!C19+4)-'DCF Model'!C16)*1000000/'DCF Model'!C15,0),"") -> 2731 | D22: =IFERROR(ROUND(('DCF Model'!C45/(1+$B22)^('DCF Model'!C19+0)+'DCF Model'!D45/(1+$B22)^('DCF Model'!C19+1)+'DCF Model'!E45/(1+$B22)^('DCF Model'!C19+2)+'DCF Model'!F45/(1+$B22)^('DCF Model'!C19+3)+'DCF Model'!G45/(1+$B22)^('DCF Model'!C19+4)+('DCF Model'!G39+'DCF Model'!G42)*D$17/(1+$B22)^('DCF Model'!C19+4)-'DCF Model'!C16)*1000000/'DCF Model'!C15,0),"") -> 3014 | E22: =IFERROR(ROUND(('DCF Model'!C45/(1+$B22)^('DCF Model'!C19+0)+'DCF Model'!D45/(1+$B22)^('DCF Model'!C19+1)+'DCF Model'!E45/(1+$B22)^('DCF Model'!C19+2)+'DCF Model'!F45/(1+$B22)^('DCF Model'!C19+3)+'DCF Model'!G45/(1+$B22)^('DCF Model'!C19+4)+('DCF Model'!G39+'DCF Model'!G42)*E$17/(1+$B22)^('DCF Model'!C19+4)-'DCF Model'!C16)*1000000/'DCF Model'!C15,0),"") -> 3297 | F22: =IFERROR(ROUND(('DCF Model'!C45/(1+$B22)^('DCF Model'!C19+0)+'DCF Model'!D45/(1+$B22)^('DCF Model'!C19+1)+'DCF Model'!E45/(1+$B22)^('DCF Model'!C19+2)+'DCF Model'!F45/(1+$B22)^('DCF Model'!C19+3)+'DCF Model'!G45/(1+$B22)^('DCF Model'!C19+4)+('DCF Model'!G39+'DCF Model'!G42)*F$17/(1+$B22)^('DCF Model'!C19+4)-'DCF Model'!C16)*1000000/'DCF Model'!C15,0),"") -> 3580 | G22: =IFERROR(ROUND(('DCF Model'!C45/(1+$B22)^('DCF Model'!C19+0)+'DCF Model'!D45/(1+$B22)^('DCF Model'!C19+1)+'DCF Model'!E45/(1+$B22)^('DCF Model'!C19+2)+'DCF Model'!F45/(1+$B22)^('DCF Model'!C19+3)+'DCF Model'!G45/(1+$B22)^('DCF Model'!C19+4)+('DCF Model'!G39+'DCF Model'!G42)*G$17/(1+$B22)^('DCF Model'!C19+4)-'DCF Model'!C16)*1000000/'DCF Model'!C15,0),"") -> 3864 | H22: =IFERROR(ROUND(('DCF Model'!C45/(1+$B22)^('DCF Model'!C19+0)+'DCF Model'!D45/(1+$B22)^('DCF Model'!C19+1)+'DCF Model'!E45/(1+$B22)^('DCF Model'!C19+2)+'DCF Model'!F45/(1+$B22)^('DCF Model'!C19+3)+'DCF Model'!G45/(1+$B22)^('DCF Model'!C19+4)+('DCF Model'!G39+'DCF Model'!G42)*H$17/(1+$B22)^('DCF Model'!C19+4)-'DCF Model'!C16)*1000000/'DCF Model'!C15,0),"") -> 4147 | I22: =IFERROR(ROUND(('DCF Model'!C45/(1+$B22)^('DCF Model'!C19+0)+'DCF Model'!D45/(1+$B22)^('DCF Model'!C19+1)+'DCF Model'!E45/(1+$B22)^('DCF Model'!C19+2)+'DCF Model'!F45/(1+$B22)^('DCF Model'!C19+3)+'DCF Model'!G45/(1+$B22)^('DCF Model'!C19+4)+('DCF Model'!G39+'DCF Model'!G42)*I$17/(1+$B22)^('DCF Model'!C19+4)-'DCF Model'!C16)*1000000/'DCF Model'!C15,0),"") -> 4430
B23: =$C$3+0.01 -> 0.1315 | C23: =IFERROR(ROUND(('DCF Model'!C45/(1+$B23)^('DCF Model'!C19+0)+'DCF Model'!D45/(1+$B23)^('DCF Model'!C19+1)+'DCF Model'!E45/(1+$B23)^('DCF Model'!C19+2)+'DCF Model'!F45/(1+$B23)^('DCF Model'!C19+3)+'DCF Model'!G45/(1+$B23)^('DCF Model'!C19+4)+('DCF Model'!G39+'DCF Model'!G42)*C$17/(1+$B23)^('DCF Model'!C19+4)-'DCF Model'!C16)*1000000/'DCF Model'!C15,0),"") -> 2698 | D23: =IFERROR(ROUND(('DCF Model'!C45/(1+$B23)^('DCF Model'!C19+0)+'DCF Model'!D45/(1+$B23)^('DCF Model'!C19+1)+'DCF Model'!E45/(1+$B23)^('DCF Model'!C19+2)+'DCF Model'!F45/(1+$B23)^('DCF Model'!C19+3)+'DCF Model'!G45/(1+$B23)^('DCF Model'!C19+4)+('DCF Model'!G39+'DCF Model'!G42)*D$17/(1+$B23)^('DCF Model'!C19+4)-'DCF Model'!C16)*1000000/'DCF Model'!C15,0),"") -> 2977 | E23: =IFERROR(ROUND(('DCF Model'!C45/(1+$B23)^('DCF Model'!C19+0)+'DCF Model'!D45/(1+$B23)^('DCF Model'!C19+1)+'DCF Model'!E45/(1+$B23)^('DCF Model'!C19+2)+'DCF Model'!F45/(1+$B23)^('DCF Model'!C19+3)+'DCF Model'!G45/(1+$B23)^('DCF Model'!C19+4)+('DCF Model'!G39+'DCF Model'!G42)*E$17/(1+$B23)^('DCF Model'!C19+4)-'DCF Model'!C16)*1000000/'DCF Model'!C15,0),"") -> 3255 | F23: =IFERROR(ROUND(('DCF Model'!C45/(1+$B23)^('DCF Model'!C19+0)+'DCF Model'!D45/(1+$B23)^('DCF Model'!C19+1)+'DCF Model'!E45/(1+$B23)^('DCF Model'!C19+2)+'DCF Model'!F45/(1+$B23)^('DCF Model'!C19+3)+'DCF Model'!G45/(1+$B23)^('DCF Model'!C19+4)+('DCF Model'!G39+'DCF Model'!G42)*F$17/(1+$B23)^('DCF Model'!C19+4)-'DCF Model'!C16)*1000000/'DCF Model'!C15,0),"") -> 3533 | G23: =IFERROR(ROUND(('DCF Model'!C45/(1+$B23)^('DCF Model'!C19+0)+'DCF Model'!D45/(1+$B23)^('DCF Model'!C19+1)+'DCF Model'!E45/(1+$B23)^('DCF Model'!C19+2)+'DCF Model'!F45/(1+$B23)^('DCF Model'!C19+3)+'DCF Model'!G45/(1+$B23)^('DCF Model'!C19+4)+('DCF Model'!G39+'DCF Model'!G42)*G$17/(1+$B23)^('DCF Model'!C19+4)-'DCF Model'!C16)*1000000/'DCF Model'!C15,0),"") -> 3811 | H23: =IFERROR(ROUND(('DCF Model'!C45/(1+$B23)^('DCF Model'!C19+0)+'DCF Model'!D45/(1+$B23)^('DCF Model'!C19+1)+'DCF Model'!E45/(1+$B23)^('DCF Model'!C19+2)+'DCF Model'!F45/(1+$B23)^('DCF Model'!C19+3)+'DCF Model'!G45/(1+$B23)^('DCF Model'!C19+4)+('DCF Model'!G39+'DCF Model'!G42)*H$17/(1+$B23)^('DCF Model'!C19+4)-'DCF Model'!C16)*1000000/'DCF Model'!C15,0),"") -> 4089 | I23: =IFERROR(ROUND(('DCF Model'!C45/(1+$B23)^('DCF Model'!C19+0)+'DCF Model'!D45/(1+$B23)^('DCF Model'!C19+1)+'DCF Model'!E45/(1+$B23)^('DCF Model'!C19+2)+'DCF Model'!F45/(1+$B23)^('DCF Model'!C19+3)+'DCF Model'!G45/(1+$B23)^('DCF Model'!C19+4)+('DCF Model'!G39+'DCF Model'!G42)*I$17/(1+$B23)^('DCF Model'!C19+4)-'DCF Model'!C16)*1000000/'DCF Model'!C15,0),"") -> 4368
B24: =$C$3+0.015 -> 0.1365 | C24: =IFERROR(ROUND(('DCF Model'!C45/(1+$B24)^('DCF Model'!C19+0)+'DCF Model'!D45/(1+$B24)^('DCF Model'!C19+1)+'DCF Model'!E45/(1+$B24)^('DCF Model'!C19+2)+'DCF Model'!F45/(1+$B24)^('DCF Model'!C19+3)+'DCF Model'!G45/(1+$B24)^('DCF Model'!C19+4)+('DCF Model'!G39+'DCF Model'!G42)*C$17/(1+$B24)^('DCF Model'!C19+4)-'DCF Model'!C16)*1000000/'DCF Model'!C15,0),"") -> 2667 | D24: =IFERROR(ROUND(('DCF Model'!C45/(1+$B24)^('DCF Model'!C19+0)+'DCF Model'!D45/(1+$B24)^('DCF Model'!C19+1)+'DCF Model'!E45/(1+$B24)^('DCF Model'!C19+2)+'DCF Model'!F45/(1+$B24)^('DCF Model'!C19+3)+'DCF Model'!G45/(1+$B24)^('DCF Model'!C19+4)+('DCF Model'!G39+'DCF Model'!G42)*D$17/(1+$B24)^('DCF Model'!C19+4)-'DCF Model'!C16)*1000000/'DCF Model'!C15,0),"") -> 2940 | E24: =IFERROR(ROUND(('DCF Model'!C45/(1+$B24)^('DCF Model'!C19+0)+'DCF Model'!D45/(1+$B24)^('DCF Model'!C19+1)+'DCF Model'!E45/(1+$B24)^('DCF Model'!C19+2)+'DCF Model'!F45/(1+$B24)^('DCF Model'!C19+3)+'DCF Model'!G45/(1+$B24)^('DCF Model'!C19+4)+('DCF Model'!G39+'DCF Model'!G42)*E$17/(1+$B24)^('DCF Model'!C19+4)-'DCF Model'!C16)*1000000/'DCF Model'!C15,0),"") -> 3213 | F24: =IFERROR(ROUND(('DCF Model'!C45/(1+$B24)^('DCF Model'!C19+0)+'DCF Model'!D45/(1+$B24)^('DCF Model'!C19+1)+'DCF Model'!E45/(1+$B24)^('DCF Model'!C19+2)+'DCF Model'!F45/(1+$B24)^('DCF Model'!C19+3)+'DCF Model'!G45/(1+$B24)^('DCF Model'!C19+4)+('DCF Model'!G39+'DCF Model'!G42)*F$17/(1+$B24)^('DCF Model'!C19+4)-'DCF Model'!C16)*1000000/'DCF Model'!C15,0),"") -> 3487 | G24: =IFERROR(ROUND(('DCF Model'!C45/(1+$B24)^('DCF Model'!C19+0)+'DCF Model'!D45/(1+$B24)^('DCF Model'!C19+1)+'DCF Model'!E45/(1+$B24)^('DCF Model'!C19+2)+'DCF Model'!F45/(1+$B24)^('DCF Model'!C19+3)+'DCF Model'!G45/(1+$B24)^('DCF Model'!C19+4)+('DCF Model'!G39+'DCF Model'!G42)*G$17/(1+$B24)^('DCF Model'!C19+4)-'DCF Model'!C16)*1000000/'DCF Model'!C15,0),"") -> 3760 | H24: =IFERROR(ROUND(('DCF Model'!C45/(1+$B24)^('DCF Model'!C19+0)+'DCF Model'!D45/(1+$B24)^('DCF Model'!C19+1)+'DCF Model'!E45/(1+$B24)^('DCF Model'!C19+2)+'DCF Model'!F45/(1+$B24)^('DCF Model'!C19+3)+'DCF Model'!G45/(1+$B24)^('DCF Model'!C19+4)+('DCF Model'!G39+'DCF Model'!G42)*H$17/(1+$B24)^('DCF Model'!C19+4)-'DCF Model'!C16)*1000000/'DCF Model'!C15,0),"") -> 4033 | I24: =IFERROR(ROUND(('DCF Model'!C45/(1+$B24)^('DCF Model'!C19+0)+'DCF Model'!D45/(1+$B24)^('DCF Model'!C19+1)+'DCF Model'!E45/(1+$B24)^('DCF Model'!C19+2)+'DCF Model'!F45/(1+$B24)^('DCF Model'!C19+3)+'DCF Model'!G45/(1+$B24)^('DCF Model'!C19+4)+('DCF Model'!G39+'DCF Model'!G42)*I$17/(1+$B24)^('DCF Model'!C19+4)-'DCF Model'!C16)*1000000/'DCF Model'!C15,0),"") -> 4307
B26: All values dynamically linked to DCF Model. Headers auto-center on current WACC / Terminal g / Exit Multiple.

Sheet Segment Analysis
B2: Segment Analysis - 株式会社コア
C4: FY2024 | D4: FY2025 | E4: FY2026 | F4: FY2027 | G4: FY2027(E) | H4: FY2028(E) | I4: FY2029(E) | J4: FY2030(E) | K4: FY2031(E)
B5: Future Society Solutions (未来社会ソリューション)
B6: Revenue | C6: — | D6: 4771 | E6: 4570 | F6: 5084 | G6: =F6*(1+CHOOSE('DCF Model'!$D$27,G34,G35,G36,G37,G38)) -> 6034.708 | H6: =G6*(1+CHOOSE('DCF Model'!$D$27,H34,H35,H36,H37,H38)) -> 7163.1984 | I6: =H6*(1+CHOOSE('DCF Model'!$D$27,I34,I35,I36,I37,I38)) -> 8502.7165 | J6: =I6*(1+CHOOSE('DCF Model'!$D$27,J34,J35,J36,J37,J38)) -> 9352.9881 | K6: =J6*(1+CHOOSE('DCF Model'!$D$27,K34,K35,K36,K37,K38)) -> 10007.697
B7: Operating Profit | C7: — | D7: 675 | E7: 461 | F7: 730 | G7: =G6*CHOOSE('DCF Model'!$D$27,G41,G42,G43,G44,G45) -> 875.03266 | H7: =H6*CHOOSE('DCF Model'!$D$27,H41,H42,H43,H44,H45) -> 1110.2958 | I7: =I6*CHOOSE('DCF Model'!$D$27,I41,I42,I43,I44,I45) -> 1445.4618 | J7: =J6*CHOOSE('DCF Model'!$D$27,J41,J42,J43,J44,J45) -> 1683.5379 | K7: =K6*CHOOSE('DCF Model'!$D$27,K41,K42,K43,K44,K45) -> 1851.424
B8: OP Margin | C8: — | D8: =D7/D6 -> 0.14147977 | E8: =E7/E6 -> 0.10087527 | F8: =F7/F6 -> 0.14358773 | G8: =CHOOSE('DCF Model'!$D$27,G41,G42,G43,G44,G45) -> 0.145 | H8: =CHOOSE('DCF Model'!$D$27,H41,H42,H43,H44,H45) -> 0.155 | I8: =CHOOSE('DCF Model'!$D$27,I41,I42,I43,I44,I45) -> 0.17 | J8: =CHOOSE('DCF Model'!$D$27,J41,J42,J43,J44,J45) -> 0.18 | K8: =CHOOSE('DCF Model'!$D$27,K41,K42,K43,K44,K45) -> 0.185
B10: Industrial Technology Solutions (産業技術ソリューション)
B11: Revenue | C11: — | D11: 10546 | E11: 12035 | F11: 13695 | G11: =F11*(1+CHOOSE('DCF Model'!$D$27,G48,G49,G50,G51,G52)) -> 14571.48 | H11: =G11*(1+CHOOSE('DCF Model'!$D$27,H48,H49,H50,H51,H52)) -> 15504.055 | I11: =H11*(1+CHOOSE('DCF Model'!$D$27,I48,I49,I50,I51,I52)) -> 16496.314 | J11: =I11*(1+CHOOSE('DCF Model'!$D$27,J48,J49,J50,J51,J52)) -> 17321.13 | K11: =J11*(1+CHOOSE('DCF Model'!$D$27,K48,K49,K50,K51,K52)) -> 18013.975
B12: Operating Profit | C12: — | D12: 1641 | E12: 1884 | F12: 2260 | G12: =G11*CHOOSE('DCF Model'!$D$27,G55,G56,G57,G58,G59) -> 2404.2942 | H12: =H11*CHOOSE('DCF Model'!$D$27,H55,H56,H57,H58,H59) -> 2558.169 | I12: =I11*CHOOSE('DCF Model'!$D$27,I55,I56,I57,I58,I59) -> 2721.8918 | J12: =J11*CHOOSE('DCF Model'!$D$27,J55,J56,J57,J58,J59) -> 2944.5921 | K12: =K11*CHOOSE('DCF Model'!$D$27,K55,K56,K57,K58,K59) -> 3152.4456
B13: OP Margin | C13: — | D13: =D12/D11 -> 0.15560402 | E13: =E12/E11 -> 0.15654342 | F13: =F12/F11 -> 0.16502373 | G13: =CHOOSE('DCF Model'!$D$27,G55,G56,G57,G58,G59) -> 0.165 | H13: =CHOOSE('DCF Model'!$D$27,H55,H56,H57,H58,H59) -> 0.165 | I13: =CHOOSE('DCF Model'!$D$27,I55,I56,I57,I58,I59) -> 0.165 | J13: =CHOOSE('DCF Model'!$D$27,J55,J56,J57,J58,J59) -> 0.17 | K13: =CHOOSE('DCF Model'!$D$27,K55,K56,K57,K58,K59) -> 0.175
B15: Customer Business Integration (顧客業務インテグレーション)
B16: Revenue | C16: — | D16: 8680 | E16: 7993 | F16: 7751 | G16: =F16*(1+CHOOSE('DCF Model'!$D$27,G62,G63,G64,G65,G66)) -> 8440.839 | H16: =G16*(1+CHOOSE('DCF Model'!$D$27,H62,H63,H64,H65,H66)) -> 9192.0737 | I16: =H16*(1+CHOOSE('DCF Model'!$D$27,I62,I63,I64,I65,I66)) -> 10010.168 | J16: =I16*(1+CHOOSE('DCF Model'!$D$27,J62,J63,J64,J65,J66)) -> 10410.575 | K16: =J16*(1+CHOOSE('DCF Model'!$D$27,K62,K63,K64,K65,K66)) -> 10618.786
B17: Operating Profit | C17: — | D17: 823 | E17: 829 | F17: 830 | G17: =G16*CHOOSE('DCF Model'!$D$27,G69,G70,G71,G72,G73) -> 844.0839 | H17: =H16*CHOOSE('DCF Model'!$D$27,H69,H70,H71,H72,H73) -> 965.16774 | I17: =I16*CHOOSE('DCF Model'!$D$27,I69,I70,I71,I72,I73) -> 1151.1693 | J17: =J16*CHOOSE('DCF Model'!$D$27,J69,J70,J71,J72,J73) -> 1249.269 | K17: =K16*CHOOSE('DCF Model'!$D$27,K69,K70,K71,K72,K73) -> 1327.3483
B18: OP Margin | C18: — | D18: =D17/D16 -> 0.094815668 | E18: =E17/E16 -> 0.10371575 | F18: =F17/F16 -> 0.10708296 | G18: =CHOOSE('DCF Model'!$D$27,G69,G70,G71,G72,G73) -> 0.1 | H18: =CHOOSE('DCF Model'!$D$27,H69,H70,H71,H72,H73) -> 0.105 | I18: =CHOOSE('DCF Model'!$D$27,I69,I70,I71,I72,I73) -> 0.115 | J18: =CHOOSE('DCF Model'!$D$27,J69,J70,J71,J72,J73) -> 0.12 | K18: =CHOOSE('DCF Model'!$D$27,K69,K70,K71,K72,K73) -> 0.125
B20: Consolidated Total
B21: Total Revenue | C21: =C6+C11+C16 -> #VALUE! | D21: =D6+D11+D16 -> 23997 | E21: =E6+E11+E16 -> 24598 | F21: =F6+F11+F16 -> 26530 | G21: =G6+G11+G16 -> 29047.027 | H21: =H6+H11+H16 -> 31859.327 | I21: =I6+I11+I16 -> 35009.199 | J21: =J6+J11+J16 -> 37084.693 | K21: =K6+K11+K16 -> 38640.459
B22: Total Operating Profit | C22: =C7+C12+C17 -> #VALUE! | D22: =D7+D12+D17 -> 3139 | E22: =E7+E12+E17 -> 3174 | F22: =F7+F12+F17 -> 3820 | G22: =G7+G12+G17 -> 4123.4108 | H22: =H7+H12+H17 -> 4633.6325 | I22: =I7+I12+I17 -> 5318.523 | J22: =J7+J12+J17 -> 5877.3989 | K22: =K7+K12+K17 -> 6331.218
B23: Total OP Margin | C23: =IFERROR(C22/C21,"—") -> — | D23: =IFERROR(D22/D21,"—") -> 0.13080802 | E23: =IFERROR(E22/E21,"—") -> 0.12903488 | F23: =IFERROR(F22/F21,"—") -> 0.14398794 | G23: =IFERROR(G22/G21,"—") -> 0.14195638 | H23: =IFERROR(H22/H21,"—") -> 0.14544038 | I23: =IFERROR(I22/I21,"—") -> 0.15191787 | J23: =IFERROR(J22/J21,"—") -> 0.15848585 | K23: =IFERROR(K22/K21,"—") -> 0.16384945
B25: Reconciliation vs DCF Model
B26: DCF Model Revenue | G26: ='DCF Model'!C33 -> 29047.027 | H26: ='DCF Model'!D33 -> 31859.327 | I26: ='DCF Model'!E33 -> 35009.199 | J26: ='DCF Model'!F33 -> 37084.693 | K26: ='DCF Model'!G33 -> 38640.459
B27: Segment Total Revenue | G27: =G21 -> 29047.027 | H27: =H21 -> 31859.327 | I27: =I21 -> 35009.199 | J27: =J21 -> 37084.693 | K27: =K21 -> 38640.459
B28: Difference | G28: =G27-G26 -> 0 | H28: =H27-H26 -> 0 | I28: =I27-I26 -> 0 | J28: =J27-J26 -> 0 | K28: =K27-K26 -> 0
B31: Segment Scenario Input Matrix
