Workbook

Sheet Executive Summary
B1: DISCLAIMER: This is a sample analysis for demonstration purposes only. It does not constitute investment advice.
B3: 株式会社コア (2359.T)
B4: Equity Research Report
B6: Company | C6: 株式会社コア
B7: Ticker | C7: 2359.T (TSE)
B8: Sector | C8: Information & Communication
B9: Current Price | C9: 2011
B10: Target Price (Mid) | C10: =ROUND(AVERAGE(C16:C19),0) -> 2666
B11: Recommendation | C11: =IF(C12>0.15,"BUY",IF(C12>0.05,"HOLD","SELL")) -> BUY
B12: Upside / Downside | C12: =(C10-C9)/C9 -> 0.3257086
B14: Valuation Summary
B15: Methodology | C15: Implied Value (JPY) | D15: vs Current Price
B16: DCF - Perpetuity Growth | C16: ='DCF Model'!C55 -> 2893 | D16: =(C16-C9)/C9 -> 0.43858777
B17: DCF - Exit Multiple | C17: ='DCF Model'!C64 -> 3298 | D17: =(C17-C9)/C9 -> 0.63998011
B18: Comps - EV/EBITDA Median | C18: ='Comps Analysis'!C27 -> 2450 | D18: =(C18-C9)/C9 -> 0.21829935
B19: Comps - PER Median | C19: ='Comps Analysis'!C28 -> 2021 | D19: =(C19-C9)/C9 -> 0.0049726504
B21: Integrated Valuation Range | C21: =MIN(C16:C19)&" - "&MAX(C16:C19) -> 2021 - 3298
B23: Key Investment Thesis
B24: 1. Defense Tech: GNSS anti-spoofing tech for JASDF; 4-layer moat (proprietary receiver + QZSS auth + security clearance + space tech track record)
B25: 2. AX Transformation: Layer 2 (solution) ratio rising 25.9% → 33.3%, structurally improving OPM
B26: 3. Earnings Surprise: Base case EPS >¥200 vs consensus ~¥174; Q3 OP progress rate 82.5% implies ~¥4,050M OP
B28: Key Risks
B29: 1. Defense contracts still in R&D/validation phase — mass production orders unconfirmed
B30: 2. Key person risk in specialized GNSS/space technology division
B31: 3. Revenue concentration in Japanese domestic IT services market

Sheet Financial Statements
B2: 株式会社コア - Historical Financials (JPY mn)
C4: FY2021 | D4: FY2022 | E4: FY2023 | F4: FY2024 | G4: FY2025
B5: Income Statement
B6: Revenue | C6: 20785.262 | D6: 21798.077 | E6: 22848.129 | F6: 23998.562 | G6: 24599.166
B7: COGS | C7: 15524.609 | D7: 16231.035 | E7: 16853.21 | F7: 17407.88 | G7: 17821.475
B8: Gross Profit | C8: =C6-C7 -> 5260.653 | D8: =D6-D7 -> 5567.042 | E8: =E6-E7 -> 5994.919 | F8: =F6-F7 -> 6590.682 | G8: =G6-G7 -> 6777.691
B9: Gross Margin | C9: =C8/C6 -> 0.25309534 | D9: =D8/D6 -> 0.25539143 | E9: =E8/E6 -> 0.26238118 | F9: =F8/F6 -> 0.2746282 | G9: =G8/G6 -> 0.27552524
B10: SGA | C10: 3228.568 | D10: 3199.384 | E10: 3251.051 | F10: 3450.098 | G10: 3602.229
B11: Operating Income | C11: 2032.084 | D11: 2367.658 | E11: 2743.867 | F11: 3140.583 | G11: 3175.462
B12: Net Income | C12: 1423.358 | D12: 1622.716 | E12: 1968.404 | F12: 2270.704 | G12: 2242.34
B13: Operating Margin | C13: =C11/C6 -> 0.097765619 | D13: =D11/D6 -> 0.10861775 | E13: =E11/E6 -> 0.12009154 | F13: =F11/F6 -> 0.13086547 | G13: =G11/G6 -> 0.1290882
B14: Net Margin | C14: =C12/C6 -> 0.068479195 | D14: =D12/D6 -> 0.07444308 | E14: =E12/E6 -> 0.086151649 | F14: =F12/F6 -> 0.094618336 | G14: =G12/G6 -> 0.091155123
B15: Revenue Growth (YoY) | C15: n/a | D15: =(D6-C6)/C6 -> 0.048727555 | E15: =(E6-D6)/D6 -> 0.048171772 | F15: =(F6-E6)/E6 -> 0.0503513 | G15: =(G6-F6)/F6 -> 0.025026666
B16: Operating Income Growth (YoY) | C16: n/a | D16: =(D11-C11)/C11 -> 0.16513786 | E16: =(E11-D11)/D11 -> 0.15889499 | F16: =(F11-E11)/E11 -> 0.14458281 | G16: =(G11-F11)/F11 -> 0.0111059
B18: Cash Flow Statement
B19: Operating Cash Flow | C19: 1851.105 | D19: 1799.231 | E19: 1943.795 | F19: 2190.094 | G19: 2372.799
B20: Capex | C20: 93.543 | D20: 72.084 | E20: 85.455 | F20: 93.4 | G20: 95.32
B21: Free Cash Flow | C21: =C19-C20 -> 1757.562 | D21: =D19-D20 -> 1727.147 | E21: =E19-E20 -> 1858.34 | F21: =F19-F20 -> 2096.694 | G21: =G19-G20 -> 2277.479
B22: FCF Margin | C22: =C21/C6 -> 0.084558087 | D22: =D21/D6 -> 0.079233916 | E22: =E21/E6 -> 0.08133445 | F22: =F21/F6 -> 0.087367485 | G22: =G21/G6 -> 0.092583586
B23: Capex / Revenue | C23: =C20/C6 -> 0.0045004484 | D23: =D20/D6 -> 0.0033068972 | E23: =E20/E6 -> 0.0037401312 | F23: =F20/F6 -> 0.0038918999 | G23: =G20/G6 -> 0.0038749281
B25: Balance Sheet Highlights
B26: Cash & Deposits | C26: 3636.219 | D26: 4700.235 | E26: 5586.934 | F26: 6300.075 | G26: 7586.071
B27: Short-term Debt | C27: 2109.7 | D27: 1963.6 | E27: 1812 | F27: 1734.8 | G27: 1412.4
B28: Net Debt (Cash) | C28: =C27-C26 -> -1526.519 | D28: =D27-D26 -> -2736.635 | E28: =E27-E26 -> -3774.934 | F28: =F27-F26 -> -4565.275 | G28: =G27-G26 -> -6173.671

Sheet DCF Model
B2: DCF Valuation Model - 株式会社コア
B4: Assumptions
B5: Capex / Revenue | C5: 0.0041668079
B6: Effective Tax Rate | C6: 0.305
B7: Risk-Free Rate | C7: 0.022
B8: Beta | C8: 0.88
B9: Equity Risk Premium | C9: 0.065
B10: Size Premium | C10: 0.04
B11: After-tax Cost of Debt | C11: 0.005
B12: D/E Ratio | C12: 0
B13: Terminal Growth Rate | C13: 0.02
B14: Exit Multiple (EV/EBITDA) | C14: 8
B15: Fully Diluted Shares | C15: 14368501
B16: Net Debt (JPY mn) | C16: -7296.8
... B20: LTM Revenue (JPY mn) | C20: 24599
B22: WACC Calculation
B23: Cost of Equity (Ke) | C23: =C7+C8*C9+C10 -> 0.1192
B24: Weight of Equity | C24: =1/(1+C12) -> 1
B25: Weight of Debt | C25: =C12/(1+C12) -> 0
B26: WACC | C26: =C23*C24+C11*C25 -> 0.1192
B27: Active Scenario | C27: Base | D27: =MATCH(C27,{"Base","Upside","Management","Downside 1","Downside 2"},0) -> 1
B28: Projected Free Cash Flow
C29: FY2026(E) | D29: FY2027(E) | E29: FY2028(E) | F29: FY2029(E) | G29: FY2030(E)
B30: Revenue Growth (YoY) | C30: =(C33/C17)-1 -> 0.1738837 | D30: =(D33/C33)-1 -> 0.085724203 | E30: =(E33/D33)-1 -> 0.070924591 | F30: =(F33/E33)-1 -> 0.052593291 | G30: =(G33/F33)-1 -> 0.040871093
B31: COGS % of Revenue | C31: =CHOOSE($D$27,'Segment Analysis'!F79,'Segment Analysis'!F80,'Segment Analysis'!F81,'Segment Analysis'!F82,'Segment Analysis'!F83) -> 0.7245 | D31: =CHOOSE($D$27,'Segment Analysis'!G79,'Segment Analysis'!G80,'Segment Analysis'!G81,'Segment Analysis'!G82,'Segment Analysis'!G83) -> 0.7245 | E31: =CHOOSE($D$27,'Segment Analysis'!H79,'Segment Analysis'!H80,'Segment Analysis'!H81,'Segment Analysis'!H82,'Segment Analysis'!H83) -> 0.7245 | F31: =CHOOSE($D$27,'Segment Analysis'!I79,'Segment Analysis'!I80,'Segment Analysis'!I81,'Segment Analysis'!I82,'Segment Analysis'!I83) -> 0.7245 | G31: =CHOOSE($D$27,'Segment Analysis'!J79,'Segment Analysis'!J80,'Segment Analysis'!J81,'Segment Analysis'!J82,'Segment Analysis'!J83) -> 0.7245
B32: SGA % of Revenue | C32: =CHOOSE($D$27,'Segment Analysis'!F86,'Segment Analysis'!F87,'Segment Analysis'!F88,'Segment Analysis'!F89,'Segment Analysis'!F90) -> 0.133 | D32: =CHOOSE($D$27,'Segment Analysis'!G86,'Segment Analysis'!G87,'Segment Analysis'!G88,'Segment Analysis'!G89,'Segment Analysis'!G90) -> 0.13 | E32: =CHOOSE($D$27,'Segment Analysis'!H86,'Segment Analysis'!H87,'Segment Analysis'!H88,'Segment Analysis'!H89,'Segment Analysis'!H90) -> 0.128 | F32: =CHOOSE($D$27,'Segment Analysis'!I86,'Segment Analysis'!I87,'Segment Analysis'!I88,'Segment Analysis'!I89,'Segment Analysis'!I90) -> 0.126 | G32: =CHOOSE($D$27,'Segment Analysis'!J86,'Segment Analysis'!J87,'Segment Analysis'!J88,'Segment Analysis'!J89,'Segment Analysis'!J90) -> 0.125
B33: Revenue | C33: ='Segment Analysis'!F21 -> 28876.56 | D33: ='Segment Analysis'!G21 -> 31351.98 | E33: ='Segment Analysis'!H21 -> 33575.606 | F33: ='Segment Analysis'!I21 -> 35341.458 | G33: ='Segment Analysis'!J21 -> 36785.902
B34: COGS | C34: =C33*C31 -> 20921.068 | D34: =D33*D31 -> 22714.51 | E34: =E33*E31 -> 24325.527 | F34: =F33*F31 -> 25604.886 | G34: =G33*G31 -> 26651.386
B35: Gross Profit | C35: =C33-C34 -> 7955.4923 | D35: =D33-D34 -> 8637.4705 | E35: =E33-E34 -> 9250.0796 | F35: =F33-F34 -> 9736.5717 | G35: =G33-G34 -> 10134.516
B36: Gross Margin | C36: =C35/C33 -> 0.2755 | D36: =D35/D33 -> 0.2755 | E36: =E35/E33 -> 0.2755 | F36: =F35/F33 -> 0.2755 | G36: =G35/G33 -> 0.2755
B37: SGA Expense | C37: =C33*C32 -> 3840.5825 | D37: =D33*D32 -> 4075.7574 | E37: =E33*E32 -> 4297.6776 | F37: =F33*F32 -> 4453.0237 | G37: =G33*G32 -> 4598.2378
B38: Implied Operating Margin | C38: =C39/C33 -> 0.1425 | D38: =D39/D33 -> 0.1455 | E38: =E39/E33 -> 0.1475 | F38: =F39/F33 -> 0.1495 | G38: =G39/G33 -> 0.1505
B39: Operating Income (EBIT) | C39: =C35-C37 -> 4114.9098 | D39: =D35-D37 -> 4561.7131 | E39: =E35-E37 -> 4952.402 | F39: =F35-F37 -> 5283.548 | G39: =G35-G37 -> 5536.2783
B40: Less: Tax | C40: =MAX(0,C39*C6) -> 1255.0475 | D40: =MAX(0,D39*C6) -> 1391.3225 | E40: =MAX(0,E39*C6) -> 1510.4826 | F40: =MAX(0,F39*C6) -> 1611.4821 | G40: =MAX(0,G39*C6) -> 1688.5649
B41: NOPAT | C41: =C39-C40 -> 2859.8623 | D41: =D39-D40 -> 3170.3906 | E41: =E39-E40 -> 3441.9194 | F41: =F39-F40 -> 3672.0659 | G41: =G39-G40 -> 3847.7134
B42: Plus: D&A | C42: 210 | D42: 210 | E42: 210 | F42: 215 | G42: =G33*C18 -> 315.90591
B43: Less: Capex | C43: 100 | D43: 100 | E43: 105 | F43: 105 | G43: =G33*C5 -> 153.27979
B44: Change in NWC | C44: ='NWC Schedule'!D19 -> 1026.8724 | D44: ='NWC Schedule'!E19 -> 613.76994 | E44: ='NWC Schedule'!F19 -> 570.91759 | F44: ='NWC Schedule'!G19 -> 453.38362 | G44: ='NWC Schedule'!H19 -> 370.862
B45: Unlevered Free Cash Flow | C45: =C41+C42-C43-C44 -> 1942.9899 | D45: =D41+D42-D43-D44 -> 2666.6207 | E45: =E41+E42-E43-E44 -> 2976.0018 | F45: =F41+F42-F43-F44 -> 3328.6822 | G45: =G41+G42-G43-G44 -> 3639.4775
B46: Discount Factor | C46: =1/(1+C26)^(C19+0) -> 0.97223908 | D46: =1/(1+C26)^(C19+1) -> 0.8686911 | E46: =1/(1+C26)^(C19+2) -> 0.77617146 | F46: =1/(1+C26)^(C19+3) -> 0.6935056 | G46: =1/(1+C26)^(C19+4) -> 0.61964403
...

Sheet NWC Schedule
B2: NWC Schedule - 株式会社コア
B4: Working Capital Drivers (Days) | C4: Base Year | D4: FY2026(E) | E4: FY2027(E) | F4: FY2028(E) | G4: FY2029(E) | H4: FY2030(E)
B5: DSO (Days Sales Outstanding) | C5: =C12/C9*365 -> 116.89299 | D5: =CHOOSE('DCF Model'!$D$27,D25,D26,D27,D28,D29) -> 115 | E5: =CHOOSE('DCF Model'!$D$27,E25,E26,E27,E28,E29) -> 114 | F5: =CHOOSE('DCF Model'!$D$27,F25,F26,F27,F28,F29) -> 114 | G5: =CHOOSE('DCF Model'!$D$27,G25,G26,G27,G28,G29) -> 114 | H5: =CHOOSE('DCF Model'!$D$27,H25,H26,H27,H28,H29) -> 114
B6: DIH (Days Inventory Held) | C6: =C13/C10*365 -> 5.5093644 | D6: =CHOOSE('DCF Model'!$D$27,D32,D33,D34,D35,D36) -> 6 | E6: =CHOOSE('DCF Model'!$D$27,E32,E33,E34,E35,E36) -> 6 | F6: =CHOOSE('DCF Model'!$D$27,F32,F33,F34,F35,F36) -> 6 | G6: =CHOOSE('DCF Model'!$D$27,G32,G33,G34,G35,G36) -> 6 | H6: =CHOOSE('DCF Model'!$D$27,H32,H33,H34,H35,H36) -> 6
B7: DPO (Days Payable Outstanding) | C7: =C15/C10*365 -> 35.595819 | D7: =CHOOSE('DCF Model'!$D$27,D39,D40,D41,D42,D43) -> 35 | E7: =CHOOSE('DCF Model'!$D$27,E39,E40,E41,E42,E43) -> 34 | F7: =CHOOSE('DCF Model'!$D$27,F39,F40,F41,F42,F43) -> 34 | G7: =CHOOSE('DCF Model'!$D$27,G39,G40,G41,G42,G43) -> 34 | H7: =CHOOSE('DCF Model'!$D$27,H39,H40,H41,H42,H43) -> 34
B8: P&L Reference (JPY mn)
B9: Revenue | C9: 24599.166 | D9: ='DCF Model'!C33 -> 28876.56 | E9: ='DCF Model'!D33 -> 31351.98 | F9: ='DCF Model'!E33 -> 33575.606 | G9: ='DCF Model'!F33 -> 35341.458 | H9: ='DCF Model'!G33 -> 36785.902
B10: COGS | C10: 17821.475 | D10: ='DCF Model'!C34 -> 20921.068 | E10: ='DCF Model'!D34 -> 22714.51 | F10: ='DCF Model'!E34 -> 24325.527 | G10: ='DCF Model'!F34 -> 25604.886 | H10: ='DCF Model'!G34 -> 26651.386
B11: Working Capital Items (JPY mn)
B12: Accounts Receivable | C12: 7878 | D12: =D9*D5/365 -> 9098.0942 | E12: =E9*E5/365 -> 9792.1253 | F12: =F9*F5/365 -> 10486.628 | G12: =G9*G5/365 -> 11038.154 | H12: =H9*H5/365 -> 11489.295
B13: Inventory | C13: 269 | D13: =D10*D6/365 -> 343.90796 | E13: =E10*E6/365 -> 373.3892 | F13: =F10*F6/365 -> 399.87167 | G13: =G10*G6/365 -> 420.90224 | H13: =H10*H6/365 -> 438.10498
B14: Current Assets (AR + Inv) | C14: =C12+C13 -> 8147 | D14: =D12+D13 -> 9442.0022 | E14: =E12+E13 -> 10165.514 | F14: =F12+F13 -> 10886.499 | G14: =G12+G13 -> 11459.056 | H14: =H12+H13 -> 11927.4
B15: Accounts Payable | C15: 1738 | D15: =D10*D7/365 -> 2006.1298 | E15: =E10*E7/365 -> 2115.8721 | F15: =F10*F7/365 -> 2265.9395 | G15: =G10*G7/365 -> 2385.1127 | H15: =H10*H7/365 -> 2482.5949
B16: Current Liabilities (AP) | C16: =C15 -> 1738 | D16: =D15 -> 2006.1298 | E16: =E15 -> 2115.8721 | F16: =F15 -> 2265.9395 | G16: =G15 -> 2385.1127 | H16: =H15 -> 2482.5949
B17: Net Working Capital (JPY mn)
B18: Net Working Capital | C18: =C14-C16 -> 6409 | D18: =D14-D16 -> 7435.8724 | E18: =E14-E16 -> 8049.6424 | F18: =F14-F16 -> 8620.56 | G18: =G14-G16 -> 9073.9436 | H18: =H14-H16 -> 9444.8056
B19: Change in NWC | C19: n/a | D19: =D18-C18 -> 1026.8724 | E19: =E18-D18 -> 613.76994 | F19: =F18-E18 -> 570.91759 | G19: =G18-F18 -> 453.38362 | H19: =H18-G18 -> 370.862
B22: Scenario Input Matrix (Working Capital Days)
D23: FY2026(E) | E23: FY2027(E) | F23: FY2028(E) | G23: FY2029(E) | H23: FY2030(E)
B24: DSO (Days)
B25: Base | D25: 115 | E25: 114 | F25: 114 | G25: 114 | H25: 114
B26: Upside | D26: 113 | E26: 111 | F26: 109 | G26: 107 | H26: 107
B27: Management | D27: 116 | E27: 115 | F27: 115 | G27: 115 | H27: 115
B28: Downside 1 | D28: 118 | E28: 119 | F28: 120 | G28: 120 | H28: 120
B29: Downside 2 | D29: 120 | E29: 122 | F29: 124 | G29: 125 | H29: 125
B31: DIH (Days)
B32: Base | D32: 6 | E32: 6 | F32: 6 | G32: 6 | H32: 6
B33: Upside | D33: 5.5 | E33: 5.5 | F33: 5.5 | G33: 5.5 | H33: 5.5
B34: Management | D34: 6 | E34: 6 | F34: 6 | G34: 6 | H34: 6
B35: Downside 1 | D35: 6.5 | E35: 6.5 | F35: 7 | G35: 7 | H35: 7
B36: Downside 2 | D36: 7 | E36: 7 | F36: 7.5 | G36: 7.5 | H36: 7.5
B38: DPO (Days)
B39: Base | D39: 35 | E39: 34 | F39: 34 | G39: 34 | H39: 34
B40: Upside | D40: 36 | E40: 37 | F40: 38 | G40: 38 | H40: 38
B41: Management | D41: 35 | E41: 35 | F41: 35 | G41: 35 | H41: 35
B42: Downside 1 | D42: 34 | E42: 33 | F42: 33 | G42: 33 | H42: 33
B43: Downside 2 | D43: 33 | E43: 32 | F43: 32 | G43: 32 | H43: 32

Sheet Comps Analysis
B2: Comparable Company Analysis
B4: Company | C4: Ticker | D4: Mkt Cap (JPY mn) | E4: EV (JPY mn) | F4: Revenue (JPY mn) | G4: EBITDA (JPY mn) | H4: Op Income (JPY mn) | I4: Net Income (JPY mn) | J4: EV/EBITDA | K4: EV/Revenue | L4: PER | M4: PBR | N4: Op Margin | O4: ROE
B5: Systena | C5: 2317.T | D5: 147986.71 | E5: 149536.71 | F5: 92410 | G5: 15820 | H5: 15360 | I5: 11250 | J5: =E5/G5 -> 9.4523837 | K5: =E5/F5 -> 1.6181875 | L5: =D5/I5 -> 13.154374 | M5: 4.4912507 | N5: =H5/F5 -> 0.16621578 | O5: 0.3414264
B6: SRA HD | C6: 3817.T | D6: 60200.481 | E6: 60270.481 | F6: 54700 | G6: 8490 | H6: 8300 | I6: 5000 | J6: =E6/G6 -> 7.0989966 | K6: =E6/F6 -> 1.1018369 | L6: =D6/I6 -> 12.040096 | M6: 1.9355201 | N6: =H6/F6 -> 0.15173675 | O6: 0.1607562
B7: CEC | C7: 9692.T | D7: 61796.721 | E7: 62146.721 | F7: 65000 | G7: 8018 | H7: 7200 | I7: 5150 | J7: =E7/G7 -> 7.7509006 | K7: =E7/F7 -> 0.95610339 | L7: =D7/I7 -> 11.999363 | M7: 1.5295839 | N7: =H7/F7 -> 0.11076923 | O7: 0.12747209
B8: Cresco | C8: 4674.T | D8: 58446.234 | E8: 55946.234 | F8: 48000 | G8: 6800 | H8: 5200 | I8: 3600 | J8: =E8/G8 -> 8.2273873 | K8: =E8/F8 -> 1.1655465 | L8: =D8/I8 -> 16.235065 | M8: 2.656647 | N8: =H8/F8 -> 0.10833333 | O8: 0.16363636
B9: DTS | C9: 9682.T | D9: 165563.47 | E9: 162563.47 | F9: 47000 | G9: 7500 | H9: 5700 | I9: 3900 | J9: =E9/G9 -> 21.675129 | K9: =E9/F9 -> 3.4587971 | L9: =D9/I9 -> 42.452171 | M9: 5.9129809 | N9: =H9/F9 -> 0.1212766 | O9: 0.13928571
B14: Statistics
B15: 25th Percentile | D15: =PERCENTILE(J5:J9,0.25) -> 7.7509006 | E15: =PERCENTILE(K5:K9,0.25) -> 1.1018369 | F15: =PERCENTILE(L5:L9,0.25) -> 12.040096 | G15: =PERCENTILE(M5:M9,0.25) -> 1.9355201 | H15: =PERCENTILE(N5:N9,0.25) -> 0.11076923 | I15: =PERCENTILE(O5:O9,0.25) -> 0.13928571
B16: Median (50th) | D16: =MEDIAN(J5:J9) -> 8.2273873 | E16: =MEDIAN(K5:K9) -> 1.1655465 | F16: =MEDIAN(L5:L9) -> 13.154374 | G16: =MEDIAN(M5:M9) -> 2.656647 | H16: =MEDIAN(N5:N9) -> 0.1212766 | I16: =MEDIAN(O5:O9) -> 0.1607562
B17: 75th Percentile | D17: =PERCENTILE(J5:J9,0.75) -> 9.4523837 | E17: =PERCENTILE(K5:K9,0.75) -> 1.6181875 | F17: =PERCENTILE(L5:L9,0.75) -> 16.235065 | G17: =PERCENTILE(M5:M9,0.75) -> 4.4912507 | H17: =PERCENTILE(N5:N9,0.75) -> 0.15173675 | I17: =PERCENTILE(O5:O9,0.75) -> 0.16363636
B19: Implied Valuation for 株式会社コア
B20: 株式会社コア Financials
B21: EBITDA (JPY mn) | C21: 3391
B22: Net Income (JPY mn) | C22: 2207
B23: Shares Outstanding | C23: 14368501
B24: Net Debt (JPY mn) | C24: -7296.8
B26: Implied Share Price (Median Multiples)
B27: Via EV/EBITDA (Median) | C27: =ROUND((C21*D16-C24)*1000000/C23,0) -> 2450
B28: Via PER (Median) | C28: =ROUND(C22*F16*1000000/C23,0) -> 2021

Sheet Sensitivity Analysis
B2: Sensitivity Analysis
B3: Current WACC: | C3: ='DCF Model'!C26 -> 0.1192 | E3: Terminal g: | F3: ='DCF Model'!C13 -> 0.02 | H3: Exit Multiple: | I3: ='DCF Model'!C14 -> 8
B5: Table 1: WACC vs Terminal Growth Rate (PGM - Implied Share Price, JPY)
B6: WACC \ Terminal g | C6: =$F$3-0.0075 -> 0.0125 | D6: =$F$3-0.005 -> 0.015 | E6: =$F$3-0.0025 -> 0.0175 | F6: =$F$3 -> 0.02 | G6: =$F$3+0.0025 -> 0.0225 | H6: =$F$3+0.005 -> 0.025 | I6: =$F$3+0.0075 -> 0.0275
B7: =$C$3-0.015 -> 0.1042 | C7: =IFERROR(ROUND(('DCF Model'!C45/(1+$B7)^('DCF Model'!C19+0)+'DCF Model'!D45/(1+$B7)^('DCF Model'!C19+1)+'DCF Model'!E45/(1+$B7)^('DCF Model'!C19+2)+'DCF Model'!F45/(1+$B7)^('DCF Model'!C19+3)+'DCF Model'!G45/(1+$B7)^('DCF Model'!C19+4)+'DCF Model'!G45*(1+C$6)/($B7-C$6)/(1+$B7)^('DCF Model'!C19+4)-'DCF Model'!C16)*1000000/'DCF Model'!C15,0),"") -> 3139 | D7: =IFERROR(ROUND(('DCF Model'!C45/(1+$B7)^('DCF Model'!C19+0)+'DCF Model'!D45/(1+$B7)^('DCF Model'!C19+1)+'DCF Model'!E45/(1+$B7)^('DCF Model'!C19+2)+'DCF Model'!F45/(1+$B7)^('DCF Model'!C19+3)+'DCF Model'!G45/(1+$B7)^('DCF Model'!C19+4)+'DCF Model'!G45*(1+D$6)/($B7-D$6)/(1+$B7)^('DCF Model'!C19+4)-'DCF Model'!C16)*1000000/'DCF Model'!C15,0),"") -> 3195 | E7: =IFERROR(ROUND(('DCF Model'!C45/(1+$B7)^('DCF Model'!C19+0)+'DCF Model'!D45/(1+$B7)^('DCF Model'!C19+1)+'DCF Model'!E45/(1+$B7)^('DCF Model'!C19+2)+'DCF Model'!F45/(1+$B7)^('DCF Model'!C19+3)+'DCF Model'!G45/(1+$B7)^('DCF Model'!C19+4)+'DCF Model'!G45*(1+E$6)/($B7-E$6)/(1+$B7)^('DCF Model'!C19+4)-'DCF Model'!C16)*1000000/'DCF Model'!C15,0),"") -> 3254 | F7: =IFERROR(ROUND(('DCF Model'!C45/(1+$B7)^('DCF Model'!C19+0)+'DCF Model'!D45/(1+$B7)^('DCF Model'!C19+1)+'DCF Model'!E45/(1+$B7)^('DCF Model'!C19+2)+'DCF Model'!F45/(1+$B7)^('DCF Model'!C19+3)+'DCF Model'!G45/(1+$B7)^('DCF Model'!C19+4)+'DCF Model'!G45*(1+F$6)/($B7-F$6)/(1+$B7)^('DCF Model'!C19+4)-'DCF Model'!C16)*1000000/'DCF Model'!C15,0),"") -> 3317 | G7: =IFERROR(ROUND(('DCF Model'!C45/(1+$B7)^('DCF Model'!C19+0)+'DCF Model'!D45/(1+$B7)^('DCF Model'!C19+1)+'DCF Model'!E45/(1+$B7)^('DCF Model'!C19+2)+'DCF Model'!F45/(1+$B7)^('DCF Model'!C19+3)+'DCF Model'!G45/(1+$B7)^('DCF Model'!C19+4)+'DCF Model'!G45*(1+G$6)/($B7-G$6)/(1+$B7)^('DCF Model'!C19+4)-'DCF Model'!C16)*1000000/'DCF Model'!C15,0),"") -> 3384 | H7: =IFERROR(ROUND(('DCF Model'!C45/(1+$B7)^('DCF Model'!C19+0)+'DCF Model'!D45/(1+$B7)^('DCF Model'!C19+1)+'DCF Model'!E45/(1+$B7)^('DCF Model'!C19+2)+'DCF Model'!F45/(1+$B7)^('DCF Model'!C19+3)+'DCF Model'!G45/(1+$B7)^('DCF Model'!C19+4)+'DCF Model'!G45*(1+H$6)/($B7-H$6)/(1+$B7)^('DCF Model'!C19+4)-'DCF Model'!C16)*1000000/'DCF Model'!C15,0),"") -> 3455 | I7: =IFERROR(ROUND(('DCF Model'!C45/(1+$B7)^('DCF Model'!C19+0)+'DCF Model'!D45/(1+$B7)^('DCF Model'!C19+1)+'DCF Model'!E45/(1+$B7)^('DCF Model'!C19+2)+'DCF Model'!F45/(1+$B7)^('DCF Model'!C19+3)+'DCF Model'!G45/(1+$B7)^('DCF Model'!C19+4)+'DCF Model'!G45*(1+I$6)/($B7-I$6)/(1+$B7)^('DCF Model'!C19+4)-'DCF Model'!C16)*1000000/'DCF Model'!C15,0),"") -> 3530
B8: =$C$3-0.01 -> 0.1092 | C8: =IFERROR(ROUND(('DCF Model'!C45/(1+$B8)^('DCF Model'!C19+0)+'DCF Model'!D45/(1+$B8)^('DCF Model'!C19+1)+'DCF Model'!E45/(1+$B8)^('DCF Model'!C19+2)+'DCF Model'!F45/(1+$B8)^('DCF Model'!C19+3)+'DCF Model'!G45/(1+$B8)^('DCF Model'!C19+4)+'DCF Model'!G45*(1+C$6)/($B8-C$6)/(1+$B8)^('DCF Model'!C19+4)-'DCF Model'!C16)*1000000/'DCF Model'!C15,0),"") -> 3002 | D8: =IFERROR(ROUND(('DCF Model'!C45/(1+$B8)^('DCF Model'!C19+0)+'DCF Model'!D45/(1+$B8)^('DCF Model'!C19+1)+'DCF Model'!E45/(1+$B8)^('DCF Model'!C19+2)+'DCF Model'!F45/(1+$B8)^('DCF Model'!C19+3)+'DCF Model'!G45/(1+$B8)^('DCF Model'!C19+4)+'DCF Model'!G45*(1+D$6)/($B8-D$6)/(1+$B8)^('DCF Model'!C19+4)-'DCF Model'!C16)*1000000/'DCF Model'!C15,0),"") -> 3052 | E8: =IFERROR(ROUND(('DCF Model'!C45/(1+$B8)^('DCF Model'!C19+0)+'DCF Model'!D45/(1+$B8)^('DCF Model'!C19+1)+'DCF Model'!E45/(1+$B8)^('DCF Model'!C19+2)+'DCF Model'!F45/(1+$B8)^('DCF Model'!C19+3)+'DCF Model'!G45/(1+$B8)^('DCF Model'!C19+4)+'DCF Model'!G45*(1+E$6)/($B8-E$6)/(1+$B8)^('DCF Model'!C19+4)-'DCF Model'!C16)*1000000/'DCF Model'!C15,0),"") -> 3104 | F8: =IFERROR(ROUND(('DCF Model'!C45/(1+$B8)^('DCF Model'!C19+0)+'DCF Model'!D45/(1+$B8)^('DCF Model'!C19+1)+'DCF Model'!E45/(1+$B8)^('DCF Model'!C19+2)+'DCF Model'!F45/(1+$B8)^('DCF Model'!C19+3)+'DCF Model'!G45/(1+$B8)^('DCF Model'!C19+4)+'DCF Model'!G45*(1+F$6)/($B8-F$6)/(1+$B8)^('DCF Model'!C19+4)-'DCF Model'!C16)*1000000/'DCF Model'!C15,0),"") -> 3160 | G8: =IFERROR(ROUND(('DCF Model'!C45/(1+$B8)^('DCF Model'!C19+0)+'DCF Model'!D45/(1+$B8)^('DCF Model'!C19+1)+'DCF Model'!E45/(1+$B8)^('DCF Model'!C19+2)+'DCF Model'!F45/(1+$B8)^('DCF Model'!C19+3)+'DCF Model'!G45/(1+$B8)^('DCF Model'!C19+4)+'DCF Model'!G45*(1+G$6)/($B8-G$6)/(1+$B8)^('DCF Model'!C19+4)-'DCF Model'!C16)*1000000/'DCF Model'!C15,0),"") -> 3218 | H8: =IFERROR(ROUND(('DCF Model'!C45/(1+$B8)^('DCF Model'!C19+0)+'DCF Model'!D45/(1+$B8)^('DCF Model'!C19+1)+'DCF Model'!E45/(1+$B8)^('DCF Model'!C19+2)+'DCF Model'!F45/(1+$B8)^('DCF Model'!C19+3)+'DCF Model'!G45/(1+$B8)^('DCF Model'!C19+4)+'DCF Model'!G45*(1+H$6)/($B8-H$6)/(1+$B8)^('DCF Model'!C19+4)-'DCF Model'!C16)*1000000/'DCF Model'!C15,0),"") -> 3280 | I8: =IFERROR(ROUND(('DCF Model'!C45/(1+$B8)^('DCF Model'!C19+0)+'DCF Model'!D45/(1+$B8)^('DCF Model'!C19+1)+'DCF Model'!E45/(1+$B8)^('DCF Model'!C19+2)+'DCF Model'!F45/(1+$B8)^('DCF Model'!C19+3)+'DCF Model'!G45/(1+$B8)^('DCF Model'!C19+4)+'DCF Model'!G45*(1+I$6)/($B8-I$6)/(1+$B8)^('DCF Model'!C19+4)-'DCF Model'!C16)*1000000/'DCF Model'!C15,0),"") -> 3346
B9: =$C$3-0.005 -> 0.1142 | C9: =IFERROR(ROUND(('DCF Model'!C45/(1+$B9)^('DCF Model'!C19+0)+'DCF Model'!D45/(1+$B9)^('DCF Model'!C19+1)+'DCF Model'!E45/(1+$B9)^('DCF Model'!C19+2)+'DCF Model'!F45/(1+$B9)^('DCF Model'!C19+3)+'DCF Model'!G45/(1+$B9)^('DCF Model'!C19+4)+'DCF Model'!G45*(1+C$6)/($B9-C$6)/(1+$B9)^('DCF Model'!C19+4)-'DCF Model'!C16)*1000000/'DCF Model'!C15,0),"") -> 2880 | D9: =IFERROR(ROUND(('DCF Model'!C45/(1+$B9)^('DCF Model'!C19+0)+'DCF Model'!D45/(1+$B9)^('DCF Model'!C19+1)+'DCF Model'!E45/(1+$B9)^('DCF Model'!C19+2)+'DCF Model'!F45/(1+$B9)^('DCF Model'!C19+3)+'DCF Model'!G45/(1+$B9)^('DCF Model'!C19+4)+'DCF Model'!G45*(1+D$6)/($B9-D$6)/(1+$B9)^('DCF Model'!C19+4)-'DCF Model'!C16)*1000000/'DCF Model'!C15,0),"") -> 2924 | E9: =IFERROR(ROUND(('DCF Model'!C45/(1+$B9)^('DCF Model'!C19+0)+'DCF Model'!D45/(1+$B9)^('DCF Model'!C19+1)+'DCF Model'!E45/(1+$B9)^('DCF Model'!C19+2)+'DCF Model'!F45/(1+$B9)^('DCF Model'!C19+3)+'DCF Model'!G45/(1+$B9)^('DCF Model'!C19+4)+'DCF Model'!G45*(1+E$6)/($B9-E$6)/(1+$B9)^('DCF Model'!C19+4)-'DCF Model'!C16)*1000000/'DCF Model'!C15,0),"") -> 2970 | F9: =IFERROR(ROUND(('DCF Model'!C45/(1+$B9)^('DCF Model'!C19+0)+'DCF Model'!D45/(1+$B9)^('DCF Model'!C19+1)+'DCF Model'!E45/(1+$B9)^('DCF Model'!C19+2)+'DCF Model'!F45/(1+$B9)^('DCF Model'!C19+3)+'DCF Model'!G45/(1+$B9)^('DCF Model'!C19+4)+'DCF Model'!G45*(1+F$6)/($B9-F$6)/(1+$B9)^('DCF Model'!C19+4)-'DCF Model'!C16)*1000000/'DCF Model'!C15,0),"") -> 3019 | G9: =IFERROR(ROUND(('DCF Model'!C45/(1+$B9)^('DCF Model'!C19+0)+'DCF Model'!D45/(1+$B9)^('DCF Model'!C19+1)+'DCF Model'!E45/(1+$B9)^('DCF Model'!C19+2)+'DCF Model'!F45/(1+$B9)^('DCF Model'!C19+3)+'DCF Model'!G45/(1+$B9)^('DCF Model'!C19+4)+'DCF Model'!G45*(1+G$6)/($B9-G$6)/(1+$B9)^('DCF Model'!C19+4)-'DCF Model'!C16)*1000000/'DCF Model'!C15,0),"") -> 3071 | H9: =IFERROR(ROUND(('DCF Model'!C45/(1+$B9)^('DCF Model'!C19+0)+'DCF Model'!D45/(1+$B9)^('DCF Model'!C19+1)+'DCF Model'!E45/(1+$B9)^('DCF Model'!C19+2)+'DCF Model'!F45/(1+$B9)^('DCF Model'!C19+3)+'DCF Model'!G45/(1+$B9)^('DCF Model'!C19+4)+'DCF Model'!G45*(1+H$6)/($B9-H$6)/(1+$B9)^('DCF Model'!C19+4)-'DCF Model'!C16)*1000000/'DCF Model'!C15,0),"") -> 3125 | I9: =IFERROR(ROUND(('DCF Model'!C45/(1+$B9)^('DCF Model'!C19+0)+'DCF Model'!D45/(1+$B9)^('DCF Model'!C19+1)+'DCF Model'!E45/(1+$B9)^('DCF Model'!C19+2)+'DCF Model'!F45/(1+$B9)^('DCF Model'!C19+3)+'DCF Model'!G45/(1+$B9)^('DCF Model'!C19+4)+'DCF Model'!G45*(1+I$6)/($B9-I$6)/(1+$B9)^('DCF Model'!C19+4)-'DCF Model'!C16)*1000000/'DCF Model'!C15,0),"") -> 3183
B10: =$C$3 -> 0.1192 | C10: =IFERROR(ROUND(('DCF Model'!C45/(1+$B10)^('DCF Model'!C19+0)+'DCF Model'!D45/(1+$B10)^('DCF Model'!C19+1)+'DCF Model'!E45/(1+$B10)^('DCF Model'!C19+2)+'DCF Model'!F45/(1+$B10)^('DCF Model'!C19+3)+'DCF Model'!G45/(1+$B10)^('DCF Model'!C19+4)+'DCF Model'!G45*(1+C$6)/($B10-C$6)/(1+$B10)^('DCF Model'!C19+4)-'DCF Model'!C16)*1000000/'DCF Model'!C15,0),"") -> 2768 | D10: =IFERROR(ROUND(('DCF Model'!C45/(1+$B10)^('DCF Model'!C19+0)+'DCF Model'!D45/(1+$B10)^('DCF Model'!C19+1)+'DCF Model'!E45/(1+$B10)^('DCF Model'!C19+2)+'DCF Model'!F45/(1+$B10)^('DCF Model'!C19+3)+'DCF Model'!G45/(1+$B10)^('DCF Model'!C19+4)+'DCF Model'!G45*(1+D$6)/($B10-D$6)/(1+$B10)^('DCF Model'!C19+4)-'DCF Model'!C16)*1000000/'DCF Model'!C15,0),"") -> 2808 | E10: =IFERROR(ROUND(('DCF Model'!C45/(1+$B10)^('DCF Model'!C19+0)+'DCF Model'!D45/(1+$B10)^('DCF Model'!C19+1)+'DCF Model'!E45/(1+$B10)^('DCF Model'!C19+2)+'DCF Model'!F45/(1+$B10)^('DCF Model'!C19+3)+'DCF Model'!G45/(1+$B10)^('DCF Model'!C19+4)+'DCF Model'!G45*(1+E$6)/($B10-E$6)/(1+$B10)^('DCF Model'!C19+4)-'DCF Model'!C16)*1000000/'DCF Model'!C15,0),"") -> 2849 | F10: =IFERROR(ROUND(('DCF Model'!C45/(1+$B10)^('DCF Model'!C19+0)+'DCF Model'!D45/(1+$B10)^('DCF Model'!C19+1)+'DCF Model'!E45/(1+$B10)^('DCF Model'!C19+2)+'DCF Model'!F45/(1+$B10)^('DCF Model'!C19+3)+'DCF Model'!G45/(1+$B10)^('DCF Model'!C19+4)+'DCF Model'!G45*(1+F$6)/($B10-F$6)/(1+$B10)^('DCF Model'!C19+4)-'DCF Model'!C16)*1000000/'DCF Model'!C15,0),"") -> 2893 | G10: =IFERROR(ROUND(('DCF Model'!C45/(1+$B10)^('DCF Model'!C19+0)+'DCF Model'!D45/(1+$B10)^('DCF Model'!C19+1)+'DCF Model'!E45/(1+$B10)^('DCF Model'!C19+2)+'DCF Model'!F45/(1+$B10)^('DCF Model'!C19+3)+'DCF Model'!G45/(1+$B10)^('DCF Model'!C19+4)+'DCF Model'!G45*(1+G$6)/($B10-G$6)/(1+$B10)^('DCF Model'!C19+4)-'DCF Model'!C16)*1000000/'DCF Model'!C15,0),"") -> 2939 | H10: =IFERROR(ROUND(('DCF Model'!C45/(1+$B10)^('DCF Model'!C19+0)+'DCF Model'!D45/(1+$B10)^('DCF Model'!C19+1)+'DCF Model'!E45/(1+$B10)^('DCF Model'!C19+2)+'DCF Model'!F45/(1+$B10)^('DCF Model'!C19+3)+'DCF Model'!G45/(1+$B10)^('DCF Model'!C19+4)+'DCF Model'!G45*(1+H$6)/($B10-H$6)/(1+$B10)^('DCF Model'!C19+4)-'DCF Model'!C16)*1000000/'DCF Model'!C15,0),"") -> 2987 | I10: =IFERROR(ROUND(('DCF Model'!C45/(1+$B10)^('DCF Model'!C19+0)+'DCF Model'!D45/(1+$B10)^('DCF Model'!C19+1)+'DCF Model'!E45/(1+$B10)^('DCF Model'!C19+2)+'DCF Model'!F45/(1+$B10)^('DCF Model'!C19+3)+'DCF Model'!G45/(1+$B10)^('DCF Model'!C19+4)+'DCF Model'!G45*(1+I$6)/($B10-I$6)/(1+$B10)^('DCF Model'!C19+4)-'DCF Model'!C16)*1000000/'DCF Model'!C15,0),"") -> 3038
B11: =$C$3+0.005 -> 0.1242 | C11: =IFERROR(ROUND(('DCF Model'!C45/(1+$B11)^('DCF Model'!C19+0)+'DCF Model'!D45/(1+$B11)^('DCF Model'!C19+1)+'DCF Model'!E45/(1+$B11)^('DCF Model'!C19+2)+'DCF Model'!F45/(1+$B11)^('DCF Model'!C19+3)+'DCF Model'!G45/(1+$B11)^('DCF Model'!C19+4)+'DCF Model'!G45*(1+C$6)/($B11-C$6)/(1+$B11)^('DCF Model'!C19+4)-'DCF Model'!C16)*1000000/'DCF Model'!C15,0),"") -> 2667 | D11: =IFERROR(ROUND(('DCF Model'!C45/(1+$B11)^('DCF Model'!C19+0)+'DCF Model'!D45/(1+$B11)^('DCF Model'!C19+1)+'DCF Model'!E45/(1+$B11)^('DCF Model'!C19+2)+'DCF Model'!F45/(1+$B11)^('DCF Model'!C19+3)+'DCF Model'!G45/(1+$B11)^('DCF Model'!C19+4)+'DCF Model'!G45*(1+D$6)/($B11-D$6)/(1+$B11)^('DCF Model'!C19+4)-'DCF Model'!C16)*1000000/'DCF Model'!C15,0),"") -> 2702 | E11: =IFERROR(ROUND(('DCF Model'!C45/(1+$B11)^('DCF Model'!C19+0)+'DCF Model'!D45/(1+$B11)^('DCF Model'!C19+1)+'DCF Model'!E45/(1+$B11)^('DCF Model'!C19+2)+'DCF Model'!F45/(1+$B11)^('DCF Model'!C19+3)+'DCF Model'!G45/(1+$B11)^('DCF Model'!C19+4)+'DCF Model'!G45*(1+E$6)/($B11-E$6)/(1+$B11)^('DCF Model'!C19+4)-'DCF Model'!C16)*1000000/'DCF Model'!C15,0),"") -> 2740 | F11: =IFERROR(ROUND(('DCF Model'!C45/(1+$B11)^('DCF Model'!C19+0)+'DCF Model'!D45/(1+$B11)^('DCF Model'!C19+1)+'DCF Model'!E45/(1+$B11)^('DCF Model'!C19+2)+'DCF Model'!F45/(1+$B11)^('DCF Model'!C19+3)+'DCF Model'!G45/(1+$B11)^('DCF Model'!C19+4)+'DCF Model'!G45*(1+F$6)/($B11-F$6)/(1+$B11)^('DCF Model'!C19+4)-'DCF Model'!C16)*1000000/'DCF Model'!C15,0),"") -> 2779 | G11: =IFERROR(ROUND(('DCF Model'!C45/(1+$B11)^('DCF Model'!C19+0)+'DCF Model'!D45/(1+$B11)^('DCF Model'!C19+1)+'DCF Model'!E45/(1+$B11)^('DCF Model'!C19+2)+'DCF Model'!F45/(1+$B11)^('DCF Model'!C19+3)+'DCF Model'!G45/(1+$B11)^('DCF Model'!C19+4)+'DCF Model'!G45*(1+G$6)/($B11-G$6)/(1+$B11)^('DCF Model'!C19+4)-'DCF Model'!C16)*1000000/'DCF Model'!C15,0),"") -> 2819 | H11: =IFERROR(ROUND(('DCF Model'!C45/(1+$B11)^('DCF Model'!C19+0)+'DCF Model'!D45/(1+$B11)^('DCF Model'!C19+1)+'DCF Model'!E45/(1+$B11)^('DCF Model'!C19+2)+'DCF Model'!F45/(1+$B11)^('DCF Model'!C19+3)+'DCF Model'!G45/(1+$B11)^('DCF Model'!C19+4)+'DCF Model'!G45*(1+H$6)/($B11-H$6)/(1+$B11)^('DCF Model'!C19+4)-'DCF Model'!C16)*1000000/'DCF Model'!C15,0),"") -> 2862 | I11: =IFERROR(ROUND(('DCF Model'!C45/(1+$B11)^('DCF Model'!C19+0)+'DCF Model'!D45/(1+$B11)^('DCF Model'!C19+1)+'DCF Model'!E45/(1+$B11)^('DCF Model'!C19+2)+'DCF Model'!F45/(1+$B11)^('DCF Model'!C19+3)+'DCF Model'!G45/(1+$B11)^('DCF Model'!C19+4)+'DCF Model'!G45*(1+I$6)/($B11-I$6)/(1+$B11)^('DCF Model'!C19+4)-'DCF Model'!C16)*1000000/'DCF Model'!C15,0),"") -> 2907
B12: =$C$3+0.01 -> 0.1292 | C12: =IFERROR(ROUND(('DCF Model'!C45/(1+$B12)^('DCF Model'!C19+0)+'DCF Model'!D45/(1+$B12)^('DCF Model'!C19+1)+'DCF Model'!E45/(1+$B12)^('DCF Model'!C19+2)+'DCF Model'!F45/(1+$B12)^('DCF Model'!C19+3)+'DCF Model'!G45/(1+$B12)^('DCF Model'!C19+4)+'DCF Model'!G45*(1+C$6)/($B12-C$6)/(1+$B12)^('DCF Model'!C19+4)-'DCF Model'!C16)*1000000/'DCF Model'!C15,0),"") -> 2574 | D12: =IFERROR(ROUND(('DCF Model'!C45/(1+$B12)^('DCF Model'!C19+0)+'DCF Model'!D45/(1+$B12)^('DCF Model'!C19+1)+'DCF Model'!E45/(1+$B12)^('DCF Model'!C19+2)+'DCF Model'!F45/(1+$B12)^('DCF Model'!C19+3)+'DCF Model'!G45/(1+$B12)^('DCF Model'!C19+4)+'DCF Model'!G45*(1+D$6)/($B12-D$6)/(1+$B12)^('DCF Model'!C19+4)-'DCF Model'!C16)*1000000/'DCF Model'!C15,0),"") -> 2606 | E12: =IFERROR(ROUND(('DCF Model'!C45/(1+$B12)^('DCF Model'!C19+0)+'DCF Model'!D45/(1+$B12)^('DCF Model'!C19+1)+'DCF Model'!E45/(1+$B12)^('DCF Model'!C19+2)+'DCF Model'!F45/(1+$B12)^('DCF Model'!C19+3)+'DCF Model'!G45/(1+$B12)^('DCF Model'!C19+4)+'DCF Model'!G45*(1+E$6)/($B12-E$6)/(1+$B12)^('DCF Model'!C19+4)-'DCF Model'!C16)*1000000/'DCF Model'!C15,0),"") -> 2640 | F12: =IFERROR(ROUND(('DCF Model'!C45/(1+$B12)^('DCF Model'!C19+0)+'DCF Model'!D45/(1+$B12)^('DCF Model'!C19+1)+'DCF Model'!E45/(1+$B12)^('DCF Model'!C19+2)+'DCF Model'!F45/(1+$B12)^('DCF Model'!C19+3)+'DCF Model'!G45/(1+$B12)^('DCF Model'!C19+4)+'DCF Model'!G45*(1+F$6)/($B12-F$6)/(1+$B12)^('DCF Model'!C19+4)-'DCF Model'!C16)*1000000/'DCF Model'!C15,0),"") -> 2675 | G12: =IFERROR(ROUND(('DCF Model'!C45/(1+$B12)^('DCF Model'!C19+0)+'DCF Model'!D45/(1+$B12)^('DCF Model'!C19+1)+'DCF Model'!E45/(1+$B12)^('DCF Model'!C19+2)+'DCF Model'!F45/(1+$B12)^('DCF Model'!C19+3)+'DCF Model'!G45/(1+$B12)^('DCF Model'!C19+4)+'DCF Model'!G45*(1+G$6)/($B12-G$6)/(1+$B12)^('DCF Model'!C19+4)-'DCF Model'!C16)*1000000/'DCF Model'!C15,0),"") -> 2712 | H12: =IFERROR(ROUND(('DCF Model'!C45/(1+$B12)^('DCF Model'!C19+0)+'DCF Model'!D45/(1+$B12)^('DCF Model'!C19+1)+'DCF Model'!E45/(1+$B12)^('DCF Model'!C19+2)+'DCF Model'!F45/(1+$B12)^('DCF Model'!C19+3)+'DCF Model'!G45/(1+$B12)^('DCF Model'!C19+4)+'DCF Model'!G45*(1+H$6)/($B12-H$6)/(1+$B12)^('DCF Model'!C19+4)-'DCF Model'!C16)*1000000/'DCF Model'!C15,0),"") -> 2750 | I12: =IFERROR(ROUND(('DCF Model'!C45/(1+$B12)^('DCF Model'!C19+0)+'DCF Model'!D45/(1+$B12)^('DCF Model'!C19+1)+'DCF Model'!E45/(1+$B12)^('DCF Model'!C19+2)+'DCF Model'!F45/(1+$B12)^('DCF Model'!C19+3)+'DCF Model'!G45/(1+$B12)^('DCF Model'!C19+4)+'DCF Model'!G45*(1+I$6)/($B12-I$6)/(1+$B12)^('DCF Model'!C19+4)-'DCF Model'!C16)*1000000/'DCF Model'!C15,0),"") -> 2790
B13: =$C$3+0.015 -> 0.1342 | C13: =IFERROR(ROUND(('DCF Model'!C45/(1+$B13)^('DCF Model'!C19+0)+'DCF Model'!D45/(1+$B13)^('DCF Model'!C19+1)+'DCF Model'!E45/(1+$B13)^('DCF Model'!C19+2)+'DCF Model'!F45/(1+$B13)^('DCF Model'!C19+3)+'DCF Model'!G45/(1+$B13)^('DCF Model'!C19+4)+'DCF Model'!G45*(1+C$6)/($B13-C$6)/(1+$B13)^('DCF Model'!C19+4)-'DCF Model'!C16)*1000000/'DCF Model'!C15,0),"") -> 2490 | D13: =IFERROR(ROUND(('DCF Model'!C45/(1+$B13)^('DCF Model'!C19+0)+'DCF Model'!D45/(1+$B13)^('DCF Model'!C19+1)+'DCF Model'!E45/(1+$B13)^('DCF Model'!C19+2)+'DCF Model'!F45/(1+$B13)^('DCF Model'!C19+3)+'DCF Model'!G45/(1+$B13)^('DCF Model'!C19+4)+'DCF Model'!G45*(1+D$6)/($B13-D$6)/(1+$B13)^('DCF Model'!C19+4)-'DCF Model'!C16)*1000000/'DCF Model'!C15,0),"") -> 2519 | E13: =IFERROR(ROUND(('DCF Model'!C45/(1+$B13)^('DCF Model'!C19+0)+'DCF Model'!D45/(1+$B13)^('DCF Model'!C19+1)+'DCF Model'!E45/(1+$B13)^('DCF Model'!C19+2)+'DCF Model'!F45/(1+$B13)^('DCF Model'!C19+3)+'DCF Model'!G45/(1+$B13)^('DCF Model'!C19+4)+'DCF Model'!G45*(1+E$6)/($B13-E$6)/(1+$B13)^('DCF Model'!C19+4)-'DCF Model'!C16)*1000000/'DCF Model'!C15,0),"") -> 2549 | F13: =IFERROR(ROUND(('DCF Model'!C45/(1+$B13)^('DCF Model'!C19+0)+'DCF Model'!D45/(1+$B13)^('DCF Model'!C19+1)+'DCF Model'!E45/(1+$B13)^('DCF Model'!C19+2)+'DCF Model'!F45/(1+$B13)^('DCF Model'!C19+3)+'DCF Model'!G45/(1+$B13)^('DCF Model'!C19+4)+'DCF Model'!G45*(1+F$6)/($B13-F$6)/(1+$B13)^('DCF Model'!C19+4)-'DCF Model'!C16)*1000000/'DCF Model'!C15,0),"") -> 2580 | G13: =IFERROR(ROUND(('DCF Model'!C45/(1+$B13)^('DCF Model'!C19+0)+'DCF Model'!D45/(1+$B13)^('DCF Model'!C19+1)+'DCF Model'!E45/(1+$B13)^('DCF Model'!C19+2)+'DCF Model'!F45/(1+$B13)^('DCF Model'!C19+3)+'DCF Model'!G45/(1+$B13)^('DCF Model'!C19+4)+'DCF Model'!G45*(1+G$6)/($B13-G$6)/(1+$B13)^('DCF Model'!C19+4)-'DCF Model'!C16)*1000000/'DCF Model'!C15,0),"") -> 2613 | H13: =IFERROR(ROUND(('DCF Model'!C45/(1+$B13)^('DCF Model'!C19+0)+'DCF Model'!D45/(1+$B13)^('DCF Model'!C19+1)+'DCF Model'!E45/(1+$B13)^('DCF Model'!C19+2)+'DCF Model'!F45/(1+$B13)^('DCF Model'!C19+3)+'DCF Model'!G45/(1+$B13)^('DCF Model'!C19+4)+'DCF Model'!G45*(1+H$6)/($B13-H$6)/(1+$B13)^('DCF Model'!C19+4)-'DCF Model'!C16)*1000000/'DCF Model'!C15,0),"") -> 2648 | I13: =IFERROR(ROUND(('DCF Model'!C45/(1+$B13)^('DCF Model'!C19+0)+'DCF Model'!D45/(1+$B13)^('DCF Model'!C19+1)+'DCF Model'!E45/(1+$B13)^('DCF Model'!C19+2)+'DCF Model'!F45/(1+$B13)^('DCF Model'!C19+3)+'DCF Model'!G45/(1+$B13)^('DCF Model'!C19+4)+'DCF Model'!G45*(1+I$6)/($B13-I$6)/(1+$B13)^('DCF Model'!C19+4)-'DCF Model'!C16)*1000000/'DCF Model'!C15,0),"") -> 2684
B16: Table 2: WACC vs Exit Multiple (Exit Multiple - Implied Share Price, JPY)
B17: WACC \ Exit Multiple | C17: =$I$3-3 -> 5 | D17: =$I$3-2 -> 6 | E17: =$I$3-1 -> 7 | F17: =$I$3 -> 8 | G17: =$I$3+1 -> 9 | H17: =$I$3+2 -> 10 | I17: =$I$3+3 -> 11
B18: =$C$3-0.015 -> 0.1042 | C18: =IFERROR(ROUND(('DCF Model'!C45/(1+$B18)^('DCF Model'!C19+0)+'DCF Model'!D45/(1+$B18)^('DCF Model'!C19+1)+'DCF Model'!E45/(1+$B18)^('DCF Model'!C19+2)+'DCF Model'!F45/(1+$B18)^('DCF Model'!C19+3)+'DCF Model'!G45/(1+$B18)^('DCF Model'!C19+4)+('DCF Model'!G39+'DCF Model'!G42)*C$17/(1+$B18)^('DCF Model'!C19+4)-'DCF Model'!C16)*1000000/'DCF Model'!C15,0),"") -> 2640 | D18: =IFERROR(ROUND(('DCF Model'!C45/(1+$B18)^('DCF Model'!C19+0)+'DCF Model'!D45/(1+$B18)^('DCF Model'!C19+1)+'DCF Model'!E45/(1+$B18)^('DCF Model'!C19+2)+'DCF Model'!F45/(1+$B18)^('DCF Model'!C19+3)+'DCF Model'!G45/(1+$B18)^('DCF Model'!C19+4)+('DCF Model'!G39+'DCF Model'!G42)*D$17/(1+$B18)^('DCF Model'!C19+4)-'DCF Model'!C16)*1000000/'DCF Model'!C15,0),"") -> 2907 | E18: =IFERROR(ROUND(('DCF Model'!C45/(1+$B18)^('DCF Model'!C19+0)+'DCF Model'!D45/(1+$B18)^('DCF Model'!C19+1)+'DCF Model'!E45/(1+$B18)^('DCF Model'!C19+2)+'DCF Model'!F45/(1+$B18)^('DCF Model'!C19+3)+'DCF Model'!G45/(1+$B18)^('DCF Model'!C19+4)+('DCF Model'!G39+'DCF Model'!G42)*E$17/(1+$B18)^('DCF Model'!C19+4)-'DCF Model'!C16)*1000000/'DCF Model'!C15,0),"") -> 3174 | F18: =IFERROR(ROUND(('DCF Model'!C45/(1+$B18)^('DCF Model'!C19+0)+'DCF Model'!D45/(1+$B18)^('DCF Model'!C19+1)+'DCF Model'!E45/(1+$B18)^('DCF Model'!C19+2)+'DCF Model'!F45/(1+$B18)^('DCF Model'!C19+3)+'DCF Model'!G45/(1+$B18)^('DCF Model'!C19+4)+('DCF Model'!G39+'DCF Model'!G42)*F$17/(1+$B18)^('DCF Model'!C19+4)-'DCF Model'!C16)*1000000/'DCF Model'!C15,0),"") -> 3442 | G18: =IFERROR(ROUND(('DCF Model'!C45/(1+$B18)^('DCF Model'!C19+0)+'DCF Model'!D45/(1+$B18)^('DCF Model'!C19+1)+'DCF Model'!E45/(1+$B18)^('DCF Model'!C19+2)+'DCF Model'!F45/(1+$B18)^('DCF Model'!C19+3)+'DCF Model'!G45/(1+$B18)^('DCF Model'!C19+4)+('DCF Model'!G39+'DCF Model'!G42)*G$17/(1+$B18)^('DCF Model'!C19+4)-'DCF Model'!C16)*1000000/'DCF Model'!C15,0),"") -> 3709 | H18: =IFERROR(ROUND(('DCF Model'!C45/(1+$B18)^('DCF Model'!C19+0)+'DCF Model'!D45/(1+$B18)^('DCF Model'!C19+1)+'DCF Model'!E45/(1+$B18)^('DCF Model'!C19+2)+'DCF Model'!F45/(1+$B18)^('DCF Model'!C19+3)+'DCF Model'!G45/(1+$B18)^('DCF Model'!C19+4)+('DCF Model'!G39+'DCF Model'!G42)*H$17/(1+$B18)^('DCF Model'!C19+4)-'DCF Model'!C16)*1000000/'DCF Model'!C15,0),"") -> 3976 | I18: =IFERROR(ROUND(('DCF Model'!C45/(1+$B18)^('DCF Model'!C19+0)+'DCF Model'!D45/(1+$B18)^('DCF Model'!C19+1)+'DCF Model'!E45/(1+$B18)^('DCF Model'!C19+2)+'DCF Model'!F45/(1+$B18)^('DCF Model'!C19+3)+'DCF Model'!G45/(1+$B18)^('DCF Model'!C19+4)+('DCF Model'!G39+'DCF Model'!G42)*I$17/(1+$B18)^('DCF Model'!C19+4)-'DCF Model'!C16)*1000000/'DCF Model'!C15,0),"") -> 4243
B19: =$C$3-0.01 -> 0.1092 | C19: =IFERROR(ROUND(('DCF Model'!C45/(1+$B19)^('DCF Model'!C19+0)+'DCF Model'!D45/(1+$B19)^('DCF Model'!C19+1)+'DCF Model'!E45/(1+$B19)^('DCF Model'!C19+2)+'DCF Model'!F45/(1+$B19)^('DCF Model'!C19+3)+'DCF Model'!G45/(1+$B19)^('DCF Model'!C19+4)+('DCF Model'!G39+'DCF Model'!G42)*C$17/(1+$B19)^('DCF Model'!C19+4)-'DCF Model'!C16)*1000000/'DCF Model'!C15,0),"") -> 2606 | D19: =IFERROR(ROUND(('DCF Model'!C45/(1+$B19)^('DCF Model'!C19+0)+'DCF Model'!D45/(1+$B19)^('DCF Model'!C19+1)+'DCF Model'!E45/(1+$B19)^('DCF Model'!C19+2)+'DCF Model'!F45/(1+$B19)^('DCF Model'!C19+3)+'DCF Model'!G45/(1+$B19)^('DCF Model'!C19+4)+('DCF Model'!G39+'DCF Model'!G42)*D$17/(1+$B19)^('DCF Model'!C19+4)-'DCF Model'!C16)*1000000/'DCF Model'!C15,0),"") -> 2868 | E19: =IFERROR(ROUND(('DCF Model'!C45/(1+$B19)^('DCF Model'!C19+0)+'DCF Model'!D45/(1+$B19)^('DCF Model'!C19+1)+'DCF Model'!E45/(1+$B19)^('DCF Model'!C19+2)+'DCF Model'!F45/(1+$B19)^('DCF Model'!C19+3)+'DCF Model'!G45/(1+$B19)^('DCF Model'!C19+4)+('DCF Model'!G39+'DCF Model'!G42)*E$17/(1+$B19)^('DCF Model'!C19+4)-'DCF Model'!C16)*1000000/'DCF Model'!C15,0),"") -> 3130 | F19: =IFERROR(ROUND(('DCF Model'!C45/(1+$B19)^('DCF Model'!C19+0)+'DCF Model'!D45/(1+$B19)^('DCF Model'!C19+1)+'DCF Model'!E45/(1+$B19)^('DCF Model'!C19+2)+'DCF Model'!F45/(1+$B19)^('DCF Model'!C19+3)+'DCF Model'!G45/(1+$B19)^('DCF Model'!C19+4)+('DCF Model'!G39+'DCF Model'!G42)*F$17/(1+$B19)^('DCF Model'!C19+4)-'DCF Model'!C16)*1000000/'DCF Model'!C15,0),"") -> 3393 | G19: =IFERROR(ROUND(('DCF Model'!C45/(1+$B19)^('DCF Model'!C19+0)+'DCF Model'!D45/(1+$B19)^('DCF Model'!C19+1)+'DCF Model'!E45/(1+$B19)^('DCF Model'!C19+2)+'DCF Model'!F45/(1+$B19)^('DCF Model'!C19+3)+'DCF Model'!G45/(1+$B19)^('DCF Model'!C19+4)+('DCF Model'!G39+'DCF Model'!G42)*G$17/(1+$B19)^('DCF Model'!C19+4)-'DCF Model'!C16)*1000000/'DCF Model'!C15,0),"") -> 3655 | H19: =IFERROR(ROUND(('DCF Model'!C45/(1+$B19)^('DCF Model'!C19+0)+'DCF Model'!D45/(1+$B19)^('DCF Model'!C19+1)+'DCF Model'!E45/(1+$B19)^('DCF Model'!C19+2)+'DCF Model'!F45/(1+$B19)^('DCF Model'!C19+3)+'DCF Model'!G45/(1+$B19)^('DCF Model'!C19+4)+('DCF Model'!G39+'DCF Model'!G42)*H$17/(1+$B19)^('DCF Model'!C19+4)-'DCF Model'!C16)*1000000/'DCF Model'!C15,0),"") -> 3917 | I19: =IFERROR(ROUND(('DCF Model'!C45/(1+$B19)^('DCF Model'!C19+0)+'DCF Model'!D45/(1+$B19)^('DCF Model'!C19+1)+'DCF Model'!E45/(1+$B19)^('DCF Model'!C19+2)+'DCF Model'!F45/(1+$B19)^('DCF Model'!C19+3)+'DCF Model'!G45/(1+$B19)^('DCF Model'!C19+4)+('DCF Model'!G39+'DCF Model'!G42)*I$17/(1+$B19)^('DCF Model'!C19+4)-'DCF Model'!C16)*1000000/'DCF Model'!C15,0),"") -> 4179
B20: =$C$3-0.005 -> 0.1142 | C20: =IFERROR(ROUND(('DCF Model'!C45/(1+$B20)^('DCF Model'!C19+0)+'DCF Model'!D45/(1+$B20)^('DCF Model'!C19+1)+'DCF Model'!E45/(1+$B20)^('DCF Model'!C19+2)+'DCF Model'!F45/(1+$B20)^('DCF Model'!C19+3)+'DCF Model'!G45/(1+$B20)^('DCF Model'!C19+4)+('DCF Model'!G39+'DCF Model'!G42)*C$17/(1+$B20)^('DCF Model'!C19+4)-'DCF Model'!C16)*1000000/'DCF Model'!C15,0),"") -> 2573 | D20: =IFERROR(ROUND(('DCF Model'!C45/(1+$B20)^('DCF Model'!C19+0)+'DCF Model'!D45/(1+$B20)^('DCF Model'!C19+1)+'DCF Model'!E45/(1+$B20)^('DCF Model'!C19+2)+'DCF Model'!F45/(1+$B20)^('DCF Model'!C19+3)+'DCF Model'!G45/(1+$B20)^('DCF Model'!C19+4)+('DCF Model'!G39+'DCF Model'!G42)*D$17/(1+$B20)^('DCF Model'!C19+4)-'DCF Model'!C16)*1000000/'DCF Model'!C15,0),"") -> 2830 | E20: =IFERROR(ROUND(('DCF Model'!C45/(1+$B20)^('DCF Model'!C19+0)+'DCF Model'!D45/(1+$B20)^('DCF Model'!C19+1)+'DCF Model'!E45/(1+$B20)^('DCF Model'!C19+2)+'DCF Model'!F45/(1+$B20)^('DCF Model'!C19+3)+'DCF Model'!G45/(1+$B20)^('DCF Model'!C19+4)+('DCF Model'!G39+'DCF Model'!G42)*E$17/(1+$B20)^('DCF Model'!C19+4)-'DCF Model'!C16)*1000000/'DCF Model'!C15,0),"") -> 3088 | F20: =IFERROR(ROUND(('DCF Model'!C45/(1+$B20)^('DCF Model'!C19+0)+'DCF Model'!D45/(1+$B20)^('DCF Model'!C19+1)+'DCF Model'!E45/(1+$B20)^('DCF Model'!C19+2)+'DCF Model'!F45/(1+$B20)^('DCF Model'!C19+3)+'DCF Model'!G45/(1+$B20)^('DCF Model'!C19+4)+('DCF Model'!G39+'DCF Model'!G42)*F$17/(1+$B20)^('DCF Model'!C19+4)-'DCF Model'!C16)*1000000/'DCF Model'!C15,0),"") -> 3345 | G20: =IFERROR(ROUND(('DCF Model'!C45/(1+$B20)^('DCF Model'!C19+0)+'DCF Model'!D45/(1+$B20)^('DCF Model'!C19+1)+'DCF Model'!E45/(1+$B20)^('DCF Model'!C19+2)+'DCF Model'!F45/(1+$B20)^('DCF Model'!C19+3)+'DCF Model'!G45/(1+$B20)^('DCF Model'!C19+4)+('DCF Model'!G39+'DCF Model'!G42)*G$17/(1+$B20)^('DCF Model'!C19+4)-'DCF Model'!C16)*1000000/'DCF Model'!C15,0),"") -> 3602 | H20: =IFERROR(ROUND(('DCF Model'!C45/(1+$B20)^('DCF Model'!C19+0)+'DCF Model'!D45/(1+$B20)^('DCF Model'!C19+1)+'DCF Model'!E45/(1+$B20)^('DCF Model'!C19+2)+'DCF Model'!F45/(1+$B20)^('DCF Model'!C19+3)+'DCF Model'!G45/(1+$B20)^('DCF Model'!C19+4)+('DCF Model'!G39+'DCF Model'!G42)*H$17/(1+$B20)^('DCF Model'!C19+4)-'DCF Model'!C16)*1000000/'DCF Model'!C15,0),"") -> 3859 | I20: =IFERROR(ROUND(('DCF Model'!C45/(1+$B20)^('DCF Model'!C19+0)+'DCF Model'!D45/(1+$B20)^('DCF Model'!C19+1)+'DCF Model'!E45/(1+$B20)^('DCF Model'!C19+2)+'DCF Model'!F45/(1+$B20)^('DCF Model'!C19+3)+'DCF Model'!G45/(1+$B20)^('DCF Model'!C19+4)+('DCF Model'!G39+'DCF Model'!G42)*I$17/(1+$B20)^('DCF Model'!C19+4)-'DCF Model'!C16)*1000000/'DCF Model'!C15,0),"") -> 4116
B21: =$C$3 -> 0.1192 | C21: =IFERROR(ROUND(('DCF Model'!C45/(1+$B21)^('DCF Model'!C19+0)+'DCF Model'!D45/(1+$B21)^('DCF Model'!C19+1)+'DCF Model'!E45/(1+$B21)^('DCF Model'!C19+2)+'DCF Model'!F45/(1+$B21)^('DCF Model'!C19+3)+'DCF Model'!G45/(1+$B21)^('DCF Model'!C19+4)+('DCF Model'!G39+'DCF Model'!G42)*C$17/(1+$B21)^('DCF Model'!C19+4)-'DCF Model'!C16)*1000000/'DCF Model'!C15,0),"") -> 2541 | D21: =IFERROR(ROUND(('DCF Model'!C45/(1+$B21)^('DCF Model'!C19+0)+'DCF Model'!D45/(1+$B21)^('DCF Model'!C19+1)+'DCF Model'!E45/(1+$B21)^('DCF Model'!C19+2)+'DCF Model'!F45/(1+$B21)^('DCF Model'!C19+3)+'DCF Model'!G45/(1+$B21)^('DCF Model'!C19+4)+('DCF Model'!G39+'DCF Model'!G42)*D$17/(1+$B21)^('DCF Model'!C19+4)-'DCF Model'!C16)*1000000/'DCF Model'!C15,0),"") -> 2793 | E21: =IFERROR(ROUND(('DCF Model'!C45/(1+$B21)^('DCF Model'!C19+0)+'DCF Model'!D45/(1+$B21)^('DCF Model'!C19+1)+'DCF Model'!E45/(1+$B21)^('DCF Model'!C19+2)+'DCF Model'!F45/(1+$B21)^('DCF Model'!C19+3)+'DCF Model'!G45/(1+$B21)^('DCF Model'!C19+4)+('DCF Model'!G39+'DCF Model'!G42)*E$17/(1+$B21)^('DCF Model'!C19+4)-'DCF Model'!C16)*1000000/'DCF Model'!C15,0),"") -> 3046 | F21: =IFERROR(ROUND(('DCF Model'!C45/(1+$B21)^('DCF Model'!C19+0)+'DCF Model'!D45/(1+$B21)^('DCF Model'!C19+1)+'DCF Model'!E45/(1+$B21)^('DCF Model'!C19+2)+'DCF Model'!F45/(1+$B21)^('DCF Model'!C19+3)+'DCF Model'!G45/(1+$B21)^('DCF Model'!C19+4)+('DCF Model'!G39+'DCF Model'!G42)*F$17/(1+$B21)^('DCF Model'!C19+4)-'DCF Model'!C16)*1000000/'DCF Model'!C15,0),"") -> 3298 | G21: =IFERROR(ROUND(('DCF Model'!C45/(1+$B21)^('DCF Model'!C19+0)+'DCF Model'!D45/(1+$B21)^('DCF Model'!C19+1)+'DCF Model'!E45/(1+$B21)^('DCF Model'!C19+2)+'DCF Model'!F45/(1+$B21)^('DCF Model'!C19+3)+'DCF Model'!G45/(1+$B21)^('DCF Model'!C19+4)+('DCF Model'!G39+'DCF Model'!G42)*G$17/(1+$B21)^('DCF Model'!C19+4)-'DCF Model'!C16)*1000000/'DCF Model'!C15,0),"") -> 3550 | H21: =IFERROR(ROUND(('DCF Model'!C45/(1+$B21)^('DCF Model'!C19+0)+'DCF Model'!D45/(1+$B21)^('DCF Model'!C19+1)+'DCF Model'!E45/(1+$B21)^('DCF Model'!C19+2)+'DCF Model'!F45/(1+$B21)^('DCF Model'!C19+3)+'DCF Model'!G45/(1+$B21)^('DCF Model'!C19+4)+('DCF Model'!G39+'DCF Model'!G42)*H$17/(1+$B21)^('DCF Model'!C19+4)-'DCF Model'!C16)*1000000/'DCF Model'!C15,0),"") -> 3803 | I21: =IFERROR(ROUND(('DCF Model'!C45/(1+$B21)^('DCF Model'!C19+0)+'DCF Model'!D45/(1+$B21)^('DCF Model'!C19+1)+'DCF Model'!E45/(1+$B21)^('DCF Model'!C19+2)+'DCF Model'!F45/(1+$B21)^('DCF Model'!C19+3)+'DCF Model'!G45/(1+$B21)^('DCF Model'!C19+4)+('DCF Model'!G39+'DCF Model'!G42)*I$17/(1+$B21)^('DCF Model'!C19+4)-'DCF Model'!C16)*1000000/'DCF Model'!C15,0),"") -> 4055
B22: =$C$3+0.005 -> 0.1242 | C22: =IFERROR(ROUND(('DCF Model'!C45/(1+$B22)^('DCF Model'!C19+0)+'DCF Model'!D45/(1+$B22)^('DCF Model'!C19+1)+'DCF Model'!E45/(1+$B22)^('DCF Model'!C19+2)+'DCF Model'!F45/(1+$B22)^('DCF Model'!C19+3)+'DCF Model'!G45/(1+$B22)^('DCF Model'!C19+4)+('DCF Model'!G39+'DCF Model'!G42)*C$17/(1+$B22)^('DCF Model'!C19+4)-'DCF Model'!C16)*1000000/'DCF Model'!C15,0),"") -> 2509 | D22: =IFERROR(ROUND(('DCF Model'!C45/(1+$B22)^('DCF Model'!C19+0)+'DCF Model'!D45/(1+$B22)^('DCF Model'!C19+1)+'DCF Model'!E45/(1+$B22)^('DCF Model'!C19+2)+'DCF Model'!F45/(1+$B22)^('DCF Model'!C19+3)+'DCF Model'!G45/(1+$B22)^('DCF Model'!C19+4)+('DCF Model'!G39+'DCF Model'!G42)*D$17/(1+$B22)^('DCF Model'!C19+4)-'DCF Model'!C16)*1000000/'DCF Model'!C15,0),"") -> 2757 | E22: =IFERROR(ROUND(('DCF Model'!C45/(1+$B22)^('DCF Model'!C19+0)+'DCF Model'!D45/(1+$B22)^('DCF Model'!C19+1)+'DCF Model'!E45/(1+$B22)^('DCF Model'!C19+2)+'DCF Model'!F45/(1+$B22)^('DCF Model'!C19+3)+'DCF Model'!G45/(1+$B22)^('DCF Model'!C19+4)+('DCF Model'!G39+'DCF Model'!G42)*E$17/(1+$B22)^('DCF Model'!C19+4)-'DCF Model'!C16)*1000000/'DCF Model'!C15,0),"") -> 3004 | F22: =IFERROR(ROUND(('DCF Model'!C45/(1+$B22)^('DCF Model'!C19+0)+'DCF Model'!D45/(1+$B22)^('DCF Model'!C19+1)+'DCF Model'!E45/(1+$B22)^('DCF Model'!C19+2)+'DCF Model'!F45/(1+$B22)^('DCF Model'!C19+3)+'DCF Model'!G45/(1+$B22)^('DCF Model'!C19+4)+('DCF Model'!G39+'DCF Model'!G42)*F$17/(1+$B22)^('DCF Model'!C19+4)-'DCF Model'!C16)*1000000/'DCF Model'!C15,0),"") -> 3252 | G22: =IFERROR(ROUND(('DCF Model'!C45/(1+$B22)^('DCF Model'!C19+0)+'DCF Model'!D45/(1+$B22)^('DCF Model'!C19+1)+'DCF Model'!E45/(1+$B22)^('DCF Model'!C19+2)+'DCF Model'!F45/(1+$B22)^('DCF Model'!C19+3)+'DCF Model'!G45/(1+$B22)^('DCF Model'!C19+4)+('DCF Model'!G39+'DCF Model'!G42)*G$17/(1+$B22)^('DCF Model'!C19+4)-'DCF Model'!C16)*1000000/'DCF Model'!C15,0),"") -> 3500 | H22: =IFERROR(ROUND(('DCF Model'!C45/(1+$B22)^('DCF Model'!C19+0)+'DCF Model'!D45/(1+$B22)^('DCF Model'!C19+1)+'DCF Model'!E45/(1+$B22)^('DCF Model'!C19+2)+'DCF Model'!F45/(1+$B22)^('DCF Model'!C19+3)+'DCF Model'!G45/(1+$B22)^('DCF Model'!C19+4)+('DCF Model'!G39+'DCF Model'!G42)*H$17/(1+$B22)^('DCF Model'!C19+4)-'DCF Model'!C16)*1000000/'DCF Model'!C15,0),"") -> 3747 | I22: =IFERROR(ROUND(('DCF Model'!C45/(1+$B22)^('DCF Model'!C19+0)+'DCF Model'!D45/(1+$B22)^('DCF Model'!C19+1)+'DCF Model'!E45/(1+$B22)^('DCF Model'!C19+2)+'DCF Model'!F45/(1+$B22)^('DCF Model'!C19+3)+'DCF Model'!G45/(1+$B22)^('DCF Model'!C19+4)+('DCF Model'!G39+'DCF Model'!G42)*I$17/(1+$B22)^('DCF Model'!C19+4)-'DCF Model'!C16)*1000000/'DCF Model'!C15,0),"") -> 3995
B23: =$C$3+0.01 -> 0.1292 | C23: =IFERROR(ROUND(('DCF Model'!C45/(1+$B23)^('DCF Model'!C19+0)+'DCF Model'!D45/(1+$B23)^('DCF Model'!C19+1)+'DCF Model'!E45/(1+$B23)^('DCF Model'!C19+2)+'DCF Model'!F45/(1+$B23)^('DCF Model'!C19+3)+'DCF Model'!G45/(1+$B23)^('DCF Model'!C19+4)+('DCF Model'!G39+'DCF Model'!G42)*C$17/(1+$B23)^('DCF Model'!C19+4)-'DCF Model'!C16)*1000000/'DCF Model'!C15,0),"") -> 2478 | D23: =IFERROR(ROUND(('DCF Model'!C45/(1+$B23)^('DCF Model'!C19+0)+'DCF Model'!D45/(1+$B23)^('DCF Model'!C19+1)+'DCF Model'!E45/(1+$B23)^('DCF Model'!C19+2)+'DCF Model'!F45/(1+$B23)^('DCF Model'!C19+3)+'DCF Model'!G45/(1+$B23)^('DCF Model'!C19+4)+('DCF Model'!G39+'DCF Model'!G42)*D$17/(1+$B23)^('DCF Model'!C19+4)-'DCF Model'!C16)*1000000/'DCF Model'!C15,0),"") -> 2721 | E23: =IFERROR(ROUND(('DCF Model'!C45/(1+$B23)^('DCF Model'!C19+0)+'DCF Model'!D45/(1+$B23)^('DCF Model'!C19+1)+'DCF Model'!E45/(1+$B23)^('DCF Model'!C19+2)+'DCF Model'!F45/(1+$B23)^('DCF Model'!C19+3)+'DCF Model'!G45/(1+$B23)^('DCF Model'!C19+4)+('DCF Model'!G39+'DCF Model'!G42)*E$17/(1+$B23)^('DCF Model'!C19+4)-'DCF Model'!C16)*1000000/'DCF Model'!C15,0),"") -> 2964 | F23: =IFERROR(ROUND(('DCF Model'!C45/(1+$B23)^('DCF Model'!C19+0)+'DCF Model'!D45/(1+$B23)^('DCF Model'!C19+1)+'DCF Model'!E45/(1+$B23)^('DCF Model'!C19+2)+'DCF Model'!F45/(1+$B23)^('DCF Model'!C19+3)+'DCF Model'!G45/(1+$B23)^('DCF Model'!C19+4)+('DCF Model'!G39+'DCF Model'!G42)*F$17/(1+$B23)^('DCF Model'!C19+4)-'DCF Model'!C16)*1000000/'DCF Model'!C15,0),"") -> 3207 | G23: =IFERROR(ROUND(('DCF Model'!C45/(1+$B23)^('DCF Model'!C19+0)+'DCF Model'!D45/(1+$B23)^('DCF Model'!C19+1)+'DCF Model'!E45/(1+$B23)^('DCF Model'!C19+2)+'DCF Model'!F45/(1+$B23)^('DCF Model'!C19+3)+'DCF Model'!G45/(1+$B23)^('DCF Model'!C19+4)+('DCF Model'!G39+'DCF Model'!G42)*G$17/(1+$B23)^('DCF Model'!C19+4)-'DCF Model'!C16)*1000000/'DCF Model'!C15,0),"") -> 3450 | H23: =IFERROR(ROUND(('DCF Model'!C45/(1+$B23)^('DCF Model'!C19+0)+'DCF Model'!D45/(1+$B23)^('DCF Model'!C19+1)+'DCF Model'!E45/(1+$B23)^('DCF Model'!C19+2)+'DCF Model'!F45/(1+$B23)^('DCF Model'!C19+3)+'DCF Model'!G45/(1+$B23)^('DCF Model'!C19+4)+('DCF Model'!G39+'DCF Model'!G42)*H$17/(1+$B23)^('DCF Model'!C19+4)-'DCF Model'!C16)*1000000/'DCF Model'!C15,0),"") -> 3693 | I23: =IFERROR(ROUND(('DCF Model'!C45/(1+$B23)^('DCF Model'!C19+0)+'DCF Model'!D45/(1+$B23)^('DCF Model'!C19+1)+'DCF Model'!E45/(1+$B23)^('DCF Model'!C19+2)+'DCF Model'!F45/(1+$B23)^('DCF Model'!C19+3)+'DCF Model'!G45/(1+$B23)^('DCF Model'!C19+4)+('DCF Model'!G39+'DCF Model'!G42)*I$17/(1+$B23)^('DCF Model'!C19+4)-'DCF Model'!C16)*1000000/'DCF Model'!C15,0),"") -> 3936
B24: =$C$3+0.015 -> 0.1342 | C24: =IFERROR(ROUND(('DCF Model'!C45/(1+$B24)^('DCF Model'!C19+0)+'DCF Model'!D45/(1+$B24)^('DCF Model'!C19+1)+'DCF Model'!E45/(1+$B24)^('DCF Model'!C19+2)+'DCF Model'!F45/(1+$B24)^('DCF Model'!C19+3)+'DCF Model'!G45/(1+$B24)^('DCF Model'!C19+4)+('DCF Model'!G39+'DCF Model'!G42)*C$17/(1+$B24)^('DCF Model'!C19+4)-'DCF Model'!C16)*1000000/'DCF Model'!C15,0),"") -> 2448 | D24: =IFERROR(ROUND(('DCF Model'!C45/(1+$B24)^('DCF Model'!C19+0)+'DCF Model'!D45/(1+$B24)^('DCF Model'!C19+1)+'DCF Model'!E45/(1+$B24)^('DCF Model'!C19+2)+'DCF Model'!F45/(1+$B24)^('DCF Model'!C19+3)+'DCF Model'!G45/(1+$B24)^('DCF Model'!C19+4)+('DCF Model'!G39+'DCF Model'!G42)*D$17/(1+$B24)^('DCF Model'!C19+4)-'DCF Model'!C16)*1000000/'DCF Model'!C15,0),"") -> 2687 | E24: =IFERROR(ROUND(('DCF Model'!C45/(1+$B24)^('DCF Model'!C19+0)+'DCF Model'!D45/(1+$B24)^('DCF Model'!C19+1)+'DCF Model'!E45/(1+$B24)^('DCF Model'!C19+2)+'DCF Model'!F45/(1+$B24)^('DCF Model'!C19+3)+'DCF Model'!G45/(1+$B24)^('DCF Model'!C19+4)+('DCF Model'!G39+'DCF Model'!G42)*E$17/(1+$B24)^('DCF Model'!C19+4)-'DCF Model'!C16)*1000000/'DCF Model'!C15,0),"") -> 2925 | F24: =IFERROR(ROUND(('DCF Model'!C45/(1+$B24)^('DCF Model'!C19+0)+'DCF Model'!D45/(1+$B24)^('DCF Model'!C19+1)+'DCF Model'!E45/(1+$B24)^('DCF Model'!C19+2)+'DCF Model'!F45/(1+$B24)^('DCF Model'!C19+3)+'DCF Model'!G45/(1+$B24)^('DCF Model'!C19+4)+('DCF Model'!G39+'DCF Model'!G42)*F$17/(1+$B24)^('DCF Model'!C19+4)-'DCF Model'!C16)*1000000/'DCF Model'!C15,0),"") -> 3164 | G24: =IFERROR(ROUND(('DCF Model'!C45/(1+$B24)^('DCF Model'!C19+0)+'DCF Model'!D45/(1+$B24)^('DCF Model'!C19+1)+'DCF Model'!E45/(1+$B24)^('DCF Model'!C19+2)+'DCF Model'!F45/(1+$B24)^('DCF Model'!C19+3)+'DCF Model'!G45/(1+$B24)^('DCF Model'!C19+4)+('DCF Model'!G39+'DCF Model'!G42)*G$17/(1+$B24)^('DCF Model'!C19+4)-'DCF Model'!C16)*1000000/'DCF Model'!C15,0),"") -> 3402 | H24: =IFERROR(ROUND(('DCF Model'!C45/(1+$B24)^('DCF Model'!C19+0)+'DCF Model'!D45/(1+$B24)^('DCF Model'!C19+1)+'DCF Model'!E45/(1+$B24)^('DCF Model'!C19+2)+'DCF Model'!F45/(1+$B24)^('DCF Model'!C19+3)+'DCF Model'!G45/(1+$B24)^('DCF Model'!C19+4)+('DCF Model'!G39+'DCF Model'!G42)*H$17/(1+$B24)^('DCF Model'!C19+4)-'DCF Model'!C16)*1000000/'DCF Model'!C15,0),"") -> 3641 | I24: =IFERROR(ROUND(('DCF Model'!C45/(1+$B24)^('DCF Model'!C19+0)+'DCF Model'!D45/(1+$B24)^('DCF Model'!C19+1)+'DCF Model'!E45/(1+$B24)^('DCF Model'!C19+2)+'DCF Model'!F45/(1+$B24)^('DCF Model'!C19+3)+'DCF Model'!G45/(1+$B24)^('DCF Model'!C19+4)+('DCF Model'!G39+'DCF Model'!G42)*I$17/(1+$B24)^('DCF Model'!C19+4)-'DCF Model'!C16)*1000000/'DCF Model'!C15,0),"") -> 3879
B26: All values dynamically linked to DCF Model. Headers auto-center on current WACC / Terminal g / Exit Multiple.

Sheet Segment Analysis
B2: Segment Analysis - 株式会社コア
C4: FY2024 | D4: FY2025 | E4: FY2026 | F4: FY2026(E) | G4: FY2027(E) | H4: FY2028(E) | I4: FY2029(E) | J4: FY2030(E)
B5: Future Society Solutions (未来社会ソリューション)
B6: Revenue | C6: — | D6: 4771 | E6: 5084 | F6: =E6*(1+CHOOSE('DCF Model'!$D$27,F34,F35,F36,F37,F38)) -> 5846.6 | G6: =F6*(1+CHOOSE('DCF Model'!$D$27,G34,G35,G36,G37,G38)) -> 6723.59 | H6: =G6*(1+CHOOSE('DCF Model'!$D$27,H34,H35,H36,H37,H38)) -> 7530.4208 | I6: =H6*(1+CHOOSE('DCF Model'!$D$27,I34,I35,I36,I37,I38)) -> 8132.8545 | J6: =I6*(1+CHOOSE('DCF Model'!$D$27,J34,J35,J36,J37,J38)) -> 8539.4972
B7: Operating Profit | C7: — | D7: 675 | E7: 741 | F7: =F6*CHOOSE('DCF Model'!$D$27,F41,F42,F43,F44,F45) -> 876.99 | G7: =G6*CHOOSE('DCF Model'!$D$27,G41,G42,G43,G44,G45) -> 1042.1564 | H7: =H6*CHOOSE('DCF Model'!$D$27,H41,H42,H43,H44,H45) -> 1204.8673 | I7: =I6*CHOOSE('DCF Model'!$D$27,I41,I42,I43,I44,I45) -> 1341.921 | J7: =J6*CHOOSE('DCF Model'!$D$27,J41,J42,J43,J44,J45) -> 1451.7145
B8: OP Margin | C8: — | D8: =D7/D6 -> 0.14147977 | E8: =E7/E6 -> 0.14575138 | F8: =CHOOSE('DCF Model'!$D$27,F41,F42,F43,F44,F45) -> 0.15 | G8: =CHOOSE('DCF Model'!$D$27,G41,G42,G43,G44,G45) -> 0.155 | H8: =CHOOSE('DCF Model'!$D$27,H41,H42,H43,H44,H45) -> 0.16 | I8: =CHOOSE('DCF Model'!$D$27,I41,I42,I43,I44,I45) -> 0.165 | J8: =CHOOSE('DCF Model'!$D$27,J41,J42,J43,J44,J45) -> 0.17
B10: Industrial Technology Solutions (産業技術ソリューション)
B11: Revenue | C11: — | D11: 10546 | E11: 13695 | F11: =E11*(1+CHOOSE('DCF Model'!$D$27,F48,F49,F50,F51,F52)) -> 15201.45 | G11: =F11*(1+CHOOSE('DCF Model'!$D$27,G48,G49,G50,G51,G52)) -> 16721.595 | H11: =G11*(1+CHOOSE('DCF Model'!$D$27,H48,H49,H50,H51,H52)) -> 18059.323 | I11: =H11*(1+CHOOSE('DCF Model'!$D$27,I48,I49,I50,I51,I52)) -> 19142.882 | J11: =I11*(1+CHOOSE('DCF Model'!$D$27,J48,J49,J50,J51,J52)) -> 20100.026
B12: Operating Profit | C12: — | D12: 1641 | E12: 2312 | F12: =F11*CHOOSE('DCF Model'!$D$27,F55,F56,F57,F58,F59) -> 2660.2537 | G12: =G11*CHOOSE('DCF Model'!$D$27,G55,G56,G57,G58,G59) -> 2976.4439 | H12: =H11*CHOOSE('DCF Model'!$D$27,H55,H56,H57,H58,H59) -> 3250.6781 | I12: =I11*CHOOSE('DCF Model'!$D$27,I55,I56,I57,I58,I59) -> 3484.0045 | J12: =J11*CHOOSE('DCF Model'!$D$27,J55,J56,J57,J58,J59) -> 3718.5048
B13: OP Margin | C13: — | D13: =D12/D11 -> 0.15560402 | E13: =E12/E11 -> 0.16882074 | F13: =CHOOSE('DCF Model'!$D$27,F55,F56,F57,F58,F59) -> 0.175 | G13: =CHOOSE('DCF Model'!$D$27,G55,G56,G57,G58,G59) -> 0.178 | H13: =CHOOSE('DCF Model'!$D$27,H55,H56,H57,H58,H59) -> 0.18 | I13: =CHOOSE('DCF Model'!$D$27,I55,I56,I57,I58,I59) -> 0.182 | J13: =CHOOSE('DCF Model'!$D$27,J55,J56,J57,J58,J59) -> 0.185
B15: Customer Business Integration (顧客業務インテグレーション)
B16: Revenue | C16: — | D16: 8680 | E16: 7751 | F16: =E16*(1+CHOOSE('DCF Model'!$D$27,F62,F63,F64,F65,F66)) -> 7828.51 | G16: =F16*(1+CHOOSE('DCF Model'!$D$27,G62,G63,G64,G65,G66)) -> 7906.7951 | H16: =G16*(1+CHOOSE('DCF Model'!$D$27,H62,H63,H64,H65,H66)) -> 7985.8631 | I16: =H16*(1+CHOOSE('DCF Model'!$D$27,I62,I63,I64,I65,I66)) -> 8065.7217 | J16: =I16*(1+CHOOSE('DCF Model'!$D$27,J62,J63,J64,J65,J66)) -> 8146.3789
B17: Operating Profit | C17: — | D17: 823 | E17: 765 | F17: =F16*CHOOSE('DCF Model'!$D$27,F69,F70,F71,F72,F73) -> 821.99355 | G17: =G16*CHOOSE('DCF Model'!$D$27,G69,G70,G71,G72,G73) -> 869.74746 | H17: =H16*CHOOSE('DCF Model'!$D$27,H69,H70,H71,H72,H73) -> 918.37425 | I17: =I16*CHOOSE('DCF Model'!$D$27,I69,I70,I71,I72,I73) -> 967.8866 | J17: =J16*CHOOSE('DCF Model'!$D$27,J69,J70,J71,J72,J73) -> 977.56547
B18: OP Margin | C18: — | D18: =D17/D16 -> 0.094815668 | E18: =E17/E16 -> 0.098696942 | F18: =CHOOSE('DCF Model'!$D$27,F69,F70,F71,F72,F73) -> 0.105 | G18: =CHOOSE('DCF Model'!$D$27,G69,G70,G71,G72,G73) -> 0.11 | H18: =CHOOSE('DCF Model'!$D$27,H69,H70,H71,H72,H73) -> 0.115 | I18: =CHOOSE('DCF Model'!$D$27,I69,I70,I71,I72,I73) -> 0.12 | J18: =CHOOSE('DCF Model'!$D$27,J69,J70,J71,J72,J73) -> 0.12
B20: Consolidated Total
B21: Total Revenue | C21: =C6+C11+C16 -> #VALUE! | D21: =D6+D11+D16 -> 23997 | E21: =E6+E11+E16 -> 26530 | F21: =F6+F11+F16 -> 28876.56 | G21: =G6+G11+G16 -> 31351.98 | H21: =H6+H11+H16 -> 33575.606 | I21: =I6+I11+I16 -> 35341.458 | J21: =J6+J11+J16 -> 36785.902
B22: Total Operating Profit | C22: =C7+C12+C17 -> #VALUE! | D22: =D7+D12+D17 -> 3139 | E22: =E7+E12+E17 -> 3818 | F22: =F7+F12+F17 -> 4359.2373 | G22: =G7+G12+G17 -> 4888.3478 | H22: =H7+H12+H17 -> 5373.9196 | I22: =I7+I12+I17 -> 5793.8121 | J22: =J7+J12+J17 -> 6147.7848
B23: Total OP Margin | C23: =IFERROR(C22/C21,"—") -> — | D23: =IFERROR(D22/D21,"—") -> 0.13080802 | E23: =IFERROR(E22/E21,"—") -> 0.14391255 | F23: =IFERROR(F22/F21,"—") -> 0.1509611 | G23: =IFERROR(G22/G21,"—") -> 0.15591831 | H23: =IFERROR(H22/H21,"—") -> 0.16005428 | I23: =IFERROR(I22/I21,"—") -> 0.16393812 | J23: =IFERROR(J22/J21,"—") -> 0.16712339
B25: Reconciliation vs DCF Model
B26: DCF Model Revenue | F26: ='DCF Model'!C33 -> 28876.56 | G26: ='DCF Model'!D33 -> 31351.98 | H26: ='DCF Model'!E33 -> 33575.606 | I26: ='DCF Model'!F33 -> 35341.458 | J26: ='DCF Model'!G33 -> 36785.902
B27: Segment Total Revenue | F27: =F21 -> 28876.56 | G27: =G21 -> 31351.98 | H27: =H21 -> 33575.606 | I27: =I21 -> 35341.458 | J27: =J21 -> 36785.902
B28: Difference | F28: =F27-F26 -> 0 | G28: =G27-G26 -> 0 | H28: =H27-H26 -> 0 | I28: =I27-I26 -> 0 | J28: =J27-J26 -> 0
B31: Segment Scenario Input Matrix
F32: FY2026(E) | G32: FY2027(E) | H32: FY2028(E) | I32: FY2029(E) | J32: FY2030(E)
B33: Future Society Solutions - Revenue Growth (YoY)
B34: Base | F34: 0.15 | G34: 0.15 | H34: 0.12 | I34: 0.08 | J34: 0.05
B35: Upside | F35: 0.25 | G35: 0.22 | H35: 0.18 | I35: 0.12 | J35: 0.08
B36: Management | F36: 0.12 | G36: 0.12 | H36: 0.1 | I36: 0.07 | J36: 0.05
B37: Downside 1 | F37: 0.08 | G37: 0.07 | H37: 0.05 | I37: 0.03 | J37: 0.02
B38: Downside 2 | F38: 0.03 | G38: 0.03 | H38: 0.02 | I38: 0.01 | J38: 0.01
B40: Future Society Solutions - OP Margin
B41: Base | F41: 0.15 | G41: 0.155 | H41: 0.16 | I41: 0.165 | J41: 0.17
B42: Upside | F42: 0.155 | G42: 0.165 | H42: 0.175 | I42: 0.18 | J42: 0.185
B43: Management | F43: 0.148 | G43: 0.15 | H43: 0.152 | I43: 0.155 | J43: 0.158
B44: Downside 1 | F44: 0.14 | G44: 0.14 | H44: 0.142 | I44: 0.145 | J44: 0.145
