Workbook

Sheet Executive Summary
B1: DISCLAIMER: This is a sample analysis for demonstration purposes only. It does not constitute investment advice.
B3: Terra Drone (278A)
B4: Equity Research Report
B6: Company | C6: Terra Drone
B7: Ticker | C7: 278A (TSE Growth)
B8: Sector | C8: Industrial Drone Services / UTM
B9: Current Price | C9: 21620
B10: Target Price (DCF Mid) | C10: =IF(COUNT(C16:C17)=0,"N/A",ROUND(AVERAGE(C16:C17),0)) -> 529
B11: Recommendation | C11: =IF(NOT(ISNUMBER(C12)),"N/A",IF(C12>0.15,"BUY",IF(C12>0.05,"HOLD","SELL"))) -> SELL
B12: Upside / Downside | C12: =IF(ISNUMBER(C10),(C10-C9)/C9,"N/A") -> -0.97553191
B14: Valuation Summary
B15: Methodology | C15: Implied Value (JPY) | D15: vs Current Price
B16: DCF - Perpetuity Growth | C16: =IF('DCF Model'!C53<'DCF Model'!C16,"INVALID (EV < net debt)",'DCF Model'!C55) -> 59 | D16: =IF(ISNUMBER(C16),(C16-C9)/C9,"N/A") -> -0.99727105
B17: DCF - Exit Multiple | C17: =IF('DCF Model'!C62<'DCF Model'!C16,"INVALID (EV < net debt)",'DCF Model'!C64) -> 999 | D17: =IF(ISNUMBER(C17),(C17-C9)/C9,"N/A") -> -0.95379278
B18: Comps - EV/Sales Median [参考・Target不算入] | C18: ='Comps Analysis'!C27 -> 5725 | D18: =IF(ISNUMBER(C18),(C18-C9)/C9,"N/A") -> -0.73519889
B19: Comps - PER Median [参考・Target不算入] | C19: ='Comps Analysis'!C28 -> N/A | D19: =IF(ISNUMBER(C19),(C19-C9)/C9,"N/A") -> N/A
B20: Note: Target Mid は DCF 2法（PGM / Exit）の平均のみ。Comps 2法は [参考] で Target 不算入；PER法は赤字（純利益≦0）のため除外（EV<ネットデットで株式価値が負になる手法は INVALID として平均から除外）
B21: DCF Valuation Range (PGM - Exit) | C21: =IF(COUNT(C16:C17)=0,"N/A",MIN(C16:C17)&" - "&MAX(C16:C17)) -> 59 - 999
B23: Key Investment Thesis
B24: ="The August 2026 defence contract for the Terra B1 intercept drone re-rated the shares to "&TEXT(C9,"#,##0")&" from about 13,000 a month earlier. Its value, volume and schedule are all undisclosed, so this model measures two things only: what the price requires, and how far it can fall." -> The August 2026 defence contract for the Terra B1 intercept drone re-rated the shares to 21,620 from about 13,000 a month earlier. Its value, volume and schedule are all undisclosed, so this model measures two things only: what the price requires, and how far it can fall.
B25: ="At "&TEXT(C9,"#,##0")&" the enterprise value is about JPY222bn against FY1/26 revenue of JPY4,783mn. Growth is slowing as losses widen: sales rose 49.7%, then 7.8%, then 6.6%, while the operating loss went from JPY243mn to JPY627mn to JPY1,144mn." -> At 21,620 the enterprise value is about JPY222bn against FY1/26 revenue of JPY4,783mn. Growth is slowing as losses widen: sales rose 49.7%, then 7.8%, then 6.6%, while the operating loss went from JPY243mn to JPY627mn to JPY1,144mn.
B26: ="The DCF target of "&TEXT(C10,"#,##0")&" implies "&TEXT(C12,"+0.0%;-0.0%")&" at a WACC of "&TEXT('DCF Model'!C26,"0.00%")&", and the shares trade at "&TEXT('Comps Analysis'!M5,"0.00""x""")&" PBR. For a story-led name the target is not the point: the Reverse DCF sheet and the two downside scenarios are." -> The DCF target of 529 implies -97.6% at a WACC of 12.93%, and the shares trade at 50.19x PBR. For a story-led name the target is not the point: the Reverse DCF sheet and the two downside scenarios are.
B28: Key Risks
B29: Runway and dilution: FY1/26 burned JPY716mn of operating cash and JPY1,718mn of investing cash, and cash was JPY2,258mn at the end of April 2026 - roughly one year without external funding. Every prior year was funded by equity (JPY2,497mn at IPO, JPY617mn in FY1/26), so continued issuance is the base case and every per-share number in this workbook is pre-dilution and therefore flattering.
B30: The defence contract has no disclosed value, volume or schedule. Every defence assumption in this model is an estimate at JPY5.0mn per unit, and the whole re-rating rests on a programme whose economics are unknown; the second-quarter results due in mid-September 2026 and any follow-on disclosure are the near-term catalysts in both directions.
B31: Both segments were loss-making and getting worse before the contract: Drone Solutions swung from a JPY194mn to a JPY435mn segment loss and UTM from JPY433mn to JPY709mn, with a further JPY439mn of equity-method losses below the line, and the whole business carries theme-stock volatility of about 115% annualised.

Sheet Financial Statements
B2: Terra Drone - Historical Financials (JPY mn)
C4: FY2024/1 | D4: FY2025/1 | E4: FY2026/1
B5: Income Statement
B6: Revenue | C6: 2963.3 | D6: 4435.6 | E6: 4782.6
B7: COGS | C7: 1424.1 | D7: 2144 | E7: 2469.7
B8: Gross Profit | C8: =C6-C7 -> 1539.2 | D8: =D6-D7 -> 2291.6 | E8: =E6-E7 -> 2312.9
B9: Gross Margin | C9: =C8/C6 -> 0.51942092 | D9: =D8/D6 -> 0.51663811 | E9: =E8/E6 -> 0.48360724
B10: SGA | C10: 1782.3 | D10: 2918.8 | E10: 3456.7
B11: Operating Income | C11: -243.1 | D11: -627.2 | E11: -1143.8
B12: Net Income | C12: -353.9 | D12: -474.8 | E12: -2497.9
B13: Operating Margin | C13: =C11/C6 -> -0.082036918 | D13: =D11/D6 -> -0.14140139 | E13: =E11/E6 -> -0.23915862
B14: Net Margin | C14: =C12/C6 -> -0.11942767 | D14: =D12/D6 -> -0.10704302 | E14: =E12/E6 -> -0.52228913
B15: Revenue Growth (YoY) | C15: n/a | D15: =(D6-C6)/C6 -> 0.49684473 | E15: =(E6-D6)/D6 -> 0.078230679
B16: Operating Income Growth (YoY) | C16: n/a | D16: =(D11-C11)/C11 -> 1.5800082 | E16: =(E11-D11)/D11 -> 0.82366071
B18: Cash Flow Statement
B19: Operating Cash Flow | C19: -15.6 | D19: -927.9 | E19: -716.5
B20: Capex | C20: 249.9 | D20: 683.4 | E20: 875.9
B21: Free Cash Flow | C21: =C19-C20 -> -265.5 | D21: =D19-D20 -> -1611.3 | E21: =E19-E20 -> -1592.4
B22: FCF Margin | C22: =C21/C6 -> -0.089596058 | D22: =D21/D6 -> -0.3632654 | E22: =E21/E6 -> -0.33295697
B23: Capex / Revenue | C23: =C20/C6 -> 0.084331657 | D23: =D20/D6 -> 0.1540716 | E23: =E20/E6 -> 0.18314306
B25: Balance Sheet Highlights
B26: Cash & Deposits | C26: 5008.7 | D26: 4145.6 | E26: 2019
B27: Total Interest-bearing Debt (short + long) | C27: 965.1 | D27: 570.5 | E27: 0
B28: Net Debt (Cash) | C28: =C27-C26 -> -4043.6 | D28: =D27-D26 -> -3575.1 | E28: =E27-E26 -> -2019
B30: Note: OCF / Cash / Debt coverage OCF 3/3, Cash 3/3, Debt 3/3 — blank cells are years with no year-key match in the source data (verify against 決算短信 or set hist_ocf / hist_cash / hist_debt in overrides).

Sheet DCF Model
B2: DCF Valuation Model - Terra Drone
B4: Assumptions
B5: Capex / Revenue | C5: 0.075
B6: Effective Tax Rate | C6: 0.306
B7: Risk-Free Rate | C7: 0.029
B8: Beta | C8: 1.55
B9: Equity Risk Premium | C9: 0.055
B10: Size Premium | C10: 0.015
B11: After-tax Cost of Debt | C11: 0.014
B12: D/E Ratio | C12: 0
B13: Terminal Growth Rate | C13: 0.02
B14: Exit Multiple (EV/Sales) | C14: 2
B15: Fully Diluted Shares | C15: 10397100
B16: Net Debt (JPY mn) | C16: -2257
... B20: LTM Revenue (JPY mn) (override) | C20: 4845.6
B22: WACC Calculation
B23: Cost of Equity (Ke) | C23: =C7+C8*C9+C10 -> 0.12925
B24: Weight of Equity | C24: =1/(1+C12) -> 1
B25: Weight of Debt | C25: =C12/(1+C12) -> 0
B26: WACC | C26: =C23*C24+C11*C25 -> 0.12925
B27: Active Scenario | C27: Base | D27: =MATCH(C27,B69:B73,0) -> 1
B28: Projected Free Cash Flow
C29: FY2027(E) | D29: FY2028(E) | E29: FY2029(E) | F29: FY2030(E) | G29: FY2031(E) | H29: FY2032(E) | I29: FY2033(E) | J29: FY2034(E)
B30: Revenue Growth (YoY) | C30: =CHOOSE($D$27,C69,C70,C71,C72,C73) -> 0.1619 | D30: =CHOOSE($D$27,D69,D70,D71,D72,D73) -> 0.2597 | E30: =CHOOSE($D$27,E69,E70,E71,E72,E73) -> 0.2743 | F30: =CHOOSE($D$27,F69,F70,F71,F72,F73) -> 0.2099 | G30: =CHOOSE($D$27,G69,G70,G71,G72,G73) -> 0.1567 | H30: =CHOOSE($D$27,H69,H70,H71,H72,H73) -> 0.1025 | I30: =CHOOSE($D$27,I69,I70,I71,I72,I73) -> 0.0743 | J30: =CHOOSE($D$27,J69,J70,J71,J72,J73) -> 0.0511
B31: COGS % of Revenue | C31: =CHOOSE($D$27,C76,C77,C78,C79,C80) -> 0.555 | D31: =CHOOSE($D$27,D76,D77,D78,D79,D80) -> 0.56 | E31: =CHOOSE($D$27,E76,E77,E78,E79,E80) -> 0.57 | F31: =CHOOSE($D$27,F76,F77,F78,F79,F80) -> 0.57 | G31: =CHOOSE($D$27,G76,G77,G78,G79,G80) -> 0.57 | H31: =CHOOSE($D$27,H76,H77,H78,H79,H80) -> 0.57 | I31: =CHOOSE($D$27,I76,I77,I78,I79,I80) -> 0.57 | J31: =CHOOSE($D$27,J76,J77,J78,J79,J80) -> 0.57
B32: SGA % of Revenue | C32: =CHOOSE($D$27,C83,C84,C85,C86,C87) -> 0.702 | D32: =CHOOSE($D$27,D83,D84,D85,D86,D87) -> 0.604 | E32: =CHOOSE($D$27,E83,E84,E85,E86,E87) -> 0.514 | F32: =CHOOSE($D$27,F83,F84,F85,F86,F87) -> 0.456 | G32: =CHOOSE($D$27,G83,G84,G85,G86,G87) -> 0.42 | H32: =CHOOSE($D$27,H83,H84,H85,H86,H87) -> 0.376 | I32: =CHOOSE($D$27,I83,I84,I85,I86,I87) -> 0.35 | J32: =CHOOSE($D$27,J83,J84,J85,J86,J87) -> 0.33
B33: Revenue | C33: =C17*(1+C30) -> 5556.9029 | D33: =C33*(1+D30) -> 7000.0306 | E33: =D33*(1+E30) -> 8920.139 | F33: =E33*(1+F30) -> 10792.476 | G33: =F33*(1+G30) -> 12483.657 | H33: =G33*(1+H30) -> 13763.232 | I33: =H33*(1+I30) -> 14785.84 | J33: =I33*(1+J30) -> 15541.397
B34: COGS | C34: =C33*C31 -> 3084.0811 | D34: =D33*D31 -> 3920.0172 | E34: =E33*E31 -> 5084.4793 | F34: =F33*F31 -> 6151.7114 | G34: =G33*G31 -> 7115.6846 | H34: =H33*H31 -> 7845.0423 | I34: =I33*I31 -> 8427.9289 | J34: =J33*J31 -> 8858.5961
B35: Gross Profit | C35: =C33-C34 -> 2472.8218 | D35: =D33-D34 -> 3080.0135 | E35: =E33-E34 -> 3835.6598 | F35: =F33-F34 -> 4640.7648 | G35: =G33-G34 -> 5367.9726 | H35: =H33-H34 -> 5918.1898 | I35: =I33-I34 -> 6357.9113 | J35: =J33-J34 -> 6682.8006
B36: Gross Margin | C36: =C35/C33 -> 0.445 | D36: =D35/D33 -> 0.44 | E36: =E35/E33 -> 0.43 | F36: =F35/F33 -> 0.43 | G36: =G35/G33 -> 0.43 | H36: =H35/H33 -> 0.43 | I36: =I35/I33 -> 0.43 | J36: =J35/J33 -> 0.43
B37: SGA Expense | C37: =C33*C32 -> 3900.9459 | D37: =D33*D32 -> 4228.0185 | E37: =E33*E32 -> 4584.9515 | F37: =F33*F32 -> 4921.3692 | G37: =G33*G32 -> 5243.136 | H37: =H33*H32 -> 5174.9753 | I37: =I33*I32 -> 5175.0441 | J37: =J33*J32 -> 5128.6609
B38: Implied Operating Margin | C38: =(C35-C37)/C33 -> -0.257 | D38: =(D35-D37)/D33 -> -0.164 | E38: =(E35-E37)/E33 -> -0.084 | F38: =(F35-F37)/F33 -> -0.026 | G38: =(G35-G37)/G33 -> 0.01 | H38: =(H35-H37)/H33 -> 0.054 | I38: =(I35-I37)/I33 -> 0.08 | J38: =(J35-J37)/J33 -> 0.1
B39: Operating Income (EBIT) | C39: =C35-C37 -> -1428.1241 | D39: =D35-D37 -> -1148.005 | E39: =E35-E37 -> -749.29168 | F39: =F35-F37 -> -280.60438 | G39: =G35-G37 -> 124.83657 | H39: =H35-H37 -> 743.21453 | I39: =I35-I37 -> 1182.8672 | J39: =J35-J37 -> 1554.1397
B40: Less: Tax | C40: =MAX(0,C39*C6) -> 0 | D40: =MAX(0,D39*C6) -> 0 | E40: =MAX(0,E39*C6) -> 0 | F40: =MAX(0,F39*C6) -> 0 | G40: =MAX(0,G39*C6) -> 38.199991 | H40: =MAX(0,H39*C6) -> 227.42365 | I40: =MAX(0,I39*C6) -> 361.95737 | J40: =MAX(0,J39*C6) -> 475.56674
B41: NOPAT | C41: =C39-C40 -> -1428.1241 | D41: =D39-D40 -> -1148.005 | E41: =E39-E40 -> -749.29168 | F41: =F39-F40 -> -280.60438 | G41: =G39-G40 -> 86.636581 | H41: =H39-H40 -> 515.79089 | I41: =I39-I40 -> 820.90985 | J41: =J39-J40 -> 1078.5729
B42: Plus: D&A | C42: =C33*C18 -> 388.98321 | D42: =D33*C18 -> 490.00214 | E42: =E33*C18 -> 624.40973 | F42: =F33*C18 -> 755.47334 | G42: =G33*C18 -> 873.85601 | H42: =H33*C18 -> 963.42625 | I42: =I33*C18 -> 1035.0088 | J42: =J33*C18 -> 1087.8978
B43: Less: Capex | C43: =C33*C5 -> 416.76772 | D43: =D33*C5 -> 525.0023 | E43: =E33*C5 -> 669.01043 | F43: =F33*C5 -> 809.43572 | G43: =G33*C5 -> 936.27429 | H43: =H33*C5 -> 1032.2424 | I43: =I33*C5 -> 1108.938 | J43: =J33*C5 -> 1165.6048
B44: Change in NWC | C44: ='NWC Schedule'!D19 -> 281.14162 | D44: ='NWC Schedule'!E19 -> 482.74457 | E44: ='NWC Schedule'!F19 -> 627.57729 | F44: ='NWC Schedule'!G19 -> 651.98372 | G44: ='NWC Schedule'!H19 -> 520.49806 | H44: ='NWC Schedule'!I19 -> 395.57461 | I44: ='NWC Schedule'!J19 -> 225.76708 | J44: ='NWC Schedule'!K19 -> 250.38933
B45: Unlevered Free Cash Flow | C45: =C41+C42-C43-C44 -> -1737.0502 | D45: =D41+D42-D43-D44 -> -1665.7497 | E45: =E41+E42-E43-E44 -> -1421.4697 | F45: =F41+F42-F43-F44 -> -986.55048 | G45: =G41+G42-G43-G44 -> -496.27977 | H45: =H41+H42-H43-H44 -> 51.40012 | I45: =I41+I42-I43-I44 -> 521.21357 | J45: =J41+J42-J43-J44 -> 750.47661
B46: Discount Factor | C46: =1/(1+C26)^(C19+0) -> 0.95022873 | D46: =1/(1+C26)^(C19+1) -> 0.84146888 | E46: =1/(1+C26)^(C19+2) -> 0.7451573 | F46: =1/(1+C26)^(C19+3) -> 0.6598692 | G46: =1/(1+C26)^(C19+4) -> 0.58434289 | H46: =1/(1+C26)^(C19+5) -> 0.51746105 | I46: =1/(1+C26)^(C19+6) -> 0.45823427 | J46: =1/(1+C26)^(C19+7) -> 0.40578638
...

Sheet Reverse DCF
B2: Reverse DCF - Terra Drone (278A)
B3: What is the current share price already assuming? Every value below is a live formula off the other sheets.
B5: Block 0: Market-implied enterprise value (live)
B6: Current Share Price (JPY) | C6: ='Executive Summary'!C9 -> 21620
B7: Fully Diluted Shares | C7: ='DCF Model'!C15 -> 10397100
B8: Market Capitalisation (JPY mn) | C8: =C6*C7/1000000 -> 224785.3
B9: Net Debt (JPY mn) | C9: ='DCF Model'!C16 -> -2257
B10: Enterprise Value (JPY mn) | C10: =C8+C9 -> 222528.3
B11: WACC (w) | C11: ='DCF Model'!C26 -> 0.12925
B12: Terminal Growth (g) | C12: ='DCF Model'!C13 -> 0.02
B13: Effective Tax Rate (t) | C13: ='DCF Model'!C6 -> 0.306
B14: Starting Operating Profit OP0 (FY2026/1 actual) | C14: -1143.8
B15: Cycle-peak Operating Profit (Upside scenario FY2034/1 - model, not actual) | C15: 6385
B16: Terminal-year Revenue, active scenario (JPY mn) | C16: ='DCF Model'!J33 -> 15541.397
B17: Base-case DCF Enterprise Value, PGM (JPY mn) | C17: ='DCF Model'!C53 -> -1639.2743
B18: Cycle-peak Operating Margin (Upside scenario FY2034/1 - model, not actual) | C18: 0.15
B19: Gap: market EV less base-case DCF EV (JPY mn) | C19: =C10-C17 -> 224167.58
B20: Gap per share (JPY) - the part of the price the base case does not explain | C20: =IFERROR(ROUND(C19*1000000/C7,0),"N/A") -> 21561
B22: Block A: Required steady-state operating profit, reached IMMEDIATELY (no ramp)
B23: The lowest bar the price can clear: today's EV read as a perpetuity of one steady-state profit, capex = D&A, no NWC build.
B24: Required steady-state NOPAT (JPY mn) | C24: =C10*(C11-C12) -> 24311.217
B25: Required steady-state Operating Profit (JPY mn) | C25: =IFERROR(C24/(1-C13),"N/A") -> 35030.572
B26: ... as a multiple of the Upside scenario FY2034/1 - model, not peak | C26: =IFERROR(C25/C15,"N/A") -> 5.4863856
B27: ... as a multiple of FY2026/1 actual | C27: =IFERROR(C25/C14,"N/A") -> -30.626484
B28: ... implied OPM on terminal-year revenue | C28: =IFERROR(C25/C16,"N/A") -> 2.254017
B29: ... revenue needed if margins only reach the cycle peak | C29: =IFERROR(C25/C18,"N/A") -> 233537.15
B32: Block B: Required steady-state operating profit by YEARS-TO-REACH (linear ramp) x WACC
B33: Operating profit ramps linearly from OP0 (C14) to OP* over N years, then grows at g for ever. Column F is the model WACC.
B34: OP* = ( EV/(1-t) - OP0*(A-B) ) / ( B + TVF ). A longer ramp needs a HIGHER steady state, because more years are spent below it.
B36: Years to steady state (N) \ WACC | C36: N | D36: ='DCF Model'!C26-0.02 -> 0.10925 | E36: ='DCF Model'!C26-0.01 -> 0.11925 | F36: ='DCF Model'!C26 -> 0.12925 | G36: ='DCF Model'!C26+0.01 -> 0.13925 | H36: ='DCF Model'!C26+0.02 -> 0.14925
B37: B-1 PV weight on the RAMP from OP0 (A - B)
B38: N = 5 years | C38: 5 | D38: =IFERROR((1-(1+D$36)^(-$C38))/D$36-(1+D$36)/(D$36^2*$C38)*(1-($C38+1)/(1+D$36)^$C38+$C38/(1+D$36)^($C38+1)),"N/A") -> 1.6340133 | E38: =IFERROR((1-(1+E$36)^(-$C38))/E$36-(1+E$36)/(E$36^2*$C38)*(1-($C38+1)/(1+E$36)^$C38+$C38/(1+E$36)^($C38+1)),"N/A") -> 1.6064514 | F38: =IFERROR((1-(1+F$36)^(-$C38))/F$36-(1+F$36)/(F$36^2*$C38)*(1-($C38+1)/(1+F$36)^$C38+$C38/(1+F$36)^($C38+1)),"N/A") -> 1.5797099 | G38: =IFERROR((1-(1+G$36)^(-$C38))/G$36-(1+G$36)/(G$36^2*$C38)*(1-($C38+1)/(1+G$36)^$C38+$C38/(1+G$36)^($C38+1)),"N/A") -> 1.5537553 | H38: =IFERROR((1-(1+H$36)^(-$C38))/H$36-(1+H$36)/(H$36^2*$C38)*(1-($C38+1)/(1+H$36)^$C38+$C38/(1+H$36)^($C38+1)),"N/A") -> 1.5285559
B39: N = 8 years | C39: 8 | D39: =IFERROR((1-(1+D$36)^(-$C39))/D$36-(1+D$36)/(D$36^2*$C39)*(1-($C39+1)/(1+D$36)^$C39+$C39/(1+D$36)^($C39+1)),"N/A") -> 2.6045347 | E39: =IFERROR((1-(1+E$36)^(-$C39))/E$36-(1+E$36)/(E$36^2*$C39)*(1-($C39+1)/(1+E$36)^$C39+$C39/(1+E$36)^($C39+1)),"N/A") -> 2.5423159 | F39: =IFERROR((1-(1+F$36)^(-$C39))/F$36-(1+F$36)/(F$36^2*$C39)*(1-($C39+1)/(1+F$36)^$C39+$C39/(1+F$36)^($C39+1)),"N/A") -> 2.4826367 | G39: =IFERROR((1-(1+G$36)^(-$C39))/G$36-(1+G$36)/(G$36^2*$C39)*(1-($C39+1)/(1+G$36)^$C39+$C39/(1+G$36)^($C39+1)),"N/A") -> 2.4253591 | H39: =IFERROR((1-(1+H$36)^(-$C39))/H$36-(1+H$36)/(H$36^2*$C39)*(1-($C39+1)/(1+H$36)^$C39+$C39/(1+H$36)^($C39+1)),"N/A") -> 2.3703541
B40: N = 10 years | C40: 10 | D40: =IFERROR((1-(1+D$36)^(-$C40))/D$36-(1+D$36)/(D$36^2*$C40)*(1-($C40+1)/(1+D$36)^$C40+$C40/(1+D$36)^($C40+1)),"N/A") -> 3.1549419 | E40: =IFERROR((1-(1+E$36)^(-$C40))/E$36-(1+E$36)/(E$36^2*$C40)*(1-($C40+1)/(1+E$36)^$C40+$C40/(1+E$36)^($C40+1)),"N/A") -> 3.0662686 | F40: =IFERROR((1-(1+F$36)^(-$C40))/F$36-(1+F$36)/(F$36^2*$C40)*(1-($C40+1)/(1+F$36)^$C40+$C40/(1+F$36)^($C40+1)),"N/A") -> 2.9818207 | G40: =IFERROR((1-(1+G$36)^(-$C40))/G$36-(1+G$36)/(G$36^2*$C40)*(1-($C40+1)/(1+G$36)^$C40+$C40/(1+G$36)^($C40+1)),"N/A") -> 2.9013326 | H40: =IFERROR((1-(1+H$36)^(-$C40))/H$36-(1+H$36)/(H$36^2*$C40)*(1-($C40+1)/(1+H$36)^$C40+$C40/(1+H$36)^($C40+1)),"N/A") -> 2.8245588
B41: N = 15 years | C41: 15 | D41: =IFERROR((1-(1+D$36)^(-$C41))/D$36-(1+D$36)/(D$36^2*$C41)*(1-($C41+1)/(1+D$36)^$C41+$C41/(1+D$36)^($C41+1)),"N/A") -> 4.2656866 | E41: =IFERROR((1-(1+E$36)^(-$C41))/E$36-(1+E$36)/(E$36^2*$C41)*(1-($C41+1)/(1+E$36)^$C41+$C41/(1+E$36)^($C41+1)),"N/A") -> 4.1069533 | F41: =IFERROR((1-(1+F$36)^(-$C41))/F$36-(1+F$36)/(F$36^2*$C41)*(1-($C41+1)/(1+F$36)^$C41+$C41/(1+F$36)^($C41+1)),"N/A") -> 3.9582177 | G41: =IFERROR((1-(1+G$36)^(-$C41))/G$36-(1+G$36)/(G$36^2*$C41)*(1-($C41+1)/(1+G$36)^$C41+$C41/(1+G$36)^($C41+1)),"N/A") -> 3.8186559 | H41: =IFERROR((1-(1+H$36)^(-$C41))/H$36-(1+H$36)/(H$36^2*$C41)*(1-($C41+1)/(1+H$36)^$C41+$C41/(1+H$36)^($C41+1)),"N/A") -> 3.6875249
B42: B-2 PV weight on the STEADY STATE OP* (B + terminal factor)
B43: N = 5 years | C43: 5 | D43: =IFERROR((1+D$36)/(D$36^2*$C43)*(1-($C43+1)/(1+D$36)^$C43+$C43/(1+D$36)^($C43+1))+(1+$C$12)/((D$36-$C$12)*(1+D$36)^$C43),"N/A") -> 8.8741278 | E43: =IFERROR((1+E$36)/(E$36^2*$C43)*(1-($C43+1)/(1+E$36)^$C43+$C43/(1+E$36)^($C43+1))+(1+$C$12)/((E$36-$C$12)*(1+E$36)^$C43),"N/A") -> 7.856087 | F43: =IFERROR((1+F$36)/(F$36^2*$C43)*(1-($C43+1)/(1+F$36)^$C43+$C43/(1+F$36)^($C43+1))+(1+$C$12)/((F$36-$C$12)*(1+F$36)^$C43),"N/A") -> 7.0282329 | G43: =IFERROR((1+G$36)/(G$36^2*$C43)*(1-($C43+1)/(1+G$36)^$C43+$C43/(1+G$36)^($C43+1))+(1+$C$12)/((G$36-$C$12)*(1+G$36)^$C43),"N/A") -> 6.3425637 | H43: =IFERROR((1+H$36)/(H$36^2*$C43)*(1-($C43+1)/(1+H$36)^$C43+$C43/(1+H$36)^($C43+1))+(1+$C$12)/((H$36-$C$12)*(1+H$36)^$C43),"N/A") -> 5.7659408
B44: N = 8 years | C44: 8 | D44: =IFERROR((1+D$36)/(D$36^2*$C44)*(1-($C44+1)/(1+D$36)^$C44+$C44/(1+D$36)^($C44+1))+(1+$C$12)/((D$36-$C$12)*(1+D$36)^$C44),"N/A") -> 7.5414291 | E44: =IFERROR((1+E$36)/(E$36^2*$C44)*(1-($C44+1)/(1+E$36)^$C44+$C44/(1+E$36)^($C44+1))+(1+$C$12)/((E$36-$C$12)*(1+E$36)^$C44),"N/A") -> 6.611411 | F44: =IFERROR((1+F$36)/(F$36^2*$C44)*(1-($C44+1)/(1+F$36)^$C44+$C44/(1+F$36)^($C44+1))+(1+$C$12)/((F$36-$C$12)*(1+F$36)^$C44),"N/A") -> 5.8591567 | G44: =IFERROR((1+G$36)/(G$36^2*$C44)*(1-($C44+1)/(1+G$36)^$C44+$C44/(1+G$36)^($C44+1))+(1+$C$12)/((G$36-$C$12)*(1+G$36)^$C44),"N/A") -> 5.2395214 | H44: =IFERROR((1+H$36)/(H$36^2*$C44)*(1-($C44+1)/(1+H$36)^$C44+$C44/(1+H$36)^($C44+1))+(1+$C$12)/((H$36-$C$12)*(1+H$36)^$C44),"N/A") -> 4.7213601
B45: N = 10 years | C45: 10 | D45: =IFERROR((1+D$36)/(D$36^2*$C45)*(1-($C45+1)/(1+D$36)^$C45+$C45/(1+D$36)^($C45+1))+(1+$C$12)/((D$36-$C$12)*(1+D$36)^$C45),"N/A") -> 6.8051195 | E45: =IFERROR((1+E$36)/(E$36^2*$C45)*(1-($C45+1)/(1+E$36)^$C45+$C45/(1+E$36)^($C45+1))+(1+$C$12)/((E$36-$C$12)*(1+E$36)^$C45),"N/A") -> 5.9325275 | F45: =IFERROR((1+F$36)/(F$36^2*$C45)*(1-($C45+1)/(1+F$36)^$C45+$C45/(1+F$36)^($C45+1))+(1+$C$12)/((F$36-$C$12)*(1+F$36)^$C45),"N/A") -> 5.2294385 | G45: =IFERROR((1+G$36)/(G$36^2*$C45)*(1-($C45+1)/(1+G$36)^$C45+$C45/(1+G$36)^($C45+1))+(1+$C$12)/((G$36-$C$12)*(1+G$36)^$C45),"N/A") -> 4.6525635 | H45: =IFERROR((1+H$36)/(H$36^2*$C45)*(1-($C45+1)/(1+H$36)^$C45+$C45/(1+H$36)^($C45+1))+(1+$C$12)/((H$36-$C$12)*(1+H$36)^$C45),"N/A") -> 4.1720608
B46: N = 15 years | C46: 15 | D46: =IFERROR((1+D$36)/(D$36^2*$C46)*(1-($C46+1)/(1+D$36)^$C46+$C46/(1+D$36)^($C46+1))+(1+$C$12)/((D$36-$C$12)*(1+D$36)^$C46),"N/A") -> 5.3680151 | E46: =IFERROR((1+E$36)/(E$36^2*$C46)*(1-($C46+1)/(1+E$36)^$C46+$C46/(1+E$36)^($C46+1))+(1+$C$12)/((E$36-$C$12)*(1+E$36)^$C46),"N/A") -> 4.62782 | F46: =IFERROR((1+F$36)/(F$36^2*$C46)*(1-($C46+1)/(1+F$36)^$C46+$C46/(1+F$36)^($C46+1))+(1+$C$12)/((F$36-$C$12)*(1+F$36)^$C46),"N/A") -> 4.0370216 | G46: =IFERROR((1+G$36)/(G$36^2*$C46)*(1-($C46+1)/(1+G$36)^$C46+$C46/(1+G$36)^($C46+1))+(1+$C$12)/((G$36-$C$12)*(1+G$36)^$C46),"N/A") -> 3.5568104 | H46: =IFERROR((1+H$36)/(H$36^2*$C46)*(1-($C46+1)/(1+H$36)^$C46+$C46/(1+H$36)^($C46+1))+(1+$C$12)/((H$36-$C$12)*(1+H$36)^$C46),"N/A") -> 3.1605132
...

Sheet NWC Schedule
B2: NWC Schedule - Terra Drone
B4: Working Capital Drivers (Days) | C4: Base Year | D4: FY2027(E) | E4: FY2028(E) | F4: FY2029(E) | G4: FY2030(E) | H4: FY2031(E) | I4: FY2032(E) | J4: FY2033(E) | K4: FY2034(E)
B5: DSO (Days Sales Outstanding) | C5: =C12/C9*365 -> 115.70621 | D5: =CHOOSE('DCF Model'!$D$27,D25,D26,D27,D28,D29) -> 115 | E5: =CHOOSE('DCF Model'!$D$27,E25,E26,E27,E28,E29) -> 113 | F5: =CHOOSE('DCF Model'!$D$27,F25,F26,F27,F28,F29) -> 110 | G5: =CHOOSE('DCF Model'!$D$27,G25,G26,G27,G28,G29) -> 110 | H5: =CHOOSE('DCF Model'!$D$27,H25,H26,H27,H28,H29) -> 108 | I5: =CHOOSE('DCF Model'!$D$27,I25,I26,I27,I28,I29) -> 108 | J5: =CHOOSE('DCF Model'!$D$27,J25,J26,J27,J28,J29) -> 105 | K5: =CHOOSE('DCF Model'!$D$27,K25,K26,K27,K28,K29) -> 105
B6: DIH (Days Inventory Held) | C6: =C13/C10*365 -> 88.349597 | D6: =CHOOSE('DCF Model'!$D$27,D32,D33,D34,D35,D36) -> 88 | E6: =CHOOSE('DCF Model'!$D$27,E32,E33,E34,E35,E36) -> 88 | F6: =CHOOSE('DCF Model'!$D$27,F32,F33,F34,F35,F36) -> 90 | G6: =CHOOSE('DCF Model'!$D$27,G32,G33,G34,G35,G36) -> 90 | H6: =CHOOSE('DCF Model'!$D$27,H32,H33,H34,H35,H36) -> 90 | I6: =CHOOSE('DCF Model'!$D$27,I32,I33,I34,I35,I36) -> 88 | J6: =CHOOSE('DCF Model'!$D$27,J32,J33,J34,J35,J36) -> 88 | K6: =CHOOSE('DCF Model'!$D$27,K32,K33,K34,K35,K36) -> 88
B7: DPO (Days Payable Outstanding) | C7: =C15/C10*365 -> 58.998259 | D7: =CHOOSE('DCF Model'!$D$27,D39,D40,D41,D42,D43) -> 59 | E7: =CHOOSE('DCF Model'!$D$27,E39,E40,E41,E42,E43) -> 59 | F7: =CHOOSE('DCF Model'!$D$27,F39,F40,F41,F42,F43) -> 60 | G7: =CHOOSE('DCF Model'!$D$27,G39,G40,G41,G42,G43) -> 60 | H7: =CHOOSE('DCF Model'!$D$27,H39,H40,H41,H42,H43) -> 60 | I7: =CHOOSE('DCF Model'!$D$27,I39,I40,I41,I42,I43) -> 60 | J7: =CHOOSE('DCF Model'!$D$27,J39,J40,J41,J42,J43) -> 60 | K7: =CHOOSE('DCF Model'!$D$27,K39,K40,K41,K42,K43) -> 60
B8: P&L Reference (JPY mn)
B9: Revenue | C9: 4782.6 | D9: ='DCF Model'!C33 -> 5556.9029 | E9: ='DCF Model'!D33 -> 7000.0306 | F9: ='DCF Model'!E33 -> 8920.139 | G9: ='DCF Model'!F33 -> 10792.476 | H9: ='DCF Model'!G33 -> 12483.657 | I9: ='DCF Model'!H33 -> 13763.232 | J9: ='DCF Model'!I33 -> 14785.84 | K9: ='DCF Model'!J33 -> 15541.397
B10: COGS | C10: 2469.7 | D10: ='DCF Model'!C34 -> 3084.0811 | E10: ='DCF Model'!D34 -> 3920.0172 | F10: ='DCF Model'!E34 -> 5084.4793 | G10: ='DCF Model'!F34 -> 6151.7114 | H10: ='DCF Model'!G34 -> 7115.6846 | I10: ='DCF Model'!H34 -> 7845.0423 | J10: ='DCF Model'!I34 -> 8427.9289 | K10: ='DCF Model'!J34 -> 8858.5961
B11: Working Capital Items (JPY mn)
B12: Accounts Receivable | C12: 1516.1 | D12: =D9*D5/365 -> 1750.805 | E12: =E9*E5/365 -> 2167.1328 | F12: =F9*F5/365 -> 2688.2611 | G12: =G9*G5/365 -> 3252.5271 | H12: =H9*H5/365 -> 3693.7945 | I12: =I9*I5/365 -> 4072.4084 | J12: =J9*J5/365 -> 4253.4609 | K12: =K9*K5/365 -> 4470.8127
B13: Inventory | C13: 597.8 | D13: =D10*D6/365 -> 743.55929 | E13: =E10*E6/365 -> 945.10003 | F13: =F10*F6/365 -> 1253.7072 | G13: =G10*G6/365 -> 1516.8604 | H13: =H10*H6/365 -> 1754.5524 | I13: =I10*I6/365 -> 1891.4075 | J13: =J10*J6/365 -> 2031.939 | K13: =K10*K6/365 -> 2135.7711
B14: Current Assets (AR + Inv) | C14: =C12+C13 -> 2113.9 | D14: =D12+D13 -> 2494.3643 | E14: =E12+E13 -> 3112.2328 | F14: =F12+F13 -> 3941.9683 | G14: =G12+G13 -> 4769.3874 | H14: =H12+H13 -> 5448.3468 | I14: =I12+I13 -> 5963.8159 | J14: =J12+J13 -> 6285.3999 | K14: =K12+K13 -> 6606.5839
B15: Accounts Payable | C15: 399.2 | D15: =D10*D7/365 -> 498.5227 | E15: =E10*E7/365 -> 633.64661 | F15: =F10*F7/365 -> 835.80481 | G15: =G10*G7/365 -> 1011.2402 | H15: =H10*H7/365 -> 1169.7016 | I15: =I10*I7/365 -> 1289.596 | J15: =J10*J7/365 -> 1385.413 | K15: =K10*K7/365 -> 1456.2076
B16: Current Liabilities (AP) | C16: =C15 -> 399.2 | D16: =D15 -> 498.5227 | E16: =E15 -> 633.64661 | F16: =F15 -> 835.80481 | G16: =G15 -> 1011.2402 | H16: =H15 -> 1169.7016 | I16: =I15 -> 1289.596 | J16: =J15 -> 1385.413 | K16: =K15 -> 1456.2076
B17: Net Working Capital (JPY mn)
B18: Net Working Capital | C18: =C14-C16 -> 1714.7 | D18: =D14-D16 -> 1995.8416 | E18: =E14-E16 -> 2478.5862 | F18: =F14-F16 -> 3106.1635 | G18: =G14-G16 -> 3758.1472 | H18: =H14-H16 -> 4278.6453 | I18: =I14-I16 -> 4674.2199 | J18: =J14-J16 -> 4899.987 | K18: =K14-K16 -> 5150.3763
B19: Change in NWC | C19: n/a | D19: =D18-C18 -> 281.14162 | E19: =E18-D18 -> 482.74457 | F19: =F18-E18 -> 627.57729 | G19: =G18-F18 -> 651.98372 | H19: =H18-G18 -> 520.49806 | I19: =I18-H18 -> 395.57461 | J19: =J18-I18 -> 225.76708 | K19: =K18-J18 -> 250.38933
B22: Scenario Input Matrix (Working Capital Days)
D23: FY2027(E) | E23: FY2028(E) | F23: FY2029(E) | G23: FY2030(E) | H23: FY2031(E) | I23: FY2032(E) | J23: FY2033(E) | K23: FY2034(E)
B24: DSO (Days)
B25: Base | D25: 115 | E25: 113 | F25: 110 | G25: 110 | H25: 108 | I25: 108 | J25: 105 | K25: 105
B26: Upside | D26: 112 | E26: 110 | F26: 108 | G26: 105 | H26: 105 | I26: 103 | J26: 100 | K26: 100
B27: Management | D27: 115 | E27: 113 | F27: 110 | G27: 110 | H27: 108 | I27: 108 | J27: 105 | K27: 105
B28: Downside 1 | D28: 118 | E28: 120 | F28: 122 | G28: 122 | H28: 122 | I28: 122 | J28: 122 | K28: 122
B29: Downside 2 | D29: 122 | E29: 125 | F29: 128 | G29: 128 | H29: 128 | I29: 128 | J29: 128 | K29: 128
B31: DIH (Days)
B32: Base | D32: 88 | E32: 88 | F32: 90 | G32: 90 | H32: 90 | I32: 88 | J32: 88 | K32: 88
B33: Upside | D33: 90 | E33: 92 | F33: 95 | G33: 95 | H33: 95 | I33: 92 | J33: 90 | K33: 90
B34: Management | D34: 88 | E34: 88 | F34: 90 | G34: 90 | H34: 90 | I34: 88 | J34: 88 | K34: 88
B35: Downside 1 | D35: 90 | E35: 92 | F35: 95 | G35: 95 | H35: 95 | I35: 95 | J35: 95 | K35: 95
B36: Downside 2 | D36: 92 | E36: 95 | F36: 98 | G36: 98 | H36: 98 | I36: 98 | J36: 98 | K36: 98
B38: DPO (Days)
B39: Base | D39: 59 | E39: 59 | F39: 60 | G39: 60 | H39: 60 | I39: 60 | J39: 60 | K39: 60
B40: Upside | D40: 62 | E40: 62 | F40: 65 | G40: 65 | H40: 65 | I40: 65 | J40: 65 | K40: 65
B41: Management | D41: 59 | E41: 59 | F41: 60 | G41: 60 | H41: 60 | I41: 60 | J41: 60 | K41: 60
B42: Downside 1 | D42: 57 | E42: 56 | F42: 55 | G42: 55 | H42: 55 | I42: 55 | J42: 55 | K42: 55
B43: Downside 2 | D43: 55 | E43: 54 | F43: 52 | G43: 52 | H43: 52 | I43: 52 | J43: 52 | K43: 52

Sheet Comps Analysis
B2: Comparable Company Analysis
B3: Peer prices as of 2026-08-29 (Mkt Cap / EV of peer rows are static CSV values; the subject row is live-linked to Executive Summary)
B4: Company | C4: Ticker | D4: Mkt Cap (JPY mn) | E4: EV (JPY mn) | F4: Revenue (JPY mn) | G4: EBITDA (JPY mn) | H4: Op Income (JPY mn) | I4: Net Income (JPY mn) | J4: EV/EBITDA | K4: EV/Revenue | L4: PER | M4: PBR | N4: Op Margin | O4: ROE | P4: Book Value (JPY mn) | Q4: Note
B5: Terra Drone (278A) [subject] | C5: 278A.T | D5: ='Executive Summary'!C9*C23/1000000 -> 224785.3 | E5: =D5+C24 -> 222528.3 | F5: 4783 | G5: -617 | H5: -1144 | I5: -2498 | J5: N/A | K5: =IFERROR(E5/F5,"") -> 46.524838 | L5: N/A | M5: =IFERROR(D5/P5,"") -> 50.186493 | N5: =IFERROR(H5/F5,"") -> -0.23918043 | O5: =IFERROR(I5/P5,"") -> -0.55771378 | P5: 4479
B6: ACSL (6232) | C6: 6232.T | D6: 30278 | E6: 31123 | F6: 2599 | G6: -1768 | H6: -1840 | I6: -1364 | J6: N/A | K6: =IFERROR(E6/F6,"") -> 11.97499 | L6: N/A | M6: =IFERROR(D6/P6,"") -> 17.242597 | N6: =IFERROR(H6/F6,"") -> -0.7079646 | O6: =IFERROR(I6/P6,"") -> -0.77676538 | P6: 1756
B7: AeroVironment (AVAV) | C7: AVAV | D7: 1203277 | E7: 1235683 | F7: 316370 | G7: 31167 | H7: -11249 | I7: -42430 | J7: =IFERROR(E7/G7,"") -> 39.647159 | K7: =IFERROR(E7/F7,"") -> 3.905816 | L7: N/A | M7: =IFERROR(D7/P7,"") -> 1.7086396 | N7: =IFERROR(H7/F7,"") -> -0.035556469 | O7: =IFERROR(I7/P7,"") -> -0.060250117 | P7: 704231
B8: Kratos Defense (KTOS) | C8: KTOS | D8: 1562212 | E8: 1495828 | F8: 215539 | G8: 13923 | H8: 4433 | I8: 3521 | J8: =IFERROR(E8/G8,"") -> 107.43575 | K8: =IFERROR(E8/F8,"") -> 6.9399413 | L8: =IFERROR(D8/I8,"") -> 443.68418 | M8: =IFERROR(D8/P8,"") -> 4.8897973 | N8: =IFERROR(H8/F8,"") -> 0.020567044 | O8: =IFERROR(I8/P8,"") -> 0.011020896 | P8: 319484
B9: Red Cat Holdings (RCAT) | C9: RCAT | D9: 207496 | E9: 183582 | F9: 6518 | G9: -10296 | H9: -10658 | I9: -11535 | J9: N/A | K9: =IFERROR(E9/F9,"") -> 28.165388 | L9: N/A | M9: =IFERROR(D9/P9,"") -> 5.2741599 | N9: =IFERROR(H9/F9,"") -> -1.6351642 | O9: =IFERROR(I9/P9,"") -> -0.29319811 | P9: 39342
B10: Ondas Holdings (ONDS) | C10: ONDS | D10: 721349 | E10: 637629 | F10: 8119 | G10: -8066 | H10: -9344 | I10: -21128 | J10: N/A | K10: =IFERROR(E10/F10,"") -> 78.535411 | L10: N/A | M10: =IFERROR(D10/P10,"") -> 10.295279 | N10: =IFERROR(H10/F10,"") -> -1.1508807 | O10: =IFERROR(I10/P10,"") -> -0.30154426 | P10: 70066
B14: Statistics
B15: 25th Percentile | D15: =PERCENTILE(J7:J8,0.25) -> 56.594308 | E15: =PERCENTILE(K6:K10,0.25) -> 6.9399413 | F15: =PERCENTILE(L6:L10,0.25) -> 443.68418 | G15: =PERCENTILE(M6:M10,0.25) -> 4.8897973 | H15: =PERCENTILE(N6:N10,0.25) -> -1.1508807 | I15: =PERCENTILE(O6:O10,0.25) -> -0.30154426
B16: Median (50th) | D16: =MEDIAN(J7:J8) -> 73.541456 | E16: =MEDIAN(K6:K10) -> 11.97499 | F16: =MEDIAN(L6:L10) -> 443.68418 | G16: =MEDIAN(M6:M10) -> 5.2741599 | H16: =MEDIAN(N6:N10) -> -0.7079646 | I16: =MEDIAN(O6:O10) -> -0.29319811
B17: 75th Percentile | D17: =PERCENTILE(J7:J8,0.75) -> 90.488605 | E17: =PERCENTILE(K6:K10,0.75) -> 28.165388 | F17: =PERCENTILE(L6:L10,0.75) -> 443.68418 | G17: =PERCENTILE(M6:M10,0.75) -> 10.295279 | H17: =PERCENTILE(N6:N10,0.75) -> -0.035556469 | I17: =PERCENTILE(O6:O10,0.75) -> -0.060250117
B19: Implied Valuation for Terra Drone
B20: Terra Drone Financials
B21: Revenue (JPY mn) | C21: 4782.6
B22: Net Income (JPY mn) | C22: -2497.9
B23: Shares Outstanding | C23: 10397100
B24: Net Debt (JPY mn) | C24: -2257
B26: Implied Share Price (Median Multiples)
B27: Via EV/Sales (Median) | C27: =ROUND((C21*E16-C24)*1000000/C23,0) -> 5725
B28: Via PER (Median) | C28: N/A | D28: Net income <= 0 — PER not meaningful

Sheet Sensitivity Analysis
B2: Sensitivity Analysis
B3: Current WACC: | C3: ='DCF Model'!C26 -> 0.12925 | E3: Terminal g: | F3: ='DCF Model'!C13 -> 0.02 | H3: Exit Multiple: | I3: ='DCF Model'!C14 -> 2
B5: Table 1: WACC vs Terminal Growth Rate (PGM - Implied Share Price, JPY)
B6: WACC \ Terminal g | C6: =$F$3-0.0075 -> 0.0125 | D6: =$F$3-0.005 -> 0.015 | E6: =$F$3-0.0025 -> 0.0175 | F6: =$F$3 -> 0.02 | G6: =$F$3+0.0025 -> 0.0225 | H6: =$F$3+0.005 -> 0.025 | I6: =$F$3+0.0075 -> 0.0275
B7: =$C$3-0.015 -> 0.11425 | C7: =IFERROR(ROUND(('DCF Model'!C45/(1+$B7)^('DCF Model'!C19+0)+'DCF Model'!D45/(1+$B7)^('DCF Model'!C19+1)+'DCF Model'!E45/(1+$B7)^('DCF Model'!C19+2)+'DCF Model'!F45/(1+$B7)^('DCF Model'!C19+3)+'DCF Model'!G45/(1+$B7)^('DCF Model'!C19+4)+'DCF Model'!H45/(1+$B7)^('DCF Model'!C19+5)+'DCF Model'!I45/(1+$B7)^('DCF Model'!C19+6)+'DCF Model'!J45/(1+$B7)^('DCF Model'!C19+7)+'DCF Model'!J45*(1+C$6)/($B7-C$6)/(1+$B7)^('DCF Model'!C19+7)-'DCF Model'!C16)*1000000/'DCF Model'!C15,0),"") -> 102 | D7: =IFERROR(ROUND(('DCF Model'!C45/(1+$B7)^('DCF Model'!C19+0)+'DCF Model'!D45/(1+$B7)^('DCF Model'!C19+1)+'DCF Model'!E45/(1+$B7)^('DCF Model'!C19+2)+'DCF Model'!F45/(1+$B7)^('DCF Model'!C19+3)+'DCF Model'!G45/(1+$B7)^('DCF Model'!C19+4)+'DCF Model'!H45/(1+$B7)^('DCF Model'!C19+5)+'DCF Model'!I45/(1+$B7)^('DCF Model'!C19+6)+'DCF Model'!J45/(1+$B7)^('DCF Model'!C19+7)+'DCF Model'!J45*(1+D$6)/($B7-D$6)/(1+$B7)^('DCF Model'!C19+7)-'DCF Model'!C16)*1000000/'DCF Model'!C15,0),"") -> 111 | E7: =IFERROR(ROUND(('DCF Model'!C45/(1+$B7)^('DCF Model'!C19+0)+'DCF Model'!D45/(1+$B7)^('DCF Model'!C19+1)+'DCF Model'!E45/(1+$B7)^('DCF Model'!C19+2)+'DCF Model'!F45/(1+$B7)^('DCF Model'!C19+3)+'DCF Model'!G45/(1+$B7)^('DCF Model'!C19+4)+'DCF Model'!H45/(1+$B7)^('DCF Model'!C19+5)+'DCF Model'!I45/(1+$B7)^('DCF Model'!C19+6)+'DCF Model'!J45/(1+$B7)^('DCF Model'!C19+7)+'DCF Model'!J45*(1+E$6)/($B7-E$6)/(1+$B7)^('DCF Model'!C19+7)-'DCF Model'!C16)*1000000/'DCF Model'!C15,0),"") -> 120 | F7: =IFERROR(ROUND(('DCF Model'!C45/(1+$B7)^('DCF Model'!C19+0)+'DCF Model'!D45/(1+$B7)^('DCF Model'!C19+1)+'DCF Model'!E45/(1+$B7)^('DCF Model'!C19+2)+'DCF Model'!F45/(1+$B7)^('DCF Model'!C19+3)+'DCF Model'!G45/(1+$B7)^('DCF Model'!C19+4)+'DCF Model'!H45/(1+$B7)^('DCF Model'!C19+5)+'DCF Model'!I45/(1+$B7)^('DCF Model'!C19+6)+'DCF Model'!J45/(1+$B7)^('DCF Model'!C19+7)+'DCF Model'!J45*(1+F$6)/($B7-F$6)/(1+$B7)^('DCF Model'!C19+7)-'DCF Model'!C16)*1000000/'DCF Model'!C15,0),"") -> 130 | G7: =IFERROR(ROUND(('DCF Model'!C45/(1+$B7)^('DCF Model'!C19+0)+'DCF Model'!D45/(1+$B7)^('DCF Model'!C19+1)+'DCF Model'!E45/(1+$B7)^('DCF Model'!C19+2)+'DCF Model'!F45/(1+$B7)^('DCF Model'!C19+3)+'DCF Model'!G45/(1+$B7)^('DCF Model'!C19+4)+'DCF Model'!H45/(1+$B7)^('DCF Model'!C19+5)+'DCF Model'!I45/(1+$B7)^('DCF Model'!C19+6)+'DCF Model'!J45/(1+$B7)^('DCF Model'!C19+7)+'DCF Model'!J45*(1+G$6)/($B7-G$6)/(1+$B7)^('DCF Model'!C19+7)-'DCF Model'!C16)*1000000/'DCF Model'!C15,0),"") -> 140 | H7: =IFERROR(ROUND(('DCF Model'!C45/(1+$B7)^('DCF Model'!C19+0)+'DCF Model'!D45/(1+$B7)^('DCF Model'!C19+1)+'DCF Model'!E45/(1+$B7)^('DCF Model'!C19+2)+'DCF Model'!F45/(1+$B7)^('DCF Model'!C19+3)+'DCF Model'!G45/(1+$B7)^('DCF Model'!C19+4)+'DCF Model'!H45/(1+$B7)^('DCF Model'!C19+5)+'DCF Model'!I45/(1+$B7)^('DCF Model'!C19+6)+'DCF Model'!J45/(1+$B7)^('DCF Model'!C19+7)+'DCF Model'!J45*(1+H$6)/($B7-H$6)/(1+$B7)^('DCF Model'!C19+7)-'DCF Model'!C16)*1000000/'DCF Model'!C15,0),"") -> 151 | I7: =IFERROR(ROUND(('DCF Model'!C45/(1+$B7)^('DCF Model'!C19+0)+'DCF Model'!D45/(1+$B7)^('DCF Model'!C19+1)+'DCF Model'!E45/(1+$B7)^('DCF Model'!C19+2)+'DCF Model'!F45/(1+$B7)^('DCF Model'!C19+3)+'DCF Model'!G45/(1+$B7)^('DCF Model'!C19+4)+'DCF Model'!H45/(1+$B7)^('DCF Model'!C19+5)+'DCF Model'!I45/(1+$B7)^('DCF Model'!C19+6)+'DCF Model'!J45/(1+$B7)^('DCF Model'!C19+7)+'DCF Model'!J45*(1+I$6)/($B7-I$6)/(1+$B7)^('DCF Model'!C19+7)-'DCF Model'!C16)*1000000/'DCF Model'!C15,0),"") -> 163
B8: =$C$3-0.01 -> 0.11925 | C8: =IFERROR(ROUND(('DCF Model'!C45/(1+$B8)^('DCF Model'!C19+0)+'DCF Model'!D45/(1+$B8)^('DCF Model'!C19+1)+'DCF Model'!E45/(1+$B8)^('DCF Model'!C19+2)+'DCF Model'!F45/(1+$B8)^('DCF Model'!C19+3)+'DCF Model'!G45/(1+$B8)^('DCF Model'!C19+4)+'DCF Model'!H45/(1+$B8)^('DCF Model'!C19+5)+'DCF Model'!I45/(1+$B8)^('DCF Model'!C19+6)+'DCF Model'!J45/(1+$B8)^('DCF Model'!C19+7)+'DCF Model'!J45*(1+C$6)/($B8-C$6)/(1+$B8)^('DCF Model'!C19+7)-'DCF Model'!C16)*1000000/'DCF Model'!C15,0),"") -> 79 | D8: =IFERROR(ROUND(('DCF Model'!C45/(1+$B8)^('DCF Model'!C19+0)+'DCF Model'!D45/(1+$B8)^('DCF Model'!C19+1)+'DCF Model'!E45/(1+$B8)^('DCF Model'!C19+2)+'DCF Model'!F45/(1+$B8)^('DCF Model'!C19+3)+'DCF Model'!G45/(1+$B8)^('DCF Model'!C19+4)+'DCF Model'!H45/(1+$B8)^('DCF Model'!C19+5)+'DCF Model'!I45/(1+$B8)^('DCF Model'!C19+6)+'DCF Model'!J45/(1+$B8)^('DCF Model'!C19+7)+'DCF Model'!J45*(1+D$6)/($B8-D$6)/(1+$B8)^('DCF Model'!C19+7)-'DCF Model'!C16)*1000000/'DCF Model'!C15,0),"") -> 86 | E8: =IFERROR(ROUND(('DCF Model'!C45/(1+$B8)^('DCF Model'!C19+0)+'DCF Model'!D45/(1+$B8)^('DCF Model'!C19+1)+'DCF Model'!E45/(1+$B8)^('DCF Model'!C19+2)+'DCF Model'!F45/(1+$B8)^('DCF Model'!C19+3)+'DCF Model'!G45/(1+$B8)^('DCF Model'!C19+4)+'DCF Model'!H45/(1+$B8)^('DCF Model'!C19+5)+'DCF Model'!I45/(1+$B8)^('DCF Model'!C19+6)+'DCF Model'!J45/(1+$B8)^('DCF Model'!C19+7)+'DCF Model'!J45*(1+E$6)/($B8-E$6)/(1+$B8)^('DCF Model'!C19+7)-'DCF Model'!C16)*1000000/'DCF Model'!C15,0),"") -> 95 | F8: =IFERROR(ROUND(('DCF Model'!C45/(1+$B8)^('DCF Model'!C19+0)+'DCF Model'!D45/(1+$B8)^('DCF Model'!C19+1)+'DCF Model'!E45/(1+$B8)^('DCF Model'!C19+2)+'DCF Model'!F45/(1+$B8)^('DCF Model'!C19+3)+'DCF Model'!G45/(1+$B8)^('DCF Model'!C19+4)+'DCF Model'!H45/(1+$B8)^('DCF Model'!C19+5)+'DCF Model'!I45/(1+$B8)^('DCF Model'!C19+6)+'DCF Model'!J45/(1+$B8)^('DCF Model'!C19+7)+'DCF Model'!J45*(1+F$6)/($B8-F$6)/(1+$B8)^('DCF Model'!C19+7)-'DCF Model'!C16)*1000000/'DCF Model'!C15,0),"") -> 103 | G8: =IFERROR(ROUND(('DCF Model'!C45/(1+$B8)^('DCF Model'!C19+0)+'DCF Model'!D45/(1+$B8)^('DCF Model'!C19+1)+'DCF Model'!E45/(1+$B8)^('DCF Model'!C19+2)+'DCF Model'!F45/(1+$B8)^('DCF Model'!C19+3)+'DCF Model'!G45/(1+$B8)^('DCF Model'!C19+4)+'DCF Model'!H45/(1+$B8)^('DCF Model'!C19+5)+'DCF Model'!I45/(1+$B8)^('DCF Model'!C19+6)+'DCF Model'!J45/(1+$B8)^('DCF Model'!C19+7)+'DCF Model'!J45*(1+G$6)/($B8-G$6)/(1+$B8)^('DCF Model'!C19+7)-'DCF Model'!C16)*1000000/'DCF Model'!C15,0),"") -> 113 | H8: =IFERROR(ROUND(('DCF Model'!C45/(1+$B8)^('DCF Model'!C19+0)+'DCF Model'!D45/(1+$B8)^('DCF Model'!C19+1)+'DCF Model'!E45/(1+$B8)^('DCF Model'!C19+2)+'DCF Model'!F45/(1+$B8)^('DCF Model'!C19+3)+'DCF Model'!G45/(1+$B8)^('DCF Model'!C19+4)+'DCF Model'!H45/(1+$B8)^('DCF Model'!C19+5)+'DCF Model'!I45/(1+$B8)^('DCF Model'!C19+6)+'DCF Model'!J45/(1+$B8)^('DCF Model'!C19+7)+'DCF Model'!J45*(1+H$6)/($B8-H$6)/(1+$B8)^('DCF Model'!C19+7)-'DCF Model'!C16)*1000000/'DCF Model'!C15,0),"") -> 122 | I8: =IFERROR(ROUND(('DCF Model'!C45/(1+$B8)^('DCF Model'!C19+0)+'DCF Model'!D45/(1+$B8)^('DCF Model'!C19+1)+'DCF Model'!E45/(1+$B8)^('DCF Model'!C19+2)+'DCF Model'!F45/(1+$B8)^('DCF Model'!C19+3)+'DCF Model'!G45/(1+$B8)^('DCF Model'!C19+4)+'DCF Model'!H45/(1+$B8)^('DCF Model'!C19+5)+'DCF Model'!I45/(1+$B8)^('DCF Model'!C19+6)+'DCF Model'!J45/(1+$B8)^('DCF Model'!C19+7)+'DCF Model'!J45*(1+I$6)/($B8-I$6)/(1+$B8)^('DCF Model'!C19+7)-'DCF Model'!C16)*1000000/'DCF Model'!C15,0),"") -> 132
B9: =$C$3-0.005 -> 0.12425 | C9: =IFERROR(ROUND(('DCF Model'!C45/(1+$B9)^('DCF Model'!C19+0)+'DCF Model'!D45/(1+$B9)^('DCF Model'!C19+1)+'DCF Model'!E45/(1+$B9)^('DCF Model'!C19+2)+'DCF Model'!F45/(1+$B9)^('DCF Model'!C19+3)+'DCF Model'!G45/(1+$B9)^('DCF Model'!C19+4)+'DCF Model'!H45/(1+$B9)^('DCF Model'!C19+5)+'DCF Model'!I45/(1+$B9)^('DCF Model'!C19+6)+'DCF Model'!J45/(1+$B9)^('DCF Model'!C19+7)+'DCF Model'!J45*(1+C$6)/($B9-C$6)/(1+$B9)^('DCF Model'!C19+7)-'DCF Model'!C16)*1000000/'DCF Model'!C15,0),"") -> 58 | D9: =IFERROR(ROUND(('DCF Model'!C45/(1+$B9)^('DCF Model'!C19+0)+'DCF Model'!D45/(1+$B9)^('DCF Model'!C19+1)+'DCF Model'!E45/(1+$B9)^('DCF Model'!C19+2)+'DCF Model'!F45/(1+$B9)^('DCF Model'!C19+3)+'DCF Model'!G45/(1+$B9)^('DCF Model'!C19+4)+'DCF Model'!H45/(1+$B9)^('DCF Model'!C19+5)+'DCF Model'!I45/(1+$B9)^('DCF Model'!C19+6)+'DCF Model'!J45/(1+$B9)^('DCF Model'!C19+7)+'DCF Model'!J45*(1+D$6)/($B9-D$6)/(1+$B9)^('DCF Model'!C19+7)-'DCF Model'!C16)*1000000/'DCF Model'!C15,0),"") -> 65 | E9: =IFERROR(ROUND(('DCF Model'!C45/(1+$B9)^('DCF Model'!C19+0)+'DCF Model'!D45/(1+$B9)^('DCF Model'!C19+1)+'DCF Model'!E45/(1+$B9)^('DCF Model'!C19+2)+'DCF Model'!F45/(1+$B9)^('DCF Model'!C19+3)+'DCF Model'!G45/(1+$B9)^('DCF Model'!C19+4)+'DCF Model'!H45/(1+$B9)^('DCF Model'!C19+5)+'DCF Model'!I45/(1+$B9)^('DCF Model'!C19+6)+'DCF Model'!J45/(1+$B9)^('DCF Model'!C19+7)+'DCF Model'!J45*(1+E$6)/($B9-E$6)/(1+$B9)^('DCF Model'!C19+7)-'DCF Model'!C16)*1000000/'DCF Model'!C15,0),"") -> 72 | F9: =IFERROR(ROUND(('DCF Model'!C45/(1+$B9)^('DCF Model'!C19+0)+'DCF Model'!D45/(1+$B9)^('DCF Model'!C19+1)+'DCF Model'!E45/(1+$B9)^('DCF Model'!C19+2)+'DCF Model'!F45/(1+$B9)^('DCF Model'!C19+3)+'DCF Model'!G45/(1+$B9)^('DCF Model'!C19+4)+'DCF Model'!H45/(1+$B9)^('DCF Model'!C19+5)+'DCF Model'!I45/(1+$B9)^('DCF Model'!C19+6)+'DCF Model'!J45/(1+$B9)^('DCF Model'!C19+7)+'DCF Model'!J45*(1+F$6)/($B9-F$6)/(1+$B9)^('DCF Model'!C19+7)-'DCF Model'!C16)*1000000/'DCF Model'!C15,0),"") -> 80 | G9: =IFERROR(ROUND(('DCF Model'!C45/(1+$B9)^('DCF Model'!C19+0)+'DCF Model'!D45/(1+$B9)^('DCF Model'!C19+1)+'DCF Model'!E45/(1+$B9)^('DCF Model'!C19+2)+'DCF Model'!F45/(1+$B9)^('DCF Model'!C19+3)+'DCF Model'!G45/(1+$B9)^('DCF Model'!C19+4)+'DCF Model'!H45/(1+$B9)^('DCF Model'!C19+5)+'DCF Model'!I45/(1+$B9)^('DCF Model'!C19+6)+'DCF Model'!J45/(1+$B9)^('DCF Model'!C19+7)+'DCF Model'!J45*(1+G$6)/($B9-G$6)/(1+$B9)^('DCF Model'!C19+7)-'DCF Model'!C16)*1000000/'DCF Model'!C15,0),"") -> 88 | H9: =IFERROR(ROUND(('DCF Model'!C45/(1+$B9)^('DCF Model'!C19+0)+'DCF Model'!D45/(1+$B9)^('DCF Model'!C19+1)+'DCF Model'!E45/(1+$B9)^('DCF Model'!C19+2)+'DCF Model'!F45/(1+$B9)^('DCF Model'!C19+3)+'DCF Model'!G45/(1+$B9)^('DCF Model'!C19+4)+'DCF Model'!H45/(1+$B9)^('DCF Model'!C19+5)+'DCF Model'!I45/(1+$B9)^('DCF Model'!C19+6)+'DCF Model'!J45/(1+$B9)^('DCF Model'!C19+7)+'DCF Model'!J45*(1+H$6)/($B9-H$6)/(1+$B9)^('DCF Model'!C19+7)-'DCF Model'!C16)*1000000/'DCF Model'!C15,0),"") -> 97 | I9: =IFERROR(ROUND(('DCF Model'!C45/(1+$B9)^('DCF Model'!C19+0)+'DCF Model'!D45/(1+$B9)^('DCF Model'!C19+1)+'DCF Model'!E45/(1+$B9)^('DCF Model'!C19+2)+'DCF Model'!F45/(1+$B9)^('DCF Model'!C19+3)+'DCF Model'!G45/(1+$B9)^('DCF Model'!C19+4)+'DCF Model'!H45/(1+$B9)^('DCF Model'!C19+5)+'DCF Model'!I45/(1+$B9)^('DCF Model'!C19+6)+'DCF Model'!J45/(1+$B9)^('DCF Model'!C19+7)+'DCF Model'!J45*(1+I$6)/($B9-I$6)/(1+$B9)^('DCF Model'!C19+7)-'DCF Model'!C16)*1000000/'DCF Model'!C15,0),"") -> 105
B10: =$C$3 -> 0.12925 | C10: =IFERROR(ROUND(('DCF Model'!C45/(1+$B10)^('DCF Model'!C19+0)+'DCF Model'!D45/(1+$B10)^('DCF Model'!C19+1)+'DCF Model'!E45/(1+$B10)^('DCF Model'!C19+2)+'DCF Model'!F45/(1+$B10)^('DCF Model'!C19+3)+'DCF Model'!G45/(1+$B10)^('DCF Model'!C19+4)+'DCF Model'!H45/(1+$B10)^('DCF Model'!C19+5)+'DCF Model'!I45/(1+$B10)^('DCF Model'!C19+6)+'DCF Model'!J45/(1+$B10)^('DCF Model'!C19+7)+'DCF Model'!J45*(1+C$6)/($B10-C$6)/(1+$B10)^('DCF Model'!C19+7)-'DCF Model'!C16)*1000000/'DCF Model'!C15,0),"") -> 40 | D10: =IFERROR(ROUND(('DCF Model'!C45/(1+$B10)^('DCF Model'!C19+0)+'DCF Model'!D45/(1+$B10)^('DCF Model'!C19+1)+'DCF Model'!E45/(1+$B10)^('DCF Model'!C19+2)+'DCF Model'!F45/(1+$B10)^('DCF Model'!C19+3)+'DCF Model'!G45/(1+$B10)^('DCF Model'!C19+4)+'DCF Model'!H45/(1+$B10)^('DCF Model'!C19+5)+'DCF Model'!I45/(1+$B10)^('DCF Model'!C19+6)+'DCF Model'!J45/(1+$B10)^('DCF Model'!C19+7)+'DCF Model'!J45*(1+D$6)/($B10-D$6)/(1+$B10)^('DCF Model'!C19+7)-'DCF Model'!C16)*1000000/'DCF Model'!C15,0),"") -> 46 | E10: =IFERROR(ROUND(('DCF Model'!C45/(1+$B10)^('DCF Model'!C19+0)+'DCF Model'!D45/(1+$B10)^('DCF Model'!C19+1)+'DCF Model'!E45/(1+$B10)^('DCF Model'!C19+2)+'DCF Model'!F45/(1+$B10)^('DCF Model'!C19+3)+'DCF Model'!G45/(1+$B10)^('DCF Model'!C19+4)+'DCF Model'!H45/(1+$B10)^('DCF Model'!C19+5)+'DCF Model'!I45/(1+$B10)^('DCF Model'!C19+6)+'DCF Model'!J45/(1+$B10)^('DCF Model'!C19+7)+'DCF Model'!J45*(1+E$6)/($B10-E$6)/(1+$B10)^('DCF Model'!C19+7)-'DCF Model'!C16)*1000000/'DCF Model'!C15,0),"") -> 53 | F10: =IFERROR(ROUND(('DCF Model'!C45/(1+$B10)^('DCF Model'!C19+0)+'DCF Model'!D45/(1+$B10)^('DCF Model'!C19+1)+'DCF Model'!E45/(1+$B10)^('DCF Model'!C19+2)+'DCF Model'!F45/(1+$B10)^('DCF Model'!C19+3)+'DCF Model'!G45/(1+$B10)^('DCF Model'!C19+4)+'DCF Model'!H45/(1+$B10)^('DCF Model'!C19+5)+'DCF Model'!I45/(1+$B10)^('DCF Model'!C19+6)+'DCF Model'!J45/(1+$B10)^('DCF Model'!C19+7)+'DCF Model'!J45*(1+F$6)/($B10-F$6)/(1+$B10)^('DCF Model'!C19+7)-'DCF Model'!C16)*1000000/'DCF Model'!C15,0),"") -> 59 | G10: =IFERROR(ROUND(('DCF Model'!C45/(1+$B10)^('DCF Model'!C19+0)+'DCF Model'!D45/(1+$B10)^('DCF Model'!C19+1)+'DCF Model'!E45/(1+$B10)^('DCF Model'!C19+2)+'DCF Model'!F45/(1+$B10)^('DCF Model'!C19+3)+'DCF Model'!G45/(1+$B10)^('DCF Model'!C19+4)+'DCF Model'!H45/(1+$B10)^('DCF Model'!C19+5)+'DCF Model'!I45/(1+$B10)^('DCF Model'!C19+6)+'DCF Model'!J45/(1+$B10)^('DCF Model'!C19+7)+'DCF Model'!J45*(1+G$6)/($B10-G$6)/(1+$B10)^('DCF Model'!C19+7)-'DCF Model'!C16)*1000000/'DCF Model'!C15,0),"") -> 67 | H10: =IFERROR(ROUND(('DCF Model'!C45/(1+$B10)^('DCF Model'!C19+0)+'DCF Model'!D45/(1+$B10)^('DCF Model'!C19+1)+'DCF Model'!E45/(1+$B10)^('DCF Model'!C19+2)+'DCF Model'!F45/(1+$B10)^('DCF Model'!C19+3)+'DCF Model'!G45/(1+$B10)^('DCF Model'!C19+4)+'DCF Model'!H45/(1+$B10)^('DCF Model'!C19+5)+'DCF Model'!I45/(1+$B10)^('DCF Model'!C19+6)+'DCF Model'!J45/(1+$B10)^('DCF Model'!C19+7)+'DCF Model'!J45*(1+H$6)/($B10-H$6)/(1+$B10)^('DCF Model'!C19+7)-'DCF Model'!C16)*1000000/'DCF Model'!C15,0),"") -> 74 | I10: =IFERROR(ROUND(('DCF Model'!C45/(1+$B10)^('DCF Model'!C19+0)+'DCF Model'!D45/(1+$B10)^('DCF Model'!C19+1)+'DCF Model'!E45/(1+$B10)^('DCF Model'!C19+2)+'DCF Model'!F45/(1+$B10)^('DCF Model'!C19+3)+'DCF Model'!G45/(1+$B10)^('DCF Model'!C19+4)+'DCF Model'!H45/(1+$B10)^('DCF Model'!C19+5)+'DCF Model'!I45/(1+$B10)^('DCF Model'!C19+6)+'DCF Model'!J45/(1+$B10)^('DCF Model'!C19+7)+'DCF Model'!J45*(1+I$6)/($B10-I$6)/(1+$B10)^('DCF Model'!C19+7)-'DCF Model'!C16)*1000000/'DCF Model'!C15,0),"") -> 82
B11: =$C$3+0.005 -> 0.13425 | C11: =IFERROR(ROUND(('DCF Model'!C45/(1+$B11)^('DCF Model'!C19+0)+'DCF Model'!D45/(1+$B11)^('DCF Model'!C19+1)+'DCF Model'!E45/(1+$B11)^('DCF Model'!C19+2)+'DCF Model'!F45/(1+$B11)^('DCF Model'!C19+3)+'DCF Model'!G45/(1+$B11)^('DCF Model'!C19+4)+'DCF Model'!H45/(1+$B11)^('DCF Model'!C19+5)+'DCF Model'!I45/(1+$B11)^('DCF Model'!C19+6)+'DCF Model'!J45/(1+$B11)^('DCF Model'!C19+7)+'DCF Model'!J45*(1+C$6)/($B11-C$6)/(1+$B11)^('DCF Model'!C19+7)-'DCF Model'!C16)*1000000/'DCF Model'!C15,0),"") -> 24 | D11: =IFERROR(ROUND(('DCF Model'!C45/(1+$B11)^('DCF Model'!C19+0)+'DCF Model'!D45/(1+$B11)^('DCF Model'!C19+1)+'DCF Model'!E45/(1+$B11)^('DCF Model'!C19+2)+'DCF Model'!F45/(1+$B11)^('DCF Model'!C19+3)+'DCF Model'!G45/(1+$B11)^('DCF Model'!C19+4)+'DCF Model'!H45/(1+$B11)^('DCF Model'!C19+5)+'DCF Model'!I45/(1+$B11)^('DCF Model'!C19+6)+'DCF Model'!J45/(1+$B11)^('DCF Model'!C19+7)+'DCF Model'!J45*(1+D$6)/($B11-D$6)/(1+$B11)^('DCF Model'!C19+7)-'DCF Model'!C16)*1000000/'DCF Model'!C15,0),"") -> 29 | E11: =IFERROR(ROUND(('DCF Model'!C45/(1+$B11)^('DCF Model'!C19+0)+'DCF Model'!D45/(1+$B11)^('DCF Model'!C19+1)+'DCF Model'!E45/(1+$B11)^('DCF Model'!C19+2)+'DCF Model'!F45/(1+$B11)^('DCF Model'!C19+3)+'DCF Model'!G45/(1+$B11)^('DCF Model'!C19+4)+'DCF Model'!H45/(1+$B11)^('DCF Model'!C19+5)+'DCF Model'!I45/(1+$B11)^('DCF Model'!C19+6)+'DCF Model'!J45/(1+$B11)^('DCF Model'!C19+7)+'DCF Model'!J45*(1+E$6)/($B11-E$6)/(1+$B11)^('DCF Model'!C19+7)-'DCF Model'!C16)*1000000/'DCF Model'!C15,0),"") -> 35 | F11: =IFERROR(ROUND(('DCF Model'!C45/(1+$B11)^('DCF Model'!C19+0)+'DCF Model'!D45/(1+$B11)^('DCF Model'!C19+1)+'DCF Model'!E45/(1+$B11)^('DCF Model'!C19+2)+'DCF Model'!F45/(1+$B11)^('DCF Model'!C19+3)+'DCF Model'!G45/(1+$B11)^('DCF Model'!C19+4)+'DCF Model'!H45/(1+$B11)^('DCF Model'!C19+5)+'DCF Model'!I45/(1+$B11)^('DCF Model'!C19+6)+'DCF Model'!J45/(1+$B11)^('DCF Model'!C19+7)+'DCF Model'!J45*(1+F$6)/($B11-F$6)/(1+$B11)^('DCF Model'!C19+7)-'DCF Model'!C16)*1000000/'DCF Model'!C15,0),"") -> 41 | G11: =IFERROR(ROUND(('DCF Model'!C45/(1+$B11)^('DCF Model'!C19+0)+'DCF Model'!D45/(1+$B11)^('DCF Model'!C19+1)+'DCF Model'!E45/(1+$B11)^('DCF Model'!C19+2)+'DCF Model'!F45/(1+$B11)^('DCF Model'!C19+3)+'DCF Model'!G45/(1+$B11)^('DCF Model'!C19+4)+'DCF Model'!H45/(1+$B11)^('DCF Model'!C19+5)+'DCF Model'!I45/(1+$B11)^('DCF Model'!C19+6)+'DCF Model'!J45/(1+$B11)^('DCF Model'!C19+7)+'DCF Model'!J45*(1+G$6)/($B11-G$6)/(1+$B11)^('DCF Model'!C19+7)-'DCF Model'!C16)*1000000/'DCF Model'!C15,0),"") -> 47 | H11: =IFERROR(ROUND(('DCF Model'!C45/(1+$B11)^('DCF Model'!C19+0)+'DCF Model'!D45/(1+$B11)^('DCF Model'!C19+1)+'DCF Model'!E45/(1+$B11)^('DCF Model'!C19+2)+'DCF Model'!F45/(1+$B11)^('DCF Model'!C19+3)+'DCF Model'!G45/(1+$B11)^('DCF Model'!C19+4)+'DCF Model'!H45/(1+$B11)^('DCF Model'!C19+5)+'DCF Model'!I45/(1+$B11)^('DCF Model'!C19+6)+'DCF Model'!J45/(1+$B11)^('DCF Model'!C19+7)+'DCF Model'!J45*(1+H$6)/($B11-H$6)/(1+$B11)^('DCF Model'!C19+7)-'DCF Model'!C16)*1000000/'DCF Model'!C15,0),"") -> 54 | I11: =IFERROR(ROUND(('DCF Model'!C45/(1+$B11)^('DCF Model'!C19+0)+'DCF Model'!D45/(1+$B11)^('DCF Model'!C19+1)+'DCF Model'!E45/(1+$B11)^('DCF Model'!C19+2)+'DCF Model'!F45/(1+$B11)^('DCF Model'!C19+3)+'DCF Model'!G45/(1+$B11)^('DCF Model'!C19+4)+'DCF Model'!H45/(1+$B11)^('DCF Model'!C19+5)+'DCF Model'!I45/(1+$B11)^('DCF Model'!C19+6)+'DCF Model'!J45/(1+$B11)^('DCF Model'!C19+7)+'DCF Model'!J45*(1+I$6)/($B11-I$6)/(1+$B11)^('DCF Model'!C19+7)-'DCF Model'!C16)*1000000/'DCF Model'!C15,0),"") -> 61
B12: =$C$3+0.01 -> 0.13925 | C12: =IFERROR(ROUND(('DCF Model'!C45/(1+$B12)^('DCF Model'!C19+0)+'DCF Model'!D45/(1+$B12)^('DCF Model'!C19+1)+'DCF Model'!E45/(1+$B12)^('DCF Model'!C19+2)+'DCF Model'!F45/(1+$B12)^('DCF Model'!C19+3)+'DCF Model'!G45/(1+$B12)^('DCF Model'!C19+4)+'DCF Model'!H45/(1+$B12)^('DCF Model'!C19+5)+'DCF Model'!I45/(1+$B12)^('DCF Model'!C19+6)+'DCF Model'!J45/(1+$B12)^('DCF Model'!C19+7)+'DCF Model'!J45*(1+C$6)/($B12-C$6)/(1+$B12)^('DCF Model'!C19+7)-'DCF Model'!C16)*1000000/'DCF Model'!C15,0),"") -> 9 | D12: =IFERROR(ROUND(('DCF Model'!C45/(1+$B12)^('DCF Model'!C19+0)+'DCF Model'!D45/(1+$B12)^('DCF Model'!C19+1)+'DCF Model'!E45/(1+$B12)^('DCF Model'!C19+2)+'DCF Model'!F45/(1+$B12)^('DCF Model'!C19+3)+'DCF Model'!G45/(1+$B12)^('DCF Model'!C19+4)+'DCF Model'!H45/(1+$B12)^('DCF Model'!C19+5)+'DCF Model'!I45/(1+$B12)^('DCF Model'!C19+6)+'DCF Model'!J45/(1+$B12)^('DCF Model'!C19+7)+'DCF Model'!J45*(1+D$6)/($B12-D$6)/(1+$B12)^('DCF Model'!C19+7)-'DCF Model'!C16)*1000000/'DCF Model'!C15,0),"") -> 14 | E12: =IFERROR(ROUND(('DCF Model'!C45/(1+$B12)^('DCF Model'!C19+0)+'DCF Model'!D45/(1+$B12)^('DCF Model'!C19+1)+'DCF Model'!E45/(1+$B12)^('DCF Model'!C19+2)+'DCF Model'!F45/(1+$B12)^('DCF Model'!C19+3)+'DCF Model'!G45/(1+$B12)^('DCF Model'!C19+4)+'DCF Model'!H45/(1+$B12)^('DCF Model'!C19+5)+'DCF Model'!I45/(1+$B12)^('DCF Model'!C19+6)+'DCF Model'!J45/(1+$B12)^('DCF Model'!C19+7)+'DCF Model'!J45*(1+E$6)/($B12-E$6)/(1+$B12)^('DCF Model'!C19+7)-'DCF Model'!C16)*1000000/'DCF Model'!C15,0),"") -> 19 | F12: =IFERROR(ROUND(('DCF Model'!C45/(1+$B12)^('DCF Model'!C19+0)+'DCF Model'!D45/(1+$B12)^('DCF Model'!C19+1)+'DCF Model'!E45/(1+$B12)^('DCF Model'!C19+2)+'DCF Model'!F45/(1+$B12)^('DCF Model'!C19+3)+'DCF Model'!G45/(1+$B12)^('DCF Model'!C19+4)+'DCF Model'!H45/(1+$B12)^('DCF Model'!C19+5)+'DCF Model'!I45/(1+$B12)^('DCF Model'!C19+6)+'DCF Model'!J45/(1+$B12)^('DCF Model'!C19+7)+'DCF Model'!J45*(1+F$6)/($B12-F$6)/(1+$B12)^('DCF Model'!C19+7)-'DCF Model'!C16)*1000000/'DCF Model'!C15,0),"") -> 25 | G12: =IFERROR(ROUND(('DCF Model'!C45/(1+$B12)^('DCF Model'!C19+0)+'DCF Model'!D45/(1+$B12)^('DCF Model'!C19+1)+'DCF Model'!E45/(1+$B12)^('DCF Model'!C19+2)+'DCF Model'!F45/(1+$B12)^('DCF Model'!C19+3)+'DCF Model'!G45/(1+$B12)^('DCF Model'!C19+4)+'DCF Model'!H45/(1+$B12)^('DCF Model'!C19+5)+'DCF Model'!I45/(1+$B12)^('DCF Model'!C19+6)+'DCF Model'!J45/(1+$B12)^('DCF Model'!C19+7)+'DCF Model'!J45*(1+G$6)/($B12-G$6)/(1+$B12)^('DCF Model'!C19+7)-'DCF Model'!C16)*1000000/'DCF Model'!C15,0),"") -> 30 | H12: =IFERROR(ROUND(('DCF Model'!C45/(1+$B12)^('DCF Model'!C19+0)+'DCF Model'!D45/(1+$B12)^('DCF Model'!C19+1)+'DCF Model'!E45/(1+$B12)^('DCF Model'!C19+2)+'DCF Model'!F45/(1+$B12)^('DCF Model'!C19+3)+'DCF Model'!G45/(1+$B12)^('DCF Model'!C19+4)+'DCF Model'!H45/(1+$B12)^('DCF Model'!C19+5)+'DCF Model'!I45/(1+$B12)^('DCF Model'!C19+6)+'DCF Model'!J45/(1+$B12)^('DCF Model'!C19+7)+'DCF Model'!J45*(1+H$6)/($B12-H$6)/(1+$B12)^('DCF Model'!C19+7)-'DCF Model'!C16)*1000000/'DCF Model'!C15,0),"") -> 36 | I12: =IFERROR(ROUND(('DCF Model'!C45/(1+$B12)^('DCF Model'!C19+0)+'DCF Model'!D45/(1+$B12)^('DCF Model'!C19+1)+'DCF Model'!E45/(1+$B12)^('DCF Model'!C19+2)+'DCF Model'!F45/(1+$B12)^('DCF Model'!C19+3)+'DCF Model'!G45/(1+$B12)^('DCF Model'!C19+4)+'DCF Model'!H45/(1+$B12)^('DCF Model'!C19+5)+'DCF Model'!I45/(1+$B12)^('DCF Model'!C19+6)+'DCF Model'!J45/(1+$B12)^('DCF Model'!C19+7)+'DCF Model'!J45*(1+I$6)/($B12-I$6)/(1+$B12)^('DCF Model'!C19+7)-'DCF Model'!C16)*1000000/'DCF Model'!C15,0),"") -> 42
B13: =$C$3+0.015 -> 0.14425 | C13: =IFERROR(ROUND(('DCF Model'!C45/(1+$B13)^('DCF Model'!C19+0)+'DCF Model'!D45/(1+$B13)^('DCF Model'!C19+1)+'DCF Model'!E45/(1+$B13)^('DCF Model'!C19+2)+'DCF Model'!F45/(1+$B13)^('DCF Model'!C19+3)+'DCF Model'!G45/(1+$B13)^('DCF Model'!C19+4)+'DCF Model'!H45/(1+$B13)^('DCF Model'!C19+5)+'DCF Model'!I45/(1+$B13)^('DCF Model'!C19+6)+'DCF Model'!J45/(1+$B13)^('DCF Model'!C19+7)+'DCF Model'!J45*(1+C$6)/($B13-C$6)/(1+$B13)^('DCF Model'!C19+7)-'DCF Model'!C16)*1000000/'DCF Model'!C15,0),"") -> -4 | D13: =IFERROR(ROUND(('DCF Model'!C45/(1+$B13)^('DCF Model'!C19+0)+'DCF Model'!D45/(1+$B13)^('DCF Model'!C19+1)+'DCF Model'!E45/(1+$B13)^('DCF Model'!C19+2)+'DCF Model'!F45/(1+$B13)^('DCF Model'!C19+3)+'DCF Model'!G45/(1+$B13)^('DCF Model'!C19+4)+'DCF Model'!H45/(1+$B13)^('DCF Model'!C19+5)+'DCF Model'!I45/(1+$B13)^('DCF Model'!C19+6)+'DCF Model'!J45/(1+$B13)^('DCF Model'!C19+7)+'DCF Model'!J45*(1+D$6)/($B13-D$6)/(1+$B13)^('DCF Model'!C19+7)-'DCF Model'!C16)*1000000/'DCF Model'!C15,0),"") -> 1 | E13: =IFERROR(ROUND(('DCF Model'!C45/(1+$B13)^('DCF Model'!C19+0)+'DCF Model'!D45/(1+$B13)^('DCF Model'!C19+1)+'DCF Model'!E45/(1+$B13)^('DCF Model'!C19+2)+'DCF Model'!F45/(1+$B13)^('DCF Model'!C19+3)+'DCF Model'!G45/(1+$B13)^('DCF Model'!C19+4)+'DCF Model'!H45/(1+$B13)^('DCF Model'!C19+5)+'DCF Model'!I45/(1+$B13)^('DCF Model'!C19+6)+'DCF Model'!J45/(1+$B13)^('DCF Model'!C19+7)+'DCF Model'!J45*(1+E$6)/($B13-E$6)/(1+$B13)^('DCF Model'!C19+7)-'DCF Model'!C16)*1000000/'DCF Model'!C15,0),"") -> 5 | F13: =IFERROR(ROUND(('DCF Model'!C45/(1+$B13)^('DCF Model'!C19+0)+'DCF Model'!D45/(1+$B13)^('DCF Model'!C19+1)+'DCF Model'!E45/(1+$B13)^('DCF Model'!C19+2)+'DCF Model'!F45/(1+$B13)^('DCF Model'!C19+3)+'DCF Model'!G45/(1+$B13)^('DCF Model'!C19+4)+'DCF Model'!H45/(1+$B13)^('DCF Model'!C19+5)+'DCF Model'!I45/(1+$B13)^('DCF Model'!C19+6)+'DCF Model'!J45/(1+$B13)^('DCF Model'!C19+7)+'DCF Model'!J45*(1+F$6)/($B13-F$6)/(1+$B13)^('DCF Model'!C19+7)-'DCF Model'!C16)*1000000/'DCF Model'!C15,0),"") -> 10 | G13: =IFERROR(ROUND(('DCF Model'!C45/(1+$B13)^('DCF Model'!C19+0)+'DCF Model'!D45/(1+$B13)^('DCF Model'!C19+1)+'DCF Model'!E45/(1+$B13)^('DCF Model'!C19+2)+'DCF Model'!F45/(1+$B13)^('DCF Model'!C19+3)+'DCF Model'!G45/(1+$B13)^('DCF Model'!C19+4)+'DCF Model'!H45/(1+$B13)^('DCF Model'!C19+5)+'DCF Model'!I45/(1+$B13)^('DCF Model'!C19+6)+'DCF Model'!J45/(1+$B13)^('DCF Model'!C19+7)+'DCF Model'!J45*(1+G$6)/($B13-G$6)/(1+$B13)^('DCF Model'!C19+7)-'DCF Model'!C16)*1000000/'DCF Model'!C15,0),"") -> 15 | H13: =IFERROR(ROUND(('DCF Model'!C45/(1+$B13)^('DCF Model'!C19+0)+'DCF Model'!D45/(1+$B13)^('DCF Model'!C19+1)+'DCF Model'!E45/(1+$B13)^('DCF Model'!C19+2)+'DCF Model'!F45/(1+$B13)^('DCF Model'!C19+3)+'DCF Model'!G45/(1+$B13)^('DCF Model'!C19+4)+'DCF Model'!H45/(1+$B13)^('DCF Model'!C19+5)+'DCF Model'!I45/(1+$B13)^('DCF Model'!C19+6)+'DCF Model'!J45/(1+$B13)^('DCF Model'!C19+7)+'DCF Model'!J45*(1+H$6)/($B13-H$6)/(1+$B13)^('DCF Model'!C19+7)-'DCF Model'!C16)*1000000/'DCF Model'!C15,0),"") -> 20 | I13: =IFERROR(ROUND(('DCF Model'!C45/(1+$B13)^('DCF Model'!C19+0)+'DCF Model'!D45/(1+$B13)^('DCF Model'!C19+1)+'DCF Model'!E45/(1+$B13)^('DCF Model'!C19+2)+'DCF Model'!F45/(1+$B13)^('DCF Model'!C19+3)+'DCF Model'!G45/(1+$B13)^('DCF Model'!C19+4)+'DCF Model'!H45/(1+$B13)^('DCF Model'!C19+5)+'DCF Model'!I45/(1+$B13)^('DCF Model'!C19+6)+'DCF Model'!J45/(1+$B13)^('DCF Model'!C19+7)+'DCF Model'!J45*(1+I$6)/($B13-I$6)/(1+$B13)^('DCF Model'!C19+7)-'DCF Model'!C16)*1000000/'DCF Model'!C15,0),"") -> 26
B16: Table 2: WACC vs Exit Multiple (Exit Multiple - Implied Share Price, JPY)
B17: WACC \ Exit Multiple | C17: =$I$3-3 -> -1 | D17: =$I$3-2 -> 0 | E17: =$I$3-1 -> 1 | F17: =$I$3 -> 2 | G17: =$I$3+1 -> 3 | H17: =$I$3+2 -> 4 | I17: =$I$3+3 -> 5
B18: =$C$3-0.015 -> 0.11425 | C18: =IFERROR(ROUND(('DCF Model'!C45/(1+$B18)^('DCF Model'!C19+0)+'DCF Model'!D45/(1+$B18)^('DCF Model'!C19+1)+'DCF Model'!E45/(1+$B18)^('DCF Model'!C19+2)+'DCF Model'!F45/(1+$B18)^('DCF Model'!C19+3)+'DCF Model'!G45/(1+$B18)^('DCF Model'!C19+4)+'DCF Model'!H45/(1+$B18)^('DCF Model'!C19+5)+'DCF Model'!I45/(1+$B18)^('DCF Model'!C19+6)+'DCF Model'!J45/(1+$B18)^('DCF Model'!C19+7)+'DCF Model'!J33*C$17/(1+$B18)^('DCF Model'!C19+7)-'DCF Model'!C16)*1000000/'DCF Model'!C15,0),"") -> -890 | D18: =IFERROR(ROUND(('DCF Model'!C45/(1+$B18)^('DCF Model'!C19+0)+'DCF Model'!D45/(1+$B18)^('DCF Model'!C19+1)+'DCF Model'!E45/(1+$B18)^('DCF Model'!C19+2)+'DCF Model'!F45/(1+$B18)^('DCF Model'!C19+3)+'DCF Model'!G45/(1+$B18)^('DCF Model'!C19+4)+'DCF Model'!H45/(1+$B18)^('DCF Model'!C19+5)+'DCF Model'!I45/(1+$B18)^('DCF Model'!C19+6)+'DCF Model'!J45/(1+$B18)^('DCF Model'!C19+7)+'DCF Model'!J33*D$17/(1+$B18)^('DCF Model'!C19+7)-'DCF Model'!C16)*1000000/'DCF Model'!C15,0),"") -> -220 | E18: =IFERROR(ROUND(('DCF Model'!C45/(1+$B18)^('DCF Model'!C19+0)+'DCF Model'!D45/(1+$B18)^('DCF Model'!C19+1)+'DCF Model'!E45/(1+$B18)^('DCF Model'!C19+2)+'DCF Model'!F45/(1+$B18)^('DCF Model'!C19+3)+'DCF Model'!G45/(1+$B18)^('DCF Model'!C19+4)+'DCF Model'!H45/(1+$B18)^('DCF Model'!C19+5)+'DCF Model'!I45/(1+$B18)^('DCF Model'!C19+6)+'DCF Model'!J45/(1+$B18)^('DCF Model'!C19+7)+'DCF Model'!J33*E$17/(1+$B18)^('DCF Model'!C19+7)-'DCF Model'!C16)*1000000/'DCF Model'!C15,0),"") -> 450 | F18: =IFERROR(ROUND(('DCF Model'!C45/(1+$B18)^('DCF Model'!C19+0)+'DCF Model'!D45/(1+$B18)^('DCF Model'!C19+1)+'DCF Model'!E45/(1+$B18)^('DCF Model'!C19+2)+'DCF Model'!F45/(1+$B18)^('DCF Model'!C19+3)+'DCF Model'!G45/(1+$B18)^('DCF Model'!C19+4)+'DCF Model'!H45/(1+$B18)^('DCF Model'!C19+5)+'DCF Model'!I45/(1+$B18)^('DCF Model'!C19+6)+'DCF Model'!J45/(1+$B18)^('DCF Model'!C19+7)+'DCF Model'!J33*F$17/(1+$B18)^('DCF Model'!C19+7)-'DCF Model'!C16)*1000000/'DCF Model'!C15,0),"") -> 1119 | G18: =IFERROR(ROUND(('DCF Model'!C45/(1+$B18)^('DCF Model'!C19+0)+'DCF Model'!D45/(1+$B18)^('DCF Model'!C19+1)+'DCF Model'!E45/(1+$B18)^('DCF Model'!C19+2)+'DCF Model'!F45/(1+$B18)^('DCF Model'!C19+3)+'DCF Model'!G45/(1+$B18)^('DCF Model'!C19+4)+'DCF Model'!H45/(1+$B18)^('DCF Model'!C19+5)+'DCF Model'!I45/(1+$B18)^('DCF Model'!C19+6)+'DCF Model'!J45/(1+$B18)^('DCF Model'!C19+7)+'DCF Model'!J33*G$17/(1+$B18)^('DCF Model'!C19+7)-'DCF Model'!C16)*1000000/'DCF Model'!C15,0),"") -> 1789 | H18: =IFERROR(ROUND(('DCF Model'!C45/(1+$B18)^('DCF Model'!C19+0)+'DCF Model'!D45/(1+$B18)^('DCF Model'!C19+1)+'DCF Model'!E45/(1+$B18)^('DCF Model'!C19+2)+'DCF Model'!F45/(1+$B18)^('DCF Model'!C19+3)+'DCF Model'!G45/(1+$B18)^('DCF Model'!C19+4)+'DCF Model'!H45/(1+$B18)^('DCF Model'!C19+5)+'DCF Model'!I45/(1+$B18)^('DCF Model'!C19+6)+'DCF Model'!J45/(1+$B18)^('DCF Model'!C19+7)+'DCF Model'!J33*H$17/(1+$B18)^('DCF Model'!C19+7)-'DCF Model'!C16)*1000000/'DCF Model'!C15,0),"") -> 2459 | I18: =IFERROR(ROUND(('DCF Model'!C45/(1+$B18)^('DCF Model'!C19+0)+'DCF Model'!D45/(1+$B18)^('DCF Model'!C19+1)+'DCF Model'!E45/(1+$B18)^('DCF Model'!C19+2)+'DCF Model'!F45/(1+$B18)^('DCF Model'!C19+3)+'DCF Model'!G45/(1+$B18)^('DCF Model'!C19+4)+'DCF Model'!H45/(1+$B18)^('DCF Model'!C19+5)+'DCF Model'!I45/(1+$B18)^('DCF Model'!C19+6)+'DCF Model'!J45/(1+$B18)^('DCF Model'!C19+7)+'DCF Model'!J33*I$17/(1+$B18)^('DCF Model'!C19+7)-'DCF Model'!C16)*1000000/'DCF Model'!C15,0),"") -> 3129
