Workbook

Sheet Executive Summary
B1: DISCLAIMER: This is a sample analysis for demonstration purposes only. It does not constitute investment advice.
B3: Nitto Boseki (3110.T)
B4: Equity Research Report
B6: Company | C6: Nitto Boseki
B7: Ticker | C7: 3110.T (TSE Prime)
B8: Sector | C8: Glass Fibre / Electronic Materials
B9: Current Price | C9: 3065
B10: Target Price (Mid) | C10: =ROUND(AVERAGE(C16:C19),0) -> 1466
B11: Recommendation | C11: =IF(C12>0.15,"BUY",IF(C12>0.05,"HOLD","SELL")) -> SELL
B12: Upside / Downside | C12: =(C10-C9)/C9 -> -0.52169657
B14: Valuation Summary
B15: Methodology | C15: Implied Value (JPY) | D15: vs Current Price
B16: DCF - Perpetuity Growth | C16: =IF('DCF Model'!C53<'DCF Model'!C16,"INVALID (EV < net debt)",'DCF Model'!C55) -> 869 | D16: =IF(ISNUMBER(C16),(C16-C9)/C9,"N/A") -> -0.71647635
B17: DCF - Exit Multiple | C17: ='DCF Model'!C64 -> 1578 | D17: =(C17-C9)/C9 -> -0.48515498
B18: Comps - EV/EBITDA Median | C18: ='Comps Analysis'!C27 -> 1110 | D18: =IF(ISNUMBER(C18),(C18-C9)/C9,"N/A") -> -0.63784666
B19: Comps - PER Median | C19: ='Comps Analysis'!C28 -> 2305 | D19: =IF(ISNUMBER(C19),(C19-C9)/C9,"N/A") -> -0.24796085
B21: Integrated Valuation Range | C21: =MIN(C16:C19)&" - "&MAX(C16:C19) -> 869 - 2305
B23: Key Investment Thesis
B24: Electronic materials (low-dielectric glass cloth for AI servers) now generate ~84% of segment profit; consolidated operating margin rose from 9% in FY3/24 to 23% in Q1 FY3/27.
B25: Management guides FY3/27 operating profit of JPY30bn (+44%), and Q1 already delivered 26% of that with the full ramp of new capacity still ahead.
B26: ="At "&TEXT(C9,"#,##0")&" the stock trades at "&TEXT('Comps Analysis'!L5,"0.0""x""")&" PER and "&TEXT('Comps Analysis'!M5,"0.00""x""")&" PBR; our target of "&TEXT(C10,"#,##0")&" implies "&TEXT(C12,"+0.0%;-0.0%")&" with WACC of "&TEXT('DCF Model'!C26,"0.00%")&"." -> At 3,065 the stock trades at 32.6x PER and 3.23x PBR; our target of 1,466 implies -52.2% with WACC of 10.94%.
B28: Key Risks
B29: Capex is running at ~17% of sales to add capacity into a demand boom; if AI-server investment pauses, utilisation and margins fall fast.
B30: Inventory equals ~50% of annual sales (about 300 days of COGS), so a demand air-pocket would hit free cash flow before the P&L.
B31: Competitors are entering low-dielectric glass; our Base case already assumes margins peak in year 2 and fade to ~18% by year 5.

Sheet Financial Statements
B2: Nitto Boseki - Historical Financials (JPY mn)
C4: FY2024/3 | D4: FY2025/3 | E4: FY2026/3
B5: Income Statement
B6: Revenue | C6: 93253 | D6: 109035 | E6: 118229
B7: COGS | C7: 62638 | D7: 68657 | E7: 70652
B8: Gross Profit | C8: =C6-C7 -> 30615 | D8: =D6-D7 -> 40378 | E8: =E6-E7 -> 47577
B9: Gross Margin | C9: =C8/C6 -> 0.32830043 | D9: =D8/D6 -> 0.37032146 | E9: =E8/E6 -> 0.40241396
B10: SGA | C10: 22226 | D10: 23933 | E10: 26757
B11: Operating Income | C11: 8387 | D11: 16445 | E11: 20819
B12: Net Income | C12: 7296 | D12: 12837 | E12: 41770
B13: Operating Margin | C13: =C11/C6 -> 0.089938125 | D13: =D11/D6 -> 0.15082313 | E13: =E11/E6 -> 0.17609047
B14: Net Margin | C14: =C12/C6 -> 0.07823877 | D14: =D12/D6 -> 0.11773284 | E14: =E12/E6 -> 0.35329741
B15: Revenue Growth (YoY) | C15: n/a | D15: =(D6-C6)/C6 -> 0.16923852 | E15: =(E6-D6)/D6 -> 0.084321548
B16: Operating Income Growth (YoY) | C16: n/a | D16: =(D11-C11)/C11 -> 0.96077262 | E16: =(E11-D11)/D11 -> 0.2659775
B18: Cash Flow Statement
B19: Operating Cash Flow | C19: 5057 | D19: 19121 | E19: 17296
B20: Capex | C20: 6949 | D20: 13138 | E20: 20518
B21: Free Cash Flow | C21: =C19-C20 -> -1892 | D21: =D19-D20 -> 5983 | E21: =E19-E20 -> -3222
B22: FCF Margin | C22: =C21/C6 -> -0.020288892 | D22: =D21/D6 -> 0.054872289 | E22: =E21/E6 -> -0.027252197
B23: Capex / Revenue | C23: =C20/C6 -> 0.07451771 | D23: =D20/D6 -> 0.12049342 | E23: =E20/E6 -> 0.17354456
B25: Balance Sheet Highlights
B26: Cash & Deposits | C26: 23664 | D26: 28546 | E26: 62014
B27: Short-term Debt | C27: 53137 | D27: 52746 | E27: 50684
B28: Net Debt (Cash) | C28: =C27-C26 -> 29473 | D28: =D27-D26 -> 24200 | E28: =E27-E26 -> -11330
B30: Note: OCF / Cash / Debt coverage OCF 3/3, Cash 3/3, Debt 3/3 — blank cells are years with no year-key match in the source data (verify against 決算短信 or set hist_ocf / hist_cash / hist_debt in overrides).

Sheet DCF Model
B2: DCF Valuation Model - Nitto Boseki
B4: Assumptions
B5: Capex / Revenue | C5: 0.085
B6: Effective Tax Rate | C6: 0.28
B7: Risk-Free Rate | C7: 0.016
B8: Beta | C8: 1.55
B9: Equity Risk Premium | C9: 0.055
B10: Size Premium | C10: 0.01
B11: After-tax Cost of Debt | C11: 0.0108
B12: D/E Ratio | C12: 0.0187
B13: Terminal Growth Rate | C13: 0.01
B14: Exit Multiple (EV/EBITDA) | C14: 9
B15: Fully Diluted Shares | C15: 182886560
B16: Net Debt (JPY mn) | C16: 10478
... B20: LTM Revenue (JPY mn) (override) | C20: 124031
B22: WACC Calculation
B23: Cost of Equity (Ke) | C23: =C7+C8*C9+C10 -> 0.11125
B24: Weight of Equity | C24: =1/(1+C12) -> 0.98164327
B25: Weight of Debt | C25: =C12/(1+C12) -> 0.018356729
B26: WACC | C26: =C23*C24+C11*C25 -> 0.10940607
B27: Active Scenario | C27: Base | D27: =MATCH(C27,B69:B73,0) -> 1
B28: Projected Free Cash Flow
C29: FY2027(E) | D29: FY2028(E) | E29: FY2029(E) | F29: FY2030(E) | G29: FY2031(E)
B30: Revenue Growth (YoY) | C30: =CHOOSE($D$27,C69,C70,C71,C72,C73) -> 0.17 | D30: =CHOOSE($D$27,D69,D70,D71,D72,D73) -> 0.12 | E30: =CHOOSE($D$27,E69,E70,E71,E72,E73) -> 0.06 | F30: =CHOOSE($D$27,F69,F70,F71,F72,F73) -> 0.02 | G30: =CHOOSE($D$27,G69,G70,G71,G72,G73) -> 0.02
B31: COGS % of Revenue | C31: =CHOOSE($D$27,C76,C77,C78,C79,C80) -> 0.575 | D31: =CHOOSE($D$27,D76,D77,D78,D79,D80) -> 0.569 | E31: =CHOOSE($D$27,E76,E77,E78,E79,E80) -> 0.574 | F31: =CHOOSE($D$27,F76,F77,F78,F79,F80) -> 0.585 | G31: =CHOOSE($D$27,G76,G77,G78,G79,G80) -> 0.592
B32: SGA % of Revenue | C32: =CHOOSE($D$27,C83,C84,C85,C86,C87) -> 0.22 | D32: =CHOOSE($D$27,D83,D84,D85,D86,D87) -> 0.216 | E32: =CHOOSE($D$27,E83,E84,E85,E86,E87) -> 0.216 | F32: =CHOOSE($D$27,F83,F84,F85,F86,F87) -> 0.22 | G32: =CHOOSE($D$27,G83,G84,G85,G86,G87) -> 0.223
B33: Revenue | C33: =C17*(1+C30) -> 138327.93 | D33: =C33*(1+D30) -> 154927.28 | E33: =D33*(1+E30) -> 164222.92 | F33: =E33*(1+F30) -> 167507.38 | G33: =F33*(1+G30) -> 170857.52
B34: COGS | C34: =C33*C31 -> 79538.56 | D34: =D33*D31 -> 88153.623 | E34: =E33*E31 -> 94263.955 | F34: =F33*F31 -> 97991.815 | G34: =G33*G31 -> 101147.65
B35: Gross Profit | C35: =C33-C34 -> 58789.37 | D35: =D33-D34 -> 66773.658 | E35: =E33-E34 -> 69958.963 | F35: =F33-F34 -> 69515.561 | G35: =G33-G34 -> 69709.87
B36: Gross Margin | C36: =C35/C33 -> 0.425 | D36: =D35/D33 -> 0.431 | E36: =E35/E33 -> 0.426 | F36: =F35/F33 -> 0.415 | G36: =G35/G33 -> 0.408
B37: SGA Expense | C37: =C33*C32 -> 30432.145 | D37: =D33*D32 -> 33464.293 | E37: =E33*E32 -> 35472.15 | F37: =F33*F32 -> 36851.623 | G37: =G33*G32 -> 38101.228
B38: Implied Operating Margin | C38: =(C35-C37)/C33 -> 0.205 | D38: =(D35-D37)/D33 -> 0.215 | E38: =(E35-E37)/E33 -> 0.21 | F38: =(F35-F37)/F33 -> 0.195 | G38: =(G35-G37)/G33 -> 0.185
B39: Operating Income (EBIT) | C39: =C35-C37 -> 28357.226 | D39: =D35-D37 -> 33309.366 | E39: =E35-E37 -> 34486.813 | F39: =F35-F37 -> 32663.938 | G39: =G35-G37 -> 31608.642
B40: Less: Tax | C40: =MAX(0,C39*C6) -> 7940.0232 | D40: =MAX(0,D39*C6) -> 9326.6224 | E40: =MAX(0,E39*C6) -> 9656.3076 | F40: =MAX(0,F39*C6) -> 9145.9028 | G40: =MAX(0,G39*C6) -> 8850.4198
B41: NOPAT | C41: =C39-C40 -> 20417.202 | D41: =D39-D40 -> 23982.743 | E41: =E39-E40 -> 24830.505 | F41: =F39-F40 -> 23518.036 | G41: =G39-G40 -> 22758.222
B42: Plus: D&A | C42: =C33*C18 -> 11481.218 | D42: =D33*C18 -> 12858.964 | E42: =E33*C18 -> 13630.502 | F42: =F33*C18 -> 13903.112 | G42: =G33*C18 -> 14181.175
B43: Less: Capex | C43: =C33*C5 -> 11757.874 | D43: =D33*C5 -> 13168.819 | E43: =E33*C5 -> 13958.948 | F43: =F33*C5 -> 14238.127 | G43: =G33*C5 -> 14522.89
B44: Change in NWC | C44: ='NWC Schedule'!D19 -> 12568.11 | D44: ='NWC Schedule'!E19 -> 11279.191 | E44: ='NWC Schedule'!F19 -> 7246.4201 | F44: ='NWC Schedule'!G19 -> 3695.1506 | G44: ='NWC Schedule'!H19 -> 3301.3914
B45: Unlevered Free Cash Flow | C45: =C41+C42-C43-C44 -> 7572.437 | D45: =D41+D42-D43-D44 -> 12393.697 | E45: =E41+E42-E43-E44 -> 17255.639 | F45: =F41+F42-F43-F44 -> 19487.87 | G45: =G41+G42-G43-G44 -> 19115.116
B46: Discount Factor | C46: =1/(1+C26)^(C19+0) -> 0.90138321 | D46: =1/(1+C26)^(C19+1) -> 0.81249169 | E46: =1/(1+C26)^(C19+2) -> 0.73236637 | F46: =1/(1+C26)^(C19+3) -> 0.66014274 | G46: =1/(1+C26)^(C19+4) -> 0.59504159
...

Sheet NWC Schedule
B2: NWC Schedule - Nitto Boseki
B4: Working Capital Drivers (Days) | C4: Base Year | D4: FY2027(E) | E4: FY2028(E) | F4: FY2029(E) | G4: FY2030(E) | H4: FY2031(E)
B5: DSO (Days Sales Outstanding) | C5: =C12/C9*365 -> 111.03837 | D5: =CHOOSE('DCF Model'!$D$27,D25,D26,D27,D28,D29) -> 111 | E5: =CHOOSE('DCF Model'!$D$27,E25,E26,E27,E28,E29) -> 111 | F5: =CHOOSE('DCF Model'!$D$27,F25,F26,F27,F28,F29) -> 111 | G5: =CHOOSE('DCF Model'!$D$27,G25,G26,G27,G28,G29) -> 111 | H5: =CHOOSE('DCF Model'!$D$27,H25,H26,H27,H28,H29) -> 111
B6: DIH (Days Inventory Held) | C6: =C13/C10*365 -> 305.19646 | D6: =CHOOSE('DCF Model'!$D$27,D32,D33,D34,D35,D36) -> 305 | E6: =CHOOSE('DCF Model'!$D$27,E32,E33,E34,E35,E36) -> 305 | F6: =CHOOSE('DCF Model'!$D$27,F32,F33,F34,F35,F36) -> 305 | G6: =CHOOSE('DCF Model'!$D$27,G32,G33,G34,G35,G36) -> 305 | H6: =CHOOSE('DCF Model'!$D$27,H32,H33,H34,H35,H36) -> 305
B7: DPO (Days Payable Outstanding) | C7: =C15/C10*365 -> 41.406825 | D7: =CHOOSE('DCF Model'!$D$27,D39,D40,D41,D42,D43) -> 41 | E7: =CHOOSE('DCF Model'!$D$27,E39,E40,E41,E42,E43) -> 41 | F7: =CHOOSE('DCF Model'!$D$27,F39,F40,F41,F42,F43) -> 41 | G7: =CHOOSE('DCF Model'!$D$27,G39,G40,G41,G42,G43) -> 41 | H7: =CHOOSE('DCF Model'!$D$27,H39,H40,H41,H42,H43) -> 41
B8: P&L Reference (JPY mn)
B9: Revenue | C9: 118229 | D9: ='DCF Model'!C33 -> 138327.93 | E9: ='DCF Model'!D33 -> 154927.28 | F9: ='DCF Model'!E33 -> 164222.92 | G9: ='DCF Model'!F33 -> 167507.38 | H9: ='DCF Model'!G33 -> 170857.52
B10: COGS | C10: 70652 | D10: ='DCF Model'!C34 -> 79538.56 | E10: ='DCF Model'!D34 -> 88153.623 | F10: ='DCF Model'!E34 -> 94263.955 | G10: ='DCF Model'!F34 -> 97991.815 | H10: ='DCF Model'!G34 -> 101147.65
B11: Working Capital Items (JPY mn)
B12: Accounts Receivable | C12: 35967 | D12: =D9*D5/365 -> 42066.85 | E12: =E9*E5/365 -> 47114.872 | F12: =F9*F5/365 -> 49941.764 | G12: =G9*G5/365 -> 50940.6 | H12: =H9*H5/365 -> 51959.412
B13: Inventory | C13: 59076 | D13: =D10*D6/365 -> 66463.728 | E13: =E10*E6/365 -> 73662.617 | F13: =F10*F6/365 -> 78768.511 | G13: =G10*G6/365 -> 81883.572 | H13: =H10*H6/365 -> 84520.643
B14: Current Assets (AR + Inv) | C14: =C12+C13 -> 95043 | D14: =D12+D13 -> 108530.58 | E14: =E12+E13 -> 120777.49 | F14: =F12+F13 -> 128710.27 | G14: =G12+G13 -> 132824.17 | H14: =H12+H13 -> 136480.05
B15: Accounts Payable | C15: 8015 | D15: =D10*D7/365 -> 8934.4684 | E15: =E10*E7/365 -> 9902.1878 | F15: =F10*F7/365 -> 10588.554 | G15: =G10*G7/365 -> 11007.3 | H15: =H10*H7/365 -> 11361.791
B16: Current Liabilities (AP) | C16: =C15 -> 8015 | D16: =D15 -> 8934.4684 | E16: =E15 -> 9902.1878 | F16: =F15 -> 10588.554 | G16: =G15 -> 11007.3 | H16: =H15 -> 11361.791
B17: Net Working Capital (JPY mn)
B18: Net Working Capital | C18: =C14-C16 -> 87028 | D18: =D14-D16 -> 99596.11 | E18: =E14-E16 -> 110875.3 | F18: =F14-F16 -> 118121.72 | G18: =G14-G16 -> 121816.87 | H18: =H14-H16 -> 125118.26
B19: Change in NWC | C19: n/a | D19: =D18-C18 -> 12568.11 | E19: =E18-D18 -> 11279.191 | F19: =F18-E18 -> 7246.4201 | G19: =G18-F18 -> 3695.1506 | H19: =H18-G18 -> 3301.3914
B22: Scenario Input Matrix (Working Capital Days)
D23: FY2027(E) | E23: FY2028(E) | F23: FY2029(E) | G23: FY2030(E) | H23: FY2031(E)
B24: DSO (Days)
B25: Base | D25: 111 | E25: 111 | F25: 111 | G25: 111 | H25: 111
B26: Upside | D26: 110 | E26: 109 | F26: 108 | G26: 108 | H26: 108
B27: Management | D27: 111 | E27: 111 | F27: 111 | G27: 111 | H27: 111
B28: Downside 1 | D28: 113 | E28: 116 | F28: 118 | G28: 116 | H28: 114
B29: Downside 2 | D29: 115 | E29: 120 | F29: 122 | G29: 120 | H29: 118
B31: DIH (Days)
B32: Base | D32: 305 | E32: 305 | F32: 305 | G32: 305 | H32: 305
B33: Upside | D33: 300 | E33: 295 | F33: 290 | G33: 288 | H33: 288
B34: Management | D34: 305 | E34: 305 | F34: 305 | G34: 305 | H34: 305
B35: Downside 1 | D35: 312 | E35: 330 | F35: 340 | G35: 332 | H35: 325
B36: Downside 2 | D36: 318 | E36: 350 | F36: 365 | G36: 355 | H36: 345
B38: DPO (Days)
B39: Base | D39: 41 | E39: 41 | F39: 41 | G39: 41 | H39: 41
B40: Upside | D40: 42 | E40: 42 | F40: 43 | G40: 43 | H40: 43
B41: Management | D41: 41 | E41: 41 | F41: 41 | G41: 41 | H41: 41
B42: Downside 1 | D42: 40 | E42: 39 | F42: 39 | G42: 40 | H42: 40
B43: Downside 2 | D43: 39 | E43: 38 | F43: 38 | G43: 39 | H43: 39

Sheet Comps Analysis
B2: Comparable Company Analysis
B3: Peer prices as of 2026-08-22 (Mkt Cap / EV of peer rows are static CSV values; the subject row is live-linked to Executive Summary)
B4: Company | C4: Ticker | D4: Mkt Cap (JPY mn) | E4: EV (JPY mn) | F4: Revenue (JPY mn) | G4: EBITDA (JPY mn) | H4: Op Income (JPY mn) | I4: Net Income (JPY mn) | J4: EV/EBITDA | K4: EV/Revenue | L4: PER | M4: PBR | N4: Op Margin | O4: ROE | P4: Book Value (JPY mn) | Q4: Note
B5: Nitto Boseki | C5: 3110.T | D5: ='Executive Summary'!C9*C23/1000000 -> 560547.31 | E5: =D5+C24 -> 571025.31 | F5: 118229 | G5: 30120 | H5: 20819 | I5: 17171 | J5: =IFERROR(E5/G5,"") -> 18.958344 | K5: =IFERROR(E5/F5,"") -> 4.8298244 | L5: =IFERROR(D5/I5,"") -> 32.645001 | M5: =IFERROR(D5/P5,"") -> 3.2290335 | N5: =IFERROR(H5/F5,"") -> 0.17609047 | O5: =IFERROR(I5/P5,"") -> 0.098913569 | P5: 173596
B6: AGC | C6: 5201.T | D6: 1232468 | E6: 1784260 | F6: 2058832 | G6: 305264 | H6: 125468 | I6: 69162 | J6: =IFERROR(E6/G6,"") -> 5.8449735 | K6: =IFERROR(E6/F6,"") -> 0.86663701 | L6: =IFERROR(D6/I6,"") -> 17.820017 | M6: =IFERROR(D6/P6,"") -> 0.82987437 | N6: =IFERROR(H6/F6,"") -> 0.060941349 | O6: =IFERROR(I6/P6,"") -> 0.046569786 | P6: 1485126
B7: Nippon Electric Glass | C7: 5214.T | D7: 353313 | E7: 330001 | F7: 311402 | G7: 58337 | H7: 34131 | I7: 29616 | J7: =IFERROR(E7/G7,"") -> 5.6568044 | K7: =IFERROR(E7/F7,"") -> 1.0597267 | L7: =IFERROR(D7/I7,"") -> 11.929801 | M7: =IFERROR(D7/P7,"") -> 0.71757621 | N7: =IFERROR(H7/F7,"") -> 0.10960431 | O7: =IFERROR(I7/P7,"") -> 0.060149887 | P7: 492370
B8: Ibiden | C8: 4062.T | D8: 5394226 | E8: 5291082 | F8: 416201 | G8: 128264 | H8: 62028 | I8: 63713 | J8: =IFERROR(E8/G8,"") -> 41.251497 | K8: =IFERROR(E8/F8,"") -> 12.712805 | L8: =IFERROR(D8/I8,"") -> 84.664448 | M8: =IFERROR(D8/P8,"") -> 9.8064177 | N8: =IFERROR(H8/F8,"") -> 0.14903376 | O8: =IFERROR(I8/P8,"") -> 0.11582687 | P8: 550071
B9: Tokyo Ohka Kogyo | C9: 4186.T | D9: 1043311 | E9: 998832 | F9: 237029 | G9: 56193 | H9: 47386 | I9: 33345 | J9: =IFERROR(E9/G9,"") -> 17.775025 | K9: =IFERROR(E9/F9,"") -> 4.2139654 | L9: =IFERROR(D9/I9,"") -> 31.288379 | M9: =IFERROR(D9/P9,"") -> 4.5816525 | N9: =IFERROR(H9/F9,"") -> 0.19991647 | O9: =IFERROR(I9/P9,"") -> 0.14643304 | P9: 227715
B10: Zeon | C10: 4205.T | D10: 459134 | E10: 446416 | F10: 411966 | G10: 53606 | H10: 36376 | I10: 36226 | J10: =IFERROR(E10/G10,"") -> 8.3277245 | K10: =IFERROR(E10/F10,"") -> 1.0836234 | L10: =IFERROR(D10/I10,"") -> 12.674157 | M10: =IFERROR(D10/P10,"") -> 1.2160493 | N10: =IFERROR(H10/F10,"") -> 0.088298549 | O10: =IFERROR(I10/P10,"") -> 0.095947156 | P10: 377562
B11: Kuraray | C11: 3405.T | D11: 554085 | E11: 734902 | F11: 808447 | G11: 143585 | H11: 58883 | I11: 7468 | J11: =IFERROR(E11/G11,"") -> 5.1182366 | K11: =IFERROR(E11/F11,"") -> 0.90902929 | L11: =IFERROR(D11/I11,"") -> 74.194563 | M11: =IFERROR(D11/P11,"") -> 0.74589283 | N11: =IFERROR(H11/F11,"") -> 0.072834707 | O11: =IFERROR(I11/P11,"") -> 0.010053201 | P11: 742848
B14: Statistics
B15: 25th Percentile | D15: =PERCENTILE(J6:J11,0.25) -> 5.7038467 | E15: =PERCENTILE(K6:K11,0.25) -> 0.94670363 | F15: =PERCENTILE(L6:L11,0.25) -> 13.960622 | G15: =PERCENTILE(M6:M11,0.25) -> 0.76688822 | H15: =PERCENTILE(N6:N11,0.25) -> 0.076700667 | I15: =PERCENTILE(O6:O11,0.25) -> 0.049964811
B16: Median (50th) | D16: =MEDIAN(J6:J11) -> 7.086349 | E16: =MEDIAN(K6:K11) -> 1.071675 | F16: =MEDIAN(L6:L11) -> 24.554198 | G16: =MEDIAN(M6:M11) -> 1.0229618 | H16: =MEDIAN(N6:N11) -> 0.098951427 | I16: =MEDIAN(O6:O11) -> 0.078048521
B17: 75th Percentile | D17: =PERCENTILE(J6:J11,0.75) -> 15.4132 | E17: =PERCENTILE(K6:K11,0.75) -> 3.4313799 | F17: =PERCENTILE(L6:L11,0.75) -> 63.468017 | G17: =PERCENTILE(M6:M11,0.75) -> 3.7402517 | H17: =PERCENTILE(N6:N11,0.75) -> 0.1391764 | I17: =PERCENTILE(O6:O11,0.75) -> 0.11085694
B19: Implied Valuation for Nitto Boseki
B20: Nitto Boseki Financials
B21: EBITDA (JPY mn) | C21: 30120
B22: Net Income (JPY mn) | C22: 17171
B23: Shares Outstanding | C23: 182886560
B24: Net Debt (JPY mn) | C24: 10478
B26: Implied Share Price (Median Multiples)
B27: Via EV/EBITDA (Median) | C27: =ROUND((C21*D16-C24)*1000000/C23,0) -> 1110
B28: Via PER (Median) | C28: =ROUND(C22*F16*1000000/C23,0) -> 2305

Sheet Sensitivity Analysis
B2: Sensitivity Analysis
B3: Current WACC: | C3: ='DCF Model'!C26 -> 0.10940607 | E3: Terminal g: | F3: ='DCF Model'!C13 -> 0.01 | H3: Exit Multiple: | I3: ='DCF Model'!C14 -> 9
B5: Table 1: WACC vs Terminal Growth Rate (PGM - Implied Share Price, JPY)
B6: WACC \ Terminal g | C6: =$F$3-0.0075 -> 0.0025 | D6: =$F$3-0.005 -> 0.005 | E6: =$F$3-0.0025 -> 0.0075 | F6: =$F$3 -> 0.01 | G6: =$F$3+0.0025 -> 0.0125 | H6: =$F$3+0.005 -> 0.015 | I6: =$F$3+0.0075 -> 0.0175
B7: =$C$3-0.015 -> 0.094406067 | C7: =IFERROR(ROUND(('DCF Model'!C45/(1+$B7)^('DCF Model'!C19+0)+'DCF Model'!D45/(1+$B7)^('DCF Model'!C19+1)+'DCF Model'!E45/(1+$B7)^('DCF Model'!C19+2)+'DCF Model'!F45/(1+$B7)^('DCF Model'!C19+3)+'DCF Model'!G45/(1+$B7)^('DCF Model'!C19+4)+'DCF Model'!G45*(1+C$6)/($B7-C$6)/(1+$B7)^('DCF Model'!C19+4)-'DCF Model'!C16)*1000000/'DCF Model'!C15,0),"") -> 976 | D7: =IFERROR(ROUND(('DCF Model'!C45/(1+$B7)^('DCF Model'!C19+0)+'DCF Model'!D45/(1+$B7)^('DCF Model'!C19+1)+'DCF Model'!E45/(1+$B7)^('DCF Model'!C19+2)+'DCF Model'!F45/(1+$B7)^('DCF Model'!C19+3)+'DCF Model'!G45/(1+$B7)^('DCF Model'!C19+4)+'DCF Model'!G45*(1+D$6)/($B7-D$6)/(1+$B7)^('DCF Model'!C19+4)-'DCF Model'!C16)*1000000/'DCF Model'!C15,0),"") -> 998 | E7: =IFERROR(ROUND(('DCF Model'!C45/(1+$B7)^('DCF Model'!C19+0)+'DCF Model'!D45/(1+$B7)^('DCF Model'!C19+1)+'DCF Model'!E45/(1+$B7)^('DCF Model'!C19+2)+'DCF Model'!F45/(1+$B7)^('DCF Model'!C19+3)+'DCF Model'!G45/(1+$B7)^('DCF Model'!C19+4)+'DCF Model'!G45*(1+E$6)/($B7-E$6)/(1+$B7)^('DCF Model'!C19+4)-'DCF Model'!C16)*1000000/'DCF Model'!C15,0),"") -> 1022 | F7: =IFERROR(ROUND(('DCF Model'!C45/(1+$B7)^('DCF Model'!C19+0)+'DCF Model'!D45/(1+$B7)^('DCF Model'!C19+1)+'DCF Model'!E45/(1+$B7)^('DCF Model'!C19+2)+'DCF Model'!F45/(1+$B7)^('DCF Model'!C19+3)+'DCF Model'!G45/(1+$B7)^('DCF Model'!C19+4)+'DCF Model'!G45*(1+F$6)/($B7-F$6)/(1+$B7)^('DCF Model'!C19+4)-'DCF Model'!C16)*1000000/'DCF Model'!C15,0),"") -> 1047 | G7: =IFERROR(ROUND(('DCF Model'!C45/(1+$B7)^('DCF Model'!C19+0)+'DCF Model'!D45/(1+$B7)^('DCF Model'!C19+1)+'DCF Model'!E45/(1+$B7)^('DCF Model'!C19+2)+'DCF Model'!F45/(1+$B7)^('DCF Model'!C19+3)+'DCF Model'!G45/(1+$B7)^('DCF Model'!C19+4)+'DCF Model'!G45*(1+G$6)/($B7-G$6)/(1+$B7)^('DCF Model'!C19+4)-'DCF Model'!C16)*1000000/'DCF Model'!C15,0),"") -> 1073 | H7: =IFERROR(ROUND(('DCF Model'!C45/(1+$B7)^('DCF Model'!C19+0)+'DCF Model'!D45/(1+$B7)^('DCF Model'!C19+1)+'DCF Model'!E45/(1+$B7)^('DCF Model'!C19+2)+'DCF Model'!F45/(1+$B7)^('DCF Model'!C19+3)+'DCF Model'!G45/(1+$B7)^('DCF Model'!C19+4)+'DCF Model'!G45*(1+H$6)/($B7-H$6)/(1+$B7)^('DCF Model'!C19+4)-'DCF Model'!C16)*1000000/'DCF Model'!C15,0),"") -> 1101 | I7: =IFERROR(ROUND(('DCF Model'!C45/(1+$B7)^('DCF Model'!C19+0)+'DCF Model'!D45/(1+$B7)^('DCF Model'!C19+1)+'DCF Model'!E45/(1+$B7)^('DCF Model'!C19+2)+'DCF Model'!F45/(1+$B7)^('DCF Model'!C19+3)+'DCF Model'!G45/(1+$B7)^('DCF Model'!C19+4)+'DCF Model'!G45*(1+I$6)/($B7-I$6)/(1+$B7)^('DCF Model'!C19+4)-'DCF Model'!C16)*1000000/'DCF Model'!C15,0),"") -> 1131
B8: =$C$3-0.01 -> 0.099406067 | C8: =IFERROR(ROUND(('DCF Model'!C45/(1+$B8)^('DCF Model'!C19+0)+'DCF Model'!D45/(1+$B8)^('DCF Model'!C19+1)+'DCF Model'!E45/(1+$B8)^('DCF Model'!C19+2)+'DCF Model'!F45/(1+$B8)^('DCF Model'!C19+3)+'DCF Model'!G45/(1+$B8)^('DCF Model'!C19+4)+'DCF Model'!G45*(1+C$6)/($B8-C$6)/(1+$B8)^('DCF Model'!C19+4)-'DCF Model'!C16)*1000000/'DCF Model'!C15,0),"") -> 919 | D8: =IFERROR(ROUND(('DCF Model'!C45/(1+$B8)^('DCF Model'!C19+0)+'DCF Model'!D45/(1+$B8)^('DCF Model'!C19+1)+'DCF Model'!E45/(1+$B8)^('DCF Model'!C19+2)+'DCF Model'!F45/(1+$B8)^('DCF Model'!C19+3)+'DCF Model'!G45/(1+$B8)^('DCF Model'!C19+4)+'DCF Model'!G45*(1+D$6)/($B8-D$6)/(1+$B8)^('DCF Model'!C19+4)-'DCF Model'!C16)*1000000/'DCF Model'!C15,0),"") -> 938 | E8: =IFERROR(ROUND(('DCF Model'!C45/(1+$B8)^('DCF Model'!C19+0)+'DCF Model'!D45/(1+$B8)^('DCF Model'!C19+1)+'DCF Model'!E45/(1+$B8)^('DCF Model'!C19+2)+'DCF Model'!F45/(1+$B8)^('DCF Model'!C19+3)+'DCF Model'!G45/(1+$B8)^('DCF Model'!C19+4)+'DCF Model'!G45*(1+E$6)/($B8-E$6)/(1+$B8)^('DCF Model'!C19+4)-'DCF Model'!C16)*1000000/'DCF Model'!C15,0),"") -> 959 | F8: =IFERROR(ROUND(('DCF Model'!C45/(1+$B8)^('DCF Model'!C19+0)+'DCF Model'!D45/(1+$B8)^('DCF Model'!C19+1)+'DCF Model'!E45/(1+$B8)^('DCF Model'!C19+2)+'DCF Model'!F45/(1+$B8)^('DCF Model'!C19+3)+'DCF Model'!G45/(1+$B8)^('DCF Model'!C19+4)+'DCF Model'!G45*(1+F$6)/($B8-F$6)/(1+$B8)^('DCF Model'!C19+4)-'DCF Model'!C16)*1000000/'DCF Model'!C15,0),"") -> 981 | G8: =IFERROR(ROUND(('DCF Model'!C45/(1+$B8)^('DCF Model'!C19+0)+'DCF Model'!D45/(1+$B8)^('DCF Model'!C19+1)+'DCF Model'!E45/(1+$B8)^('DCF Model'!C19+2)+'DCF Model'!F45/(1+$B8)^('DCF Model'!C19+3)+'DCF Model'!G45/(1+$B8)^('DCF Model'!C19+4)+'DCF Model'!G45*(1+G$6)/($B8-G$6)/(1+$B8)^('DCF Model'!C19+4)-'DCF Model'!C16)*1000000/'DCF Model'!C15,0),"") -> 1004 | H8: =IFERROR(ROUND(('DCF Model'!C45/(1+$B8)^('DCF Model'!C19+0)+'DCF Model'!D45/(1+$B8)^('DCF Model'!C19+1)+'DCF Model'!E45/(1+$B8)^('DCF Model'!C19+2)+'DCF Model'!F45/(1+$B8)^('DCF Model'!C19+3)+'DCF Model'!G45/(1+$B8)^('DCF Model'!C19+4)+'DCF Model'!G45*(1+H$6)/($B8-H$6)/(1+$B8)^('DCF Model'!C19+4)-'DCF Model'!C16)*1000000/'DCF Model'!C15,0),"") -> 1028 | I8: =IFERROR(ROUND(('DCF Model'!C45/(1+$B8)^('DCF Model'!C19+0)+'DCF Model'!D45/(1+$B8)^('DCF Model'!C19+1)+'DCF Model'!E45/(1+$B8)^('DCF Model'!C19+2)+'DCF Model'!F45/(1+$B8)^('DCF Model'!C19+3)+'DCF Model'!G45/(1+$B8)^('DCF Model'!C19+4)+'DCF Model'!G45*(1+I$6)/($B8-I$6)/(1+$B8)^('DCF Model'!C19+4)-'DCF Model'!C16)*1000000/'DCF Model'!C15,0),"") -> 1054
B9: =$C$3-0.005 -> 0.10440607 | C9: =IFERROR(ROUND(('DCF Model'!C45/(1+$B9)^('DCF Model'!C19+0)+'DCF Model'!D45/(1+$B9)^('DCF Model'!C19+1)+'DCF Model'!E45/(1+$B9)^('DCF Model'!C19+2)+'DCF Model'!F45/(1+$B9)^('DCF Model'!C19+3)+'DCF Model'!G45/(1+$B9)^('DCF Model'!C19+4)+'DCF Model'!G45*(1+C$6)/($B9-C$6)/(1+$B9)^('DCF Model'!C19+4)-'DCF Model'!C16)*1000000/'DCF Model'!C15,0),"") -> 867 | D9: =IFERROR(ROUND(('DCF Model'!C45/(1+$B9)^('DCF Model'!C19+0)+'DCF Model'!D45/(1+$B9)^('DCF Model'!C19+1)+'DCF Model'!E45/(1+$B9)^('DCF Model'!C19+2)+'DCF Model'!F45/(1+$B9)^('DCF Model'!C19+3)+'DCF Model'!G45/(1+$B9)^('DCF Model'!C19+4)+'DCF Model'!G45*(1+D$6)/($B9-D$6)/(1+$B9)^('DCF Model'!C19+4)-'DCF Model'!C16)*1000000/'DCF Model'!C15,0),"") -> 884 | E9: =IFERROR(ROUND(('DCF Model'!C45/(1+$B9)^('DCF Model'!C19+0)+'DCF Model'!D45/(1+$B9)^('DCF Model'!C19+1)+'DCF Model'!E45/(1+$B9)^('DCF Model'!C19+2)+'DCF Model'!F45/(1+$B9)^('DCF Model'!C19+3)+'DCF Model'!G45/(1+$B9)^('DCF Model'!C19+4)+'DCF Model'!G45*(1+E$6)/($B9-E$6)/(1+$B9)^('DCF Model'!C19+4)-'DCF Model'!C16)*1000000/'DCF Model'!C15,0),"") -> 902 | F9: =IFERROR(ROUND(('DCF Model'!C45/(1+$B9)^('DCF Model'!C19+0)+'DCF Model'!D45/(1+$B9)^('DCF Model'!C19+1)+'DCF Model'!E45/(1+$B9)^('DCF Model'!C19+2)+'DCF Model'!F45/(1+$B9)^('DCF Model'!C19+3)+'DCF Model'!G45/(1+$B9)^('DCF Model'!C19+4)+'DCF Model'!G45*(1+F$6)/($B9-F$6)/(1+$B9)^('DCF Model'!C19+4)-'DCF Model'!C16)*1000000/'DCF Model'!C15,0),"") -> 922 | G9: =IFERROR(ROUND(('DCF Model'!C45/(1+$B9)^('DCF Model'!C19+0)+'DCF Model'!D45/(1+$B9)^('DCF Model'!C19+1)+'DCF Model'!E45/(1+$B9)^('DCF Model'!C19+2)+'DCF Model'!F45/(1+$B9)^('DCF Model'!C19+3)+'DCF Model'!G45/(1+$B9)^('DCF Model'!C19+4)+'DCF Model'!G45*(1+G$6)/($B9-G$6)/(1+$B9)^('DCF Model'!C19+4)-'DCF Model'!C16)*1000000/'DCF Model'!C15,0),"") -> 942 | H9: =IFERROR(ROUND(('DCF Model'!C45/(1+$B9)^('DCF Model'!C19+0)+'DCF Model'!D45/(1+$B9)^('DCF Model'!C19+1)+'DCF Model'!E45/(1+$B9)^('DCF Model'!C19+2)+'DCF Model'!F45/(1+$B9)^('DCF Model'!C19+3)+'DCF Model'!G45/(1+$B9)^('DCF Model'!C19+4)+'DCF Model'!G45*(1+H$6)/($B9-H$6)/(1+$B9)^('DCF Model'!C19+4)-'DCF Model'!C16)*1000000/'DCF Model'!C15,0),"") -> 963 | I9: =IFERROR(ROUND(('DCF Model'!C45/(1+$B9)^('DCF Model'!C19+0)+'DCF Model'!D45/(1+$B9)^('DCF Model'!C19+1)+'DCF Model'!E45/(1+$B9)^('DCF Model'!C19+2)+'DCF Model'!F45/(1+$B9)^('DCF Model'!C19+3)+'DCF Model'!G45/(1+$B9)^('DCF Model'!C19+4)+'DCF Model'!G45*(1+I$6)/($B9-I$6)/(1+$B9)^('DCF Model'!C19+4)-'DCF Model'!C16)*1000000/'DCF Model'!C15,0),"") -> 986
B10: =$C$3 -> 0.10940607 | C10: =IFERROR(ROUND(('DCF Model'!C45/(1+$B10)^('DCF Model'!C19+0)+'DCF Model'!D45/(1+$B10)^('DCF Model'!C19+1)+'DCF Model'!E45/(1+$B10)^('DCF Model'!C19+2)+'DCF Model'!F45/(1+$B10)^('DCF Model'!C19+3)+'DCF Model'!G45/(1+$B10)^('DCF Model'!C19+4)+'DCF Model'!G45*(1+C$6)/($B10-C$6)/(1+$B10)^('DCF Model'!C19+4)-'DCF Model'!C16)*1000000/'DCF Model'!C15,0),"") -> 820 | D10: =IFERROR(ROUND(('DCF Model'!C45/(1+$B10)^('DCF Model'!C19+0)+'DCF Model'!D45/(1+$B10)^('DCF Model'!C19+1)+'DCF Model'!E45/(1+$B10)^('DCF Model'!C19+2)+'DCF Model'!F45/(1+$B10)^('DCF Model'!C19+3)+'DCF Model'!G45/(1+$B10)^('DCF Model'!C19+4)+'DCF Model'!G45*(1+D$6)/($B10-D$6)/(1+$B10)^('DCF Model'!C19+4)-'DCF Model'!C16)*1000000/'DCF Model'!C15,0),"") -> 835 | E10: =IFERROR(ROUND(('DCF Model'!C45/(1+$B10)^('DCF Model'!C19+0)+'DCF Model'!D45/(1+$B10)^('DCF Model'!C19+1)+'DCF Model'!E45/(1+$B10)^('DCF Model'!C19+2)+'DCF Model'!F45/(1+$B10)^('DCF Model'!C19+3)+'DCF Model'!G45/(1+$B10)^('DCF Model'!C19+4)+'DCF Model'!G45*(1+E$6)/($B10-E$6)/(1+$B10)^('DCF Model'!C19+4)-'DCF Model'!C16)*1000000/'DCF Model'!C15,0),"") -> 852 | F10: =IFERROR(ROUND(('DCF Model'!C45/(1+$B10)^('DCF Model'!C19+0)+'DCF Model'!D45/(1+$B10)^('DCF Model'!C19+1)+'DCF Model'!E45/(1+$B10)^('DCF Model'!C19+2)+'DCF Model'!F45/(1+$B10)^('DCF Model'!C19+3)+'DCF Model'!G45/(1+$B10)^('DCF Model'!C19+4)+'DCF Model'!G45*(1+F$6)/($B10-F$6)/(1+$B10)^('DCF Model'!C19+4)-'DCF Model'!C16)*1000000/'DCF Model'!C15,0),"") -> 869 | G10: =IFERROR(ROUND(('DCF Model'!C45/(1+$B10)^('DCF Model'!C19+0)+'DCF Model'!D45/(1+$B10)^('DCF Model'!C19+1)+'DCF Model'!E45/(1+$B10)^('DCF Model'!C19+2)+'DCF Model'!F45/(1+$B10)^('DCF Model'!C19+3)+'DCF Model'!G45/(1+$B10)^('DCF Model'!C19+4)+'DCF Model'!G45*(1+G$6)/($B10-G$6)/(1+$B10)^('DCF Model'!C19+4)-'DCF Model'!C16)*1000000/'DCF Model'!C15,0),"") -> 887 | H10: =IFERROR(ROUND(('DCF Model'!C45/(1+$B10)^('DCF Model'!C19+0)+'DCF Model'!D45/(1+$B10)^('DCF Model'!C19+1)+'DCF Model'!E45/(1+$B10)^('DCF Model'!C19+2)+'DCF Model'!F45/(1+$B10)^('DCF Model'!C19+3)+'DCF Model'!G45/(1+$B10)^('DCF Model'!C19+4)+'DCF Model'!G45*(1+H$6)/($B10-H$6)/(1+$B10)^('DCF Model'!C19+4)-'DCF Model'!C16)*1000000/'DCF Model'!C15,0),"") -> 905 | I10: =IFERROR(ROUND(('DCF Model'!C45/(1+$B10)^('DCF Model'!C19+0)+'DCF Model'!D45/(1+$B10)^('DCF Model'!C19+1)+'DCF Model'!E45/(1+$B10)^('DCF Model'!C19+2)+'DCF Model'!F45/(1+$B10)^('DCF Model'!C19+3)+'DCF Model'!G45/(1+$B10)^('DCF Model'!C19+4)+'DCF Model'!G45*(1+I$6)/($B10-I$6)/(1+$B10)^('DCF Model'!C19+4)-'DCF Model'!C16)*1000000/'DCF Model'!C15,0),"") -> 925
B11: =$C$3+0.005 -> 0.11440607 | C11: =IFERROR(ROUND(('DCF Model'!C45/(1+$B11)^('DCF Model'!C19+0)+'DCF Model'!D45/(1+$B11)^('DCF Model'!C19+1)+'DCF Model'!E45/(1+$B11)^('DCF Model'!C19+2)+'DCF Model'!F45/(1+$B11)^('DCF Model'!C19+3)+'DCF Model'!G45/(1+$B11)^('DCF Model'!C19+4)+'DCF Model'!G45*(1+C$6)/($B11-C$6)/(1+$B11)^('DCF Model'!C19+4)-'DCF Model'!C16)*1000000/'DCF Model'!C15,0),"") -> 777 | D11: =IFERROR(ROUND(('DCF Model'!C45/(1+$B11)^('DCF Model'!C19+0)+'DCF Model'!D45/(1+$B11)^('DCF Model'!C19+1)+'DCF Model'!E45/(1+$B11)^('DCF Model'!C19+2)+'DCF Model'!F45/(1+$B11)^('DCF Model'!C19+3)+'DCF Model'!G45/(1+$B11)^('DCF Model'!C19+4)+'DCF Model'!G45*(1+D$6)/($B11-D$6)/(1+$B11)^('DCF Model'!C19+4)-'DCF Model'!C16)*1000000/'DCF Model'!C15,0),"") -> 791 | E11: =IFERROR(ROUND(('DCF Model'!C45/(1+$B11)^('DCF Model'!C19+0)+'DCF Model'!D45/(1+$B11)^('DCF Model'!C19+1)+'DCF Model'!E45/(1+$B11)^('DCF Model'!C19+2)+'DCF Model'!F45/(1+$B11)^('DCF Model'!C19+3)+'DCF Model'!G45/(1+$B11)^('DCF Model'!C19+4)+'DCF Model'!G45*(1+E$6)/($B11-E$6)/(1+$B11)^('DCF Model'!C19+4)-'DCF Model'!C16)*1000000/'DCF Model'!C15,0),"") -> 806 | F11: =IFERROR(ROUND(('DCF Model'!C45/(1+$B11)^('DCF Model'!C19+0)+'DCF Model'!D45/(1+$B11)^('DCF Model'!C19+1)+'DCF Model'!E45/(1+$B11)^('DCF Model'!C19+2)+'DCF Model'!F45/(1+$B11)^('DCF Model'!C19+3)+'DCF Model'!G45/(1+$B11)^('DCF Model'!C19+4)+'DCF Model'!G45*(1+F$6)/($B11-F$6)/(1+$B11)^('DCF Model'!C19+4)-'DCF Model'!C16)*1000000/'DCF Model'!C15,0),"") -> 821 | G11: =IFERROR(ROUND(('DCF Model'!C45/(1+$B11)^('DCF Model'!C19+0)+'DCF Model'!D45/(1+$B11)^('DCF Model'!C19+1)+'DCF Model'!E45/(1+$B11)^('DCF Model'!C19+2)+'DCF Model'!F45/(1+$B11)^('DCF Model'!C19+3)+'DCF Model'!G45/(1+$B11)^('DCF Model'!C19+4)+'DCF Model'!G45*(1+G$6)/($B11-G$6)/(1+$B11)^('DCF Model'!C19+4)-'DCF Model'!C16)*1000000/'DCF Model'!C15,0),"") -> 837 | H11: =IFERROR(ROUND(('DCF Model'!C45/(1+$B11)^('DCF Model'!C19+0)+'DCF Model'!D45/(1+$B11)^('DCF Model'!C19+1)+'DCF Model'!E45/(1+$B11)^('DCF Model'!C19+2)+'DCF Model'!F45/(1+$B11)^('DCF Model'!C19+3)+'DCF Model'!G45/(1+$B11)^('DCF Model'!C19+4)+'DCF Model'!G45*(1+H$6)/($B11-H$6)/(1+$B11)^('DCF Model'!C19+4)-'DCF Model'!C16)*1000000/'DCF Model'!C15,0),"") -> 853 | I11: =IFERROR(ROUND(('DCF Model'!C45/(1+$B11)^('DCF Model'!C19+0)+'DCF Model'!D45/(1+$B11)^('DCF Model'!C19+1)+'DCF Model'!E45/(1+$B11)^('DCF Model'!C19+2)+'DCF Model'!F45/(1+$B11)^('DCF Model'!C19+3)+'DCF Model'!G45/(1+$B11)^('DCF Model'!C19+4)+'DCF Model'!G45*(1+I$6)/($B11-I$6)/(1+$B11)^('DCF Model'!C19+4)-'DCF Model'!C16)*1000000/'DCF Model'!C15,0),"") -> 871
B12: =$C$3+0.01 -> 0.11940607 | C12: =IFERROR(ROUND(('DCF Model'!C45/(1+$B12)^('DCF Model'!C19+0)+'DCF Model'!D45/(1+$B12)^('DCF Model'!C19+1)+'DCF Model'!E45/(1+$B12)^('DCF Model'!C19+2)+'DCF Model'!F45/(1+$B12)^('DCF Model'!C19+3)+'DCF Model'!G45/(1+$B12)^('DCF Model'!C19+4)+'DCF Model'!G45*(1+C$6)/($B12-C$6)/(1+$B12)^('DCF Model'!C19+4)-'DCF Model'!C16)*1000000/'DCF Model'!C15,0),"") -> 738 | D12: =IFERROR(ROUND(('DCF Model'!C45/(1+$B12)^('DCF Model'!C19+0)+'DCF Model'!D45/(1+$B12)^('DCF Model'!C19+1)+'DCF Model'!E45/(1+$B12)^('DCF Model'!C19+2)+'DCF Model'!F45/(1+$B12)^('DCF Model'!C19+3)+'DCF Model'!G45/(1+$B12)^('DCF Model'!C19+4)+'DCF Model'!G45*(1+D$6)/($B12-D$6)/(1+$B12)^('DCF Model'!C19+4)-'DCF Model'!C16)*1000000/'DCF Model'!C15,0),"") -> 751 | E12: =IFERROR(ROUND(('DCF Model'!C45/(1+$B12)^('DCF Model'!C19+0)+'DCF Model'!D45/(1+$B12)^('DCF Model'!C19+1)+'DCF Model'!E45/(1+$B12)^('DCF Model'!C19+2)+'DCF Model'!F45/(1+$B12)^('DCF Model'!C19+3)+'DCF Model'!G45/(1+$B12)^('DCF Model'!C19+4)+'DCF Model'!G45*(1+E$6)/($B12-E$6)/(1+$B12)^('DCF Model'!C19+4)-'DCF Model'!C16)*1000000/'DCF Model'!C15,0),"") -> 764 | F12: =IFERROR(ROUND(('DCF Model'!C45/(1+$B12)^('DCF Model'!C19+0)+'DCF Model'!D45/(1+$B12)^('DCF Model'!C19+1)+'DCF Model'!E45/(1+$B12)^('DCF Model'!C19+2)+'DCF Model'!F45/(1+$B12)^('DCF Model'!C19+3)+'DCF Model'!G45/(1+$B12)^('DCF Model'!C19+4)+'DCF Model'!G45*(1+F$6)/($B12-F$6)/(1+$B12)^('DCF Model'!C19+4)-'DCF Model'!C16)*1000000/'DCF Model'!C15,0),"") -> 777 | G12: =IFERROR(ROUND(('DCF Model'!C45/(1+$B12)^('DCF Model'!C19+0)+'DCF Model'!D45/(1+$B12)^('DCF Model'!C19+1)+'DCF Model'!E45/(1+$B12)^('DCF Model'!C19+2)+'DCF Model'!F45/(1+$B12)^('DCF Model'!C19+3)+'DCF Model'!G45/(1+$B12)^('DCF Model'!C19+4)+'DCF Model'!G45*(1+G$6)/($B12-G$6)/(1+$B12)^('DCF Model'!C19+4)-'DCF Model'!C16)*1000000/'DCF Model'!C15,0),"") -> 792 | H12: =IFERROR(ROUND(('DCF Model'!C45/(1+$B12)^('DCF Model'!C19+0)+'DCF Model'!D45/(1+$B12)^('DCF Model'!C19+1)+'DCF Model'!E45/(1+$B12)^('DCF Model'!C19+2)+'DCF Model'!F45/(1+$B12)^('DCF Model'!C19+3)+'DCF Model'!G45/(1+$B12)^('DCF Model'!C19+4)+'DCF Model'!G45*(1+H$6)/($B12-H$6)/(1+$B12)^('DCF Model'!C19+4)-'DCF Model'!C16)*1000000/'DCF Model'!C15,0),"") -> 806 | I12: =IFERROR(ROUND(('DCF Model'!C45/(1+$B12)^('DCF Model'!C19+0)+'DCF Model'!D45/(1+$B12)^('DCF Model'!C19+1)+'DCF Model'!E45/(1+$B12)^('DCF Model'!C19+2)+'DCF Model'!F45/(1+$B12)^('DCF Model'!C19+3)+'DCF Model'!G45/(1+$B12)^('DCF Model'!C19+4)+'DCF Model'!G45*(1+I$6)/($B12-I$6)/(1+$B12)^('DCF Model'!C19+4)-'DCF Model'!C16)*1000000/'DCF Model'!C15,0),"") -> 822
B13: =$C$3+0.015 -> 0.12440607 | C13: =IFERROR(ROUND(('DCF Model'!C45/(1+$B13)^('DCF Model'!C19+0)+'DCF Model'!D45/(1+$B13)^('DCF Model'!C19+1)+'DCF Model'!E45/(1+$B13)^('DCF Model'!C19+2)+'DCF Model'!F45/(1+$B13)^('DCF Model'!C19+3)+'DCF Model'!G45/(1+$B13)^('DCF Model'!C19+4)+'DCF Model'!G45*(1+C$6)/($B13-C$6)/(1+$B13)^('DCF Model'!C19+4)-'DCF Model'!C16)*1000000/'DCF Model'!C15,0),"") -> 703 | D13: =IFERROR(ROUND(('DCF Model'!C45/(1+$B13)^('DCF Model'!C19+0)+'DCF Model'!D45/(1+$B13)^('DCF Model'!C19+1)+'DCF Model'!E45/(1+$B13)^('DCF Model'!C19+2)+'DCF Model'!F45/(1+$B13)^('DCF Model'!C19+3)+'DCF Model'!G45/(1+$B13)^('DCF Model'!C19+4)+'DCF Model'!G45*(1+D$6)/($B13-D$6)/(1+$B13)^('DCF Model'!C19+4)-'DCF Model'!C16)*1000000/'DCF Model'!C15,0),"") -> 714 | E13: =IFERROR(ROUND(('DCF Model'!C45/(1+$B13)^('DCF Model'!C19+0)+'DCF Model'!D45/(1+$B13)^('DCF Model'!C19+1)+'DCF Model'!E45/(1+$B13)^('DCF Model'!C19+2)+'DCF Model'!F45/(1+$B13)^('DCF Model'!C19+3)+'DCF Model'!G45/(1+$B13)^('DCF Model'!C19+4)+'DCF Model'!G45*(1+E$6)/($B13-E$6)/(1+$B13)^('DCF Model'!C19+4)-'DCF Model'!C16)*1000000/'DCF Model'!C15,0),"") -> 725 | F13: =IFERROR(ROUND(('DCF Model'!C45/(1+$B13)^('DCF Model'!C19+0)+'DCF Model'!D45/(1+$B13)^('DCF Model'!C19+1)+'DCF Model'!E45/(1+$B13)^('DCF Model'!C19+2)+'DCF Model'!F45/(1+$B13)^('DCF Model'!C19+3)+'DCF Model'!G45/(1+$B13)^('DCF Model'!C19+4)+'DCF Model'!G45*(1+F$6)/($B13-F$6)/(1+$B13)^('DCF Model'!C19+4)-'DCF Model'!C16)*1000000/'DCF Model'!C15,0),"") -> 738 | G13: =IFERROR(ROUND(('DCF Model'!C45/(1+$B13)^('DCF Model'!C19+0)+'DCF Model'!D45/(1+$B13)^('DCF Model'!C19+1)+'DCF Model'!E45/(1+$B13)^('DCF Model'!C19+2)+'DCF Model'!F45/(1+$B13)^('DCF Model'!C19+3)+'DCF Model'!G45/(1+$B13)^('DCF Model'!C19+4)+'DCF Model'!G45*(1+G$6)/($B13-G$6)/(1+$B13)^('DCF Model'!C19+4)-'DCF Model'!C16)*1000000/'DCF Model'!C15,0),"") -> 750 | H13: =IFERROR(ROUND(('DCF Model'!C45/(1+$B13)^('DCF Model'!C19+0)+'DCF Model'!D45/(1+$B13)^('DCF Model'!C19+1)+'DCF Model'!E45/(1+$B13)^('DCF Model'!C19+2)+'DCF Model'!F45/(1+$B13)^('DCF Model'!C19+3)+'DCF Model'!G45/(1+$B13)^('DCF Model'!C19+4)+'DCF Model'!G45*(1+H$6)/($B13-H$6)/(1+$B13)^('DCF Model'!C19+4)-'DCF Model'!C16)*1000000/'DCF Model'!C15,0),"") -> 764 | I13: =IFERROR(ROUND(('DCF Model'!C45/(1+$B13)^('DCF Model'!C19+0)+'DCF Model'!D45/(1+$B13)^('DCF Model'!C19+1)+'DCF Model'!E45/(1+$B13)^('DCF Model'!C19+2)+'DCF Model'!F45/(1+$B13)^('DCF Model'!C19+3)+'DCF Model'!G45/(1+$B13)^('DCF Model'!C19+4)+'DCF Model'!G45*(1+I$6)/($B13-I$6)/(1+$B13)^('DCF Model'!C19+4)-'DCF Model'!C16)*1000000/'DCF Model'!C15,0),"") -> 778
B16: Table 2: WACC vs Exit Multiple (Exit Multiple - Implied Share Price, JPY)
B17: WACC \ Exit Multiple | C17: =$I$3-3 -> 6 | D17: =$I$3-2 -> 7 | E17: =$I$3-1 -> 8 | F17: =$I$3 -> 9 | G17: =$I$3+1 -> 10 | H17: =$I$3+2 -> 11 | I17: =$I$3+3 -> 12
B18: =$C$3-0.015 -> 0.094406067 | C18: =IFERROR(ROUND(('DCF Model'!C45/(1+$B18)^('DCF Model'!C19+0)+'DCF Model'!D45/(1+$B18)^('DCF Model'!C19+1)+'DCF Model'!E45/(1+$B18)^('DCF Model'!C19+2)+'DCF Model'!F45/(1+$B18)^('DCF Model'!C19+3)+'DCF Model'!G45/(1+$B18)^('DCF Model'!C19+4)+('DCF Model'!G39+'DCF Model'!G42)*C$17/(1+$B18)^('DCF Model'!C19+4)-'DCF Model'!C16)*1000000/'DCF Model'!C15,0),"") -> 1207 | D18: =IFERROR(ROUND(('DCF Model'!C45/(1+$B18)^('DCF Model'!C19+0)+'DCF Model'!D45/(1+$B18)^('DCF Model'!C19+1)+'DCF Model'!E45/(1+$B18)^('DCF Model'!C19+2)+'DCF Model'!F45/(1+$B18)^('DCF Model'!C19+3)+'DCF Model'!G45/(1+$B18)^('DCF Model'!C19+4)+('DCF Model'!G39+'DCF Model'!G42)*D$17/(1+$B18)^('DCF Model'!C19+4)-'DCF Model'!C16)*1000000/'DCF Model'!C15,0),"") -> 1366 | E18: =IFERROR(ROUND(('DCF Model'!C45/(1+$B18)^('DCF Model'!C19+0)+'DCF Model'!D45/(1+$B18)^('DCF Model'!C19+1)+'DCF Model'!E45/(1+$B18)^('DCF Model'!C19+2)+'DCF Model'!F45/(1+$B18)^('DCF Model'!C19+3)+'DCF Model'!G45/(1+$B18)^('DCF Model'!C19+4)+('DCF Model'!G39+'DCF Model'!G42)*E$17/(1+$B18)^('DCF Model'!C19+4)-'DCF Model'!C16)*1000000/'DCF Model'!C15,0),"") -> 1526 | F18: =IFERROR(ROUND(('DCF Model'!C45/(1+$B18)^('DCF Model'!C19+0)+'DCF Model'!D45/(1+$B18)^('DCF Model'!C19+1)+'DCF Model'!E45/(1+$B18)^('DCF Model'!C19+2)+'DCF Model'!F45/(1+$B18)^('DCF Model'!C19+3)+'DCF Model'!G45/(1+$B18)^('DCF Model'!C19+4)+('DCF Model'!G39+'DCF Model'!G42)*F$17/(1+$B18)^('DCF Model'!C19+4)-'DCF Model'!C16)*1000000/'DCF Model'!C15,0),"") -> 1685 | G18: =IFERROR(ROUND(('DCF Model'!C45/(1+$B18)^('DCF Model'!C19+0)+'DCF Model'!D45/(1+$B18)^('DCF Model'!C19+1)+'DCF Model'!E45/(1+$B18)^('DCF Model'!C19+2)+'DCF Model'!F45/(1+$B18)^('DCF Model'!C19+3)+'DCF Model'!G45/(1+$B18)^('DCF Model'!C19+4)+('DCF Model'!G39+'DCF Model'!G42)*G$17/(1+$B18)^('DCF Model'!C19+4)-'DCF Model'!C16)*1000000/'DCF Model'!C15,0),"") -> 1845 | H18: =IFERROR(ROUND(('DCF Model'!C45/(1+$B18)^('DCF Model'!C19+0)+'DCF Model'!D45/(1+$B18)^('DCF Model'!C19+1)+'DCF Model'!E45/(1+$B18)^('DCF Model'!C19+2)+'DCF Model'!F45/(1+$B18)^('DCF Model'!C19+3)+'DCF Model'!G45/(1+$B18)^('DCF Model'!C19+4)+('DCF Model'!G39+'DCF Model'!G42)*H$17/(1+$B18)^('DCF Model'!C19+4)-'DCF Model'!C16)*1000000/'DCF Model'!C15,0),"") -> 2004 | I18: =IFERROR(ROUND(('DCF Model'!C45/(1+$B18)^('DCF Model'!C19+0)+'DCF Model'!D45/(1+$B18)^('DCF Model'!C19+1)+'DCF Model'!E45/(1+$B18)^('DCF Model'!C19+2)+'DCF Model'!F45/(1+$B18)^('DCF Model'!C19+3)+'DCF Model'!G45/(1+$B18)^('DCF Model'!C19+4)+('DCF Model'!G39+'DCF Model'!G42)*I$17/(1+$B18)^('DCF Model'!C19+4)-'DCF Model'!C16)*1000000/'DCF Model'!C15,0),"") -> 2164
B19: =$C$3-0.01 -> 0.099406067 | C19: =IFERROR(ROUND(('DCF Model'!C45/(1+$B19)^('DCF Model'!C19+0)+'DCF Model'!D45/(1+$B19)^('DCF Model'!C19+1)+'DCF Model'!E45/(1+$B19)^('DCF Model'!C19+2)+'DCF Model'!F45/(1+$B19)^('DCF Model'!C19+3)+'DCF Model'!G45/(1+$B19)^('DCF Model'!C19+4)+('DCF Model'!G39+'DCF Model'!G42)*C$17/(1+$B19)^('DCF Model'!C19+4)-'DCF Model'!C16)*1000000/'DCF Model'!C15,0),"") -> 1181 | D19: =IFERROR(ROUND(('DCF Model'!C45/(1+$B19)^('DCF Model'!C19+0)+'DCF Model'!D45/(1+$B19)^('DCF Model'!C19+1)+'DCF Model'!E45/(1+$B19)^('DCF Model'!C19+2)+'DCF Model'!F45/(1+$B19)^('DCF Model'!C19+3)+'DCF Model'!G45/(1+$B19)^('DCF Model'!C19+4)+('DCF Model'!G39+'DCF Model'!G42)*D$17/(1+$B19)^('DCF Model'!C19+4)-'DCF Model'!C16)*1000000/'DCF Model'!C15,0),"") -> 1337 | E19: =IFERROR(ROUND(('DCF Model'!C45/(1+$B19)^('DCF Model'!C19+0)+'DCF Model'!D45/(1+$B19)^('DCF Model'!C19+1)+'DCF Model'!E45/(1+$B19)^('DCF Model'!C19+2)+'DCF Model'!F45/(1+$B19)^('DCF Model'!C19+3)+'DCF Model'!G45/(1+$B19)^('DCF Model'!C19+4)+('DCF Model'!G39+'DCF Model'!G42)*E$17/(1+$B19)^('DCF Model'!C19+4)-'DCF Model'!C16)*1000000/'DCF Model'!C15,0),"") -> 1493 | F19: =IFERROR(ROUND(('DCF Model'!C45/(1+$B19)^('DCF Model'!C19+0)+'DCF Model'!D45/(1+$B19)^('DCF Model'!C19+1)+'DCF Model'!E45/(1+$B19)^('DCF Model'!C19+2)+'DCF Model'!F45/(1+$B19)^('DCF Model'!C19+3)+'DCF Model'!G45/(1+$B19)^('DCF Model'!C19+4)+('DCF Model'!G39+'DCF Model'!G42)*F$17/(1+$B19)^('DCF Model'!C19+4)-'DCF Model'!C16)*1000000/'DCF Model'!C15,0),"") -> 1648 | G19: =IFERROR(ROUND(('DCF Model'!C45/(1+$B19)^('DCF Model'!C19+0)+'DCF Model'!D45/(1+$B19)^('DCF Model'!C19+1)+'DCF Model'!E45/(1+$B19)^('DCF Model'!C19+2)+'DCF Model'!F45/(1+$B19)^('DCF Model'!C19+3)+'DCF Model'!G45/(1+$B19)^('DCF Model'!C19+4)+('DCF Model'!G39+'DCF Model'!G42)*G$17/(1+$B19)^('DCF Model'!C19+4)-'DCF Model'!C16)*1000000/'DCF Model'!C15,0),"") -> 1804 | H19: =IFERROR(ROUND(('DCF Model'!C45/(1+$B19)^('DCF Model'!C19+0)+'DCF Model'!D45/(1+$B19)^('DCF Model'!C19+1)+'DCF Model'!E45/(1+$B19)^('DCF Model'!C19+2)+'DCF Model'!F45/(1+$B19)^('DCF Model'!C19+3)+'DCF Model'!G45/(1+$B19)^('DCF Model'!C19+4)+('DCF Model'!G39+'DCF Model'!G42)*H$17/(1+$B19)^('DCF Model'!C19+4)-'DCF Model'!C16)*1000000/'DCF Model'!C15,0),"") -> 1960 | I19: =IFERROR(ROUND(('DCF Model'!C45/(1+$B19)^('DCF Model'!C19+0)+'DCF Model'!D45/(1+$B19)^('DCF Model'!C19+1)+'DCF Model'!E45/(1+$B19)^('DCF Model'!C19+2)+'DCF Model'!F45/(1+$B19)^('DCF Model'!C19+3)+'DCF Model'!G45/(1+$B19)^('DCF Model'!C19+4)+('DCF Model'!G39+'DCF Model'!G42)*I$17/(1+$B19)^('DCF Model'!C19+4)-'DCF Model'!C16)*1000000/'DCF Model'!C15,0),"") -> 2116
B20: =$C$3-0.005 -> 0.10440607 | C20: =IFERROR(ROUND(('DCF Model'!C45/(1+$B20)^('DCF Model'!C19+0)+'DCF Model'!D45/(1+$B20)^('DCF Model'!C19+1)+'DCF Model'!E45/(1+$B20)^('DCF Model'!C19+2)+'DCF Model'!F45/(1+$B20)^('DCF Model'!C19+3)+'DCF Model'!G45/(1+$B20)^('DCF Model'!C19+4)+('DCF Model'!G39+'DCF Model'!G42)*C$17/(1+$B20)^('DCF Model'!C19+4)-'DCF Model'!C16)*1000000/'DCF Model'!C15,0),"") -> 1155 | D20: =IFERROR(ROUND(('DCF Model'!C45/(1+$B20)^('DCF Model'!C19+0)+'DCF Model'!D45/(1+$B20)^('DCF Model'!C19+1)+'DCF Model'!E45/(1+$B20)^('DCF Model'!C19+2)+'DCF Model'!F45/(1+$B20)^('DCF Model'!C19+3)+'DCF Model'!G45/(1+$B20)^('DCF Model'!C19+4)+('DCF Model'!G39+'DCF Model'!G42)*D$17/(1+$B20)^('DCF Model'!C19+4)-'DCF Model'!C16)*1000000/'DCF Model'!C15,0),"") -> 1308 | E20: =IFERROR(ROUND(('DCF Model'!C45/(1+$B20)^('DCF Model'!C19+0)+'DCF Model'!D45/(1+$B20)^('DCF Model'!C19+1)+'DCF Model'!E45/(1+$B20)^('DCF Model'!C19+2)+'DCF Model'!F45/(1+$B20)^('DCF Model'!C19+3)+'DCF Model'!G45/(1+$B20)^('DCF Model'!C19+4)+('DCF Model'!G39+'DCF Model'!G42)*E$17/(1+$B20)^('DCF Model'!C19+4)-'DCF Model'!C16)*1000000/'DCF Model'!C15,0),"") -> 1460 | F20: =IFERROR(ROUND(('DCF Model'!C45/(1+$B20)^('DCF Model'!C19+0)+'DCF Model'!D45/(1+$B20)^('DCF Model'!C19+1)+'DCF Model'!E45/(1+$B20)^('DCF Model'!C19+2)+'DCF Model'!F45/(1+$B20)^('DCF Model'!C19+3)+'DCF Model'!G45/(1+$B20)^('DCF Model'!C19+4)+('DCF Model'!G39+'DCF Model'!G42)*F$17/(1+$B20)^('DCF Model'!C19+4)-'DCF Model'!C16)*1000000/'DCF Model'!C15,0),"") -> 1613 | G20: =IFERROR(ROUND(('DCF Model'!C45/(1+$B20)^('DCF Model'!C19+0)+'DCF Model'!D45/(1+$B20)^('DCF Model'!C19+1)+'DCF Model'!E45/(1+$B20)^('DCF Model'!C19+2)+'DCF Model'!F45/(1+$B20)^('DCF Model'!C19+3)+'DCF Model'!G45/(1+$B20)^('DCF Model'!C19+4)+('DCF Model'!G39+'DCF Model'!G42)*G$17/(1+$B20)^('DCF Model'!C19+4)-'DCF Model'!C16)*1000000/'DCF Model'!C15,0),"") -> 1765 | H20: =IFERROR(ROUND(('DCF Model'!C45/(1+$B20)^('DCF Model'!C19+0)+'DCF Model'!D45/(1+$B20)^('DCF Model'!C19+1)+'DCF Model'!E45/(1+$B20)^('DCF Model'!C19+2)+'DCF Model'!F45/(1+$B20)^('DCF Model'!C19+3)+'DCF Model'!G45/(1+$B20)^('DCF Model'!C19+4)+('DCF Model'!G39+'DCF Model'!G42)*H$17/(1+$B20)^('DCF Model'!C19+4)-'DCF Model'!C16)*1000000/'DCF Model'!C15,0),"") -> 1917 | I20: =IFERROR(ROUND(('DCF Model'!C45/(1+$B20)^('DCF Model'!C19+0)+'DCF Model'!D45/(1+$B20)^('DCF Model'!C19+1)+'DCF Model'!E45/(1+$B20)^('DCF Model'!C19+2)+'DCF Model'!F45/(1+$B20)^('DCF Model'!C19+3)+'DCF Model'!G45/(1+$B20)^('DCF Model'!C19+4)+('DCF Model'!G39+'DCF Model'!G42)*I$17/(1+$B20)^('DCF Model'!C19+4)-'DCF Model'!C16)*1000000/'DCF Model'!C15,0),"") -> 2070
B21: =$C$3 -> 0.10940607 | C21: =IFERROR(ROUND(('DCF Model'!C45/(1+$B21)^('DCF Model'!C19+0)+'DCF Model'!D45/(1+$B21)^('DCF Model'!C19+1)+'DCF Model'!E45/(1+$B21)^('DCF Model'!C19+2)+'DCF Model'!F45/(1+$B21)^('DCF Model'!C19+3)+'DCF Model'!G45/(1+$B21)^('DCF Model'!C19+4)+('DCF Model'!G39+'DCF Model'!G42)*C$17/(1+$B21)^('DCF Model'!C19+4)-'DCF Model'!C16)*1000000/'DCF Model'!C15,0),"") -> 1131 | D21: =IFERROR(ROUND(('DCF Model'!C45/(1+$B21)^('DCF Model'!C19+0)+'DCF Model'!D45/(1+$B21)^('DCF Model'!C19+1)+'DCF Model'!E45/(1+$B21)^('DCF Model'!C19+2)+'DCF Model'!F45/(1+$B21)^('DCF Model'!C19+3)+'DCF Model'!G45/(1+$B21)^('DCF Model'!C19+4)+('DCF Model'!G39+'DCF Model'!G42)*D$17/(1+$B21)^('DCF Model'!C19+4)-'DCF Model'!C16)*1000000/'DCF Model'!C15,0),"") -> 1280 | E21: =IFERROR(ROUND(('DCF Model'!C45/(1+$B21)^('DCF Model'!C19+0)+'DCF Model'!D45/(1+$B21)^('DCF Model'!C19+1)+'DCF Model'!E45/(1+$B21)^('DCF Model'!C19+2)+'DCF Model'!F45/(1+$B21)^('DCF Model'!C19+3)+'DCF Model'!G45/(1+$B21)^('DCF Model'!C19+4)+('DCF Model'!G39+'DCF Model'!G42)*E$17/(1+$B21)^('DCF Model'!C19+4)-'DCF Model'!C16)*1000000/'DCF Model'!C15,0),"") -> 1429 | F21: =IFERROR(ROUND(('DCF Model'!C45/(1+$B21)^('DCF Model'!C19+0)+'DCF Model'!D45/(1+$B21)^('DCF Model'!C19+1)+'DCF Model'!E45/(1+$B21)^('DCF Model'!C19+2)+'DCF Model'!F45/(1+$B21)^('DCF Model'!C19+3)+'DCF Model'!G45/(1+$B21)^('DCF Model'!C19+4)+('DCF Model'!G39+'DCF Model'!G42)*F$17/(1+$B21)^('DCF Model'!C19+4)-'DCF Model'!C16)*1000000/'DCF Model'!C15,0),"") -> 1578 | G21: =IFERROR(ROUND(('DCF Model'!C45/(1+$B21)^('DCF Model'!C19+0)+'DCF Model'!D45/(1+$B21)^('DCF Model'!C19+1)+'DCF Model'!E45/(1+$B21)^('DCF Model'!C19+2)+'DCF Model'!F45/(1+$B21)^('DCF Model'!C19+3)+'DCF Model'!G45/(1+$B21)^('DCF Model'!C19+4)+('DCF Model'!G39+'DCF Model'!G42)*G$17/(1+$B21)^('DCF Model'!C19+4)-'DCF Model'!C16)*1000000/'DCF Model'!C15,0),"") -> 1727 | H21: =IFERROR(ROUND(('DCF Model'!C45/(1+$B21)^('DCF Model'!C19+0)+'DCF Model'!D45/(1+$B21)^('DCF Model'!C19+1)+'DCF Model'!E45/(1+$B21)^('DCF Model'!C19+2)+'DCF Model'!F45/(1+$B21)^('DCF Model'!C19+3)+'DCF Model'!G45/(1+$B21)^('DCF Model'!C19+4)+('DCF Model'!G39+'DCF Model'!G42)*H$17/(1+$B21)^('DCF Model'!C19+4)-'DCF Model'!C16)*1000000/'DCF Model'!C15,0),"") -> 1876 | I21: =IFERROR(ROUND(('DCF Model'!C45/(1+$B21)^('DCF Model'!C19+0)+'DCF Model'!D45/(1+$B21)^('DCF Model'!C19+1)+'DCF Model'!E45/(1+$B21)^('DCF Model'!C19+2)+'DCF Model'!F45/(1+$B21)^('DCF Model'!C19+3)+'DCF Model'!G45/(1+$B21)^('DCF Model'!C19+4)+('DCF Model'!G39+'DCF Model'!G42)*I$17/(1+$B21)^('DCF Model'!C19+4)-'DCF Model'!C16)*1000000/'DCF Model'!C15,0),"") -> 2025
B22: =$C$3+0.005 -> 0.11440607 | C22: =IFERROR(ROUND(('DCF Model'!C45/(1+$B22)^('DCF Model'!C19+0)+'DCF Model'!D45/(1+$B22)^('DCF Model'!C19+1)+'DCF Model'!E45/(1+$B22)^('DCF Model'!C19+2)+'DCF Model'!F45/(1+$B22)^('DCF Model'!C19+3)+'DCF Model'!G45/(1+$B22)^('DCF Model'!C19+4)+('DCF Model'!G39+'DCF Model'!G42)*C$17/(1+$B22)^('DCF Model'!C19+4)-'DCF Model'!C16)*1000000/'DCF Model'!C15,0),"") -> 1107 | D22: =IFERROR(ROUND(('DCF Model'!C45/(1+$B22)^('DCF Model'!C19+0)+'DCF Model'!D45/(1+$B22)^('DCF Model'!C19+1)+'DCF Model'!E45/(1+$B22)^('DCF Model'!C19+2)+'DCF Model'!F45/(1+$B22)^('DCF Model'!C19+3)+'DCF Model'!G45/(1+$B22)^('DCF Model'!C19+4)+('DCF Model'!G39+'DCF Model'!G42)*D$17/(1+$B22)^('DCF Model'!C19+4)-'DCF Model'!C16)*1000000/'DCF Model'!C15,0),"") -> 1252 | E22: =IFERROR(ROUND(('DCF Model'!C45/(1+$B22)^('DCF Model'!C19+0)+'DCF Model'!D45/(1+$B22)^('DCF Model'!C19+1)+'DCF Model'!E45/(1+$B22)^('DCF Model'!C19+2)+'DCF Model'!F45/(1+$B22)^('DCF Model'!C19+3)+'DCF Model'!G45/(1+$B22)^('DCF Model'!C19+4)+('DCF Model'!G39+'DCF Model'!G42)*E$17/(1+$B22)^('DCF Model'!C19+4)-'DCF Model'!C16)*1000000/'DCF Model'!C15,0),"") -> 1398 | F22: =IFERROR(ROUND(('DCF Model'!C45/(1+$B22)^('DCF Model'!C19+0)+'DCF Model'!D45/(1+$B22)^('DCF Model'!C19+1)+'DCF Model'!E45/(1+$B22)^('DCF Model'!C19+2)+'DCF Model'!F45/(1+$B22)^('DCF Model'!C19+3)+'DCF Model'!G45/(1+$B22)^('DCF Model'!C19+4)+('DCF Model'!G39+'DCF Model'!G42)*F$17/(1+$B22)^('DCF Model'!C19+4)-'DCF Model'!C16)*1000000/'DCF Model'!C15,0),"") -> 1544 | G22: =IFERROR(ROUND(('DCF Model'!C45/(1+$B22)^('DCF Model'!C19+0)+'DCF Model'!D45/(1+$B22)^('DCF Model'!C19+1)+'DCF Model'!E45/(1+$B22)^('DCF Model'!C19+2)+'DCF Model'!F45/(1+$B22)^('DCF Model'!C19+3)+'DCF Model'!G45/(1+$B22)^('DCF Model'!C19+4)+('DCF Model'!G39+'DCF Model'!G42)*G$17/(1+$B22)^('DCF Model'!C19+4)-'DCF Model'!C16)*1000000/'DCF Model'!C15,0),"") -> 1689 | H22: =IFERROR(ROUND(('DCF Model'!C45/(1+$B22)^('DCF Model'!C19+0)+'DCF Model'!D45/(1+$B22)^('DCF Model'!C19+1)+'DCF Model'!E45/(1+$B22)^('DCF Model'!C19+2)+'DCF Model'!F45/(1+$B22)^('DCF Model'!C19+3)+'DCF Model'!G45/(1+$B22)^('DCF Model'!C19+4)+('DCF Model'!G39+'DCF Model'!G42)*H$17/(1+$B22)^('DCF Model'!C19+4)-'DCF Model'!C16)*1000000/'DCF Model'!C15,0),"") -> 1835 | I22: =IFERROR(ROUND(('DCF Model'!C45/(1+$B22)^('DCF Model'!C19+0)+'DCF Model'!D45/(1+$B22)^('DCF Model'!C19+1)+'DCF Model'!E45/(1+$B22)^('DCF Model'!C19+2)+'DCF Model'!F45/(1+$B22)^('DCF Model'!C19+3)+'DCF Model'!G45/(1+$B22)^('DCF Model'!C19+4)+('DCF Model'!G39+'DCF Model'!G42)*I$17/(1+$B22)^('DCF Model'!C19+4)-'DCF Model'!C16)*1000000/'DCF Model'!C15,0),"") -> 1981
B23: =$C$3+0.01 -> 0.11940607 | C23: =IFERROR(ROUND(('DCF Model'!C45/(1+$B23)^('DCF Model'!C19+0)+'DCF Model'!D45/(1+$B23)^('DCF Model'!C19+1)+'DCF Model'!E45/(1+$B23)^('DCF Model'!C19+2)+'DCF Model'!F45/(1+$B23)^('DCF Model'!C19+3)+'DCF Model'!G45/(1+$B23)^('DCF Model'!C19+4)+('DCF Model'!G39+'DCF Model'!G42)*C$17/(1+$B23)^('DCF Model'!C19+4)-'DCF Model'!C16)*1000000/'DCF Model'!C15,0),"") -> 1083 | D23: =IFERROR(ROUND(('DCF Model'!C45/(1+$B23)^('DCF Model'!C19+0)+'DCF Model'!D45/(1+$B23)^('DCF Model'!C19+1)+'DCF Model'!E45/(1+$B23)^('DCF Model'!C19+2)+'DCF Model'!F45/(1+$B23)^('DCF Model'!C19+3)+'DCF Model'!G45/(1+$B23)^('DCF Model'!C19+4)+('DCF Model'!G39+'DCF Model'!G42)*D$17/(1+$B23)^('DCF Model'!C19+4)-'DCF Model'!C16)*1000000/'DCF Model'!C15,0),"") -> 1225 | E23: =IFERROR(ROUND(('DCF Model'!C45/(1+$B23)^('DCF Model'!C19+0)+'DCF Model'!D45/(1+$B23)^('DCF Model'!C19+1)+'DCF Model'!E45/(1+$B23)^('DCF Model'!C19+2)+'DCF Model'!F45/(1+$B23)^('DCF Model'!C19+3)+'DCF Model'!G45/(1+$B23)^('DCF Model'!C19+4)+('DCF Model'!G39+'DCF Model'!G42)*E$17/(1+$B23)^('DCF Model'!C19+4)-'DCF Model'!C16)*1000000/'DCF Model'!C15,0),"") -> 1368 | F23: =IFERROR(ROUND(('DCF Model'!C45/(1+$B23)^('DCF Model'!C19+0)+'DCF Model'!D45/(1+$B23)^('DCF Model'!C19+1)+'DCF Model'!E45/(1+$B23)^('DCF Model'!C19+2)+'DCF Model'!F45/(1+$B23)^('DCF Model'!C19+3)+'DCF Model'!G45/(1+$B23)^('DCF Model'!C19+4)+('DCF Model'!G39+'DCF Model'!G42)*F$17/(1+$B23)^('DCF Model'!C19+4)-'DCF Model'!C16)*1000000/'DCF Model'!C15,0),"") -> 1510 | G23: =IFERROR(ROUND(('DCF Model'!C45/(1+$B23)^('DCF Model'!C19+0)+'DCF Model'!D45/(1+$B23)^('DCF Model'!C19+1)+'DCF Model'!E45/(1+$B23)^('DCF Model'!C19+2)+'DCF Model'!F45/(1+$B23)^('DCF Model'!C19+3)+'DCF Model'!G45/(1+$B23)^('DCF Model'!C19+4)+('DCF Model'!G39+'DCF Model'!G42)*G$17/(1+$B23)^('DCF Model'!C19+4)-'DCF Model'!C16)*1000000/'DCF Model'!C15,0),"") -> 1653 | H23: =IFERROR(ROUND(('DCF Model'!C45/(1+$B23)^('DCF Model'!C19+0)+'DCF Model'!D45/(1+$B23)^('DCF Model'!C19+1)+'DCF Model'!E45/(1+$B23)^('DCF Model'!C19+2)+'DCF Model'!F45/(1+$B23)^('DCF Model'!C19+3)+'DCF Model'!G45/(1+$B23)^('DCF Model'!C19+4)+('DCF Model'!G39+'DCF Model'!G42)*H$17/(1+$B23)^('DCF Model'!C19+4)-'DCF Model'!C16)*1000000/'DCF Model'!C15,0),"") -> 1795 | I23: =IFERROR(ROUND(('DCF Model'!C45/(1+$B23)^('DCF Model'!C19+0)+'DCF Model'!D45/(1+$B23)^('DCF Model'!C19+1)+'DCF Model'!E45/(1+$B23)^('DCF Model'!C19+2)+'DCF Model'!F45/(1+$B23)^('DCF Model'!C19+3)+'DCF Model'!G45/(1+$B23)^('DCF Model'!C19+4)+('DCF Model'!G39+'DCF Model'!G42)*I$17/(1+$B23)^('DCF Model'!C19+4)-'DCF Model'!C16)*1000000/'DCF Model'!C15,0),"") -> 1938
B24: =$C$3+0.015 -> 0.12440607 | C24: =IFERROR(ROUND(('DCF Model'!C45/(1+$B24)^('DCF Model'!C19+0)+'DCF Model'!D45/(1+$B24)^('DCF Model'!C19+1)+'DCF Model'!E45/(1+$B24)^('DCF Model'!C19+2)+'DCF Model'!F45/(1+$B24)^('DCF Model'!C19+3)+'DCF Model'!G45/(1+$B24)^('DCF Model'!C19+4)+('DCF Model'!G39+'DCF Model'!G42)*C$17/(1+$B24)^('DCF Model'!C19+4)-'DCF Model'!C16)*1000000/'DCF Model'!C15,0),"") -> 1060 | D24: =IFERROR(ROUND(('DCF Model'!C45/(1+$B24)^('DCF Model'!C19+0)+'DCF Model'!D45/(1+$B24)^('DCF Model'!C19+1)+'DCF Model'!E45/(1+$B24)^('DCF Model'!C19+2)+'DCF Model'!F45/(1+$B24)^('DCF Model'!C19+3)+'DCF Model'!G45/(1+$B24)^('DCF Model'!C19+4)+('DCF Model'!G39+'DCF Model'!G42)*D$17/(1+$B24)^('DCF Model'!C19+4)-'DCF Model'!C16)*1000000/'DCF Model'!C15,0),"") -> 1199 | E24: =IFERROR(ROUND(('DCF Model'!C45/(1+$B24)^('DCF Model'!C19+0)+'DCF Model'!D45/(1+$B24)^('DCF Model'!C19+1)+'DCF Model'!E45/(1+$B24)^('DCF Model'!C19+2)+'DCF Model'!F45/(1+$B24)^('DCF Model'!C19+3)+'DCF Model'!G45/(1+$B24)^('DCF Model'!C19+4)+('DCF Model'!G39+'DCF Model'!G42)*E$17/(1+$B24)^('DCF Model'!C19+4)-'DCF Model'!C16)*1000000/'DCF Model'!C15,0),"") -> 1339 | F24: =IFERROR(ROUND(('DCF Model'!C45/(1+$B24)^('DCF Model'!C19+0)+'DCF Model'!D45/(1+$B24)^('DCF Model'!C19+1)+'DCF Model'!E45/(1+$B24)^('DCF Model'!C19+2)+'DCF Model'!F45/(1+$B24)^('DCF Model'!C19+3)+'DCF Model'!G45/(1+$B24)^('DCF Model'!C19+4)+('DCF Model'!G39+'DCF Model'!G42)*F$17/(1+$B24)^('DCF Model'!C19+4)-'DCF Model'!C16)*1000000/'DCF Model'!C15,0),"") -> 1478 | G24: =IFERROR(ROUND(('DCF Model'!C45/(1+$B24)^('DCF Model'!C19+0)+'DCF Model'!D45/(1+$B24)^('DCF Model'!C19+1)+'DCF Model'!E45/(1+$B24)^('DCF Model'!C19+2)+'DCF Model'!F45/(1+$B24)^('DCF Model'!C19+3)+'DCF Model'!G45/(1+$B24)^('DCF Model'!C19+4)+('DCF Model'!G39+'DCF Model'!G42)*G$17/(1+$B24)^('DCF Model'!C19+4)-'DCF Model'!C16)*1000000/'DCF Model'!C15,0),"") -> 1617 | H24: =IFERROR(ROUND(('DCF Model'!C45/(1+$B24)^('DCF Model'!C19+0)+'DCF Model'!D45/(1+$B24)^('DCF Model'!C19+1)+'DCF Model'!E45/(1+$B24)^('DCF Model'!C19+2)+'DCF Model'!F45/(1+$B24)^('DCF Model'!C19+3)+'DCF Model'!G45/(1+$B24)^('DCF Model'!C19+4)+('DCF Model'!G39+'DCF Model'!G42)*H$17/(1+$B24)^('DCF Model'!C19+4)-'DCF Model'!C16)*1000000/'DCF Model'!C15,0),"") -> 1757 | I24: =IFERROR(ROUND(('DCF Model'!C45/(1+$B24)^('DCF Model'!C19+0)+'DCF Model'!D45/(1+$B24)^('DCF Model'!C19+1)+'DCF Model'!E45/(1+$B24)^('DCF Model'!C19+2)+'DCF Model'!F45/(1+$B24)^('DCF Model'!C19+3)+'DCF Model'!G45/(1+$B24)^('DCF Model'!C19+4)+('DCF Model'!G39+'DCF Model'!G42)*I$17/(1+$B24)^('DCF Model'!C19+4)-'DCF Model'!C16)*1000000/'DCF Model'!C15,0),"") -> 1896
B26: All values dynamically linked to DCF Model. Headers auto-center on current WACC / Terminal g / Exit Multiple.

Sheet Adjustments Log
B2: Adjustments Log - Nitto Boseki
B4: 日付 | C4: セル | D4: 変更内容 | E4: 理由 | F4: 元の値 | G4: 状態
B5: 2026-08-22 | C5: - | D5: Generated by pipeline on 2026-08-22 13:35, template rev e5effd6 | E5: 初期生成（手修正なし） | F5: - | G5: generated
B6: 2026-08-22 | C6: 'DCF Model'!C5 | D6: capex_pct = 8.5% (single value) applied to all 5 projection years | E6: overrides_validator の ALLOWED_KEYS で capex_pct は数値スカラーのみ(配列は契約違反)。プロンプト指定の年次テーパー [0.15,0.13,0.10,0.085,0.080] を表現できず、ターミナル整合(capex/D&A = 1.02x)を優先して Y5 近傍の単一値を採用した。 | F6: - | G6: 未解決
B7: 2026-08-22 | C7: 'DCF Model'!C43 (Y1-Y2) | D7: Y1-Y2 の capex が実勢(FY2026/3 実績 売上比17.4%、建設仮勘定12,067)を大幅に過小評価 | E7: 単一値8.5%のため増産投資期の初期2年の投資額が約半分になり、その分だけY1-Y2 の FCF が過大に出る。PGM/Exit いずれの Target も上振れ方向のバイアスを持つ。年次配列が必要なら capex_method='direct' への切替をスキーマ側で再検討すること。 | F7: - | G7: 未解決
B8: 2026-08-22 | C8: 'Segment Bridge'!E?? / D?? | D8: Segment Bridge の tie-out 差異: Q1営業利益 -12、FY2026/3 D&A +40 | E8: 開示セグメント数値(百万円丸め)の積上げと連結開示値の差。ゼロに強制せず差異行として表示。 | F8: - | G8: 未解決
B12: Pipeline Metadata (do not edit — read by scripts/validate_output.py)
B13: key | C13: value
B14: capex_pct_basis | C14: assumption
B15: capex_pct_c5 | C15: 0.085
B16: capex_pct_hist3yr | C16: 0.122852
B17: company_name | C17: Nitto Boseki
B18: comps_asof | C18: 2026-08-22
B19: comps_da_missing | C19: none
B20: comps_ev_ebitda_invalid | C20: no
B21: comps_ev_ebitda_rows | C21: 6,7,8,9,10,11
B22: comps_impl_mult_row | C22: 27
B23: comps_impl_per_row | C23: 28
B24: comps_peer_rows | C24: 6,7,8,9,10,11
... B40: ticker | C40: 3110.T

Sheet Segment Bridge
B2: Segment Bridge - Nitto Boseki (3110)
B3: Segment profit total less corporate costs / eliminations reconciled to consolidated operating profit. All figures JPY mn.
B4: Only 2 full FYs plus Q1 are disclosed on a comparable basis - too few for the 3-year hist_years array - hence this separate sheet rather than a 'segments' override block.
B6: 1. Segment Revenue (JPY mn)
B7: Segment | C7: FY2025/3 | D7: FY2026/3 | E7: Q1 FY2027/3 | F7: Note
B8: Electronic Materials 電子材料 | C8: 52093 | D8: 61418 | E8: 18082
B9: Medical メディカル | C9: 13619 | D9: 13935 | E9: 3853
B10: Composite Materials 複合材 | C10: 14520 | D10: 14457 | E10: 4093
B11: Capital & Chemicals 資本・ケミカル | C11: 11968 | D11: 11726 | E11: 3142
B12: Insulation 断熱材 | C12: 15352 | D12: 15165 | E12: 4399
B13: Other その他 | C13: 19586 | D13: 22128 | E13: 6784
B14: Segment total セグメント計 | C14: =SUM(C8:C13) -> 127138 | D14: =SUM(D8:D13) -> 138829 | E14: =SUM(E8:E13) -> 40353
B15: Adjustment 調整額 (内部売上高消去等) | C15: =109035-C14 -> -18103 | D15: =118229-D14 -> -20600 | E15: =34033-E14 -> -6320 | F15: Derived as a residual - the disclosed segment note gives the profit adjustment only.
B16: Consolidated revenue 連結売上高 | C16: 109035 | D16: 118229 | E16: 34033 | F16: Q1 revenue 34,033 is the same figure used in the LTM bridge (118,229 - 28,231 + 34,033 = 124,031).
B18: 2. Segment Profit to Consolidated Operating Profit (JPY mn)
B19: Segment | C19: FY2025/3 | D19: FY2026/3 | E19: Q1 FY2027/3 | F19: Note
B20: Electronic Materials 電子材料 | C20: 13880 | D20: 19391 | E20: 7036
B21: Medical メディカル | C21: 2381 | D21: 2431 | E21: 705
B22: Composite Materials 複合材 | C22: -900 | D22: -122 | E22: 0
B23: Capital & Chemicals 資本・ケミカル | C23: 839 | D23: 588 | E23: 222
B24: Insulation 断熱材 | C24: 693 | D24: 202 | E24: 251
B25: Other その他 | C25: 409 | D25: 488 | E25: 203
B26: Segment profit total セグメント利益計 | C26: =SUM(C20:C25) -> 17302 | D26: =SUM(D20:D25) -> 22978 | E26: =SUM(E20:E25) -> 8417
B27: Adjustment 調整額 (全社費用・消去) | C27: -858 | D27: -2160 | E27: -486
B28: Bridged operating profit 計算値 | C28: =C26+C27 -> 16444 | D28: =D26+D27 -> 20818 | E28: =E26+E27 -> 7931
B29: Consolidated operating profit 連結営業利益 (開示値) | C29: 16445 | D29: 20819 | E29: 7943
B30: Variance 差異 (計算値 - 開示値) | C30: =C28-C29 -> -1 | D30: =D28-D29 -> -1 | E30: =E28-E29 -> -12 | F30: Rounding of the disclosed JPY mn segment figures. A non-zero variance is shown rather than forced to zero.
B32: 3. Segment vs Consolidated Operating Margin
B33: Metric | C33: FY2025/3 | D33: FY2026/3 | E33: Q1 FY2027/3 | F33: Note
B34: Electronic Materials segment margin | C34: =IFERROR(C20/C8,"") -> 0.26644655 | D34: =IFERROR(D20/D8,"") -> 0.31572178 | E34: =IFERROR(E20/E8,"") -> 0.38911625 | F34: The single driver of the consolidated margin expansion.
B35: Consolidated operating margin | C35: =IFERROR(C29/C16,"") -> 0.15082313 | D35: =IFERROR(D29/D16,"") -> 0.17609047 | E35: =IFERROR(E29/E16,"") -> 0.23339112
B36: Electronic Materials share of segment profit | C36: =IFERROR(C20/C26,"") -> 0.8022194 | D36: =IFERROR(D20/D26,"") -> 0.84389416 | E36: =IFERROR(E20/E26,"") -> 0.83592729 | F36: Concentration measure: the DCF's margin path is effectively a single-segment call.
B37: Electronic Materials share of revenue | C37: =IFERROR(C8/C14,"") -> 0.40973588 | D37: =IFERROR(D8/D14,"") -> 0.44240036 | E37: =IFERROR(E8/E14,"") -> 0.44809556
B39: 4. FY2026/3 D&A by Segment and Segment EBITDA (JPY mn)
B40: Segment | C40: Segment profit | D40: D&A | E40: Segment EBITDA | F40: Note
B41: Electronic Materials 電子材料 | C41: =D20 -> 19391 | D41: 7229 | E41: =C41+D41 -> 26620
B42: Medical メディカル | C42: =D21 -> 2431 | D42: 751 | E42: =C42+D42 -> 3182
B43: Composite Materials 複合材 | C43: =D22 -> -122 | D43: 180 | E43: =C43+D43 -> 58
B44: Capital & Chemicals 資本・ケミカル | C44: =D23 -> 588 | D44: 261 | E44: =C44+D44 -> 849
B45: Insulation 断熱材 | C45: =D24 -> 202 | D45: 614 | E45: =C45+D45 -> 816
...
