Workbook

Sheet Executive Summary
B1: DISCLAIMER: This is a sample analysis for demonstration purposes only. It does not constitute investment advice.
B3: 株式会社フィックスターズ (3687.T)
B4: Equity Research Report
B6: Company | C6: 株式会社フィックスターズ
B7: Ticker | C7: 3687.T (TSE)
B8: Sector | C8: Information & Communication (software / AI optimization)
B9: Current Price | C9: 2079
B10: Target Price (Mid) | C10: =ROUND(AVERAGE(C16:C19),0) -> 1381
B11: Recommendation | C11: =IF(C12>0.15,"BUY",IF(C12>0.05,"HOLD","SELL")) -> SELL
B12: Upside / Downside | C12: =(C10-C9)/C9 -> -0.33573834
B14: Valuation Summary
B15: Methodology | C15: Implied Value (JPY) | D15: vs Current Price
B16: DCF - Perpetuity Growth | C16: ='DCF Model'!C55 -> 970 | D16: =(C16-C9)/C9 -> -0.53342953
B17: DCF - Exit Multiple | C17: ='DCF Model'!C64 -> 1559 | D17: =(C17-C9)/C9 -> -0.25012025
B18: Comps - EV/EBITDA Median | C18: ='Comps Analysis'!C27 -> 1256 | D18: =IF(ISNUMBER(C18),(C18-C9)/C9,"N/A") -> -0.3958634
B19: Comps - PER Median | C19: ='Comps Analysis'!C28 -> 1737 | D19: =IF(ISNUMBER(C19),(C19-C9)/C9,"N/A") -> -0.16450216
B21: Integrated Valuation Range | C21: =MIN(C16:C19)&" - "&MAX(C16:C19) -> 970 - 1737
B23: Key Investment Thesis
B24: 1. The consolidated 26.8% operating margin understates the core franchise. The Solution segment earned 3,236 on 9,171 of revenue, a 35.3% margin, up from 32.0% a year earlier. The gap to the consolidated figure is deliberate investment: SaaS lost 424 and the CVC book took a 232 securities writedown that runs through cost of sales. Strip both and the normalised margin is about 29%.
B25: 2. Asset-light compounding with no leverage. Revenue grew from 6,311 to 9,618 over three years, a 15.1% CAGR, on capex averaging under 1.5% of revenue and D&A of 1.7%. Long-term borrowings were fully repaid in FY2025/9, leaving net cash of 5,131 and an interest coverage ratio of 3,597x. ROE is 26.0% with an 83.6% equity ratio.
B26: 3. AI demand is the stated growth vector and it is already showing in the mix. Revenue recognised over time rose from 1,465 to 2,466 (+68%), indicating a shift toward longer, stickier engagements, while the "Speed up your AI" repositioning targets AI development acceleration where the company's optimisation expertise transfers directly.
B28: Key Risks
B29: 1. Customer concentration is severe and cyclically exposed. Kioxia alone was 1,647 of revenue, or 17.1%, and Nexty Electronics 1,119, or 11.6% - 28.8% from two names. Renesas was a further 16.0% in the prior year. These are semiconductor customers whose R&D budgets move with the NAND and MCU cycles, so a memory downcycle transmits directly into Solution revenue.
B30: 2. FY2026/9 guidance is for a 17.8% fall in parent net income. Management cites headquarters relocation costs, higher rent, large wage increases, and the reversal of a one-off tax benefit from the Sider liquidation. Operating profit is guided merely flat at 2,600 (+0.8%), so the growth narrative pauses for a year even on the company's own numbers.
B31: 3. Valuation leaves no margin for error. At 2,079 the shares trade at 34.5x trailing and 41.9x guided earnings, 8.13x book and 22.6x EV/EBITDA, against an exit multiple assumption of 12.0x. The SaaS segment has consumed 575 of cumulative operating losses over two years with no revenue inflection yet - 446 of revenue against a 424 loss.

Sheet Financial Statements
B2: 株式会社フィックスターズ - Historical Financials (JPY mn)
C4: FY2022/9 | D4: FY2023/9 | E4: FY2024/9 | F4: FY2025/9
B5: Income Statement
B6: Revenue | C6: 6311 | D6: 7038 | E6: 7995 | F6: 9618
B7: COGS | C7: 3285 | D7: 3463 | E7: 3817 | F7: 4611
B8: Gross Profit | C8: =C6-C7 -> 3026 | D8: =D6-D7 -> 3575 | E8: =E6-E7 -> 4178 | F8: =F6-F7 -> 5007
B9: Gross Margin | C9: =C8/C6 -> 0.47948027 | D9: =D8/D6 -> 0.50795681 | E9: =E8/E6 -> 0.52257661 | F9: =F8/F6 -> 0.5205864
B10: SGA | C10: 1402 | D10: 1489 | E10: 1874 | F10: 2428
B11: Operating Income | C11: 1624 | D11: 2086 | E11: 2304 | F11: 2578
B12: Net Income | C12: 1083 | D12: 1448 | E12: 1494 | F12: 1945
B13: Operating Margin | C13: =C11/C6 -> 0.25732847 | D13: =D11/D6 -> 0.29639102 | E13: =E11/E6 -> 0.28818011 | F13: =F11/F6 -> 0.26803909
B14: Net Margin | C14: =C12/C6 -> 0.17160513 | D14: =D12/D6 -> 0.20574027 | E14: =E12/E6 -> 0.18686679 | F14: =F12/F6 -> 0.20222499
B15: Revenue Growth (YoY) | C15: n/a | D15: =(D6-C6)/C6 -> 0.11519569 | E15: =(E6-D6)/D6 -> 0.13597613 | F15: =(F6-E6)/E6 -> 0.20300188
B16: Operating Income Growth (YoY) | C16: n/a | D16: =(D11-C11)/C11 -> 0.28448276 | E16: =(E11-D11)/D11 -> 0.10450623 | F16: =(F11-E11)/E11 -> 0.11892361
B18: Cash Flow Statement
B19: Operating Cash Flow | C19: 1488 | D19: 719 | E19: 1656 | F19: 1979
B20: Capex (有形固定資産の取得) | C20: 41 | D20: 38 | E20: 165 | F20: 110
B21: Free Cash Flow | C21: =C19-C20 -> 1447 | D21: =D19-D20 -> 681 | E21: =E19-E20 -> 1491 | F21: =F19-F20 -> 1869
B22: FCF Margin | C22: =C21/C6 -> 0.22928221 | D22: =D21/D6 -> 0.096760443 | E22: =E21/E6 -> 0.18649156 | F22: =F21/F6 -> 0.19432314
B23: Capex / Revenue | C23: =C20/C6 -> 0.0064965932 | D23: =D20/D6 -> 0.0053992612 | E23: =E20/E6 -> 0.020637899 | F23: =F20/F6 -> 0.011436889
B25: Balance Sheet Highlights
B26: Cash & Deposits (現金及び預金) | C26: 5057 | D26: 4629 | E26: 4856 | F26: 5178
B27: Interest-Bearing Debt (borrowings + lease) | C27: 2104 | D27: 1297 | E27: 547 | F27: 47
B28: Net Debt (Cash) - financial only, excl. MI | C28: =C27-C26 -> -2953 | D28: =D27-D26 -> -3332 | E28: =E27-E26 -> -4309 | F28: =F27-F26 -> -5131
B30: Source: 決算短信 FY2023/9 and FY2025/9, 連結キャッシュ・フロー計算書 and 連結貸借対照表, converted from 千円 to 百万円. Operating cash flow 1,488,034 / 719,450 / 1,656,074 / 1,978,609 千円. Cash & deposits 5,056,616 / 4,629,112 / 4,856,480 / 5,178,150 千円. Interest-bearing debt = 1年内返済予定の長期借入金 + 長期借入金 + リース債務(流動+固定).
B31: Fixstars became effectively debt-free in FY2025/9: the remaining 493,018 千円 of long-term borrowings was repaid, leaving only 47,176 千円 of lease liabilities against 5,178,150 千円 of cash. Interest coverage was 3,597x and the 短信 reports a cash-flow to interest-bearing-debt ratio of 0.0 years.
B32: Row 28 (-5,131 at FY2025/9) is the FINANCIAL component of 'DCF Model'!C16 = -4,856. The 275 difference is non-controlling interests (274,530 千円), folded into net debt in the DCF because the template computes Equity = EV - net_debt and has no separate minority-interest deduction. Because net debt stays negative, de_ratio remains 0 and WACC equals the cost of equity.
B33: Not deducted as a non-operating asset: 敷金及び保証金 of 513,375 千円 (513, or about 16 per share), the deposit on the new head office. Recoverable on exit, so an argument exists for treating it as surplus.
B34: Income Statement rows are 決算短信 actuals converted from 千円: revenue 6,310,732 / 7,038,276 / 7,995,406 / 9,617,686. Operating income reconciles to Revenue - COGS - SGA within 1 for all four years. FY2025/9 COGS includes a 232,459 千円 securities writedown on the CVC book - see the Segment Bridge sheet for the normalisation.

Sheet DCF Model
B2: DCF Valuation Model - 株式会社フィックスターズ
B4: Assumptions
B5: Capex / Revenue | C5: 0.011436889
B6: Effective Tax Rate | C6: 0.32
B7: Risk-Free Rate | C7: 0.023
B8: Beta | C8: 1.04
B9: Equity Risk Premium | C9: 0.06
B10: Size Premium | C10: 0.03
B11: After-tax Cost of Debt | C11: 0.008
B12: D/E Ratio | C12: 0
B13: Terminal Growth Rate | C13: 0.015
B14: Exit Multiple (EV/EBITDA) | C14: 12
B15: Fully Diluted Shares | C15: 32252858
B16: Net Debt (JPY mn) | C16: -4856
... B20: LTM Revenue (JPY mn) | C20: 10276.9
B22: WACC Calculation
B23: Cost of Equity (Ke) | C23: =C7+C8*C9+C10 -> 0.1154
B24: Weight of Equity | C24: =1/(1+C12) -> 1
B25: Weight of Debt | C25: =C12/(1+C12) -> 0
B26: WACC | C26: =C23*C24+C11*C25 -> 0.1154
B27: Active Scenario | C27: Base | D27: =MATCH(C27,B69:B73,0) -> 1
B28: Projected Free Cash Flow
C29: FY2026(E) | D29: FY2027(E) | E29: FY2028(E) | F29: FY2029(E) | G29: FY2030(E)
B30: Revenue Growth (YoY) | C30: =CHOOSE($D$27,C69,C70,C71,C72,C73) -> 0.12 | D30: =CHOOSE($D$27,D69,D70,D71,D72,D73) -> 0.13 | E30: =CHOOSE($D$27,E69,E70,E71,E72,E73) -> 0.12 | F30: =CHOOSE($D$27,F69,F70,F71,F72,F73) -> 0.1 | G30: =CHOOSE($D$27,G69,G70,G71,G72,G73) -> 0.09
B31: COGS % of Revenue | C31: =CHOOSE($D$27,C76,C77,C78,C79,C80) -> 0.465 | D31: =CHOOSE($D$27,D76,D77,D78,D79,D80) -> 0.46 | E31: =CHOOSE($D$27,E76,E77,E78,E79,E80) -> 0.455 | F31: =CHOOSE($D$27,F76,F77,F78,F79,F80) -> 0.453 | G31: =CHOOSE($D$27,G76,G77,G78,G79,G80) -> 0.45
B32: SGA % of Revenue | C32: =CHOOSE($D$27,C83,C84,C85,C86,C87) -> 0.255 | D32: =CHOOSE($D$27,D83,D84,D85,D86,D87) -> 0.25 | E32: =CHOOSE($D$27,E83,E84,E85,E86,E87) -> 0.245 | F32: =CHOOSE($D$27,F83,F84,F85,F86,F87) -> 0.242 | G32: =CHOOSE($D$27,G83,G84,G85,G86,G87) -> 0.24
B33: Revenue | C33: =C17*(1+C30) -> 10772.16 | D33: =C33*(1+D30) -> 12172.541 | E33: =D33*(1+E30) -> 13633.246 | F33: =E33*(1+F30) -> 14996.57 | G33: =F33*(1+G30) -> 16346.262
B34: COGS | C34: =C33*C31 -> 5009.0544 | D34: =D33*D31 -> 5599.3688 | E34: =E33*E31 -> 6203.1268 | F34: =F33*F31 -> 6793.4463 | G34: =G33*G31 -> 7355.8177
B35: Gross Profit | C35: =C33-C34 -> 5763.1056 | D35: =D33-D34 -> 6573.172 | E35: =E33-E34 -> 7430.1189 | F35: =F33-F34 -> 8203.1239 | G35: =G33-G34 -> 8990.4439
B36: Gross Margin | C36: =C35/C33 -> 0.535 | D36: =D35/D33 -> 0.54 | E36: =E35/E33 -> 0.545 | F36: =F35/F33 -> 0.547 | G36: =G35/G33 -> 0.55
B37: SGA Expense | C37: =C33*C32 -> 2746.9008 | D37: =D33*D32 -> 3043.1352 | E37: =E33*E32 -> 3340.1452 | F37: =F33*F32 -> 3629.17 | G37: =G33*G32 -> 3923.1028
B38: Implied Operating Margin | C38: =(C35-C37)/C33 -> 0.28 | D38: =(D35-D37)/D33 -> 0.29 | E38: =(E35-E37)/E33 -> 0.3 | F38: =(F35-F37)/F33 -> 0.305 | G38: =(G35-G37)/G33 -> 0.31
B39: Operating Income (EBIT) | C39: =C35-C37 -> 3016.2048 | D39: =D35-D37 -> 3530.0368 | E39: =E35-E37 -> 4089.9737 | F39: =F35-F37 -> 4573.9539 | G39: =G35-G37 -> 5067.3411
B40: Less: Tax | C40: =MAX(0,C39*C6) -> 965.18554 | D40: =MAX(0,D39*C6) -> 1129.6118 | E40: =MAX(0,E39*C6) -> 1308.7916 | F40: =MAX(0,F39*C6) -> 1463.6653 | G40: =MAX(0,G39*C6) -> 1621.5491
B41: NOPAT | C41: =C39-C40 -> 2051.0193 | D41: =D39-D40 -> 2400.425 | E41: =E39-E40 -> 2781.1821 | F41: =F39-F40 -> 3110.2887 | G41: =G39-G40 -> 3445.7919
B42: Plus: D&A | C42: 200 | D42: 230 | E42: 250 | F42: 265 | G42: 280
B43: Less: Capex | C43: 400 | D43: 250 | E43: 220 | F43: 230 | G43: 240
B44: Change in NWC | C44: ='NWC Schedule'!D19 -> 343.63172 | D44: ='NWC Schedule'!E19 -> 394.34959 | E44: ='NWC Schedule'!F19 -> 411.66533 | F44: ='NWC Schedule'!G19 -> 383.48639 | G44: ='NWC Schedule'!H19 -> 380.2555
B45: Unlevered Free Cash Flow | C45: =C41+C42-C43-C44 -> 1507.3875 | D45: =D41+D42-D43-D44 -> 1986.0755 | E45: =E41+E42-E43-E44 -> 2399.5168 | F45: =F41+F42-F43-F44 -> 2761.8023 | G45: =G41+G42-G43-G44 -> 3105.5364
B46: Discount Factor | C46: =1/(1+C26)^(C19+0) -> 0.89653936 | D46: =1/(1+C26)^(C19+1) -> 0.80378282 | E46: =1/(1+C26)^(C19+2) -> 0.72062293 | F46: =1/(1+C26)^(C19+3) -> 0.64606682 | G46: =1/(1+C26)^(C19+4) -> 0.57922433
...

Sheet NWC Schedule
B2: NWC Schedule - 株式会社フィックスターズ
B4: Working Capital Drivers (Days) | C4: Base Year | D4: FY2026(E) | E4: FY2027(E) | F4: FY2028(E) | G4: FY2029(E) | H4: FY2030(E)
B5: DSO (Days Sales Outstanding) | C5: =C12/C9*365 -> 106.82834 | D5: =CHOOSE('DCF Model'!$D$27,D25,D26,D27,D28,D29) -> 107 | E5: =CHOOSE('DCF Model'!$D$27,E25,E26,E27,E28,E29) -> 107 | F5: =CHOOSE('DCF Model'!$D$27,F25,F26,F27,F28,F29) -> 107 | G5: =CHOOSE('DCF Model'!$D$27,G25,G26,G27,G28,G29) -> 107 | H5: =CHOOSE('DCF Model'!$D$27,H25,H26,H27,H28,H29) -> 107
B6: DIH (Days Inventory Held) | C6: =C13/C10*365 -> 0.31663414 | D6: =CHOOSE('DCF Model'!$D$27,D32,D33,D34,D35,D36) -> 1 | E6: =CHOOSE('DCF Model'!$D$27,E32,E33,E34,E35,E36) -> 1 | F6: =CHOOSE('DCF Model'!$D$27,F32,F33,F34,F35,F36) -> 1 | G6: =CHOOSE('DCF Model'!$D$27,G32,G33,G34,G35,G36) -> 1 | H6: =CHOOSE('DCF Model'!$D$27,H32,H33,H34,H35,H36) -> 1
B7: DPO (Days Payable Outstanding) | C7: =C15/C10*365 -> 11.240512 | D7: =CHOOSE('DCF Model'!$D$27,D39,D40,D41,D42,D43) -> 11 | E7: =CHOOSE('DCF Model'!$D$27,E39,E40,E41,E42,E43) -> 11 | F7: =CHOOSE('DCF Model'!$D$27,F39,F40,F41,F42,F43) -> 11 | G7: =CHOOSE('DCF Model'!$D$27,G39,G40,G41,G42,G43) -> 11 | H7: =CHOOSE('DCF Model'!$D$27,H39,H40,H41,H42,H43) -> 11
B8: P&L Reference (JPY mn)
B9: Revenue | C9: 9618 | D9: ='DCF Model'!C33 -> 10772.16 | E9: ='DCF Model'!D33 -> 12172.541 | F9: ='DCF Model'!E33 -> 13633.246 | G9: ='DCF Model'!F33 -> 14996.57 | H9: ='DCF Model'!G33 -> 16346.262
B10: COGS | C10: 4611 | D10: ='DCF Model'!C34 -> 5009.0544 | E10: ='DCF Model'!D34 -> 5599.3688 | F10: ='DCF Model'!E34 -> 6203.1268 | G10: ='DCF Model'!F34 -> 6793.4463 | H10: ='DCF Model'!G34 -> 7355.8177
B11: Working Capital Items (JPY mn)
B12: Accounts Receivable | C12: 2815 | D12: =D9*D5/365 -> 3157.8661 | E12: =E9*E5/365 -> 3568.3887 | F12: =F9*F5/365 -> 3996.5953 | G12: =G9*G5/365 -> 4396.2548 | H12: =H9*H5/365 -> 4791.9178
B13: Inventory | C13: 4 | D13: =D10*D6/365 -> 13.723437 | E13: =E10*E6/365 -> 15.340736 | F13: =F10*F6/365 -> 16.994868 | G13: =G10*G6/365 -> 18.612182 | H13: =H10*H6/365 -> 20.152925
B14: Current Assets (AR + Inv) | C14: =C12+C13 -> 2819 | D14: =D12+D13 -> 3171.5895 | E14: =E12+E13 -> 3583.7294 | F14: =F12+F13 -> 4013.5902 | G14: =G12+G13 -> 4414.867 | H14: =H12+H13 -> 4812.0707
B15: Accounts Payable | C15: 142 | D15: =D10*D7/365 -> 150.9578 | E15: =E10*E7/365 -> 168.7481 | F15: =F10*F7/365 -> 186.94355 | G15: =G10*G7/365 -> 204.734 | H15: =H10*H7/365 -> 221.68218
B16: Current Liabilities (AP) | C16: =C15 -> 142 | D16: =D15 -> 150.9578 | E16: =E15 -> 168.7481 | F16: =F15 -> 186.94355 | G16: =G15 -> 204.734 | H16: =H15 -> 221.68218
B17: Net Working Capital (JPY mn)
B18: Net Working Capital | C18: =C14-C16 -> 2677 | D18: =D14-D16 -> 3020.6317 | E18: =E14-E16 -> 3414.9813 | F18: =F14-F16 -> 3826.6466 | G18: =G14-G16 -> 4210.133 | H18: =H14-H16 -> 4590.3885
B19: Change in NWC | C19: n/a | D19: =D18-C18 -> 343.63172 | E19: =E18-D18 -> 394.34959 | F19: =F18-E18 -> 411.66533 | G19: =G18-F18 -> 383.48639 | H19: =H18-G18 -> 380.2555
B22: Scenario Input Matrix (Working Capital Days)
D23: FY2026(E) | E23: FY2027(E) | F23: FY2028(E) | G23: FY2029(E) | H23: FY2030(E)
B24: DSO (Days)
B25: Base | D25: 107 | E25: 107 | F25: 107 | G25: 107 | H25: 107
B26: Upside | D26: 105 | E26: 103 | F26: 101 | G26: 100 | H26: 100
B27: Management | D27: 107 | E27: 107 | F27: 107 | G27: 107 | H27: 107
B28: Downside 1 | D28: 110 | E28: 115 | F28: 113 | G28: 112 | H28: 112
B29: Downside 2 | D29: 115 | E29: 125 | F29: 122 | G29: 120 | H29: 120
B31: DIH (Days)
B32: Base | D32: 1 | E32: 1 | F32: 1 | G32: 1 | H32: 1
B33: Upside | D33: 1 | E33: 1 | F33: 1 | G33: 1 | H33: 1
B34: Management | D34: 1 | E34: 1 | F34: 1 | G34: 1 | H34: 1
B35: Downside 1 | D35: 1 | E35: 1 | F35: 1 | G35: 1 | H35: 1
B36: Downside 2 | D36: 2 | E36: 2 | F36: 2 | G36: 2 | H36: 2
B38: DPO (Days)
B39: Base | D39: 11 | E39: 11 | F39: 11 | G39: 11 | H39: 11
B40: Upside | D40: 12 | E40: 12 | F40: 12 | G40: 12 | H40: 12
B41: Management | D41: 11 | E41: 11 | F41: 11 | G41: 11 | H41: 11
B42: Downside 1 | D42: 11 | E42: 11 | F42: 11 | G42: 11 | H42: 11
B43: Downside 2 | D43: 10 | E43: 10 | F43: 10 | G43: 10 | H43: 10

Sheet Comps Analysis
B2: Comparable Company Analysis
B4: Company | C4: Ticker | D4: Mkt Cap (JPY mn) | E4: EV (JPY mn) | F4: Revenue (JPY mn) | G4: EBITDA (JPY mn) | H4: Op Income (JPY mn) | I4: Net Income (JPY mn) | J4: EV/EBITDA | K4: EV/Revenue | L4: PER | M4: PBR | N4: Op Margin | O4: ROE | P4: EV/EBIT
B5: Fixstars | C5: 3687.T | D5: 67054 | E5: 62198 | F5: 9618 | G5: 2745 | H5: 2578 | I5: 1945 | J5: =E5/G5 -> 22.658652 | K5: =E5/F5 -> 6.466833 | L5: =D5/I5 -> 34.475064 | M5: 8.1307142 | N5: =H5/F5 -> 0.26803909 | O5: 0.23584334 | P5: =IFERROR(E5/H5,"") -> 24.126455
B6: Base Corporation | C6: 4481.T | D6: 59170 | E6: 46234 | F6: 21787 | G6: 5766 | H6: 5750 | I6: 4221 | J6: =E6/G6 -> 8.0183836 | K6: =E6/F6 -> 2.1220912 | L6: =D6/I6 -> 14.018005 | M6: 4.0474725 | N6: =H6/F6 -> 0.26391885 | O6: 0.28873384 | P6: =IFERROR(E6/H6,"") -> 8.0406957
B7: PKSHA Technology | C7: 3993.T | D7: 85980 | E7: 77823 | F7: 21771 | G7: 5991 | H7: 4005 | I7: 2683 | J7: =E7/G7 -> 12.989985 | K7: =E7/F7 -> 3.5746176 | L7: =D7/I7 -> 32.046217 | M7: 2.3680079 | N7: =H7/F7 -> 0.18396031 | O7: 0.073893525 | P7: =IFERROR(E7/H7,"") -> 19.431461
B8: Baycurrent Consulting | C8: 6532.T | D8: 1090000 | E8: 1024267 | F8: 148332 | G8: 53456 | H8: 50931 | I8: 37840 | J8: =E8/G8 -> 19.160936 | K8: =E8/F8 -> 6.9052329 | L8: =D8/I8 -> 28.805497 | M8: 9.3132145 | N8: =H8/F8 -> 0.34335814 | O8: 0.3233138 | P8: =IFERROR(E8/H8,"") -> 20.110875
B9: TIS Inc. | C9: 3626.T | D9: 826510 | E9: 771009 | F9: 596479 | G9: 94915 | H9: 76229 | I9: 46624 | J9: =E9/G9 -> 8.1231523 | K9: =E9/F9 -> 1.2926004 | L9: =D9/I9 -> 17.727136 | M9: 2.5452222 | N9: =H9/F9 -> 0.1277983 | O9: 0.14357774 | P9: =IFERROR(E9/H9,"") -> 10.114379
B10: FRONTEO | C10: 2158.T | D10: 24100 | E10: 26389 | F10: 7643 | G10: 1163 | H10: 721 | I10: 544 | J10: =E10/G10 -> 22.690456 | K10: =E10/F10 -> 3.4527018 | L10: =D10/I10 -> 44.301471 | M10: 6.2727746 | N10: =H10/F10 -> 0.094334685 | O10: 0.14159292 | P10: =IFERROR(E10/H10,"") -> 36.600555
B14: Statistics | J14: EV/EBIT
B15: 25th Percentile | D15: =PERCENTILE(J6:J10,0.25) -> 8.1231523 | E15: =PERCENTILE(K6:K10,0.25) -> 2.1220912 | F15: =PERCENTILE(L6:L10,0.25) -> 17.727136 | G15: =PERCENTILE(M6:M10,0.25) -> 2.5452222 | H15: =PERCENTILE(N6:N10,0.25) -> 0.1277983 | I15: =PERCENTILE(O6:O10,0.25) -> 0.14159292 | J15: =PERCENTILE(P6:P10,0.25) -> 10.114379
B16: Median (50th) | D16: =MEDIAN(J6:J10) -> 12.989985 | E16: =MEDIAN(K6:K10) -> 3.4527018 | F16: =MEDIAN(L6:L10) -> 28.805497 | G16: =MEDIAN(M6:M10) -> 4.0474725 | H16: =MEDIAN(N6:N10) -> 0.18396031 | I16: =MEDIAN(O6:O10) -> 0.14357774 | J16: =MEDIAN(P6:P10) -> 19.431461
B17: 75th Percentile | D17: =PERCENTILE(J6:J10,0.75) -> 19.160936 | E17: =PERCENTILE(K6:K10,0.75) -> 3.5746176 | F17: =PERCENTILE(L6:L10,0.75) -> 32.046217 | G17: =PERCENTILE(M6:M10,0.75) -> 6.2727746 | H17: =PERCENTILE(N6:N10,0.75) -> 0.26391885 | I17: =PERCENTILE(O6:O10,0.75) -> 0.28873384 | J17: =PERCENTILE(P6:P10,0.75) -> 20.110875
B19: Implied Valuation for 株式会社フィックスターズ
B20: 株式会社フィックスターズ Financials
B21: EBITDA (JPY mn) | C21: 2745
B22: Net Income (JPY mn) | C22: 1945
B23: Shares Outstanding | C23: 32252858
B24: Net Debt (JPY mn) | C24: -4856
B26: Implied Share Price (Median Multiples)
B27: Via EV/EBITDA (Median) | C27: =ROUND((C21*D16-C24)*1000000/C23,0) -> 1256
B28: Via PER (Median) | C28: =ROUND(C22*F16*1000000/C23,0) -> 1737
B30: SUPPLEMENTARY: Via EV/EBIT (Median) - not in Target Price | C30: =ROUND((H5*J16-C24)*1000000/C23,0) -> 1704
B32: Why EV/EBIT is added: Fixstars is asset-light, with D&A of 167 against EBIT of 2,578 (6.5%). Peer D&A runs 49.6% of EBIT at PKSHA, 61.3% at FRONTEO and 24.5% at TIS, so their EBITDA is inflated relative to Fixstars' and their EV/EBITDA multiples are correspondingly deflated. On EV/EBIT the peer median is about 19.4x versus 13.0x on EV/EBITDA, implying roughly 1,704 per share rather than 1,256 - a 448 difference driven purely by the definitional asymmetry, not by any view on the business. Including it as a fifth method would move the Target Price from 1,381 to about 1,445; it has deliberately been left out of C10 on the Executive Summary.
B33: Peer set: the specification listed 4483.T for ベース, which is JMDC - the correct ticker 4481.T was used instead. SBテクノロジー (4726.T) was replaced by FRONTEO (2158.T) from the specification's fallback list; this substitution was not previously documented. FRONTEO carries the weakest margin of the set (9.4%) and the highest PER (44.3x), so it widens the upper percentile without moving the median. Statistics correctly exclude Fixstars (ranges are row 6 to row 10). Base Corporation's implied D&A of 16 on revenue of 21,787 (0.07%) is low even for a labour-based offshore developer and is worth verifying, though at 8.02x it sits below the median and does not move it.

Sheet Sensitivity Analysis
B2: Sensitivity Analysis
B3: Current WACC: | C3: ='DCF Model'!C26 -> 0.1154 | E3: Terminal g: | F3: ='DCF Model'!C13 -> 0.015 | H3: Exit Multiple: | I3: ='DCF Model'!C14 -> 12
B5: Table 1: WACC vs Terminal Growth Rate (PGM - Implied Share Price, JPY)
B6: WACC \ Terminal g | C6: =$F$3-0.0075 -> 0.0075 | D6: =$F$3-0.005 -> 0.01 | E6: =$F$3-0.0025 -> 0.0125 | F6: =$F$3 -> 0.015 | G6: =$F$3+0.0025 -> 0.0175 | H6: =$F$3+0.005 -> 0.02 | I6: =$F$3+0.0075 -> 0.0225
B7: =$C$3-0.015 -> 0.1004 | C7: =IFERROR(ROUND(('DCF Model'!C45/(1+$B7)^('DCF Model'!C19+0)+'DCF Model'!D45/(1+$B7)^('DCF Model'!C19+1)+'DCF Model'!E45/(1+$B7)^('DCF Model'!C19+2)+'DCF Model'!F45/(1+$B7)^('DCF Model'!C19+3)+'DCF Model'!G45/(1+$B7)^('DCF Model'!C19+4)+'DCF Model'!G45*(1+C$6)/($B7-C$6)/(1+$B7)^('DCF Model'!C19+4)-'DCF Model'!C16)*1000000/'DCF Model'!C15,0),"") -> 1065 | D7: =IFERROR(ROUND(('DCF Model'!C45/(1+$B7)^('DCF Model'!C19+0)+'DCF Model'!D45/(1+$B7)^('DCF Model'!C19+1)+'DCF Model'!E45/(1+$B7)^('DCF Model'!C19+2)+'DCF Model'!F45/(1+$B7)^('DCF Model'!C19+3)+'DCF Model'!G45/(1+$B7)^('DCF Model'!C19+4)+'DCF Model'!G45*(1+D$6)/($B7-D$6)/(1+$B7)^('DCF Model'!C19+4)-'DCF Model'!C16)*1000000/'DCF Model'!C15,0),"") -> 1085 | E7: =IFERROR(ROUND(('DCF Model'!C45/(1+$B7)^('DCF Model'!C19+0)+'DCF Model'!D45/(1+$B7)^('DCF Model'!C19+1)+'DCF Model'!E45/(1+$B7)^('DCF Model'!C19+2)+'DCF Model'!F45/(1+$B7)^('DCF Model'!C19+3)+'DCF Model'!G45/(1+$B7)^('DCF Model'!C19+4)+'DCF Model'!G45*(1+E$6)/($B7-E$6)/(1+$B7)^('DCF Model'!C19+4)-'DCF Model'!C16)*1000000/'DCF Model'!C15,0),"") -> 1105 | F7: =IFERROR(ROUND(('DCF Model'!C45/(1+$B7)^('DCF Model'!C19+0)+'DCF Model'!D45/(1+$B7)^('DCF Model'!C19+1)+'DCF Model'!E45/(1+$B7)^('DCF Model'!C19+2)+'DCF Model'!F45/(1+$B7)^('DCF Model'!C19+3)+'DCF Model'!G45/(1+$B7)^('DCF Model'!C19+4)+'DCF Model'!G45*(1+F$6)/($B7-F$6)/(1+$B7)^('DCF Model'!C19+4)-'DCF Model'!C16)*1000000/'DCF Model'!C15,0),"") -> 1127 | G7: =IFERROR(ROUND(('DCF Model'!C45/(1+$B7)^('DCF Model'!C19+0)+'DCF Model'!D45/(1+$B7)^('DCF Model'!C19+1)+'DCF Model'!E45/(1+$B7)^('DCF Model'!C19+2)+'DCF Model'!F45/(1+$B7)^('DCF Model'!C19+3)+'DCF Model'!G45/(1+$B7)^('DCF Model'!C19+4)+'DCF Model'!G45*(1+G$6)/($B7-G$6)/(1+$B7)^('DCF Model'!C19+4)-'DCF Model'!C16)*1000000/'DCF Model'!C15,0),"") -> 1150 | H7: =IFERROR(ROUND(('DCF Model'!C45/(1+$B7)^('DCF Model'!C19+0)+'DCF Model'!D45/(1+$B7)^('DCF Model'!C19+1)+'DCF Model'!E45/(1+$B7)^('DCF Model'!C19+2)+'DCF Model'!F45/(1+$B7)^('DCF Model'!C19+3)+'DCF Model'!G45/(1+$B7)^('DCF Model'!C19+4)+'DCF Model'!G45*(1+H$6)/($B7-H$6)/(1+$B7)^('DCF Model'!C19+4)-'DCF Model'!C16)*1000000/'DCF Model'!C15,0),"") -> 1175 | I7: =IFERROR(ROUND(('DCF Model'!C45/(1+$B7)^('DCF Model'!C19+0)+'DCF Model'!D45/(1+$B7)^('DCF Model'!C19+1)+'DCF Model'!E45/(1+$B7)^('DCF Model'!C19+2)+'DCF Model'!F45/(1+$B7)^('DCF Model'!C19+3)+'DCF Model'!G45/(1+$B7)^('DCF Model'!C19+4)+'DCF Model'!G45*(1+I$6)/($B7-I$6)/(1+$B7)^('DCF Model'!C19+4)-'DCF Model'!C16)*1000000/'DCF Model'!C15,0),"") -> 1201
B8: =$C$3-0.01 -> 0.1054 | C8: =IFERROR(ROUND(('DCF Model'!C45/(1+$B8)^('DCF Model'!C19+0)+'DCF Model'!D45/(1+$B8)^('DCF Model'!C19+1)+'DCF Model'!E45/(1+$B8)^('DCF Model'!C19+2)+'DCF Model'!F45/(1+$B8)^('DCF Model'!C19+3)+'DCF Model'!G45/(1+$B8)^('DCF Model'!C19+4)+'DCF Model'!G45*(1+C$6)/($B8-C$6)/(1+$B8)^('DCF Model'!C19+4)-'DCF Model'!C16)*1000000/'DCF Model'!C15,0),"") -> 1014 | D8: =IFERROR(ROUND(('DCF Model'!C45/(1+$B8)^('DCF Model'!C19+0)+'DCF Model'!D45/(1+$B8)^('DCF Model'!C19+1)+'DCF Model'!E45/(1+$B8)^('DCF Model'!C19+2)+'DCF Model'!F45/(1+$B8)^('DCF Model'!C19+3)+'DCF Model'!G45/(1+$B8)^('DCF Model'!C19+4)+'DCF Model'!G45*(1+D$6)/($B8-D$6)/(1+$B8)^('DCF Model'!C19+4)-'DCF Model'!C16)*1000000/'DCF Model'!C15,0),"") -> 1032 | E8: =IFERROR(ROUND(('DCF Model'!C45/(1+$B8)^('DCF Model'!C19+0)+'DCF Model'!D45/(1+$B8)^('DCF Model'!C19+1)+'DCF Model'!E45/(1+$B8)^('DCF Model'!C19+2)+'DCF Model'!F45/(1+$B8)^('DCF Model'!C19+3)+'DCF Model'!G45/(1+$B8)^('DCF Model'!C19+4)+'DCF Model'!G45*(1+E$6)/($B8-E$6)/(1+$B8)^('DCF Model'!C19+4)-'DCF Model'!C16)*1000000/'DCF Model'!C15,0),"") -> 1050 | F8: =IFERROR(ROUND(('DCF Model'!C45/(1+$B8)^('DCF Model'!C19+0)+'DCF Model'!D45/(1+$B8)^('DCF Model'!C19+1)+'DCF Model'!E45/(1+$B8)^('DCF Model'!C19+2)+'DCF Model'!F45/(1+$B8)^('DCF Model'!C19+3)+'DCF Model'!G45/(1+$B8)^('DCF Model'!C19+4)+'DCF Model'!G45*(1+F$6)/($B8-F$6)/(1+$B8)^('DCF Model'!C19+4)-'DCF Model'!C16)*1000000/'DCF Model'!C15,0),"") -> 1069 | G8: =IFERROR(ROUND(('DCF Model'!C45/(1+$B8)^('DCF Model'!C19+0)+'DCF Model'!D45/(1+$B8)^('DCF Model'!C19+1)+'DCF Model'!E45/(1+$B8)^('DCF Model'!C19+2)+'DCF Model'!F45/(1+$B8)^('DCF Model'!C19+3)+'DCF Model'!G45/(1+$B8)^('DCF Model'!C19+4)+'DCF Model'!G45*(1+G$6)/($B8-G$6)/(1+$B8)^('DCF Model'!C19+4)-'DCF Model'!C16)*1000000/'DCF Model'!C15,0),"") -> 1089 | H8: =IFERROR(ROUND(('DCF Model'!C45/(1+$B8)^('DCF Model'!C19+0)+'DCF Model'!D45/(1+$B8)^('DCF Model'!C19+1)+'DCF Model'!E45/(1+$B8)^('DCF Model'!C19+2)+'DCF Model'!F45/(1+$B8)^('DCF Model'!C19+3)+'DCF Model'!G45/(1+$B8)^('DCF Model'!C19+4)+'DCF Model'!G45*(1+H$6)/($B8-H$6)/(1+$B8)^('DCF Model'!C19+4)-'DCF Model'!C16)*1000000/'DCF Model'!C15,0),"") -> 1111 | I8: =IFERROR(ROUND(('DCF Model'!C45/(1+$B8)^('DCF Model'!C19+0)+'DCF Model'!D45/(1+$B8)^('DCF Model'!C19+1)+'DCF Model'!E45/(1+$B8)^('DCF Model'!C19+2)+'DCF Model'!F45/(1+$B8)^('DCF Model'!C19+3)+'DCF Model'!G45/(1+$B8)^('DCF Model'!C19+4)+'DCF Model'!G45*(1+I$6)/($B8-I$6)/(1+$B8)^('DCF Model'!C19+4)-'DCF Model'!C16)*1000000/'DCF Model'!C15,0),"") -> 1134
B9: =$C$3-0.005 -> 0.1104 | C9: =IFERROR(ROUND(('DCF Model'!C45/(1+$B9)^('DCF Model'!C19+0)+'DCF Model'!D45/(1+$B9)^('DCF Model'!C19+1)+'DCF Model'!E45/(1+$B9)^('DCF Model'!C19+2)+'DCF Model'!F45/(1+$B9)^('DCF Model'!C19+3)+'DCF Model'!G45/(1+$B9)^('DCF Model'!C19+4)+'DCF Model'!G45*(1+C$6)/($B9-C$6)/(1+$B9)^('DCF Model'!C19+4)-'DCF Model'!C16)*1000000/'DCF Model'!C15,0),"") -> 969 | D9: =IFERROR(ROUND(('DCF Model'!C45/(1+$B9)^('DCF Model'!C19+0)+'DCF Model'!D45/(1+$B9)^('DCF Model'!C19+1)+'DCF Model'!E45/(1+$B9)^('DCF Model'!C19+2)+'DCF Model'!F45/(1+$B9)^('DCF Model'!C19+3)+'DCF Model'!G45/(1+$B9)^('DCF Model'!C19+4)+'DCF Model'!G45*(1+D$6)/($B9-D$6)/(1+$B9)^('DCF Model'!C19+4)-'DCF Model'!C16)*1000000/'DCF Model'!C15,0),"") -> 984 | E9: =IFERROR(ROUND(('DCF Model'!C45/(1+$B9)^('DCF Model'!C19+0)+'DCF Model'!D45/(1+$B9)^('DCF Model'!C19+1)+'DCF Model'!E45/(1+$B9)^('DCF Model'!C19+2)+'DCF Model'!F45/(1+$B9)^('DCF Model'!C19+3)+'DCF Model'!G45/(1+$B9)^('DCF Model'!C19+4)+'DCF Model'!G45*(1+E$6)/($B9-E$6)/(1+$B9)^('DCF Model'!C19+4)-'DCF Model'!C16)*1000000/'DCF Model'!C15,0),"") -> 1000 | F9: =IFERROR(ROUND(('DCF Model'!C45/(1+$B9)^('DCF Model'!C19+0)+'DCF Model'!D45/(1+$B9)^('DCF Model'!C19+1)+'DCF Model'!E45/(1+$B9)^('DCF Model'!C19+2)+'DCF Model'!F45/(1+$B9)^('DCF Model'!C19+3)+'DCF Model'!G45/(1+$B9)^('DCF Model'!C19+4)+'DCF Model'!G45*(1+F$6)/($B9-F$6)/(1+$B9)^('DCF Model'!C19+4)-'DCF Model'!C16)*1000000/'DCF Model'!C15,0),"") -> 1017 | G9: =IFERROR(ROUND(('DCF Model'!C45/(1+$B9)^('DCF Model'!C19+0)+'DCF Model'!D45/(1+$B9)^('DCF Model'!C19+1)+'DCF Model'!E45/(1+$B9)^('DCF Model'!C19+2)+'DCF Model'!F45/(1+$B9)^('DCF Model'!C19+3)+'DCF Model'!G45/(1+$B9)^('DCF Model'!C19+4)+'DCF Model'!G45*(1+G$6)/($B9-G$6)/(1+$B9)^('DCF Model'!C19+4)-'DCF Model'!C16)*1000000/'DCF Model'!C15,0),"") -> 1035 | H9: =IFERROR(ROUND(('DCF Model'!C45/(1+$B9)^('DCF Model'!C19+0)+'DCF Model'!D45/(1+$B9)^('DCF Model'!C19+1)+'DCF Model'!E45/(1+$B9)^('DCF Model'!C19+2)+'DCF Model'!F45/(1+$B9)^('DCF Model'!C19+3)+'DCF Model'!G45/(1+$B9)^('DCF Model'!C19+4)+'DCF Model'!G45*(1+H$6)/($B9-H$6)/(1+$B9)^('DCF Model'!C19+4)-'DCF Model'!C16)*1000000/'DCF Model'!C15,0),"") -> 1054 | I9: =IFERROR(ROUND(('DCF Model'!C45/(1+$B9)^('DCF Model'!C19+0)+'DCF Model'!D45/(1+$B9)^('DCF Model'!C19+1)+'DCF Model'!E45/(1+$B9)^('DCF Model'!C19+2)+'DCF Model'!F45/(1+$B9)^('DCF Model'!C19+3)+'DCF Model'!G45/(1+$B9)^('DCF Model'!C19+4)+'DCF Model'!G45*(1+I$6)/($B9-I$6)/(1+$B9)^('DCF Model'!C19+4)-'DCF Model'!C16)*1000000/'DCF Model'!C15,0),"") -> 1074
B10: =$C$3 -> 0.1154 | C10: =IFERROR(ROUND(('DCF Model'!C45/(1+$B10)^('DCF Model'!C19+0)+'DCF Model'!D45/(1+$B10)^('DCF Model'!C19+1)+'DCF Model'!E45/(1+$B10)^('DCF Model'!C19+2)+'DCF Model'!F45/(1+$B10)^('DCF Model'!C19+3)+'DCF Model'!G45/(1+$B10)^('DCF Model'!C19+4)+'DCF Model'!G45*(1+C$6)/($B10-C$6)/(1+$B10)^('DCF Model'!C19+4)-'DCF Model'!C16)*1000000/'DCF Model'!C15,0),"") -> 927 | D10: =IFERROR(ROUND(('DCF Model'!C45/(1+$B10)^('DCF Model'!C19+0)+'DCF Model'!D45/(1+$B10)^('DCF Model'!C19+1)+'DCF Model'!E45/(1+$B10)^('DCF Model'!C19+2)+'DCF Model'!F45/(1+$B10)^('DCF Model'!C19+3)+'DCF Model'!G45/(1+$B10)^('DCF Model'!C19+4)+'DCF Model'!G45*(1+D$6)/($B10-D$6)/(1+$B10)^('DCF Model'!C19+4)-'DCF Model'!C16)*1000000/'DCF Model'!C15,0),"") -> 941 | E10: =IFERROR(ROUND(('DCF Model'!C45/(1+$B10)^('DCF Model'!C19+0)+'DCF Model'!D45/(1+$B10)^('DCF Model'!C19+1)+'DCF Model'!E45/(1+$B10)^('DCF Model'!C19+2)+'DCF Model'!F45/(1+$B10)^('DCF Model'!C19+3)+'DCF Model'!G45/(1+$B10)^('DCF Model'!C19+4)+'DCF Model'!G45*(1+E$6)/($B10-E$6)/(1+$B10)^('DCF Model'!C19+4)-'DCF Model'!C16)*1000000/'DCF Model'!C15,0),"") -> 955 | F10: =IFERROR(ROUND(('DCF Model'!C45/(1+$B10)^('DCF Model'!C19+0)+'DCF Model'!D45/(1+$B10)^('DCF Model'!C19+1)+'DCF Model'!E45/(1+$B10)^('DCF Model'!C19+2)+'DCF Model'!F45/(1+$B10)^('DCF Model'!C19+3)+'DCF Model'!G45/(1+$B10)^('DCF Model'!C19+4)+'DCF Model'!G45*(1+F$6)/($B10-F$6)/(1+$B10)^('DCF Model'!C19+4)-'DCF Model'!C16)*1000000/'DCF Model'!C15,0),"") -> 970 | G10: =IFERROR(ROUND(('DCF Model'!C45/(1+$B10)^('DCF Model'!C19+0)+'DCF Model'!D45/(1+$B10)^('DCF Model'!C19+1)+'DCF Model'!E45/(1+$B10)^('DCF Model'!C19+2)+'DCF Model'!F45/(1+$B10)^('DCF Model'!C19+3)+'DCF Model'!G45/(1+$B10)^('DCF Model'!C19+4)+'DCF Model'!G45*(1+G$6)/($B10-G$6)/(1+$B10)^('DCF Model'!C19+4)-'DCF Model'!C16)*1000000/'DCF Model'!C15,0),"") -> 986 | H10: =IFERROR(ROUND(('DCF Model'!C45/(1+$B10)^('DCF Model'!C19+0)+'DCF Model'!D45/(1+$B10)^('DCF Model'!C19+1)+'DCF Model'!E45/(1+$B10)^('DCF Model'!C19+2)+'DCF Model'!F45/(1+$B10)^('DCF Model'!C19+3)+'DCF Model'!G45/(1+$B10)^('DCF Model'!C19+4)+'DCF Model'!G45*(1+H$6)/($B10-H$6)/(1+$B10)^('DCF Model'!C19+4)-'DCF Model'!C16)*1000000/'DCF Model'!C15,0),"") -> 1003 | I10: =IFERROR(ROUND(('DCF Model'!C45/(1+$B10)^('DCF Model'!C19+0)+'DCF Model'!D45/(1+$B10)^('DCF Model'!C19+1)+'DCF Model'!E45/(1+$B10)^('DCF Model'!C19+2)+'DCF Model'!F45/(1+$B10)^('DCF Model'!C19+3)+'DCF Model'!G45/(1+$B10)^('DCF Model'!C19+4)+'DCF Model'!G45*(1+I$6)/($B10-I$6)/(1+$B10)^('DCF Model'!C19+4)-'DCF Model'!C16)*1000000/'DCF Model'!C15,0),"") -> 1021
B11: =$C$3+0.005 -> 0.1204 | C11: =IFERROR(ROUND(('DCF Model'!C45/(1+$B11)^('DCF Model'!C19+0)+'DCF Model'!D45/(1+$B11)^('DCF Model'!C19+1)+'DCF Model'!E45/(1+$B11)^('DCF Model'!C19+2)+'DCF Model'!F45/(1+$B11)^('DCF Model'!C19+3)+'DCF Model'!G45/(1+$B11)^('DCF Model'!C19+4)+'DCF Model'!G45*(1+C$6)/($B11-C$6)/(1+$B11)^('DCF Model'!C19+4)-'DCF Model'!C16)*1000000/'DCF Model'!C15,0),"") -> 890 | D11: =IFERROR(ROUND(('DCF Model'!C45/(1+$B11)^('DCF Model'!C19+0)+'DCF Model'!D45/(1+$B11)^('DCF Model'!C19+1)+'DCF Model'!E45/(1+$B11)^('DCF Model'!C19+2)+'DCF Model'!F45/(1+$B11)^('DCF Model'!C19+3)+'DCF Model'!G45/(1+$B11)^('DCF Model'!C19+4)+'DCF Model'!G45*(1+D$6)/($B11-D$6)/(1+$B11)^('DCF Model'!C19+4)-'DCF Model'!C16)*1000000/'DCF Model'!C15,0),"") -> 902 | E11: =IFERROR(ROUND(('DCF Model'!C45/(1+$B11)^('DCF Model'!C19+0)+'DCF Model'!D45/(1+$B11)^('DCF Model'!C19+1)+'DCF Model'!E45/(1+$B11)^('DCF Model'!C19+2)+'DCF Model'!F45/(1+$B11)^('DCF Model'!C19+3)+'DCF Model'!G45/(1+$B11)^('DCF Model'!C19+4)+'DCF Model'!G45*(1+E$6)/($B11-E$6)/(1+$B11)^('DCF Model'!C19+4)-'DCF Model'!C16)*1000000/'DCF Model'!C15,0),"") -> 915 | F11: =IFERROR(ROUND(('DCF Model'!C45/(1+$B11)^('DCF Model'!C19+0)+'DCF Model'!D45/(1+$B11)^('DCF Model'!C19+1)+'DCF Model'!E45/(1+$B11)^('DCF Model'!C19+2)+'DCF Model'!F45/(1+$B11)^('DCF Model'!C19+3)+'DCF Model'!G45/(1+$B11)^('DCF Model'!C19+4)+'DCF Model'!G45*(1+F$6)/($B11-F$6)/(1+$B11)^('DCF Model'!C19+4)-'DCF Model'!C16)*1000000/'DCF Model'!C15,0),"") -> 928 | G11: =IFERROR(ROUND(('DCF Model'!C45/(1+$B11)^('DCF Model'!C19+0)+'DCF Model'!D45/(1+$B11)^('DCF Model'!C19+1)+'DCF Model'!E45/(1+$B11)^('DCF Model'!C19+2)+'DCF Model'!F45/(1+$B11)^('DCF Model'!C19+3)+'DCF Model'!G45/(1+$B11)^('DCF Model'!C19+4)+'DCF Model'!G45*(1+G$6)/($B11-G$6)/(1+$B11)^('DCF Model'!C19+4)-'DCF Model'!C16)*1000000/'DCF Model'!C15,0),"") -> 942 | H11: =IFERROR(ROUND(('DCF Model'!C45/(1+$B11)^('DCF Model'!C19+0)+'DCF Model'!D45/(1+$B11)^('DCF Model'!C19+1)+'DCF Model'!E45/(1+$B11)^('DCF Model'!C19+2)+'DCF Model'!F45/(1+$B11)^('DCF Model'!C19+3)+'DCF Model'!G45/(1+$B11)^('DCF Model'!C19+4)+'DCF Model'!G45*(1+H$6)/($B11-H$6)/(1+$B11)^('DCF Model'!C19+4)-'DCF Model'!C16)*1000000/'DCF Model'!C15,0),"") -> 957 | I11: =IFERROR(ROUND(('DCF Model'!C45/(1+$B11)^('DCF Model'!C19+0)+'DCF Model'!D45/(1+$B11)^('DCF Model'!C19+1)+'DCF Model'!E45/(1+$B11)^('DCF Model'!C19+2)+'DCF Model'!F45/(1+$B11)^('DCF Model'!C19+3)+'DCF Model'!G45/(1+$B11)^('DCF Model'!C19+4)+'DCF Model'!G45*(1+I$6)/($B11-I$6)/(1+$B11)^('DCF Model'!C19+4)-'DCF Model'!C16)*1000000/'DCF Model'!C15,0),"") -> 973
B12: =$C$3+0.01 -> 0.1254 | C12: =IFERROR(ROUND(('DCF Model'!C45/(1+$B12)^('DCF Model'!C19+0)+'DCF Model'!D45/(1+$B12)^('DCF Model'!C19+1)+'DCF Model'!E45/(1+$B12)^('DCF Model'!C19+2)+'DCF Model'!F45/(1+$B12)^('DCF Model'!C19+3)+'DCF Model'!G45/(1+$B12)^('DCF Model'!C19+4)+'DCF Model'!G45*(1+C$6)/($B12-C$6)/(1+$B12)^('DCF Model'!C19+4)-'DCF Model'!C16)*1000000/'DCF Model'!C15,0),"") -> 855 | D12: =IFERROR(ROUND(('DCF Model'!C45/(1+$B12)^('DCF Model'!C19+0)+'DCF Model'!D45/(1+$B12)^('DCF Model'!C19+1)+'DCF Model'!E45/(1+$B12)^('DCF Model'!C19+2)+'DCF Model'!F45/(1+$B12)^('DCF Model'!C19+3)+'DCF Model'!G45/(1+$B12)^('DCF Model'!C19+4)+'DCF Model'!G45*(1+D$6)/($B12-D$6)/(1+$B12)^('DCF Model'!C19+4)-'DCF Model'!C16)*1000000/'DCF Model'!C15,0),"") -> 866 | E12: =IFERROR(ROUND(('DCF Model'!C45/(1+$B12)^('DCF Model'!C19+0)+'DCF Model'!D45/(1+$B12)^('DCF Model'!C19+1)+'DCF Model'!E45/(1+$B12)^('DCF Model'!C19+2)+'DCF Model'!F45/(1+$B12)^('DCF Model'!C19+3)+'DCF Model'!G45/(1+$B12)^('DCF Model'!C19+4)+'DCF Model'!G45*(1+E$6)/($B12-E$6)/(1+$B12)^('DCF Model'!C19+4)-'DCF Model'!C16)*1000000/'DCF Model'!C15,0),"") -> 878 | F12: =IFERROR(ROUND(('DCF Model'!C45/(1+$B12)^('DCF Model'!C19+0)+'DCF Model'!D45/(1+$B12)^('DCF Model'!C19+1)+'DCF Model'!E45/(1+$B12)^('DCF Model'!C19+2)+'DCF Model'!F45/(1+$B12)^('DCF Model'!C19+3)+'DCF Model'!G45/(1+$B12)^('DCF Model'!C19+4)+'DCF Model'!G45*(1+F$6)/($B12-F$6)/(1+$B12)^('DCF Model'!C19+4)-'DCF Model'!C16)*1000000/'DCF Model'!C15,0),"") -> 890 | G12: =IFERROR(ROUND(('DCF Model'!C45/(1+$B12)^('DCF Model'!C19+0)+'DCF Model'!D45/(1+$B12)^('DCF Model'!C19+1)+'DCF Model'!E45/(1+$B12)^('DCF Model'!C19+2)+'DCF Model'!F45/(1+$B12)^('DCF Model'!C19+3)+'DCF Model'!G45/(1+$B12)^('DCF Model'!C19+4)+'DCF Model'!G45*(1+G$6)/($B12-G$6)/(1+$B12)^('DCF Model'!C19+4)-'DCF Model'!C16)*1000000/'DCF Model'!C15,0),"") -> 903 | H12: =IFERROR(ROUND(('DCF Model'!C45/(1+$B12)^('DCF Model'!C19+0)+'DCF Model'!D45/(1+$B12)^('DCF Model'!C19+1)+'DCF Model'!E45/(1+$B12)^('DCF Model'!C19+2)+'DCF Model'!F45/(1+$B12)^('DCF Model'!C19+3)+'DCF Model'!G45/(1+$B12)^('DCF Model'!C19+4)+'DCF Model'!G45*(1+H$6)/($B12-H$6)/(1+$B12)^('DCF Model'!C19+4)-'DCF Model'!C16)*1000000/'DCF Model'!C15,0),"") -> 916 | I12: =IFERROR(ROUND(('DCF Model'!C45/(1+$B12)^('DCF Model'!C19+0)+'DCF Model'!D45/(1+$B12)^('DCF Model'!C19+1)+'DCF Model'!E45/(1+$B12)^('DCF Model'!C19+2)+'DCF Model'!F45/(1+$B12)^('DCF Model'!C19+3)+'DCF Model'!G45/(1+$B12)^('DCF Model'!C19+4)+'DCF Model'!G45*(1+I$6)/($B12-I$6)/(1+$B12)^('DCF Model'!C19+4)-'DCF Model'!C16)*1000000/'DCF Model'!C15,0),"") -> 930
B13: =$C$3+0.015 -> 0.1304 | C13: =IFERROR(ROUND(('DCF Model'!C45/(1+$B13)^('DCF Model'!C19+0)+'DCF Model'!D45/(1+$B13)^('DCF Model'!C19+1)+'DCF Model'!E45/(1+$B13)^('DCF Model'!C19+2)+'DCF Model'!F45/(1+$B13)^('DCF Model'!C19+3)+'DCF Model'!G45/(1+$B13)^('DCF Model'!C19+4)+'DCF Model'!G45*(1+C$6)/($B13-C$6)/(1+$B13)^('DCF Model'!C19+4)-'DCF Model'!C16)*1000000/'DCF Model'!C15,0),"") -> 824 | D13: =IFERROR(ROUND(('DCF Model'!C45/(1+$B13)^('DCF Model'!C19+0)+'DCF Model'!D45/(1+$B13)^('DCF Model'!C19+1)+'DCF Model'!E45/(1+$B13)^('DCF Model'!C19+2)+'DCF Model'!F45/(1+$B13)^('DCF Model'!C19+3)+'DCF Model'!G45/(1+$B13)^('DCF Model'!C19+4)+'DCF Model'!G45*(1+D$6)/($B13-D$6)/(1+$B13)^('DCF Model'!C19+4)-'DCF Model'!C16)*1000000/'DCF Model'!C15,0),"") -> 834 | E13: =IFERROR(ROUND(('DCF Model'!C45/(1+$B13)^('DCF Model'!C19+0)+'DCF Model'!D45/(1+$B13)^('DCF Model'!C19+1)+'DCF Model'!E45/(1+$B13)^('DCF Model'!C19+2)+'DCF Model'!F45/(1+$B13)^('DCF Model'!C19+3)+'DCF Model'!G45/(1+$B13)^('DCF Model'!C19+4)+'DCF Model'!G45*(1+E$6)/($B13-E$6)/(1+$B13)^('DCF Model'!C19+4)-'DCF Model'!C16)*1000000/'DCF Model'!C15,0),"") -> 844 | F13: =IFERROR(ROUND(('DCF Model'!C45/(1+$B13)^('DCF Model'!C19+0)+'DCF Model'!D45/(1+$B13)^('DCF Model'!C19+1)+'DCF Model'!E45/(1+$B13)^('DCF Model'!C19+2)+'DCF Model'!F45/(1+$B13)^('DCF Model'!C19+3)+'DCF Model'!G45/(1+$B13)^('DCF Model'!C19+4)+'DCF Model'!G45*(1+F$6)/($B13-F$6)/(1+$B13)^('DCF Model'!C19+4)-'DCF Model'!C16)*1000000/'DCF Model'!C15,0),"") -> 855 | G13: =IFERROR(ROUND(('DCF Model'!C45/(1+$B13)^('DCF Model'!C19+0)+'DCF Model'!D45/(1+$B13)^('DCF Model'!C19+1)+'DCF Model'!E45/(1+$B13)^('DCF Model'!C19+2)+'DCF Model'!F45/(1+$B13)^('DCF Model'!C19+3)+'DCF Model'!G45/(1+$B13)^('DCF Model'!C19+4)+'DCF Model'!G45*(1+G$6)/($B13-G$6)/(1+$B13)^('DCF Model'!C19+4)-'DCF Model'!C16)*1000000/'DCF Model'!C15,0),"") -> 866 | H13: =IFERROR(ROUND(('DCF Model'!C45/(1+$B13)^('DCF Model'!C19+0)+'DCF Model'!D45/(1+$B13)^('DCF Model'!C19+1)+'DCF Model'!E45/(1+$B13)^('DCF Model'!C19+2)+'DCF Model'!F45/(1+$B13)^('DCF Model'!C19+3)+'DCF Model'!G45/(1+$B13)^('DCF Model'!C19+4)+'DCF Model'!G45*(1+H$6)/($B13-H$6)/(1+$B13)^('DCF Model'!C19+4)-'DCF Model'!C16)*1000000/'DCF Model'!C15,0),"") -> 878 | I13: =IFERROR(ROUND(('DCF Model'!C45/(1+$B13)^('DCF Model'!C19+0)+'DCF Model'!D45/(1+$B13)^('DCF Model'!C19+1)+'DCF Model'!E45/(1+$B13)^('DCF Model'!C19+2)+'DCF Model'!F45/(1+$B13)^('DCF Model'!C19+3)+'DCF Model'!G45/(1+$B13)^('DCF Model'!C19+4)+'DCF Model'!G45*(1+I$6)/($B13-I$6)/(1+$B13)^('DCF Model'!C19+4)-'DCF Model'!C16)*1000000/'DCF Model'!C15,0),"") -> 891
B16: Table 2: WACC vs Exit Multiple (Exit Multiple - Implied Share Price, JPY)
B17: WACC \ Exit Multiple | C17: =$I$3-3 -> 9 | D17: =$I$3-2 -> 10 | E17: =$I$3-1 -> 11 | F17: =$I$3 -> 12 | G17: =$I$3+1 -> 13 | H17: =$I$3+2 -> 14 | I17: =$I$3+3 -> 15
B18: =$C$3-0.015 -> 0.1004 | C18: =IFERROR(ROUND(('DCF Model'!C45/(1+$B18)^('DCF Model'!C19+0)+'DCF Model'!D45/(1+$B18)^('DCF Model'!C19+1)+'DCF Model'!E45/(1+$B18)^('DCF Model'!C19+2)+'DCF Model'!F45/(1+$B18)^('DCF Model'!C19+3)+'DCF Model'!G45/(1+$B18)^('DCF Model'!C19+4)+('DCF Model'!G39+'DCF Model'!G42)*C$17/(1+$B18)^('DCF Model'!C19+4)-'DCF Model'!C16)*1000000/'DCF Model'!C15,0),"") -> 1343 | D18: =IFERROR(ROUND(('DCF Model'!C45/(1+$B18)^('DCF Model'!C19+0)+'DCF Model'!D45/(1+$B18)^('DCF Model'!C19+1)+'DCF Model'!E45/(1+$B18)^('DCF Model'!C19+2)+'DCF Model'!F45/(1+$B18)^('DCF Model'!C19+3)+'DCF Model'!G45/(1+$B18)^('DCF Model'!C19+4)+('DCF Model'!G39+'DCF Model'!G42)*D$17/(1+$B18)^('DCF Model'!C19+4)-'DCF Model'!C16)*1000000/'DCF Model'!C15,0),"") -> 1445 | E18: =IFERROR(ROUND(('DCF Model'!C45/(1+$B18)^('DCF Model'!C19+0)+'DCF Model'!D45/(1+$B18)^('DCF Model'!C19+1)+'DCF Model'!E45/(1+$B18)^('DCF Model'!C19+2)+'DCF Model'!F45/(1+$B18)^('DCF Model'!C19+3)+'DCF Model'!G45/(1+$B18)^('DCF Model'!C19+4)+('DCF Model'!G39+'DCF Model'!G42)*E$17/(1+$B18)^('DCF Model'!C19+4)-'DCF Model'!C16)*1000000/'DCF Model'!C15,0),"") -> 1548 | F18: =IFERROR(ROUND(('DCF Model'!C45/(1+$B18)^('DCF Model'!C19+0)+'DCF Model'!D45/(1+$B18)^('DCF Model'!C19+1)+'DCF Model'!E45/(1+$B18)^('DCF Model'!C19+2)+'DCF Model'!F45/(1+$B18)^('DCF Model'!C19+3)+'DCF Model'!G45/(1+$B18)^('DCF Model'!C19+4)+('DCF Model'!G39+'DCF Model'!G42)*F$17/(1+$B18)^('DCF Model'!C19+4)-'DCF Model'!C16)*1000000/'DCF Model'!C15,0),"") -> 1651 | G18: =IFERROR(ROUND(('DCF Model'!C45/(1+$B18)^('DCF Model'!C19+0)+'DCF Model'!D45/(1+$B18)^('DCF Model'!C19+1)+'DCF Model'!E45/(1+$B18)^('DCF Model'!C19+2)+'DCF Model'!F45/(1+$B18)^('DCF Model'!C19+3)+'DCF Model'!G45/(1+$B18)^('DCF Model'!C19+4)+('DCF Model'!G39+'DCF Model'!G42)*G$17/(1+$B18)^('DCF Model'!C19+4)-'DCF Model'!C16)*1000000/'DCF Model'!C15,0),"") -> 1754 | H18: =IFERROR(ROUND(('DCF Model'!C45/(1+$B18)^('DCF Model'!C19+0)+'DCF Model'!D45/(1+$B18)^('DCF Model'!C19+1)+'DCF Model'!E45/(1+$B18)^('DCF Model'!C19+2)+'DCF Model'!F45/(1+$B18)^('DCF Model'!C19+3)+'DCF Model'!G45/(1+$B18)^('DCF Model'!C19+4)+('DCF Model'!G39+'DCF Model'!G42)*H$17/(1+$B18)^('DCF Model'!C19+4)-'DCF Model'!C16)*1000000/'DCF Model'!C15,0),"") -> 1856 | I18: =IFERROR(ROUND(('DCF Model'!C45/(1+$B18)^('DCF Model'!C19+0)+'DCF Model'!D45/(1+$B18)^('DCF Model'!C19+1)+'DCF Model'!E45/(1+$B18)^('DCF Model'!C19+2)+'DCF Model'!F45/(1+$B18)^('DCF Model'!C19+3)+'DCF Model'!G45/(1+$B18)^('DCF Model'!C19+4)+('DCF Model'!G39+'DCF Model'!G42)*I$17/(1+$B18)^('DCF Model'!C19+4)-'DCF Model'!C16)*1000000/'DCF Model'!C15,0),"") -> 1959
B19: =$C$3-0.01 -> 0.1054 | C19: =IFERROR(ROUND(('DCF Model'!C45/(1+$B19)^('DCF Model'!C19+0)+'DCF Model'!D45/(1+$B19)^('DCF Model'!C19+1)+'DCF Model'!E45/(1+$B19)^('DCF Model'!C19+2)+'DCF Model'!F45/(1+$B19)^('DCF Model'!C19+3)+'DCF Model'!G45/(1+$B19)^('DCF Model'!C19+4)+('DCF Model'!G39+'DCF Model'!G42)*C$17/(1+$B19)^('DCF Model'!C19+4)-'DCF Model'!C16)*1000000/'DCF Model'!C15,0),"") -> 1318 | D19: =IFERROR(ROUND(('DCF Model'!C45/(1+$B19)^('DCF Model'!C19+0)+'DCF Model'!D45/(1+$B19)^('DCF Model'!C19+1)+'DCF Model'!E45/(1+$B19)^('DCF Model'!C19+2)+'DCF Model'!F45/(1+$B19)^('DCF Model'!C19+3)+'DCF Model'!G45/(1+$B19)^('DCF Model'!C19+4)+('DCF Model'!G39+'DCF Model'!G42)*D$17/(1+$B19)^('DCF Model'!C19+4)-'DCF Model'!C16)*1000000/'DCF Model'!C15,0),"") -> 1419 | E19: =IFERROR(ROUND(('DCF Model'!C45/(1+$B19)^('DCF Model'!C19+0)+'DCF Model'!D45/(1+$B19)^('DCF Model'!C19+1)+'DCF Model'!E45/(1+$B19)^('DCF Model'!C19+2)+'DCF Model'!F45/(1+$B19)^('DCF Model'!C19+3)+'DCF Model'!G45/(1+$B19)^('DCF Model'!C19+4)+('DCF Model'!G39+'DCF Model'!G42)*E$17/(1+$B19)^('DCF Model'!C19+4)-'DCF Model'!C16)*1000000/'DCF Model'!C15,0),"") -> 1519 | F19: =IFERROR(ROUND(('DCF Model'!C45/(1+$B19)^('DCF Model'!C19+0)+'DCF Model'!D45/(1+$B19)^('DCF Model'!C19+1)+'DCF Model'!E45/(1+$B19)^('DCF Model'!C19+2)+'DCF Model'!F45/(1+$B19)^('DCF Model'!C19+3)+'DCF Model'!G45/(1+$B19)^('DCF Model'!C19+4)+('DCF Model'!G39+'DCF Model'!G42)*F$17/(1+$B19)^('DCF Model'!C19+4)-'DCF Model'!C16)*1000000/'DCF Model'!C15,0),"") -> 1619 | G19: =IFERROR(ROUND(('DCF Model'!C45/(1+$B19)^('DCF Model'!C19+0)+'DCF Model'!D45/(1+$B19)^('DCF Model'!C19+1)+'DCF Model'!E45/(1+$B19)^('DCF Model'!C19+2)+'DCF Model'!F45/(1+$B19)^('DCF Model'!C19+3)+'DCF Model'!G45/(1+$B19)^('DCF Model'!C19+4)+('DCF Model'!G39+'DCF Model'!G42)*G$17/(1+$B19)^('DCF Model'!C19+4)-'DCF Model'!C16)*1000000/'DCF Model'!C15,0),"") -> 1720 | H19: =IFERROR(ROUND(('DCF Model'!C45/(1+$B19)^('DCF Model'!C19+0)+'DCF Model'!D45/(1+$B19)^('DCF Model'!C19+1)+'DCF Model'!E45/(1+$B19)^('DCF Model'!C19+2)+'DCF Model'!F45/(1+$B19)^('DCF Model'!C19+3)+'DCF Model'!G45/(1+$B19)^('DCF Model'!C19+4)+('DCF Model'!G39+'DCF Model'!G42)*H$17/(1+$B19)^('DCF Model'!C19+4)-'DCF Model'!C16)*1000000/'DCF Model'!C15,0),"") -> 1820 | I19: =IFERROR(ROUND(('DCF Model'!C45/(1+$B19)^('DCF Model'!C19+0)+'DCF Model'!D45/(1+$B19)^('DCF Model'!C19+1)+'DCF Model'!E45/(1+$B19)^('DCF Model'!C19+2)+'DCF Model'!F45/(1+$B19)^('DCF Model'!C19+3)+'DCF Model'!G45/(1+$B19)^('DCF Model'!C19+4)+('DCF Model'!G39+'DCF Model'!G42)*I$17/(1+$B19)^('DCF Model'!C19+4)-'DCF Model'!C16)*1000000/'DCF Model'!C15,0),"") -> 1921
B20: =$C$3-0.005 -> 0.1104 | C20: =IFERROR(ROUND(('DCF Model'!C45/(1+$B20)^('DCF Model'!C19+0)+'DCF Model'!D45/(1+$B20)^('DCF Model'!C19+1)+'DCF Model'!E45/(1+$B20)^('DCF Model'!C19+2)+'DCF Model'!F45/(1+$B20)^('DCF Model'!C19+3)+'DCF Model'!G45/(1+$B20)^('DCF Model'!C19+4)+('DCF Model'!G39+'DCF Model'!G42)*C$17/(1+$B20)^('DCF Model'!C19+4)-'DCF Model'!C16)*1000000/'DCF Model'!C15,0),"") -> 1294 | D20: =IFERROR(ROUND(('DCF Model'!C45/(1+$B20)^('DCF Model'!C19+0)+'DCF Model'!D45/(1+$B20)^('DCF Model'!C19+1)+'DCF Model'!E45/(1+$B20)^('DCF Model'!C19+2)+'DCF Model'!F45/(1+$B20)^('DCF Model'!C19+3)+'DCF Model'!G45/(1+$B20)^('DCF Model'!C19+4)+('DCF Model'!G39+'DCF Model'!G42)*D$17/(1+$B20)^('DCF Model'!C19+4)-'DCF Model'!C16)*1000000/'DCF Model'!C15,0),"") -> 1392 | E20: =IFERROR(ROUND(('DCF Model'!C45/(1+$B20)^('DCF Model'!C19+0)+'DCF Model'!D45/(1+$B20)^('DCF Model'!C19+1)+'DCF Model'!E45/(1+$B20)^('DCF Model'!C19+2)+'DCF Model'!F45/(1+$B20)^('DCF Model'!C19+3)+'DCF Model'!G45/(1+$B20)^('DCF Model'!C19+4)+('DCF Model'!G39+'DCF Model'!G42)*E$17/(1+$B20)^('DCF Model'!C19+4)-'DCF Model'!C16)*1000000/'DCF Model'!C15,0),"") -> 1491 | F20: =IFERROR(ROUND(('DCF Model'!C45/(1+$B20)^('DCF Model'!C19+0)+'DCF Model'!D45/(1+$B20)^('DCF Model'!C19+1)+'DCF Model'!E45/(1+$B20)^('DCF Model'!C19+2)+'DCF Model'!F45/(1+$B20)^('DCF Model'!C19+3)+'DCF Model'!G45/(1+$B20)^('DCF Model'!C19+4)+('DCF Model'!G39+'DCF Model'!G42)*F$17/(1+$B20)^('DCF Model'!C19+4)-'DCF Model'!C16)*1000000/'DCF Model'!C15,0),"") -> 1589 | G20: =IFERROR(ROUND(('DCF Model'!C45/(1+$B20)^('DCF Model'!C19+0)+'DCF Model'!D45/(1+$B20)^('DCF Model'!C19+1)+'DCF Model'!E45/(1+$B20)^('DCF Model'!C19+2)+'DCF Model'!F45/(1+$B20)^('DCF Model'!C19+3)+'DCF Model'!G45/(1+$B20)^('DCF Model'!C19+4)+('DCF Model'!G39+'DCF Model'!G42)*G$17/(1+$B20)^('DCF Model'!C19+4)-'DCF Model'!C16)*1000000/'DCF Model'!C15,0),"") -> 1687 | H20: =IFERROR(ROUND(('DCF Model'!C45/(1+$B20)^('DCF Model'!C19+0)+'DCF Model'!D45/(1+$B20)^('DCF Model'!C19+1)+'DCF Model'!E45/(1+$B20)^('DCF Model'!C19+2)+'DCF Model'!F45/(1+$B20)^('DCF Model'!C19+3)+'DCF Model'!G45/(1+$B20)^('DCF Model'!C19+4)+('DCF Model'!G39+'DCF Model'!G42)*H$17/(1+$B20)^('DCF Model'!C19+4)-'DCF Model'!C16)*1000000/'DCF Model'!C15,0),"") -> 1785 | I20: =IFERROR(ROUND(('DCF Model'!C45/(1+$B20)^('DCF Model'!C19+0)+'DCF Model'!D45/(1+$B20)^('DCF Model'!C19+1)+'DCF Model'!E45/(1+$B20)^('DCF Model'!C19+2)+'DCF Model'!F45/(1+$B20)^('DCF Model'!C19+3)+'DCF Model'!G45/(1+$B20)^('DCF Model'!C19+4)+('DCF Model'!G39+'DCF Model'!G42)*I$17/(1+$B20)^('DCF Model'!C19+4)-'DCF Model'!C16)*1000000/'DCF Model'!C15,0),"") -> 1884
B21: =$C$3 -> 0.1154 | C21: =IFERROR(ROUND(('DCF Model'!C45/(1+$B21)^('DCF Model'!C19+0)+'DCF Model'!D45/(1+$B21)^('DCF Model'!C19+1)+'DCF Model'!E45/(1+$B21)^('DCF Model'!C19+2)+'DCF Model'!F45/(1+$B21)^('DCF Model'!C19+3)+'DCF Model'!G45/(1+$B21)^('DCF Model'!C19+4)+('DCF Model'!G39+'DCF Model'!G42)*C$17/(1+$B21)^('DCF Model'!C19+4)-'DCF Model'!C16)*1000000/'DCF Model'!C15,0),"") -> 1271 | D21: =IFERROR(ROUND(('DCF Model'!C45/(1+$B21)^('DCF Model'!C19+0)+'DCF Model'!D45/(1+$B21)^('DCF Model'!C19+1)+'DCF Model'!E45/(1+$B21)^('DCF Model'!C19+2)+'DCF Model'!F45/(1+$B21)^('DCF Model'!C19+3)+'DCF Model'!G45/(1+$B21)^('DCF Model'!C19+4)+('DCF Model'!G39+'DCF Model'!G42)*D$17/(1+$B21)^('DCF Model'!C19+4)-'DCF Model'!C16)*1000000/'DCF Model'!C15,0),"") -> 1367 | E21: =IFERROR(ROUND(('DCF Model'!C45/(1+$B21)^('DCF Model'!C19+0)+'DCF Model'!D45/(1+$B21)^('DCF Model'!C19+1)+'DCF Model'!E45/(1+$B21)^('DCF Model'!C19+2)+'DCF Model'!F45/(1+$B21)^('DCF Model'!C19+3)+'DCF Model'!G45/(1+$B21)^('DCF Model'!C19+4)+('DCF Model'!G39+'DCF Model'!G42)*E$17/(1+$B21)^('DCF Model'!C19+4)-'DCF Model'!C16)*1000000/'DCF Model'!C15,0),"") -> 1463 | F21: =IFERROR(ROUND(('DCF Model'!C45/(1+$B21)^('DCF Model'!C19+0)+'DCF Model'!D45/(1+$B21)^('DCF Model'!C19+1)+'DCF Model'!E45/(1+$B21)^('DCF Model'!C19+2)+'DCF Model'!F45/(1+$B21)^('DCF Model'!C19+3)+'DCF Model'!G45/(1+$B21)^('DCF Model'!C19+4)+('DCF Model'!G39+'DCF Model'!G42)*F$17/(1+$B21)^('DCF Model'!C19+4)-'DCF Model'!C16)*1000000/'DCF Model'!C15,0),"") -> 1559 | G21: =IFERROR(ROUND(('DCF Model'!C45/(1+$B21)^('DCF Model'!C19+0)+'DCF Model'!D45/(1+$B21)^('DCF Model'!C19+1)+'DCF Model'!E45/(1+$B21)^('DCF Model'!C19+2)+'DCF Model'!F45/(1+$B21)^('DCF Model'!C19+3)+'DCF Model'!G45/(1+$B21)^('DCF Model'!C19+4)+('DCF Model'!G39+'DCF Model'!G42)*G$17/(1+$B21)^('DCF Model'!C19+4)-'DCF Model'!C16)*1000000/'DCF Model'!C15,0),"") -> 1655 | H21: =IFERROR(ROUND(('DCF Model'!C45/(1+$B21)^('DCF Model'!C19+0)+'DCF Model'!D45/(1+$B21)^('DCF Model'!C19+1)+'DCF Model'!E45/(1+$B21)^('DCF Model'!C19+2)+'DCF Model'!F45/(1+$B21)^('DCF Model'!C19+3)+'DCF Model'!G45/(1+$B21)^('DCF Model'!C19+4)+('DCF Model'!G39+'DCF Model'!G42)*H$17/(1+$B21)^('DCF Model'!C19+4)-'DCF Model'!C16)*1000000/'DCF Model'!C15,0),"") -> 1751 | I21: =IFERROR(ROUND(('DCF Model'!C45/(1+$B21)^('DCF Model'!C19+0)+'DCF Model'!D45/(1+$B21)^('DCF Model'!C19+1)+'DCF Model'!E45/(1+$B21)^('DCF Model'!C19+2)+'DCF Model'!F45/(1+$B21)^('DCF Model'!C19+3)+'DCF Model'!G45/(1+$B21)^('DCF Model'!C19+4)+('DCF Model'!G39+'DCF Model'!G42)*I$17/(1+$B21)^('DCF Model'!C19+4)-'DCF Model'!C16)*1000000/'DCF Model'!C15,0),"") -> 1847
B22: =$C$3+0.005 -> 0.1204 | C22: =IFERROR(ROUND(('DCF Model'!C45/(1+$B22)^('DCF Model'!C19+0)+'DCF Model'!D45/(1+$B22)^('DCF Model'!C19+1)+'DCF Model'!E45/(1+$B22)^('DCF Model'!C19+2)+'DCF Model'!F45/(1+$B22)^('DCF Model'!C19+3)+'DCF Model'!G45/(1+$B22)^('DCF Model'!C19+4)+('DCF Model'!G39+'DCF Model'!G42)*C$17/(1+$B22)^('DCF Model'!C19+4)-'DCF Model'!C16)*1000000/'DCF Model'!C15,0),"") -> 1248 | D22: =IFERROR(ROUND(('DCF Model'!C45/(1+$B22)^('DCF Model'!C19+0)+'DCF Model'!D45/(1+$B22)^('DCF Model'!C19+1)+'DCF Model'!E45/(1+$B22)^('DCF Model'!C19+2)+'DCF Model'!F45/(1+$B22)^('DCF Model'!C19+3)+'DCF Model'!G45/(1+$B22)^('DCF Model'!C19+4)+('DCF Model'!G39+'DCF Model'!G42)*D$17/(1+$B22)^('DCF Model'!C19+4)-'DCF Model'!C16)*1000000/'DCF Model'!C15,0),"") -> 1342 | E22: =IFERROR(ROUND(('DCF Model'!C45/(1+$B22)^('DCF Model'!C19+0)+'DCF Model'!D45/(1+$B22)^('DCF Model'!C19+1)+'DCF Model'!E45/(1+$B22)^('DCF Model'!C19+2)+'DCF Model'!F45/(1+$B22)^('DCF Model'!C19+3)+'DCF Model'!G45/(1+$B22)^('DCF Model'!C19+4)+('DCF Model'!G39+'DCF Model'!G42)*E$17/(1+$B22)^('DCF Model'!C19+4)-'DCF Model'!C16)*1000000/'DCF Model'!C15,0),"") -> 1436 | F22: =IFERROR(ROUND(('DCF Model'!C45/(1+$B22)^('DCF Model'!C19+0)+'DCF Model'!D45/(1+$B22)^('DCF Model'!C19+1)+'DCF Model'!E45/(1+$B22)^('DCF Model'!C19+2)+'DCF Model'!F45/(1+$B22)^('DCF Model'!C19+3)+'DCF Model'!G45/(1+$B22)^('DCF Model'!C19+4)+('DCF Model'!G39+'DCF Model'!G42)*F$17/(1+$B22)^('DCF Model'!C19+4)-'DCF Model'!C16)*1000000/'DCF Model'!C15,0),"") -> 1530 | G22: =IFERROR(ROUND(('DCF Model'!C45/(1+$B22)^('DCF Model'!C19+0)+'DCF Model'!D45/(1+$B22)^('DCF Model'!C19+1)+'DCF Model'!E45/(1+$B22)^('DCF Model'!C19+2)+'DCF Model'!F45/(1+$B22)^('DCF Model'!C19+3)+'DCF Model'!G45/(1+$B22)^('DCF Model'!C19+4)+('DCF Model'!G39+'DCF Model'!G42)*G$17/(1+$B22)^('DCF Model'!C19+4)-'DCF Model'!C16)*1000000/'DCF Model'!C15,0),"") -> 1624 | H22: =IFERROR(ROUND(('DCF Model'!C45/(1+$B22)^('DCF Model'!C19+0)+'DCF Model'!D45/(1+$B22)^('DCF Model'!C19+1)+'DCF Model'!E45/(1+$B22)^('DCF Model'!C19+2)+'DCF Model'!F45/(1+$B22)^('DCF Model'!C19+3)+'DCF Model'!G45/(1+$B22)^('DCF Model'!C19+4)+('DCF Model'!G39+'DCF Model'!G42)*H$17/(1+$B22)^('DCF Model'!C19+4)-'DCF Model'!C16)*1000000/'DCF Model'!C15,0),"") -> 1718 | I22: =IFERROR(ROUND(('DCF Model'!C45/(1+$B22)^('DCF Model'!C19+0)+'DCF Model'!D45/(1+$B22)^('DCF Model'!C19+1)+'DCF Model'!E45/(1+$B22)^('DCF Model'!C19+2)+'DCF Model'!F45/(1+$B22)^('DCF Model'!C19+3)+'DCF Model'!G45/(1+$B22)^('DCF Model'!C19+4)+('DCF Model'!G39+'DCF Model'!G42)*I$17/(1+$B22)^('DCF Model'!C19+4)-'DCF Model'!C16)*1000000/'DCF Model'!C15,0),"") -> 1812
B23: =$C$3+0.01 -> 0.1254 | C23: =IFERROR(ROUND(('DCF Model'!C45/(1+$B23)^('DCF Model'!C19+0)+'DCF Model'!D45/(1+$B23)^('DCF Model'!C19+1)+'DCF Model'!E45/(1+$B23)^('DCF Model'!C19+2)+'DCF Model'!F45/(1+$B23)^('DCF Model'!C19+3)+'DCF Model'!G45/(1+$B23)^('DCF Model'!C19+4)+('DCF Model'!G39+'DCF Model'!G42)*C$17/(1+$B23)^('DCF Model'!C19+4)-'DCF Model'!C16)*1000000/'DCF Model'!C15,0),"") -> 1226 | D23: =IFERROR(ROUND(('DCF Model'!C45/(1+$B23)^('DCF Model'!C19+0)+'DCF Model'!D45/(1+$B23)^('DCF Model'!C19+1)+'DCF Model'!E45/(1+$B23)^('DCF Model'!C19+2)+'DCF Model'!F45/(1+$B23)^('DCF Model'!C19+3)+'DCF Model'!G45/(1+$B23)^('DCF Model'!C19+4)+('DCF Model'!G39+'DCF Model'!G42)*D$17/(1+$B23)^('DCF Model'!C19+4)-'DCF Model'!C16)*1000000/'DCF Model'!C15,0),"") -> 1318 | E23: =IFERROR(ROUND(('DCF Model'!C45/(1+$B23)^('DCF Model'!C19+0)+'DCF Model'!D45/(1+$B23)^('DCF Model'!C19+1)+'DCF Model'!E45/(1+$B23)^('DCF Model'!C19+2)+'DCF Model'!F45/(1+$B23)^('DCF Model'!C19+3)+'DCF Model'!G45/(1+$B23)^('DCF Model'!C19+4)+('DCF Model'!G39+'DCF Model'!G42)*E$17/(1+$B23)^('DCF Model'!C19+4)-'DCF Model'!C16)*1000000/'DCF Model'!C15,0),"") -> 1410 | F23: =IFERROR(ROUND(('DCF Model'!C45/(1+$B23)^('DCF Model'!C19+0)+'DCF Model'!D45/(1+$B23)^('DCF Model'!C19+1)+'DCF Model'!E45/(1+$B23)^('DCF Model'!C19+2)+'DCF Model'!F45/(1+$B23)^('DCF Model'!C19+3)+'DCF Model'!G45/(1+$B23)^('DCF Model'!C19+4)+('DCF Model'!G39+'DCF Model'!G42)*F$17/(1+$B23)^('DCF Model'!C19+4)-'DCF Model'!C16)*1000000/'DCF Model'!C15,0),"") -> 1502 | G23: =IFERROR(ROUND(('DCF Model'!C45/(1+$B23)^('DCF Model'!C19+0)+'DCF Model'!D45/(1+$B23)^('DCF Model'!C19+1)+'DCF Model'!E45/(1+$B23)^('DCF Model'!C19+2)+'DCF Model'!F45/(1+$B23)^('DCF Model'!C19+3)+'DCF Model'!G45/(1+$B23)^('DCF Model'!C19+4)+('DCF Model'!G39+'DCF Model'!G42)*G$17/(1+$B23)^('DCF Model'!C19+4)-'DCF Model'!C16)*1000000/'DCF Model'!C15,0),"") -> 1594 | H23: =IFERROR(ROUND(('DCF Model'!C45/(1+$B23)^('DCF Model'!C19+0)+'DCF Model'!D45/(1+$B23)^('DCF Model'!C19+1)+'DCF Model'!E45/(1+$B23)^('DCF Model'!C19+2)+'DCF Model'!F45/(1+$B23)^('DCF Model'!C19+3)+'DCF Model'!G45/(1+$B23)^('DCF Model'!C19+4)+('DCF Model'!G39+'DCF Model'!G42)*H$17/(1+$B23)^('DCF Model'!C19+4)-'DCF Model'!C16)*1000000/'DCF Model'!C15,0),"") -> 1685 | I23: =IFERROR(ROUND(('DCF Model'!C45/(1+$B23)^('DCF Model'!C19+0)+'DCF Model'!D45/(1+$B23)^('DCF Model'!C19+1)+'DCF Model'!E45/(1+$B23)^('DCF Model'!C19+2)+'DCF Model'!F45/(1+$B23)^('DCF Model'!C19+3)+'DCF Model'!G45/(1+$B23)^('DCF Model'!C19+4)+('DCF Model'!G39+'DCF Model'!G42)*I$17/(1+$B23)^('DCF Model'!C19+4)-'DCF Model'!C16)*1000000/'DCF Model'!C15,0),"") -> 1777
B24: =$C$3+0.015 -> 0.1304 | C24: =IFERROR(ROUND(('DCF Model'!C45/(1+$B24)^('DCF Model'!C19+0)+'DCF Model'!D45/(1+$B24)^('DCF Model'!C19+1)+'DCF Model'!E45/(1+$B24)^('DCF Model'!C19+2)+'DCF Model'!F45/(1+$B24)^('DCF Model'!C19+3)+'DCF Model'!G45/(1+$B24)^('DCF Model'!C19+4)+('DCF Model'!G39+'DCF Model'!G42)*C$17/(1+$B24)^('DCF Model'!C19+4)-'DCF Model'!C16)*1000000/'DCF Model'!C15,0),"") -> 1205 | D24: =IFERROR(ROUND(('DCF Model'!C45/(1+$B24)^('DCF Model'!C19+0)+'DCF Model'!D45/(1+$B24)^('DCF Model'!C19+1)+'DCF Model'!E45/(1+$B24)^('DCF Model'!C19+2)+'DCF Model'!F45/(1+$B24)^('DCF Model'!C19+3)+'DCF Model'!G45/(1+$B24)^('DCF Model'!C19+4)+('DCF Model'!G39+'DCF Model'!G42)*D$17/(1+$B24)^('DCF Model'!C19+4)-'DCF Model'!C16)*1000000/'DCF Model'!C15,0),"") -> 1294 | E24: =IFERROR(ROUND(('DCF Model'!C45/(1+$B24)^('DCF Model'!C19+0)+'DCF Model'!D45/(1+$B24)^('DCF Model'!C19+1)+'DCF Model'!E45/(1+$B24)^('DCF Model'!C19+2)+'DCF Model'!F45/(1+$B24)^('DCF Model'!C19+3)+'DCF Model'!G45/(1+$B24)^('DCF Model'!C19+4)+('DCF Model'!G39+'DCF Model'!G42)*E$17/(1+$B24)^('DCF Model'!C19+4)-'DCF Model'!C16)*1000000/'DCF Model'!C15,0),"") -> 1384 | F24: =IFERROR(ROUND(('DCF Model'!C45/(1+$B24)^('DCF Model'!C19+0)+'DCF Model'!D45/(1+$B24)^('DCF Model'!C19+1)+'DCF Model'!E45/(1+$B24)^('DCF Model'!C19+2)+'DCF Model'!F45/(1+$B24)^('DCF Model'!C19+3)+'DCF Model'!G45/(1+$B24)^('DCF Model'!C19+4)+('DCF Model'!G39+'DCF Model'!G42)*F$17/(1+$B24)^('DCF Model'!C19+4)-'DCF Model'!C16)*1000000/'DCF Model'!C15,0),"") -> 1474 | G24: =IFERROR(ROUND(('DCF Model'!C45/(1+$B24)^('DCF Model'!C19+0)+'DCF Model'!D45/(1+$B24)^('DCF Model'!C19+1)+'DCF Model'!E45/(1+$B24)^('DCF Model'!C19+2)+'DCF Model'!F45/(1+$B24)^('DCF Model'!C19+3)+'DCF Model'!G45/(1+$B24)^('DCF Model'!C19+4)+('DCF Model'!G39+'DCF Model'!G42)*G$17/(1+$B24)^('DCF Model'!C19+4)-'DCF Model'!C16)*1000000/'DCF Model'!C15,0),"") -> 1564 | H24: =IFERROR(ROUND(('DCF Model'!C45/(1+$B24)^('DCF Model'!C19+0)+'DCF Model'!D45/(1+$B24)^('DCF Model'!C19+1)+'DCF Model'!E45/(1+$B24)^('DCF Model'!C19+2)+'DCF Model'!F45/(1+$B24)^('DCF Model'!C19+3)+'DCF Model'!G45/(1+$B24)^('DCF Model'!C19+4)+('DCF Model'!G39+'DCF Model'!G42)*H$17/(1+$B24)^('DCF Model'!C19+4)-'DCF Model'!C16)*1000000/'DCF Model'!C15,0),"") -> 1654 | I24: =IFERROR(ROUND(('DCF Model'!C45/(1+$B24)^('DCF Model'!C19+0)+'DCF Model'!D45/(1+$B24)^('DCF Model'!C19+1)+'DCF Model'!E45/(1+$B24)^('DCF Model'!C19+2)+'DCF Model'!F45/(1+$B24)^('DCF Model'!C19+3)+'DCF Model'!G45/(1+$B24)^('DCF Model'!C19+4)+('DCF Model'!G39+'DCF Model'!G42)*I$17/(1+$B24)^('DCF Model'!C19+4)-'DCF Model'!C16)*1000000/'DCF Model'!C15,0),"") -> 1744
B26: All values dynamically linked to DCF Model. Headers auto-center on current WACC / Terminal g / Exit Multiple.

Sheet Segment Bridge
B2: Segment Bridge: Solution vs SaaS vs Other (CVC)
B3: Only 2 fiscal years of segment data are disclosed (FY2024/9, FY2025/9) -- too few for the main DCF's 4-year hist_years array, hence this separate sheet rather than a 'segments' override block.
B5: Segment P&L (JPY mn)
C6: FY2024/9 | D6: FY2025/9 | E6: YoY %
B7: Solution Revenue | C7: 7680 | D7: 9171 | E7: =D7/C7-1 -> 0.19414063
B8: Solution Operating Income | C8: 2458 | D8: 3236 | E8: =D8/C8-1 -> 0.31651749
B9: Solution Margin | C9: =C8/C7 -> 0.32005208 | D9: =D8/D7 -> 0.35285138
B11: SaaS Revenue | C11: 315 | D11: 446 | E11: =D11/C11-1 -> 0.41587302
B12: SaaS Operating Income/(Loss) | C12: -151 | D12: -424 | E12: loss widened
B14: Other (incl. CVC) Operating Income/(Loss) | C14: -3 | D14: -234 | E14: n/a (base near zero)
B16: Consolidated Operating Income | C16: 2304 | D16: 2578 | E16: =D16/C16-1 -> 0.11892361
B17: Check: Solution OI + SaaS OI + Other OI = Consolidated OI | D17: =D8+D12+D14 -> 2578
B19: Depreciation by segment (reference)
C20: FY2024/9 | D20: FY2025/9
B21: Solution D&A | C21: 122 | D21: 127
B22: SaaS D&A | C22: 24 | D22: 40
B24: Normalization (FY2025/9, JPY mn)
B25: Consolidated Operating Income | C25: =D16 -> 2578
B26: + CVC securities writedown (one-off, in COGS) | C26: 232
B27: Normalized OI (ex-CVC only) | C27: =C25+C26 -> 2810
B28: as % of revenue (9,618) | C28: =C27/9618 -> 0.29216053
B30: + SaaS operating loss (strategic investment) | C30: =-D12 -> 424
B31: Fully Normalized OI (ex-CVC, ex-SaaS loss) | C31: =C27+C30 -> 3234
B32: as % of revenue (9,618) | C32: =C31/9618 -> 0.33624454
B34: The gap between consolidated margin (26.8%) and Solution-segment margin (35.3%) is the sum of a deliberate investment (SaaS loss) and a one-off charge (CVC writedown), not core-business deterioration. The investment case reduces to two questions: (a) when does the 424 SaaS operating loss shrink or turn positive, and (b) does the CVC writedown recur. Neither is knowable from FY2025/9 data alone.
B37: Customer Concentration (disclosed 10%+ customers only)
B38: Customer | C38: FY2024/9 | D38: % of Rev | E38: FY2025/9 | F38: % of Rev
B39: Kioxia Corporation | C39: 1613 | D39: =C39/7995 -> 0.20175109 | E39: 1647 | F39: =E39/9618 -> 0.17124142
B40: Renesas Electronics Corp. | C40: 1275 | D40: =C40/7995 -> 0.15947467 | E40: - | F40: -
B41: Nexty Electronics Corp. | C41: 807 | D41: =C41/7995 -> 0.10093809 | E41: 1119 | F41: =E41/9618 -> 0.11634435
B42: Disclosed customers, total | C42: =SUM(C39:C41) -> 3695 | D42: =C42/7995 -> 0.46216385 | E42: =SUM(E39:E41) -> 2766 | F42: =E42/9618 -> 0.28758578
