Workbook

Sheet Executive Summary
B1: DISCLAIMER: This is a sample analysis for demonstration purposes only. It does not constitute investment advice.
B3: Data Section (3905.T)
B4: Equity Research Report
B6: Company | C6: Data Section
B7: Ticker | C7: 3905.T (TSE Growth)
B8: Sector | C8: GPU Cloud / Data Center
B9: Current Price | C9: 1840
B10: Target Price (Mid) | C10: =ROUND(AVERAGE(C16:C19),0) -> 420
B11: Recommendation | C11: =IF(C12>0.15,"BUY",IF(C12>0.05,"HOLD","SELL")) -> SELL
B12: Upside / Downside | C12: =(C10-C9)/C9 -> -0.77173913
B14: Valuation Summary
B15: Methodology | C15: Implied Value (JPY) | D15: vs Current Price
B16: DCF - Perpetuity Growth | C16: =IF('DCF Model'!C53<'DCF Model'!C16,"INVALID (EV < net debt)",'DCF Model'!C55) -> 327 | D16: =IF(ISNUMBER(C16),(C16-C9)/C9,"N/A") -> -0.82228261
B17: DCF - Exit Multiple | C17: ='DCF Model'!C64 -> 513 | D17: =(C17-C9)/C9 -> -0.72119565
B18: Comps - EV/EBITDA Median | C18: N/A (FY3/26 EBITDA from cancelled contract) | D18: =IF(ISNUMBER(C18),(C18-C9)/C9,"N/A") -> N/A
B19: Comps - PER Median | C19: N/A (FY3/26 NI from cancelled contract) | D19: =IF(ISNUMBER(C19),(C19-C9)/C9,"N/A") -> N/A
B21: Integrated Valuation Range | C21: =MIN(C16:C19)&" - "&MAX(C16:C19) -> 327 - 513
B23: Key Investment Thesis
B24: Physical progress is real: ~4,700 GPUs procured with a Taiwanese server partner, Thai BOI approval secured, and servers delivered to the first domestic data center.
B25: Our Base case excludes the cancelled JPY80bn contract and treats the JPY5.6bn Q1 arrangement fee as one-off; three data centers at full run-rate still imply revenue above JPY50bn from FY3/28.
B26: ="At "&TEXT(C9,"#,##0")&" the stock trades at "&TEXT('Comps Analysis'!L5,"0.0""x""")&" PER and "&TEXT('Comps Analysis'!M5,"0.00""x""")&" PBR; our target of "&TEXT(C10,"#,##0")&" implies "&TEXT(C12,"+0.0%;-0.0%")&" with WACC of "&TEXT('DCF Model'!C26,"0.00%")&"." -> At 1,840 the stock trades at 21.0x PER and 3.18x PBR; our target of 420 implies -77.2% with WACC of 12.53%.
B28: Key Risks
B29: A large contract was cancelled retroactively; receivables and contract assets of JPY8.8bn may be partly unrecoverable and FY3/26 results could be restated.
B30: Cash is under JPY1bn against JPY6.7bn of construction in progress; warrant exercises keep diluting shareholders, so the target uses the treasury-stock-method share count (47.5m, +48%).
B31: A short-seller report alleges export-control breaches on GPU sourcing; the company is suing, but an adverse regulatory finding would stall the Thai project.
B33: Note (2026-08-23): Target = average of DCF PGM and Exit only. Comps EV/EBITDA (1,417) and PER (3,626) are excluded because the FY3/26 EBITDA/NI they rest on came mostly from the retroactively cancelled JPY80bn contract. Share count is treasury-stock-method diluted (47,465,390); on basic shares (32,017,051) PGM/Exit would be about 1,967 / 3,169 (mid 2,568). Base Y1 includes the one-off JPY5.6bn arrangement fee; ex-fee Y1 operating income is roughly break-even.

Sheet Financial Statements
B2: Data Section - Historical Financials (JPY mn)
C4: FY2024/3 | D4: FY2025/3 | E4: FY2026/3
B5: Income Statement
B6: Revenue | C6: 2229 | D6: 2943 | E6: 33605
B7: COGS | C7: 1528 | D7: 1690 | E7: 27208
B8: Gross Profit | C8: =C6-C7 -> 701 | D8: =D6-D7 -> 1253 | E8: =E6-E7 -> 6397
B9: Gross Margin | C9: =C8/C6 -> 0.3144908 | D9: =D8/D6 -> 0.42575603 | E9: =E8/E6 -> 0.19035858
B10: SGA | C10: 917 | D10: 1748 | E10: 2852
B11: Operating Income | C11: -216 | D11: -496 | E11: 3545
B12: Net Income | C12: -1262 | D12: -655 | E12: 2802
B13: Operating Margin | C13: =C11/C6 -> -0.096904441 | D13: =D11/D6 -> -0.16853551 | E13: =E11/E6 -> 0.10549025
B14: Net Margin | C14: =C12/C6 -> -0.56617317 | D14: =D12/D6 -> -0.22256201 | E14: =E12/E6 -> 0.083380449
B15: Revenue Growth (YoY) | C15: n/a | D15: =(D6-C6)/C6 -> 0.32032301 | E15: =(E6-D6)/D6 -> 10.41862
B16: Operating Income Growth (YoY) | C16: n/a | D16: =(D11-C11)/C11 -> 1.2962963 | E16: =(E11-D11)/D11 -> -8.1471774
B18: Cash Flow Statement
B19: Operating Cash Flow | C19: 334 | D19: -83 | E19: -4914
B20: Capex | C20: 537 | D20: 94 | E20: 4629
B21: Free Cash Flow | C21: =C19-C20 -> -203 | D21: =D19-D20 -> -177 | E21: =E19-E20 -> -9543
B22: FCF Margin | C22: =C21/C6 -> -0.09107223 | D22: =D21/D6 -> -0.060142712 | E22: =E21/E6 -> -0.2839756
B23: Capex / Revenue | C23: =C20/C6 -> 0.24091521 | D23: =D20/D6 -> 0.031940197 | E23: =E20/E6 -> 0.13774736
B25: Balance Sheet Highlights
B26: Cash & Deposits | C26: 1659 | D26: 526 | E26: 418
B27: Short-term Debt | C27: 1238 | D27: 1370 | E27: 545
B28: Net Debt (Cash) | C28: =C27-C26 -> -421 | D28: =D27-D26 -> 844 | E28: =E27-E26 -> 127
B30: Note: OCF / Cash / Debt coverage OCF 3/3, Cash 3/3, Debt 3/3 — blank cells are years with no year-key match in the source data (verify against 決算短信 or set hist_ocf / hist_cash / hist_debt in overrides).

Sheet DCF Model
B2: DCF Valuation Model - Data Section
B4: Assumptions
B5: Capex / Revenue | C5: 0.06
B6: Effective Tax Rate | C6: 0.306
B7: Risk-Free Rate | C7: 0.016
B8: Beta | C8: 1.35
B9: Equity Risk Premium | C9: 0.055
B10: Size Premium | C10: 0.035
B11: After-tax Cost of Debt | C11: 0.01735
B12: D/E Ratio | C12: 0
B13: Terminal Growth Rate | C13: 0.015
B14: Exit Multiple (EV/EBITDA) | C14: 8
B15: Fully Diluted Shares | C15: 47465390
B16: Net Debt (JPY mn) | C16: -216
... B20: LTM Revenue (JPY mn) (override) | C20: 39265
B22: WACC Calculation
B23: Cost of Equity (Ke) | C23: =C7+C8*C9+C10 -> 0.12525
B24: Weight of Equity | C24: =1/(1+C12) -> 1
B25: Weight of Debt | C25: =C12/(1+C12) -> 0
B26: WACC | C26: =C23*C24+C11*C25 -> 0.12525
B27: Active Scenario | C27: Base | D27: 4
B28: Projected Free Cash Flow
C29: FY2027(E) | D29: FY2028(E) | E29: FY2029(E) | F29: FY2030(E) | G29: FY2031(E)
B30: Revenue Growth (YoY) | C30: =CHOOSE($D$27,C69,C70,C71,C72,C73) -> -0.55 | D30: =CHOOSE($D$27,D69,D70,D71,D72,D73) -> 0.33 | E30: =CHOOSE($D$27,E69,E70,E71,E72,E73) -> 0.1 | F30: =CHOOSE($D$27,F69,F70,F71,F72,F73) -> 0.05 | G30: =CHOOSE($D$27,G69,G70,G71,G72,G73) -> 0.03
B31: COGS % of Revenue | C31: =CHOOSE($D$27,C76,C77,C78,C79,C80) -> 0.81 | D31: =CHOOSE($D$27,D76,D77,D78,D79,D80) -> 0.825 | E31: =CHOOSE($D$27,E76,E77,E78,E79,E80) -> 0.8 | F31: =CHOOSE($D$27,F76,F77,F78,F79,F80) -> 0.805 | G31: =CHOOSE($D$27,G76,G77,G78,G79,G80) -> 0.81
B32: SGA % of Revenue | C32: =CHOOSE($D$27,C83,C84,C85,C86,C87) -> 0.09 | D32: =CHOOSE($D$27,D83,D84,D85,D86,D87) -> 0.095 | E32: =CHOOSE($D$27,E83,E84,E85,E86,E87) -> 0.1 | F32: =CHOOSE($D$27,F83,F84,F85,F86,F87) -> 0.095 | G32: =CHOOSE($D$27,G83,G84,G85,G86,G87) -> 0.09
B33: Revenue | C33: =C17*(1+C30) -> 15122.25 | D33: =C33*(1+D30) -> 20112.592 | E33: =D33*(1+E30) -> 22123.852 | F33: =E33*(1+F30) -> 23230.044 | G33: =F33*(1+G30) -> 23926.946
B34: COGS | C34: =C33*C31 -> 12249.022 | D34: =D33*D31 -> 16592.889 | E34: =E33*E31 -> 17699.081 | F34: =F33*F31 -> 18700.186 | G34: =G33*G31 -> 19380.826
B35: Gross Profit | C35: =C33-C34 -> 2873.2275 | D35: =D33-D34 -> 3519.7037 | E35: =E33-E34 -> 4424.7703 | F35: =F33-F34 -> 4529.8586 | G35: =G33-G34 -> 4546.1197
B36: Gross Margin | C36: =C35/C33 -> 0.19 | D36: =D35/D33 -> 0.175 | E36: =E35/E33 -> 0.2 | F36: =F35/F33 -> 0.195 | G36: =G35/G33 -> 0.19
B37: SGA Expense | C37: =C33*C32 -> 1361.0025 | D37: =D33*D32 -> 1910.6963 | E37: =E33*E32 -> 2212.3852 | F37: =F33*F32 -> 2206.8542 | G37: =G33*G32 -> 2153.4251
B38: Implied Operating Margin | C38: =(C35-C37)/C33 -> 0.1 | D38: =(D35-D37)/D33 -> 0.08 | E38: =(E35-E37)/E33 -> 0.1 | F38: =(F35-F37)/F33 -> 0.1 | G38: =(G35-G37)/G33 -> 0.1
B39: Operating Income (EBIT) | C39: =C35-C37 -> 1512.225 | D39: =D35-D37 -> 1609.0074 | E39: =E35-E37 -> 2212.3852 | F39: =F35-F37 -> 2323.0044 | G39: =G35-G37 -> 2392.6946
B40: Less: Tax | C40: =MAX(0,C39*C6) -> 462.74085 | D40: =MAX(0,D39*C6) -> 492.35626 | E40: =MAX(0,E39*C6) -> 676.98986 | F40: =MAX(0,F39*C6) -> 710.83936 | G40: =MAX(0,G39*C6) -> 732.16454
B41: NOPAT | C41: =C39-C40 -> 1049.4841 | D41: =D39-D40 -> 1116.6511 | E41: =E39-E40 -> 1535.3953 | F41: =F39-F40 -> 1612.1651 | G41: =G39-G40 -> 1660.53
B42: Plus: D&A | C42: =C33*C18 -> 877.0905 | D42: =D33*C18 -> 1166.5304 | E42: =E33*C18 -> 1283.1834 | F42: =F33*C18 -> 1347.3426 | G42: =G33*C18 -> 1387.7628
B43: Less: Capex | C43: =C33*C5 -> 907.335 | D43: =D33*C5 -> 1206.7555 | E43: =E33*C5 -> 1327.4311 | F43: =F33*C5 -> 1393.8027 | G43: =G33*C5 -> 1435.6167
B44: Change in NWC | C44: ='NWC Schedule'!D19 -> -5093.9626 | D44: ='NWC Schedule'!E19 -> 1543.7746 | E44: ='NWC Schedule'!F19 -> 725.70642 | F44: ='NWC Schedule'!G19 -> 132.0309 | G44: ='NWC Schedule'!H19 -> 55.300234
B45: Unlevered Free Cash Flow | C45: =C41+C42-C43-C44 -> 6113.2023 | D45: =D41+D42-D43-D44 -> -467.34862 | E45: =E41+E42-E43-E44 -> 765.44119 | F45: =F41+F42-F43-F44 -> 1433.6741 | G45: =G41+G42-G43-G44 -> 1557.3759
B46: Discount Factor | C46: =1/(1+C26)^(C19+0) -> 0.8886914 | D46: =1/(1+C26)^(C19+1) -> 0.78977241 | E46: =1/(1+C26)^(C19+2) -> 0.70186395 | F46: =1/(1+C26)^(C19+3) -> 0.62374046 | G46: =1/(1+C26)^(C19+4) -> 0.55431278
...

Sheet NWC Schedule
B2: NWC Schedule - Data Section
B4: Working Capital Drivers (Days) | C4: Base Year | D4: FY2027(E) | E4: FY2028(E) | F4: FY2029(E) | G4: FY2030(E) | H4: FY2031(E)
B5: DSO (Days Sales Outstanding) | C5: =C12/C9*365 -> 121.46392 | D5: =CHOOSE('DCF Model'!$D$27,D25,D26,D27,D28,D29) -> 121 | E5: =CHOOSE('DCF Model'!$D$27,E25,E26,E27,E28,E29) -> 124 | F5: =CHOOSE('DCF Model'!$D$27,F25,F26,F27,F28,F29) -> 126 | G5: =CHOOSE('DCF Model'!$D$27,G25,G26,G27,G28,G29) -> 124 | H5: =CHOOSE('DCF Model'!$D$27,H25,H26,H27,H28,H29) -> 122
B6: DIH (Days Inventory Held) | C6: =C13/C10*365 -> 1.1939503 | D6: =CHOOSE('DCF Model'!$D$27,D32,D33,D34,D35,D36) -> 1 | E6: =CHOOSE('DCF Model'!$D$27,E32,E33,E34,E35,E36) -> 1 | F6: =CHOOSE('DCF Model'!$D$27,F32,F33,F34,F35,F36) -> 1 | G6: =CHOOSE('DCF Model'!$D$27,G32,G33,G34,G35,G36) -> 1 | H6: =CHOOSE('DCF Model'!$D$27,H32,H33,H34,H35,H36) -> 1
B7: DPO (Days Payable Outstanding) | C7: =C15/C10*365 -> 27.782821 | D7: =CHOOSE('DCF Model'!$D$27,D39,D40,D41,D42,D43) -> 28 | E7: =CHOOSE('DCF Model'!$D$27,E39,E40,E41,E42,E43) -> 27 | F7: =CHOOSE('DCF Model'!$D$27,F39,F40,F41,F42,F43) -> 27 | G7: =CHOOSE('DCF Model'!$D$27,G39,G40,G41,G42,G43) -> 28 | H7: =CHOOSE('DCF Model'!$D$27,H39,H40,H41,H42,H43) -> 28
B8: P&L Reference (JPY mn)
B9: Revenue | C9: 33605 | D9: ='DCF Model'!C33 -> 15122.25 | E9: ='DCF Model'!D33 -> 20112.592 | F9: ='DCF Model'!E33 -> 22123.852 | G9: ='DCF Model'!F33 -> 23230.044 | H9: ='DCF Model'!G33 -> 23926.946
B10: COGS | C10: 27208 | D10: ='DCF Model'!C34 -> 12249.022 | E10: ='DCF Model'!D34 -> 16592.889 | F10: ='DCF Model'!E34 -> 17699.081 | G10: ='DCF Model'!F34 -> 18700.186 | H10: ='DCF Model'!G34 -> 19380.826
B11: Working Capital Items (JPY mn)
B12: Accounts Receivable | C12: 11183 | D12: =D9*D5/365 -> 5013.1295 | E12: =E9*E5/365 -> 6832.7712 | F12: =F9*F5/365 -> 7637.2749 | G12: =G9*G5/365 -> 7891.8507 | H12: =H9*H5/365 -> 7997.4996
B13: Inventory | C13: 89 | D13: =D10*D6/365 -> 33.558966 | E13: =E10*E6/365 -> 45.459969 | F13: =F10*F6/365 -> 48.490634 | G13: =G10*G6/365 -> 51.233385 | H13: =H10*H6/365 -> 53.098153
B14: Current Assets (AR + Inv) | C14: =C12+C13 -> 11272 | D14: =D12+D13 -> 5046.6884 | E14: =E12+E13 -> 6878.2311 | F14: =F12+F13 -> 7685.7655 | G14: =G12+G13 -> 7943.0841 | H14: =H12+H13 -> 8050.5978
B15: Accounts Payable | C15: 2071 | D15: =D10*D7/365 -> 939.65104 | E15: =E10*E7/365 -> 1227.4192 | F15: =F10*F7/365 -> 1309.2471 | G15: =G10*G7/365 -> 1434.5348 | H15: =H10*H7/365 -> 1486.7483
B16: Current Liabilities (AP) | C16: =C15 -> 2071 | D16: =D15 -> 939.65104 | E16: =E15 -> 1227.4192 | F16: =F15 -> 1309.2471 | G16: =G15 -> 1434.5348 | H16: =H15 -> 1486.7483
B17: Net Working Capital (JPY mn)
B18: Net Working Capital | C18: =C14-C16 -> 9201 | D18: =D14-D16 -> 4107.0374 | E18: =E14-E16 -> 5650.8119 | F18: =F14-F16 -> 6376.5184 | G18: =G14-G16 -> 6508.5493 | H18: =H14-H16 -> 6563.8495
B19: Change in NWC | C19: n/a | D19: =D18-C18 -> -5093.9626 | E19: =E18-D18 -> 1543.7746 | F19: =F18-E18 -> 725.70642 | G19: =G18-F18 -> 132.0309 | H19: =H18-G18 -> 55.300234
B22: Scenario Input Matrix (Working Capital Days)
D23: FY2027(E) | E23: FY2028(E) | F23: FY2029(E) | G23: FY2030(E) | H23: FY2031(E)
B24: DSO (Days)
B25: Base | D25: 121 | E25: 121 | F25: 121 | G25: 121 | H25: 121
B26: Upside | D26: 115 | E26: 110 | F26: 105 | G26: 100 | H26: 100
B27: Management | D27: 121 | E27: 121 | F27: 121 | G27: 121 | H27: 121
B28: Downside 1 | D28: 121 | E28: 124 | F28: 126 | G28: 124 | H28: 122
B29: Downside 2 | D29: 124 | E29: 128 | F29: 130 | G29: 128 | H29: 126
B31: DIH (Days)
B32: Base | D32: 1 | E32: 1 | F32: 1 | G32: 1 | H32: 1
B33: Upside | D33: 1 | E33: 1 | F33: 1 | G33: 1 | H33: 1
B34: Management | D34: 1 | E34: 1 | F34: 1 | G34: 1 | H34: 1
B35: Downside 1 | D35: 1 | E35: 1 | F35: 1 | G35: 1 | H35: 1
B36: Downside 2 | D36: 1 | E36: 1 | F36: 1 | G36: 1 | H36: 1
B38: DPO (Days)
B39: Base | D39: 28 | E39: 28 | F39: 28 | G39: 28 | H39: 28
B40: Upside | D40: 28 | E40: 29 | F40: 30 | G40: 30 | H40: 30
B41: Management | D41: 28 | E41: 28 | F41: 28 | G41: 28 | H41: 28
B42: Downside 1 | D42: 28 | E42: 27 | F42: 27 | G42: 28 | H42: 28
B43: Downside 2 | D43: 27 | E43: 26 | F43: 26 | G43: 27 | H43: 27

Sheet Comps Analysis
B2: Comparable Company Analysis
B3: Peer prices as of 2026-08-22 (Mkt Cap / EV of peer rows are static CSV values; the subject row is live-linked to Executive Summary)
B4: Company | C4: Ticker | D4: Mkt Cap (JPY mn) | E4: EV (JPY mn) | F4: Revenue (JPY mn) | G4: EBITDA (JPY mn) | H4: Op Income (JPY mn) | I4: Net Income (JPY mn) | J4: EV/EBITDA | K4: EV/Revenue | L4: PER | M4: PBR | N4: Op Margin | O4: ROE | P4: Book Value (JPY mn) | Q4: Note
B5: Data Section | C5: 3905.T | D5: ='Executive Summary'!C9*C23/1000000 -> 58911.374 | E5: =D5+C24 -> 58695.374 | F5: 33605 | G5: 4000 | H5: 3545 | I5: 2802 | J5: =IFERROR(E5/G5,"") -> 14.673843 | K5: =IFERROR(E5/F5,"") -> 1.7466262 | L5: =IFERROR(D5/I5,"") -> 21.024759 | M5: =IFERROR(D5/P5,"") -> 3.1790715 | N5: =IFERROR(H5/F5,"") -> 0.10549025 | O5: =IFERROR(I5/P5,"") -> 0.15120609 | P5: 18531
B6: SAKURA Internet | C6: 3778.T | D6: 142888 | E6: 163324 | F6: 35302 | G6: 7335 | H6: -404 | I6: 216 | J6: =IFERROR(E6/G6,"") -> 22.266394 | K6: =IFERROR(E6/F6,"") -> 4.6264801 | L6: =IFERROR(D6/I6,"") -> 661.51852 | M6: =IFERROR(D6/P6,"") -> 4.7469519 | N6: =IFERROR(H6/F6,"") -> -0.011444111 | O6: =IFERROR(I6/P6,"") -> 0.0071758413 | P6: 30101
B7: GMO internet | C7: 4784.T | D7: 183461 | E7: 178442 | F7: 78548 | G7: 12989 | H7: 8225 | I7: 5563 | J7: =IFERROR(E7/G7,"") -> 13.737932 | K7: =IFERROR(E7/F7,"") -> 2.2717574 | L7: =IFERROR(D7/I7,"") -> 32.978788 | M7: =IFERROR(D7/P7,"") -> 13.207185 | N7: =IFERROR(H7/F7,"") -> 0.10471304 | O7: =IFERROR(I7/P7,"") -> 0.40047513 | P7: 13891
B8: Internet Initiative Japan | C8: 3774.T | D8: 599553 | E8: 596728 | F8: 345395 | G8: 67509 | H8: 34835 | I8: 24188 | J8: =IFERROR(E8/G8,"") -> 8.8392362 | K8: =IFERROR(E8/F8,"") -> 1.7276683 | L8: =IFERROR(D8/I8,"") -> 24.787209 | M8: =IFERROR(D8/P8,"") -> 3.7944711 | N8: =IFERROR(H8/F8,"") -> 0.10085554 | O8: =IFERROR(I8/P8,"") -> 0.15308183 | P8: 158007
B9: BroadBand Tower | C9: 3776.T | D9: 14966 | E9: 10354 | F9: 15290 | G9: 1750 | H9: 811 | I9: 300 | J9: =IFERROR(E9/G9,"") -> 5.9165714 | K9: =IFERROR(E9/F9,"") -> 0.67717462 | L9: =IFERROR(D9/I9,"") -> 49.886667 | M9: =IFERROR(D9/P9,"") -> 1.7043617 | N9: =IFERROR(H9/F9,"") -> 0.053041203 | O9: =IFERROR(I9/P9,"") -> 0.034164674 | P9: 8781
B14: Statistics
B15: 25th Percentile | D15: =PERCENTILE(J6:J9,0.25) -> 8.10857 | E15: =PERCENTILE(K6:K9,0.25) -> 1.4650449 | F15: =PERCENTILE(L6:L9,0.25) -> 30.930893 | G15: =PERCENTILE(M6:M9,0.25) -> 3.2719438 | H15: =PERCENTILE(N6:N9,0.25) -> 0.036919875 | I15: =PERCENTILE(O6:O9,0.25) -> 0.027417466
B16: Median (50th) | D16: =MEDIAN(J6:J9) -> 11.288584 | E16: =MEDIAN(K6:K9) -> 1.9997129 | F16: =MEDIAN(L6:L9) -> 41.432728 | G16: =MEDIAN(M6:M9) -> 4.2707115 | H16: =MEDIAN(N6:N9) -> 0.076948373 | I16: =MEDIAN(O6:O9) -> 0.09362325
B17: 75th Percentile | D17: =PERCENTILE(J6:J9,0.75) -> 15.870048 | E17: =PERCENTILE(K6:K9,0.75) -> 2.8604381 | F17: =PERCENTILE(L6:L9,0.75) -> 202.79463 | G17: =PERCENTILE(M6:M9,0.75) -> 6.8620101 | H17: =PERCENTILE(N6:N9,0.75) -> 0.10181992 | I17: =PERCENTILE(O6:O9,0.75) -> 0.21493015
B19: Implied Valuation for Data Section
B20: Data Section Financials
B21: EBITDA (JPY mn) | C21: 4000
B22: Net Income (JPY mn) | C22: 2802
B23: Shares Outstanding | C23: 32017051
B24: Net Debt (JPY mn) | C24: -216
B26: Implied Share Price (Median Multiples)
B27: Via EV/EBITDA (Median) | C27: =ROUND((C21*D16-C24)*1000000/C23,0) -> 1417
B28: Via PER (Median) | C28: =ROUND(C22*F16*1000000/C23,0) -> 3626

Sheet Sensitivity Analysis
B2: Sensitivity Analysis
B3: Current WACC: | C3: ='DCF Model'!C26 -> 0.12525 | E3: Terminal g: | F3: ='DCF Model'!C13 -> 0.015 | H3: Exit Multiple: | I3: ='DCF Model'!C14 -> 8
B5: Table 1: WACC vs Terminal Growth Rate (PGM - Implied Share Price, JPY)
B6: WACC \ Terminal g | C6: =$F$3-0.0075 -> 0.0075 | D6: =$F$3-0.005 -> 0.01 | E6: =$F$3-0.0025 -> 0.0125 | F6: =$F$3 -> 0.015 | G6: =$F$3+0.0025 -> 0.0175 | H6: =$F$3+0.005 -> 0.02 | I6: =$F$3+0.0075 -> 0.0225
B7: =$C$3-0.015 -> 0.11025 | C7: =IFERROR(ROUND(('DCF Model'!C45/(1+$B7)^('DCF Model'!C19+0)+'DCF Model'!D45/(1+$B7)^('DCF Model'!C19+1)+'DCF Model'!E45/(1+$B7)^('DCF Model'!C19+2)+'DCF Model'!F45/(1+$B7)^('DCF Model'!C19+3)+'DCF Model'!G45/(1+$B7)^('DCF Model'!C19+4)+'DCF Model'!G45*(1+C$6)/($B7-C$6)/(1+$B7)^('DCF Model'!C19+4)-'DCF Model'!C16)*1000000/'DCF Model'!C15,0),"") -> 354 | D7: =IFERROR(ROUND(('DCF Model'!C45/(1+$B7)^('DCF Model'!C19+0)+'DCF Model'!D45/(1+$B7)^('DCF Model'!C19+1)+'DCF Model'!E45/(1+$B7)^('DCF Model'!C19+2)+'DCF Model'!F45/(1+$B7)^('DCF Model'!C19+3)+'DCF Model'!G45/(1+$B7)^('DCF Model'!C19+4)+'DCF Model'!G45*(1+D$6)/($B7-D$6)/(1+$B7)^('DCF Model'!C19+4)-'DCF Model'!C16)*1000000/'DCF Model'!C15,0),"") -> 360 | E7: =IFERROR(ROUND(('DCF Model'!C45/(1+$B7)^('DCF Model'!C19+0)+'DCF Model'!D45/(1+$B7)^('DCF Model'!C19+1)+'DCF Model'!E45/(1+$B7)^('DCF Model'!C19+2)+'DCF Model'!F45/(1+$B7)^('DCF Model'!C19+3)+'DCF Model'!G45/(1+$B7)^('DCF Model'!C19+4)+'DCF Model'!G45*(1+E$6)/($B7-E$6)/(1+$B7)^('DCF Model'!C19+4)-'DCF Model'!C16)*1000000/'DCF Model'!C15,0),"") -> 365 | F7: =IFERROR(ROUND(('DCF Model'!C45/(1+$B7)^('DCF Model'!C19+0)+'DCF Model'!D45/(1+$B7)^('DCF Model'!C19+1)+'DCF Model'!E45/(1+$B7)^('DCF Model'!C19+2)+'DCF Model'!F45/(1+$B7)^('DCF Model'!C19+3)+'DCF Model'!G45/(1+$B7)^('DCF Model'!C19+4)+'DCF Model'!G45*(1+F$6)/($B7-F$6)/(1+$B7)^('DCF Model'!C19+4)-'DCF Model'!C16)*1000000/'DCF Model'!C15,0),"") -> 371 | G7: =IFERROR(ROUND(('DCF Model'!C45/(1+$B7)^('DCF Model'!C19+0)+'DCF Model'!D45/(1+$B7)^('DCF Model'!C19+1)+'DCF Model'!E45/(1+$B7)^('DCF Model'!C19+2)+'DCF Model'!F45/(1+$B7)^('DCF Model'!C19+3)+'DCF Model'!G45/(1+$B7)^('DCF Model'!C19+4)+'DCF Model'!G45*(1+G$6)/($B7-G$6)/(1+$B7)^('DCF Model'!C19+4)-'DCF Model'!C16)*1000000/'DCF Model'!C15,0),"") -> 377 | H7: =IFERROR(ROUND(('DCF Model'!C45/(1+$B7)^('DCF Model'!C19+0)+'DCF Model'!D45/(1+$B7)^('DCF Model'!C19+1)+'DCF Model'!E45/(1+$B7)^('DCF Model'!C19+2)+'DCF Model'!F45/(1+$B7)^('DCF Model'!C19+3)+'DCF Model'!G45/(1+$B7)^('DCF Model'!C19+4)+'DCF Model'!G45*(1+H$6)/($B7-H$6)/(1+$B7)^('DCF Model'!C19+4)-'DCF Model'!C16)*1000000/'DCF Model'!C15,0),"") -> 383 | I7: =IFERROR(ROUND(('DCF Model'!C45/(1+$B7)^('DCF Model'!C19+0)+'DCF Model'!D45/(1+$B7)^('DCF Model'!C19+1)+'DCF Model'!E45/(1+$B7)^('DCF Model'!C19+2)+'DCF Model'!F45/(1+$B7)^('DCF Model'!C19+3)+'DCF Model'!G45/(1+$B7)^('DCF Model'!C19+4)+'DCF Model'!G45*(1+I$6)/($B7-I$6)/(1+$B7)^('DCF Model'!C19+4)-'DCF Model'!C16)*1000000/'DCF Model'!C15,0),"") -> 390
B8: =$C$3-0.01 -> 0.11525 | C8: =IFERROR(ROUND(('DCF Model'!C45/(1+$B8)^('DCF Model'!C19+0)+'DCF Model'!D45/(1+$B8)^('DCF Model'!C19+1)+'DCF Model'!E45/(1+$B8)^('DCF Model'!C19+2)+'DCF Model'!F45/(1+$B8)^('DCF Model'!C19+3)+'DCF Model'!G45/(1+$B8)^('DCF Model'!C19+4)+'DCF Model'!G45*(1+C$6)/($B8-C$6)/(1+$B8)^('DCF Model'!C19+4)-'DCF Model'!C16)*1000000/'DCF Model'!C15,0),"") -> 340 | D8: =IFERROR(ROUND(('DCF Model'!C45/(1+$B8)^('DCF Model'!C19+0)+'DCF Model'!D45/(1+$B8)^('DCF Model'!C19+1)+'DCF Model'!E45/(1+$B8)^('DCF Model'!C19+2)+'DCF Model'!F45/(1+$B8)^('DCF Model'!C19+3)+'DCF Model'!G45/(1+$B8)^('DCF Model'!C19+4)+'DCF Model'!G45*(1+D$6)/($B8-D$6)/(1+$B8)^('DCF Model'!C19+4)-'DCF Model'!C16)*1000000/'DCF Model'!C15,0),"") -> 345 | E8: =IFERROR(ROUND(('DCF Model'!C45/(1+$B8)^('DCF Model'!C19+0)+'DCF Model'!D45/(1+$B8)^('DCF Model'!C19+1)+'DCF Model'!E45/(1+$B8)^('DCF Model'!C19+2)+'DCF Model'!F45/(1+$B8)^('DCF Model'!C19+3)+'DCF Model'!G45/(1+$B8)^('DCF Model'!C19+4)+'DCF Model'!G45*(1+E$6)/($B8-E$6)/(1+$B8)^('DCF Model'!C19+4)-'DCF Model'!C16)*1000000/'DCF Model'!C15,0),"") -> 350 | F8: =IFERROR(ROUND(('DCF Model'!C45/(1+$B8)^('DCF Model'!C19+0)+'DCF Model'!D45/(1+$B8)^('DCF Model'!C19+1)+'DCF Model'!E45/(1+$B8)^('DCF Model'!C19+2)+'DCF Model'!F45/(1+$B8)^('DCF Model'!C19+3)+'DCF Model'!G45/(1+$B8)^('DCF Model'!C19+4)+'DCF Model'!G45*(1+F$6)/($B8-F$6)/(1+$B8)^('DCF Model'!C19+4)-'DCF Model'!C16)*1000000/'DCF Model'!C15,0),"") -> 355 | G8: =IFERROR(ROUND(('DCF Model'!C45/(1+$B8)^('DCF Model'!C19+0)+'DCF Model'!D45/(1+$B8)^('DCF Model'!C19+1)+'DCF Model'!E45/(1+$B8)^('DCF Model'!C19+2)+'DCF Model'!F45/(1+$B8)^('DCF Model'!C19+3)+'DCF Model'!G45/(1+$B8)^('DCF Model'!C19+4)+'DCF Model'!G45*(1+G$6)/($B8-G$6)/(1+$B8)^('DCF Model'!C19+4)-'DCF Model'!C16)*1000000/'DCF Model'!C15,0),"") -> 360 | H8: =IFERROR(ROUND(('DCF Model'!C45/(1+$B8)^('DCF Model'!C19+0)+'DCF Model'!D45/(1+$B8)^('DCF Model'!C19+1)+'DCF Model'!E45/(1+$B8)^('DCF Model'!C19+2)+'DCF Model'!F45/(1+$B8)^('DCF Model'!C19+3)+'DCF Model'!G45/(1+$B8)^('DCF Model'!C19+4)+'DCF Model'!G45*(1+H$6)/($B8-H$6)/(1+$B8)^('DCF Model'!C19+4)-'DCF Model'!C16)*1000000/'DCF Model'!C15,0),"") -> 366 | I8: =IFERROR(ROUND(('DCF Model'!C45/(1+$B8)^('DCF Model'!C19+0)+'DCF Model'!D45/(1+$B8)^('DCF Model'!C19+1)+'DCF Model'!E45/(1+$B8)^('DCF Model'!C19+2)+'DCF Model'!F45/(1+$B8)^('DCF Model'!C19+3)+'DCF Model'!G45/(1+$B8)^('DCF Model'!C19+4)+'DCF Model'!G45*(1+I$6)/($B8-I$6)/(1+$B8)^('DCF Model'!C19+4)-'DCF Model'!C16)*1000000/'DCF Model'!C15,0),"") -> 372
B9: =$C$3-0.005 -> 0.12025 | C9: =IFERROR(ROUND(('DCF Model'!C45/(1+$B9)^('DCF Model'!C19+0)+'DCF Model'!D45/(1+$B9)^('DCF Model'!C19+1)+'DCF Model'!E45/(1+$B9)^('DCF Model'!C19+2)+'DCF Model'!F45/(1+$B9)^('DCF Model'!C19+3)+'DCF Model'!G45/(1+$B9)^('DCF Model'!C19+4)+'DCF Model'!G45*(1+C$6)/($B9-C$6)/(1+$B9)^('DCF Model'!C19+4)-'DCF Model'!C16)*1000000/'DCF Model'!C15,0),"") -> 327 | D9: =IFERROR(ROUND(('DCF Model'!C45/(1+$B9)^('DCF Model'!C19+0)+'DCF Model'!D45/(1+$B9)^('DCF Model'!C19+1)+'DCF Model'!E45/(1+$B9)^('DCF Model'!C19+2)+'DCF Model'!F45/(1+$B9)^('DCF Model'!C19+3)+'DCF Model'!G45/(1+$B9)^('DCF Model'!C19+4)+'DCF Model'!G45*(1+D$6)/($B9-D$6)/(1+$B9)^('DCF Model'!C19+4)-'DCF Model'!C16)*1000000/'DCF Model'!C15,0),"") -> 331 | E9: =IFERROR(ROUND(('DCF Model'!C45/(1+$B9)^('DCF Model'!C19+0)+'DCF Model'!D45/(1+$B9)^('DCF Model'!C19+1)+'DCF Model'!E45/(1+$B9)^('DCF Model'!C19+2)+'DCF Model'!F45/(1+$B9)^('DCF Model'!C19+3)+'DCF Model'!G45/(1+$B9)^('DCF Model'!C19+4)+'DCF Model'!G45*(1+E$6)/($B9-E$6)/(1+$B9)^('DCF Model'!C19+4)-'DCF Model'!C16)*1000000/'DCF Model'!C15,0),"") -> 336 | F9: =IFERROR(ROUND(('DCF Model'!C45/(1+$B9)^('DCF Model'!C19+0)+'DCF Model'!D45/(1+$B9)^('DCF Model'!C19+1)+'DCF Model'!E45/(1+$B9)^('DCF Model'!C19+2)+'DCF Model'!F45/(1+$B9)^('DCF Model'!C19+3)+'DCF Model'!G45/(1+$B9)^('DCF Model'!C19+4)+'DCF Model'!G45*(1+F$6)/($B9-F$6)/(1+$B9)^('DCF Model'!C19+4)-'DCF Model'!C16)*1000000/'DCF Model'!C15,0),"") -> 340 | G9: =IFERROR(ROUND(('DCF Model'!C45/(1+$B9)^('DCF Model'!C19+0)+'DCF Model'!D45/(1+$B9)^('DCF Model'!C19+1)+'DCF Model'!E45/(1+$B9)^('DCF Model'!C19+2)+'DCF Model'!F45/(1+$B9)^('DCF Model'!C19+3)+'DCF Model'!G45/(1+$B9)^('DCF Model'!C19+4)+'DCF Model'!G45*(1+G$6)/($B9-G$6)/(1+$B9)^('DCF Model'!C19+4)-'DCF Model'!C16)*1000000/'DCF Model'!C15,0),"") -> 345 | H9: =IFERROR(ROUND(('DCF Model'!C45/(1+$B9)^('DCF Model'!C19+0)+'DCF Model'!D45/(1+$B9)^('DCF Model'!C19+1)+'DCF Model'!E45/(1+$B9)^('DCF Model'!C19+2)+'DCF Model'!F45/(1+$B9)^('DCF Model'!C19+3)+'DCF Model'!G45/(1+$B9)^('DCF Model'!C19+4)+'DCF Model'!G45*(1+H$6)/($B9-H$6)/(1+$B9)^('DCF Model'!C19+4)-'DCF Model'!C16)*1000000/'DCF Model'!C15,0),"") -> 350 | I9: =IFERROR(ROUND(('DCF Model'!C45/(1+$B9)^('DCF Model'!C19+0)+'DCF Model'!D45/(1+$B9)^('DCF Model'!C19+1)+'DCF Model'!E45/(1+$B9)^('DCF Model'!C19+2)+'DCF Model'!F45/(1+$B9)^('DCF Model'!C19+3)+'DCF Model'!G45/(1+$B9)^('DCF Model'!C19+4)+'DCF Model'!G45*(1+I$6)/($B9-I$6)/(1+$B9)^('DCF Model'!C19+4)-'DCF Model'!C16)*1000000/'DCF Model'!C15,0),"") -> 355
B10: =$C$3 -> 0.12525 | C10: =IFERROR(ROUND(('DCF Model'!C45/(1+$B10)^('DCF Model'!C19+0)+'DCF Model'!D45/(1+$B10)^('DCF Model'!C19+1)+'DCF Model'!E45/(1+$B10)^('DCF Model'!C19+2)+'DCF Model'!F45/(1+$B10)^('DCF Model'!C19+3)+'DCF Model'!G45/(1+$B10)^('DCF Model'!C19+4)+'DCF Model'!G45*(1+C$6)/($B10-C$6)/(1+$B10)^('DCF Model'!C19+4)-'DCF Model'!C16)*1000000/'DCF Model'!C15,0),"") -> 315 | D10: =IFERROR(ROUND(('DCF Model'!C45/(1+$B10)^('DCF Model'!C19+0)+'DCF Model'!D45/(1+$B10)^('DCF Model'!C19+1)+'DCF Model'!E45/(1+$B10)^('DCF Model'!C19+2)+'DCF Model'!F45/(1+$B10)^('DCF Model'!C19+3)+'DCF Model'!G45/(1+$B10)^('DCF Model'!C19+4)+'DCF Model'!G45*(1+D$6)/($B10-D$6)/(1+$B10)^('DCF Model'!C19+4)-'DCF Model'!C16)*1000000/'DCF Model'!C15,0),"") -> 319 | E10: =IFERROR(ROUND(('DCF Model'!C45/(1+$B10)^('DCF Model'!C19+0)+'DCF Model'!D45/(1+$B10)^('DCF Model'!C19+1)+'DCF Model'!E45/(1+$B10)^('DCF Model'!C19+2)+'DCF Model'!F45/(1+$B10)^('DCF Model'!C19+3)+'DCF Model'!G45/(1+$B10)^('DCF Model'!C19+4)+'DCF Model'!G45*(1+E$6)/($B10-E$6)/(1+$B10)^('DCF Model'!C19+4)-'DCF Model'!C16)*1000000/'DCF Model'!C15,0),"") -> 323 | F10: =IFERROR(ROUND(('DCF Model'!C45/(1+$B10)^('DCF Model'!C19+0)+'DCF Model'!D45/(1+$B10)^('DCF Model'!C19+1)+'DCF Model'!E45/(1+$B10)^('DCF Model'!C19+2)+'DCF Model'!F45/(1+$B10)^('DCF Model'!C19+3)+'DCF Model'!G45/(1+$B10)^('DCF Model'!C19+4)+'DCF Model'!G45*(1+F$6)/($B10-F$6)/(1+$B10)^('DCF Model'!C19+4)-'DCF Model'!C16)*1000000/'DCF Model'!C15,0),"") -> 327 | G10: =IFERROR(ROUND(('DCF Model'!C45/(1+$B10)^('DCF Model'!C19+0)+'DCF Model'!D45/(1+$B10)^('DCF Model'!C19+1)+'DCF Model'!E45/(1+$B10)^('DCF Model'!C19+2)+'DCF Model'!F45/(1+$B10)^('DCF Model'!C19+3)+'DCF Model'!G45/(1+$B10)^('DCF Model'!C19+4)+'DCF Model'!G45*(1+G$6)/($B10-G$6)/(1+$B10)^('DCF Model'!C19+4)-'DCF Model'!C16)*1000000/'DCF Model'!C15,0),"") -> 331 | H10: =IFERROR(ROUND(('DCF Model'!C45/(1+$B10)^('DCF Model'!C19+0)+'DCF Model'!D45/(1+$B10)^('DCF Model'!C19+1)+'DCF Model'!E45/(1+$B10)^('DCF Model'!C19+2)+'DCF Model'!F45/(1+$B10)^('DCF Model'!C19+3)+'DCF Model'!G45/(1+$B10)^('DCF Model'!C19+4)+'DCF Model'!G45*(1+H$6)/($B10-H$6)/(1+$B10)^('DCF Model'!C19+4)-'DCF Model'!C16)*1000000/'DCF Model'!C15,0),"") -> 336 | I10: =IFERROR(ROUND(('DCF Model'!C45/(1+$B10)^('DCF Model'!C19+0)+'DCF Model'!D45/(1+$B10)^('DCF Model'!C19+1)+'DCF Model'!E45/(1+$B10)^('DCF Model'!C19+2)+'DCF Model'!F45/(1+$B10)^('DCF Model'!C19+3)+'DCF Model'!G45/(1+$B10)^('DCF Model'!C19+4)+'DCF Model'!G45*(1+I$6)/($B10-I$6)/(1+$B10)^('DCF Model'!C19+4)-'DCF Model'!C16)*1000000/'DCF Model'!C15,0),"") -> 341
B11: =$C$3+0.005 -> 0.13025 | C11: =IFERROR(ROUND(('DCF Model'!C45/(1+$B11)^('DCF Model'!C19+0)+'DCF Model'!D45/(1+$B11)^('DCF Model'!C19+1)+'DCF Model'!E45/(1+$B11)^('DCF Model'!C19+2)+'DCF Model'!F45/(1+$B11)^('DCF Model'!C19+3)+'DCF Model'!G45/(1+$B11)^('DCF Model'!C19+4)+'DCF Model'!G45*(1+C$6)/($B11-C$6)/(1+$B11)^('DCF Model'!C19+4)-'DCF Model'!C16)*1000000/'DCF Model'!C15,0),"") -> 304 | D11: =IFERROR(ROUND(('DCF Model'!C45/(1+$B11)^('DCF Model'!C19+0)+'DCF Model'!D45/(1+$B11)^('DCF Model'!C19+1)+'DCF Model'!E45/(1+$B11)^('DCF Model'!C19+2)+'DCF Model'!F45/(1+$B11)^('DCF Model'!C19+3)+'DCF Model'!G45/(1+$B11)^('DCF Model'!C19+4)+'DCF Model'!G45*(1+D$6)/($B11-D$6)/(1+$B11)^('DCF Model'!C19+4)-'DCF Model'!C16)*1000000/'DCF Model'!C15,0),"") -> 308 | E11: =IFERROR(ROUND(('DCF Model'!C45/(1+$B11)^('DCF Model'!C19+0)+'DCF Model'!D45/(1+$B11)^('DCF Model'!C19+1)+'DCF Model'!E45/(1+$B11)^('DCF Model'!C19+2)+'DCF Model'!F45/(1+$B11)^('DCF Model'!C19+3)+'DCF Model'!G45/(1+$B11)^('DCF Model'!C19+4)+'DCF Model'!G45*(1+E$6)/($B11-E$6)/(1+$B11)^('DCF Model'!C19+4)-'DCF Model'!C16)*1000000/'DCF Model'!C15,0),"") -> 311 | F11: =IFERROR(ROUND(('DCF Model'!C45/(1+$B11)^('DCF Model'!C19+0)+'DCF Model'!D45/(1+$B11)^('DCF Model'!C19+1)+'DCF Model'!E45/(1+$B11)^('DCF Model'!C19+2)+'DCF Model'!F45/(1+$B11)^('DCF Model'!C19+3)+'DCF Model'!G45/(1+$B11)^('DCF Model'!C19+4)+'DCF Model'!G45*(1+F$6)/($B11-F$6)/(1+$B11)^('DCF Model'!C19+4)-'DCF Model'!C16)*1000000/'DCF Model'!C15,0),"") -> 315 | G11: =IFERROR(ROUND(('DCF Model'!C45/(1+$B11)^('DCF Model'!C19+0)+'DCF Model'!D45/(1+$B11)^('DCF Model'!C19+1)+'DCF Model'!E45/(1+$B11)^('DCF Model'!C19+2)+'DCF Model'!F45/(1+$B11)^('DCF Model'!C19+3)+'DCF Model'!G45/(1+$B11)^('DCF Model'!C19+4)+'DCF Model'!G45*(1+G$6)/($B11-G$6)/(1+$B11)^('DCF Model'!C19+4)-'DCF Model'!C16)*1000000/'DCF Model'!C15,0),"") -> 319 | H11: =IFERROR(ROUND(('DCF Model'!C45/(1+$B11)^('DCF Model'!C19+0)+'DCF Model'!D45/(1+$B11)^('DCF Model'!C19+1)+'DCF Model'!E45/(1+$B11)^('DCF Model'!C19+2)+'DCF Model'!F45/(1+$B11)^('DCF Model'!C19+3)+'DCF Model'!G45/(1+$B11)^('DCF Model'!C19+4)+'DCF Model'!G45*(1+H$6)/($B11-H$6)/(1+$B11)^('DCF Model'!C19+4)-'DCF Model'!C16)*1000000/'DCF Model'!C15,0),"") -> 323 | I11: =IFERROR(ROUND(('DCF Model'!C45/(1+$B11)^('DCF Model'!C19+0)+'DCF Model'!D45/(1+$B11)^('DCF Model'!C19+1)+'DCF Model'!E45/(1+$B11)^('DCF Model'!C19+2)+'DCF Model'!F45/(1+$B11)^('DCF Model'!C19+3)+'DCF Model'!G45/(1+$B11)^('DCF Model'!C19+4)+'DCF Model'!G45*(1+I$6)/($B11-I$6)/(1+$B11)^('DCF Model'!C19+4)-'DCF Model'!C16)*1000000/'DCF Model'!C15,0),"") -> 327
B12: =$C$3+0.01 -> 0.13525 | C12: =IFERROR(ROUND(('DCF Model'!C45/(1+$B12)^('DCF Model'!C19+0)+'DCF Model'!D45/(1+$B12)^('DCF Model'!C19+1)+'DCF Model'!E45/(1+$B12)^('DCF Model'!C19+2)+'DCF Model'!F45/(1+$B12)^('DCF Model'!C19+3)+'DCF Model'!G45/(1+$B12)^('DCF Model'!C19+4)+'DCF Model'!G45*(1+C$6)/($B12-C$6)/(1+$B12)^('DCF Model'!C19+4)-'DCF Model'!C16)*1000000/'DCF Model'!C15,0),"") -> 294 | D12: =IFERROR(ROUND(('DCF Model'!C45/(1+$B12)^('DCF Model'!C19+0)+'DCF Model'!D45/(1+$B12)^('DCF Model'!C19+1)+'DCF Model'!E45/(1+$B12)^('DCF Model'!C19+2)+'DCF Model'!F45/(1+$B12)^('DCF Model'!C19+3)+'DCF Model'!G45/(1+$B12)^('DCF Model'!C19+4)+'DCF Model'!G45*(1+D$6)/($B12-D$6)/(1+$B12)^('DCF Model'!C19+4)-'DCF Model'!C16)*1000000/'DCF Model'!C15,0),"") -> 297 | E12: =IFERROR(ROUND(('DCF Model'!C45/(1+$B12)^('DCF Model'!C19+0)+'DCF Model'!D45/(1+$B12)^('DCF Model'!C19+1)+'DCF Model'!E45/(1+$B12)^('DCF Model'!C19+2)+'DCF Model'!F45/(1+$B12)^('DCF Model'!C19+3)+'DCF Model'!G45/(1+$B12)^('DCF Model'!C19+4)+'DCF Model'!G45*(1+E$6)/($B12-E$6)/(1+$B12)^('DCF Model'!C19+4)-'DCF Model'!C16)*1000000/'DCF Model'!C15,0),"") -> 300 | F12: =IFERROR(ROUND(('DCF Model'!C45/(1+$B12)^('DCF Model'!C19+0)+'DCF Model'!D45/(1+$B12)^('DCF Model'!C19+1)+'DCF Model'!E45/(1+$B12)^('DCF Model'!C19+2)+'DCF Model'!F45/(1+$B12)^('DCF Model'!C19+3)+'DCF Model'!G45/(1+$B12)^('DCF Model'!C19+4)+'DCF Model'!G45*(1+F$6)/($B12-F$6)/(1+$B12)^('DCF Model'!C19+4)-'DCF Model'!C16)*1000000/'DCF Model'!C15,0),"") -> 304 | G12: =IFERROR(ROUND(('DCF Model'!C45/(1+$B12)^('DCF Model'!C19+0)+'DCF Model'!D45/(1+$B12)^('DCF Model'!C19+1)+'DCF Model'!E45/(1+$B12)^('DCF Model'!C19+2)+'DCF Model'!F45/(1+$B12)^('DCF Model'!C19+3)+'DCF Model'!G45/(1+$B12)^('DCF Model'!C19+4)+'DCF Model'!G45*(1+G$6)/($B12-G$6)/(1+$B12)^('DCF Model'!C19+4)-'DCF Model'!C16)*1000000/'DCF Model'!C15,0),"") -> 307 | H12: =IFERROR(ROUND(('DCF Model'!C45/(1+$B12)^('DCF Model'!C19+0)+'DCF Model'!D45/(1+$B12)^('DCF Model'!C19+1)+'DCF Model'!E45/(1+$B12)^('DCF Model'!C19+2)+'DCF Model'!F45/(1+$B12)^('DCF Model'!C19+3)+'DCF Model'!G45/(1+$B12)^('DCF Model'!C19+4)+'DCF Model'!G45*(1+H$6)/($B12-H$6)/(1+$B12)^('DCF Model'!C19+4)-'DCF Model'!C16)*1000000/'DCF Model'!C15,0),"") -> 311 | I12: =IFERROR(ROUND(('DCF Model'!C45/(1+$B12)^('DCF Model'!C19+0)+'DCF Model'!D45/(1+$B12)^('DCF Model'!C19+1)+'DCF Model'!E45/(1+$B12)^('DCF Model'!C19+2)+'DCF Model'!F45/(1+$B12)^('DCF Model'!C19+3)+'DCF Model'!G45/(1+$B12)^('DCF Model'!C19+4)+'DCF Model'!G45*(1+I$6)/($B12-I$6)/(1+$B12)^('DCF Model'!C19+4)-'DCF Model'!C16)*1000000/'DCF Model'!C15,0),"") -> 315
B13: =$C$3+0.015 -> 0.14025 | C13: =IFERROR(ROUND(('DCF Model'!C45/(1+$B13)^('DCF Model'!C19+0)+'DCF Model'!D45/(1+$B13)^('DCF Model'!C19+1)+'DCF Model'!E45/(1+$B13)^('DCF Model'!C19+2)+'DCF Model'!F45/(1+$B13)^('DCF Model'!C19+3)+'DCF Model'!G45/(1+$B13)^('DCF Model'!C19+4)+'DCF Model'!G45*(1+C$6)/($B13-C$6)/(1+$B13)^('DCF Model'!C19+4)-'DCF Model'!C16)*1000000/'DCF Model'!C15,0),"") -> 285 | D13: =IFERROR(ROUND(('DCF Model'!C45/(1+$B13)^('DCF Model'!C19+0)+'DCF Model'!D45/(1+$B13)^('DCF Model'!C19+1)+'DCF Model'!E45/(1+$B13)^('DCF Model'!C19+2)+'DCF Model'!F45/(1+$B13)^('DCF Model'!C19+3)+'DCF Model'!G45/(1+$B13)^('DCF Model'!C19+4)+'DCF Model'!G45*(1+D$6)/($B13-D$6)/(1+$B13)^('DCF Model'!C19+4)-'DCF Model'!C16)*1000000/'DCF Model'!C15,0),"") -> 288 | E13: =IFERROR(ROUND(('DCF Model'!C45/(1+$B13)^('DCF Model'!C19+0)+'DCF Model'!D45/(1+$B13)^('DCF Model'!C19+1)+'DCF Model'!E45/(1+$B13)^('DCF Model'!C19+2)+'DCF Model'!F45/(1+$B13)^('DCF Model'!C19+3)+'DCF Model'!G45/(1+$B13)^('DCF Model'!C19+4)+'DCF Model'!G45*(1+E$6)/($B13-E$6)/(1+$B13)^('DCF Model'!C19+4)-'DCF Model'!C16)*1000000/'DCF Model'!C15,0),"") -> 291 | F13: =IFERROR(ROUND(('DCF Model'!C45/(1+$B13)^('DCF Model'!C19+0)+'DCF Model'!D45/(1+$B13)^('DCF Model'!C19+1)+'DCF Model'!E45/(1+$B13)^('DCF Model'!C19+2)+'DCF Model'!F45/(1+$B13)^('DCF Model'!C19+3)+'DCF Model'!G45/(1+$B13)^('DCF Model'!C19+4)+'DCF Model'!G45*(1+F$6)/($B13-F$6)/(1+$B13)^('DCF Model'!C19+4)-'DCF Model'!C16)*1000000/'DCF Model'!C15,0),"") -> 294 | G13: =IFERROR(ROUND(('DCF Model'!C45/(1+$B13)^('DCF Model'!C19+0)+'DCF Model'!D45/(1+$B13)^('DCF Model'!C19+1)+'DCF Model'!E45/(1+$B13)^('DCF Model'!C19+2)+'DCF Model'!F45/(1+$B13)^('DCF Model'!C19+3)+'DCF Model'!G45/(1+$B13)^('DCF Model'!C19+4)+'DCF Model'!G45*(1+G$6)/($B13-G$6)/(1+$B13)^('DCF Model'!C19+4)-'DCF Model'!C16)*1000000/'DCF Model'!C15,0),"") -> 297 | H13: =IFERROR(ROUND(('DCF Model'!C45/(1+$B13)^('DCF Model'!C19+0)+'DCF Model'!D45/(1+$B13)^('DCF Model'!C19+1)+'DCF Model'!E45/(1+$B13)^('DCF Model'!C19+2)+'DCF Model'!F45/(1+$B13)^('DCF Model'!C19+3)+'DCF Model'!G45/(1+$B13)^('DCF Model'!C19+4)+'DCF Model'!G45*(1+H$6)/($B13-H$6)/(1+$B13)^('DCF Model'!C19+4)-'DCF Model'!C16)*1000000/'DCF Model'!C15,0),"") -> 300 | I13: =IFERROR(ROUND(('DCF Model'!C45/(1+$B13)^('DCF Model'!C19+0)+'DCF Model'!D45/(1+$B13)^('DCF Model'!C19+1)+'DCF Model'!E45/(1+$B13)^('DCF Model'!C19+2)+'DCF Model'!F45/(1+$B13)^('DCF Model'!C19+3)+'DCF Model'!G45/(1+$B13)^('DCF Model'!C19+4)+'DCF Model'!G45*(1+I$6)/($B13-I$6)/(1+$B13)^('DCF Model'!C19+4)-'DCF Model'!C16)*1000000/'DCF Model'!C15,0),"") -> 304
B16: Table 2: WACC vs Exit Multiple (Exit Multiple - Implied Share Price, JPY)
B17: WACC \ Exit Multiple | C17: =$I$3-3 -> 5 | D17: =$I$3-2 -> 6 | E17: =$I$3-1 -> 7 | F17: =$I$3 -> 8 | G17: =$I$3+1 -> 9 | H17: =$I$3+2 -> 10 | I17: =$I$3+3 -> 11
B18: =$C$3-0.015 -> 0.11025 | C18: =IFERROR(ROUND(('DCF Model'!C45/(1+$B18)^('DCF Model'!C19+0)+'DCF Model'!D45/(1+$B18)^('DCF Model'!C19+1)+'DCF Model'!E45/(1+$B18)^('DCF Model'!C19+2)+'DCF Model'!F45/(1+$B18)^('DCF Model'!C19+3)+'DCF Model'!G45/(1+$B18)^('DCF Model'!C19+4)+('DCF Model'!G39+'DCF Model'!G42)*C$17/(1+$B18)^('DCF Model'!C19+4)-'DCF Model'!C16)*1000000/'DCF Model'!C15,0),"") -> 400 | D18: =IFERROR(ROUND(('DCF Model'!C45/(1+$B18)^('DCF Model'!C19+0)+'DCF Model'!D45/(1+$B18)^('DCF Model'!C19+1)+'DCF Model'!E45/(1+$B18)^('DCF Model'!C19+2)+'DCF Model'!F45/(1+$B18)^('DCF Model'!C19+3)+'DCF Model'!G45/(1+$B18)^('DCF Model'!C19+4)+('DCF Model'!G39+'DCF Model'!G42)*D$17/(1+$B18)^('DCF Model'!C19+4)-'DCF Model'!C16)*1000000/'DCF Model'!C15,0),"") -> 447 | E18: =IFERROR(ROUND(('DCF Model'!C45/(1+$B18)^('DCF Model'!C19+0)+'DCF Model'!D45/(1+$B18)^('DCF Model'!C19+1)+'DCF Model'!E45/(1+$B18)^('DCF Model'!C19+2)+'DCF Model'!F45/(1+$B18)^('DCF Model'!C19+3)+'DCF Model'!G45/(1+$B18)^('DCF Model'!C19+4)+('DCF Model'!G39+'DCF Model'!G42)*E$17/(1+$B18)^('DCF Model'!C19+4)-'DCF Model'!C16)*1000000/'DCF Model'!C15,0),"") -> 494 | F18: =IFERROR(ROUND(('DCF Model'!C45/(1+$B18)^('DCF Model'!C19+0)+'DCF Model'!D45/(1+$B18)^('DCF Model'!C19+1)+'DCF Model'!E45/(1+$B18)^('DCF Model'!C19+2)+'DCF Model'!F45/(1+$B18)^('DCF Model'!C19+3)+'DCF Model'!G45/(1+$B18)^('DCF Model'!C19+4)+('DCF Model'!G39+'DCF Model'!G42)*F$17/(1+$B18)^('DCF Model'!C19+4)-'DCF Model'!C16)*1000000/'DCF Model'!C15,0),"") -> 541 | G18: =IFERROR(ROUND(('DCF Model'!C45/(1+$B18)^('DCF Model'!C19+0)+'DCF Model'!D45/(1+$B18)^('DCF Model'!C19+1)+'DCF Model'!E45/(1+$B18)^('DCF Model'!C19+2)+'DCF Model'!F45/(1+$B18)^('DCF Model'!C19+3)+'DCF Model'!G45/(1+$B18)^('DCF Model'!C19+4)+('DCF Model'!G39+'DCF Model'!G42)*G$17/(1+$B18)^('DCF Model'!C19+4)-'DCF Model'!C16)*1000000/'DCF Model'!C15,0),"") -> 589 | H18: =IFERROR(ROUND(('DCF Model'!C45/(1+$B18)^('DCF Model'!C19+0)+'DCF Model'!D45/(1+$B18)^('DCF Model'!C19+1)+'DCF Model'!E45/(1+$B18)^('DCF Model'!C19+2)+'DCF Model'!F45/(1+$B18)^('DCF Model'!C19+3)+'DCF Model'!G45/(1+$B18)^('DCF Model'!C19+4)+('DCF Model'!G39+'DCF Model'!G42)*H$17/(1+$B18)^('DCF Model'!C19+4)-'DCF Model'!C16)*1000000/'DCF Model'!C15,0),"") -> 636 | I18: =IFERROR(ROUND(('DCF Model'!C45/(1+$B18)^('DCF Model'!C19+0)+'DCF Model'!D45/(1+$B18)^('DCF Model'!C19+1)+'DCF Model'!E45/(1+$B18)^('DCF Model'!C19+2)+'DCF Model'!F45/(1+$B18)^('DCF Model'!C19+3)+'DCF Model'!G45/(1+$B18)^('DCF Model'!C19+4)+('DCF Model'!G39+'DCF Model'!G42)*I$17/(1+$B18)^('DCF Model'!C19+4)-'DCF Model'!C16)*1000000/'DCF Model'!C15,0),"") -> 683
B19: =$C$3-0.01 -> 0.11525 | C19: =IFERROR(ROUND(('DCF Model'!C45/(1+$B19)^('DCF Model'!C19+0)+'DCF Model'!D45/(1+$B19)^('DCF Model'!C19+1)+'DCF Model'!E45/(1+$B19)^('DCF Model'!C19+2)+'DCF Model'!F45/(1+$B19)^('DCF Model'!C19+3)+'DCF Model'!G45/(1+$B19)^('DCF Model'!C19+4)+('DCF Model'!G39+'DCF Model'!G42)*C$17/(1+$B19)^('DCF Model'!C19+4)-'DCF Model'!C16)*1000000/'DCF Model'!C15,0),"") -> 393 | D19: =IFERROR(ROUND(('DCF Model'!C45/(1+$B19)^('DCF Model'!C19+0)+'DCF Model'!D45/(1+$B19)^('DCF Model'!C19+1)+'DCF Model'!E45/(1+$B19)^('DCF Model'!C19+2)+'DCF Model'!F45/(1+$B19)^('DCF Model'!C19+3)+'DCF Model'!G45/(1+$B19)^('DCF Model'!C19+4)+('DCF Model'!G39+'DCF Model'!G42)*D$17/(1+$B19)^('DCF Model'!C19+4)-'DCF Model'!C16)*1000000/'DCF Model'!C15,0),"") -> 439 | E19: =IFERROR(ROUND(('DCF Model'!C45/(1+$B19)^('DCF Model'!C19+0)+'DCF Model'!D45/(1+$B19)^('DCF Model'!C19+1)+'DCF Model'!E45/(1+$B19)^('DCF Model'!C19+2)+'DCF Model'!F45/(1+$B19)^('DCF Model'!C19+3)+'DCF Model'!G45/(1+$B19)^('DCF Model'!C19+4)+('DCF Model'!G39+'DCF Model'!G42)*E$17/(1+$B19)^('DCF Model'!C19+4)-'DCF Model'!C16)*1000000/'DCF Model'!C15,0),"") -> 485 | F19: =IFERROR(ROUND(('DCF Model'!C45/(1+$B19)^('DCF Model'!C19+0)+'DCF Model'!D45/(1+$B19)^('DCF Model'!C19+1)+'DCF Model'!E45/(1+$B19)^('DCF Model'!C19+2)+'DCF Model'!F45/(1+$B19)^('DCF Model'!C19+3)+'DCF Model'!G45/(1+$B19)^('DCF Model'!C19+4)+('DCF Model'!G39+'DCF Model'!G42)*F$17/(1+$B19)^('DCF Model'!C19+4)-'DCF Model'!C16)*1000000/'DCF Model'!C15,0),"") -> 532 | G19: =IFERROR(ROUND(('DCF Model'!C45/(1+$B19)^('DCF Model'!C19+0)+'DCF Model'!D45/(1+$B19)^('DCF Model'!C19+1)+'DCF Model'!E45/(1+$B19)^('DCF Model'!C19+2)+'DCF Model'!F45/(1+$B19)^('DCF Model'!C19+3)+'DCF Model'!G45/(1+$B19)^('DCF Model'!C19+4)+('DCF Model'!G39+'DCF Model'!G42)*G$17/(1+$B19)^('DCF Model'!C19+4)-'DCF Model'!C16)*1000000/'DCF Model'!C15,0),"") -> 578 | H19: =IFERROR(ROUND(('DCF Model'!C45/(1+$B19)^('DCF Model'!C19+0)+'DCF Model'!D45/(1+$B19)^('DCF Model'!C19+1)+'DCF Model'!E45/(1+$B19)^('DCF Model'!C19+2)+'DCF Model'!F45/(1+$B19)^('DCF Model'!C19+3)+'DCF Model'!G45/(1+$B19)^('DCF Model'!C19+4)+('DCF Model'!G39+'DCF Model'!G42)*H$17/(1+$B19)^('DCF Model'!C19+4)-'DCF Model'!C16)*1000000/'DCF Model'!C15,0),"") -> 624 | I19: =IFERROR(ROUND(('DCF Model'!C45/(1+$B19)^('DCF Model'!C19+0)+'DCF Model'!D45/(1+$B19)^('DCF Model'!C19+1)+'DCF Model'!E45/(1+$B19)^('DCF Model'!C19+2)+'DCF Model'!F45/(1+$B19)^('DCF Model'!C19+3)+'DCF Model'!G45/(1+$B19)^('DCF Model'!C19+4)+('DCF Model'!G39+'DCF Model'!G42)*I$17/(1+$B19)^('DCF Model'!C19+4)-'DCF Model'!C16)*1000000/'DCF Model'!C15,0),"") -> 670
B20: =$C$3-0.005 -> 0.12025 | C20: =IFERROR(ROUND(('DCF Model'!C45/(1+$B20)^('DCF Model'!C19+0)+'DCF Model'!D45/(1+$B20)^('DCF Model'!C19+1)+'DCF Model'!E45/(1+$B20)^('DCF Model'!C19+2)+'DCF Model'!F45/(1+$B20)^('DCF Model'!C19+3)+'DCF Model'!G45/(1+$B20)^('DCF Model'!C19+4)+('DCF Model'!G39+'DCF Model'!G42)*C$17/(1+$B20)^('DCF Model'!C19+4)-'DCF Model'!C16)*1000000/'DCF Model'!C15,0),"") -> 387 | D20: =IFERROR(ROUND(('DCF Model'!C45/(1+$B20)^('DCF Model'!C19+0)+'DCF Model'!D45/(1+$B20)^('DCF Model'!C19+1)+'DCF Model'!E45/(1+$B20)^('DCF Model'!C19+2)+'DCF Model'!F45/(1+$B20)^('DCF Model'!C19+3)+'DCF Model'!G45/(1+$B20)^('DCF Model'!C19+4)+('DCF Model'!G39+'DCF Model'!G42)*D$17/(1+$B20)^('DCF Model'!C19+4)-'DCF Model'!C16)*1000000/'DCF Model'!C15,0),"") -> 432 | E20: =IFERROR(ROUND(('DCF Model'!C45/(1+$B20)^('DCF Model'!C19+0)+'DCF Model'!D45/(1+$B20)^('DCF Model'!C19+1)+'DCF Model'!E45/(1+$B20)^('DCF Model'!C19+2)+'DCF Model'!F45/(1+$B20)^('DCF Model'!C19+3)+'DCF Model'!G45/(1+$B20)^('DCF Model'!C19+4)+('DCF Model'!G39+'DCF Model'!G42)*E$17/(1+$B20)^('DCF Model'!C19+4)-'DCF Model'!C16)*1000000/'DCF Model'!C15,0),"") -> 477 | F20: =IFERROR(ROUND(('DCF Model'!C45/(1+$B20)^('DCF Model'!C19+0)+'DCF Model'!D45/(1+$B20)^('DCF Model'!C19+1)+'DCF Model'!E45/(1+$B20)^('DCF Model'!C19+2)+'DCF Model'!F45/(1+$B20)^('DCF Model'!C19+3)+'DCF Model'!G45/(1+$B20)^('DCF Model'!C19+4)+('DCF Model'!G39+'DCF Model'!G42)*F$17/(1+$B20)^('DCF Model'!C19+4)-'DCF Model'!C16)*1000000/'DCF Model'!C15,0),"") -> 522 | G20: =IFERROR(ROUND(('DCF Model'!C45/(1+$B20)^('DCF Model'!C19+0)+'DCF Model'!D45/(1+$B20)^('DCF Model'!C19+1)+'DCF Model'!E45/(1+$B20)^('DCF Model'!C19+2)+'DCF Model'!F45/(1+$B20)^('DCF Model'!C19+3)+'DCF Model'!G45/(1+$B20)^('DCF Model'!C19+4)+('DCF Model'!G39+'DCF Model'!G42)*G$17/(1+$B20)^('DCF Model'!C19+4)-'DCF Model'!C16)*1000000/'DCF Model'!C15,0),"") -> 567 | H20: =IFERROR(ROUND(('DCF Model'!C45/(1+$B20)^('DCF Model'!C19+0)+'DCF Model'!D45/(1+$B20)^('DCF Model'!C19+1)+'DCF Model'!E45/(1+$B20)^('DCF Model'!C19+2)+'DCF Model'!F45/(1+$B20)^('DCF Model'!C19+3)+'DCF Model'!G45/(1+$B20)^('DCF Model'!C19+4)+('DCF Model'!G39+'DCF Model'!G42)*H$17/(1+$B20)^('DCF Model'!C19+4)-'DCF Model'!C16)*1000000/'DCF Model'!C15,0),"") -> 612 | I20: =IFERROR(ROUND(('DCF Model'!C45/(1+$B20)^('DCF Model'!C19+0)+'DCF Model'!D45/(1+$B20)^('DCF Model'!C19+1)+'DCF Model'!E45/(1+$B20)^('DCF Model'!C19+2)+'DCF Model'!F45/(1+$B20)^('DCF Model'!C19+3)+'DCF Model'!G45/(1+$B20)^('DCF Model'!C19+4)+('DCF Model'!G39+'DCF Model'!G42)*I$17/(1+$B20)^('DCF Model'!C19+4)-'DCF Model'!C16)*1000000/'DCF Model'!C15,0),"") -> 657
B21: =$C$3 -> 0.12525 | C21: =IFERROR(ROUND(('DCF Model'!C45/(1+$B21)^('DCF Model'!C19+0)+'DCF Model'!D45/(1+$B21)^('DCF Model'!C19+1)+'DCF Model'!E45/(1+$B21)^('DCF Model'!C19+2)+'DCF Model'!F45/(1+$B21)^('DCF Model'!C19+3)+'DCF Model'!G45/(1+$B21)^('DCF Model'!C19+4)+('DCF Model'!G39+'DCF Model'!G42)*C$17/(1+$B21)^('DCF Model'!C19+4)-'DCF Model'!C16)*1000000/'DCF Model'!C15,0),"") -> 380 | D21: =IFERROR(ROUND(('DCF Model'!C45/(1+$B21)^('DCF Model'!C19+0)+'DCF Model'!D45/(1+$B21)^('DCF Model'!C19+1)+'DCF Model'!E45/(1+$B21)^('DCF Model'!C19+2)+'DCF Model'!F45/(1+$B21)^('DCF Model'!C19+3)+'DCF Model'!G45/(1+$B21)^('DCF Model'!C19+4)+('DCF Model'!G39+'DCF Model'!G42)*D$17/(1+$B21)^('DCF Model'!C19+4)-'DCF Model'!C16)*1000000/'DCF Model'!C15,0),"") -> 424 | E21: =IFERROR(ROUND(('DCF Model'!C45/(1+$B21)^('DCF Model'!C19+0)+'DCF Model'!D45/(1+$B21)^('DCF Model'!C19+1)+'DCF Model'!E45/(1+$B21)^('DCF Model'!C19+2)+'DCF Model'!F45/(1+$B21)^('DCF Model'!C19+3)+'DCF Model'!G45/(1+$B21)^('DCF Model'!C19+4)+('DCF Model'!G39+'DCF Model'!G42)*E$17/(1+$B21)^('DCF Model'!C19+4)-'DCF Model'!C16)*1000000/'DCF Model'!C15,0),"") -> 469 | F21: =IFERROR(ROUND(('DCF Model'!C45/(1+$B21)^('DCF Model'!C19+0)+'DCF Model'!D45/(1+$B21)^('DCF Model'!C19+1)+'DCF Model'!E45/(1+$B21)^('DCF Model'!C19+2)+'DCF Model'!F45/(1+$B21)^('DCF Model'!C19+3)+'DCF Model'!G45/(1+$B21)^('DCF Model'!C19+4)+('DCF Model'!G39+'DCF Model'!G42)*F$17/(1+$B21)^('DCF Model'!C19+4)-'DCF Model'!C16)*1000000/'DCF Model'!C15,0),"") -> 513 | G21: =IFERROR(ROUND(('DCF Model'!C45/(1+$B21)^('DCF Model'!C19+0)+'DCF Model'!D45/(1+$B21)^('DCF Model'!C19+1)+'DCF Model'!E45/(1+$B21)^('DCF Model'!C19+2)+'DCF Model'!F45/(1+$B21)^('DCF Model'!C19+3)+'DCF Model'!G45/(1+$B21)^('DCF Model'!C19+4)+('DCF Model'!G39+'DCF Model'!G42)*G$17/(1+$B21)^('DCF Model'!C19+4)-'DCF Model'!C16)*1000000/'DCF Model'!C15,0),"") -> 557 | H21: =IFERROR(ROUND(('DCF Model'!C45/(1+$B21)^('DCF Model'!C19+0)+'DCF Model'!D45/(1+$B21)^('DCF Model'!C19+1)+'DCF Model'!E45/(1+$B21)^('DCF Model'!C19+2)+'DCF Model'!F45/(1+$B21)^('DCF Model'!C19+3)+'DCF Model'!G45/(1+$B21)^('DCF Model'!C19+4)+('DCF Model'!G39+'DCF Model'!G42)*H$17/(1+$B21)^('DCF Model'!C19+4)-'DCF Model'!C16)*1000000/'DCF Model'!C15,0),"") -> 601 | I21: =IFERROR(ROUND(('DCF Model'!C45/(1+$B21)^('DCF Model'!C19+0)+'DCF Model'!D45/(1+$B21)^('DCF Model'!C19+1)+'DCF Model'!E45/(1+$B21)^('DCF Model'!C19+2)+'DCF Model'!F45/(1+$B21)^('DCF Model'!C19+3)+'DCF Model'!G45/(1+$B21)^('DCF Model'!C19+4)+('DCF Model'!G39+'DCF Model'!G42)*I$17/(1+$B21)^('DCF Model'!C19+4)-'DCF Model'!C16)*1000000/'DCF Model'!C15,0),"") -> 645
B22: =$C$3+0.005 -> 0.13025 | C22: =IFERROR(ROUND(('DCF Model'!C45/(1+$B22)^('DCF Model'!C19+0)+'DCF Model'!D45/(1+$B22)^('DCF Model'!C19+1)+'DCF Model'!E45/(1+$B22)^('DCF Model'!C19+2)+'DCF Model'!F45/(1+$B22)^('DCF Model'!C19+3)+'DCF Model'!G45/(1+$B22)^('DCF Model'!C19+4)+('DCF Model'!G39+'DCF Model'!G42)*C$17/(1+$B22)^('DCF Model'!C19+4)-'DCF Model'!C16)*1000000/'DCF Model'!C15,0),"") -> 374 | D22: =IFERROR(ROUND(('DCF Model'!C45/(1+$B22)^('DCF Model'!C19+0)+'DCF Model'!D45/(1+$B22)^('DCF Model'!C19+1)+'DCF Model'!E45/(1+$B22)^('DCF Model'!C19+2)+'DCF Model'!F45/(1+$B22)^('DCF Model'!C19+3)+'DCF Model'!G45/(1+$B22)^('DCF Model'!C19+4)+('DCF Model'!G39+'DCF Model'!G42)*D$17/(1+$B22)^('DCF Model'!C19+4)-'DCF Model'!C16)*1000000/'DCF Model'!C15,0),"") -> 417 | E22: =IFERROR(ROUND(('DCF Model'!C45/(1+$B22)^('DCF Model'!C19+0)+'DCF Model'!D45/(1+$B22)^('DCF Model'!C19+1)+'DCF Model'!E45/(1+$B22)^('DCF Model'!C19+2)+'DCF Model'!F45/(1+$B22)^('DCF Model'!C19+3)+'DCF Model'!G45/(1+$B22)^('DCF Model'!C19+4)+('DCF Model'!G39+'DCF Model'!G42)*E$17/(1+$B22)^('DCF Model'!C19+4)-'DCF Model'!C16)*1000000/'DCF Model'!C15,0),"") -> 461 | F22: =IFERROR(ROUND(('DCF Model'!C45/(1+$B22)^('DCF Model'!C19+0)+'DCF Model'!D45/(1+$B22)^('DCF Model'!C19+1)+'DCF Model'!E45/(1+$B22)^('DCF Model'!C19+2)+'DCF Model'!F45/(1+$B22)^('DCF Model'!C19+3)+'DCF Model'!G45/(1+$B22)^('DCF Model'!C19+4)+('DCF Model'!G39+'DCF Model'!G42)*F$17/(1+$B22)^('DCF Model'!C19+4)-'DCF Model'!C16)*1000000/'DCF Model'!C15,0),"") -> 504 | G22: =IFERROR(ROUND(('DCF Model'!C45/(1+$B22)^('DCF Model'!C19+0)+'DCF Model'!D45/(1+$B22)^('DCF Model'!C19+1)+'DCF Model'!E45/(1+$B22)^('DCF Model'!C19+2)+'DCF Model'!F45/(1+$B22)^('DCF Model'!C19+3)+'DCF Model'!G45/(1+$B22)^('DCF Model'!C19+4)+('DCF Model'!G39+'DCF Model'!G42)*G$17/(1+$B22)^('DCF Model'!C19+4)-'DCF Model'!C16)*1000000/'DCF Model'!C15,0),"") -> 547 | H22: =IFERROR(ROUND(('DCF Model'!C45/(1+$B22)^('DCF Model'!C19+0)+'DCF Model'!D45/(1+$B22)^('DCF Model'!C19+1)+'DCF Model'!E45/(1+$B22)^('DCF Model'!C19+2)+'DCF Model'!F45/(1+$B22)^('DCF Model'!C19+3)+'DCF Model'!G45/(1+$B22)^('DCF Model'!C19+4)+('DCF Model'!G39+'DCF Model'!G42)*H$17/(1+$B22)^('DCF Model'!C19+4)-'DCF Model'!C16)*1000000/'DCF Model'!C15,0),"") -> 590 | I22: =IFERROR(ROUND(('DCF Model'!C45/(1+$B22)^('DCF Model'!C19+0)+'DCF Model'!D45/(1+$B22)^('DCF Model'!C19+1)+'DCF Model'!E45/(1+$B22)^('DCF Model'!C19+2)+'DCF Model'!F45/(1+$B22)^('DCF Model'!C19+3)+'DCF Model'!G45/(1+$B22)^('DCF Model'!C19+4)+('DCF Model'!G39+'DCF Model'!G42)*I$17/(1+$B22)^('DCF Model'!C19+4)-'DCF Model'!C16)*1000000/'DCF Model'!C15,0),"") -> 633
B23: =$C$3+0.01 -> 0.13525 | C23: =IFERROR(ROUND(('DCF Model'!C45/(1+$B23)^('DCF Model'!C19+0)+'DCF Model'!D45/(1+$B23)^('DCF Model'!C19+1)+'DCF Model'!E45/(1+$B23)^('DCF Model'!C19+2)+'DCF Model'!F45/(1+$B23)^('DCF Model'!C19+3)+'DCF Model'!G45/(1+$B23)^('DCF Model'!C19+4)+('DCF Model'!G39+'DCF Model'!G42)*C$17/(1+$B23)^('DCF Model'!C19+4)-'DCF Model'!C16)*1000000/'DCF Model'!C15,0),"") -> 368 | D23: =IFERROR(ROUND(('DCF Model'!C45/(1+$B23)^('DCF Model'!C19+0)+'DCF Model'!D45/(1+$B23)^('DCF Model'!C19+1)+'DCF Model'!E45/(1+$B23)^('DCF Model'!C19+2)+'DCF Model'!F45/(1+$B23)^('DCF Model'!C19+3)+'DCF Model'!G45/(1+$B23)^('DCF Model'!C19+4)+('DCF Model'!G39+'DCF Model'!G42)*D$17/(1+$B23)^('DCF Model'!C19+4)-'DCF Model'!C16)*1000000/'DCF Model'!C15,0),"") -> 410 | E23: =IFERROR(ROUND(('DCF Model'!C45/(1+$B23)^('DCF Model'!C19+0)+'DCF Model'!D45/(1+$B23)^('DCF Model'!C19+1)+'DCF Model'!E45/(1+$B23)^('DCF Model'!C19+2)+'DCF Model'!F45/(1+$B23)^('DCF Model'!C19+3)+'DCF Model'!G45/(1+$B23)^('DCF Model'!C19+4)+('DCF Model'!G39+'DCF Model'!G42)*E$17/(1+$B23)^('DCF Model'!C19+4)-'DCF Model'!C16)*1000000/'DCF Model'!C15,0),"") -> 453 | F23: =IFERROR(ROUND(('DCF Model'!C45/(1+$B23)^('DCF Model'!C19+0)+'DCF Model'!D45/(1+$B23)^('DCF Model'!C19+1)+'DCF Model'!E45/(1+$B23)^('DCF Model'!C19+2)+'DCF Model'!F45/(1+$B23)^('DCF Model'!C19+3)+'DCF Model'!G45/(1+$B23)^('DCF Model'!C19+4)+('DCF Model'!G39+'DCF Model'!G42)*F$17/(1+$B23)^('DCF Model'!C19+4)-'DCF Model'!C16)*1000000/'DCF Model'!C15,0),"") -> 495 | G23: =IFERROR(ROUND(('DCF Model'!C45/(1+$B23)^('DCF Model'!C19+0)+'DCF Model'!D45/(1+$B23)^('DCF Model'!C19+1)+'DCF Model'!E45/(1+$B23)^('DCF Model'!C19+2)+'DCF Model'!F45/(1+$B23)^('DCF Model'!C19+3)+'DCF Model'!G45/(1+$B23)^('DCF Model'!C19+4)+('DCF Model'!G39+'DCF Model'!G42)*G$17/(1+$B23)^('DCF Model'!C19+4)-'DCF Model'!C16)*1000000/'DCF Model'!C15,0),"") -> 537 | H23: =IFERROR(ROUND(('DCF Model'!C45/(1+$B23)^('DCF Model'!C19+0)+'DCF Model'!D45/(1+$B23)^('DCF Model'!C19+1)+'DCF Model'!E45/(1+$B23)^('DCF Model'!C19+2)+'DCF Model'!F45/(1+$B23)^('DCF Model'!C19+3)+'DCF Model'!G45/(1+$B23)^('DCF Model'!C19+4)+('DCF Model'!G39+'DCF Model'!G42)*H$17/(1+$B23)^('DCF Model'!C19+4)-'DCF Model'!C16)*1000000/'DCF Model'!C15,0),"") -> 579 | I23: =IFERROR(ROUND(('DCF Model'!C45/(1+$B23)^('DCF Model'!C19+0)+'DCF Model'!D45/(1+$B23)^('DCF Model'!C19+1)+'DCF Model'!E45/(1+$B23)^('DCF Model'!C19+2)+'DCF Model'!F45/(1+$B23)^('DCF Model'!C19+3)+'DCF Model'!G45/(1+$B23)^('DCF Model'!C19+4)+('DCF Model'!G39+'DCF Model'!G42)*I$17/(1+$B23)^('DCF Model'!C19+4)-'DCF Model'!C16)*1000000/'DCF Model'!C15,0),"") -> 622
B24: =$C$3+0.015 -> 0.14025 | C24: =IFERROR(ROUND(('DCF Model'!C45/(1+$B24)^('DCF Model'!C19+0)+'DCF Model'!D45/(1+$B24)^('DCF Model'!C19+1)+'DCF Model'!E45/(1+$B24)^('DCF Model'!C19+2)+'DCF Model'!F45/(1+$B24)^('DCF Model'!C19+3)+'DCF Model'!G45/(1+$B24)^('DCF Model'!C19+4)+('DCF Model'!G39+'DCF Model'!G42)*C$17/(1+$B24)^('DCF Model'!C19+4)-'DCF Model'!C16)*1000000/'DCF Model'!C15,0),"") -> 362 | D24: =IFERROR(ROUND(('DCF Model'!C45/(1+$B24)^('DCF Model'!C19+0)+'DCF Model'!D45/(1+$B24)^('DCF Model'!C19+1)+'DCF Model'!E45/(1+$B24)^('DCF Model'!C19+2)+'DCF Model'!F45/(1+$B24)^('DCF Model'!C19+3)+'DCF Model'!G45/(1+$B24)^('DCF Model'!C19+4)+('DCF Model'!G39+'DCF Model'!G42)*D$17/(1+$B24)^('DCF Model'!C19+4)-'DCF Model'!C16)*1000000/'DCF Model'!C15,0),"") -> 404 | E24: =IFERROR(ROUND(('DCF Model'!C45/(1+$B24)^('DCF Model'!C19+0)+'DCF Model'!D45/(1+$B24)^('DCF Model'!C19+1)+'DCF Model'!E45/(1+$B24)^('DCF Model'!C19+2)+'DCF Model'!F45/(1+$B24)^('DCF Model'!C19+3)+'DCF Model'!G45/(1+$B24)^('DCF Model'!C19+4)+('DCF Model'!G39+'DCF Model'!G42)*E$17/(1+$B24)^('DCF Model'!C19+4)-'DCF Model'!C16)*1000000/'DCF Model'!C15,0),"") -> 445 | F24: =IFERROR(ROUND(('DCF Model'!C45/(1+$B24)^('DCF Model'!C19+0)+'DCF Model'!D45/(1+$B24)^('DCF Model'!C19+1)+'DCF Model'!E45/(1+$B24)^('DCF Model'!C19+2)+'DCF Model'!F45/(1+$B24)^('DCF Model'!C19+3)+'DCF Model'!G45/(1+$B24)^('DCF Model'!C19+4)+('DCF Model'!G39+'DCF Model'!G42)*F$17/(1+$B24)^('DCF Model'!C19+4)-'DCF Model'!C16)*1000000/'DCF Model'!C15,0),"") -> 486 | G24: =IFERROR(ROUND(('DCF Model'!C45/(1+$B24)^('DCF Model'!C19+0)+'DCF Model'!D45/(1+$B24)^('DCF Model'!C19+1)+'DCF Model'!E45/(1+$B24)^('DCF Model'!C19+2)+'DCF Model'!F45/(1+$B24)^('DCF Model'!C19+3)+'DCF Model'!G45/(1+$B24)^('DCF Model'!C19+4)+('DCF Model'!G39+'DCF Model'!G42)*G$17/(1+$B24)^('DCF Model'!C19+4)-'DCF Model'!C16)*1000000/'DCF Model'!C15,0),"") -> 528 | H24: =IFERROR(ROUND(('DCF Model'!C45/(1+$B24)^('DCF Model'!C19+0)+'DCF Model'!D45/(1+$B24)^('DCF Model'!C19+1)+'DCF Model'!E45/(1+$B24)^('DCF Model'!C19+2)+'DCF Model'!F45/(1+$B24)^('DCF Model'!C19+3)+'DCF Model'!G45/(1+$B24)^('DCF Model'!C19+4)+('DCF Model'!G39+'DCF Model'!G42)*H$17/(1+$B24)^('DCF Model'!C19+4)-'DCF Model'!C16)*1000000/'DCF Model'!C15,0),"") -> 569 | I24: =IFERROR(ROUND(('DCF Model'!C45/(1+$B24)^('DCF Model'!C19+0)+'DCF Model'!D45/(1+$B24)^('DCF Model'!C19+1)+'DCF Model'!E45/(1+$B24)^('DCF Model'!C19+2)+'DCF Model'!F45/(1+$B24)^('DCF Model'!C19+3)+'DCF Model'!G45/(1+$B24)^('DCF Model'!C19+4)+('DCF Model'!G39+'DCF Model'!G42)*I$17/(1+$B24)^('DCF Model'!C19+4)-'DCF Model'!C16)*1000000/'DCF Model'!C15,0),"") -> 610
B26: All values dynamically linked to DCF Model. Headers auto-center on current WACC / Terminal g / Exit Multiple.

Sheet Adjustments Log
B2: Adjustments Log - Data Section
B4: 日付 | C4: セル | D4: 変更内容 | E4: 理由 | F4: 元の値 | G4: 状態
B5: 2026-08-22 | C5: - | D5: Generated by pipeline on 2026-08-22 15:39, template rev e5effd6 | E5: 初期生成（手修正なし） | F5: - | G5: generated
B6: 2026-08-22 | C6: 'DCF Model'!C15 / 'Comps Analysis'!C23 | D6: 未行使新株予約権による希薄化が Target Price に未反映(株数 32,017,051 のまま) | E6: 有報 第26期(S100YMGV)に「当連結会計年度末現在の新株予約権による潜在株式数は38,737,100株であり発行済株式総数29,769,051株の130.1%に相当」と明記。Q1行使済2,248,000株を控除した残 約36,489,100株。単純加算の Fully Diluted は約68,506,151株(+114.0%)、行使代金を織り込む treasury stock method(平均行使価額1,061円 / 株価1,840円)では約47,465,390株(+48.3%)。プロンプト指定の時価総額58,911百万円との整合を優先して未反映のままとした。Target Mid 3,586円は希薄化前の値であり、+48.3%希薄化なら約2,418円相当。 | F6: - | G6: 解決(2026-08-23: C15 を TSM 47,465,390 に変更)
B7: 2026-08-22 | C7: 'DCF Model'!C5 / C18 | D7: capex_pct 6.0% / da_pct 5.8% を単一値で全5年に適用 | E7: overrides_validator の ALLOWED_KEYS で capex_pct / da_pct は数値スカラーのみ(配列は契約違反)。プロンプト指定の年次テーパー(capex 12%→5% / D&A 3.0%→5.0%)を表現できず、ターミナル整合(capex/D&A = 1.03x)を満たす単一値フォールバックを採用した。帰結: Y1 の capex が過小(6.0% vs 想定12%、約4,436 vs 8,872百万円)かつ Y1 の D&A が過大(5.8% vs 想定3.0%、約4,288 vs 2,218百万円)。両者とも Y1 FCF を過大に見せる方向で、合計で約6,506百万円 Y1 FCF が上振れしている。GPU資産の償却は稼働に遅れて立ち上がるため、本来は D&A 比率が後年に向けて上昇する形が実態に近い。 | F7: - | G7: 未解決
B8: 2026-08-22 | C8: 'Comps Analysis'!C21 | D8: 自社 EBITDA に FY2026/3 通期実績 4,000(営業利益3,545 + D&A 455)を採用 | E8: LTM ベースなら 約9,330(営業利益8,730 + D&A約600)。収益構造が FY2026/3(物販中心・粗利19%)とQ1 FY2027/3(賃貸中心・粗利91%)で別物のため、どちらを採るかで Comps EV/EBITDA の implied 株価が1,417円 と 3,296円 に分かれる。peer 4社が通期実績ベースであり基準混在を避けるため通期を採用したが、構造転換後の実力を測るなら LTM の方が適切という判断もあり得る。 | F8: - | G8: 未解決
B9: 2026-08-23 | C9: 'DCF Model'!C69:G73 / C76:G80 / C83:G87 | D9: シナリオ行列を全面改定。Base Y1 売上 −20%(26,884)/営業利益率20%(うち一時手数料5,578)、Y2 +100%(53,768)/18%。Upside Y1 +79%、Downside 1 Y1 −55%、Downside 2 Y1 −70%/−10%(貸倒織込)。Management は会社予想据え置きのまま Y2以降を減速 | E9: 前回Baseは Q1 の案件組成・紹介手数料5,578(一時)を継続収益と誤読し、遡及解約された79,864百万円の案件を織り込んでいた。Q1短信の説明で判明 | F9: Base: [1.2,0.4,0.2,0.1,0.05] / COGS [0.72,0.71,0.715,0.74,0.76] | G9: 解決
B10: 2026-08-23 | C10: 'DCF Model'!C15 / C27 / D27 | D10: 株数を TSM 希薄化後 47,465,390 に変更。アクティブシナリオを Base(D27=1)に戻した(受領時は D27=3 Management) | E10: 未行使新株予約権の希薄化(+48.3%)を Target に反映。market_analysis 用に Base をアクティブに | F10: 32,017,051 / D27=3 | G10: 解決
B11: 2026-08-23 | C11: 'Executive Summary'!C18 / C19 / B33 / B24-B31 | D11: Comps EV/EBITDA と PER を Target 平均から除外(N/A 表示)。thesis/risks を一時手数料・遡及解約・希薄化・空売りレポート反映に書換。B33 に注記追加 | E11: FY3/26 の EBITDA 4,000 / 純利益 2,802 は解約済み契約由来で継続水準ではない(手順書§8: 無意味な指標を Target に残さない)。基本株数ベースの値は B33 に併記 | F11: Comps 1,417 / PER 3,626 を平均に含めていた | G11: 解決
B12: Pipeline Metadata (do not edit — read by scripts/validate_output.py)
B13: key | C13: value
B14: capex_pct_basis | C14: assumption
B15: capex_pct_c5 | C15: 0.06
B16: capex_pct_hist3yr | C16: 0.136868
B17: company_name | C17: Data Section
B18: comps_asof | C18: 2026-08-22
B19: comps_da_missing | C19: none
B20: comps_ev_ebitda_invalid | C20: no
B21: comps_ev_ebitda_rows | C21: 6,7,8,9
B22: comps_impl_mult_row | C22: 27
B23: comps_impl_per_row | C23: 28
B24: comps_peer_rows | C24: 6,7,8,9
... B40: ticker | C40: 3905.T
