Workbook

Sheet Executive Summary
B1: DISCLAIMER: This is a sample analysis for demonstration purposes only. It does not constitute investment advice.
B3: DMW Corporation (6365.T)
B4: Equity Research Report
B6: Company | C6: DMW Corporation
B7: Ticker | C7: 6365.T (TSE Prime)
B8: Sector | C8: Machinery - Pumps & Blowers
B9: Current Price | C9: 5900
B10: Target Price (Mid) | C10: =ROUND(AVERAGE(C16:C19),0)
B11: Recommendation | C11: =IF(C12>0.15,"BUY",IF(C12>0.05,"HOLD","SELL"))
B12: Upside / Downside | C12: =(C10-C9)/C9
B14: Valuation Summary
B15: Methodology | C15: Implied Value (JPY) | D15: vs Current Price
B16: DCF - Perpetuity Growth | C16: ='DCF Model'!C55 | D16: =(C16-C9)/C9
B17: DCF - Exit Multiple | C17: ='DCF Model'!C64 | D17: =(C17-C9)/C9
B18: Comps - EV/EBITDA Median | C18: ='Comps Analysis'!C27 | D18: =(C18-C9)/C9
B19: Comps - PER Median | C19: ='Comps Analysis'!C28 | D19: =(C19-C9)/C9
B21: Integrated Valuation Range | C21: =MIN(C16:C19)&" - "&MAX(C16:C19)
B23: Key Investment Thesis
B24: 1. DeROs energy recovery device achieves world-leading 99.7% efficiency, positioning DMW for Middle East/India desalination demand growth
B25: 2. India plant expansion enables overseas shipment of large high-pressure pumps, lifting export revenue mix
B26: 3. METI Energy Conservation Grand Prize win reinforces technology brand and strengthens public-sector competitive moat
B27: 4. Stable domestic public-sector backlog (water/sewage/power) provides defensive base while overseas grows
B28: Key Risks
B29: 1. Middle East geopolitical risk could freeze plant projects, delaying DeROs revenue recognition
B30: 2. Q4-skewed revenue recognition creates large quarterly earnings volatility
B31: 3. FX (yen appreciation) compresses overseas margins given JPY-denominated cost base
B32: 4. Domestic public-investment cuts would directly hit ~46% of revenue from government tenders

Sheet Financial Statements
B2: DMW Corporation - Historical Financials (JPY mn)
C4: FY2021 | D4: FY2022 | E4: FY2023 | F4: FY2024 | G4: FY2025
B5: Income Statement
B6: Revenue | C6: 21750 | D6: 22820 | E6: 23874 | F6: 24096 | G6: 28077
B7: COGS | C7: 16112 | D7: 17099 | E7: 17950 | F7: 18111 | G7: 20750
B8: Gross Profit | C8: =C6-C7 | D8: =D6-D7 | E8: =E6-E7 | F8: =F6-F7 | G8: =G6-G7
B9: Gross Margin | C9: =C8/C6 | D9: =D8/D6 | E9: =E8/E6 | F9: =F8/F6 | G9: =G8/G6
B10: SGA | C10: 3090 | D10: 3294 | E10: 3378 | F10: 3700 | G10: 4091
B11: Operating Income | C11: 2547 | D11: 2425 | E11: 2545 | F11: 2283 | G11: 3235
B12: Net Income | C12: 2003 | D12: 1877 | E12: 1871 | F12: 1750 | G12: 2426
B13: Operating Margin | C13: =C11/C6 | D13: =D11/D6 | E13: =E11/E6 | F13: =F11/F6 | G13: =G11/G6
B14: Net Margin | C14: =C12/C6 | D14: =D12/D6 | E14: =E12/E6 | F14: =F12/F6 | G14: =G12/G6
B15: Revenue Growth (YoY) | C15: n/a | D15: =(D6-C6)/C6 | E15: =(E6-D6)/D6 | F15: =(F6-E6)/E6 | G15: =(G6-F6)/F6
B16: Operating Income Growth (YoY) | C16: n/a | D16: =(D11-C11)/C11 | E16: =(E11-D11)/D11 | F16: =(F11-E11)/E11 | G16: =(G11-F11)/F11
B18: Cash Flow Statement
B19: Operating Cash Flow | C19: 1298 | D19: 162 | E19: 1573 | F19: 730 | G19: 2109
B20: Capex | C20: 648 | D20: 556 | E20: 848 | F20: 682 | G20: 560
B21: Free Cash Flow | C21: =C19-C20 | D21: =D19-D20 | E21: =E19-E20 | F21: =F19-F20 | G21: =G19-G20
B22: FCF Margin | C22: =C21/C6 | D22: =D21/D6 | E22: =E21/E6 | F22: =F21/F6 | G22: =G21/G6
B23: Capex / Revenue | C23: =C20/C6 | D23: =D20/D6 | E23: =E20/E6 | F23: =F20/F6 | G23: =G20/G6
B25: Balance Sheet Highlights
B26: Cash & Deposits | C26: 7005 | D26: 5885 | E26: 6036 | F26: 6099 | G26: 6515
B27: Short-term Debt | C27: 0 | D27: 0 | E27: 0 | F27: 0 | G27: 0
B28: Net Debt (Cash) | C28: =C27-C26 | D28: =D27-D26 | E28: =E27-E26 | F28: =F27-F26 | G28: =G27-G26

Sheet DCF Model
B2: DCF Valuation Model - DMW Corporation
B4: Assumptions
B5: Capex / Revenue | C5: 0.03
B6: Effective Tax Rate | C6: 0.3
B7: Risk-Free Rate | C7: 0.01
B8: Beta | C8: 0.85
B9: Equity Risk Premium | C9: 0.06
B10: Size Premium | C10: 0.02
B11: After-tax Cost of Debt | C11: 0.008
B12: D/E Ratio | C12: 0
B13: Terminal Growth Rate | C13: 0.015
B14: Exit Multiple (EV/EBITDA) | C14: 8
B15: Fully Diluted Shares | C15: 4144556
B16: Net Debt (JPY mn) | C16: 0
... B20: LTM Revenue (JPY mn) | C20: 30148
B22: WACC Calculation
B23: Cost of Equity (Ke) | C23: =C7+C8*C9+C10
B24: Weight of Equity | C24: =1/(1+C12)
B25: Weight of Debt | C25: =C12/(1+C12)
B26: WACC | C26: =C23*C24+C11*C25
B27: Active Scenario | C27: Base | D27: =MATCH(C27,{"Base","Upside","Management","Downside 1","Downside 2"},0)
B28: Projected Free Cash Flow
C29: FY2026(E) | D29: FY2027(E) | E29: FY2028(E) | F29: FY2029(E) | G29: FY2030(E)
B30: Revenue Growth (YoY) | C30: =(C33/C17)-1 | D30: =(D33/C33)-1 | E30: =(E33/D33)-1 | F30: =(F33/E33)-1 | G30: =(G33/F33)-1
B31: COGS % of Revenue | C31: =CHOOSE($D$27,'Segment Analysis'!G79,'Segment Analysis'!G80,'Segment Analysis'!G81,'Segment Analysis'!G82,'Segment Analysis'!G83) | D31: =CHOOSE($D$27,'Segment Analysis'!H79,'Segment Analysis'!H80,'Segment Analysis'!H81,'Segment Analysis'!H82,'Segment Analysis'!H83) | E31: =CHOOSE($D$27,'Segment Analysis'!I79,'Segment Analysis'!I80,'Segment Analysis'!I81,'Segment Analysis'!I82,'Segment Analysis'!I83) | F31: =CHOOSE($D$27,'Segment Analysis'!J79,'Segment Analysis'!J80,'Segment Analysis'!J81,'Segment Analysis'!J82,'Segment Analysis'!J83) | G31: =CHOOSE($D$27,'Segment Analysis'!K79,'Segment Analysis'!K80,'Segment Analysis'!K81,'Segment Analysis'!K82,'Segment Analysis'!K83)
B32: SGA % of Revenue | C32: =CHOOSE($D$27,'Segment Analysis'!G86,'Segment Analysis'!G87,'Segment Analysis'!G88,'Segment Analysis'!G89,'Segment Analysis'!G90) | D32: =CHOOSE($D$27,'Segment Analysis'!H86,'Segment Analysis'!H87,'Segment Analysis'!H88,'Segment Analysis'!H89,'Segment Analysis'!H90) | E32: =CHOOSE($D$27,'Segment Analysis'!I86,'Segment Analysis'!I87,'Segment Analysis'!I88,'Segment Analysis'!I89,'Segment Analysis'!I90) | F32: =CHOOSE($D$27,'Segment Analysis'!J86,'Segment Analysis'!J87,'Segment Analysis'!J88,'Segment Analysis'!J89,'Segment Analysis'!J90) | G32: =CHOOSE($D$27,'Segment Analysis'!K86,'Segment Analysis'!K87,'Segment Analysis'!K88,'Segment Analysis'!K89,'Segment Analysis'!K90)
B33: Revenue | C33: ='Segment Analysis'!G21 | D33: ='Segment Analysis'!H21 | E33: ='Segment Analysis'!I21 | F33: ='Segment Analysis'!J21 | G33: ='Segment Analysis'!K21
B34: COGS | C34: =C33*C31 | D34: =D33*D31 | E34: =E33*E31 | F34: =F33*F31 | G34: =G33*G31
B35: Gross Profit | C35: =C33-C34 | D35: =D33-D34 | E35: =E33-E34 | F35: =F33-F34 | G35: =G33-G34
B36: Gross Margin | C36: =C35/C33 | D36: =D35/D33 | E36: =E35/E33 | F36: =F35/F33 | G36: =G35/G33
B37: SGA Expense | C37: =C33*C32 | D37: =D33*D32 | E37: =E33*E32 | F37: =F33*F32 | G37: =G33*G32
B38: Implied Operating Margin | C38: =C39/C33 | D38: =D39/D33 | E38: =E39/E33 | F38: =F39/F33 | G38: =G39/G33
B39: Operating Income (EBIT) | C39: =C35-C37 | D39: =D35-D37 | E39: =E35-E37 | F39: =F35-F37 | G39: =G35-G37
B40: Less: Tax | C40: =MAX(0,C39*C6) | D40: =MAX(0,D39*C6) | E40: =MAX(0,E39*C6) | F40: =MAX(0,F39*C6) | G40: =MAX(0,G39*C6)
B41: NOPAT | C41: =C39-C40 | D41: =D39-D40 | E41: =E39-E40 | F41: =F39-F40 | G41: =G39-G40
B42: Plus: D&A | C42: =C33*C18 | D42: =D33*C18 | E42: =E33*C18 | F42: =F33*C18 | G42: =G33*C18
B43: Less: Capex | C43: =C33*C5 | D43: =D33*C5 | E43: =E33*C5 | F43: =F33*C5 | G43: =G33*C5
B44: Change in NWC | C44: ='NWC Schedule'!D19 | D44: ='NWC Schedule'!E19 | E44: ='NWC Schedule'!F19 | F44: ='NWC Schedule'!G19 | G44: ='NWC Schedule'!H19
B45: Unlevered Free Cash Flow | C45: =C41+C42-C43-C44 | D45: =D41+D42-D43-D44 | E45: =E41+E42-E43-E44 | F45: =F41+F42-F43-F44 | G45: =G41+G42-G43-G44
B46: Discount Factor | C46: =1/(1+C26)^(C19+0) | D46: =1/(1+C26)^(C19+1) | E46: =1/(1+C26)^(C19+2) | F46: =1/(1+C26)^(C19+3) | G46: =1/(1+C26)^(C19+4)
...

Sheet NWC Schedule
B2: NWC Schedule - DMW Corporation
B4: Working Capital Drivers (% of Revenue) | C4: Base Year | D4: FY2026(E) | E4: FY2027(E) | F4: FY2028(E) | G4: FY2029(E) | H4: FY2030(E)
B5: NWC % of Revenue | C5: =C18/C9 | D5: =CHOOSE('DCF Model'!$D$27,'Segment Analysis'!G93,'Segment Analysis'!G94,'Segment Analysis'!G95,'Segment Analysis'!G96,'Segment Analysis'!G97) | E5: =CHOOSE('DCF Model'!$D$27,'Segment Analysis'!H93,'Segment Analysis'!H94,'Segment Analysis'!H95,'Segment Analysis'!H96,'Segment Analysis'!H97) | F5: =CHOOSE('DCF Model'!$D$27,'Segment Analysis'!I93,'Segment Analysis'!I94,'Segment Analysis'!I95,'Segment Analysis'!I96,'Segment Analysis'!I97) | G5: =CHOOSE('DCF Model'!$D$27,'Segment Analysis'!J93,'Segment Analysis'!J94,'Segment Analysis'!J95,'Segment Analysis'!J96,'Segment Analysis'!J97) | H5: =CHOOSE('DCF Model'!$D$27,'Segment Analysis'!K93,'Segment Analysis'!K94,'Segment Analysis'!K95,'Segment Analysis'!K96,'Segment Analysis'!K97)
B6: — | C6: — | D6: — | E6: — | F6: — | G6: — | H6: —
B7: — | C7: — | D7: — | E7: — | F7: — | G7: — | H7: —
B8: P&L Reference (JPY mn)
B9: Revenue | C9: 28077 | D9: ='DCF Model'!C33 | E9: ='DCF Model'!D33 | F9: ='DCF Model'!E33 | G9: ='DCF Model'!F33 | H9: ='DCF Model'!G33
B10: — | C10: — | D10: — | E10: — | F10: — | G10: — | H10: —
B11: Working Capital Items (JPY mn)
B12: — | C12: — | D12: — | E12: — | F12: — | G12: — | H12: —
B13: — | C13: — | D13: — | E13: — | F13: — | G13: — | H13: —
B14: — | C14: — | D14: — | E14: — | F14: — | G14: — | H14: —
B15: — | C15: — | D15: — | E15: — | F15: — | G15: — | H15: —
B16: — | C16: — | D16: — | E16: — | F16: — | G16: — | H16: —
B17: Net Working Capital (JPY mn)
B18: Net Working Capital | C18: 9949 | D18: =D9*D5 | E18: =E9*E5 | F18: =F9*F5 | G18: =G9*G5 | H18: =H9*H5
B19: Change in NWC | C19: n/a | D19: =D18-C18 | E19: =E18-D18 | F19: =F18-E18 | G19: =G18-F18 | H19: =H18-G18
B22: NWC inputs are in Segment Analysis sheet.

Sheet Comps Analysis
B2: Comparable Company Analysis
B4: Company | C4: Ticker | D4: Mkt Cap (JPY mn) | E4: EV (JPY mn) | F4: Revenue (JPY mn) | G4: EBITDA (JPY mn) | H4: Op Income (JPY mn) | I4: Net Income (JPY mn) | J4: EV/EBITDA | K4: EV/Revenue | L4: PER | M4: PBR | N4: Op Margin | O4: ROE
B5: Torishima Pump Mfg. Co., Ltd. | C5: 6363.T | D5: 87765.983 | E5: 110493.98 | F5: 89000 | G5: 8483 | H5: 5800 | I5: 5600 | J5: =E5/G5 | K5: =E5/F5 | L5: =D5/I5 | M5: 1.5556655 | N5: =H5/F5 | O5: 0.099260861
B6: Tsurumi Manufacturing Co., Ltd. | C6: 6351.T | D6: 115360.28 | E6: 131039.28 | F6: 74000 | G6: 12694 | H6: 11000 | I6: 7800 | J6: =E6/G6 | K6: =E6/F6 | L6: =D6/I6 | M6: 1.2035251 | N6: =H6/F6 | O6: 0.081375454
B7: Iwaki Co., Ltd. | C7: 6237.T | D7: 61559.521 | E7: 64316.521 | F7: 48439 | G7: 7407 | H7: 6159 | I7: 4788 | J7: =E7/G7 | K7: =E7/F7 | L7: =D7/I7 | M7: 1.6153115 | N7: =H7/F7 | O7: 0.12563632
B8: Maezawa Industries, Inc. | C8: 6489.T | D8: 36339.413 | E8: 38761.413 | F8: 39000 | G8: 5579 | H8: 4900 | I8: 3200 | J8: =E8/G8 | K8: =E8/F8 | L8: =D8/I8 | M8: 1.2145932 | N8: =H8/F8 | O8: 0.10695545
B9: Kaji Technology Corporation | C9: 6391.T | D9: 7882.306 | E9: 9254.306 | F9: 7700 | G9: 1260 | H9: 970 | I9: 730 | J9: =E9/G9 | K9: =E9/F9 | L9: =D9/I9 | M9: 1.0082254 | N9: =H9/F9 | O9: 0.093374265
B14: Statistics
B15: 25th Percentile | D15: =PERCENTILE(J5:J9,0.25) | E15: =PERCENTILE(K5:K9,0.25) | F15: =PERCENTILE(L5:L9,0.25) | G15: =PERCENTILE(M5:M9,0.25) | H15: =PERCENTILE(N5:N9,0.25) | I15: =PERCENTILE(O5:O9,0.25)
B16: Median (50th) | D16: =MEDIAN(J5:J9) | E16: =MEDIAN(K5:K9) | F16: =MEDIAN(L5:L9) | G16: =MEDIAN(M5:M9) | H16: =MEDIAN(N5:N9) | I16: =MEDIAN(O5:O9)
B17: 75th Percentile | D17: =PERCENTILE(J5:J9,0.75) | E17: =PERCENTILE(K5:K9,0.75) | F17: =PERCENTILE(L5:L9,0.75) | G17: =PERCENTILE(M5:M9,0.75) | H17: =PERCENTILE(N5:N9,0.75) | I17: =PERCENTILE(O5:O9,0.75)
B19: Implied Valuation for DMW Corporation
B20: DMW Corporation Financials
B21: EBITDA (JPY mn) | C21: 3929
B22: Net Income (JPY mn) | C22: 2426
B23: Shares Outstanding | C23: 4144556
B24: Net Debt (JPY mn) | C24: 0
B26: Implied Share Price (Median Multiples)
B27: Via EV/EBITDA (Median) | C27: =ROUND((C21*D16-C24)*1000000/C23,0)
B28: Via PER (Median) | C28: =ROUND(C22*F16*1000000/C23,0)

Sheet Sensitivity Analysis
B2: Sensitivity Analysis
B3: Current WACC: | C3: ='DCF Model'!C26 | E3: Terminal g: | F3: ='DCF Model'!C13 | H3: Exit Multiple: | I3: ='DCF Model'!C14
B5: Table 1: WACC vs Terminal Growth Rate (PGM - Implied Share Price, JPY)
B6: WACC \ Terminal g | C6: =$F$3-0.0075 | D6: =$F$3-0.005 | E6: =$F$3-0.0025 | F6: =$F$3 | G6: =$F$3+0.0025 | H6: =$F$3+0.005 | I6: =$F$3+0.0075
B7: =$C$3-0.015 | C7: =IFERROR(ROUND(('DCF Model'!C45/(1+$B7)^('DCF Model'!C19+0)+'DCF Model'!D45/(1+$B7)^('DCF Model'!C19+1)+'DCF Model'!E45/(1+$B7)^('DCF Model'!C19+2)+'DCF Model'!F45/(1+$B7)^('DCF Model'!C19+3)+'DCF Model'!G45/(1+$B7)^('DCF Model'!C19+4)+'DCF Model'!G45*(1+C$6)/($B7-C$6)/(1+$B7)^('DCF Model'!C19+4)-'DCF Model'!C16)*1000000/'DCF Model'!C15,0),"") | D7: =IFERROR(ROUND(('DCF Model'!C45/(1+$B7)^('DCF Model'!C19+0)+'DCF Model'!D45/(1+$B7)^('DCF Model'!C19+1)+'DCF Model'!E45/(1+$B7)^('DCF Model'!C19+2)+'DCF Model'!F45/(1+$B7)^('DCF Model'!C19+3)+'DCF Model'!G45/(1+$B7)^('DCF Model'!C19+4)+'DCF Model'!G45*(1+D$6)/($B7-D$6)/(1+$B7)^('DCF Model'!C19+4)-'DCF Model'!C16)*1000000/'DCF Model'!C15,0),"") | E7: =IFERROR(ROUND(('DCF Model'!C45/(1+$B7)^('DCF Model'!C19+0)+'DCF Model'!D45/(1+$B7)^('DCF Model'!C19+1)+'DCF Model'!E45/(1+$B7)^('DCF Model'!C19+2)+'DCF Model'!F45/(1+$B7)^('DCF Model'!C19+3)+'DCF Model'!G45/(1+$B7)^('DCF Model'!C19+4)+'DCF Model'!G45*(1+E$6)/($B7-E$6)/(1+$B7)^('DCF Model'!C19+4)-'DCF Model'!C16)*1000000/'DCF Model'!C15,0),"") | F7: =IFERROR(ROUND(('DCF Model'!C45/(1+$B7)^('DCF Model'!C19+0)+'DCF Model'!D45/(1+$B7)^('DCF Model'!C19+1)+'DCF Model'!E45/(1+$B7)^('DCF Model'!C19+2)+'DCF Model'!F45/(1+$B7)^('DCF Model'!C19+3)+'DCF Model'!G45/(1+$B7)^('DCF Model'!C19+4)+'DCF Model'!G45*(1+F$6)/($B7-F$6)/(1+$B7)^('DCF Model'!C19+4)-'DCF Model'!C16)*1000000/'DCF Model'!C15,0),"") | G7: =IFERROR(ROUND(('DCF Model'!C45/(1+$B7)^('DCF Model'!C19+0)+'DCF Model'!D45/(1+$B7)^('DCF Model'!C19+1)+'DCF Model'!E45/(1+$B7)^('DCF Model'!C19+2)+'DCF Model'!F45/(1+$B7)^('DCF Model'!C19+3)+'DCF Model'!G45/(1+$B7)^('DCF Model'!C19+4)+'DCF Model'!G45*(1+G$6)/($B7-G$6)/(1+$B7)^('DCF Model'!C19+4)-'DCF Model'!C16)*1000000/'DCF Model'!C15,0),"") | H7: =IFERROR(ROUND(('DCF Model'!C45/(1+$B7)^('DCF Model'!C19+0)+'DCF Model'!D45/(1+$B7)^('DCF Model'!C19+1)+'DCF Model'!E45/(1+$B7)^('DCF Model'!C19+2)+'DCF Model'!F45/(1+$B7)^('DCF Model'!C19+3)+'DCF Model'!G45/(1+$B7)^('DCF Model'!C19+4)+'DCF Model'!G45*(1+H$6)/($B7-H$6)/(1+$B7)^('DCF Model'!C19+4)-'DCF Model'!C16)*1000000/'DCF Model'!C15,0),"") | I7: =IFERROR(ROUND(('DCF Model'!C45/(1+$B7)^('DCF Model'!C19+0)+'DCF Model'!D45/(1+$B7)^('DCF Model'!C19+1)+'DCF Model'!E45/(1+$B7)^('DCF Model'!C19+2)+'DCF Model'!F45/(1+$B7)^('DCF Model'!C19+3)+'DCF Model'!G45/(1+$B7)^('DCF Model'!C19+4)+'DCF Model'!G45*(1+I$6)/($B7-I$6)/(1+$B7)^('DCF Model'!C19+4)-'DCF Model'!C16)*1000000/'DCF Model'!C15,0),"")
B8: =$C$3-0.01 | C8: =IFERROR(ROUND(('DCF Model'!C45/(1+$B8)^('DCF Model'!C19+0)+'DCF Model'!D45/(1+$B8)^('DCF Model'!C19+1)+'DCF Model'!E45/(1+$B8)^('DCF Model'!C19+2)+'DCF Model'!F45/(1+$B8)^('DCF Model'!C19+3)+'DCF Model'!G45/(1+$B8)^('DCF Model'!C19+4)+'DCF Model'!G45*(1+C$6)/($B8-C$6)/(1+$B8)^('DCF Model'!C19+4)-'DCF Model'!C16)*1000000/'DCF Model'!C15,0),"") | D8: =IFERROR(ROUND(('DCF Model'!C45/(1+$B8)^('DCF Model'!C19+0)+'DCF Model'!D45/(1+$B8)^('DCF Model'!C19+1)+'DCF Model'!E45/(1+$B8)^('DCF Model'!C19+2)+'DCF Model'!F45/(1+$B8)^('DCF Model'!C19+3)+'DCF Model'!G45/(1+$B8)^('DCF Model'!C19+4)+'DCF Model'!G45*(1+D$6)/($B8-D$6)/(1+$B8)^('DCF Model'!C19+4)-'DCF Model'!C16)*1000000/'DCF Model'!C15,0),"") | E8: =IFERROR(ROUND(('DCF Model'!C45/(1+$B8)^('DCF Model'!C19+0)+'DCF Model'!D45/(1+$B8)^('DCF Model'!C19+1)+'DCF Model'!E45/(1+$B8)^('DCF Model'!C19+2)+'DCF Model'!F45/(1+$B8)^('DCF Model'!C19+3)+'DCF Model'!G45/(1+$B8)^('DCF Model'!C19+4)+'DCF Model'!G45*(1+E$6)/($B8-E$6)/(1+$B8)^('DCF Model'!C19+4)-'DCF Model'!C16)*1000000/'DCF Model'!C15,0),"") | F8: =IFERROR(ROUND(('DCF Model'!C45/(1+$B8)^('DCF Model'!C19+0)+'DCF Model'!D45/(1+$B8)^('DCF Model'!C19+1)+'DCF Model'!E45/(1+$B8)^('DCF Model'!C19+2)+'DCF Model'!F45/(1+$B8)^('DCF Model'!C19+3)+'DCF Model'!G45/(1+$B8)^('DCF Model'!C19+4)+'DCF Model'!G45*(1+F$6)/($B8-F$6)/(1+$B8)^('DCF Model'!C19+4)-'DCF Model'!C16)*1000000/'DCF Model'!C15,0),"") | G8: =IFERROR(ROUND(('DCF Model'!C45/(1+$B8)^('DCF Model'!C19+0)+'DCF Model'!D45/(1+$B8)^('DCF Model'!C19+1)+'DCF Model'!E45/(1+$B8)^('DCF Model'!C19+2)+'DCF Model'!F45/(1+$B8)^('DCF Model'!C19+3)+'DCF Model'!G45/(1+$B8)^('DCF Model'!C19+4)+'DCF Model'!G45*(1+G$6)/($B8-G$6)/(1+$B8)^('DCF Model'!C19+4)-'DCF Model'!C16)*1000000/'DCF Model'!C15,0),"") | H8: =IFERROR(ROUND(('DCF Model'!C45/(1+$B8)^('DCF Model'!C19+0)+'DCF Model'!D45/(1+$B8)^('DCF Model'!C19+1)+'DCF Model'!E45/(1+$B8)^('DCF Model'!C19+2)+'DCF Model'!F45/(1+$B8)^('DCF Model'!C19+3)+'DCF Model'!G45/(1+$B8)^('DCF Model'!C19+4)+'DCF Model'!G45*(1+H$6)/($B8-H$6)/(1+$B8)^('DCF Model'!C19+4)-'DCF Model'!C16)*1000000/'DCF Model'!C15,0),"") | I8: =IFERROR(ROUND(('DCF Model'!C45/(1+$B8)^('DCF Model'!C19+0)+'DCF Model'!D45/(1+$B8)^('DCF Model'!C19+1)+'DCF Model'!E45/(1+$B8)^('DCF Model'!C19+2)+'DCF Model'!F45/(1+$B8)^('DCF Model'!C19+3)+'DCF Model'!G45/(1+$B8)^('DCF Model'!C19+4)+'DCF Model'!G45*(1+I$6)/($B8-I$6)/(1+$B8)^('DCF Model'!C19+4)-'DCF Model'!C16)*1000000/'DCF Model'!C15,0),"")
B9: =$C$3-0.005 | C9: =IFERROR(ROUND(('DCF Model'!C45/(1+$B9)^('DCF Model'!C19+0)+'DCF Model'!D45/(1+$B9)^('DCF Model'!C19+1)+'DCF Model'!E45/(1+$B9)^('DCF Model'!C19+2)+'DCF Model'!F45/(1+$B9)^('DCF Model'!C19+3)+'DCF Model'!G45/(1+$B9)^('DCF Model'!C19+4)+'DCF Model'!G45*(1+C$6)/($B9-C$6)/(1+$B9)^('DCF Model'!C19+4)-'DCF Model'!C16)*1000000/'DCF Model'!C15,0),"") | D9: =IFERROR(ROUND(('DCF Model'!C45/(1+$B9)^('DCF Model'!C19+0)+'DCF Model'!D45/(1+$B9)^('DCF Model'!C19+1)+'DCF Model'!E45/(1+$B9)^('DCF Model'!C19+2)+'DCF Model'!F45/(1+$B9)^('DCF Model'!C19+3)+'DCF Model'!G45/(1+$B9)^('DCF Model'!C19+4)+'DCF Model'!G45*(1+D$6)/($B9-D$6)/(1+$B9)^('DCF Model'!C19+4)-'DCF Model'!C16)*1000000/'DCF Model'!C15,0),"") | E9: =IFERROR(ROUND(('DCF Model'!C45/(1+$B9)^('DCF Model'!C19+0)+'DCF Model'!D45/(1+$B9)^('DCF Model'!C19+1)+'DCF Model'!E45/(1+$B9)^('DCF Model'!C19+2)+'DCF Model'!F45/(1+$B9)^('DCF Model'!C19+3)+'DCF Model'!G45/(1+$B9)^('DCF Model'!C19+4)+'DCF Model'!G45*(1+E$6)/($B9-E$6)/(1+$B9)^('DCF Model'!C19+4)-'DCF Model'!C16)*1000000/'DCF Model'!C15,0),"") | F9: =IFERROR(ROUND(('DCF Model'!C45/(1+$B9)^('DCF Model'!C19+0)+'DCF Model'!D45/(1+$B9)^('DCF Model'!C19+1)+'DCF Model'!E45/(1+$B9)^('DCF Model'!C19+2)+'DCF Model'!F45/(1+$B9)^('DCF Model'!C19+3)+'DCF Model'!G45/(1+$B9)^('DCF Model'!C19+4)+'DCF Model'!G45*(1+F$6)/($B9-F$6)/(1+$B9)^('DCF Model'!C19+4)-'DCF Model'!C16)*1000000/'DCF Model'!C15,0),"") | G9: =IFERROR(ROUND(('DCF Model'!C45/(1+$B9)^('DCF Model'!C19+0)+'DCF Model'!D45/(1+$B9)^('DCF Model'!C19+1)+'DCF Model'!E45/(1+$B9)^('DCF Model'!C19+2)+'DCF Model'!F45/(1+$B9)^('DCF Model'!C19+3)+'DCF Model'!G45/(1+$B9)^('DCF Model'!C19+4)+'DCF Model'!G45*(1+G$6)/($B9-G$6)/(1+$B9)^('DCF Model'!C19+4)-'DCF Model'!C16)*1000000/'DCF Model'!C15,0),"") | H9: =IFERROR(ROUND(('DCF Model'!C45/(1+$B9)^('DCF Model'!C19+0)+'DCF Model'!D45/(1+$B9)^('DCF Model'!C19+1)+'DCF Model'!E45/(1+$B9)^('DCF Model'!C19+2)+'DCF Model'!F45/(1+$B9)^('DCF Model'!C19+3)+'DCF Model'!G45/(1+$B9)^('DCF Model'!C19+4)+'DCF Model'!G45*(1+H$6)/($B9-H$6)/(1+$B9)^('DCF Model'!C19+4)-'DCF Model'!C16)*1000000/'DCF Model'!C15,0),"") | I9: =IFERROR(ROUND(('DCF Model'!C45/(1+$B9)^('DCF Model'!C19+0)+'DCF Model'!D45/(1+$B9)^('DCF Model'!C19+1)+'DCF Model'!E45/(1+$B9)^('DCF Model'!C19+2)+'DCF Model'!F45/(1+$B9)^('DCF Model'!C19+3)+'DCF Model'!G45/(1+$B9)^('DCF Model'!C19+4)+'DCF Model'!G45*(1+I$6)/($B9-I$6)/(1+$B9)^('DCF Model'!C19+4)-'DCF Model'!C16)*1000000/'DCF Model'!C15,0),"")
B10: =$C$3 | C10: =IFERROR(ROUND(('DCF Model'!C45/(1+$B10)^('DCF Model'!C19+0)+'DCF Model'!D45/(1+$B10)^('DCF Model'!C19+1)+'DCF Model'!E45/(1+$B10)^('DCF Model'!C19+2)+'DCF Model'!F45/(1+$B10)^('DCF Model'!C19+3)+'DCF Model'!G45/(1+$B10)^('DCF Model'!C19+4)+'DCF Model'!G45*(1+C$6)/($B10-C$6)/(1+$B10)^('DCF Model'!C19+4)-'DCF Model'!C16)*1000000/'DCF Model'!C15,0),"") | D10: =IFERROR(ROUND(('DCF Model'!C45/(1+$B10)^('DCF Model'!C19+0)+'DCF Model'!D45/(1+$B10)^('DCF Model'!C19+1)+'DCF Model'!E45/(1+$B10)^('DCF Model'!C19+2)+'DCF Model'!F45/(1+$B10)^('DCF Model'!C19+3)+'DCF Model'!G45/(1+$B10)^('DCF Model'!C19+4)+'DCF Model'!G45*(1+D$6)/($B10-D$6)/(1+$B10)^('DCF Model'!C19+4)-'DCF Model'!C16)*1000000/'DCF Model'!C15,0),"") | E10: =IFERROR(ROUND(('DCF Model'!C45/(1+$B10)^('DCF Model'!C19+0)+'DCF Model'!D45/(1+$B10)^('DCF Model'!C19+1)+'DCF Model'!E45/(1+$B10)^('DCF Model'!C19+2)+'DCF Model'!F45/(1+$B10)^('DCF Model'!C19+3)+'DCF Model'!G45/(1+$B10)^('DCF Model'!C19+4)+'DCF Model'!G45*(1+E$6)/($B10-E$6)/(1+$B10)^('DCF Model'!C19+4)-'DCF Model'!C16)*1000000/'DCF Model'!C15,0),"") | F10: =IFERROR(ROUND(('DCF Model'!C45/(1+$B10)^('DCF Model'!C19+0)+'DCF Model'!D45/(1+$B10)^('DCF Model'!C19+1)+'DCF Model'!E45/(1+$B10)^('DCF Model'!C19+2)+'DCF Model'!F45/(1+$B10)^('DCF Model'!C19+3)+'DCF Model'!G45/(1+$B10)^('DCF Model'!C19+4)+'DCF Model'!G45*(1+F$6)/($B10-F$6)/(1+$B10)^('DCF Model'!C19+4)-'DCF Model'!C16)*1000000/'DCF Model'!C15,0),"") | G10: =IFERROR(ROUND(('DCF Model'!C45/(1+$B10)^('DCF Model'!C19+0)+'DCF Model'!D45/(1+$B10)^('DCF Model'!C19+1)+'DCF Model'!E45/(1+$B10)^('DCF Model'!C19+2)+'DCF Model'!F45/(1+$B10)^('DCF Model'!C19+3)+'DCF Model'!G45/(1+$B10)^('DCF Model'!C19+4)+'DCF Model'!G45*(1+G$6)/($B10-G$6)/(1+$B10)^('DCF Model'!C19+4)-'DCF Model'!C16)*1000000/'DCF Model'!C15,0),"") | H10: =IFERROR(ROUND(('DCF Model'!C45/(1+$B10)^('DCF Model'!C19+0)+'DCF Model'!D45/(1+$B10)^('DCF Model'!C19+1)+'DCF Model'!E45/(1+$B10)^('DCF Model'!C19+2)+'DCF Model'!F45/(1+$B10)^('DCF Model'!C19+3)+'DCF Model'!G45/(1+$B10)^('DCF Model'!C19+4)+'DCF Model'!G45*(1+H$6)/($B10-H$6)/(1+$B10)^('DCF Model'!C19+4)-'DCF Model'!C16)*1000000/'DCF Model'!C15,0),"") | I10: =IFERROR(ROUND(('DCF Model'!C45/(1+$B10)^('DCF Model'!C19+0)+'DCF Model'!D45/(1+$B10)^('DCF Model'!C19+1)+'DCF Model'!E45/(1+$B10)^('DCF Model'!C19+2)+'DCF Model'!F45/(1+$B10)^('DCF Model'!C19+3)+'DCF Model'!G45/(1+$B10)^('DCF Model'!C19+4)+'DCF Model'!G45*(1+I$6)/($B10-I$6)/(1+$B10)^('DCF Model'!C19+4)-'DCF Model'!C16)*1000000/'DCF Model'!C15,0),"")
B11: =$C$3+0.005 | C11: =IFERROR(ROUND(('DCF Model'!C45/(1+$B11)^('DCF Model'!C19+0)+'DCF Model'!D45/(1+$B11)^('DCF Model'!C19+1)+'DCF Model'!E45/(1+$B11)^('DCF Model'!C19+2)+'DCF Model'!F45/(1+$B11)^('DCF Model'!C19+3)+'DCF Model'!G45/(1+$B11)^('DCF Model'!C19+4)+'DCF Model'!G45*(1+C$6)/($B11-C$6)/(1+$B11)^('DCF Model'!C19+4)-'DCF Model'!C16)*1000000/'DCF Model'!C15,0),"") | D11: =IFERROR(ROUND(('DCF Model'!C45/(1+$B11)^('DCF Model'!C19+0)+'DCF Model'!D45/(1+$B11)^('DCF Model'!C19+1)+'DCF Model'!E45/(1+$B11)^('DCF Model'!C19+2)+'DCF Model'!F45/(1+$B11)^('DCF Model'!C19+3)+'DCF Model'!G45/(1+$B11)^('DCF Model'!C19+4)+'DCF Model'!G45*(1+D$6)/($B11-D$6)/(1+$B11)^('DCF Model'!C19+4)-'DCF Model'!C16)*1000000/'DCF Model'!C15,0),"") | E11: =IFERROR(ROUND(('DCF Model'!C45/(1+$B11)^('DCF Model'!C19+0)+'DCF Model'!D45/(1+$B11)^('DCF Model'!C19+1)+'DCF Model'!E45/(1+$B11)^('DCF Model'!C19+2)+'DCF Model'!F45/(1+$B11)^('DCF Model'!C19+3)+'DCF Model'!G45/(1+$B11)^('DCF Model'!C19+4)+'DCF Model'!G45*(1+E$6)/($B11-E$6)/(1+$B11)^('DCF Model'!C19+4)-'DCF Model'!C16)*1000000/'DCF Model'!C15,0),"") | F11: =IFERROR(ROUND(('DCF Model'!C45/(1+$B11)^('DCF Model'!C19+0)+'DCF Model'!D45/(1+$B11)^('DCF Model'!C19+1)+'DCF Model'!E45/(1+$B11)^('DCF Model'!C19+2)+'DCF Model'!F45/(1+$B11)^('DCF Model'!C19+3)+'DCF Model'!G45/(1+$B11)^('DCF Model'!C19+4)+'DCF Model'!G45*(1+F$6)/($B11-F$6)/(1+$B11)^('DCF Model'!C19+4)-'DCF Model'!C16)*1000000/'DCF Model'!C15,0),"") | G11: =IFERROR(ROUND(('DCF Model'!C45/(1+$B11)^('DCF Model'!C19+0)+'DCF Model'!D45/(1+$B11)^('DCF Model'!C19+1)+'DCF Model'!E45/(1+$B11)^('DCF Model'!C19+2)+'DCF Model'!F45/(1+$B11)^('DCF Model'!C19+3)+'DCF Model'!G45/(1+$B11)^('DCF Model'!C19+4)+'DCF Model'!G45*(1+G$6)/($B11-G$6)/(1+$B11)^('DCF Model'!C19+4)-'DCF Model'!C16)*1000000/'DCF Model'!C15,0),"") | H11: =IFERROR(ROUND(('DCF Model'!C45/(1+$B11)^('DCF Model'!C19+0)+'DCF Model'!D45/(1+$B11)^('DCF Model'!C19+1)+'DCF Model'!E45/(1+$B11)^('DCF Model'!C19+2)+'DCF Model'!F45/(1+$B11)^('DCF Model'!C19+3)+'DCF Model'!G45/(1+$B11)^('DCF Model'!C19+4)+'DCF Model'!G45*(1+H$6)/($B11-H$6)/(1+$B11)^('DCF Model'!C19+4)-'DCF Model'!C16)*1000000/'DCF Model'!C15,0),"") | I11: =IFERROR(ROUND(('DCF Model'!C45/(1+$B11)^('DCF Model'!C19+0)+'DCF Model'!D45/(1+$B11)^('DCF Model'!C19+1)+'DCF Model'!E45/(1+$B11)^('DCF Model'!C19+2)+'DCF Model'!F45/(1+$B11)^('DCF Model'!C19+3)+'DCF Model'!G45/(1+$B11)^('DCF Model'!C19+4)+'DCF Model'!G45*(1+I$6)/($B11-I$6)/(1+$B11)^('DCF Model'!C19+4)-'DCF Model'!C16)*1000000/'DCF Model'!C15,0),"")
B12: =$C$3+0.01 | C12: =IFERROR(ROUND(('DCF Model'!C45/(1+$B12)^('DCF Model'!C19+0)+'DCF Model'!D45/(1+$B12)^('DCF Model'!C19+1)+'DCF Model'!E45/(1+$B12)^('DCF Model'!C19+2)+'DCF Model'!F45/(1+$B12)^('DCF Model'!C19+3)+'DCF Model'!G45/(1+$B12)^('DCF Model'!C19+4)+'DCF Model'!G45*(1+C$6)/($B12-C$6)/(1+$B12)^('DCF Model'!C19+4)-'DCF Model'!C16)*1000000/'DCF Model'!C15,0),"") | D12: =IFERROR(ROUND(('DCF Model'!C45/(1+$B12)^('DCF Model'!C19+0)+'DCF Model'!D45/(1+$B12)^('DCF Model'!C19+1)+'DCF Model'!E45/(1+$B12)^('DCF Model'!C19+2)+'DCF Model'!F45/(1+$B12)^('DCF Model'!C19+3)+'DCF Model'!G45/(1+$B12)^('DCF Model'!C19+4)+'DCF Model'!G45*(1+D$6)/($B12-D$6)/(1+$B12)^('DCF Model'!C19+4)-'DCF Model'!C16)*1000000/'DCF Model'!C15,0),"") | E12: =IFERROR(ROUND(('DCF Model'!C45/(1+$B12)^('DCF Model'!C19+0)+'DCF Model'!D45/(1+$B12)^('DCF Model'!C19+1)+'DCF Model'!E45/(1+$B12)^('DCF Model'!C19+2)+'DCF Model'!F45/(1+$B12)^('DCF Model'!C19+3)+'DCF Model'!G45/(1+$B12)^('DCF Model'!C19+4)+'DCF Model'!G45*(1+E$6)/($B12-E$6)/(1+$B12)^('DCF Model'!C19+4)-'DCF Model'!C16)*1000000/'DCF Model'!C15,0),"") | F12: =IFERROR(ROUND(('DCF Model'!C45/(1+$B12)^('DCF Model'!C19+0)+'DCF Model'!D45/(1+$B12)^('DCF Model'!C19+1)+'DCF Model'!E45/(1+$B12)^('DCF Model'!C19+2)+'DCF Model'!F45/(1+$B12)^('DCF Model'!C19+3)+'DCF Model'!G45/(1+$B12)^('DCF Model'!C19+4)+'DCF Model'!G45*(1+F$6)/($B12-F$6)/(1+$B12)^('DCF Model'!C19+4)-'DCF Model'!C16)*1000000/'DCF Model'!C15,0),"") | G12: =IFERROR(ROUND(('DCF Model'!C45/(1+$B12)^('DCF Model'!C19+0)+'DCF Model'!D45/(1+$B12)^('DCF Model'!C19+1)+'DCF Model'!E45/(1+$B12)^('DCF Model'!C19+2)+'DCF Model'!F45/(1+$B12)^('DCF Model'!C19+3)+'DCF Model'!G45/(1+$B12)^('DCF Model'!C19+4)+'DCF Model'!G45*(1+G$6)/($B12-G$6)/(1+$B12)^('DCF Model'!C19+4)-'DCF Model'!C16)*1000000/'DCF Model'!C15,0),"") | H12: =IFERROR(ROUND(('DCF Model'!C45/(1+$B12)^('DCF Model'!C19+0)+'DCF Model'!D45/(1+$B12)^('DCF Model'!C19+1)+'DCF Model'!E45/(1+$B12)^('DCF Model'!C19+2)+'DCF Model'!F45/(1+$B12)^('DCF Model'!C19+3)+'DCF Model'!G45/(1+$B12)^('DCF Model'!C19+4)+'DCF Model'!G45*(1+H$6)/($B12-H$6)/(1+$B12)^('DCF Model'!C19+4)-'DCF Model'!C16)*1000000/'DCF Model'!C15,0),"") | I12: =IFERROR(ROUND(('DCF Model'!C45/(1+$B12)^('DCF Model'!C19+0)+'DCF Model'!D45/(1+$B12)^('DCF Model'!C19+1)+'DCF Model'!E45/(1+$B12)^('DCF Model'!C19+2)+'DCF Model'!F45/(1+$B12)^('DCF Model'!C19+3)+'DCF Model'!G45/(1+$B12)^('DCF Model'!C19+4)+'DCF Model'!G45*(1+I$6)/($B12-I$6)/(1+$B12)^('DCF Model'!C19+4)-'DCF Model'!C16)*1000000/'DCF Model'!C15,0),"")
B13: =$C$3+0.015 | C13: =IFERROR(ROUND(('DCF Model'!C45/(1+$B13)^('DCF Model'!C19+0)+'DCF Model'!D45/(1+$B13)^('DCF Model'!C19+1)+'DCF Model'!E45/(1+$B13)^('DCF Model'!C19+2)+'DCF Model'!F45/(1+$B13)^('DCF Model'!C19+3)+'DCF Model'!G45/(1+$B13)^('DCF Model'!C19+4)+'DCF Model'!G45*(1+C$6)/($B13-C$6)/(1+$B13)^('DCF Model'!C19+4)-'DCF Model'!C16)*1000000/'DCF Model'!C15,0),"") | D13: =IFERROR(ROUND(('DCF Model'!C45/(1+$B13)^('DCF Model'!C19+0)+'DCF Model'!D45/(1+$B13)^('DCF Model'!C19+1)+'DCF Model'!E45/(1+$B13)^('DCF Model'!C19+2)+'DCF Model'!F45/(1+$B13)^('DCF Model'!C19+3)+'DCF Model'!G45/(1+$B13)^('DCF Model'!C19+4)+'DCF Model'!G45*(1+D$6)/($B13-D$6)/(1+$B13)^('DCF Model'!C19+4)-'DCF Model'!C16)*1000000/'DCF Model'!C15,0),"") | E13: =IFERROR(ROUND(('DCF Model'!C45/(1+$B13)^('DCF Model'!C19+0)+'DCF Model'!D45/(1+$B13)^('DCF Model'!C19+1)+'DCF Model'!E45/(1+$B13)^('DCF Model'!C19+2)+'DCF Model'!F45/(1+$B13)^('DCF Model'!C19+3)+'DCF Model'!G45/(1+$B13)^('DCF Model'!C19+4)+'DCF Model'!G45*(1+E$6)/($B13-E$6)/(1+$B13)^('DCF Model'!C19+4)-'DCF Model'!C16)*1000000/'DCF Model'!C15,0),"") | F13: =IFERROR(ROUND(('DCF Model'!C45/(1+$B13)^('DCF Model'!C19+0)+'DCF Model'!D45/(1+$B13)^('DCF Model'!C19+1)+'DCF Model'!E45/(1+$B13)^('DCF Model'!C19+2)+'DCF Model'!F45/(1+$B13)^('DCF Model'!C19+3)+'DCF Model'!G45/(1+$B13)^('DCF Model'!C19+4)+'DCF Model'!G45*(1+F$6)/($B13-F$6)/(1+$B13)^('DCF Model'!C19+4)-'DCF Model'!C16)*1000000/'DCF Model'!C15,0),"") | G13: =IFERROR(ROUND(('DCF Model'!C45/(1+$B13)^('DCF Model'!C19+0)+'DCF Model'!D45/(1+$B13)^('DCF Model'!C19+1)+'DCF Model'!E45/(1+$B13)^('DCF Model'!C19+2)+'DCF Model'!F45/(1+$B13)^('DCF Model'!C19+3)+'DCF Model'!G45/(1+$B13)^('DCF Model'!C19+4)+'DCF Model'!G45*(1+G$6)/($B13-G$6)/(1+$B13)^('DCF Model'!C19+4)-'DCF Model'!C16)*1000000/'DCF Model'!C15,0),"") | H13: =IFERROR(ROUND(('DCF Model'!C45/(1+$B13)^('DCF Model'!C19+0)+'DCF Model'!D45/(1+$B13)^('DCF Model'!C19+1)+'DCF Model'!E45/(1+$B13)^('DCF Model'!C19+2)+'DCF Model'!F45/(1+$B13)^('DCF Model'!C19+3)+'DCF Model'!G45/(1+$B13)^('DCF Model'!C19+4)+'DCF Model'!G45*(1+H$6)/($B13-H$6)/(1+$B13)^('DCF Model'!C19+4)-'DCF Model'!C16)*1000000/'DCF Model'!C15,0),"") | I13: =IFERROR(ROUND(('DCF Model'!C45/(1+$B13)^('DCF Model'!C19+0)+'DCF Model'!D45/(1+$B13)^('DCF Model'!C19+1)+'DCF Model'!E45/(1+$B13)^('DCF Model'!C19+2)+'DCF Model'!F45/(1+$B13)^('DCF Model'!C19+3)+'DCF Model'!G45/(1+$B13)^('DCF Model'!C19+4)+'DCF Model'!G45*(1+I$6)/($B13-I$6)/(1+$B13)^('DCF Model'!C19+4)-'DCF Model'!C16)*1000000/'DCF Model'!C15,0),"")
B16: Table 2: WACC vs Exit Multiple (Exit Multiple - Implied Share Price, JPY)
B17: WACC \ Exit Multiple | C17: =$I$3-3.0 | D17: =$I$3-2.0 | E17: =$I$3-1.0 | F17: =$I$3 | G17: =$I$3+1.0 | H17: =$I$3+2.0 | I17: =$I$3+3.0
B18: =$C$3-0.015 | C18: =IFERROR(ROUND(('DCF Model'!C45/(1+$B18)^('DCF Model'!C19+0)+'DCF Model'!D45/(1+$B18)^('DCF Model'!C19+1)+'DCF Model'!E45/(1+$B18)^('DCF Model'!C19+2)+'DCF Model'!F45/(1+$B18)^('DCF Model'!C19+3)+'DCF Model'!G45/(1+$B18)^('DCF Model'!C19+4)+('DCF Model'!G39+'DCF Model'!G42)*C$17/(1+$B18)^('DCF Model'!C19+4)-'DCF Model'!C16)*1000000/'DCF Model'!C15,0),"") | D18: =IFERROR(ROUND(('DCF Model'!C45/(1+$B18)^('DCF Model'!C19+0)+'DCF Model'!D45/(1+$B18)^('DCF Model'!C19+1)+'DCF Model'!E45/(1+$B18)^('DCF Model'!C19+2)+'DCF Model'!F45/(1+$B18)^('DCF Model'!C19+3)+'DCF Model'!G45/(1+$B18)^('DCF Model'!C19+4)+('DCF Model'!G39+'DCF Model'!G42)*D$17/(1+$B18)^('DCF Model'!C19+4)-'DCF Model'!C16)*1000000/'DCF Model'!C15,0),"") | E18: =IFERROR(ROUND(('DCF Model'!C45/(1+$B18)^('DCF Model'!C19+0)+'DCF Model'!D45/(1+$B18)^('DCF Model'!C19+1)+'DCF Model'!E45/(1+$B18)^('DCF Model'!C19+2)+'DCF Model'!F45/(1+$B18)^('DCF Model'!C19+3)+'DCF Model'!G45/(1+$B18)^('DCF Model'!C19+4)+('DCF Model'!G39+'DCF Model'!G42)*E$17/(1+$B18)^('DCF Model'!C19+4)-'DCF Model'!C16)*1000000/'DCF Model'!C15,0),"") | F18: =IFERROR(ROUND(('DCF Model'!C45/(1+$B18)^('DCF Model'!C19+0)+'DCF Model'!D45/(1+$B18)^('DCF Model'!C19+1)+'DCF Model'!E45/(1+$B18)^('DCF Model'!C19+2)+'DCF Model'!F45/(1+$B18)^('DCF Model'!C19+3)+'DCF Model'!G45/(1+$B18)^('DCF Model'!C19+4)+('DCF Model'!G39+'DCF Model'!G42)*F$17/(1+$B18)^('DCF Model'!C19+4)-'DCF Model'!C16)*1000000/'DCF Model'!C15,0),"") | G18: =IFERROR(ROUND(('DCF Model'!C45/(1+$B18)^('DCF Model'!C19+0)+'DCF Model'!D45/(1+$B18)^('DCF Model'!C19+1)+'DCF Model'!E45/(1+$B18)^('DCF Model'!C19+2)+'DCF Model'!F45/(1+$B18)^('DCF Model'!C19+3)+'DCF Model'!G45/(1+$B18)^('DCF Model'!C19+4)+('DCF Model'!G39+'DCF Model'!G42)*G$17/(1+$B18)^('DCF Model'!C19+4)-'DCF Model'!C16)*1000000/'DCF Model'!C15,0),"") | H18: =IFERROR(ROUND(('DCF Model'!C45/(1+$B18)^('DCF Model'!C19+0)+'DCF Model'!D45/(1+$B18)^('DCF Model'!C19+1)+'DCF Model'!E45/(1+$B18)^('DCF Model'!C19+2)+'DCF Model'!F45/(1+$B18)^('DCF Model'!C19+3)+'DCF Model'!G45/(1+$B18)^('DCF Model'!C19+4)+('DCF Model'!G39+'DCF Model'!G42)*H$17/(1+$B18)^('DCF Model'!C19+4)-'DCF Model'!C16)*1000000/'DCF Model'!C15,0),"") | I18: =IFERROR(ROUND(('DCF Model'!C45/(1+$B18)^('DCF Model'!C19+0)+'DCF Model'!D45/(1+$B18)^('DCF Model'!C19+1)+'DCF Model'!E45/(1+$B18)^('DCF Model'!C19+2)+'DCF Model'!F45/(1+$B18)^('DCF Model'!C19+3)+'DCF Model'!G45/(1+$B18)^('DCF Model'!C19+4)+('DCF Model'!G39+'DCF Model'!G42)*I$17/(1+$B18)^('DCF Model'!C19+4)-'DCF Model'!C16)*1000000/'DCF Model'!C15,0),"")
B19: =$C$3-0.01 | C19: =IFERROR(ROUND(('DCF Model'!C45/(1+$B19)^('DCF Model'!C19+0)+'DCF Model'!D45/(1+$B19)^('DCF Model'!C19+1)+'DCF Model'!E45/(1+$B19)^('DCF Model'!C19+2)+'DCF Model'!F45/(1+$B19)^('DCF Model'!C19+3)+'DCF Model'!G45/(1+$B19)^('DCF Model'!C19+4)+('DCF Model'!G39+'DCF Model'!G42)*C$17/(1+$B19)^('DCF Model'!C19+4)-'DCF Model'!C16)*1000000/'DCF Model'!C15,0),"") | D19: =IFERROR(ROUND(('DCF Model'!C45/(1+$B19)^('DCF Model'!C19+0)+'DCF Model'!D45/(1+$B19)^('DCF Model'!C19+1)+'DCF Model'!E45/(1+$B19)^('DCF Model'!C19+2)+'DCF Model'!F45/(1+$B19)^('DCF Model'!C19+3)+'DCF Model'!G45/(1+$B19)^('DCF Model'!C19+4)+('DCF Model'!G39+'DCF Model'!G42)*D$17/(1+$B19)^('DCF Model'!C19+4)-'DCF Model'!C16)*1000000/'DCF Model'!C15,0),"") | E19: =IFERROR(ROUND(('DCF Model'!C45/(1+$B19)^('DCF Model'!C19+0)+'DCF Model'!D45/(1+$B19)^('DCF Model'!C19+1)+'DCF Model'!E45/(1+$B19)^('DCF Model'!C19+2)+'DCF Model'!F45/(1+$B19)^('DCF Model'!C19+3)+'DCF Model'!G45/(1+$B19)^('DCF Model'!C19+4)+('DCF Model'!G39+'DCF Model'!G42)*E$17/(1+$B19)^('DCF Model'!C19+4)-'DCF Model'!C16)*1000000/'DCF Model'!C15,0),"") | F19: =IFERROR(ROUND(('DCF Model'!C45/(1+$B19)^('DCF Model'!C19+0)+'DCF Model'!D45/(1+$B19)^('DCF Model'!C19+1)+'DCF Model'!E45/(1+$B19)^('DCF Model'!C19+2)+'DCF Model'!F45/(1+$B19)^('DCF Model'!C19+3)+'DCF Model'!G45/(1+$B19)^('DCF Model'!C19+4)+('DCF Model'!G39+'DCF Model'!G42)*F$17/(1+$B19)^('DCF Model'!C19+4)-'DCF Model'!C16)*1000000/'DCF Model'!C15,0),"") | G19: =IFERROR(ROUND(('DCF Model'!C45/(1+$B19)^('DCF Model'!C19+0)+'DCF Model'!D45/(1+$B19)^('DCF Model'!C19+1)+'DCF Model'!E45/(1+$B19)^('DCF Model'!C19+2)+'DCF Model'!F45/(1+$B19)^('DCF Model'!C19+3)+'DCF Model'!G45/(1+$B19)^('DCF Model'!C19+4)+('DCF Model'!G39+'DCF Model'!G42)*G$17/(1+$B19)^('DCF Model'!C19+4)-'DCF Model'!C16)*1000000/'DCF Model'!C15,0),"") | H19: =IFERROR(ROUND(('DCF Model'!C45/(1+$B19)^('DCF Model'!C19+0)+'DCF Model'!D45/(1+$B19)^('DCF Model'!C19+1)+'DCF Model'!E45/(1+$B19)^('DCF Model'!C19+2)+'DCF Model'!F45/(1+$B19)^('DCF Model'!C19+3)+'DCF Model'!G45/(1+$B19)^('DCF Model'!C19+4)+('DCF Model'!G39+'DCF Model'!G42)*H$17/(1+$B19)^('DCF Model'!C19+4)-'DCF Model'!C16)*1000000/'DCF Model'!C15,0),"") | I19: =IFERROR(ROUND(('DCF Model'!C45/(1+$B19)^('DCF Model'!C19+0)+'DCF Model'!D45/(1+$B19)^('DCF Model'!C19+1)+'DCF Model'!E45/(1+$B19)^('DCF Model'!C19+2)+'DCF Model'!F45/(1+$B19)^('DCF Model'!C19+3)+'DCF Model'!G45/(1+$B19)^('DCF Model'!C19+4)+('DCF Model'!G39+'DCF Model'!G42)*I$17/(1+$B19)^('DCF Model'!C19+4)-'DCF Model'!C16)*1000000/'DCF Model'!C15,0),"")
B20: =$C$3-0.005 | C20: =IFERROR(ROUND(('DCF Model'!C45/(1+$B20)^('DCF Model'!C19+0)+'DCF Model'!D45/(1+$B20)^('DCF Model'!C19+1)+'DCF Model'!E45/(1+$B20)^('DCF Model'!C19+2)+'DCF Model'!F45/(1+$B20)^('DCF Model'!C19+3)+'DCF Model'!G45/(1+$B20)^('DCF Model'!C19+4)+('DCF Model'!G39+'DCF Model'!G42)*C$17/(1+$B20)^('DCF Model'!C19+4)-'DCF Model'!C16)*1000000/'DCF Model'!C15,0),"") | D20: =IFERROR(ROUND(('DCF Model'!C45/(1+$B20)^('DCF Model'!C19+0)+'DCF Model'!D45/(1+$B20)^('DCF Model'!C19+1)+'DCF Model'!E45/(1+$B20)^('DCF Model'!C19+2)+'DCF Model'!F45/(1+$B20)^('DCF Model'!C19+3)+'DCF Model'!G45/(1+$B20)^('DCF Model'!C19+4)+('DCF Model'!G39+'DCF Model'!G42)*D$17/(1+$B20)^('DCF Model'!C19+4)-'DCF Model'!C16)*1000000/'DCF Model'!C15,0),"") | E20: =IFERROR(ROUND(('DCF Model'!C45/(1+$B20)^('DCF Model'!C19+0)+'DCF Model'!D45/(1+$B20)^('DCF Model'!C19+1)+'DCF Model'!E45/(1+$B20)^('DCF Model'!C19+2)+'DCF Model'!F45/(1+$B20)^('DCF Model'!C19+3)+'DCF Model'!G45/(1+$B20)^('DCF Model'!C19+4)+('DCF Model'!G39+'DCF Model'!G42)*E$17/(1+$B20)^('DCF Model'!C19+4)-'DCF Model'!C16)*1000000/'DCF Model'!C15,0),"") | F20: =IFERROR(ROUND(('DCF Model'!C45/(1+$B20)^('DCF Model'!C19+0)+'DCF Model'!D45/(1+$B20)^('DCF Model'!C19+1)+'DCF Model'!E45/(1+$B20)^('DCF Model'!C19+2)+'DCF Model'!F45/(1+$B20)^('DCF Model'!C19+3)+'DCF Model'!G45/(1+$B20)^('DCF Model'!C19+4)+('DCF Model'!G39+'DCF Model'!G42)*F$17/(1+$B20)^('DCF Model'!C19+4)-'DCF Model'!C16)*1000000/'DCF Model'!C15,0),"") | G20: =IFERROR(ROUND(('DCF Model'!C45/(1+$B20)^('DCF Model'!C19+0)+'DCF Model'!D45/(1+$B20)^('DCF Model'!C19+1)+'DCF Model'!E45/(1+$B20)^('DCF Model'!C19+2)+'DCF Model'!F45/(1+$B20)^('DCF Model'!C19+3)+'DCF Model'!G45/(1+$B20)^('DCF Model'!C19+4)+('DCF Model'!G39+'DCF Model'!G42)*G$17/(1+$B20)^('DCF Model'!C19+4)-'DCF Model'!C16)*1000000/'DCF Model'!C15,0),"") | H20: =IFERROR(ROUND(('DCF Model'!C45/(1+$B20)^('DCF Model'!C19+0)+'DCF Model'!D45/(1+$B20)^('DCF Model'!C19+1)+'DCF Model'!E45/(1+$B20)^('DCF Model'!C19+2)+'DCF Model'!F45/(1+$B20)^('DCF Model'!C19+3)+'DCF Model'!G45/(1+$B20)^('DCF Model'!C19+4)+('DCF Model'!G39+'DCF Model'!G42)*H$17/(1+$B20)^('DCF Model'!C19+4)-'DCF Model'!C16)*1000000/'DCF Model'!C15,0),"") | I20: =IFERROR(ROUND(('DCF Model'!C45/(1+$B20)^('DCF Model'!C19+0)+'DCF Model'!D45/(1+$B20)^('DCF Model'!C19+1)+'DCF Model'!E45/(1+$B20)^('DCF Model'!C19+2)+'DCF Model'!F45/(1+$B20)^('DCF Model'!C19+3)+'DCF Model'!G45/(1+$B20)^('DCF Model'!C19+4)+('DCF Model'!G39+'DCF Model'!G42)*I$17/(1+$B20)^('DCF Model'!C19+4)-'DCF Model'!C16)*1000000/'DCF Model'!C15,0),"")
B21: =$C$3 | C21: =IFERROR(ROUND(('DCF Model'!C45/(1+$B21)^('DCF Model'!C19+0)+'DCF Model'!D45/(1+$B21)^('DCF Model'!C19+1)+'DCF Model'!E45/(1+$B21)^('DCF Model'!C19+2)+'DCF Model'!F45/(1+$B21)^('DCF Model'!C19+3)+'DCF Model'!G45/(1+$B21)^('DCF Model'!C19+4)+('DCF Model'!G39+'DCF Model'!G42)*C$17/(1+$B21)^('DCF Model'!C19+4)-'DCF Model'!C16)*1000000/'DCF Model'!C15,0),"") | D21: =IFERROR(ROUND(('DCF Model'!C45/(1+$B21)^('DCF Model'!C19+0)+'DCF Model'!D45/(1+$B21)^('DCF Model'!C19+1)+'DCF Model'!E45/(1+$B21)^('DCF Model'!C19+2)+'DCF Model'!F45/(1+$B21)^('DCF Model'!C19+3)+'DCF Model'!G45/(1+$B21)^('DCF Model'!C19+4)+('DCF Model'!G39+'DCF Model'!G42)*D$17/(1+$B21)^('DCF Model'!C19+4)-'DCF Model'!C16)*1000000/'DCF Model'!C15,0),"") | E21: =IFERROR(ROUND(('DCF Model'!C45/(1+$B21)^('DCF Model'!C19+0)+'DCF Model'!D45/(1+$B21)^('DCF Model'!C19+1)+'DCF Model'!E45/(1+$B21)^('DCF Model'!C19+2)+'DCF Model'!F45/(1+$B21)^('DCF Model'!C19+3)+'DCF Model'!G45/(1+$B21)^('DCF Model'!C19+4)+('DCF Model'!G39+'DCF Model'!G42)*E$17/(1+$B21)^('DCF Model'!C19+4)-'DCF Model'!C16)*1000000/'DCF Model'!C15,0),"") | F21: =IFERROR(ROUND(('DCF Model'!C45/(1+$B21)^('DCF Model'!C19+0)+'DCF Model'!D45/(1+$B21)^('DCF Model'!C19+1)+'DCF Model'!E45/(1+$B21)^('DCF Model'!C19+2)+'DCF Model'!F45/(1+$B21)^('DCF Model'!C19+3)+'DCF Model'!G45/(1+$B21)^('DCF Model'!C19+4)+('DCF Model'!G39+'DCF Model'!G42)*F$17/(1+$B21)^('DCF Model'!C19+4)-'DCF Model'!C16)*1000000/'DCF Model'!C15,0),"") | G21: =IFERROR(ROUND(('DCF Model'!C45/(1+$B21)^('DCF Model'!C19+0)+'DCF Model'!D45/(1+$B21)^('DCF Model'!C19+1)+'DCF Model'!E45/(1+$B21)^('DCF Model'!C19+2)+'DCF Model'!F45/(1+$B21)^('DCF Model'!C19+3)+'DCF Model'!G45/(1+$B21)^('DCF Model'!C19+4)+('DCF Model'!G39+'DCF Model'!G42)*G$17/(1+$B21)^('DCF Model'!C19+4)-'DCF Model'!C16)*1000000/'DCF Model'!C15,0),"") | H21: =IFERROR(ROUND(('DCF Model'!C45/(1+$B21)^('DCF Model'!C19+0)+'DCF Model'!D45/(1+$B21)^('DCF Model'!C19+1)+'DCF Model'!E45/(1+$B21)^('DCF Model'!C19+2)+'DCF Model'!F45/(1+$B21)^('DCF Model'!C19+3)+'DCF Model'!G45/(1+$B21)^('DCF Model'!C19+4)+('DCF Model'!G39+'DCF Model'!G42)*H$17/(1+$B21)^('DCF Model'!C19+4)-'DCF Model'!C16)*1000000/'DCF Model'!C15,0),"") | I21: =IFERROR(ROUND(('DCF Model'!C45/(1+$B21)^('DCF Model'!C19+0)+'DCF Model'!D45/(1+$B21)^('DCF Model'!C19+1)+'DCF Model'!E45/(1+$B21)^('DCF Model'!C19+2)+'DCF Model'!F45/(1+$B21)^('DCF Model'!C19+3)+'DCF Model'!G45/(1+$B21)^('DCF Model'!C19+4)+('DCF Model'!G39+'DCF Model'!G42)*I$17/(1+$B21)^('DCF Model'!C19+4)-'DCF Model'!C16)*1000000/'DCF Model'!C15,0),"")
B22: =$C$3+0.005 | C22: =IFERROR(ROUND(('DCF Model'!C45/(1+$B22)^('DCF Model'!C19+0)+'DCF Model'!D45/(1+$B22)^('DCF Model'!C19+1)+'DCF Model'!E45/(1+$B22)^('DCF Model'!C19+2)+'DCF Model'!F45/(1+$B22)^('DCF Model'!C19+3)+'DCF Model'!G45/(1+$B22)^('DCF Model'!C19+4)+('DCF Model'!G39+'DCF Model'!G42)*C$17/(1+$B22)^('DCF Model'!C19+4)-'DCF Model'!C16)*1000000/'DCF Model'!C15,0),"") | D22: =IFERROR(ROUND(('DCF Model'!C45/(1+$B22)^('DCF Model'!C19+0)+'DCF Model'!D45/(1+$B22)^('DCF Model'!C19+1)+'DCF Model'!E45/(1+$B22)^('DCF Model'!C19+2)+'DCF Model'!F45/(1+$B22)^('DCF Model'!C19+3)+'DCF Model'!G45/(1+$B22)^('DCF Model'!C19+4)+('DCF Model'!G39+'DCF Model'!G42)*D$17/(1+$B22)^('DCF Model'!C19+4)-'DCF Model'!C16)*1000000/'DCF Model'!C15,0),"") | E22: =IFERROR(ROUND(('DCF Model'!C45/(1+$B22)^('DCF Model'!C19+0)+'DCF Model'!D45/(1+$B22)^('DCF Model'!C19+1)+'DCF Model'!E45/(1+$B22)^('DCF Model'!C19+2)+'DCF Model'!F45/(1+$B22)^('DCF Model'!C19+3)+'DCF Model'!G45/(1+$B22)^('DCF Model'!C19+4)+('DCF Model'!G39+'DCF Model'!G42)*E$17/(1+$B22)^('DCF Model'!C19+4)-'DCF Model'!C16)*1000000/'DCF Model'!C15,0),"") | F22: =IFERROR(ROUND(('DCF Model'!C45/(1+$B22)^('DCF Model'!C19+0)+'DCF Model'!D45/(1+$B22)^('DCF Model'!C19+1)+'DCF Model'!E45/(1+$B22)^('DCF Model'!C19+2)+'DCF Model'!F45/(1+$B22)^('DCF Model'!C19+3)+'DCF Model'!G45/(1+$B22)^('DCF Model'!C19+4)+('DCF Model'!G39+'DCF Model'!G42)*F$17/(1+$B22)^('DCF Model'!C19+4)-'DCF Model'!C16)*1000000/'DCF Model'!C15,0),"") | G22: =IFERROR(ROUND(('DCF Model'!C45/(1+$B22)^('DCF Model'!C19+0)+'DCF Model'!D45/(1+$B22)^('DCF Model'!C19+1)+'DCF Model'!E45/(1+$B22)^('DCF Model'!C19+2)+'DCF Model'!F45/(1+$B22)^('DCF Model'!C19+3)+'DCF Model'!G45/(1+$B22)^('DCF Model'!C19+4)+('DCF Model'!G39+'DCF Model'!G42)*G$17/(1+$B22)^('DCF Model'!C19+4)-'DCF Model'!C16)*1000000/'DCF Model'!C15,0),"") | H22: =IFERROR(ROUND(('DCF Model'!C45/(1+$B22)^('DCF Model'!C19+0)+'DCF Model'!D45/(1+$B22)^('DCF Model'!C19+1)+'DCF Model'!E45/(1+$B22)^('DCF Model'!C19+2)+'DCF Model'!F45/(1+$B22)^('DCF Model'!C19+3)+'DCF Model'!G45/(1+$B22)^('DCF Model'!C19+4)+('DCF Model'!G39+'DCF Model'!G42)*H$17/(1+$B22)^('DCF Model'!C19+4)-'DCF Model'!C16)*1000000/'DCF Model'!C15,0),"") | I22: =IFERROR(ROUND(('DCF Model'!C45/(1+$B22)^('DCF Model'!C19+0)+'DCF Model'!D45/(1+$B22)^('DCF Model'!C19+1)+'DCF Model'!E45/(1+$B22)^('DCF Model'!C19+2)+'DCF Model'!F45/(1+$B22)^('DCF Model'!C19+3)+'DCF Model'!G45/(1+$B22)^('DCF Model'!C19+4)+('DCF Model'!G39+'DCF Model'!G42)*I$17/(1+$B22)^('DCF Model'!C19+4)-'DCF Model'!C16)*1000000/'DCF Model'!C15,0),"")
B23: =$C$3+0.01 | C23: =IFERROR(ROUND(('DCF Model'!C45/(1+$B23)^('DCF Model'!C19+0)+'DCF Model'!D45/(1+$B23)^('DCF Model'!C19+1)+'DCF Model'!E45/(1+$B23)^('DCF Model'!C19+2)+'DCF Model'!F45/(1+$B23)^('DCF Model'!C19+3)+'DCF Model'!G45/(1+$B23)^('DCF Model'!C19+4)+('DCF Model'!G39+'DCF Model'!G42)*C$17/(1+$B23)^('DCF Model'!C19+4)-'DCF Model'!C16)*1000000/'DCF Model'!C15,0),"") | D23: =IFERROR(ROUND(('DCF Model'!C45/(1+$B23)^('DCF Model'!C19+0)+'DCF Model'!D45/(1+$B23)^('DCF Model'!C19+1)+'DCF Model'!E45/(1+$B23)^('DCF Model'!C19+2)+'DCF Model'!F45/(1+$B23)^('DCF Model'!C19+3)+'DCF Model'!G45/(1+$B23)^('DCF Model'!C19+4)+('DCF Model'!G39+'DCF Model'!G42)*D$17/(1+$B23)^('DCF Model'!C19+4)-'DCF Model'!C16)*1000000/'DCF Model'!C15,0),"") | E23: =IFERROR(ROUND(('DCF Model'!C45/(1+$B23)^('DCF Model'!C19+0)+'DCF Model'!D45/(1+$B23)^('DCF Model'!C19+1)+'DCF Model'!E45/(1+$B23)^('DCF Model'!C19+2)+'DCF Model'!F45/(1+$B23)^('DCF Model'!C19+3)+'DCF Model'!G45/(1+$B23)^('DCF Model'!C19+4)+('DCF Model'!G39+'DCF Model'!G42)*E$17/(1+$B23)^('DCF Model'!C19+4)-'DCF Model'!C16)*1000000/'DCF Model'!C15,0),"") | F23: =IFERROR(ROUND(('DCF Model'!C45/(1+$B23)^('DCF Model'!C19+0)+'DCF Model'!D45/(1+$B23)^('DCF Model'!C19+1)+'DCF Model'!E45/(1+$B23)^('DCF Model'!C19+2)+'DCF Model'!F45/(1+$B23)^('DCF Model'!C19+3)+'DCF Model'!G45/(1+$B23)^('DCF Model'!C19+4)+('DCF Model'!G39+'DCF Model'!G42)*F$17/(1+$B23)^('DCF Model'!C19+4)-'DCF Model'!C16)*1000000/'DCF Model'!C15,0),"") | G23: =IFERROR(ROUND(('DCF Model'!C45/(1+$B23)^('DCF Model'!C19+0)+'DCF Model'!D45/(1+$B23)^('DCF Model'!C19+1)+'DCF Model'!E45/(1+$B23)^('DCF Model'!C19+2)+'DCF Model'!F45/(1+$B23)^('DCF Model'!C19+3)+'DCF Model'!G45/(1+$B23)^('DCF Model'!C19+4)+('DCF Model'!G39+'DCF Model'!G42)*G$17/(1+$B23)^('DCF Model'!C19+4)-'DCF Model'!C16)*1000000/'DCF Model'!C15,0),"") | H23: =IFERROR(ROUND(('DCF Model'!C45/(1+$B23)^('DCF Model'!C19+0)+'DCF Model'!D45/(1+$B23)^('DCF Model'!C19+1)+'DCF Model'!E45/(1+$B23)^('DCF Model'!C19+2)+'DCF Model'!F45/(1+$B23)^('DCF Model'!C19+3)+'DCF Model'!G45/(1+$B23)^('DCF Model'!C19+4)+('DCF Model'!G39+'DCF Model'!G42)*H$17/(1+$B23)^('DCF Model'!C19+4)-'DCF Model'!C16)*1000000/'DCF Model'!C15,0),"") | I23: =IFERROR(ROUND(('DCF Model'!C45/(1+$B23)^('DCF Model'!C19+0)+'DCF Model'!D45/(1+$B23)^('DCF Model'!C19+1)+'DCF Model'!E45/(1+$B23)^('DCF Model'!C19+2)+'DCF Model'!F45/(1+$B23)^('DCF Model'!C19+3)+'DCF Model'!G45/(1+$B23)^('DCF Model'!C19+4)+('DCF Model'!G39+'DCF Model'!G42)*I$17/(1+$B23)^('DCF Model'!C19+4)-'DCF Model'!C16)*1000000/'DCF Model'!C15,0),"")
B24: =$C$3+0.015 | C24: =IFERROR(ROUND(('DCF Model'!C45/(1+$B24)^('DCF Model'!C19+0)+'DCF Model'!D45/(1+$B24)^('DCF Model'!C19+1)+'DCF Model'!E45/(1+$B24)^('DCF Model'!C19+2)+'DCF Model'!F45/(1+$B24)^('DCF Model'!C19+3)+'DCF Model'!G45/(1+$B24)^('DCF Model'!C19+4)+('DCF Model'!G39+'DCF Model'!G42)*C$17/(1+$B24)^('DCF Model'!C19+4)-'DCF Model'!C16)*1000000/'DCF Model'!C15,0),"") | D24: =IFERROR(ROUND(('DCF Model'!C45/(1+$B24)^('DCF Model'!C19+0)+'DCF Model'!D45/(1+$B24)^('DCF Model'!C19+1)+'DCF Model'!E45/(1+$B24)^('DCF Model'!C19+2)+'DCF Model'!F45/(1+$B24)^('DCF Model'!C19+3)+'DCF Model'!G45/(1+$B24)^('DCF Model'!C19+4)+('DCF Model'!G39+'DCF Model'!G42)*D$17/(1+$B24)^('DCF Model'!C19+4)-'DCF Model'!C16)*1000000/'DCF Model'!C15,0),"") | E24: =IFERROR(ROUND(('DCF Model'!C45/(1+$B24)^('DCF Model'!C19+0)+'DCF Model'!D45/(1+$B24)^('DCF Model'!C19+1)+'DCF Model'!E45/(1+$B24)^('DCF Model'!C19+2)+'DCF Model'!F45/(1+$B24)^('DCF Model'!C19+3)+'DCF Model'!G45/(1+$B24)^('DCF Model'!C19+4)+('DCF Model'!G39+'DCF Model'!G42)*E$17/(1+$B24)^('DCF Model'!C19+4)-'DCF Model'!C16)*1000000/'DCF Model'!C15,0),"") | F24: =IFERROR(ROUND(('DCF Model'!C45/(1+$B24)^('DCF Model'!C19+0)+'DCF Model'!D45/(1+$B24)^('DCF Model'!C19+1)+'DCF Model'!E45/(1+$B24)^('DCF Model'!C19+2)+'DCF Model'!F45/(1+$B24)^('DCF Model'!C19+3)+'DCF Model'!G45/(1+$B24)^('DCF Model'!C19+4)+('DCF Model'!G39+'DCF Model'!G42)*F$17/(1+$B24)^('DCF Model'!C19+4)-'DCF Model'!C16)*1000000/'DCF Model'!C15,0),"") | G24: =IFERROR(ROUND(('DCF Model'!C45/(1+$B24)^('DCF Model'!C19+0)+'DCF Model'!D45/(1+$B24)^('DCF Model'!C19+1)+'DCF Model'!E45/(1+$B24)^('DCF Model'!C19+2)+'DCF Model'!F45/(1+$B24)^('DCF Model'!C19+3)+'DCF Model'!G45/(1+$B24)^('DCF Model'!C19+4)+('DCF Model'!G39+'DCF Model'!G42)*G$17/(1+$B24)^('DCF Model'!C19+4)-'DCF Model'!C16)*1000000/'DCF Model'!C15,0),"") | H24: =IFERROR(ROUND(('DCF Model'!C45/(1+$B24)^('DCF Model'!C19+0)+'DCF Model'!D45/(1+$B24)^('DCF Model'!C19+1)+'DCF Model'!E45/(1+$B24)^('DCF Model'!C19+2)+'DCF Model'!F45/(1+$B24)^('DCF Model'!C19+3)+'DCF Model'!G45/(1+$B24)^('DCF Model'!C19+4)+('DCF Model'!G39+'DCF Model'!G42)*H$17/(1+$B24)^('DCF Model'!C19+4)-'DCF Model'!C16)*1000000/'DCF Model'!C15,0),"") | I24: =IFERROR(ROUND(('DCF Model'!C45/(1+$B24)^('DCF Model'!C19+0)+'DCF Model'!D45/(1+$B24)^('DCF Model'!C19+1)+'DCF Model'!E45/(1+$B24)^('DCF Model'!C19+2)+'DCF Model'!F45/(1+$B24)^('DCF Model'!C19+3)+'DCF Model'!G45/(1+$B24)^('DCF Model'!C19+4)+('DCF Model'!G39+'DCF Model'!G42)*I$17/(1+$B24)^('DCF Model'!C19+4)-'DCF Model'!C16)*1000000/'DCF Model'!C15,0),"")
B26: All values dynamically linked to DCF Model. Headers auto-center on current WACC / Terminal g / Exit Multiple.

Sheet Segment Analysis
B2: Segment Analysis - DMW Corporation
C4: FY2023 | D4: FY2024 | E4: FY2025 | F4: FY2026 | G4: FY2026(E) | H4: FY2027(E) | I4: FY2028(E) | J4: FY2029(E) | K4: FY2030(E)
B5: Public Sector (Pumps & Blowers) (官需部門（ポンプ・送風機）)
B6: Revenue | C6: — | D6: — | E6: — | F6: 12915 | G6: =F6*(1+CHOOSE('DCF Model'!$D$27,G34,G35,G36,G37,G38)) | H6: =G6*(1+CHOOSE('DCF Model'!$D$27,H34,H35,H36,H37,H38)) | I6: =H6*(1+CHOOSE('DCF Model'!$D$27,I34,I35,I36,I37,I38)) | J6: =I6*(1+CHOOSE('DCF Model'!$D$27,J34,J35,J36,J37,J38)) | K6: =J6*(1+CHOOSE('DCF Model'!$D$27,K34,K35,K36,K37,K38))
B7: Operating Profit | C7: — | D7: — | E7: — | F7: — | G7: =G6*CHOOSE('DCF Model'!$D$27,G41,G42,G43,G44,G45) | H7: =H6*CHOOSE('DCF Model'!$D$27,H41,H42,H43,H44,H45) | I7: =I6*CHOOSE('DCF Model'!$D$27,I41,I42,I43,I44,I45) | J7: =J6*CHOOSE('DCF Model'!$D$27,J41,J42,J43,J44,J45) | K7: =K6*CHOOSE('DCF Model'!$D$27,K41,K42,K43,K44,K45)
B8: OP Margin | C8: — | D8: — | E8: — | F8: — | G8: =CHOOSE('DCF Model'!$D$27,G41,G42,G43,G44,G45) | H8: =CHOOSE('DCF Model'!$D$27,H41,H42,H43,H44,H45) | I8: =CHOOSE('DCF Model'!$D$27,I41,I42,I43,I44,I45) | J8: =CHOOSE('DCF Model'!$D$27,J41,J42,J43,J44,J45) | K8: =CHOOSE('DCF Model'!$D$27,K41,K42,K43,K44,K45)
B10: Private Sector (Industrial Pumps & Blowers) (民需部門（産業用ポンプ・送風機）)
B11: Revenue | C11: — | D11: — | E11: — | F11: 8985 | G11: =F11*(1+CHOOSE('DCF Model'!$D$27,G48,G49,G50,G51,G52)) | H11: =G11*(1+CHOOSE('DCF Model'!$D$27,H48,H49,H50,H51,H52)) | I11: =H11*(1+CHOOSE('DCF Model'!$D$27,I48,I49,I50,I51,I52)) | J11: =I11*(1+CHOOSE('DCF Model'!$D$27,J48,J49,J50,J51,J52)) | K11: =J11*(1+CHOOSE('DCF Model'!$D$27,K48,K49,K50,K51,K52))
B12: Operating Profit | C12: — | D12: — | E12: — | F12: — | G12: =G11*CHOOSE('DCF Model'!$D$27,G55,G56,G57,G58,G59) | H12: =H11*CHOOSE('DCF Model'!$D$27,H55,H56,H57,H58,H59) | I12: =I11*CHOOSE('DCF Model'!$D$27,I55,I56,I57,I58,I59) | J12: =J11*CHOOSE('DCF Model'!$D$27,J55,J56,J57,J58,J59) | K12: =K11*CHOOSE('DCF Model'!$D$27,K55,K56,K57,K58,K59)
B13: OP Margin | C13: — | D13: — | E13: — | F13: — | G13: =CHOOSE('DCF Model'!$D$27,G55,G56,G57,G58,G59) | H13: =CHOOSE('DCF Model'!$D$27,H55,H56,H57,H58,H59) | I13: =CHOOSE('DCF Model'!$D$27,I55,I56,I57,I58,I59) | J13: =CHOOSE('DCF Model'!$D$27,J55,J56,J57,J58,J59) | K13: =CHOOSE('DCF Model'!$D$27,K55,K56,K57,K58,K59)
B15: Overseas & Desalination (DeROs + Export) (海外・淡水化部門（DeROs・輸出）)
B16: Revenue | C16: — | D16: — | E16: — | F16: 6177 | G16: =F16*(1+CHOOSE('DCF Model'!$D$27,G62,G63,G64,G65,G66)) | H16: =G16*(1+CHOOSE('DCF Model'!$D$27,H62,H63,H64,H65,H66)) | I16: =H16*(1+CHOOSE('DCF Model'!$D$27,I62,I63,I64,I65,I66)) | J16: =I16*(1+CHOOSE('DCF Model'!$D$27,J62,J63,J64,J65,J66)) | K16: =J16*(1+CHOOSE('DCF Model'!$D$27,K62,K63,K64,K65,K66))
B17: Operating Profit | C17: — | D17: — | E17: — | F17: — | G17: =G16*CHOOSE('DCF Model'!$D$27,G69,G70,G71,G72,G73) | H17: =H16*CHOOSE('DCF Model'!$D$27,H69,H70,H71,H72,H73) | I17: =I16*CHOOSE('DCF Model'!$D$27,I69,I70,I71,I72,I73) | J17: =J16*CHOOSE('DCF Model'!$D$27,J69,J70,J71,J72,J73) | K17: =K16*CHOOSE('DCF Model'!$D$27,K69,K70,K71,K72,K73)
B18: OP Margin | C18: — | D18: — | E18: — | F18: — | G18: =CHOOSE('DCF Model'!$D$27,G69,G70,G71,G72,G73) | H18: =CHOOSE('DCF Model'!$D$27,H69,H70,H71,H72,H73) | I18: =CHOOSE('DCF Model'!$D$27,I69,I70,I71,I72,I73) | J18: =CHOOSE('DCF Model'!$D$27,J69,J70,J71,J72,J73) | K18: =CHOOSE('DCF Model'!$D$27,K69,K70,K71,K72,K73)
B20: Consolidated Total
B21: Total Revenue | C21: =C6+C11+C16 | D21: =D6+D11+D16 | E21: =E6+E11+E16 | F21: =F6+F11+F16 | G21: =G6+G11+G16 | H21: =H6+H11+H16 | I21: =I6+I11+I16 | J21: =J6+J11+J16 | K21: =K6+K11+K16
B22: Total Operating Profit | C22: =C7+C12+C17 | D22: =D7+D12+D17 | E22: =E7+E12+E17 | F22: =F7+F12+F17 | G22: =G7+G12+G17 | H22: =H7+H12+H17 | I22: =I7+I12+I17 | J22: =J7+J12+J17 | K22: =K7+K12+K17
B23: Total OP Margin | C23: =IFERROR(C22/C21,"—") | D23: =IFERROR(D22/D21,"—") | E23: =IFERROR(E22/E21,"—") | F23: =IFERROR(F22/F21,"—") | G23: =IFERROR(G22/G21,"—") | H23: =IFERROR(H22/H21,"—") | I23: =IFERROR(I22/I21,"—") | J23: =IFERROR(J22/J21,"—") | K23: =IFERROR(K22/K21,"—")
B25: Reconciliation vs DCF Model
B26: DCF Model Revenue | G26: ='DCF Model'!C33 | H26: ='DCF Model'!D33 | I26: ='DCF Model'!E33 | J26: ='DCF Model'!F33 | K26: ='DCF Model'!G33
B27: Segment Total Revenue | G27: =G21 | H27: =H21 | I27: =I21 | J27: =J21 | K27: =K21
B28: Difference | G28: =G27-G26 | H28: =H27-H26 | I28: =I27-I26 | J28: =J27-J26 | K28: =K27-K26
B31: Segment Scenario Input Matrix
G32: FY2026(E) | H32: FY2027(E) | I32: FY2028(E) | J32: FY2029(E) | K32: FY2030(E)
B33: Public Sector (Pumps & Blowers) - Revenue Growth (YoY)
B34: Base | G34: 0.02 | H34: 0.02 | I34: 0.03 | J34: 0.03 | K34: 0.03
B35: Upside | G35: 0.035 | H35: 0.035 | I35: 0.045 | J35: 0.045 | K35: 0.045
B36: Management | G36: 0.02 | H36: 0.02 | I36: 0.03 | J36: 0.03 | K36: 0.03
B37: Downside 1 | G37: 0 | H37: 0 | I37: 0.01 | J37: 0.01 | K37: 0.01
B38: Downside 2 | G38: -0.02 | H38: -0.02 | I38: -0.01 | J38: -0.01 | K38: -0.01
B40: Public Sector (Pumps & Blowers) - OP Margin
B41: Base | G41: 0.1 | H41: 0.1 | I41: 0.11 | J41: 0.11 | K41: 0.11
B42: Upside | G42: 0.11 | H42: 0.11 | I42: 0.12 | J42: 0.12 | K42: 0.12
B43: Management | G43: 0.1 | H43: 0.1 | I43: 0.11 | J43: 0.11 | K43: 0.11
B44: Downside 1 | G44: 0.09 | H44: 0.09 | I44: 0.1 | J44: 0.1 | K44: 0.1
B45: Downside 2 | G45: 0.08 | H45: 0.08 | I45: 0.09 | J45: 0.09 | K45: 0.09
B47: Private Sector (Industrial Pumps & Blowers) - Revenue Growth (YoY)
B48: Base | G48: 0.03 | H48: 0.04 | I48: 0.05 | J48: 0.05 | K48: 0.05
B49: Upside | G49: 0.045 | H49: 0.055 | I49: 0.065 | J49: 0.065 | K49: 0.065
B50: Management | G50: 0.03 | H50: 0.04 | I50: 0.05 | J50: 0.05 | K50: 0.05
...

Sheet Driver Analysis
B2: Driver Analysis - DMW Corporation
C4: FY2023 | D4: FY2024 | E4: FY2025 | F4: FY2026 | G4: FY2026(E) | H4: FY2027(E) | I4: FY2028(E) | J4: FY2029(E) | K4: FY2030(E)
B5: Public Sector (Pumps & Blowers) (官需部門（ポンプ・送風機）) [backlog]
B6: Beginning Backlog | C6: — | D6: — | E6: — | F6: — | G6: =F9 | H6: =G9 | I6: =H9 | J6: =I9 | K6: =J9
B7: + New Orders | C7: — | D7: — | E7: — | F7: — | G7: — | H7: — | I7: — | J7: — | K7: —
B8: - Revenue (Recognized) | C8: — | D8: — | E8: — | F8: 12915 | G8: 13173 | H8: 13437 | I8: 13840 | J8: 14255 | K8: 14683
B9: Ending Backlog | C9: — | D9: — | E9: — | F9: — | G9: =G6+G7-G8 | H9: =H6+H7-H8 | I9: =I6+I7-I8 | J9: =J6+J7-J8 | K9: =K6+K7-K8
B10: Book-to-Bill | C10: =IFERROR(C7/C8,"—") | D10: =IFERROR(D7/D8,"—") | E10: =IFERROR(E7/E8,"—") | F10: =IFERROR(F7/F8,"—") | G10: =IFERROR(G7/G8,"—") | H10: =IFERROR(H7/H8,"—") | I10: =IFERROR(I7/I8,"—") | J10: =IFERROR(J7/J8,"—") | K10: =IFERROR(K7/K8,"—")
B12: Private Sector (Industrial Pumps & Blowers) (民需部門（産業用ポンプ・送風機）) [backlog]
B13: Beginning Backlog | C13: — | D13: — | E13: — | F13: — | G13: =F16 | H13: =G16 | I13: =H16 | J13: =I16 | K13: =J16
B14: + New Orders | C14: — | D14: — | E14: — | F14: — | G14: — | H14: — | I14: — | J14: — | K14: —
B15: - Revenue (Recognized) | C15: — | D15: — | E15: — | F15: 8985 | G15: 9255 | H15: 9625 | I15: 10106 | J15: 10611 | K15: 11142
B16: Ending Backlog | C16: — | D16: — | E16: — | F16: — | G16: =G13+G14-G15 | H16: =H13+H14-H15 | I16: =I13+I14-I15 | J16: =J13+J14-J15 | K16: =K13+K14-K15
B17: Book-to-Bill | C17: =IFERROR(C14/C15,"—") | D17: =IFERROR(D14/D15,"—") | E17: =IFERROR(E14/E15,"—") | F17: =IFERROR(F14/F15,"—") | G17: =IFERROR(G14/G15,"—") | H17: =IFERROR(H14/H15,"—") | I17: =IFERROR(I14/I15,"—") | J17: =IFERROR(J14/J15,"—") | K17: =IFERROR(K14/K15,"—")
B19: Overseas & Desalination (DeROs + Export) (海外・淡水化部門（DeROs・輸出）) [backlog]
B20: Beginning Backlog | C20: — | D20: — | E20: — | F20: — | G20: =F23 | H20: =G23 | I20: =H23 | J20: =I23 | K20: =J23
B21: + New Orders | C21: — | D21: — | E21: — | F21: — | G21: — | H21: — | I21: — | J21: — | K21: —
B22: - Revenue (Recognized) | C22: — | D22: — | E22: — | F22: 6177 | G22: 6671 | H22: 7338 | I22: 8219 | J22: 9452 | K22: 10586
B23: Ending Backlog | C23: — | D23: — | E23: — | F23: — | G23: =G20+G21-G22 | H23: =H20+H21-H22 | I23: =I20+I21-I22 | J23: =J20+J21-J22 | K23: =K20+K21-K22
B24: Book-to-Bill | C24: =IFERROR(C21/C22,"—") | D24: =IFERROR(D21/D22,"—") | E24: =IFERROR(E21/E22,"—") | F24: =IFERROR(F21/F22,"—") | G24: =IFERROR(G21/G22,"—") | H24: =IFERROR(H21/H22,"—") | I24: =IFERROR(I21/I22,"—") | J24: =IFERROR(J21/J22,"—") | K24: =IFERROR(K21/K22,"—")
