Workbook

Sheet Executive Summary
B1: DISCLAIMER: This is a sample analysis for demonstration purposes only. It does not constitute investment advice.
B3: トヨタ自動車株式会社 (7203.T)
B4: Equity Research Report
B6: Company | C6: トヨタ自動車株式会社
B7: Ticker | C7: 7203.T (TSE)
B8: Sector | C8: Automotive (ex-captive finance)
B9: Current Price | C9: 3152
B10: Target Price (Mid) | C10: =ROUND(AVERAGE(C16:C19),0) -> 3585
B11: Recommendation | C11: =IF(C12>0.15,"BUY",IF(C12>0.05,"HOLD","SELL")) -> HOLD
B12: Upside / Downside | C12: =(C10-C9)/C9 -> 0.1373731
B14: Valuation Summary
B15: Methodology | C15: Implied Value (JPY) | D15: vs Current Price
B16: DCF - Perpetuity Growth | C16: ='DCF Model'!C55 -> 2716 | D16: =(C16-C9)/C9 -> -0.13832487
B17: DCF - Exit Multiple | C17: ='DCF Model'!C64 -> 4842 | D17: =(C17-C9)/C9 -> 0.53616751
B18: Comps - EV/EBITDA Median | C18: ='Comps Analysis'!C27 -> 2114 | D18: =IF(ISNUMBER(C18),(C18-C9)/C9,"N/A") -> -0.32931472
B19: Comps - PER Median | C19: ='Comps Analysis'!C28 -> 4666 | D19: =IF(ISNUMBER(C19),(C19-C9)/C9,"N/A") -> 0.48032995
B21: Integrated Valuation Range | C21: =MIN(C16:C19)&" - "&MAX(C16:C19) -> 2114 - 4842
B23: Key Investment Thesis
B24: 1. The reported earnings decline is entirely automotive, and the market may be mispricing the recovery path. Automotive operating margin fell from 9.68% (FY2024/3) to 4.42% (FY2026/3) while the captive finance arm grew from 24.7% to 46.2% of consolidated operating profit. Stripping finance out reveals an industrial business near a cyclical trough, not a structurally broken one.
B25: 2. Fortress balance sheet with unrecognised asset value. Automotive net cash of roughly 9,800,000 plus equity-method investments at 5,342,548 book value and other financial assets of 15,118,244 sit outside the DCF. Combined, the non-operating assets not captured in automotive FCF exceed 20,000,000, or more than 1,500 per share against a 3,152 price.
B26: 3. Hybrid franchise is the cash engine funding the transition. Toyota is monetising HEV demand at a time when pure-BEV competitors are diluting margins, giving it a self-funded path through the electrification capex cycle without external financing.
B28: Key Risks
B29: 1. Tariff and cost persistence. The 526,000 swing in automotive operating profit between FY2025/3 and FY2026/3 shows how little margin cushion exists. If US tariff costs prove permanent rather than transitional, the Downside 1 path of 3-4% automotive margin becomes the base case.
B30: 2. Chinese competition and BEV transition risk. Chinese OEMs are expanding into ASEAN and Europe where Toyota holds dominant share. Automotive capex of 2,526,996 against D&A of roughly 1,472,087 means the investment burden continues regardless of demand, compressing free cash flow.
B31: 3. Valuation depends heavily on segment allocation assumptions. Automotive D&A is estimated at 61.5% of consolidated D&A, and automotive net cash is derived rather than disclosed at this granularity. A 10-point shift in the D&A split moves automotive EBITDA by roughly 240,000, or 0.4x on the exit multiple.

Sheet Financial Statements
B2: トヨタ自動車株式会社 - Historical Financials (JPY mn)
C4: FY2023/3 | D4: FY2024/3 | E4: FY2025/3 | F4: FY2026/3
B5: Income Statement
B6: Revenue | C6: 34367619 | D6: 41648130 | E6: 43598877 | F6: 45865949
B7: COGS | C7: 29128561 | D7: 33600612 | E7: 35510157 | F7: 39141418
B8: Gross Profit | C8: =C6-C7 -> 5239058 | D8: =D6-D7 -> 8047518 | E8: =E6-E7 -> 8088720 | F8: =F6-F7 -> 6724531
B9: Gross Margin | C9: =C8/C6 -> 0.15244169 | D9: =D8/D6 -> 0.19322639 | E9: =E8/E6 -> 0.18552588 | F9: =F8/F6 -> 0.14661271
B10: SGA | C10: 3587990 | D10: 4015383 | E10: 4782452 | F10: 4697524
B11: Operating Income | C11: 1651068 | D11: 4032135 | E11: 3306268 | F11: 2027007
B12: Net Income | C12: 2451318 | D12: 4944933 | E12: 4765086 | F12: 3848098
B13: Operating Margin | C13: =C11/C6 -> 0.048041385 | D13: =D11/D6 -> 0.096814311 | E13: =E11/E6 -> 0.075833788 | F13: =F11/F6 -> 0.044194158
B14: Net Margin | C14: =C12/C6 -> 0.071326384 | D14: =D12/D6 -> 0.11873121 | E14: =E12/E6 -> 0.10929378 | F14: =F12/F6 -> 0.083898798
B15: Revenue Growth (YoY) | C15: n/a | D15: =(D6-C6)/C6 -> 0.21184217 | E15: =(E6-D6)/D6 -> 0.046838766 | F15: =(F6-E6)/E6 -> 0.051998404
B16: Operating Income Growth (YoY) | C16: n/a | D16: =(D11-C11)/C11 -> 1.4421375 | E16: =(E11-D11)/D11 -> -0.18002051 | F16: =(F11-E11)/E11 -> -0.38691994
B18: Cash Flow Statement
B19: Operating Cash Flow (consol.) | C19: 2955076 | D19: 4206373 | E19: 3696934 | F19: 5472920
B20: Capex (automotive only) | C20: 1798476 | D20: 2180734 | E20: 2260608 | F20: 2526996
B21: Free Cash Flow (mixed basis) | C21: =C19-C20 -> 1156600 | D21: =D19-D20 -> 2025639 | E21: =E19-E20 -> 1436326 | F21: =F19-F20 -> 2945924
B22: FCF Margin (mixed basis) | C22: =C21/C6 -> 0.033653772 | D22: =D21/D6 -> 0.048636974 | E22: =E21/E6 -> 0.032944105 | F22: =F21/F6 -> 0.064228999
B23: Capex / Revenue (auto) | C23: =C20/C6 -> 0.052330538 | D23: =D20/D6 -> 0.05236091 | E23: =E20/E6 -> 0.051850143 | F23: =F20/F6 -> 0.055095252
B25: Balance Sheet Highlights
B26: Cash & Equivalents (consol.) | C26: 7516966 | D26: 9412060 | E26: 8982404 | F26: 12659622
B27: Total Interest-Bearing Debt (consol.) | C27: 29380273 | D27: 36561780 | E27: 38792879 | F27: 43205469
B28: Net Debt (consol., incl. finance) | C28: =C27-C26 -> 21863307 | D28: =D27-D26 -> 27149720 | E28: =E27-E26 -> 29810475 | F28: =F27-F26 -> 30545847
B30: Source: 決算短信 FY2024/3 and FY2026/3 (連結キャッシュ・フロー計算書 / 連結財政状態計算書). Operating Cash Flow, Cash & Equivalents and Total Interest-Bearing Debt (有利子負債, current + non-current) are CONSOLIDATED and therefore INCLUDE Toyota Financial Services.
B31: Income Statement rows above are AUTOMOTIVE ONLY: Revenue = 商品・製品売上収益, COGS = 売上原価, SGA = 販売費及び一般管理費, Operating Income = Revenue - COGS - SGA. Finance-segment revenue (4,819,003 in FY2026/3) and finance costs (3,079,794) are excluded.
B32: WARNING - rows 21/22 mix bases: consolidated Operating Cash Flow less automotive-only capex. They overstate automotive free cash flow because consolidated OCF contains finance-segment earnings. Reference only; do not quote. Consolidated capex including 賃貸資産の購入 was 5,293,348 in FY2026/3, which would put consolidated FCF at +179,572.
B33: Row 28 Net Debt is CONSOLIDATED (30,545,847 at 2026/3/31) and is INTENTIONALLY DIFFERENT from 'DCF Model'!C16 = -9,800,000, which is AUTOMOTIVE net cash. The consolidated figure carries ~39,000,000 of debt funding the finance receivables book. This is not an inconsistency - the DCF deliberately values the industrial business only.

Sheet DCF Model
B2: DCF Valuation Model - トヨタ自動車株式会社
B4: Assumptions
B5: Capex / Revenue | C5: 0.055095252
B6: Effective Tax Rate | C6: 0.26
B7: Risk-Free Rate | C7: 0.023
B8: Beta | C8: 0.85
B9: Equity Risk Premium | C9: 0.06
B10: Size Premium | C10: 0
B11: After-tax Cost of Debt | C11: 0.01
B12: D/E Ratio | C12: 0
B13: Terminal Growth Rate | C13: 0.01
B14: Exit Multiple (EV/EBITDA) | C14: 12
B15: Fully Diluted Shares | C15: 13009058960
B16: Net Debt (JPY mn) | C16: -9800000
... B20: LTM Revenue (JPY mn) | C20: 45865949
B22: WACC Calculation
B23: Cost of Equity (Ke) | C23: =C7+C8*C9+C10 -> 0.074
B24: Weight of Equity | C24: =1/(1+C12) -> 1
B25: Weight of Debt | C25: =C12/(1+C12) -> 0
B26: WACC | C26: =C23*C24+C11*C25 -> 0.074
B27: Active Scenario | C27: Base | D27: 1
B28: Projected Free Cash Flow
C29: FY2027(E) | D29: FY2028(E) | E29: FY2029(E) | F29: FY2030(E) | G29: FY2031(E)
B30: Revenue Growth (YoY) | C30: =CHOOSE($D$27,C69,C70,C71,C72,C73) -> 0.03 | D30: =CHOOSE($D$27,D69,D70,D71,D72,D73) -> 0.04 | E30: =CHOOSE($D$27,E69,E70,E71,E72,E73) -> 0.03 | F30: =CHOOSE($D$27,F69,F70,F71,F72,F73) -> 0.03 | G30: =CHOOSE($D$27,G69,G70,G71,G72,G73) -> 0.02
B31: COGS % of Revenue | C31: =CHOOSE($D$27,C76,C77,C78,C79,C80) -> 0.845 | D31: =CHOOSE($D$27,D76,D77,D78,D79,D80) -> 0.836 | E31: =CHOOSE($D$27,E76,E77,E78,E79,E80) -> 0.832 | F31: =CHOOSE($D$27,F76,F77,F78,F79,F80) -> 0.83 | G31: =CHOOSE($D$27,G76,G77,G78,G79,G80) -> 0.83
B32: SGA % of Revenue | C32: =CHOOSE($D$27,C83,C84,C85,C86,C87) -> 0.1 | D32: =CHOOSE($D$27,D83,D84,D85,D86,D87) -> 0.099 | E32: =CHOOSE($D$27,E83,E84,E85,E86,E87) -> 0.098 | F32: =CHOOSE($D$27,F83,F84,F85,F86,F87) -> 0.098 | G32: =CHOOSE($D$27,G83,G84,G85,G86,G87) -> 0.098
B33: Revenue | C33: =C17*(1+C30) -> 47241927 | D33: =C33*(1+D30) -> 49131605 | E33: =D33*(1+E30) -> 50605553 | F33: =E33*(1+F30) -> 52123719 | G33: =F33*(1+G30) -> 53166194
B34: COGS | C34: =C33*C31 -> 39919429 | D34: =D33*D31 -> 41074021 | E34: =E33*E31 -> 42103820 | F34: =F33*F31 -> 43262687 | G34: =G33*G31 -> 44127941
B35: Gross Profit | C35: =C33-C34 -> 7322498.8 | D35: =D33-D34 -> 8057583.1 | E35: =E33-E34 -> 8501732.9 | F35: =F33-F34 -> 8861032.3 | G35: =G33-G34 -> 9038252.9
B36: Gross Margin | C36: =C35/C33 -> 0.155 | D36: =D35/D33 -> 0.164 | E36: =E35/E33 -> 0.168 | F36: =F35/F33 -> 0.17 | G36: =G35/G33 -> 0.17
B37: SGA Expense | C37: =C33*C32 -> 4724192.7 | D37: =D33*D32 -> 4864028.9 | E37: =E33*E32 -> 4959344.2 | F37: =F33*F32 -> 5108124.5 | G37: =G33*G32 -> 5210287
B38: Implied Operating Margin | C38: =(C35-C37)/C33 -> 0.055 | D38: =(D35-D37)/D33 -> 0.065 | E38: =(E35-E37)/E33 -> 0.07 | F38: =(F35-F37)/F33 -> 0.072 | G38: =(G35-G37)/G33 -> 0.072
B39: Operating Income (EBIT) | C39: =C35-C37 -> 2598306 | D39: =D35-D37 -> 3193554.3 | E39: =E35-E37 -> 3542388.7 | F39: =F35-F37 -> 3752907.8 | G39: =G35-G37 -> 3827965.9
B40: Less: Tax | C40: =MAX(0,C39*C6) -> 675559.56 | D40: =MAX(0,D39*C6) -> 830324.12 | E40: =MAX(0,E39*C6) -> 921021.06 | F40: =MAX(0,F39*C6) -> 975756.03 | G40: =MAX(0,G39*C6) -> 995271.15
B41: NOPAT | C41: =C39-C40 -> 1922746.4 | D41: =D39-D40 -> 2363230.2 | E41: =E39-E40 -> 2621367.6 | F41: =F39-F40 -> 2777151.8 | G41: =G39-G40 -> 2832694.8
B42: Plus: D&A | C42: 1538220 | D42: 1610004 | E42: 1681787 | F42: 1753571 | G42: 1825354
B43: Less: Capex | C43: 2600000 | D43: 2650000 | E43: 2700000 | F43: 2750000 | G43: 2800000
B44: Change in NWC | C44: ='NWC Schedule'!D19 -> 43283.063 | D44: ='NWC Schedule'!E19 -> 20641.487 | E44: ='NWC Schedule'!F19 -> -16777.433 | F44: ='NWC Schedule'!G19 -> 96206.008 | G44: ='NWC Schedule'!H19 -> 64347.802
B45: Unlevered Free Cash Flow | C45: =C41+C42-C43-C44 -> 817683.38 | D45: =D41+D42-D43-D44 -> 1302592.7 | E45: =E41+E42-E43-E44 -> 1619932.1 | F45: =F41+F42-F43-F44 -> 1684516.8 | G45: =G41+G42-G43-G44 -> 1793701
B46: Discount Factor | C46: =1/(1+C26)^(C19+0) -> 0.9310987 | D46: =1/(1+C26)^(C19+1) -> 0.86694478 | E46: =1/(1+C26)^(C19+2) -> 0.80721116 | F46: =1/(1+C26)^(C19+3) -> 0.75159326 | G46: =1/(1+C26)^(C19+4) -> 0.6998075
...

Sheet NWC Schedule
B2: NWC Schedule - トヨタ自動車株式会社
B4: Working Capital Drivers (Days) | C4: Base Year | D4: FY2027(E) | E4: FY2028(E) | F4: FY2029(E) | G4: FY2030(E) | H4: FY2031(E)
B5: DSO (Days Sales Outstanding) | C5: =C12/C9*365 -> 30.208355 | D5: =CHOOSE('DCF Model'!$D$27,D25,D26,D27,D28,D29) -> 30 | E5: =CHOOSE('DCF Model'!$D$27,E25,E26,E27,E28,E29) -> 30 | F5: =CHOOSE('DCF Model'!$D$27,F25,F26,F27,F28,F29) -> 30 | G5: =CHOOSE('DCF Model'!$D$27,G25,G26,G27,G28,G29) -> 30 | H5: =CHOOSE('DCF Model'!$D$27,H25,H26,H27,H28,H29) -> 30
B6: DIH (Days Inventory Held) | C6: =C13/C10*365 -> 47.884661 | D6: =CHOOSE('DCF Model'!$D$27,D32,D33,D34,D35,D36) -> 48 | E6: =CHOOSE('DCF Model'!$D$27,E32,E33,E34,E35,E36) -> 47 | F6: =CHOOSE('DCF Model'!$D$27,F32,F33,F34,F35,F36) -> 46 | G6: =CHOOSE('DCF Model'!$D$27,G32,G33,G34,G35,G36) -> 46 | H6: =CHOOSE('DCF Model'!$D$27,H32,H33,H34,H35,H36) -> 46
B7: DPO (Days Payable Outstanding) | C7: =C15/C10*365 -> 54.616951 | D7: =CHOOSE('DCF Model'!$D$27,D39,D40,D41,D42,D43) -> 55 | E7: =CHOOSE('DCF Model'!$D$27,E39,E40,E41,E42,E43) -> 55 | F7: =CHOOSE('DCF Model'!$D$27,F39,F40,F41,F42,F43) -> 55 | G7: =CHOOSE('DCF Model'!$D$27,G39,G40,G41,G42,G43) -> 55 | H7: =CHOOSE('DCF Model'!$D$27,H39,H40,H41,H42,H43) -> 55
B8: P&L Reference (JPY mn)
B9: Revenue | C9: 45865949 | D9: ='DCF Model'!C33 -> 47241927 | E9: ='DCF Model'!D33 -> 49131605 | F9: ='DCF Model'!E33 -> 50605553 | G9: ='DCF Model'!F33 -> 52123719 | H9: ='DCF Model'!G33 -> 53166194
B10: COGS | C10: 39141418 | D10: ='DCF Model'!C34 -> 39919429 | E10: ='DCF Model'!D34 -> 41074021 | F10: ='DCF Model'!E34 -> 42103820 | G10: ='DCF Model'!F34 -> 43262687 | H10: ='DCF Model'!G34 -> 44127941
B11: Working Capital Items (JPY mn)
B12: Accounts Receivable | C12: 3795986 | D12: =D9*D5/365 -> 3882898.1 | E12: =E9*E5/365 -> 4038214.1 | F12: =F9*F5/365 -> 4159360.5 | G12: =G9*G5/365 -> 4284141.3 | H12: =H9*H5/365 -> 4369824.1
B13: Inventory | C13: 5134996 | D13: =D10*D6/365 -> 5249678.3 | E13: =E10*E6/365 -> 5288983.6 | F13: =F10*F6/365 -> 5306234.8 | G13: =G10*G6/365 -> 5452283.8 | H13: =H10*H6/365 -> 5561329.5
B14: Current Assets (AR + Inv) | C14: =C12+C13 -> 8930982 | D14: =D12+D13 -> 9132576.4 | E14: =E12+E13 -> 9327197.7 | F14: =F12+F13 -> 9465595.3 | G14: =G12+G13 -> 9736425.2 | H14: =H12+H13 -> 9931153.7
B15: Accounts Payable | C15: 5856945 | D15: =D10*D7/365 -> 6015256.4 | E15: =E10*E7/365 -> 6189236.1 | F15: =F10*F7/365 -> 6344411.2 | G15: =G10*G7/365 -> 6519035 | H15: =H10*H7/365 -> 6649415.7
B16: Current Liabilities (AP) | C16: =C15 -> 5856945 | D16: =D15 -> 6015256.4 | E16: =E15 -> 6189236.1 | F16: =F15 -> 6344411.2 | G16: =G15 -> 6519035 | H16: =H15 -> 6649415.7
B17: Net Working Capital (JPY mn)
B18: Net Working Capital | C18: =C14-C16 -> 3074037 | D18: =D14-D16 -> 3117320.1 | E18: =E14-E16 -> 3137961.5 | F18: =F14-F16 -> 3121184.1 | G18: =G14-G16 -> 3217390.1 | H18: =H14-H16 -> 3281737.9
B19: Change in NWC | C19: n/a | D19: =D18-C18 -> 43283.063 | E19: =E18-D18 -> 20641.487 | F19: =F18-E18 -> -16777.433 | G19: =G18-F18 -> 96206.008 | H19: =H18-G18 -> 64347.802
B22: Scenario Input Matrix (Working Capital Days)
D23: FY2027(E) | E23: FY2028(E) | F23: FY2029(E) | G23: FY2030(E) | H23: FY2031(E)
B24: DSO (Days)
B25: Base | D25: 30 | E25: 30 | F25: 30 | G25: 30 | H25: 30
B26: Upside | D26: 29 | E26: 29 | F26: 28 | G26: 28 | H26: 28
B27: Management | D27: 30 | E27: 30 | F27: 30 | G27: 30 | H27: 30
B28: Downside 1 | D28: 31 | E28: 32 | F28: 32 | G28: 32 | H28: 32
B29: Downside 2 | D29: 33 | E29: 34 | F29: 34 | G29: 34 | H29: 34
B31: DIH (Days)
B32: Base | D32: 48 | E32: 47 | F32: 46 | G32: 46 | H32: 46
B33: Upside | D33: 46 | E33: 45 | F33: 44 | G33: 43 | H33: 43
B34: Management | D34: 48 | E34: 47 | F34: 47 | G34: 46 | H34: 46
B35: Downside 1 | D35: 52 | E35: 55 | F35: 54 | G35: 52 | H35: 52
B36: Downside 2 | D36: 56 | E36: 62 | F36: 60 | G36: 58 | H36: 58
B38: DPO (Days)
B39: Base | D39: 55 | E39: 55 | F39: 55 | G39: 55 | H39: 55
B40: Upside | D40: 56 | E40: 56 | F40: 57 | G40: 57 | H40: 57
B41: Management | D41: 55 | E41: 55 | F41: 55 | G41: 55 | H41: 55
B42: Downside 1 | D42: 54 | E42: 53 | F42: 53 | G42: 54 | H42: 54
B43: Downside 2 | D43: 52 | E43: 50 | F43: 50 | G43: 51 | H43: 51

Sheet Comps Analysis
B2: Comparable Company Analysis
B4: Company | C4: Ticker | D4: Mkt Cap (JPY mn) | E4: EV (JPY mn) | F4: Revenue (JPY mn) | G4: EBITDA (JPY mn) | H4: Op Income (JPY mn) | I4: Net Income (JPY mn) | J4: EV/EBITDA | K4: EV/Revenue | L4: PER | M4: PBR | N4: Op Margin | O4: ROE
B5: Toyota Motor | C5: 7203.T | D5: 41004554 | E5: 71550401 | F5: 50684952 | G5: 6158735 | H5: 3766216 | I5: 3848098 | J5: =E5/G5 -> 11.617711 | K5: =E5/F5 -> 1.4116695 | L5: =D5/I5 -> 10.655798 | M5: 1.0271977 | N5: =H5/F5 -> 0.074306394 | O5: 0.096398008
B6: Honda Motor | C6: 7267.T | D6: 6570000 | E6: 14686061 | F6: 21796610 | G6: 888917 | H6: -414346 | I6: -423941 | J6: =E6/G6 -> 16.521296 | K6: =E6/F6 -> 0.6737773 | L6: N/A | M6: 0.55595459 | N6: =H6/F6 -> -0.019009653 | O6: -0.035873964
B7: Suzuki Motor | C7: 7269.T | D7: 4140000 | E7: 3915332 | F7: 6292967 | G7: 882386 | H7: 604605 | I7: 439267 | J7: =E7/G7 -> 4.43721 | K7: =E7/F7 -> 0.62217584 | L7: =D7/I7 -> 9.4247918 | M7: 1.2240977 | N7: =H7/F7 -> 0.096076302 | O7: 0.12988061
B8: SUBARU | C8: 7270.T | D8: 2010000 | E8: 1555148 | F8: 4784965 | G8: 318095 | H8: 46989 | I8: 90842 | J8: =E8/G8 -> 4.888942 | K8: =E8/F8 -> 0.32500718 | L8: =D8/I8 -> 22.126329 | M8: 0.72291575 | N8: =H8/F8 -> 0.0098201345 | O8: 0.032672195
B9: General Motors | C9: GM | D9: 12452350 | E9: 28741370 | F9: 29371766 | G9: 2777649 | H9: 461804 | I9: 428625 | J9: =E9/G9 -> 10.347373 | K9: =E9/F9 -> 0.97853735 | L9: =D9/I9 -> 29.051852 | M9: 1.283398 | N9: =H9/F9 -> 0.015722718 | O9: 0.044176117
B10: Ford Motor | C10: F | D10: 9666288 | E10: 29486067 | F10: 29728636 | G10: -211931 | H10: -1455579 | I10: -1298892 | J10: N/A | K10: =E10/F10 -> 0.99184056 | L10: N/A | M10: 1.6923292 | N10: =H10/F10 -> -0.048962186 | O10: -0.22740403
B11: Volkswagen AG | C11: VOW3.DE | D11: 6930363 | E11: 42954310 | F11: 59051721 | G11: 8493639 | H11: 1626746 | I11: 1224095 | J11: =E11/G11 -> 5.0572328 | K11: =E11/F11 -> 0.72740149 | L11: =D11/I11 -> 5.6616219 | M11: 0.20066178 | N11: =H11/F11 -> 0.027547817 | O11: 0.035442456
B14: Statistics
B15: 25th Percentile | D15: =PERCENTILE(J6:J11,0.25) -> 4.888942 | E15: =PERCENTILE(K6:K11,0.25) -> 0.6350762 | F15: =PERCENTILE(L6:L11,0.25) -> 8.4839993 | G15: =PERCENTILE(M6:M11,0.25) -> 0.59769488 | H15: =PERCENTILE(N6:N11,0.25) -> -0.011802206 | I15: =PERCENTILE(O6:O11,0.25) -> -0.018737424
B16: Median (50th) | D16: =MEDIAN(J6:J11) -> 5.0572328 | E16: =MEDIAN(K6:K11) -> 0.7005894 | F16: =MEDIAN(L6:L11) -> 15.77556 | G16: =MEDIAN(M6:M11) -> 0.97350672 | H16: =MEDIAN(N6:N11) -> 0.012771426 | I16: =MEDIAN(O6:O11) -> 0.034057326
B17: 75th Percentile | D17: =PERCENTILE(J6:J11,0.75) -> 10.347373 | E17: =PERCENTILE(K6:K11,0.75) -> 0.91575338 | F17: =PERCENTILE(L6:L11,0.75) -> 23.85771 | G17: =PERCENTILE(M6:M11,0.75) -> 1.2685729 | H17: =PERCENTILE(N6:N11,0.75) -> 0.024591542 | I17: =PERCENTILE(O6:O11,0.75) -> 0.041992701
B18: Note: Statistics are PEERS ONLY (rows 6-11). Toyota (row 5) is shown for reference but excluded - including the subject company made the PER median equal Toyota's own multiple, so the implied price reproduced the market price. Peer rows are CONSOLIDATED (incl. captive finance) while C21/C24 below are AUTOMOTIVE-only: the EV/EBITDA implied value therefore mixes bases and is a rough reference, not a valuation. Honda and Ford operating losses are actual (Honda FY2026/3 OP -414,346 after 1,453,600 of EV-related losses).
B19: Implied Valuation for トヨタ自動車株式会社
B20: トヨタ自動車株式会社 Financials
B21: EBITDA (JPY mn) | C21: 3499094
B22: Net Income (JPY mn) | C22: 3848098
B23: Shares Outstanding | C23: 13009058960
B24: Net Debt (JPY mn) | C24: -9800000
B26: Implied Share Price (Median Multiples)
B27: Via EV/EBITDA (Median) | C27: =ROUND((C21*D16-C24)*1000000/C23,0) -> 2114
B28: Via PER (Median) | C28: =ROUND(C22*F16*1000000/C23,0) -> 4666

Sheet Sensitivity Analysis
B2: Sensitivity Analysis
B3: Current WACC: | C3: ='DCF Model'!C26 -> 0.074 | E3: Terminal g: | F3: ='DCF Model'!C13 -> 0.01 | H3: Exit Multiple: | I3: ='DCF Model'!C14 -> 12
B5: Table 1: WACC vs Terminal Growth Rate (PGM - Implied Share Price, JPY)
B6: WACC \ Terminal g | C6: =$F$3-0.0075 -> 0.0025 | D6: =$F$3-0.005 -> 0.005 | E6: =$F$3-0.0025 -> 0.0075 | F6: =$F$3 -> 0.01 | G6: =$F$3+0.0025 -> 0.0125 | H6: =$F$3+0.005 -> 0.015 | I6: =$F$3+0.0075 -> 0.0175
B7: =$C$3-0.015 -> 0.059 | C7: =IFERROR(ROUND(('DCF Model'!C45/(1+$B7)^('DCF Model'!C19+0)+'DCF Model'!D45/(1+$B7)^('DCF Model'!C19+1)+'DCF Model'!E45/(1+$B7)^('DCF Model'!C19+2)+'DCF Model'!F45/(1+$B7)^('DCF Model'!C19+3)+'DCF Model'!G45/(1+$B7)^('DCF Model'!C19+4)+'DCF Model'!G45*(1+C$6)/($B7-C$6)/(1+$B7)^('DCF Model'!C19+4)-'DCF Model'!C16)*1000000/'DCF Model'!C15,0),"") -> 3050 | D7: =IFERROR(ROUND(('DCF Model'!C45/(1+$B7)^('DCF Model'!C19+0)+'DCF Model'!D45/(1+$B7)^('DCF Model'!C19+1)+'DCF Model'!E45/(1+$B7)^('DCF Model'!C19+2)+'DCF Model'!F45/(1+$B7)^('DCF Model'!C19+3)+'DCF Model'!G45/(1+$B7)^('DCF Model'!C19+4)+'DCF Model'!G45*(1+D$6)/($B7-D$6)/(1+$B7)^('DCF Model'!C19+4)-'DCF Model'!C16)*1000000/'DCF Model'!C15,0),"") -> 3140 | E7: =IFERROR(ROUND(('DCF Model'!C45/(1+$B7)^('DCF Model'!C19+0)+'DCF Model'!D45/(1+$B7)^('DCF Model'!C19+1)+'DCF Model'!E45/(1+$B7)^('DCF Model'!C19+2)+'DCF Model'!F45/(1+$B7)^('DCF Model'!C19+3)+'DCF Model'!G45/(1+$B7)^('DCF Model'!C19+4)+'DCF Model'!G45*(1+E$6)/($B7-E$6)/(1+$B7)^('DCF Model'!C19+4)-'DCF Model'!C16)*1000000/'DCF Model'!C15,0),"") -> 3238 | F7: =IFERROR(ROUND(('DCF Model'!C45/(1+$B7)^('DCF Model'!C19+0)+'DCF Model'!D45/(1+$B7)^('DCF Model'!C19+1)+'DCF Model'!E45/(1+$B7)^('DCF Model'!C19+2)+'DCF Model'!F45/(1+$B7)^('DCF Model'!C19+3)+'DCF Model'!G45/(1+$B7)^('DCF Model'!C19+4)+'DCF Model'!G45*(1+F$6)/($B7-F$6)/(1+$B7)^('DCF Model'!C19+4)-'DCF Model'!C16)*1000000/'DCF Model'!C15,0),"") -> 3347 | G7: =IFERROR(ROUND(('DCF Model'!C45/(1+$B7)^('DCF Model'!C19+0)+'DCF Model'!D45/(1+$B7)^('DCF Model'!C19+1)+'DCF Model'!E45/(1+$B7)^('DCF Model'!C19+2)+'DCF Model'!F45/(1+$B7)^('DCF Model'!C19+3)+'DCF Model'!G45/(1+$B7)^('DCF Model'!C19+4)+'DCF Model'!G45*(1+G$6)/($B7-G$6)/(1+$B7)^('DCF Model'!C19+4)-'DCF Model'!C16)*1000000/'DCF Model'!C15,0),"") -> 3467 | H7: =IFERROR(ROUND(('DCF Model'!C45/(1+$B7)^('DCF Model'!C19+0)+'DCF Model'!D45/(1+$B7)^('DCF Model'!C19+1)+'DCF Model'!E45/(1+$B7)^('DCF Model'!C19+2)+'DCF Model'!F45/(1+$B7)^('DCF Model'!C19+3)+'DCF Model'!G45/(1+$B7)^('DCF Model'!C19+4)+'DCF Model'!G45*(1+H$6)/($B7-H$6)/(1+$B7)^('DCF Model'!C19+4)-'DCF Model'!C16)*1000000/'DCF Model'!C15,0),"") -> 3601 | I7: =IFERROR(ROUND(('DCF Model'!C45/(1+$B7)^('DCF Model'!C19+0)+'DCF Model'!D45/(1+$B7)^('DCF Model'!C19+1)+'DCF Model'!E45/(1+$B7)^('DCF Model'!C19+2)+'DCF Model'!F45/(1+$B7)^('DCF Model'!C19+3)+'DCF Model'!G45/(1+$B7)^('DCF Model'!C19+4)+'DCF Model'!G45*(1+I$6)/($B7-I$6)/(1+$B7)^('DCF Model'!C19+4)-'DCF Model'!C16)*1000000/'DCF Model'!C15,0),"") -> 3751
B8: =$C$3-0.01 -> 0.064 | C8: =IFERROR(ROUND(('DCF Model'!C45/(1+$B8)^('DCF Model'!C19+0)+'DCF Model'!D45/(1+$B8)^('DCF Model'!C19+1)+'DCF Model'!E45/(1+$B8)^('DCF Model'!C19+2)+'DCF Model'!F45/(1+$B8)^('DCF Model'!C19+3)+'DCF Model'!G45/(1+$B8)^('DCF Model'!C19+4)+'DCF Model'!G45*(1+C$6)/($B8-C$6)/(1+$B8)^('DCF Model'!C19+4)-'DCF Model'!C16)*1000000/'DCF Model'!C15,0),"") -> 2855 | D8: =IFERROR(ROUND(('DCF Model'!C45/(1+$B8)^('DCF Model'!C19+0)+'DCF Model'!D45/(1+$B8)^('DCF Model'!C19+1)+'DCF Model'!E45/(1+$B8)^('DCF Model'!C19+2)+'DCF Model'!F45/(1+$B8)^('DCF Model'!C19+3)+'DCF Model'!G45/(1+$B8)^('DCF Model'!C19+4)+'DCF Model'!G45*(1+D$6)/($B8-D$6)/(1+$B8)^('DCF Model'!C19+4)-'DCF Model'!C16)*1000000/'DCF Model'!C15,0),"") -> 2929 | E8: =IFERROR(ROUND(('DCF Model'!C45/(1+$B8)^('DCF Model'!C19+0)+'DCF Model'!D45/(1+$B8)^('DCF Model'!C19+1)+'DCF Model'!E45/(1+$B8)^('DCF Model'!C19+2)+'DCF Model'!F45/(1+$B8)^('DCF Model'!C19+3)+'DCF Model'!G45/(1+$B8)^('DCF Model'!C19+4)+'DCF Model'!G45*(1+E$6)/($B8-E$6)/(1+$B8)^('DCF Model'!C19+4)-'DCF Model'!C16)*1000000/'DCF Model'!C15,0),"") -> 3009 | F8: =IFERROR(ROUND(('DCF Model'!C45/(1+$B8)^('DCF Model'!C19+0)+'DCF Model'!D45/(1+$B8)^('DCF Model'!C19+1)+'DCF Model'!E45/(1+$B8)^('DCF Model'!C19+2)+'DCF Model'!F45/(1+$B8)^('DCF Model'!C19+3)+'DCF Model'!G45/(1+$B8)^('DCF Model'!C19+4)+'DCF Model'!G45*(1+F$6)/($B8-F$6)/(1+$B8)^('DCF Model'!C19+4)-'DCF Model'!C16)*1000000/'DCF Model'!C15,0),"") -> 3098 | G8: =IFERROR(ROUND(('DCF Model'!C45/(1+$B8)^('DCF Model'!C19+0)+'DCF Model'!D45/(1+$B8)^('DCF Model'!C19+1)+'DCF Model'!E45/(1+$B8)^('DCF Model'!C19+2)+'DCF Model'!F45/(1+$B8)^('DCF Model'!C19+3)+'DCF Model'!G45/(1+$B8)^('DCF Model'!C19+4)+'DCF Model'!G45*(1+G$6)/($B8-G$6)/(1+$B8)^('DCF Model'!C19+4)-'DCF Model'!C16)*1000000/'DCF Model'!C15,0),"") -> 3194 | H8: =IFERROR(ROUND(('DCF Model'!C45/(1+$B8)^('DCF Model'!C19+0)+'DCF Model'!D45/(1+$B8)^('DCF Model'!C19+1)+'DCF Model'!E45/(1+$B8)^('DCF Model'!C19+2)+'DCF Model'!F45/(1+$B8)^('DCF Model'!C19+3)+'DCF Model'!G45/(1+$B8)^('DCF Model'!C19+4)+'DCF Model'!G45*(1+H$6)/($B8-H$6)/(1+$B8)^('DCF Model'!C19+4)-'DCF Model'!C16)*1000000/'DCF Model'!C15,0),"") -> 3301 | I8: =IFERROR(ROUND(('DCF Model'!C45/(1+$B8)^('DCF Model'!C19+0)+'DCF Model'!D45/(1+$B8)^('DCF Model'!C19+1)+'DCF Model'!E45/(1+$B8)^('DCF Model'!C19+2)+'DCF Model'!F45/(1+$B8)^('DCF Model'!C19+3)+'DCF Model'!G45/(1+$B8)^('DCF Model'!C19+4)+'DCF Model'!G45*(1+I$6)/($B8-I$6)/(1+$B8)^('DCF Model'!C19+4)-'DCF Model'!C16)*1000000/'DCF Model'!C15,0),"") -> 3419
B9: =$C$3-0.005 -> 0.069 | C9: =IFERROR(ROUND(('DCF Model'!C45/(1+$B9)^('DCF Model'!C19+0)+'DCF Model'!D45/(1+$B9)^('DCF Model'!C19+1)+'DCF Model'!E45/(1+$B9)^('DCF Model'!C19+2)+'DCF Model'!F45/(1+$B9)^('DCF Model'!C19+3)+'DCF Model'!G45/(1+$B9)^('DCF Model'!C19+4)+'DCF Model'!G45*(1+C$6)/($B9-C$6)/(1+$B9)^('DCF Model'!C19+4)-'DCF Model'!C16)*1000000/'DCF Model'!C15,0),"") -> 2689 | D9: =IFERROR(ROUND(('DCF Model'!C45/(1+$B9)^('DCF Model'!C19+0)+'DCF Model'!D45/(1+$B9)^('DCF Model'!C19+1)+'DCF Model'!E45/(1+$B9)^('DCF Model'!C19+2)+'DCF Model'!F45/(1+$B9)^('DCF Model'!C19+3)+'DCF Model'!G45/(1+$B9)^('DCF Model'!C19+4)+'DCF Model'!G45*(1+D$6)/($B9-D$6)/(1+$B9)^('DCF Model'!C19+4)-'DCF Model'!C16)*1000000/'DCF Model'!C15,0),"") -> 2751 | E9: =IFERROR(ROUND(('DCF Model'!C45/(1+$B9)^('DCF Model'!C19+0)+'DCF Model'!D45/(1+$B9)^('DCF Model'!C19+1)+'DCF Model'!E45/(1+$B9)^('DCF Model'!C19+2)+'DCF Model'!F45/(1+$B9)^('DCF Model'!C19+3)+'DCF Model'!G45/(1+$B9)^('DCF Model'!C19+4)+'DCF Model'!G45*(1+E$6)/($B9-E$6)/(1+$B9)^('DCF Model'!C19+4)-'DCF Model'!C16)*1000000/'DCF Model'!C15,0),"") -> 2818 | F9: =IFERROR(ROUND(('DCF Model'!C45/(1+$B9)^('DCF Model'!C19+0)+'DCF Model'!D45/(1+$B9)^('DCF Model'!C19+1)+'DCF Model'!E45/(1+$B9)^('DCF Model'!C19+2)+'DCF Model'!F45/(1+$B9)^('DCF Model'!C19+3)+'DCF Model'!G45/(1+$B9)^('DCF Model'!C19+4)+'DCF Model'!G45*(1+F$6)/($B9-F$6)/(1+$B9)^('DCF Model'!C19+4)-'DCF Model'!C16)*1000000/'DCF Model'!C15,0),"") -> 2890 | G9: =IFERROR(ROUND(('DCF Model'!C45/(1+$B9)^('DCF Model'!C19+0)+'DCF Model'!D45/(1+$B9)^('DCF Model'!C19+1)+'DCF Model'!E45/(1+$B9)^('DCF Model'!C19+2)+'DCF Model'!F45/(1+$B9)^('DCF Model'!C19+3)+'DCF Model'!G45/(1+$B9)^('DCF Model'!C19+4)+'DCF Model'!G45*(1+G$6)/($B9-G$6)/(1+$B9)^('DCF Model'!C19+4)-'DCF Model'!C16)*1000000/'DCF Model'!C15,0),"") -> 2970 | H9: =IFERROR(ROUND(('DCF Model'!C45/(1+$B9)^('DCF Model'!C19+0)+'DCF Model'!D45/(1+$B9)^('DCF Model'!C19+1)+'DCF Model'!E45/(1+$B9)^('DCF Model'!C19+2)+'DCF Model'!F45/(1+$B9)^('DCF Model'!C19+3)+'DCF Model'!G45/(1+$B9)^('DCF Model'!C19+4)+'DCF Model'!G45*(1+H$6)/($B9-H$6)/(1+$B9)^('DCF Model'!C19+4)-'DCF Model'!C16)*1000000/'DCF Model'!C15,0),"") -> 3056 | I9: =IFERROR(ROUND(('DCF Model'!C45/(1+$B9)^('DCF Model'!C19+0)+'DCF Model'!D45/(1+$B9)^('DCF Model'!C19+1)+'DCF Model'!E45/(1+$B9)^('DCF Model'!C19+2)+'DCF Model'!F45/(1+$B9)^('DCF Model'!C19+3)+'DCF Model'!G45/(1+$B9)^('DCF Model'!C19+4)+'DCF Model'!G45*(1+I$6)/($B9-I$6)/(1+$B9)^('DCF Model'!C19+4)-'DCF Model'!C16)*1000000/'DCF Model'!C15,0),"") -> 3151
B10: =$C$3 -> 0.074 | C10: =IFERROR(ROUND(('DCF Model'!C45/(1+$B10)^('DCF Model'!C19+0)+'DCF Model'!D45/(1+$B10)^('DCF Model'!C19+1)+'DCF Model'!E45/(1+$B10)^('DCF Model'!C19+2)+'DCF Model'!F45/(1+$B10)^('DCF Model'!C19+3)+'DCF Model'!G45/(1+$B10)^('DCF Model'!C19+4)+'DCF Model'!G45*(1+C$6)/($B10-C$6)/(1+$B10)^('DCF Model'!C19+4)-'DCF Model'!C16)*1000000/'DCF Model'!C15,0),"") -> 2546 | D10: =IFERROR(ROUND(('DCF Model'!C45/(1+$B10)^('DCF Model'!C19+0)+'DCF Model'!D45/(1+$B10)^('DCF Model'!C19+1)+'DCF Model'!E45/(1+$B10)^('DCF Model'!C19+2)+'DCF Model'!F45/(1+$B10)^('DCF Model'!C19+3)+'DCF Model'!G45/(1+$B10)^('DCF Model'!C19+4)+'DCF Model'!G45*(1+D$6)/($B10-D$6)/(1+$B10)^('DCF Model'!C19+4)-'DCF Model'!C16)*1000000/'DCF Model'!C15,0),"") -> 2598 | E10: =IFERROR(ROUND(('DCF Model'!C45/(1+$B10)^('DCF Model'!C19+0)+'DCF Model'!D45/(1+$B10)^('DCF Model'!C19+1)+'DCF Model'!E45/(1+$B10)^('DCF Model'!C19+2)+'DCF Model'!F45/(1+$B10)^('DCF Model'!C19+3)+'DCF Model'!G45/(1+$B10)^('DCF Model'!C19+4)+'DCF Model'!G45*(1+E$6)/($B10-E$6)/(1+$B10)^('DCF Model'!C19+4)-'DCF Model'!C16)*1000000/'DCF Model'!C15,0),"") -> 2655 | F10: =IFERROR(ROUND(('DCF Model'!C45/(1+$B10)^('DCF Model'!C19+0)+'DCF Model'!D45/(1+$B10)^('DCF Model'!C19+1)+'DCF Model'!E45/(1+$B10)^('DCF Model'!C19+2)+'DCF Model'!F45/(1+$B10)^('DCF Model'!C19+3)+'DCF Model'!G45/(1+$B10)^('DCF Model'!C19+4)+'DCF Model'!G45*(1+F$6)/($B10-F$6)/(1+$B10)^('DCF Model'!C19+4)-'DCF Model'!C16)*1000000/'DCF Model'!C15,0),"") -> 2716 | G10: =IFERROR(ROUND(('DCF Model'!C45/(1+$B10)^('DCF Model'!C19+0)+'DCF Model'!D45/(1+$B10)^('DCF Model'!C19+1)+'DCF Model'!E45/(1+$B10)^('DCF Model'!C19+2)+'DCF Model'!F45/(1+$B10)^('DCF Model'!C19+3)+'DCF Model'!G45/(1+$B10)^('DCF Model'!C19+4)+'DCF Model'!G45*(1+G$6)/($B10-G$6)/(1+$B10)^('DCF Model'!C19+4)-'DCF Model'!C16)*1000000/'DCF Model'!C15,0),"") -> 2782 | H10: =IFERROR(ROUND(('DCF Model'!C45/(1+$B10)^('DCF Model'!C19+0)+'DCF Model'!D45/(1+$B10)^('DCF Model'!C19+1)+'DCF Model'!E45/(1+$B10)^('DCF Model'!C19+2)+'DCF Model'!F45/(1+$B10)^('DCF Model'!C19+3)+'DCF Model'!G45/(1+$B10)^('DCF Model'!C19+4)+'DCF Model'!G45*(1+H$6)/($B10-H$6)/(1+$B10)^('DCF Model'!C19+4)-'DCF Model'!C16)*1000000/'DCF Model'!C15,0),"") -> 2853 | I10: =IFERROR(ROUND(('DCF Model'!C45/(1+$B10)^('DCF Model'!C19+0)+'DCF Model'!D45/(1+$B10)^('DCF Model'!C19+1)+'DCF Model'!E45/(1+$B10)^('DCF Model'!C19+2)+'DCF Model'!F45/(1+$B10)^('DCF Model'!C19+3)+'DCF Model'!G45/(1+$B10)^('DCF Model'!C19+4)+'DCF Model'!G45*(1+I$6)/($B10-I$6)/(1+$B10)^('DCF Model'!C19+4)-'DCF Model'!C16)*1000000/'DCF Model'!C15,0),"") -> 2931
B11: =$C$3+0.005 -> 0.079 | C11: =IFERROR(ROUND(('DCF Model'!C45/(1+$B11)^('DCF Model'!C19+0)+'DCF Model'!D45/(1+$B11)^('DCF Model'!C19+1)+'DCF Model'!E45/(1+$B11)^('DCF Model'!C19+2)+'DCF Model'!F45/(1+$B11)^('DCF Model'!C19+3)+'DCF Model'!G45/(1+$B11)^('DCF Model'!C19+4)+'DCF Model'!G45*(1+C$6)/($B11-C$6)/(1+$B11)^('DCF Model'!C19+4)-'DCF Model'!C16)*1000000/'DCF Model'!C15,0),"") -> 2422 | D11: =IFERROR(ROUND(('DCF Model'!C45/(1+$B11)^('DCF Model'!C19+0)+'DCF Model'!D45/(1+$B11)^('DCF Model'!C19+1)+'DCF Model'!E45/(1+$B11)^('DCF Model'!C19+2)+'DCF Model'!F45/(1+$B11)^('DCF Model'!C19+3)+'DCF Model'!G45/(1+$B11)^('DCF Model'!C19+4)+'DCF Model'!G45*(1+D$6)/($B11-D$6)/(1+$B11)^('DCF Model'!C19+4)-'DCF Model'!C16)*1000000/'DCF Model'!C15,0),"") -> 2467 | E11: =IFERROR(ROUND(('DCF Model'!C45/(1+$B11)^('DCF Model'!C19+0)+'DCF Model'!D45/(1+$B11)^('DCF Model'!C19+1)+'DCF Model'!E45/(1+$B11)^('DCF Model'!C19+2)+'DCF Model'!F45/(1+$B11)^('DCF Model'!C19+3)+'DCF Model'!G45/(1+$B11)^('DCF Model'!C19+4)+'DCF Model'!G45*(1+E$6)/($B11-E$6)/(1+$B11)^('DCF Model'!C19+4)-'DCF Model'!C16)*1000000/'DCF Model'!C15,0),"") -> 2515 | F11: =IFERROR(ROUND(('DCF Model'!C45/(1+$B11)^('DCF Model'!C19+0)+'DCF Model'!D45/(1+$B11)^('DCF Model'!C19+1)+'DCF Model'!E45/(1+$B11)^('DCF Model'!C19+2)+'DCF Model'!F45/(1+$B11)^('DCF Model'!C19+3)+'DCF Model'!G45/(1+$B11)^('DCF Model'!C19+4)+'DCF Model'!G45*(1+F$6)/($B11-F$6)/(1+$B11)^('DCF Model'!C19+4)-'DCF Model'!C16)*1000000/'DCF Model'!C15,0),"") -> 2566 | G11: =IFERROR(ROUND(('DCF Model'!C45/(1+$B11)^('DCF Model'!C19+0)+'DCF Model'!D45/(1+$B11)^('DCF Model'!C19+1)+'DCF Model'!E45/(1+$B11)^('DCF Model'!C19+2)+'DCF Model'!F45/(1+$B11)^('DCF Model'!C19+3)+'DCF Model'!G45/(1+$B11)^('DCF Model'!C19+4)+'DCF Model'!G45*(1+G$6)/($B11-G$6)/(1+$B11)^('DCF Model'!C19+4)-'DCF Model'!C16)*1000000/'DCF Model'!C15,0),"") -> 2622 | H11: =IFERROR(ROUND(('DCF Model'!C45/(1+$B11)^('DCF Model'!C19+0)+'DCF Model'!D45/(1+$B11)^('DCF Model'!C19+1)+'DCF Model'!E45/(1+$B11)^('DCF Model'!C19+2)+'DCF Model'!F45/(1+$B11)^('DCF Model'!C19+3)+'DCF Model'!G45/(1+$B11)^('DCF Model'!C19+4)+'DCF Model'!G45*(1+H$6)/($B11-H$6)/(1+$B11)^('DCF Model'!C19+4)-'DCF Model'!C16)*1000000/'DCF Model'!C15,0),"") -> 2682 | I11: =IFERROR(ROUND(('DCF Model'!C45/(1+$B11)^('DCF Model'!C19+0)+'DCF Model'!D45/(1+$B11)^('DCF Model'!C19+1)+'DCF Model'!E45/(1+$B11)^('DCF Model'!C19+2)+'DCF Model'!F45/(1+$B11)^('DCF Model'!C19+3)+'DCF Model'!G45/(1+$B11)^('DCF Model'!C19+4)+'DCF Model'!G45*(1+I$6)/($B11-I$6)/(1+$B11)^('DCF Model'!C19+4)-'DCF Model'!C16)*1000000/'DCF Model'!C15,0),"") -> 2746
B12: =$C$3+0.01 -> 0.084 | C12: =IFERROR(ROUND(('DCF Model'!C45/(1+$B12)^('DCF Model'!C19+0)+'DCF Model'!D45/(1+$B12)^('DCF Model'!C19+1)+'DCF Model'!E45/(1+$B12)^('DCF Model'!C19+2)+'DCF Model'!F45/(1+$B12)^('DCF Model'!C19+3)+'DCF Model'!G45/(1+$B12)^('DCF Model'!C19+4)+'DCF Model'!G45*(1+C$6)/($B12-C$6)/(1+$B12)^('DCF Model'!C19+4)-'DCF Model'!C16)*1000000/'DCF Model'!C15,0),"") -> 2313 | D12: =IFERROR(ROUND(('DCF Model'!C45/(1+$B12)^('DCF Model'!C19+0)+'DCF Model'!D45/(1+$B12)^('DCF Model'!C19+1)+'DCF Model'!E45/(1+$B12)^('DCF Model'!C19+2)+'DCF Model'!F45/(1+$B12)^('DCF Model'!C19+3)+'DCF Model'!G45/(1+$B12)^('DCF Model'!C19+4)+'DCF Model'!G45*(1+D$6)/($B12-D$6)/(1+$B12)^('DCF Model'!C19+4)-'DCF Model'!C16)*1000000/'DCF Model'!C15,0),"") -> 2352 | E12: =IFERROR(ROUND(('DCF Model'!C45/(1+$B12)^('DCF Model'!C19+0)+'DCF Model'!D45/(1+$B12)^('DCF Model'!C19+1)+'DCF Model'!E45/(1+$B12)^('DCF Model'!C19+2)+'DCF Model'!F45/(1+$B12)^('DCF Model'!C19+3)+'DCF Model'!G45/(1+$B12)^('DCF Model'!C19+4)+'DCF Model'!G45*(1+E$6)/($B12-E$6)/(1+$B12)^('DCF Model'!C19+4)-'DCF Model'!C16)*1000000/'DCF Model'!C15,0),"") -> 2393 | F12: =IFERROR(ROUND(('DCF Model'!C45/(1+$B12)^('DCF Model'!C19+0)+'DCF Model'!D45/(1+$B12)^('DCF Model'!C19+1)+'DCF Model'!E45/(1+$B12)^('DCF Model'!C19+2)+'DCF Model'!F45/(1+$B12)^('DCF Model'!C19+3)+'DCF Model'!G45/(1+$B12)^('DCF Model'!C19+4)+'DCF Model'!G45*(1+F$6)/($B12-F$6)/(1+$B12)^('DCF Model'!C19+4)-'DCF Model'!C16)*1000000/'DCF Model'!C15,0),"") -> 2438 | G12: =IFERROR(ROUND(('DCF Model'!C45/(1+$B12)^('DCF Model'!C19+0)+'DCF Model'!D45/(1+$B12)^('DCF Model'!C19+1)+'DCF Model'!E45/(1+$B12)^('DCF Model'!C19+2)+'DCF Model'!F45/(1+$B12)^('DCF Model'!C19+3)+'DCF Model'!G45/(1+$B12)^('DCF Model'!C19+4)+'DCF Model'!G45*(1+G$6)/($B12-G$6)/(1+$B12)^('DCF Model'!C19+4)-'DCF Model'!C16)*1000000/'DCF Model'!C15,0),"") -> 2485 | H12: =IFERROR(ROUND(('DCF Model'!C45/(1+$B12)^('DCF Model'!C19+0)+'DCF Model'!D45/(1+$B12)^('DCF Model'!C19+1)+'DCF Model'!E45/(1+$B12)^('DCF Model'!C19+2)+'DCF Model'!F45/(1+$B12)^('DCF Model'!C19+3)+'DCF Model'!G45/(1+$B12)^('DCF Model'!C19+4)+'DCF Model'!G45*(1+H$6)/($B12-H$6)/(1+$B12)^('DCF Model'!C19+4)-'DCF Model'!C16)*1000000/'DCF Model'!C15,0),"") -> 2535 | I12: =IFERROR(ROUND(('DCF Model'!C45/(1+$B12)^('DCF Model'!C19+0)+'DCF Model'!D45/(1+$B12)^('DCF Model'!C19+1)+'DCF Model'!E45/(1+$B12)^('DCF Model'!C19+2)+'DCF Model'!F45/(1+$B12)^('DCF Model'!C19+3)+'DCF Model'!G45/(1+$B12)^('DCF Model'!C19+4)+'DCF Model'!G45*(1+I$6)/($B12-I$6)/(1+$B12)^('DCF Model'!C19+4)-'DCF Model'!C16)*1000000/'DCF Model'!C15,0),"") -> 2590
B13: =$C$3+0.015 -> 0.089 | C13: =IFERROR(ROUND(('DCF Model'!C45/(1+$B13)^('DCF Model'!C19+0)+'DCF Model'!D45/(1+$B13)^('DCF Model'!C19+1)+'DCF Model'!E45/(1+$B13)^('DCF Model'!C19+2)+'DCF Model'!F45/(1+$B13)^('DCF Model'!C19+3)+'DCF Model'!G45/(1+$B13)^('DCF Model'!C19+4)+'DCF Model'!G45*(1+C$6)/($B13-C$6)/(1+$B13)^('DCF Model'!C19+4)-'DCF Model'!C16)*1000000/'DCF Model'!C15,0),"") -> 2217 | D13: =IFERROR(ROUND(('DCF Model'!C45/(1+$B13)^('DCF Model'!C19+0)+'DCF Model'!D45/(1+$B13)^('DCF Model'!C19+1)+'DCF Model'!E45/(1+$B13)^('DCF Model'!C19+2)+'DCF Model'!F45/(1+$B13)^('DCF Model'!C19+3)+'DCF Model'!G45/(1+$B13)^('DCF Model'!C19+4)+'DCF Model'!G45*(1+D$6)/($B13-D$6)/(1+$B13)^('DCF Model'!C19+4)-'DCF Model'!C16)*1000000/'DCF Model'!C15,0),"") -> 2251 | E13: =IFERROR(ROUND(('DCF Model'!C45/(1+$B13)^('DCF Model'!C19+0)+'DCF Model'!D45/(1+$B13)^('DCF Model'!C19+1)+'DCF Model'!E45/(1+$B13)^('DCF Model'!C19+2)+'DCF Model'!F45/(1+$B13)^('DCF Model'!C19+3)+'DCF Model'!G45/(1+$B13)^('DCF Model'!C19+4)+'DCF Model'!G45*(1+E$6)/($B13-E$6)/(1+$B13)^('DCF Model'!C19+4)-'DCF Model'!C16)*1000000/'DCF Model'!C15,0),"") -> 2287 | F13: =IFERROR(ROUND(('DCF Model'!C45/(1+$B13)^('DCF Model'!C19+0)+'DCF Model'!D45/(1+$B13)^('DCF Model'!C19+1)+'DCF Model'!E45/(1+$B13)^('DCF Model'!C19+2)+'DCF Model'!F45/(1+$B13)^('DCF Model'!C19+3)+'DCF Model'!G45/(1+$B13)^('DCF Model'!C19+4)+'DCF Model'!G45*(1+F$6)/($B13-F$6)/(1+$B13)^('DCF Model'!C19+4)-'DCF Model'!C16)*1000000/'DCF Model'!C15,0),"") -> 2325 | G13: =IFERROR(ROUND(('DCF Model'!C45/(1+$B13)^('DCF Model'!C19+0)+'DCF Model'!D45/(1+$B13)^('DCF Model'!C19+1)+'DCF Model'!E45/(1+$B13)^('DCF Model'!C19+2)+'DCF Model'!F45/(1+$B13)^('DCF Model'!C19+3)+'DCF Model'!G45/(1+$B13)^('DCF Model'!C19+4)+'DCF Model'!G45*(1+G$6)/($B13-G$6)/(1+$B13)^('DCF Model'!C19+4)-'DCF Model'!C16)*1000000/'DCF Model'!C15,0),"") -> 2365 | H13: =IFERROR(ROUND(('DCF Model'!C45/(1+$B13)^('DCF Model'!C19+0)+'DCF Model'!D45/(1+$B13)^('DCF Model'!C19+1)+'DCF Model'!E45/(1+$B13)^('DCF Model'!C19+2)+'DCF Model'!F45/(1+$B13)^('DCF Model'!C19+3)+'DCF Model'!G45/(1+$B13)^('DCF Model'!C19+4)+'DCF Model'!G45*(1+H$6)/($B13-H$6)/(1+$B13)^('DCF Model'!C19+4)-'DCF Model'!C16)*1000000/'DCF Model'!C15,0),"") -> 2409 | I13: =IFERROR(ROUND(('DCF Model'!C45/(1+$B13)^('DCF Model'!C19+0)+'DCF Model'!D45/(1+$B13)^('DCF Model'!C19+1)+'DCF Model'!E45/(1+$B13)^('DCF Model'!C19+2)+'DCF Model'!F45/(1+$B13)^('DCF Model'!C19+3)+'DCF Model'!G45/(1+$B13)^('DCF Model'!C19+4)+'DCF Model'!G45*(1+I$6)/($B13-I$6)/(1+$B13)^('DCF Model'!C19+4)-'DCF Model'!C16)*1000000/'DCF Model'!C15,0),"") -> 2455
B16: Table 2: WACC vs Exit Multiple (Exit Multiple - Implied Share Price, JPY)
B17: WACC \ Exit Multiple | C17: =$I$3-3 -> 9 | D17: =$I$3-2 -> 10 | E17: =$I$3-1 -> 11 | F17: =$I$3 -> 12 | G17: =$I$3+1 -> 13 | H17: =$I$3+2 -> 14 | I17: =$I$3+3 -> 15
B18: =$C$3-0.015 -> 0.059 | C18: =IFERROR(ROUND(('DCF Model'!C45/(1+$B18)^('DCF Model'!C19+0)+'DCF Model'!D45/(1+$B18)^('DCF Model'!C19+1)+'DCF Model'!E45/(1+$B18)^('DCF Model'!C19+2)+'DCF Model'!F45/(1+$B18)^('DCF Model'!C19+3)+'DCF Model'!G45/(1+$B18)^('DCF Model'!C19+4)+('DCF Model'!G39+'DCF Model'!G42)*C$17/(1+$B18)^('DCF Model'!C19+4)-'DCF Model'!C16)*1000000/'DCF Model'!C15,0),"") -> 4150 | D18: =IFERROR(ROUND(('DCF Model'!C45/(1+$B18)^('DCF Model'!C19+0)+'DCF Model'!D45/(1+$B18)^('DCF Model'!C19+1)+'DCF Model'!E45/(1+$B18)^('DCF Model'!C19+2)+'DCF Model'!F45/(1+$B18)^('DCF Model'!C19+3)+'DCF Model'!G45/(1+$B18)^('DCF Model'!C19+4)+('DCF Model'!G39+'DCF Model'!G42)*D$17/(1+$B18)^('DCF Model'!C19+4)-'DCF Model'!C16)*1000000/'DCF Model'!C15,0),"") -> 4476 | E18: =IFERROR(ROUND(('DCF Model'!C45/(1+$B18)^('DCF Model'!C19+0)+'DCF Model'!D45/(1+$B18)^('DCF Model'!C19+1)+'DCF Model'!E45/(1+$B18)^('DCF Model'!C19+2)+'DCF Model'!F45/(1+$B18)^('DCF Model'!C19+3)+'DCF Model'!G45/(1+$B18)^('DCF Model'!C19+4)+('DCF Model'!G39+'DCF Model'!G42)*E$17/(1+$B18)^('DCF Model'!C19+4)-'DCF Model'!C16)*1000000/'DCF Model'!C15,0),"") -> 4802 | F18: =IFERROR(ROUND(('DCF Model'!C45/(1+$B18)^('DCF Model'!C19+0)+'DCF Model'!D45/(1+$B18)^('DCF Model'!C19+1)+'DCF Model'!E45/(1+$B18)^('DCF Model'!C19+2)+'DCF Model'!F45/(1+$B18)^('DCF Model'!C19+3)+'DCF Model'!G45/(1+$B18)^('DCF Model'!C19+4)+('DCF Model'!G39+'DCF Model'!G42)*F$17/(1+$B18)^('DCF Model'!C19+4)-'DCF Model'!C16)*1000000/'DCF Model'!C15,0),"") -> 5129 | G18: =IFERROR(ROUND(('DCF Model'!C45/(1+$B18)^('DCF Model'!C19+0)+'DCF Model'!D45/(1+$B18)^('DCF Model'!C19+1)+'DCF Model'!E45/(1+$B18)^('DCF Model'!C19+2)+'DCF Model'!F45/(1+$B18)^('DCF Model'!C19+3)+'DCF Model'!G45/(1+$B18)^('DCF Model'!C19+4)+('DCF Model'!G39+'DCF Model'!G42)*G$17/(1+$B18)^('DCF Model'!C19+4)-'DCF Model'!C16)*1000000/'DCF Model'!C15,0),"") -> 5455 | H18: =IFERROR(ROUND(('DCF Model'!C45/(1+$B18)^('DCF Model'!C19+0)+'DCF Model'!D45/(1+$B18)^('DCF Model'!C19+1)+'DCF Model'!E45/(1+$B18)^('DCF Model'!C19+2)+'DCF Model'!F45/(1+$B18)^('DCF Model'!C19+3)+'DCF Model'!G45/(1+$B18)^('DCF Model'!C19+4)+('DCF Model'!G39+'DCF Model'!G42)*H$17/(1+$B18)^('DCF Model'!C19+4)-'DCF Model'!C16)*1000000/'DCF Model'!C15,0),"") -> 5781 | I18: =IFERROR(ROUND(('DCF Model'!C45/(1+$B18)^('DCF Model'!C19+0)+'DCF Model'!D45/(1+$B18)^('DCF Model'!C19+1)+'DCF Model'!E45/(1+$B18)^('DCF Model'!C19+2)+'DCF Model'!F45/(1+$B18)^('DCF Model'!C19+3)+'DCF Model'!G45/(1+$B18)^('DCF Model'!C19+4)+('DCF Model'!G39+'DCF Model'!G42)*I$17/(1+$B18)^('DCF Model'!C19+4)-'DCF Model'!C16)*1000000/'DCF Model'!C15,0),"") -> 6107
B19: =$C$3-0.01 -> 0.064 | C19: =IFERROR(ROUND(('DCF Model'!C45/(1+$B19)^('DCF Model'!C19+0)+'DCF Model'!D45/(1+$B19)^('DCF Model'!C19+1)+'DCF Model'!E45/(1+$B19)^('DCF Model'!C19+2)+'DCF Model'!F45/(1+$B19)^('DCF Model'!C19+3)+'DCF Model'!G45/(1+$B19)^('DCF Model'!C19+4)+('DCF Model'!G39+'DCF Model'!G42)*C$17/(1+$B19)^('DCF Model'!C19+4)-'DCF Model'!C16)*1000000/'DCF Model'!C15,0),"") -> 4074 | D19: =IFERROR(ROUND(('DCF Model'!C45/(1+$B19)^('DCF Model'!C19+0)+'DCF Model'!D45/(1+$B19)^('DCF Model'!C19+1)+'DCF Model'!E45/(1+$B19)^('DCF Model'!C19+2)+'DCF Model'!F45/(1+$B19)^('DCF Model'!C19+3)+'DCF Model'!G45/(1+$B19)^('DCF Model'!C19+4)+('DCF Model'!G39+'DCF Model'!G42)*D$17/(1+$B19)^('DCF Model'!C19+4)-'DCF Model'!C16)*1000000/'DCF Model'!C15,0),"") -> 4393 | E19: =IFERROR(ROUND(('DCF Model'!C45/(1+$B19)^('DCF Model'!C19+0)+'DCF Model'!D45/(1+$B19)^('DCF Model'!C19+1)+'DCF Model'!E45/(1+$B19)^('DCF Model'!C19+2)+'DCF Model'!F45/(1+$B19)^('DCF Model'!C19+3)+'DCF Model'!G45/(1+$B19)^('DCF Model'!C19+4)+('DCF Model'!G39+'DCF Model'!G42)*E$17/(1+$B19)^('DCF Model'!C19+4)-'DCF Model'!C16)*1000000/'DCF Model'!C15,0),"") -> 4712 | F19: =IFERROR(ROUND(('DCF Model'!C45/(1+$B19)^('DCF Model'!C19+0)+'DCF Model'!D45/(1+$B19)^('DCF Model'!C19+1)+'DCF Model'!E45/(1+$B19)^('DCF Model'!C19+2)+'DCF Model'!F45/(1+$B19)^('DCF Model'!C19+3)+'DCF Model'!G45/(1+$B19)^('DCF Model'!C19+4)+('DCF Model'!G39+'DCF Model'!G42)*F$17/(1+$B19)^('DCF Model'!C19+4)-'DCF Model'!C16)*1000000/'DCF Model'!C15,0),"") -> 5030 | G19: =IFERROR(ROUND(('DCF Model'!C45/(1+$B19)^('DCF Model'!C19+0)+'DCF Model'!D45/(1+$B19)^('DCF Model'!C19+1)+'DCF Model'!E45/(1+$B19)^('DCF Model'!C19+2)+'DCF Model'!F45/(1+$B19)^('DCF Model'!C19+3)+'DCF Model'!G45/(1+$B19)^('DCF Model'!C19+4)+('DCF Model'!G39+'DCF Model'!G42)*G$17/(1+$B19)^('DCF Model'!C19+4)-'DCF Model'!C16)*1000000/'DCF Model'!C15,0),"") -> 5349 | H19: =IFERROR(ROUND(('DCF Model'!C45/(1+$B19)^('DCF Model'!C19+0)+'DCF Model'!D45/(1+$B19)^('DCF Model'!C19+1)+'DCF Model'!E45/(1+$B19)^('DCF Model'!C19+2)+'DCF Model'!F45/(1+$B19)^('DCF Model'!C19+3)+'DCF Model'!G45/(1+$B19)^('DCF Model'!C19+4)+('DCF Model'!G39+'DCF Model'!G42)*H$17/(1+$B19)^('DCF Model'!C19+4)-'DCF Model'!C16)*1000000/'DCF Model'!C15,0),"") -> 5668 | I19: =IFERROR(ROUND(('DCF Model'!C45/(1+$B19)^('DCF Model'!C19+0)+'DCF Model'!D45/(1+$B19)^('DCF Model'!C19+1)+'DCF Model'!E45/(1+$B19)^('DCF Model'!C19+2)+'DCF Model'!F45/(1+$B19)^('DCF Model'!C19+3)+'DCF Model'!G45/(1+$B19)^('DCF Model'!C19+4)+('DCF Model'!G39+'DCF Model'!G42)*I$17/(1+$B19)^('DCF Model'!C19+4)-'DCF Model'!C16)*1000000/'DCF Model'!C15,0),"") -> 5987
B20: =$C$3-0.005 -> 0.069 | C20: =IFERROR(ROUND(('DCF Model'!C45/(1+$B20)^('DCF Model'!C19+0)+'DCF Model'!D45/(1+$B20)^('DCF Model'!C19+1)+'DCF Model'!E45/(1+$B20)^('DCF Model'!C19+2)+'DCF Model'!F45/(1+$B20)^('DCF Model'!C19+3)+'DCF Model'!G45/(1+$B20)^('DCF Model'!C19+4)+('DCF Model'!G39+'DCF Model'!G42)*C$17/(1+$B20)^('DCF Model'!C19+4)-'DCF Model'!C16)*1000000/'DCF Model'!C15,0),"") -> 4001 | D20: =IFERROR(ROUND(('DCF Model'!C45/(1+$B20)^('DCF Model'!C19+0)+'DCF Model'!D45/(1+$B20)^('DCF Model'!C19+1)+'DCF Model'!E45/(1+$B20)^('DCF Model'!C19+2)+'DCF Model'!F45/(1+$B20)^('DCF Model'!C19+3)+'DCF Model'!G45/(1+$B20)^('DCF Model'!C19+4)+('DCF Model'!G39+'DCF Model'!G42)*D$17/(1+$B20)^('DCF Model'!C19+4)-'DCF Model'!C16)*1000000/'DCF Model'!C15,0),"") -> 4313 | E20: =IFERROR(ROUND(('DCF Model'!C45/(1+$B20)^('DCF Model'!C19+0)+'DCF Model'!D45/(1+$B20)^('DCF Model'!C19+1)+'DCF Model'!E45/(1+$B20)^('DCF Model'!C19+2)+'DCF Model'!F45/(1+$B20)^('DCF Model'!C19+3)+'DCF Model'!G45/(1+$B20)^('DCF Model'!C19+4)+('DCF Model'!G39+'DCF Model'!G42)*E$17/(1+$B20)^('DCF Model'!C19+4)-'DCF Model'!C16)*1000000/'DCF Model'!C15,0),"") -> 4624 | F20: =IFERROR(ROUND(('DCF Model'!C45/(1+$B20)^('DCF Model'!C19+0)+'DCF Model'!D45/(1+$B20)^('DCF Model'!C19+1)+'DCF Model'!E45/(1+$B20)^('DCF Model'!C19+2)+'DCF Model'!F45/(1+$B20)^('DCF Model'!C19+3)+'DCF Model'!G45/(1+$B20)^('DCF Model'!C19+4)+('DCF Model'!G39+'DCF Model'!G42)*F$17/(1+$B20)^('DCF Model'!C19+4)-'DCF Model'!C16)*1000000/'DCF Model'!C15,0),"") -> 4935 | G20: =IFERROR(ROUND(('DCF Model'!C45/(1+$B20)^('DCF Model'!C19+0)+'DCF Model'!D45/(1+$B20)^('DCF Model'!C19+1)+'DCF Model'!E45/(1+$B20)^('DCF Model'!C19+2)+'DCF Model'!F45/(1+$B20)^('DCF Model'!C19+3)+'DCF Model'!G45/(1+$B20)^('DCF Model'!C19+4)+('DCF Model'!G39+'DCF Model'!G42)*G$17/(1+$B20)^('DCF Model'!C19+4)-'DCF Model'!C16)*1000000/'DCF Model'!C15,0),"") -> 5246 | H20: =IFERROR(ROUND(('DCF Model'!C45/(1+$B20)^('DCF Model'!C19+0)+'DCF Model'!D45/(1+$B20)^('DCF Model'!C19+1)+'DCF Model'!E45/(1+$B20)^('DCF Model'!C19+2)+'DCF Model'!F45/(1+$B20)^('DCF Model'!C19+3)+'DCF Model'!G45/(1+$B20)^('DCF Model'!C19+4)+('DCF Model'!G39+'DCF Model'!G42)*H$17/(1+$B20)^('DCF Model'!C19+4)-'DCF Model'!C16)*1000000/'DCF Model'!C15,0),"") -> 5558 | I20: =IFERROR(ROUND(('DCF Model'!C45/(1+$B20)^('DCF Model'!C19+0)+'DCF Model'!D45/(1+$B20)^('DCF Model'!C19+1)+'DCF Model'!E45/(1+$B20)^('DCF Model'!C19+2)+'DCF Model'!F45/(1+$B20)^('DCF Model'!C19+3)+'DCF Model'!G45/(1+$B20)^('DCF Model'!C19+4)+('DCF Model'!G39+'DCF Model'!G42)*I$17/(1+$B20)^('DCF Model'!C19+4)-'DCF Model'!C16)*1000000/'DCF Model'!C15,0),"") -> 5869
B21: =$C$3 -> 0.074 | C21: =IFERROR(ROUND(('DCF Model'!C45/(1+$B21)^('DCF Model'!C19+0)+'DCF Model'!D45/(1+$B21)^('DCF Model'!C19+1)+'DCF Model'!E45/(1+$B21)^('DCF Model'!C19+2)+'DCF Model'!F45/(1+$B21)^('DCF Model'!C19+3)+'DCF Model'!G45/(1+$B21)^('DCF Model'!C19+4)+('DCF Model'!G39+'DCF Model'!G42)*C$17/(1+$B21)^('DCF Model'!C19+4)-'DCF Model'!C16)*1000000/'DCF Model'!C15,0),"") -> 3930 | D21: =IFERROR(ROUND(('DCF Model'!C45/(1+$B21)^('DCF Model'!C19+0)+'DCF Model'!D45/(1+$B21)^('DCF Model'!C19+1)+'DCF Model'!E45/(1+$B21)^('DCF Model'!C19+2)+'DCF Model'!F45/(1+$B21)^('DCF Model'!C19+3)+'DCF Model'!G45/(1+$B21)^('DCF Model'!C19+4)+('DCF Model'!G39+'DCF Model'!G42)*D$17/(1+$B21)^('DCF Model'!C19+4)-'DCF Model'!C16)*1000000/'DCF Model'!C15,0),"") -> 4234 | E21: =IFERROR(ROUND(('DCF Model'!C45/(1+$B21)^('DCF Model'!C19+0)+'DCF Model'!D45/(1+$B21)^('DCF Model'!C19+1)+'DCF Model'!E45/(1+$B21)^('DCF Model'!C19+2)+'DCF Model'!F45/(1+$B21)^('DCF Model'!C19+3)+'DCF Model'!G45/(1+$B21)^('DCF Model'!C19+4)+('DCF Model'!G39+'DCF Model'!G42)*E$17/(1+$B21)^('DCF Model'!C19+4)-'DCF Model'!C16)*1000000/'DCF Model'!C15,0),"") -> 4538 | F21: =IFERROR(ROUND(('DCF Model'!C45/(1+$B21)^('DCF Model'!C19+0)+'DCF Model'!D45/(1+$B21)^('DCF Model'!C19+1)+'DCF Model'!E45/(1+$B21)^('DCF Model'!C19+2)+'DCF Model'!F45/(1+$B21)^('DCF Model'!C19+3)+'DCF Model'!G45/(1+$B21)^('DCF Model'!C19+4)+('DCF Model'!G39+'DCF Model'!G42)*F$17/(1+$B21)^('DCF Model'!C19+4)-'DCF Model'!C16)*1000000/'DCF Model'!C15,0),"") -> 4842 | G21: =IFERROR(ROUND(('DCF Model'!C45/(1+$B21)^('DCF Model'!C19+0)+'DCF Model'!D45/(1+$B21)^('DCF Model'!C19+1)+'DCF Model'!E45/(1+$B21)^('DCF Model'!C19+2)+'DCF Model'!F45/(1+$B21)^('DCF Model'!C19+3)+'DCF Model'!G45/(1+$B21)^('DCF Model'!C19+4)+('DCF Model'!G39+'DCF Model'!G42)*G$17/(1+$B21)^('DCF Model'!C19+4)-'DCF Model'!C16)*1000000/'DCF Model'!C15,0),"") -> 5146 | H21: =IFERROR(ROUND(('DCF Model'!C45/(1+$B21)^('DCF Model'!C19+0)+'DCF Model'!D45/(1+$B21)^('DCF Model'!C19+1)+'DCF Model'!E45/(1+$B21)^('DCF Model'!C19+2)+'DCF Model'!F45/(1+$B21)^('DCF Model'!C19+3)+'DCF Model'!G45/(1+$B21)^('DCF Model'!C19+4)+('DCF Model'!G39+'DCF Model'!G42)*H$17/(1+$B21)^('DCF Model'!C19+4)-'DCF Model'!C16)*1000000/'DCF Model'!C15,0),"") -> 5451 | I21: =IFERROR(ROUND(('DCF Model'!C45/(1+$B21)^('DCF Model'!C19+0)+'DCF Model'!D45/(1+$B21)^('DCF Model'!C19+1)+'DCF Model'!E45/(1+$B21)^('DCF Model'!C19+2)+'DCF Model'!F45/(1+$B21)^('DCF Model'!C19+3)+'DCF Model'!G45/(1+$B21)^('DCF Model'!C19+4)+('DCF Model'!G39+'DCF Model'!G42)*I$17/(1+$B21)^('DCF Model'!C19+4)-'DCF Model'!C16)*1000000/'DCF Model'!C15,0),"") -> 5755
B22: =$C$3+0.005 -> 0.079 | C22: =IFERROR(ROUND(('DCF Model'!C45/(1+$B22)^('DCF Model'!C19+0)+'DCF Model'!D45/(1+$B22)^('DCF Model'!C19+1)+'DCF Model'!E45/(1+$B22)^('DCF Model'!C19+2)+'DCF Model'!F45/(1+$B22)^('DCF Model'!C19+3)+'DCF Model'!G45/(1+$B22)^('DCF Model'!C19+4)+('DCF Model'!G39+'DCF Model'!G42)*C$17/(1+$B22)^('DCF Model'!C19+4)-'DCF Model'!C16)*1000000/'DCF Model'!C15,0),"") -> 3861 | D22: =IFERROR(ROUND(('DCF Model'!C45/(1+$B22)^('DCF Model'!C19+0)+'DCF Model'!D45/(1+$B22)^('DCF Model'!C19+1)+'DCF Model'!E45/(1+$B22)^('DCF Model'!C19+2)+'DCF Model'!F45/(1+$B22)^('DCF Model'!C19+3)+'DCF Model'!G45/(1+$B22)^('DCF Model'!C19+4)+('DCF Model'!G39+'DCF Model'!G42)*D$17/(1+$B22)^('DCF Model'!C19+4)-'DCF Model'!C16)*1000000/'DCF Model'!C15,0),"") -> 4158 | E22: =IFERROR(ROUND(('DCF Model'!C45/(1+$B22)^('DCF Model'!C19+0)+'DCF Model'!D45/(1+$B22)^('DCF Model'!C19+1)+'DCF Model'!E45/(1+$B22)^('DCF Model'!C19+2)+'DCF Model'!F45/(1+$B22)^('DCF Model'!C19+3)+'DCF Model'!G45/(1+$B22)^('DCF Model'!C19+4)+('DCF Model'!G39+'DCF Model'!G42)*E$17/(1+$B22)^('DCF Model'!C19+4)-'DCF Model'!C16)*1000000/'DCF Model'!C15,0),"") -> 4455 | F22: =IFERROR(ROUND(('DCF Model'!C45/(1+$B22)^('DCF Model'!C19+0)+'DCF Model'!D45/(1+$B22)^('DCF Model'!C19+1)+'DCF Model'!E45/(1+$B22)^('DCF Model'!C19+2)+'DCF Model'!F45/(1+$B22)^('DCF Model'!C19+3)+'DCF Model'!G45/(1+$B22)^('DCF Model'!C19+4)+('DCF Model'!G39+'DCF Model'!G42)*F$17/(1+$B22)^('DCF Model'!C19+4)-'DCF Model'!C16)*1000000/'DCF Model'!C15,0),"") -> 4752 | G22: =IFERROR(ROUND(('DCF Model'!C45/(1+$B22)^('DCF Model'!C19+0)+'DCF Model'!D45/(1+$B22)^('DCF Model'!C19+1)+'DCF Model'!E45/(1+$B22)^('DCF Model'!C19+2)+'DCF Model'!F45/(1+$B22)^('DCF Model'!C19+3)+'DCF Model'!G45/(1+$B22)^('DCF Model'!C19+4)+('DCF Model'!G39+'DCF Model'!G42)*G$17/(1+$B22)^('DCF Model'!C19+4)-'DCF Model'!C16)*1000000/'DCF Model'!C15,0),"") -> 5049 | H22: =IFERROR(ROUND(('DCF Model'!C45/(1+$B22)^('DCF Model'!C19+0)+'DCF Model'!D45/(1+$B22)^('DCF Model'!C19+1)+'DCF Model'!E45/(1+$B22)^('DCF Model'!C19+2)+'DCF Model'!F45/(1+$B22)^('DCF Model'!C19+3)+'DCF Model'!G45/(1+$B22)^('DCF Model'!C19+4)+('DCF Model'!G39+'DCF Model'!G42)*H$17/(1+$B22)^('DCF Model'!C19+4)-'DCF Model'!C16)*1000000/'DCF Model'!C15,0),"") -> 5346 | I22: =IFERROR(ROUND(('DCF Model'!C45/(1+$B22)^('DCF Model'!C19+0)+'DCF Model'!D45/(1+$B22)^('DCF Model'!C19+1)+'DCF Model'!E45/(1+$B22)^('DCF Model'!C19+2)+'DCF Model'!F45/(1+$B22)^('DCF Model'!C19+3)+'DCF Model'!G45/(1+$B22)^('DCF Model'!C19+4)+('DCF Model'!G39+'DCF Model'!G42)*I$17/(1+$B22)^('DCF Model'!C19+4)-'DCF Model'!C16)*1000000/'DCF Model'!C15,0),"") -> 5644
B23: =$C$3+0.01 -> 0.084 | C23: =IFERROR(ROUND(('DCF Model'!C45/(1+$B23)^('DCF Model'!C19+0)+'DCF Model'!D45/(1+$B23)^('DCF Model'!C19+1)+'DCF Model'!E45/(1+$B23)^('DCF Model'!C19+2)+'DCF Model'!F45/(1+$B23)^('DCF Model'!C19+3)+'DCF Model'!G45/(1+$B23)^('DCF Model'!C19+4)+('DCF Model'!G39+'DCF Model'!G42)*C$17/(1+$B23)^('DCF Model'!C19+4)-'DCF Model'!C16)*1000000/'DCF Model'!C15,0),"") -> 3793 | D23: =IFERROR(ROUND(('DCF Model'!C45/(1+$B23)^('DCF Model'!C19+0)+'DCF Model'!D45/(1+$B23)^('DCF Model'!C19+1)+'DCF Model'!E45/(1+$B23)^('DCF Model'!C19+2)+'DCF Model'!F45/(1+$B23)^('DCF Model'!C19+3)+'DCF Model'!G45/(1+$B23)^('DCF Model'!C19+4)+('DCF Model'!G39+'DCF Model'!G42)*D$17/(1+$B23)^('DCF Model'!C19+4)-'DCF Model'!C16)*1000000/'DCF Model'!C15,0),"") -> 4084 | E23: =IFERROR(ROUND(('DCF Model'!C45/(1+$B23)^('DCF Model'!C19+0)+'DCF Model'!D45/(1+$B23)^('DCF Model'!C19+1)+'DCF Model'!E45/(1+$B23)^('DCF Model'!C19+2)+'DCF Model'!F45/(1+$B23)^('DCF Model'!C19+3)+'DCF Model'!G45/(1+$B23)^('DCF Model'!C19+4)+('DCF Model'!G39+'DCF Model'!G42)*E$17/(1+$B23)^('DCF Model'!C19+4)-'DCF Model'!C16)*1000000/'DCF Model'!C15,0),"") -> 4374 | F23: =IFERROR(ROUND(('DCF Model'!C45/(1+$B23)^('DCF Model'!C19+0)+'DCF Model'!D45/(1+$B23)^('DCF Model'!C19+1)+'DCF Model'!E45/(1+$B23)^('DCF Model'!C19+2)+'DCF Model'!F45/(1+$B23)^('DCF Model'!C19+3)+'DCF Model'!G45/(1+$B23)^('DCF Model'!C19+4)+('DCF Model'!G39+'DCF Model'!G42)*F$17/(1+$B23)^('DCF Model'!C19+4)-'DCF Model'!C16)*1000000/'DCF Model'!C15,0),"") -> 4664 | G23: =IFERROR(ROUND(('DCF Model'!C45/(1+$B23)^('DCF Model'!C19+0)+'DCF Model'!D45/(1+$B23)^('DCF Model'!C19+1)+'DCF Model'!E45/(1+$B23)^('DCF Model'!C19+2)+'DCF Model'!F45/(1+$B23)^('DCF Model'!C19+3)+'DCF Model'!G45/(1+$B23)^('DCF Model'!C19+4)+('DCF Model'!G39+'DCF Model'!G42)*G$17/(1+$B23)^('DCF Model'!C19+4)-'DCF Model'!C16)*1000000/'DCF Model'!C15,0),"") -> 4955 | H23: =IFERROR(ROUND(('DCF Model'!C45/(1+$B23)^('DCF Model'!C19+0)+'DCF Model'!D45/(1+$B23)^('DCF Model'!C19+1)+'DCF Model'!E45/(1+$B23)^('DCF Model'!C19+2)+'DCF Model'!F45/(1+$B23)^('DCF Model'!C19+3)+'DCF Model'!G45/(1+$B23)^('DCF Model'!C19+4)+('DCF Model'!G39+'DCF Model'!G42)*H$17/(1+$B23)^('DCF Model'!C19+4)-'DCF Model'!C16)*1000000/'DCF Model'!C15,0),"") -> 5245 | I23: =IFERROR(ROUND(('DCF Model'!C45/(1+$B23)^('DCF Model'!C19+0)+'DCF Model'!D45/(1+$B23)^('DCF Model'!C19+1)+'DCF Model'!E45/(1+$B23)^('DCF Model'!C19+2)+'DCF Model'!F45/(1+$B23)^('DCF Model'!C19+3)+'DCF Model'!G45/(1+$B23)^('DCF Model'!C19+4)+('DCF Model'!G39+'DCF Model'!G42)*I$17/(1+$B23)^('DCF Model'!C19+4)-'DCF Model'!C16)*1000000/'DCF Model'!C15,0),"") -> 5535
B24: =$C$3+0.015 -> 0.089 | C24: =IFERROR(ROUND(('DCF Model'!C45/(1+$B24)^('DCF Model'!C19+0)+'DCF Model'!D45/(1+$B24)^('DCF Model'!C19+1)+'DCF Model'!E45/(1+$B24)^('DCF Model'!C19+2)+'DCF Model'!F45/(1+$B24)^('DCF Model'!C19+3)+'DCF Model'!G45/(1+$B24)^('DCF Model'!C19+4)+('DCF Model'!G39+'DCF Model'!G42)*C$17/(1+$B24)^('DCF Model'!C19+4)-'DCF Model'!C16)*1000000/'DCF Model'!C15,0),"") -> 3728 | D24: =IFERROR(ROUND(('DCF Model'!C45/(1+$B24)^('DCF Model'!C19+0)+'DCF Model'!D45/(1+$B24)^('DCF Model'!C19+1)+'DCF Model'!E45/(1+$B24)^('DCF Model'!C19+2)+'DCF Model'!F45/(1+$B24)^('DCF Model'!C19+3)+'DCF Model'!G45/(1+$B24)^('DCF Model'!C19+4)+('DCF Model'!G39+'DCF Model'!G42)*D$17/(1+$B24)^('DCF Model'!C19+4)-'DCF Model'!C16)*1000000/'DCF Model'!C15,0),"") -> 4011 | E24: =IFERROR(ROUND(('DCF Model'!C45/(1+$B24)^('DCF Model'!C19+0)+'DCF Model'!D45/(1+$B24)^('DCF Model'!C19+1)+'DCF Model'!E45/(1+$B24)^('DCF Model'!C19+2)+'DCF Model'!F45/(1+$B24)^('DCF Model'!C19+3)+'DCF Model'!G45/(1+$B24)^('DCF Model'!C19+4)+('DCF Model'!G39+'DCF Model'!G42)*E$17/(1+$B24)^('DCF Model'!C19+4)-'DCF Model'!C16)*1000000/'DCF Model'!C15,0),"") -> 4295 | F24: =IFERROR(ROUND(('DCF Model'!C45/(1+$B24)^('DCF Model'!C19+0)+'DCF Model'!D45/(1+$B24)^('DCF Model'!C19+1)+'DCF Model'!E45/(1+$B24)^('DCF Model'!C19+2)+'DCF Model'!F45/(1+$B24)^('DCF Model'!C19+3)+'DCF Model'!G45/(1+$B24)^('DCF Model'!C19+4)+('DCF Model'!G39+'DCF Model'!G42)*F$17/(1+$B24)^('DCF Model'!C19+4)-'DCF Model'!C16)*1000000/'DCF Model'!C15,0),"") -> 4579 | G24: =IFERROR(ROUND(('DCF Model'!C45/(1+$B24)^('DCF Model'!C19+0)+'DCF Model'!D45/(1+$B24)^('DCF Model'!C19+1)+'DCF Model'!E45/(1+$B24)^('DCF Model'!C19+2)+'DCF Model'!F45/(1+$B24)^('DCF Model'!C19+3)+'DCF Model'!G45/(1+$B24)^('DCF Model'!C19+4)+('DCF Model'!G39+'DCF Model'!G42)*G$17/(1+$B24)^('DCF Model'!C19+4)-'DCF Model'!C16)*1000000/'DCF Model'!C15,0),"") -> 4863 | H24: =IFERROR(ROUND(('DCF Model'!C45/(1+$B24)^('DCF Model'!C19+0)+'DCF Model'!D45/(1+$B24)^('DCF Model'!C19+1)+'DCF Model'!E45/(1+$B24)^('DCF Model'!C19+2)+'DCF Model'!F45/(1+$B24)^('DCF Model'!C19+3)+'DCF Model'!G45/(1+$B24)^('DCF Model'!C19+4)+('DCF Model'!G39+'DCF Model'!G42)*H$17/(1+$B24)^('DCF Model'!C19+4)-'DCF Model'!C16)*1000000/'DCF Model'!C15,0),"") -> 5146 | I24: =IFERROR(ROUND(('DCF Model'!C45/(1+$B24)^('DCF Model'!C19+0)+'DCF Model'!D45/(1+$B24)^('DCF Model'!C19+1)+'DCF Model'!E45/(1+$B24)^('DCF Model'!C19+2)+'DCF Model'!F45/(1+$B24)^('DCF Model'!C19+3)+'DCF Model'!G45/(1+$B24)^('DCF Model'!C19+4)+('DCF Model'!G39+'DCF Model'!G42)*I$17/(1+$B24)^('DCF Model'!C19+4)-'DCF Model'!C16)*1000000/'DCF Model'!C15,0),"") -> 5430
B26: All values dynamically linked to DCF Model. Headers auto-center on current WACC / Terminal g / Exit Multiple.

Sheet Adjustments Log
B2: Manual Adjustments Log — 7203 Toyota automotive DCF (finalised 2026-07-30)
B4: # | C4: Sheet / Cell | D4: Was | E4: Now | F4: Why / Source
B5: 2 | C5: Comps!D15:I17 | D5: PERCENTILE/MEDIAN(x5:x11) | E5: (x6:x11) | F5: Statistics included Toyota itself. The PER median resolved to Toyota's own 10.6558x (MEDIAN skips the "N/A" text in Honda and Ford rows, leaving 5 numeric values with Toyota in the middle), so Comps-PER implied price came out at 3,152 - identical to the market price by construction, and that tautology fed the Target Price average. Now peers only.
B6: 4 | C6: FS!C19:F19, C26:F27, labels B19-B28 | D6: see col C | E6: 短信 actuals | F6: EDINET residuals: OCF read 0 / 0 / BLANK / BLANK; Cash read 3,996,258 / 5,828,255 / BLANK / BLANK; Short-term Debt read 1,133,917 / 1,326,877 / 0 / 0. FCF therefore showed -1,798,476 to -2,526,996 across all four years for a company with 5,472,920 of operating cash flow, and Net Debt showed 0 for the two latest years. Replaced with consolidated actuals: OCF 2,955,076 / 4,206,373 / 3,696,934 / 5,472,920; Cash 7,516,966 / 9,412,060 / 8,982,404 / 12,659,622; Total interest-bearing debt 29,380,273 / 36,561,780 / 38,792,879 / 43,205,469. Rows relabelled (consol.) vs (automotive) and four source/warning notes added at B30:B33.
B7: 5 | C7: Exec Summary!B30, B31 | D7: 1,435,511 / 60% | E7: 1,472,087 / 61.5% | F7: Thesis text quoted the original 60% D&A split, but Comps!C21 (core_ebitda) = 3,499,094 = automotive OI 2,027,007 + D&A 1,472,087, i.e. 61.53% of consolidated D&A 2,392,519. Text now matches the model. The "10-point shift moves EBITDA by ~240,000" statement remains valid (10% of 2,392,519 = 239,252).
B8: 6 | C8: DCF!C20 (LTM Revenue) | D8: 18,259,979 | E8: 45,865,949 | F8: Matched neither automotive revenue (45,865,949) nor consolidated (50,684,952) - an EDINET/yfinance residual. LTM = FY2026/3 automotive actual as of 2026-07-30. Reference cell only; stub fraction is 1.0 so no valuation effect.
B9: 7 | C9: DCF!C5, C18 | D9: 5.887% / 3.667% | E9: 5.510% / 3.210% | F9: Both had been back-solved from the YEAR 3 projections (2,700,000 and 1,681,787 over base revenue) rather than from actuals. These are revenue_pct FALLBACKS and are unused because capex/D&A run on the direct method (rows 42-43 hold absolute values). Corrected to automotive FY2026/3 actuals: capex 2,526,996 and D&A 1,472,087 over 45,865,949.
C10: NOT CHANGED — per instruction (option B) | F10: (1) The 745/share non-operating add-back (finance-business equity ~4,350,000 = 334/sh, equity-method investments 5,342,548 = 411/sh) is still absent from C16:C19. The DCF values the automotive business only but is compared with a whole-company share price, so PGM 2,716 understates by construction; with the add-back it would be 3,461 (+9.8% vs 3,152 rather than -13.8%). (3) The Comps EV/EBITDA line still applies a CONSOLIDATED peer multiple to AUTOMOTIVE EBITDA with AUTOMOTIVE net debt - bases are mixed and EV/EBITDA is structurally broken for OEMs with captive finance (peer range 4.44x Suzuki to 16.52x Honda is driven by how much finance debt sits in EV, not by valuation).
C11: OPEN ITEM — judgement, left alone | D11: DCF!C14 = 12.0x | F11: The PGM terminal value implies 28,306,844 / Year-5 EBITDA 5,653,320 = 5.01x, so 5.01x and 12.0x coexist in one model (PGM 2,716 vs Exit 4,842, a 78% gap). Mass-market OEM industrial segments trade 2-4x (GM/Ford); market-implied Toyota automotive is ~6.2x. At 6x Exit gives 3,018; at 7x, 3,322.
C12: OPEN ITEM — peer set at trough | D12: Comps rows 6-11 | F12: Operating margins: Honda -1.90%, Ford -4.90%, SUBARU 0.98%, GM 1.57%, VW 2.75%; only Suzuki (9.61%) and Toyota (7.43%) are near normal. Tariffs and EV write-downs hit the whole sector in FY2026, so both the PER and EV/EBITDA medians need normalising. Honda guides FY2027/3 OP of 500,000 (1,000,000 excluding further EV losses).
