Workbook

Sheet Executive Summary
B1: DISCLAIMER: This is a sample analysis for demonstration purposes only. It does not constitute investment advice.
B3: イオン株式会社 (8267.T)
B4: Equity Research Report
B6: Company | C6: イオン株式会社
B7: Ticker | C7: 8267.T (TSE)
B8: Sector | C8: Retail holding company (GMS/SM/drugstore/mall/finance/services)
B9: Current Price | C9: 1424
B10: Target Price (Mid) | C10: =ROUND(AVERAGE(C16:C19),0) -> 447
B11: Recommendation | C11: =IF(C12>0.15,"BUY",IF(C12>0.05,"HOLD","SELL")) -> SELL
B12: Upside / Downside | C12: =(C10-C9)/C9 -> -0.68609551
B14: Valuation Summary
B15: Methodology | C15: Implied Value (JPY) | D15: vs Current Price
B16: DCF - Perpetuity Growth | C16: ='DCF Model'!C55 -> -168 | D16: =(C16-C9)/C9 -> -1.1179775
B17: DCF - Exit Multiple | C17: ='DCF Model'!C64 -> 657 | D17: =(C17-C9)/C9 -> -0.5386236
B18: Comps - EV/EBITDA Median | C18: ='Comps Analysis'!C27 -> 772 | D18: =IF(ISNUMBER(C18),(C18-C9)/C9,"N/A") -> -0.45786517
B19: Comps - PER Median | C19: ='Comps Analysis'!C28 -> 527 | D19: =IF(ISNUMBER(C19),(C19-C9)/C9,"N/A") -> -0.62991573
B21: Integrated Valuation Range | C21: =MIN(C16:C19)&" - "&MAX(C16:C19) -> -168 - 772
B23: Key Investment Thesis
B24: 1. Operating profit is compounding but almost none of it reaches the parent. Operating income rose from 209,783 (FY2023/2) to 270,459 (FY2026/2) and is guided to 340,000 in FY2027/2 (+25.7%), yet guided parent net income is 73,000, up just 0.4%. Non-controlling interests took 51,858 of the 124,536 consolidated net income in FY2026/2. The investment case is entirely about whether Aeon can convert consolidated growth into parent-level value.
B25: 2. Drug-store consolidation is reshaping the group. The Tsuruha integration drove a 69,086 step-acquisition gain in FY2026/2 and underpins the guided 12.0% revenue jump to 12,000,000. Health & Wellness is now the growth engine alongside the developer business.
B26: 3. Low cost of capital supports a long-duration asset base. Interest expense of 51,376 on average interest-bearing debt of 4,140,937 is a 1.24% pre-tax cost, giving a WACC near 4.4%. For a business with 3,941,556 of property and 1,138,073 of land, cheap long-term funding is a genuine structural advantage.
B28: Key Risks
B29: 1. Minority interests are 984,094 at book, or 380 per share against a 1,424 price. Because the listed subsidiaries trade above book, the true economic deduction is larger than the balance sheet figure. Any consolidated valuation that omits this overstates the equity by more than a quarter.
B30: 2. Valuation already prices in the improvement. At 1,424 the shares trade at 3.03x book, 50.7x parent earnings and 11.90x consolidated EBITDA on a 2.52% operating margin. A retailer at 11.9x EBITDA leaves no room for the margin recovery to disappoint.
B31: 3. Impairment and leverage. FY2026/2 booked 97,486 of impairment losses with 270,803 of goodwill still on the balance sheet, and the effective tax rate has run 40-57% because much of that charge is not deductible. Interest-bearing debt of 4,449,206 against 1,218,421 of owners' equity means a small move in funding costs moves the WACC and the terminal value materially.

Sheet Financial Statements
B2: イオン株式会社 - Historical Financials (JPY mn)
C4: FY2023/2 | D4: FY2024/2 | E4: FY2025/2 | F4: FY2026/2
B5: Income Statement
B6: Revenue | C6: 9116823 | D6: 9553557 | E6: 10134877 | F6: 10715342
B7: COGS | C7: 5778894 | D7: 6007745 | E7: 6380141 | F7: 6804966
B8: Gross Profit | C8: =C6-C7 -> 3337929 | D8: =D6-D7 -> 3545812 | E8: =E6-E7 -> 3754736 | F8: =F6-F7 -> 3910376
B9: Gross Margin | C9: =C8/C6 -> 0.36612853 | D9: =D8/D6 -> 0.37115098 | E9: =E8/E6 -> 0.37047672 | F9: =F8/F6 -> 0.36493245
B10: SGA | C10: 3128145 | D10: 3294989 | E10: 3516989 | F10: 3639916
B11: Operating Income | C11: 209783 | D11: 250822 | E11: 237747 | F11: 270459
B12: Net Income | C12: 21381 | D12: 44692 | E12: 27168 | F12: 72677
B13: Operating Margin | C13: =C11/C6 -> 0.023010538 | D13: =D11/D6 -> 0.026254305 | E13: =E11/E6 -> 0.023458301 | F13: =F11/F6 -> 0.025240352
B14: Net Margin | C14: =C12/C6 -> 0.0023452249 | D14: =D12/D6 -> 0.0046780482 | E14: =E12/E6 -> 0.0026806443 | F14: =F12/F6 -> 0.006782518
B15: Revenue Growth (YoY) | C15: n/a | D15: =(D6-C6)/C6 -> 0.047904188 | E15: =(E6-D6)/D6 -> 0.06084854 | F15: =(F6-E6)/E6 -> 0.057274005
B16: Operating Income Growth (YoY) | C16: n/a | D16: =(D11-C11)/C11 -> 0.19562596 | E16: =(E11-D11)/D11 -> -0.052128601 | F16: =(F11-E11)/E11 -> 0.13759164
B18: Cash Flow Statement
B19: Operating Cash Flow | C19: 396461 | D19: 204452 | E19: 433710 | F19: 368487
B20: Capex | C20: 370848 | D20: 396236 | E20: 465958 | F20: 528536
B21: Free Cash Flow | C21: =C19-C20 -> 25613 | D21: =D19-D20 -> -191784 | E21: =E19-E20 -> -32248 | F21: =F19-F20 -> -160049
B22: FCF Margin | C22: =C21/C6 -> 0.0028094217 | D22: =D21/D6 -> -0.020074617 | E22: =E21/E6 -> -0.0031818837 | F22: =F21/F6 -> -0.014936434
B23: Capex / Revenue | C23: =C20/C6 -> 0.040677328 | D23: =D20/D6 -> 0.041475233 | E23: =E20/E6 -> 0.045975694 | F23: =F20/F6 -> 0.049325164
B25: Balance Sheet Highlights
B26: Cash & Deposits | C26: 1217054 | D26: 1090923 | E26: 1214462 | F26: 1064093
B27: Short-term Debt | C27: 2592194 | D27: 2602275 | E27: 2863648 | F27: 3030906
B28: Net Debt (Cash) | C28: =C27-C26 -> 1375140 | D28: =D27-D26 -> 1511352 | E28: =E27-E26 -> 1649186 | F28: =F27-F26 -> 1966813

Sheet DCF Model
B2: DCF Valuation Model - イオン株式会社
B4: Assumptions
B5: Capex / Revenue | C5: 0.051048301
B6: Effective Tax Rate | C6: 0.3062
B7: Risk-Free Rate | C7: 0.023
B8: Beta | C8: 0.8
B9: Equity Risk Premium | C9: 0.06
B10: Size Premium | C10: 0
B11: After-tax Cost of Debt | C11: 0.012
B12: D/E Ratio | C12: 0.8403
B13: Terminal Growth Rate | C13: 0.005
B14: Exit Multiple (EV/EBITDA) | C14: 8
B15: Fully Diluted Shares | C15: 2765768421
B16: Net Debt (JPY mn) | C16: 4083263
... B20: LTM Revenue (JPY mn) | C20: 9355439
B22: WACC Calculation
B23: Cost of Equity (Ke) | C23: =C7+C8*C9+C10 -> 0.071
B24: Weight of Equity | C24: =1/(1+C12) -> 0.54338966
B25: Weight of Debt | C25: =C12/(1+C12) -> 0.45661034
B26: WACC | C26: =C23*C24+C11*C25 -> 0.04405999
B27: Active Scenario | C27: Base | D27: 1
B28: Projected Free Cash Flow
C29: FY2027(E) | D29: FY2028(E) | E29: FY2029(E) | F29: FY2030(E) | G29: FY2031(E)
B30: Revenue Growth (YoY) | C30: =CHOOSE($D$27,C69,C70,C71,C72,C73) -> 0.08 | D30: =CHOOSE($D$27,D69,D70,D71,D72,D73) -> 0.04 | E30: =CHOOSE($D$27,E69,E70,E71,E72,E73) -> 0.03 | F30: =CHOOSE($D$27,F69,F70,F71,F72,F73) -> 0.025 | G30: =CHOOSE($D$27,G69,G70,G71,G72,G73) -> 0.02
B31: COGS % of Revenue | C31: =CHOOSE($D$27,C76,C77,C78,C79,C80) -> 0.634 | D31: =CHOOSE($D$27,D76,D77,D78,D79,D80) -> 0.633 | E31: =CHOOSE($D$27,E76,E77,E78,E79,E80) -> 0.632 | F31: =CHOOSE($D$27,F76,F77,F78,F79,F80) -> 0.631 | G31: =CHOOSE($D$27,G76,G77,G78,G79,G80) -> 0.63
B32: SGA % of Revenue | C32: =CHOOSE($D$27,C83,C84,C85,C86,C87) -> 0.339 | D32: =CHOOSE($D$27,D83,D84,D85,D86,D87) -> 0.338 | E32: =CHOOSE($D$27,E83,E84,E85,E86,E87) -> 0.3375 | F32: =CHOOSE($D$27,F83,F84,F85,F86,F87) -> 0.3375 | G32: =CHOOSE($D$27,G83,G84,G85,G86,G87) -> 0.338
B33: Revenue | C33: =C17*(1+C30) -> 11572569 | D33: =C33*(1+D30) -> 12035472 | E33: =D33*(1+E30) -> 12396536 | F33: =E33*(1+F30) -> 12706450 | G33: =F33*(1+G30) -> 12960579
B34: COGS | C34: =C33*C31 -> 7337009 | D34: =D33*D31 -> 7618453.9 | E34: =E33*E31 -> 7834610.9 | F34: =F33*F31 -> 8017769.8 | G34: =G33*G31 -> 8165164.6
B35: Gross Profit | C35: =C33-C34 -> 4235560.4 | D35: =D33-D34 -> 4417018.3 | E35: =E33-E34 -> 4561925.4 | F35: =F33-F34 -> 4688679.9 | G35: =G33-G34 -> 4795414.1
B36: Gross Margin | C36: =C35/C33 -> 0.366 | D36: =D35/D33 -> 0.367 | E36: =E35/E33 -> 0.368 | F36: =F35/F33 -> 0.369 | G36: =G35/G33 -> 0.37
B37: SGA Expense | C37: =C33*C32 -> 3923101 | D37: =D33*D32 -> 4067989.6 | E37: =E33*E32 -> 4183831 | F37: =F33*F32 -> 4288426.8 | G37: =G33*G32 -> 4380675.6
B38: Implied Operating Margin | C38: =(C35-C37)/C33 -> 0.027 | D38: =(D35-D37)/D33 -> 0.029 | E38: =(E35-E37)/E33 -> 0.0305 | F38: =(F35-F37)/F33 -> 0.0315 | G38: =(G35-G37)/G33 -> 0.032
B39: Operating Income (EBIT) | C39: =C35-C37 -> 312459.37 | D39: =D35-D37 -> 349028.69 | E39: =E35-E37 -> 378094.36 | F39: =F35-F37 -> 400253.17 | G39: =G35-G37 -> 414738.52
B40: Less: Tax | C40: =MAX(0,C39*C6) -> 95675.06 | D40: =MAX(0,D39*C6) -> 106872.59 | E40: =MAX(0,E39*C6) -> 115772.49 | F40: =MAX(0,F39*C6) -> 122557.52 | G40: =MAX(0,G39*C6) -> 126992.93
B41: NOPAT | C41: =C39-C40 -> 216784.31 | D41: =D39-D40 -> 242156.11 | E41: =E39-E40 -> 262321.86 | F41: =F39-F40 -> 277695.65 | G41: =G39-G40 -> 287745.58
B42: Plus: D&A | C42: 400000 | D42: 415000 | E42: 425000 | F42: 435000 | G42: 445000
B43: Less: Capex | C43: 560000 | D43: 550000 | E43: 540000 | F43: 540000 | G43: 545000
B44: Change in NWC | C44: ='NWC Schedule'!D19 -> 84442.041 | D44: ='NWC Schedule'!E19 -> 54178.648 | E44: ='NWC Schedule'!F19 -> 42582.49 | F44: ='NWC Schedule'!G19 -> 36777.806 | G44: ='NWC Schedule'!H19 -> 30425.855
B45: Unlevered Free Cash Flow | C45: =C41+C42-C43-C44 -> -27657.728 | D45: =D41+D42-D43-D44 -> 52977.458 | E45: =E41+E42-E43-E44 -> 104739.38 | F45: =F41+F42-F43-F44 -> 135917.84 | G45: =G41+G42-G43-G44 -> 157319.73
B46: Discount Factor | C46: =1/(1+C26)^(C19+0) -> 0.95779937 | D46: =1/(1+C26)^(C19+1) -> 0.91737963 | E46: =1/(1+C26)^(C19+2) -> 0.87866563 | F46: =1/(1+C26)^(C19+3) -> 0.84158539 | G46: =1/(1+C26)^(C19+4) -> 0.80606995
...

Sheet NWC Schedule
B2: NWC Schedule - イオン株式会社
B4: Working Capital Drivers (Days) | C4: Base Year | D4: FY2027(E) | E4: FY2028(E) | F4: FY2029(E) | G4: FY2030(E) | H4: FY2031(E)
B5: DSO (Days Sales Outstanding) | C5: =C12/C9*365 -> 64.298276 | D5: =CHOOSE('DCF Model'!$D$27,D25,D26,D27,D28,D29) -> 64 | E5: =CHOOSE('DCF Model'!$D$27,E25,E26,E27,E28,E29) -> 64 | F5: =CHOOSE('DCF Model'!$D$27,F25,F26,F27,F28,F29) -> 64 | G5: =CHOOSE('DCF Model'!$D$27,G25,G26,G27,G28,G29) -> 64 | H5: =CHOOSE('DCF Model'!$D$27,H25,H26,H27,H28,H29) -> 64
B6: DIH (Days Inventory Held) | C6: =C13/C10*365 -> 44.493427 | D6: =CHOOSE('DCF Model'!$D$27,D32,D33,D34,D35,D36) -> 44 | E6: =CHOOSE('DCF Model'!$D$27,E32,E33,E34,E35,E36) -> 44 | F6: =CHOOSE('DCF Model'!$D$27,F32,F33,F34,F35,F36) -> 44 | G6: =CHOOSE('DCF Model'!$D$27,G32,G33,G34,G35,G36) -> 44 | H6: =CHOOSE('DCF Model'!$D$27,H32,H33,H34,H35,H36) -> 44
B7: DPO (Days Payable Outstanding) | C7: =C15/C10*365 -> 79.16667 | D7: =CHOOSE('DCF Model'!$D$27,D39,D40,D41,D42,D43) -> 79 | E7: =CHOOSE('DCF Model'!$D$27,E39,E40,E41,E42,E43) -> 79 | F7: =CHOOSE('DCF Model'!$D$27,F39,F40,F41,F42,F43) -> 79 | G7: =CHOOSE('DCF Model'!$D$27,G39,G40,G41,G42,G43) -> 79 | H7: =CHOOSE('DCF Model'!$D$27,H39,H40,H41,H42,H43) -> 79
B8: P&L Reference (JPY mn)
B9: Revenue | C9: 10715342 | D9: ='DCF Model'!C33 -> 11572569 | E9: ='DCF Model'!D33 -> 12035472 | F9: ='DCF Model'!E33 -> 12396536 | G9: ='DCF Model'!F33 -> 12706450 | H9: ='DCF Model'!G33 -> 12960579
B10: COGS | C10: 6804966 | D10: ='DCF Model'!C34 -> 7337009 | E10: ='DCF Model'!D34 -> 7618453.9 | F10: ='DCF Model'!E34 -> 7834610.9 | G10: ='DCF Model'!F34 -> 8017769.8 | H10: ='DCF Model'!G34 -> 8165164.6
B11: Working Capital Items (JPY mn)
B12: Accounts Receivable | C12: 1887611 | D12: =D9*D5/365 -> 2029162.8 | E12: =E9*E5/365 -> 2110329.4 | F12: =F9*F5/365 -> 2173639.2 | G12: =G9*G5/365 -> 2227980.2 | H12: =H9*H5/365 -> 2272539.8
B13: Inventory | C13: 829524 | D13: =D10*D6/365 -> 884461.36 | E13: =E10*E6/365 -> 918388.96 | F13: =F10*F6/365 -> 944446.25 | G13: =G10*G6/365 -> 966525.67 | H13: =H10*H6/365 -> 984293.81
B14: Current Assets (AR + Inv) | C14: =C12+C13 -> 2717135 | D14: =D12+D13 -> 2913624.2 | E14: =E12+E13 -> 3028718.3 | F14: =F12+F13 -> 3118085.5 | G14: =G12+G13 -> 3194505.9 | H14: =H12+H13 -> 3256833.6
B15: Accounts Payable | C15: 1475963 | D15: =D10*D7/365 -> 1588010.2 | E15: =E10*E7/365 -> 1648925.6 | F15: =F10*F7/365 -> 1695710.3 | G15: =G10*G7/365 -> 1735352.9 | H15: =H10*H7/365 -> 1767254.8
B16: Current Liabilities (AP) | C16: =C15 -> 1475963 | D16: =D15 -> 1588010.2 | E16: =E15 -> 1648925.6 | F16: =F15 -> 1695710.3 | G16: =G15 -> 1735352.9 | H16: =H15 -> 1767254.8
B17: Net Working Capital (JPY mn)
B18: Net Working Capital | C18: =C14-C16 -> 1241172 | D18: =D14-D16 -> 1325614 | E18: =E14-E16 -> 1379792.7 | F18: =F14-F16 -> 1422375.2 | G18: =G14-G16 -> 1459153 | H18: =H14-H16 -> 1489578.8
B19: Change in NWC | C19: n/a | D19: =D18-C18 -> 84442.041 | E19: =E18-D18 -> 54178.648 | F19: =F18-E18 -> 42582.49 | G19: =G18-F18 -> 36777.806 | H19: =H18-G18 -> 30425.855
B22: Scenario Input Matrix (Working Capital Days)
D23: FY2027(E) | E23: FY2028(E) | F23: FY2029(E) | G23: FY2030(E) | H23: FY2031(E)
B24: DSO (Days)
B25: Base | D25: 64 | E25: 64 | F25: 64 | G25: 64 | H25: 64
B26: Upside | D26: 63 | E26: 63 | F26: 62 | G26: 62 | H26: 62
B27: Management | D27: 64 | E27: 64 | F27: 64 | G27: 64 | H27: 64
B28: Downside 1 | D28: 65 | E28: 66 | F28: 66 | G28: 66 | H28: 66
B29: Downside 2 | D29: 67 | E29: 68 | F29: 68 | G29: 68 | H29: 68
B31: DIH (Days)
B32: Base | D32: 44 | E32: 44 | F32: 44 | G32: 44 | H32: 44
B33: Upside | D33: 43 | E33: 43 | F33: 42 | G33: 42 | H33: 42
B34: Management | D34: 44 | E34: 44 | F34: 44 | G34: 44 | H34: 44
B35: Downside 1 | D35: 46 | E35: 47 | F35: 47 | G35: 46 | H35: 46
B36: Downside 2 | D36: 48 | E36: 50 | F36: 50 | G36: 49 | H36: 49
B38: DPO (Days)
B39: Base | D39: 79 | E39: 79 | F39: 79 | G39: 79 | H39: 79
B40: Upside | D40: 80 | E40: 80 | F40: 80 | G40: 80 | H40: 80
B41: Management | D41: 79 | E41: 79 | F41: 79 | G41: 79 | H41: 79
B42: Downside 1 | D42: 78 | E42: 78 | F42: 78 | G42: 78 | H42: 78
B43: Downside 2 | D43: 76 | E43: 75 | F43: 75 | G43: 76 | H43: 76

Sheet Comps Analysis
B2: Comparable Company Analysis
B4: Company | C4: Ticker | D4: Mkt Cap (JPY mn) | E4: EV (JPY mn) | F4: Revenue (JPY mn) | G4: EBITDA (JPY mn) | H4: Op Income (JPY mn) | I4: Net Income (JPY mn) | J4: EV/EBITDA | K4: EV/Revenue | L4: PER | M4: PBR | N4: Op Margin | O4: ROE
B5: AEON | C5: 8267.T | D5: 3938454 | E5: 8021717 | F5: 10715342 | G5: 652959 | H5: 270459 | I5: 72677 | J5: =E5/G5 -> 12.285177 | K5: =E5/F5 -> 0.74861978 | L5: =D5/I5 -> 54.191202 | M5: 3.2324246 | N5: =H5/F5 -> 0.025240352 | O5: 0.059648512
B6: Seven & I Holdings | C6: 3382.T | D6: 5875800 | E6: 7667166 | F6: 10430200 | G6: 805002 | H6: 422993 | I6: 292760 | J6: =E6/G6 -> 9.5244062 | K6: =E6/F6 -> 0.7350929 | L6: =D6/I6 -> 20.070365 | M6: 2.2305823 | N6: =H6/F6 -> 0.040554639 | O6: 0.11113811
B7: Pan Pacific International Holdings | C7: 7532.T | D7: 3060000 | E7: 3288542 | F7: 2246758 | G7: 210185 | H7: 162296 | I7: 90512 | J7: =E7/G7 -> 15.64594 | K7: =E7/F7 -> 1.4636832 | L7: =D7/I7 -> 33.807672 | M7: 5.0515556 | N7: =H7/F7 -> 0.072235639 | O7: 0.14942039
B8: Nitori Holdings | C8: 9843.T | D8: 1562700 | E8: 1577690 | F8: 912248 | G8: 195035 | H8: 125526 | I8: 89270 | J8: =E8/G8 -> 8.089266 | K8: =E8/F8 -> 1.729453 | L8: =D8/I8 -> 17.505321 | M8: 1.5807858 | N8: =H8/F8 -> 0.13760074 | O8: 0.090303158
B14: Statistics
B15: 25th Percentile | D15: =PERCENTILE(J6:J8,0.25) -> 8.8068361 | E15: =PERCENTILE(K6:K8,0.25) -> 1.0993881 | F15: =PERCENTILE(L6:L8,0.25) -> 18.787843 | G15: =PERCENTILE(M6:M8,0.25) -> 1.9056841 | H15: =PERCENTILE(N6:N8,0.25) -> 0.056395139 | I15: =PERCENTILE(O6:O8,0.25) -> 0.10072063
B16: Median (50th) | D16: =MEDIAN(J6:J8) -> 9.5244062 | E16: =MEDIAN(K6:K8) -> 1.4636832 | F16: =MEDIAN(L6:L8) -> 20.070365 | G16: =MEDIAN(M6:M8) -> 2.2305823 | H16: =MEDIAN(N6:N8) -> 0.072235639 | I16: =MEDIAN(O6:O8) -> 0.11113811
B17: 75th Percentile | D17: =PERCENTILE(J6:J8,0.75) -> 12.585173 | E17: =PERCENTILE(K6:K8,0.75) -> 1.5965681 | F17: =PERCENTILE(L6:L8,0.75) -> 26.939018 | G17: =PERCENTILE(M6:M8,0.75) -> 3.641069 | H17: =PERCENTILE(N6:N8,0.75) -> 0.10491819 | I17: =PERCENTILE(O6:O8,0.75) -> 0.13027925
B19: Implied Valuation for イオン株式会社
B20: イオン株式会社 Financials
B21: EBITDA (JPY mn) | C21: 652959
B22: Net Income (JPY mn) | C22: 72677
B23: Shares Outstanding | C23: 2765768421
B24: Net Debt (JPY mn) | C24: 4083263
B26: Implied Share Price (Median Multiples)
B27: Via EV/EBITDA (Median) | C27: =ROUND((C21*D16-C24)*1000000/C23,0) -> 772
B28: Via PER (Median) | C28: =ROUND(C22*F16*1000000/C23,0) -> 527

Sheet Sensitivity Analysis
B2: Sensitivity Analysis
B3: Current WACC: | C3: ='DCF Model'!C26 -> 0.04405999 | E3: Terminal g: | F3: ='DCF Model'!C13 -> 0.005 | H3: Exit Multiple: | I3: ='DCF Model'!C14 -> 8
B5: Table 1: WACC vs Terminal Growth Rate (PGM - Implied Share Price, JPY)
B6: WACC \ Terminal g | C6: =$F$3-0.0075 -> -0.0025 | D6: =$F$3-0.005 -> 0 | E6: =$F$3-0.0025 -> 0.0025 | F6: =$F$3 -> 0.005 | G6: =$F$3+0.0025 -> 0.0075 | H6: =$F$3+0.005 -> 0.01 | I6: =$F$3+0.0075 -> 0.0125
B7: =$C$3-0.015 -> 0.02905999 | C7: =IFERROR(ROUND(('DCF Model'!C45/(1+$B7)^('DCF Model'!C19+0)+'DCF Model'!D45/(1+$B7)^('DCF Model'!C19+1)+'DCF Model'!E45/(1+$B7)^('DCF Model'!C19+2)+'DCF Model'!F45/(1+$B7)^('DCF Model'!C19+3)+'DCF Model'!G45/(1+$B7)^('DCF Model'!C19+4)+'DCF Model'!G45*(1+C$6)/($B7-C$6)/(1+$B7)^('DCF Model'!C19+4)-'DCF Model'!C16)*1000000/'DCF Model'!C15,0),"") -> 218 | D7: =IFERROR(ROUND(('DCF Model'!C45/(1+$B7)^('DCF Model'!C19+0)+'DCF Model'!D45/(1+$B7)^('DCF Model'!C19+1)+'DCF Model'!E45/(1+$B7)^('DCF Model'!C19+2)+'DCF Model'!F45/(1+$B7)^('DCF Model'!C19+3)+'DCF Model'!G45/(1+$B7)^('DCF Model'!C19+4)+'DCF Model'!G45*(1+D$6)/($B7-D$6)/(1+$B7)^('DCF Model'!C19+4)-'DCF Model'!C16)*1000000/'DCF Model'!C15,0),"") -> 356 | E7: =IFERROR(ROUND(('DCF Model'!C45/(1+$B7)^('DCF Model'!C19+0)+'DCF Model'!D45/(1+$B7)^('DCF Model'!C19+1)+'DCF Model'!E45/(1+$B7)^('DCF Model'!C19+2)+'DCF Model'!F45/(1+$B7)^('DCF Model'!C19+3)+'DCF Model'!G45/(1+$B7)^('DCF Model'!C19+4)+'DCF Model'!G45*(1+E$6)/($B7-E$6)/(1+$B7)^('DCF Model'!C19+4)-'DCF Model'!C16)*1000000/'DCF Model'!C15,0),"") -> 520 | F7: =IFERROR(ROUND(('DCF Model'!C45/(1+$B7)^('DCF Model'!C19+0)+'DCF Model'!D45/(1+$B7)^('DCF Model'!C19+1)+'DCF Model'!E45/(1+$B7)^('DCF Model'!C19+2)+'DCF Model'!F45/(1+$B7)^('DCF Model'!C19+3)+'DCF Model'!G45/(1+$B7)^('DCF Model'!C19+4)+'DCF Model'!G45*(1+F$6)/($B7-F$6)/(1+$B7)^('DCF Model'!C19+4)-'DCF Model'!C16)*1000000/'DCF Model'!C15,0),"") -> 719 | G7: =IFERROR(ROUND(('DCF Model'!C45/(1+$B7)^('DCF Model'!C19+0)+'DCF Model'!D45/(1+$B7)^('DCF Model'!C19+1)+'DCF Model'!E45/(1+$B7)^('DCF Model'!C19+2)+'DCF Model'!F45/(1+$B7)^('DCF Model'!C19+3)+'DCF Model'!G45/(1+$B7)^('DCF Model'!C19+4)+'DCF Model'!G45*(1+G$6)/($B7-G$6)/(1+$B7)^('DCF Model'!C19+4)-'DCF Model'!C16)*1000000/'DCF Model'!C15,0),"") -> 963 | H7: =IFERROR(ROUND(('DCF Model'!C45/(1+$B7)^('DCF Model'!C19+0)+'DCF Model'!D45/(1+$B7)^('DCF Model'!C19+1)+'DCF Model'!E45/(1+$B7)^('DCF Model'!C19+2)+'DCF Model'!F45/(1+$B7)^('DCF Model'!C19+3)+'DCF Model'!G45/(1+$B7)^('DCF Model'!C19+4)+'DCF Model'!G45*(1+H$6)/($B7-H$6)/(1+$B7)^('DCF Model'!C19+4)-'DCF Model'!C16)*1000000/'DCF Model'!C15,0),"") -> 1272 | I7: =IFERROR(ROUND(('DCF Model'!C45/(1+$B7)^('DCF Model'!C19+0)+'DCF Model'!D45/(1+$B7)^('DCF Model'!C19+1)+'DCF Model'!E45/(1+$B7)^('DCF Model'!C19+2)+'DCF Model'!F45/(1+$B7)^('DCF Model'!C19+3)+'DCF Model'!G45/(1+$B7)^('DCF Model'!C19+4)+'DCF Model'!G45*(1+I$6)/($B7-I$6)/(1+$B7)^('DCF Model'!C19+4)-'DCF Model'!C16)*1000000/'DCF Model'!C15,0),"") -> 1674
B8: =$C$3-0.01 -> 0.03405999 | C8: =IFERROR(ROUND(('DCF Model'!C45/(1+$B8)^('DCF Model'!C19+0)+'DCF Model'!D45/(1+$B8)^('DCF Model'!C19+1)+'DCF Model'!E45/(1+$B8)^('DCF Model'!C19+2)+'DCF Model'!F45/(1+$B8)^('DCF Model'!C19+3)+'DCF Model'!G45/(1+$B8)^('DCF Model'!C19+4)+'DCF Model'!G45*(1+C$6)/($B8-C$6)/(1+$B8)^('DCF Model'!C19+4)-'DCF Model'!C16)*1000000/'DCF Model'!C15,0),"") -> -30 | D8: =IFERROR(ROUND(('DCF Model'!C45/(1+$B8)^('DCF Model'!C19+0)+'DCF Model'!D45/(1+$B8)^('DCF Model'!C19+1)+'DCF Model'!E45/(1+$B8)^('DCF Model'!C19+2)+'DCF Model'!F45/(1+$B8)^('DCF Model'!C19+3)+'DCF Model'!G45/(1+$B8)^('DCF Model'!C19+4)+'DCF Model'!G45*(1+D$6)/($B8-D$6)/(1+$B8)^('DCF Model'!C19+4)-'DCF Model'!C16)*1000000/'DCF Model'!C15,0),"") -> 70 | E8: =IFERROR(ROUND(('DCF Model'!C45/(1+$B8)^('DCF Model'!C19+0)+'DCF Model'!D45/(1+$B8)^('DCF Model'!C19+1)+'DCF Model'!E45/(1+$B8)^('DCF Model'!C19+2)+'DCF Model'!F45/(1+$B8)^('DCF Model'!C19+3)+'DCF Model'!G45/(1+$B8)^('DCF Model'!C19+4)+'DCF Model'!G45*(1+E$6)/($B8-E$6)/(1+$B8)^('DCF Model'!C19+4)-'DCF Model'!C16)*1000000/'DCF Model'!C15,0),"") -> 185 | F8: =IFERROR(ROUND(('DCF Model'!C45/(1+$B8)^('DCF Model'!C19+0)+'DCF Model'!D45/(1+$B8)^('DCF Model'!C19+1)+'DCF Model'!E45/(1+$B8)^('DCF Model'!C19+2)+'DCF Model'!F45/(1+$B8)^('DCF Model'!C19+3)+'DCF Model'!G45/(1+$B8)^('DCF Model'!C19+4)+'DCF Model'!G45*(1+F$6)/($B8-F$6)/(1+$B8)^('DCF Model'!C19+4)-'DCF Model'!C16)*1000000/'DCF Model'!C15,0),"") -> 321 | G8: =IFERROR(ROUND(('DCF Model'!C45/(1+$B8)^('DCF Model'!C19+0)+'DCF Model'!D45/(1+$B8)^('DCF Model'!C19+1)+'DCF Model'!E45/(1+$B8)^('DCF Model'!C19+2)+'DCF Model'!F45/(1+$B8)^('DCF Model'!C19+3)+'DCF Model'!G45/(1+$B8)^('DCF Model'!C19+4)+'DCF Model'!G45*(1+G$6)/($B8-G$6)/(1+$B8)^('DCF Model'!C19+4)-'DCF Model'!C16)*1000000/'DCF Model'!C15,0),"") -> 482 | H8: =IFERROR(ROUND(('DCF Model'!C45/(1+$B8)^('DCF Model'!C19+0)+'DCF Model'!D45/(1+$B8)^('DCF Model'!C19+1)+'DCF Model'!E45/(1+$B8)^('DCF Model'!C19+2)+'DCF Model'!F45/(1+$B8)^('DCF Model'!C19+3)+'DCF Model'!G45/(1+$B8)^('DCF Model'!C19+4)+'DCF Model'!G45*(1+H$6)/($B8-H$6)/(1+$B8)^('DCF Model'!C19+4)-'DCF Model'!C16)*1000000/'DCF Model'!C15,0),"") -> 677 | I8: =IFERROR(ROUND(('DCF Model'!C45/(1+$B8)^('DCF Model'!C19+0)+'DCF Model'!D45/(1+$B8)^('DCF Model'!C19+1)+'DCF Model'!E45/(1+$B8)^('DCF Model'!C19+2)+'DCF Model'!F45/(1+$B8)^('DCF Model'!C19+3)+'DCF Model'!G45/(1+$B8)^('DCF Model'!C19+4)+'DCF Model'!G45*(1+I$6)/($B8-I$6)/(1+$B8)^('DCF Model'!C19+4)-'DCF Model'!C16)*1000000/'DCF Model'!C15,0),"") -> 917
B9: =$C$3-0.005 -> 0.03905999 | C9: =IFERROR(ROUND(('DCF Model'!C45/(1+$B9)^('DCF Model'!C19+0)+'DCF Model'!D45/(1+$B9)^('DCF Model'!C19+1)+'DCF Model'!E45/(1+$B9)^('DCF Model'!C19+2)+'DCF Model'!F45/(1+$B9)^('DCF Model'!C19+3)+'DCF Model'!G45/(1+$B9)^('DCF Model'!C19+4)+'DCF Model'!G45*(1+C$6)/($B9-C$6)/(1+$B9)^('DCF Model'!C19+4)-'DCF Model'!C16)*1000000/'DCF Model'!C15,0),"") -> -218 | D9: =IFERROR(ROUND(('DCF Model'!C45/(1+$B9)^('DCF Model'!C19+0)+'DCF Model'!D45/(1+$B9)^('DCF Model'!C19+1)+'DCF Model'!E45/(1+$B9)^('DCF Model'!C19+2)+'DCF Model'!F45/(1+$B9)^('DCF Model'!C19+3)+'DCF Model'!G45/(1+$B9)^('DCF Model'!C19+4)+'DCF Model'!G45*(1+D$6)/($B9-D$6)/(1+$B9)^('DCF Model'!C19+4)-'DCF Model'!C16)*1000000/'DCF Model'!C15,0),"") -> -143 | E9: =IFERROR(ROUND(('DCF Model'!C45/(1+$B9)^('DCF Model'!C19+0)+'DCF Model'!D45/(1+$B9)^('DCF Model'!C19+1)+'DCF Model'!E45/(1+$B9)^('DCF Model'!C19+2)+'DCF Model'!F45/(1+$B9)^('DCF Model'!C19+3)+'DCF Model'!G45/(1+$B9)^('DCF Model'!C19+4)+'DCF Model'!G45*(1+E$6)/($B9-E$6)/(1+$B9)^('DCF Model'!C19+4)-'DCF Model'!C16)*1000000/'DCF Model'!C15,0),"") -> -58 | F9: =IFERROR(ROUND(('DCF Model'!C45/(1+$B9)^('DCF Model'!C19+0)+'DCF Model'!D45/(1+$B9)^('DCF Model'!C19+1)+'DCF Model'!E45/(1+$B9)^('DCF Model'!C19+2)+'DCF Model'!F45/(1+$B9)^('DCF Model'!C19+3)+'DCF Model'!G45/(1+$B9)^('DCF Model'!C19+4)+'DCF Model'!G45*(1+F$6)/($B9-F$6)/(1+$B9)^('DCF Model'!C19+4)-'DCF Model'!C16)*1000000/'DCF Model'!C15,0),"") -> 40 | G9: =IFERROR(ROUND(('DCF Model'!C45/(1+$B9)^('DCF Model'!C19+0)+'DCF Model'!D45/(1+$B9)^('DCF Model'!C19+1)+'DCF Model'!E45/(1+$B9)^('DCF Model'!C19+2)+'DCF Model'!F45/(1+$B9)^('DCF Model'!C19+3)+'DCF Model'!G45/(1+$B9)^('DCF Model'!C19+4)+'DCF Model'!G45*(1+G$6)/($B9-G$6)/(1+$B9)^('DCF Model'!C19+4)-'DCF Model'!C16)*1000000/'DCF Model'!C15,0),"") -> 154 | H9: =IFERROR(ROUND(('DCF Model'!C45/(1+$B9)^('DCF Model'!C19+0)+'DCF Model'!D45/(1+$B9)^('DCF Model'!C19+1)+'DCF Model'!E45/(1+$B9)^('DCF Model'!C19+2)+'DCF Model'!F45/(1+$B9)^('DCF Model'!C19+3)+'DCF Model'!G45/(1+$B9)^('DCF Model'!C19+4)+'DCF Model'!G45*(1+H$6)/($B9-H$6)/(1+$B9)^('DCF Model'!C19+4)-'DCF Model'!C16)*1000000/'DCF Model'!C15,0),"") -> 287 | I9: =IFERROR(ROUND(('DCF Model'!C45/(1+$B9)^('DCF Model'!C19+0)+'DCF Model'!D45/(1+$B9)^('DCF Model'!C19+1)+'DCF Model'!E45/(1+$B9)^('DCF Model'!C19+2)+'DCF Model'!F45/(1+$B9)^('DCF Model'!C19+3)+'DCF Model'!G45/(1+$B9)^('DCF Model'!C19+4)+'DCF Model'!G45*(1+I$6)/($B9-I$6)/(1+$B9)^('DCF Model'!C19+4)-'DCF Model'!C16)*1000000/'DCF Model'!C15,0),"") -> 445
B10: =$C$3 -> 0.04405999 | C10: =IFERROR(ROUND(('DCF Model'!C45/(1+$B10)^('DCF Model'!C19+0)+'DCF Model'!D45/(1+$B10)^('DCF Model'!C19+1)+'DCF Model'!E45/(1+$B10)^('DCF Model'!C19+2)+'DCF Model'!F45/(1+$B10)^('DCF Model'!C19+3)+'DCF Model'!G45/(1+$B10)^('DCF Model'!C19+4)+'DCF Model'!G45*(1+C$6)/($B10-C$6)/(1+$B10)^('DCF Model'!C19+4)-'DCF Model'!C16)*1000000/'DCF Model'!C15,0),"") -> -366 | D10: =IFERROR(ROUND(('DCF Model'!C45/(1+$B10)^('DCF Model'!C19+0)+'DCF Model'!D45/(1+$B10)^('DCF Model'!C19+1)+'DCF Model'!E45/(1+$B10)^('DCF Model'!C19+2)+'DCF Model'!F45/(1+$B10)^('DCF Model'!C19+3)+'DCF Model'!G45/(1+$B10)^('DCF Model'!C19+4)+'DCF Model'!G45*(1+D$6)/($B10-D$6)/(1+$B10)^('DCF Model'!C19+4)-'DCF Model'!C16)*1000000/'DCF Model'!C15,0),"") -> -307 | E10: =IFERROR(ROUND(('DCF Model'!C45/(1+$B10)^('DCF Model'!C19+0)+'DCF Model'!D45/(1+$B10)^('DCF Model'!C19+1)+'DCF Model'!E45/(1+$B10)^('DCF Model'!C19+2)+'DCF Model'!F45/(1+$B10)^('DCF Model'!C19+3)+'DCF Model'!G45/(1+$B10)^('DCF Model'!C19+4)+'DCF Model'!G45*(1+E$6)/($B10-E$6)/(1+$B10)^('DCF Model'!C19+4)-'DCF Model'!C16)*1000000/'DCF Model'!C15,0),"") -> -242 | F10: =IFERROR(ROUND(('DCF Model'!C45/(1+$B10)^('DCF Model'!C19+0)+'DCF Model'!D45/(1+$B10)^('DCF Model'!C19+1)+'DCF Model'!E45/(1+$B10)^('DCF Model'!C19+2)+'DCF Model'!F45/(1+$B10)^('DCF Model'!C19+3)+'DCF Model'!G45/(1+$B10)^('DCF Model'!C19+4)+'DCF Model'!G45*(1+F$6)/($B10-F$6)/(1+$B10)^('DCF Model'!C19+4)-'DCF Model'!C16)*1000000/'DCF Model'!C15,0),"") -> -168 | G10: =IFERROR(ROUND(('DCF Model'!C45/(1+$B10)^('DCF Model'!C19+0)+'DCF Model'!D45/(1+$B10)^('DCF Model'!C19+1)+'DCF Model'!E45/(1+$B10)^('DCF Model'!C19+2)+'DCF Model'!F45/(1+$B10)^('DCF Model'!C19+3)+'DCF Model'!G45/(1+$B10)^('DCF Model'!C19+4)+'DCF Model'!G45*(1+G$6)/($B10-G$6)/(1+$B10)^('DCF Model'!C19+4)-'DCF Model'!C16)*1000000/'DCF Model'!C15,0),"") -> -84 | H10: =IFERROR(ROUND(('DCF Model'!C45/(1+$B10)^('DCF Model'!C19+0)+'DCF Model'!D45/(1+$B10)^('DCF Model'!C19+1)+'DCF Model'!E45/(1+$B10)^('DCF Model'!C19+2)+'DCF Model'!F45/(1+$B10)^('DCF Model'!C19+3)+'DCF Model'!G45/(1+$B10)^('DCF Model'!C19+4)+'DCF Model'!G45*(1+H$6)/($B10-H$6)/(1+$B10)^('DCF Model'!C19+4)-'DCF Model'!C16)*1000000/'DCF Model'!C15,0),"") -> 12 | I10: =IFERROR(ROUND(('DCF Model'!C45/(1+$B10)^('DCF Model'!C19+0)+'DCF Model'!D45/(1+$B10)^('DCF Model'!C19+1)+'DCF Model'!E45/(1+$B10)^('DCF Model'!C19+2)+'DCF Model'!F45/(1+$B10)^('DCF Model'!C19+3)+'DCF Model'!G45/(1+$B10)^('DCF Model'!C19+4)+'DCF Model'!G45*(1+I$6)/($B10-I$6)/(1+$B10)^('DCF Model'!C19+4)-'DCF Model'!C16)*1000000/'DCF Model'!C15,0),"") -> 123
B11: =$C$3+0.005 -> 0.04905999 | C11: =IFERROR(ROUND(('DCF Model'!C45/(1+$B11)^('DCF Model'!C19+0)+'DCF Model'!D45/(1+$B11)^('DCF Model'!C19+1)+'DCF Model'!E45/(1+$B11)^('DCF Model'!C19+2)+'DCF Model'!F45/(1+$B11)^('DCF Model'!C19+3)+'DCF Model'!G45/(1+$B11)^('DCF Model'!C19+4)+'DCF Model'!G45*(1+C$6)/($B11-C$6)/(1+$B11)^('DCF Model'!C19+4)-'DCF Model'!C16)*1000000/'DCF Model'!C15,0),"") -> -484 | D11: =IFERROR(ROUND(('DCF Model'!C45/(1+$B11)^('DCF Model'!C19+0)+'DCF Model'!D45/(1+$B11)^('DCF Model'!C19+1)+'DCF Model'!E45/(1+$B11)^('DCF Model'!C19+2)+'DCF Model'!F45/(1+$B11)^('DCF Model'!C19+3)+'DCF Model'!G45/(1+$B11)^('DCF Model'!C19+4)+'DCF Model'!G45*(1+D$6)/($B11-D$6)/(1+$B11)^('DCF Model'!C19+4)-'DCF Model'!C16)*1000000/'DCF Model'!C15,0),"") -> -438 | E11: =IFERROR(ROUND(('DCF Model'!C45/(1+$B11)^('DCF Model'!C19+0)+'DCF Model'!D45/(1+$B11)^('DCF Model'!C19+1)+'DCF Model'!E45/(1+$B11)^('DCF Model'!C19+2)+'DCF Model'!F45/(1+$B11)^('DCF Model'!C19+3)+'DCF Model'!G45/(1+$B11)^('DCF Model'!C19+4)+'DCF Model'!G45*(1+E$6)/($B11-E$6)/(1+$B11)^('DCF Model'!C19+4)-'DCF Model'!C16)*1000000/'DCF Model'!C15,0),"") -> -386 | F11: =IFERROR(ROUND(('DCF Model'!C45/(1+$B11)^('DCF Model'!C19+0)+'DCF Model'!D45/(1+$B11)^('DCF Model'!C19+1)+'DCF Model'!E45/(1+$B11)^('DCF Model'!C19+2)+'DCF Model'!F45/(1+$B11)^('DCF Model'!C19+3)+'DCF Model'!G45/(1+$B11)^('DCF Model'!C19+4)+'DCF Model'!G45*(1+F$6)/($B11-F$6)/(1+$B11)^('DCF Model'!C19+4)-'DCF Model'!C16)*1000000/'DCF Model'!C15,0),"") -> -329 | G11: =IFERROR(ROUND(('DCF Model'!C45/(1+$B11)^('DCF Model'!C19+0)+'DCF Model'!D45/(1+$B11)^('DCF Model'!C19+1)+'DCF Model'!E45/(1+$B11)^('DCF Model'!C19+2)+'DCF Model'!F45/(1+$B11)^('DCF Model'!C19+3)+'DCF Model'!G45/(1+$B11)^('DCF Model'!C19+4)+'DCF Model'!G45*(1+G$6)/($B11-G$6)/(1+$B11)^('DCF Model'!C19+4)-'DCF Model'!C16)*1000000/'DCF Model'!C15,0),"") -> -265 | H11: =IFERROR(ROUND(('DCF Model'!C45/(1+$B11)^('DCF Model'!C19+0)+'DCF Model'!D45/(1+$B11)^('DCF Model'!C19+1)+'DCF Model'!E45/(1+$B11)^('DCF Model'!C19+2)+'DCF Model'!F45/(1+$B11)^('DCF Model'!C19+3)+'DCF Model'!G45/(1+$B11)^('DCF Model'!C19+4)+'DCF Model'!G45*(1+H$6)/($B11-H$6)/(1+$B11)^('DCF Model'!C19+4)-'DCF Model'!C16)*1000000/'DCF Model'!C15,0),"") -> -193 | I11: =IFERROR(ROUND(('DCF Model'!C45/(1+$B11)^('DCF Model'!C19+0)+'DCF Model'!D45/(1+$B11)^('DCF Model'!C19+1)+'DCF Model'!E45/(1+$B11)^('DCF Model'!C19+2)+'DCF Model'!F45/(1+$B11)^('DCF Model'!C19+3)+'DCF Model'!G45/(1+$B11)^('DCF Model'!C19+4)+'DCF Model'!G45*(1+I$6)/($B11-I$6)/(1+$B11)^('DCF Model'!C19+4)-'DCF Model'!C16)*1000000/'DCF Model'!C15,0),"") -> -111
B12: =$C$3+0.01 -> 0.05405999 | C12: =IFERROR(ROUND(('DCF Model'!C45/(1+$B12)^('DCF Model'!C19+0)+'DCF Model'!D45/(1+$B12)^('DCF Model'!C19+1)+'DCF Model'!E45/(1+$B12)^('DCF Model'!C19+2)+'DCF Model'!F45/(1+$B12)^('DCF Model'!C19+3)+'DCF Model'!G45/(1+$B12)^('DCF Model'!C19+4)+'DCF Model'!G45*(1+C$6)/($B12-C$6)/(1+$B12)^('DCF Model'!C19+4)-'DCF Model'!C16)*1000000/'DCF Model'!C15,0),"") -> -582 | D12: =IFERROR(ROUND(('DCF Model'!C45/(1+$B12)^('DCF Model'!C19+0)+'DCF Model'!D45/(1+$B12)^('DCF Model'!C19+1)+'DCF Model'!E45/(1+$B12)^('DCF Model'!C19+2)+'DCF Model'!F45/(1+$B12)^('DCF Model'!C19+3)+'DCF Model'!G45/(1+$B12)^('DCF Model'!C19+4)+'DCF Model'!G45*(1+D$6)/($B12-D$6)/(1+$B12)^('DCF Model'!C19+4)-'DCF Model'!C16)*1000000/'DCF Model'!C15,0),"") -> -544 | E12: =IFERROR(ROUND(('DCF Model'!C45/(1+$B12)^('DCF Model'!C19+0)+'DCF Model'!D45/(1+$B12)^('DCF Model'!C19+1)+'DCF Model'!E45/(1+$B12)^('DCF Model'!C19+2)+'DCF Model'!F45/(1+$B12)^('DCF Model'!C19+3)+'DCF Model'!G45/(1+$B12)^('DCF Model'!C19+4)+'DCF Model'!G45*(1+E$6)/($B12-E$6)/(1+$B12)^('DCF Model'!C19+4)-'DCF Model'!C16)*1000000/'DCF Model'!C15,0),"") -> -503 | F12: =IFERROR(ROUND(('DCF Model'!C45/(1+$B12)^('DCF Model'!C19+0)+'DCF Model'!D45/(1+$B12)^('DCF Model'!C19+1)+'DCF Model'!E45/(1+$B12)^('DCF Model'!C19+2)+'DCF Model'!F45/(1+$B12)^('DCF Model'!C19+3)+'DCF Model'!G45/(1+$B12)^('DCF Model'!C19+4)+'DCF Model'!G45*(1+F$6)/($B12-F$6)/(1+$B12)^('DCF Model'!C19+4)-'DCF Model'!C16)*1000000/'DCF Model'!C15,0),"") -> -457 | G12: =IFERROR(ROUND(('DCF Model'!C45/(1+$B12)^('DCF Model'!C19+0)+'DCF Model'!D45/(1+$B12)^('DCF Model'!C19+1)+'DCF Model'!E45/(1+$B12)^('DCF Model'!C19+2)+'DCF Model'!F45/(1+$B12)^('DCF Model'!C19+3)+'DCF Model'!G45/(1+$B12)^('DCF Model'!C19+4)+'DCF Model'!G45*(1+G$6)/($B12-G$6)/(1+$B12)^('DCF Model'!C19+4)-'DCF Model'!C16)*1000000/'DCF Model'!C15,0),"") -> -407 | H12: =IFERROR(ROUND(('DCF Model'!C45/(1+$B12)^('DCF Model'!C19+0)+'DCF Model'!D45/(1+$B12)^('DCF Model'!C19+1)+'DCF Model'!E45/(1+$B12)^('DCF Model'!C19+2)+'DCF Model'!F45/(1+$B12)^('DCF Model'!C19+3)+'DCF Model'!G45/(1+$B12)^('DCF Model'!C19+4)+'DCF Model'!G45*(1+H$6)/($B12-H$6)/(1+$B12)^('DCF Model'!C19+4)-'DCF Model'!C16)*1000000/'DCF Model'!C15,0),"") -> -351 | I12: =IFERROR(ROUND(('DCF Model'!C45/(1+$B12)^('DCF Model'!C19+0)+'DCF Model'!D45/(1+$B12)^('DCF Model'!C19+1)+'DCF Model'!E45/(1+$B12)^('DCF Model'!C19+2)+'DCF Model'!F45/(1+$B12)^('DCF Model'!C19+3)+'DCF Model'!G45/(1+$B12)^('DCF Model'!C19+4)+'DCF Model'!G45*(1+I$6)/($B12-I$6)/(1+$B12)^('DCF Model'!C19+4)-'DCF Model'!C16)*1000000/'DCF Model'!C15,0),"") -> -288
B13: =$C$3+0.015 -> 0.05905999 | C13: =IFERROR(ROUND(('DCF Model'!C45/(1+$B13)^('DCF Model'!C19+0)+'DCF Model'!D45/(1+$B13)^('DCF Model'!C19+1)+'DCF Model'!E45/(1+$B13)^('DCF Model'!C19+2)+'DCF Model'!F45/(1+$B13)^('DCF Model'!C19+3)+'DCF Model'!G45/(1+$B13)^('DCF Model'!C19+4)+'DCF Model'!G45*(1+C$6)/($B13-C$6)/(1+$B13)^('DCF Model'!C19+4)-'DCF Model'!C16)*1000000/'DCF Model'!C15,0),"") -> -663 | D13: =IFERROR(ROUND(('DCF Model'!C45/(1+$B13)^('DCF Model'!C19+0)+'DCF Model'!D45/(1+$B13)^('DCF Model'!C19+1)+'DCF Model'!E45/(1+$B13)^('DCF Model'!C19+2)+'DCF Model'!F45/(1+$B13)^('DCF Model'!C19+3)+'DCF Model'!G45/(1+$B13)^('DCF Model'!C19+4)+'DCF Model'!G45*(1+D$6)/($B13-D$6)/(1+$B13)^('DCF Model'!C19+4)-'DCF Model'!C16)*1000000/'DCF Model'!C15,0),"") -> -632 | E13: =IFERROR(ROUND(('DCF Model'!C45/(1+$B13)^('DCF Model'!C19+0)+'DCF Model'!D45/(1+$B13)^('DCF Model'!C19+1)+'DCF Model'!E45/(1+$B13)^('DCF Model'!C19+2)+'DCF Model'!F45/(1+$B13)^('DCF Model'!C19+3)+'DCF Model'!G45/(1+$B13)^('DCF Model'!C19+4)+'DCF Model'!G45*(1+E$6)/($B13-E$6)/(1+$B13)^('DCF Model'!C19+4)-'DCF Model'!C16)*1000000/'DCF Model'!C15,0),"") -> -598 | F13: =IFERROR(ROUND(('DCF Model'!C45/(1+$B13)^('DCF Model'!C19+0)+'DCF Model'!D45/(1+$B13)^('DCF Model'!C19+1)+'DCF Model'!E45/(1+$B13)^('DCF Model'!C19+2)+'DCF Model'!F45/(1+$B13)^('DCF Model'!C19+3)+'DCF Model'!G45/(1+$B13)^('DCF Model'!C19+4)+'DCF Model'!G45*(1+F$6)/($B13-F$6)/(1+$B13)^('DCF Model'!C19+4)-'DCF Model'!C16)*1000000/'DCF Model'!C15,0),"") -> -561 | G13: =IFERROR(ROUND(('DCF Model'!C45/(1+$B13)^('DCF Model'!C19+0)+'DCF Model'!D45/(1+$B13)^('DCF Model'!C19+1)+'DCF Model'!E45/(1+$B13)^('DCF Model'!C19+2)+'DCF Model'!F45/(1+$B13)^('DCF Model'!C19+3)+'DCF Model'!G45/(1+$B13)^('DCF Model'!C19+4)+'DCF Model'!G45*(1+G$6)/($B13-G$6)/(1+$B13)^('DCF Model'!C19+4)-'DCF Model'!C16)*1000000/'DCF Model'!C15,0),"") -> -521 | H13: =IFERROR(ROUND(('DCF Model'!C45/(1+$B13)^('DCF Model'!C19+0)+'DCF Model'!D45/(1+$B13)^('DCF Model'!C19+1)+'DCF Model'!E45/(1+$B13)^('DCF Model'!C19+2)+'DCF Model'!F45/(1+$B13)^('DCF Model'!C19+3)+'DCF Model'!G45/(1+$B13)^('DCF Model'!C19+4)+'DCF Model'!G45*(1+H$6)/($B13-H$6)/(1+$B13)^('DCF Model'!C19+4)-'DCF Model'!C16)*1000000/'DCF Model'!C15,0),"") -> -476 | I13: =IFERROR(ROUND(('DCF Model'!C45/(1+$B13)^('DCF Model'!C19+0)+'DCF Model'!D45/(1+$B13)^('DCF Model'!C19+1)+'DCF Model'!E45/(1+$B13)^('DCF Model'!C19+2)+'DCF Model'!F45/(1+$B13)^('DCF Model'!C19+3)+'DCF Model'!G45/(1+$B13)^('DCF Model'!C19+4)+'DCF Model'!G45*(1+I$6)/($B13-I$6)/(1+$B13)^('DCF Model'!C19+4)-'DCF Model'!C16)*1000000/'DCF Model'!C15,0),"") -> -427
B16: Table 2: WACC vs Exit Multiple (Exit Multiple - Implied Share Price, JPY)
B17: WACC \ Exit Multiple | C17: =$I$3-3 -> 5 | D17: =$I$3-2 -> 6 | E17: =$I$3-1 -> 7 | F17: =$I$3 -> 8 | G17: =$I$3+1 -> 9 | H17: =$I$3+2 -> 10 | I17: =$I$3+3 -> 11
B18: =$C$3-0.015 -> 0.02905999 | C18: =IFERROR(ROUND(('DCF Model'!C45/(1+$B18)^('DCF Model'!C19+0)+'DCF Model'!D45/(1+$B18)^('DCF Model'!C19+1)+'DCF Model'!E45/(1+$B18)^('DCF Model'!C19+2)+'DCF Model'!F45/(1+$B18)^('DCF Model'!C19+3)+'DCF Model'!G45/(1+$B18)^('DCF Model'!C19+4)+('DCF Model'!G39+'DCF Model'!G42)*C$17/(1+$B18)^('DCF Model'!C19+4)-'DCF Model'!C16)*1000000/'DCF Model'!C15,0),"") -> 7 | D18: =IFERROR(ROUND(('DCF Model'!C45/(1+$B18)^('DCF Model'!C19+0)+'DCF Model'!D45/(1+$B18)^('DCF Model'!C19+1)+'DCF Model'!E45/(1+$B18)^('DCF Model'!C19+2)+'DCF Model'!F45/(1+$B18)^('DCF Model'!C19+3)+'DCF Model'!G45/(1+$B18)^('DCF Model'!C19+4)+('DCF Model'!G39+'DCF Model'!G42)*D$17/(1+$B18)^('DCF Model'!C19+4)-'DCF Model'!C16)*1000000/'DCF Model'!C15,0),"") -> 276 | E18: =IFERROR(ROUND(('DCF Model'!C45/(1+$B18)^('DCF Model'!C19+0)+'DCF Model'!D45/(1+$B18)^('DCF Model'!C19+1)+'DCF Model'!E45/(1+$B18)^('DCF Model'!C19+2)+'DCF Model'!F45/(1+$B18)^('DCF Model'!C19+3)+'DCF Model'!G45/(1+$B18)^('DCF Model'!C19+4)+('DCF Model'!G39+'DCF Model'!G42)*E$17/(1+$B18)^('DCF Model'!C19+4)-'DCF Model'!C16)*1000000/'DCF Model'!C15,0),"") -> 545 | F18: =IFERROR(ROUND(('DCF Model'!C45/(1+$B18)^('DCF Model'!C19+0)+'DCF Model'!D45/(1+$B18)^('DCF Model'!C19+1)+'DCF Model'!E45/(1+$B18)^('DCF Model'!C19+2)+'DCF Model'!F45/(1+$B18)^('DCF Model'!C19+3)+'DCF Model'!G45/(1+$B18)^('DCF Model'!C19+4)+('DCF Model'!G39+'DCF Model'!G42)*F$17/(1+$B18)^('DCF Model'!C19+4)-'DCF Model'!C16)*1000000/'DCF Model'!C15,0),"") -> 815 | G18: =IFERROR(ROUND(('DCF Model'!C45/(1+$B18)^('DCF Model'!C19+0)+'DCF Model'!D45/(1+$B18)^('DCF Model'!C19+1)+'DCF Model'!E45/(1+$B18)^('DCF Model'!C19+2)+'DCF Model'!F45/(1+$B18)^('DCF Model'!C19+3)+'DCF Model'!G45/(1+$B18)^('DCF Model'!C19+4)+('DCF Model'!G39+'DCF Model'!G42)*G$17/(1+$B18)^('DCF Model'!C19+4)-'DCF Model'!C16)*1000000/'DCF Model'!C15,0),"") -> 1084 | H18: =IFERROR(ROUND(('DCF Model'!C45/(1+$B18)^('DCF Model'!C19+0)+'DCF Model'!D45/(1+$B18)^('DCF Model'!C19+1)+'DCF Model'!E45/(1+$B18)^('DCF Model'!C19+2)+'DCF Model'!F45/(1+$B18)^('DCF Model'!C19+3)+'DCF Model'!G45/(1+$B18)^('DCF Model'!C19+4)+('DCF Model'!G39+'DCF Model'!G42)*H$17/(1+$B18)^('DCF Model'!C19+4)-'DCF Model'!C16)*1000000/'DCF Model'!C15,0),"") -> 1354 | I18: =IFERROR(ROUND(('DCF Model'!C45/(1+$B18)^('DCF Model'!C19+0)+'DCF Model'!D45/(1+$B18)^('DCF Model'!C19+1)+'DCF Model'!E45/(1+$B18)^('DCF Model'!C19+2)+'DCF Model'!F45/(1+$B18)^('DCF Model'!C19+3)+'DCF Model'!G45/(1+$B18)^('DCF Model'!C19+4)+('DCF Model'!G39+'DCF Model'!G42)*I$17/(1+$B18)^('DCF Model'!C19+4)-'DCF Model'!C16)*1000000/'DCF Model'!C15,0),"") -> 1623
B19: =$C$3-0.01 -> 0.03405999 | C19: =IFERROR(ROUND(('DCF Model'!C45/(1+$B19)^('DCF Model'!C19+0)+'DCF Model'!D45/(1+$B19)^('DCF Model'!C19+1)+'DCF Model'!E45/(1+$B19)^('DCF Model'!C19+2)+'DCF Model'!F45/(1+$B19)^('DCF Model'!C19+3)+'DCF Model'!G45/(1+$B19)^('DCF Model'!C19+4)+('DCF Model'!G39+'DCF Model'!G42)*C$17/(1+$B19)^('DCF Model'!C19+4)-'DCF Model'!C16)*1000000/'DCF Model'!C15,0),"") -> -28 | D19: =IFERROR(ROUND(('DCF Model'!C45/(1+$B19)^('DCF Model'!C19+0)+'DCF Model'!D45/(1+$B19)^('DCF Model'!C19+1)+'DCF Model'!E45/(1+$B19)^('DCF Model'!C19+2)+'DCF Model'!F45/(1+$B19)^('DCF Model'!C19+3)+'DCF Model'!G45/(1+$B19)^('DCF Model'!C19+4)+('DCF Model'!G39+'DCF Model'!G42)*D$17/(1+$B19)^('DCF Model'!C19+4)-'DCF Model'!C16)*1000000/'DCF Model'!C15,0),"") -> 235 | E19: =IFERROR(ROUND(('DCF Model'!C45/(1+$B19)^('DCF Model'!C19+0)+'DCF Model'!D45/(1+$B19)^('DCF Model'!C19+1)+'DCF Model'!E45/(1+$B19)^('DCF Model'!C19+2)+'DCF Model'!F45/(1+$B19)^('DCF Model'!C19+3)+'DCF Model'!G45/(1+$B19)^('DCF Model'!C19+4)+('DCF Model'!G39+'DCF Model'!G42)*E$17/(1+$B19)^('DCF Model'!C19+4)-'DCF Model'!C16)*1000000/'DCF Model'!C15,0),"") -> 498 | F19: =IFERROR(ROUND(('DCF Model'!C45/(1+$B19)^('DCF Model'!C19+0)+'DCF Model'!D45/(1+$B19)^('DCF Model'!C19+1)+'DCF Model'!E45/(1+$B19)^('DCF Model'!C19+2)+'DCF Model'!F45/(1+$B19)^('DCF Model'!C19+3)+'DCF Model'!G45/(1+$B19)^('DCF Model'!C19+4)+('DCF Model'!G39+'DCF Model'!G42)*F$17/(1+$B19)^('DCF Model'!C19+4)-'DCF Model'!C16)*1000000/'DCF Model'!C15,0),"") -> 761 | G19: =IFERROR(ROUND(('DCF Model'!C45/(1+$B19)^('DCF Model'!C19+0)+'DCF Model'!D45/(1+$B19)^('DCF Model'!C19+1)+'DCF Model'!E45/(1+$B19)^('DCF Model'!C19+2)+'DCF Model'!F45/(1+$B19)^('DCF Model'!C19+3)+'DCF Model'!G45/(1+$B19)^('DCF Model'!C19+4)+('DCF Model'!G39+'DCF Model'!G42)*G$17/(1+$B19)^('DCF Model'!C19+4)-'DCF Model'!C16)*1000000/'DCF Model'!C15,0),"") -> 1023 | H19: =IFERROR(ROUND(('DCF Model'!C45/(1+$B19)^('DCF Model'!C19+0)+'DCF Model'!D45/(1+$B19)^('DCF Model'!C19+1)+'DCF Model'!E45/(1+$B19)^('DCF Model'!C19+2)+'DCF Model'!F45/(1+$B19)^('DCF Model'!C19+3)+'DCF Model'!G45/(1+$B19)^('DCF Model'!C19+4)+('DCF Model'!G39+'DCF Model'!G42)*H$17/(1+$B19)^('DCF Model'!C19+4)-'DCF Model'!C16)*1000000/'DCF Model'!C15,0),"") -> 1286 | I19: =IFERROR(ROUND(('DCF Model'!C45/(1+$B19)^('DCF Model'!C19+0)+'DCF Model'!D45/(1+$B19)^('DCF Model'!C19+1)+'DCF Model'!E45/(1+$B19)^('DCF Model'!C19+2)+'DCF Model'!F45/(1+$B19)^('DCF Model'!C19+3)+'DCF Model'!G45/(1+$B19)^('DCF Model'!C19+4)+('DCF Model'!G39+'DCF Model'!G42)*I$17/(1+$B19)^('DCF Model'!C19+4)-'DCF Model'!C16)*1000000/'DCF Model'!C15,0),"") -> 1549
B20: =$C$3-0.005 -> 0.03905999 | C20: =IFERROR(ROUND(('DCF Model'!C45/(1+$B20)^('DCF Model'!C19+0)+'DCF Model'!D45/(1+$B20)^('DCF Model'!C19+1)+'DCF Model'!E45/(1+$B20)^('DCF Model'!C19+2)+'DCF Model'!F45/(1+$B20)^('DCF Model'!C19+3)+'DCF Model'!G45/(1+$B20)^('DCF Model'!C19+4)+('DCF Model'!G39+'DCF Model'!G42)*C$17/(1+$B20)^('DCF Model'!C19+4)-'DCF Model'!C16)*1000000/'DCF Model'!C15,0),"") -> -62 | D20: =IFERROR(ROUND(('DCF Model'!C45/(1+$B20)^('DCF Model'!C19+0)+'DCF Model'!D45/(1+$B20)^('DCF Model'!C19+1)+'DCF Model'!E45/(1+$B20)^('DCF Model'!C19+2)+'DCF Model'!F45/(1+$B20)^('DCF Model'!C19+3)+'DCF Model'!G45/(1+$B20)^('DCF Model'!C19+4)+('DCF Model'!G39+'DCF Model'!G42)*D$17/(1+$B20)^('DCF Model'!C19+4)-'DCF Model'!C16)*1000000/'DCF Model'!C15,0),"") -> 195 | E20: =IFERROR(ROUND(('DCF Model'!C45/(1+$B20)^('DCF Model'!C19+0)+'DCF Model'!D45/(1+$B20)^('DCF Model'!C19+1)+'DCF Model'!E45/(1+$B20)^('DCF Model'!C19+2)+'DCF Model'!F45/(1+$B20)^('DCF Model'!C19+3)+'DCF Model'!G45/(1+$B20)^('DCF Model'!C19+4)+('DCF Model'!G39+'DCF Model'!G42)*E$17/(1+$B20)^('DCF Model'!C19+4)-'DCF Model'!C16)*1000000/'DCF Model'!C15,0),"") -> 451 | F20: =IFERROR(ROUND(('DCF Model'!C45/(1+$B20)^('DCF Model'!C19+0)+'DCF Model'!D45/(1+$B20)^('DCF Model'!C19+1)+'DCF Model'!E45/(1+$B20)^('DCF Model'!C19+2)+'DCF Model'!F45/(1+$B20)^('DCF Model'!C19+3)+'DCF Model'!G45/(1+$B20)^('DCF Model'!C19+4)+('DCF Model'!G39+'DCF Model'!G42)*F$17/(1+$B20)^('DCF Model'!C19+4)-'DCF Model'!C16)*1000000/'DCF Model'!C15,0),"") -> 708 | G20: =IFERROR(ROUND(('DCF Model'!C45/(1+$B20)^('DCF Model'!C19+0)+'DCF Model'!D45/(1+$B20)^('DCF Model'!C19+1)+'DCF Model'!E45/(1+$B20)^('DCF Model'!C19+2)+'DCF Model'!F45/(1+$B20)^('DCF Model'!C19+3)+'DCF Model'!G45/(1+$B20)^('DCF Model'!C19+4)+('DCF Model'!G39+'DCF Model'!G42)*G$17/(1+$B20)^('DCF Model'!C19+4)-'DCF Model'!C16)*1000000/'DCF Model'!C15,0),"") -> 965 | H20: =IFERROR(ROUND(('DCF Model'!C45/(1+$B20)^('DCF Model'!C19+0)+'DCF Model'!D45/(1+$B20)^('DCF Model'!C19+1)+'DCF Model'!E45/(1+$B20)^('DCF Model'!C19+2)+'DCF Model'!F45/(1+$B20)^('DCF Model'!C19+3)+'DCF Model'!G45/(1+$B20)^('DCF Model'!C19+4)+('DCF Model'!G39+'DCF Model'!G42)*H$17/(1+$B20)^('DCF Model'!C19+4)-'DCF Model'!C16)*1000000/'DCF Model'!C15,0),"") -> 1221 | I20: =IFERROR(ROUND(('DCF Model'!C45/(1+$B20)^('DCF Model'!C19+0)+'DCF Model'!D45/(1+$B20)^('DCF Model'!C19+1)+'DCF Model'!E45/(1+$B20)^('DCF Model'!C19+2)+'DCF Model'!F45/(1+$B20)^('DCF Model'!C19+3)+'DCF Model'!G45/(1+$B20)^('DCF Model'!C19+4)+('DCF Model'!G39+'DCF Model'!G42)*I$17/(1+$B20)^('DCF Model'!C19+4)-'DCF Model'!C16)*1000000/'DCF Model'!C15,0),"") -> 1478
B21: =$C$3 -> 0.04405999 | C21: =IFERROR(ROUND(('DCF Model'!C45/(1+$B21)^('DCF Model'!C19+0)+'DCF Model'!D45/(1+$B21)^('DCF Model'!C19+1)+'DCF Model'!E45/(1+$B21)^('DCF Model'!C19+2)+'DCF Model'!F45/(1+$B21)^('DCF Model'!C19+3)+'DCF Model'!G45/(1+$B21)^('DCF Model'!C19+4)+('DCF Model'!G39+'DCF Model'!G42)*C$17/(1+$B21)^('DCF Model'!C19+4)-'DCF Model'!C16)*1000000/'DCF Model'!C15,0),"") -> -95 | D21: =IFERROR(ROUND(('DCF Model'!C45/(1+$B21)^('DCF Model'!C19+0)+'DCF Model'!D45/(1+$B21)^('DCF Model'!C19+1)+'DCF Model'!E45/(1+$B21)^('DCF Model'!C19+2)+'DCF Model'!F45/(1+$B21)^('DCF Model'!C19+3)+'DCF Model'!G45/(1+$B21)^('DCF Model'!C19+4)+('DCF Model'!G39+'DCF Model'!G42)*D$17/(1+$B21)^('DCF Model'!C19+4)-'DCF Model'!C16)*1000000/'DCF Model'!C15,0),"") -> 156 | E21: =IFERROR(ROUND(('DCF Model'!C45/(1+$B21)^('DCF Model'!C19+0)+'DCF Model'!D45/(1+$B21)^('DCF Model'!C19+1)+'DCF Model'!E45/(1+$B21)^('DCF Model'!C19+2)+'DCF Model'!F45/(1+$B21)^('DCF Model'!C19+3)+'DCF Model'!G45/(1+$B21)^('DCF Model'!C19+4)+('DCF Model'!G39+'DCF Model'!G42)*E$17/(1+$B21)^('DCF Model'!C19+4)-'DCF Model'!C16)*1000000/'DCF Model'!C15,0),"") -> 406 | F21: =IFERROR(ROUND(('DCF Model'!C45/(1+$B21)^('DCF Model'!C19+0)+'DCF Model'!D45/(1+$B21)^('DCF Model'!C19+1)+'DCF Model'!E45/(1+$B21)^('DCF Model'!C19+2)+'DCF Model'!F45/(1+$B21)^('DCF Model'!C19+3)+'DCF Model'!G45/(1+$B21)^('DCF Model'!C19+4)+('DCF Model'!G39+'DCF Model'!G42)*F$17/(1+$B21)^('DCF Model'!C19+4)-'DCF Model'!C16)*1000000/'DCF Model'!C15,0),"") -> 657 | G21: =IFERROR(ROUND(('DCF Model'!C45/(1+$B21)^('DCF Model'!C19+0)+'DCF Model'!D45/(1+$B21)^('DCF Model'!C19+1)+'DCF Model'!E45/(1+$B21)^('DCF Model'!C19+2)+'DCF Model'!F45/(1+$B21)^('DCF Model'!C19+3)+'DCF Model'!G45/(1+$B21)^('DCF Model'!C19+4)+('DCF Model'!G39+'DCF Model'!G42)*G$17/(1+$B21)^('DCF Model'!C19+4)-'DCF Model'!C16)*1000000/'DCF Model'!C15,0),"") -> 907 | H21: =IFERROR(ROUND(('DCF Model'!C45/(1+$B21)^('DCF Model'!C19+0)+'DCF Model'!D45/(1+$B21)^('DCF Model'!C19+1)+'DCF Model'!E45/(1+$B21)^('DCF Model'!C19+2)+'DCF Model'!F45/(1+$B21)^('DCF Model'!C19+3)+'DCF Model'!G45/(1+$B21)^('DCF Model'!C19+4)+('DCF Model'!G39+'DCF Model'!G42)*H$17/(1+$B21)^('DCF Model'!C19+4)-'DCF Model'!C16)*1000000/'DCF Model'!C15,0),"") -> 1158 | I21: =IFERROR(ROUND(('DCF Model'!C45/(1+$B21)^('DCF Model'!C19+0)+'DCF Model'!D45/(1+$B21)^('DCF Model'!C19+1)+'DCF Model'!E45/(1+$B21)^('DCF Model'!C19+2)+'DCF Model'!F45/(1+$B21)^('DCF Model'!C19+3)+'DCF Model'!G45/(1+$B21)^('DCF Model'!C19+4)+('DCF Model'!G39+'DCF Model'!G42)*I$17/(1+$B21)^('DCF Model'!C19+4)-'DCF Model'!C16)*1000000/'DCF Model'!C15,0),"") -> 1408
B22: =$C$3+0.005 -> 0.04905999 | C22: =IFERROR(ROUND(('DCF Model'!C45/(1+$B22)^('DCF Model'!C19+0)+'DCF Model'!D45/(1+$B22)^('DCF Model'!C19+1)+'DCF Model'!E45/(1+$B22)^('DCF Model'!C19+2)+'DCF Model'!F45/(1+$B22)^('DCF Model'!C19+3)+'DCF Model'!G45/(1+$B22)^('DCF Model'!C19+4)+('DCF Model'!G39+'DCF Model'!G42)*C$17/(1+$B22)^('DCF Model'!C19+4)-'DCF Model'!C16)*1000000/'DCF Model'!C15,0),"") -> -127 | D22: =IFERROR(ROUND(('DCF Model'!C45/(1+$B22)^('DCF Model'!C19+0)+'DCF Model'!D45/(1+$B22)^('DCF Model'!C19+1)+'DCF Model'!E45/(1+$B22)^('DCF Model'!C19+2)+'DCF Model'!F45/(1+$B22)^('DCF Model'!C19+3)+'DCF Model'!G45/(1+$B22)^('DCF Model'!C19+4)+('DCF Model'!G39+'DCF Model'!G42)*D$17/(1+$B22)^('DCF Model'!C19+4)-'DCF Model'!C16)*1000000/'DCF Model'!C15,0),"") -> 118 | E22: =IFERROR(ROUND(('DCF Model'!C45/(1+$B22)^('DCF Model'!C19+0)+'DCF Model'!D45/(1+$B22)^('DCF Model'!C19+1)+'DCF Model'!E45/(1+$B22)^('DCF Model'!C19+2)+'DCF Model'!F45/(1+$B22)^('DCF Model'!C19+3)+'DCF Model'!G45/(1+$B22)^('DCF Model'!C19+4)+('DCF Model'!G39+'DCF Model'!G42)*E$17/(1+$B22)^('DCF Model'!C19+4)-'DCF Model'!C16)*1000000/'DCF Model'!C15,0),"") -> 362 | F22: =IFERROR(ROUND(('DCF Model'!C45/(1+$B22)^('DCF Model'!C19+0)+'DCF Model'!D45/(1+$B22)^('DCF Model'!C19+1)+'DCF Model'!E45/(1+$B22)^('DCF Model'!C19+2)+'DCF Model'!F45/(1+$B22)^('DCF Model'!C19+3)+'DCF Model'!G45/(1+$B22)^('DCF Model'!C19+4)+('DCF Model'!G39+'DCF Model'!G42)*F$17/(1+$B22)^('DCF Model'!C19+4)-'DCF Model'!C16)*1000000/'DCF Model'!C15,0),"") -> 607 | G22: =IFERROR(ROUND(('DCF Model'!C45/(1+$B22)^('DCF Model'!C19+0)+'DCF Model'!D45/(1+$B22)^('DCF Model'!C19+1)+'DCF Model'!E45/(1+$B22)^('DCF Model'!C19+2)+'DCF Model'!F45/(1+$B22)^('DCF Model'!C19+3)+'DCF Model'!G45/(1+$B22)^('DCF Model'!C19+4)+('DCF Model'!G39+'DCF Model'!G42)*G$17/(1+$B22)^('DCF Model'!C19+4)-'DCF Model'!C16)*1000000/'DCF Model'!C15,0),"") -> 852 | H22: =IFERROR(ROUND(('DCF Model'!C45/(1+$B22)^('DCF Model'!C19+0)+'DCF Model'!D45/(1+$B22)^('DCF Model'!C19+1)+'DCF Model'!E45/(1+$B22)^('DCF Model'!C19+2)+'DCF Model'!F45/(1+$B22)^('DCF Model'!C19+3)+'DCF Model'!G45/(1+$B22)^('DCF Model'!C19+4)+('DCF Model'!G39+'DCF Model'!G42)*H$17/(1+$B22)^('DCF Model'!C19+4)-'DCF Model'!C16)*1000000/'DCF Model'!C15,0),"") -> 1096 | I22: =IFERROR(ROUND(('DCF Model'!C45/(1+$B22)^('DCF Model'!C19+0)+'DCF Model'!D45/(1+$B22)^('DCF Model'!C19+1)+'DCF Model'!E45/(1+$B22)^('DCF Model'!C19+2)+'DCF Model'!F45/(1+$B22)^('DCF Model'!C19+3)+'DCF Model'!G45/(1+$B22)^('DCF Model'!C19+4)+('DCF Model'!G39+'DCF Model'!G42)*I$17/(1+$B22)^('DCF Model'!C19+4)-'DCF Model'!C16)*1000000/'DCF Model'!C15,0),"") -> 1341
B23: =$C$3+0.01 -> 0.05405999 | C23: =IFERROR(ROUND(('DCF Model'!C45/(1+$B23)^('DCF Model'!C19+0)+'DCF Model'!D45/(1+$B23)^('DCF Model'!C19+1)+'DCF Model'!E45/(1+$B23)^('DCF Model'!C19+2)+'DCF Model'!F45/(1+$B23)^('DCF Model'!C19+3)+'DCF Model'!G45/(1+$B23)^('DCF Model'!C19+4)+('DCF Model'!G39+'DCF Model'!G42)*C$17/(1+$B23)^('DCF Model'!C19+4)-'DCF Model'!C16)*1000000/'DCF Model'!C15,0),"") -> -158 | D23: =IFERROR(ROUND(('DCF Model'!C45/(1+$B23)^('DCF Model'!C19+0)+'DCF Model'!D45/(1+$B23)^('DCF Model'!C19+1)+'DCF Model'!E45/(1+$B23)^('DCF Model'!C19+2)+'DCF Model'!F45/(1+$B23)^('DCF Model'!C19+3)+'DCF Model'!G45/(1+$B23)^('DCF Model'!C19+4)+('DCF Model'!G39+'DCF Model'!G42)*D$17/(1+$B23)^('DCF Model'!C19+4)-'DCF Model'!C16)*1000000/'DCF Model'!C15,0),"") -> 81 | E23: =IFERROR(ROUND(('DCF Model'!C45/(1+$B23)^('DCF Model'!C19+0)+'DCF Model'!D45/(1+$B23)^('DCF Model'!C19+1)+'DCF Model'!E45/(1+$B23)^('DCF Model'!C19+2)+'DCF Model'!F45/(1+$B23)^('DCF Model'!C19+3)+'DCF Model'!G45/(1+$B23)^('DCF Model'!C19+4)+('DCF Model'!G39+'DCF Model'!G42)*E$17/(1+$B23)^('DCF Model'!C19+4)-'DCF Model'!C16)*1000000/'DCF Model'!C15,0),"") -> 320 | F23: =IFERROR(ROUND(('DCF Model'!C45/(1+$B23)^('DCF Model'!C19+0)+'DCF Model'!D45/(1+$B23)^('DCF Model'!C19+1)+'DCF Model'!E45/(1+$B23)^('DCF Model'!C19+2)+'DCF Model'!F45/(1+$B23)^('DCF Model'!C19+3)+'DCF Model'!G45/(1+$B23)^('DCF Model'!C19+4)+('DCF Model'!G39+'DCF Model'!G42)*F$17/(1+$B23)^('DCF Model'!C19+4)-'DCF Model'!C16)*1000000/'DCF Model'!C15,0),"") -> 558 | G23: =IFERROR(ROUND(('DCF Model'!C45/(1+$B23)^('DCF Model'!C19+0)+'DCF Model'!D45/(1+$B23)^('DCF Model'!C19+1)+'DCF Model'!E45/(1+$B23)^('DCF Model'!C19+2)+'DCF Model'!F45/(1+$B23)^('DCF Model'!C19+3)+'DCF Model'!G45/(1+$B23)^('DCF Model'!C19+4)+('DCF Model'!G39+'DCF Model'!G42)*G$17/(1+$B23)^('DCF Model'!C19+4)-'DCF Model'!C16)*1000000/'DCF Model'!C15,0),"") -> 797 | H23: =IFERROR(ROUND(('DCF Model'!C45/(1+$B23)^('DCF Model'!C19+0)+'DCF Model'!D45/(1+$B23)^('DCF Model'!C19+1)+'DCF Model'!E45/(1+$B23)^('DCF Model'!C19+2)+'DCF Model'!F45/(1+$B23)^('DCF Model'!C19+3)+'DCF Model'!G45/(1+$B23)^('DCF Model'!C19+4)+('DCF Model'!G39+'DCF Model'!G42)*H$17/(1+$B23)^('DCF Model'!C19+4)-'DCF Model'!C16)*1000000/'DCF Model'!C15,0),"") -> 1036 | I23: =IFERROR(ROUND(('DCF Model'!C45/(1+$B23)^('DCF Model'!C19+0)+'DCF Model'!D45/(1+$B23)^('DCF Model'!C19+1)+'DCF Model'!E45/(1+$B23)^('DCF Model'!C19+2)+'DCF Model'!F45/(1+$B23)^('DCF Model'!C19+3)+'DCF Model'!G45/(1+$B23)^('DCF Model'!C19+4)+('DCF Model'!G39+'DCF Model'!G42)*I$17/(1+$B23)^('DCF Model'!C19+4)-'DCF Model'!C16)*1000000/'DCF Model'!C15,0),"") -> 1275
B24: =$C$3+0.015 -> 0.05905999 | C24: =IFERROR(ROUND(('DCF Model'!C45/(1+$B24)^('DCF Model'!C19+0)+'DCF Model'!D45/(1+$B24)^('DCF Model'!C19+1)+'DCF Model'!E45/(1+$B24)^('DCF Model'!C19+2)+'DCF Model'!F45/(1+$B24)^('DCF Model'!C19+3)+'DCF Model'!G45/(1+$B24)^('DCF Model'!C19+4)+('DCF Model'!G39+'DCF Model'!G42)*C$17/(1+$B24)^('DCF Model'!C19+4)-'DCF Model'!C16)*1000000/'DCF Model'!C15,0),"") -> -188 | D24: =IFERROR(ROUND(('DCF Model'!C45/(1+$B24)^('DCF Model'!C19+0)+'DCF Model'!D45/(1+$B24)^('DCF Model'!C19+1)+'DCF Model'!E45/(1+$B24)^('DCF Model'!C19+2)+'DCF Model'!F45/(1+$B24)^('DCF Model'!C19+3)+'DCF Model'!G45/(1+$B24)^('DCF Model'!C19+4)+('DCF Model'!G39+'DCF Model'!G42)*D$17/(1+$B24)^('DCF Model'!C19+4)-'DCF Model'!C16)*1000000/'DCF Model'!C15,0),"") -> 45 | E24: =IFERROR(ROUND(('DCF Model'!C45/(1+$B24)^('DCF Model'!C19+0)+'DCF Model'!D45/(1+$B24)^('DCF Model'!C19+1)+'DCF Model'!E45/(1+$B24)^('DCF Model'!C19+2)+'DCF Model'!F45/(1+$B24)^('DCF Model'!C19+3)+'DCF Model'!G45/(1+$B24)^('DCF Model'!C19+4)+('DCF Model'!G39+'DCF Model'!G42)*E$17/(1+$B24)^('DCF Model'!C19+4)-'DCF Model'!C16)*1000000/'DCF Model'!C15,0),"") -> 278 | F24: =IFERROR(ROUND(('DCF Model'!C45/(1+$B24)^('DCF Model'!C19+0)+'DCF Model'!D45/(1+$B24)^('DCF Model'!C19+1)+'DCF Model'!E45/(1+$B24)^('DCF Model'!C19+2)+'DCF Model'!F45/(1+$B24)^('DCF Model'!C19+3)+'DCF Model'!G45/(1+$B24)^('DCF Model'!C19+4)+('DCF Model'!G39+'DCF Model'!G42)*F$17/(1+$B24)^('DCF Model'!C19+4)-'DCF Model'!C16)*1000000/'DCF Model'!C15,0),"") -> 511 | G24: =IFERROR(ROUND(('DCF Model'!C45/(1+$B24)^('DCF Model'!C19+0)+'DCF Model'!D45/(1+$B24)^('DCF Model'!C19+1)+'DCF Model'!E45/(1+$B24)^('DCF Model'!C19+2)+'DCF Model'!F45/(1+$B24)^('DCF Model'!C19+3)+'DCF Model'!G45/(1+$B24)^('DCF Model'!C19+4)+('DCF Model'!G39+'DCF Model'!G42)*G$17/(1+$B24)^('DCF Model'!C19+4)-'DCF Model'!C16)*1000000/'DCF Model'!C15,0),"") -> 745 | H24: =IFERROR(ROUND(('DCF Model'!C45/(1+$B24)^('DCF Model'!C19+0)+'DCF Model'!D45/(1+$B24)^('DCF Model'!C19+1)+'DCF Model'!E45/(1+$B24)^('DCF Model'!C19+2)+'DCF Model'!F45/(1+$B24)^('DCF Model'!C19+3)+'DCF Model'!G45/(1+$B24)^('DCF Model'!C19+4)+('DCF Model'!G39+'DCF Model'!G42)*H$17/(1+$B24)^('DCF Model'!C19+4)-'DCF Model'!C16)*1000000/'DCF Model'!C15,0),"") -> 978 | I24: =IFERROR(ROUND(('DCF Model'!C45/(1+$B24)^('DCF Model'!C19+0)+'DCF Model'!D45/(1+$B24)^('DCF Model'!C19+1)+'DCF Model'!E45/(1+$B24)^('DCF Model'!C19+2)+'DCF Model'!F45/(1+$B24)^('DCF Model'!C19+3)+'DCF Model'!G45/(1+$B24)^('DCF Model'!C19+4)+('DCF Model'!G39+'DCF Model'!G42)*I$17/(1+$B24)^('DCF Model'!C19+4)-'DCF Model'!C16)*1000000/'DCF Model'!C15,0),"") -> 1211
B26: All values dynamically linked to DCF Model. Headers auto-center on current WACC / Terminal g / Exit Multiple.

Sheet SOTP Cross-Check
B2: SOTP Cross-Check (intended PRIMARY framework -- see note)
B3: AEON is a holding company for many listed/unlisted subsidiaries; a consolidated DCF ('DCF Model' sheet) is an approximation. SOTP is the theoretically correct lens, but see the critical finding below before using this sheet's totals.
B5: CRITICAL FINDING: 3 of 9 originally-in-scope subsidiaries went private in 2025
B6: AEON Mall (8905) | C6: Delisted 2025-06-27 (share exchange -> 100% AEON-owned)
B7: AEON Delight (9787) | C7: Delisted 2025-07-17 (TOB + squeeze-out -> 100% AEON-owned)
B8: Welcia Holdings (3141) | C8: Delisted 2025-11-27 (merged into Tsuruha Holdings as wholly-owned sub)
B10: Only 6 of the 9 remain listed with a market price. Per the source prompt's own fallback instruction, this sheet presents the sum of the 6 remaining listed stakes as an explicit FLOOR value -- it does NOT attempt to price the now-wholly-owned AEON Mall / AEON Delight, the Welcia business now inside Tsuruha, or the GMS/SM retail core (no reliable, non-guessed EBITDA breakdown by segment is available for AEON). The floor will therefore sit far below AEON's actual market cap by construction -- that gap IS the (unquantified) value of the wholly-owned businesses.
B13: Listed Subsidiary / Affiliate Stakes
B14: Company | C14: Ticker | D14: Market Cap (JPY mn) | E14: AEON Ownership % | F14: Implied Stake Value (JPY mn)
B15: AEON Financial Service | C15: 8570.T | D15: 325500 | E15: 0.4817 | F15: =D15*E15 -> 156793.35
B16: Tsuruha Holdings | C16: 3391.T | D16: 1175800 | E16: 0.5033 | F16: =D16*E16 -> 591780.14
B17: AEON Kyushu | C17: 2653.T | D17: 99171 | E17: 0.699 | F17: =D17*E17 -> 69320.529
B18: AEON Hokkaido | C18: 7512.T | D18: 121016 | E18: 0.6562 | F18: =D18*E18 -> 79410.699
B19: Maxvalu Tokai | C19: 8198.T | D19: 107751 | E19: 0.6386 | F19: =D19*E19 -> 68809.789
B20: Ministop | C20: 9946.T | D20: 52871 | E20: 0.4871 | F20: =D20*E20 -> 25753.464
B21: Sum of Listed Stakes (JPY mn) | F21: =SUM(F15:F20) -> 991867.97
B22: Market cap data as of late Jul 2026; ownership % from FY2026/2 yuho 'related companies' disclosures (Tsuruha stake reflects the Jan-2026 TOB result, 50.11%->50.33% via subsequent market purchases).
B24: Non-listed / wholly-owned businesses (AEON Mall, AEON Delight, GMS/SM core, Welcia-in-Tsuruha)
B25: NOT PRICED -- no reliable per-segment EBITDA breakdown available; not guessed (per instruction).
B27: Bridge to SOTP Equity Value (FLOOR -- listed stakes only)
B28: Sum of Listed Stakes (JPY mn) | C28: =F21 -> 991867.97
B29: Less: Parent (unconsolidated) net interest-bearing debt | C29: 3099169
B30: Note: parent-only (単体) net debt was not obtained; using CONSOLIDATED net interest-bearing debt (excl. bank deposits, excl. MI addback) as a fallback per prompt instruction -- this OVERSTATES the deduction versus a true parent-only figure, making the floor value conservative (too low).
B31: SOTP Equity Value - FLOOR (JPY mn) | C31: =C28-C29 -> -2107301
B32: Shares Outstanding | C32: ='DCF Model'!C15 -> 2765768421
B33: SOTP Floor Value per Share (JPY, pre-discount) | C33: =ROUND(C31/C32*1000000,0) -> -762
B35: This floor is likely NEGATIVE or small: it deducts group-level debt against only a small slice of group value (the 6 remaining minority-held listed stakes), deliberately excluding the wholly-owned businesses that generate most of consolidated EBITDA. A negative or very low floor does NOT mean AEON is worth that little -- it means this floor construction cannot see most of the company. Treat as a data-availability limitation, not a valuation conclusion.
B38: Holding Company Discount Sensitivity (applied to floor equity value)
B39: Discount % | C39: SOTP Equity Value (JPY mn) | D39: Per Share (JPY) | E39: vs Current Price (1,424)
B40: 0 | C40: =$C$31*(1-B40) -> -2107301 | D40: =ROUND(C40/$C$32*1000000,0) -> -762 | E40: =D40/1424-1 -> -1.5351124
B41: 0.1 | C41: =$C$31*(1-B41) -> -1896570.9 | D41: =ROUND(C41/$C$32*1000000,0) -> -686 | E41: =D41/1424-1 -> -1.4817416
B42: 0.2 | C42: =$C$31*(1-B42) -> -1685840.8 | D42: =ROUND(C42/$C$32*1000000,0) -> -610 | E42: =D42/1424-1 -> -1.4283708
B43: 0.3 | C43: =$C$31*(1-B43) -> -1475110.7 | D43: =ROUND(C43/$C$32*1000000,0) -> -533 | E43: =D43/1424-1 -> -1.3742978
B44: 0.4 | C44: =$C$31*(1-B44) -> -1264380.6 | D44: =ROUND(C44/$C$32*1000000,0) -> -457 | E44: =D44/1424-1 -> -1.320927
B46: No discount level makes the floor value approach the current price of 1,424 -- confirming this floor is not a usable standalone valuation. It only demonstrates that the value of AEON's remaining minority listed stakes is a small fraction of the group's total equity value; the balance of AEON's ~3,938,454mn market cap is attributable to wholly-owned businesses this sheet cannot independently price.
B49: Cross-check: Sum of Listed Stakes vs Non-Controlling Interests (book)
B50: Sum of Listed Stakes (JPY mn, AEON's share) | C50: =F21 -> 991867.97
B51: Non-Controlling Interests, book value (JPY mn) | C51: 984094
B52: Difference (JPY mn) | C52: =C50-C51 -> 7773.9709
B53: Difference per share (JPY) | C53: =ROUND(C52/C32*1000000,0) -> 3
...
